{"symbol":"TONUSDT","bids":[["3.1493","403.1"],["3.1492","2216.2"],["3.1490","2254.5"],["3.1489","996.3"],["3.1487","1110.7"],["3.1485","1856.2"],["3.1483","1771.2"],["3.1481","3176.8"],["3.1479","1143.3"],["3.1477","1335.5"],["3.1465","592.1"],["3.1461","875.9"],["3.1457","573.1"],["3.1453","891.7"],["3.1449","2632.1"]],"asks":[["3.1501","0"],["3.1503","61.6"],["3.1504","164.8"],["3.1505","663.2"],["3.1506","5.0"],["3.1507","117.8"],["3.1508","1120.2"],["3.1509","1439.2"],["3.1510","1406.1"],["3.1511","1107.7"],["3.1513","2487.1"],["3.1518","3062.9"],["3.1523","2760.4"],["3.1528","2404.6"],["3.1532","1888.2"],["3.1535","751.7"],["3.1537","2672.9"],["3.1538","890.2"],["3.1541","1426.7"],["3.1543","1372.8"],["3.1545","1040.7"],["3.1547","1638.2"],["3.1549","2571.3"],["3.1551","2400.8"],["3.1552","3336.7"]],"timestamp":1756901034489,"update_id":50200439,"fetch_time":1756901034538}
{"symbol":"TONUSDT","bids":[["3.1497","14.1"],["3.1496","513.2"],["3.1495","71.9"],["3.1494","1075.0"],["3.1493","445.3"],["3.1490","1989.9"],["3.1485","2897.8"],["3.1478","1270.7"],["3.1448","0"]],"asks":[["3.1504","6.1"],["3.1507","74.8"],["3.1508","1020.6"],["3.1509","1396.2"],["3.1510","1362.8"],["3.1511","1064.4"],["3.1512","3146.5"],["3.1515","1253.3"],["3.1517","2886.1"]],"timestamp":1756901034509,"update_id":50200440,"fetch_time":1756901034561}
{"symbol":"TONUSDT","bids":[],"asks":[["3.1508","2456.8"]],"timestamp":1756901034549,"update_id":50200442,"fetch_time":1756901034598}
{"symbol":"TONUSDT","bids":[],"asks":[["3.1507","607.5"]],"timestamp":1756901034850,"update_id":50200444,"fetch_time":1756901034899}
{"symbol":"TONUSDT","bids":[],"asks":[["3.1508","2496.0"],["3.1509","1435.4"],["3.1510","1595.2"]],"timestamp":1756901034869,"update_id":50200445,"fetch_time":1756901034914}
{"symbol":"TONUSDT","bids":[],"asks":[["3.1509","1276.8"],["3.1514","4166.5"]],"timestamp":1756901035050,"update_id":50200446,"fetch_time":1756901035098}
{"symbol":"TONUSDT","bids":[["3.1495","165.8"]],"asks":[],"timestamp":1756901035109,"update_id":50200448,"fetch_time":1756901035158}
{"symbol":"TONUSDT","bids":[["3.1495","170.6"]],"asks":[],"timestamp":1756901035589,"update_id":50200450,"fetch_time":1756901035636}
{"symbol":"TONUSDT","bids":[],"asks":[["3.1511","826.7"]],"timestamp":1756901035610,"update_id":50200451,"fetch_time":1756901035658}
{"symbol":"TONUSDT","bids":[],"asks":[["3.1510","1814.1"]],"timestamp":1756901035630,"update_id":50200452,"fetch_time":1756901035681}
{"symbol":"TONUSDT","bids":[["3.1493","434.3"]],"asks":[],"timestamp":1756901035930,"update_id":50200453,"fetch_time":1756901035985}
{"symbol":"TONUSDT","bids":[["3.1497","0"],["3.1448","11026.9"]],"asks":[],"timestamp":1756901035949,"update_id":50200454,"fetch_time":1756901035996}
{"symbol":"TONUSDT","bids":[],"asks":[["3.1514","4354.7"],["3.1517","3187.2"],["3.1520","2204.7"],["3.1523","3287.3"],["3.1526","2064.5"],["3.1529","1750.3"],["3.1536","5788.2"],["3.1541","1238.5"],["3.1543","1071.7"],["3.1545","827.3"],["3.1547","1111.3"],["3.1549","663.9"],["3.1551","1848.7"]],"timestamp":1756901035970,"update_id":50200455,"fetch_time":1756901036022}
{"symbol":"TONUSDT","bids":[],"asks":[["3.1505","700.9"]],"timestamp":1756901036009,"update_id":50200457,"fetch_time":1756901036055}
{"symbol":"TONUSDT","bids":[],"asks":[["3.1530","2170.0"],["3.1532","4886.7"]],"timestamp":1756901036150,"update_id":50200458,"fetch_time":1756901036197}
{"symbol":"TONUSDT","bids":[],"asks":[["3.1528","1665.2"],["3.1550","2399.4"]],"timestamp":1756901036169,"update_id":50200459,"fetch_time":1756901036219}
{"symbol":"TONUSDT","bids":[],"asks":[["3.1548","3648.0"]],"timestamp":1756901036189,"update_id":50200460,"fetch_time":1756901036247}
{"symbol":"TONUSDT","bids":[["3.1492","2216.2"]],"asks":[],"timestamp":1756901036209,"update_id":50200461,"fetch_time":1756901036257}
{"symbol":"TONUSDT","bids":[],"asks":[["3.1550","3667.0"]],"timestamp":1756901036230,"update_id":50200462,"fetch_time":1756901036278}
{"symbol":"TONUSDT","bids":[],"asks":[["3.1548","4029.0"]],"timestamp":1756901036250,"update_id":50200463,"fetch_time":1756901036299}
{"symbol":"TONUSDT","bids":[],"asks":[["3.1505","663.2"]],"timestamp":1756901036289,"update_id":50200465,"fetch_time":1756901036338}
{"symbol":"TONUSDT","bids":[],"asks":[["3.1506","83.4"],["3.1507","646.7"]],"timestamp":1756901036410,"update_id":50200466,"fetch_time":1756901036458}
{"symbol":"TONUSDT","bids":[["3.1493","434.3"]],"asks":[],"timestamp":1756901036530,"update_id":50200467,"fetch_time":1756901036576}
{"symbol":"TONUSDT","bids":[["3.1486","1437.9"]],"asks":[],"timestamp":1756901036550,"update_id":50200468,"fetch_time":1756901036600}
{"symbol":"TONUSDT","bids":[],"asks":[["3.1503","201.6"],["3.1505","700.9"],["3.1509","1369.1"],["3.1510","1595.2"]],"timestamp":1756901036750,"update_id":50200469,"fetch_time":1756901036800}
{"symbol":"TONUSDT","bids":[["3.1493","395.1"],["3.1492","2177.0"]],"asks":[["3.1501","28.8"],["3.1502","20.0"],["3.1504","176.3"],["3.1505","739.1"],["3.1536","5759.9"],["3.1537","2674.9"],["3.1538","888.2"],["3.1549","1931.5"],["3.1550","2399.4"],["3.1551","0"],["3.1552","0"]],"timestamp":1756901036770,"update_id":50200470,"fetch_time":1756901036823}
{"symbol":"TONUSDT","bids":[["3.1495","9.6"],["3.1489","1257.9"]],"asks":[["3.1502","0"],["3.1503","231.0"],["3.1506","146.8"],["3.1511","787.5"],["3.1536","5761.9"],["3.1537","2672.9"],["3.1551","1848.7"]],"timestamp":1756901036789,"update_id":50200471,"fetch_time":1756901036839}
{"symbol":"TONUSDT","bids":[],"asks":[["3.1504","179.5"],["3.1506","807.9"],["3.1507","890.0"],["3.1508","2827.5"]],"timestamp":1756901036810,"update_id":50200472,"fetch_time":1756901036865}
{"symbol":"TONUSDT","bids":[],"asks":[["3.1508","2103.5"]],"timestamp":1756901036870,"update_id":50200475,"fetch_time":1756901036925}
{"symbol":"TONUSDT","bids":[],"asks":[["3.1508","1820.3"]],"timestamp":1756901036910,"update_id":50200476,"fetch_time":1756901036982}
{"symbol":"TONUSDT","bids":[],"asks":[["3.1507","699.0"]],"timestamp":1756901036930,"update_id":50200477,"fetch_time":1756901036982}
{"symbol":"TONUSDT","bids":[["3.1495","8.0"]],"asks":[],"timestamp":1756901037009,"update_id":50200479,"fetch_time":1756901037057}
{"symbol":"TONUSDT","bids":[["3.1498","5.2"],["3.1494","994.1"],["3.1493","352.9"],["3.1492","2137.8"]],"asks":[],"timestamp":1756901037330,"update_id":50200480,"fetch_time":1756901037381}
{"symbol":"TONUSDT","bids":[["3.1498","1.0"]],"asks":[],"timestamp":1756901037349,"update_id":50200481,"fetch_time":1756901037397}
{"symbol":"TONUSDT","bids":[],"asks":[["3.1510","1954.4"],["3.1514","4196.1"],["3.1548","3648.0"],["3.1549","1931.5"]],"timestamp":1756901037410,"update_id":50200484,"fetch_time":1756901037457}
{"symbol":"TONUSDT","bids":[["3.1492","1859.6"]],"asks":[],"timestamp":1756901037470,"update_id":50200486,"fetch_time":1756901037518}
{"symbol":"TONUSDT","bids":[["3.1492","1898.8"]],"asks":[],"timestamp":1756901037489,"update_id":50200487,"fetch_time":1756901037537}
{"symbol":"TONUSDT","bids":[],"asks":[["3.1530","2999.7"]],"timestamp":1756901037629,"update_id":50200489,"fetch_time":1756901037677}
{"symbol":"TONUSDT","bids":[["3.1498","3.7"]],"asks":[["3.1500","39.2"],["3.1551","0"]],"timestamp":1756901037690,"update_id":50200490,"fetch_time":1756901037738}
{"symbol":"TONUSDT","bids":[["3.1496","460.1"],["3.1495","8.0"]],"asks":[["3.1499","28.8"],["3.1501","0"],["3.1502","158.7"],["3.1503","204.8"],["3.1505","927.9"],["3.1510","1772.2"],["3.1511","621.9"],["3.1513","2318.5"],["3.1534","3585.9"],["3.1536","5759.9"],["3.1546","1815.4"],["3.1548","4029.0"],["3.1550","0"]],"timestamp":1756901037710,"update_id":50200491,"fetch_time":1756901037761}
{"symbol":"TONUSDT","bids":[],"asks":[["3.1502","0"],["3.1504","935.1"],["3.1505","1351.4"],["3.1550","2399.4"]],"timestamp":1756901037730,"update_id":50200492,"fetch_time":1756901037777}
{"symbol":"TONUSDT","bids":[["3.1493","258.3"],["3.1490","2029.1"]],"asks":[["3.1502","169.2"],["3.1503","363.5"],["3.1504","983.8"],["3.1505","1807.4"],["3.1550","0"]],"timestamp":1756901037749,"update_id":50200493,"fetch_time":1756901037797}
{"symbol":"TONUSDT","bids":[],"asks":[["3.1502","157.1"],["3.1504","1172.6"],["3.1506","713.4"]],"timestamp":1756901037769,"update_id":50200494,"fetch_time":1756901037817}
{"symbol":"TONUSDT","bids":[],"asks":[["3.1506","430.2"],["3.1549","663.9"]],"timestamp":1756901037790,"update_id":50200495,"fetch_time":1756901037837}
{"symbol":"TONUSDT","bids":[],"asks":[["3.1548","3648.0"],["3.1549","1931.5"]],"timestamp":1756901037809,"update_id":50200496,"fetch_time":1756901037857}
{"symbol":"TONUSDT","bids":[],"asks":[["3.1506","146.8"],["3.1549","663.9"]],"timestamp":1756901037830,"update_id":50200497,"fetch_time":1756901037877}
{"symbol":"TONUSDT","bids":[],"asks":[["3.1506","83.4"]],"timestamp":1756901037849,"update_id":50200498,"fetch_time":1756901037897}
{"symbol":"TONUSDT","bids":[],"asks":[["3.1505","1618.6"]],"timestamp":1756901037870,"update_id":50200499,"fetch_time":1756901037917}
{"symbol":"TONUSDT","bids":[["3.1496","309.9"],["3.1462","1251.9"],["3.1456","3799.4"]],"asks":[],"timestamp":1756901038010,"update_id":50200500,"fetch_time":1756901038062}
{"symbol":"TONUSDT","bids":[["3.1495","134.7"],["3.1458","1373.7"]],"asks":[],"timestamp":1756901038029,"update_id":50200501,"fetch_time":1756901038077}
{"symbol":"TONUSDT","bids":[["3.1489","1099.3"]],"asks":[],"timestamp":1756901038049,"update_id":50200502,"fetch_time":1756901038097}
{"symbol":"TONUSDT","bids":[["3.1484","1559.5"]],"asks":[],"timestamp":1756901038070,"update_id":50200503,"fetch_time":1756901038117}
{"symbol":"TONUSDT","bids":[],"asks":[["3.1549","663.9"]],"timestamp":1756901038169,"update_id":50200505,"fetch_time":1756901038285}
{"symbol":"TONUSDT","bids":[],"asks":[["3.1506","109.6"],["3.1507","672.8"],["3.1512","3009.7"],["3.1513","2256.5"],["3.1549","1931.5"]],"timestamp":1756901038210,"update_id":50200506,"fetch_time":1756901038285}
{"symbol":"TONUSDT","bids":[],"asks":[["3.1549","663.9"]],"timestamp":1756901038229,"update_id":50200507,"fetch_time":1756901038285}
{"symbol":"TONUSDT","bids":[],"asks":[["3.1512","3809.7"]],"timestamp":1756901038289,"update_id":50200508,"fetch_time":1756901038337}
{"symbol":"TONUSDT","bids":[],"asks":[["3.1549","663.9"]],"timestamp":1756901038350,"update_id":50200510,"fetch_time":1756901038401}
{"symbol":"TONUSDT","bids":[],"asks":[["3.1549","1931.5"]],"timestamp":1756901038410,"update_id":50200511,"fetch_time":1756901038457}
{"symbol":"TONUSDT","bids":[],"asks":[["3.1549","663.9"]],"timestamp":1756901038670,"update_id":50200512,"fetch_time":1756901038717}
{"symbol":"TONUSDT","bids":[],"asks":[["3.1549","1931.5"]],"timestamp":1756901038690,"update_id":50200513,"fetch_time":1756901038741}
{"symbol":"TONUSDT","bids":[["3.1498","0"],["3.1497","133.5"],["3.1496","445.0"],["3.1494","990.5"],["3.1492","1859.6"],["3.1488","897.9"]],"asks":[["3.1502","3.2"],["3.1504","1013.9"],["3.1512","3009.7"]],"timestamp":1756901038989,"update_id":50200514,"fetch_time":1756901039037}
{"symbol":"TONUSDT","bids":[["3.1494","838.5"],["3.1492","2048.4"]],"asks":[],"timestamp":1756901039029,"update_id":50200516,"fetch_time":1756901039077}
{"symbol":"TONUSDT","bids":[["3.1473","2290.1"],["3.1471","1434.7"]],"asks":[],"timestamp":1756901039049,"update_id":50200517,"fetch_time":1756901039097}
{"symbol":"TONUSDT","bids":[["3.1498","0.6"],["3.1495","151.4"],["3.1493","44.8"],["3.1448","0"]],"asks":[["3.1505","1636.2"],["3.1506","83.4"]],"timestamp":1756901039069,"update_id":50200518,"fetch_time":1756901039121}
{"symbol":"TONUSDT","bids":[["3.1493","233.6"]],"asks":[],"timestamp":1756901039130,"update_id":50200519,"fetch_time":1756901039181}
{"symbol":"TONUSDT","bids":[["3.1492","1859.6"]],"asks":[],"timestamp":1756901039169,"update_id":50200520,"fetch_time":1756901039217}
{"symbol":"TONUSDT","bids":[["3.1484","2200.9"]],"asks":[],"timestamp":1756901039410,"update_id":50200523,"fetch_time":1756901039457}
{"symbol":"TONUSDT","bids":[["3.1492","1898.8"]],"asks":[],"timestamp":1756901039429,"update_id":50200524,"fetch_time":1756901039477}
{"symbol":"TONUSDT","bids":[],"asks":[["3.1505","1601.4"],["3.1506","44.2"],["3.1507","629.8"],["3.1508","1777.1"],["3.1509","1325.9"],["3.1510","1574.4"],["3.1548","4029.0"]],"timestamp":1756901039829,"update_id":50200525,"fetch_time":1756901039877}
{"symbol":"TONUSDT","bids":[["3.1494","897.1"],["3.1493","272.8"]],"asks":[],"timestamp":1756901039930,"update_id":50200526,"fetch_time":1756901039977}
{"symbol":"TONUSDT","bids":[],"asks":[["3.1539","1516.9"]],"timestamp":1756901039970,"update_id":50200527,"fetch_time":1756901040017}
{"symbol":"TONUSDT","bids":[["3.1498","0"],["3.1448","11747.4"]],"asks":[],"timestamp":1756901040009,"update_id":50200528,"fetch_time":1756901040057}
{"symbol":"TONUSDT","bids":[["3.1493","84.0"],["3.1492","2087.6"],["3.1484","1400.9"]],"asks":[],"timestamp":1756901040030,"update_id":50200529,"fetch_time":1756901040077}
{"symbol":"TONUSDT","bids":[["3.1496","449.1"]],"asks":[],"timestamp":1756901040329,"update_id":50200530,"fetch_time":1756901040377}
{"symbol":"TONUSDT","bids":[["3.1498","18.2"],["3.1496","445.9"],["3.1448","0"]],"asks":[["3.1499","0"],["3.1503","64.8"],["3.1504","6.1"],["3.1505","1563.2"],["3.1506","5.0"],["3.1507","590.6"],["3.1508","1737.9"],["3.1509","1286.7"],["3.1510","1700.8"],["3.1534","3583.9"],["3.1535","753.7"],["3.1550","2399.4"]],"timestamp":1756901040429,"update_id":50200531,"fetch_time":1756901040481}
{"symbol":"TONUSDT","bids":[],"asks":[["3.1505","1752.1"],["3.1508","1777.1"],["3.1509","1325.9"]],"timestamp":1756901040450,"update_id":50200532,"fetch_time":1756901040497}
{"symbol":"TONUSDT","bids":[["3.1492","1898.8"]],"asks":[],"timestamp":1756901040590,"update_id":50200535,"fetch_time":1756901040641}
{"symbol":"TONUSDT","bids":[],"asks":[["3.1504","164.8"]],"timestamp":1756901040630,"update_id":50200536,"fetch_time":1756901040681}
{"symbol":"TONUSDT","bids":[],"asks":[["3.1508","1816.3"]],"timestamp":1756901040649,"update_id":50200537,"fetch_time":1756901040701}
{"symbol":"TONUSDT","bids":[],"asks":[["3.1509","1107.0"],["3.1510","1892.6"]],"timestamp":1756901040689,"update_id":50200538,"fetch_time":1756901040741}
{"symbol":"TONUSDT","bids":[["3.1495","134.7"],["3.1494","857.9"]],"asks":[],"timestamp":1756901040710,"update_id":50200539,"fetch_time":1756901040757}
{"symbol":"TONUSDT","bids":[],"asks":[["3.1507","629.8"]],"timestamp":1756901040789,"update_id":50200540,"fetch_time":1756901040837}
{"symbol":"TONUSDT","bids":[["3.1494","836.6"]],"asks":[],"timestamp":1756901040810,"update_id":50200541,"fetch_time":1756901040861}
{"symbol":"TONUSDT","bids":[],"asks":[["3.1506","44.2"]],"timestamp":1756901040830,"update_id":50200542,"fetch_time":1756901040877}
{"symbol":"TONUSDT","bids":[["3.1494","875.8"]],"asks":[],"timestamp":1756901040850,"update_id":50200543,"fetch_time":1756901040901}
{"symbol":"TONUSDT","bids":[],"asks":[["3.1549","2788.2"]],"timestamp":1756901040950,"update_id":50200544,"fetch_time":1756901040997}
{"symbol":"TONUSDT","bids":[["3.1485","3118.2"]],"asks":[],"timestamp":1756901040989,"update_id":50200545,"fetch_time":1756901041038}
{"symbol":"TONUSDT","bids":[["3.1494","951.0"]],"asks":[],"timestamp":1756901041050,"update_id":50200546,"fetch_time":1756901041097}
{"symbol":"TONUSDT","bids":[],"asks":[["3.1504","6.1"],["3.1549","2788.2"],["3.1550","2399.4"]],"timestamp":1756901041110,"update_id":50200548,"fetch_time":1756901041161}
{"symbol":"TONUSDT","bids":[],"asks":[["3.1506","5.0"],["3.1507","590.6"],["3.1508","1693.9"],["3.1509","1067.8"],["3.1549","1520.6"],["3.1550","3667.0"]],"timestamp":1756901041130,"update_id":50200549,"fetch_time":1756901041178}
{"symbol":"TONUSDT","bids":[["3.1490","2516.2"]],"asks":[],"timestamp":1756901041189,"update_id":50200550,"fetch_time":1756901041237}
{"symbol":"TONUSDT","bids":[["3.1496","445.9"],["3.1495","173.9"]],"asks":[],"timestamp":1756901041229,"update_id":50200551,"fetch_time":1756901041277}
{"symbol":"TONUSDT","bids":[["3.1495","213.1"]],"asks":[],"timestamp":1756901041410,"update_id":50200552,"fetch_time":1756901041457}
{"symbol":"TONUSDT","bids":[],"asks":[["3.1508","1767.3"],["3.1509","1107.0"]],"timestamp":1756901041470,"update_id":50200553,"fetch_time":1756901041517}
{"symbol":"TONUSDT","bids":[["3.1498","20.4"]],"asks":[],"timestamp":1756901041829,"update_id":50200554,"fetch_time":1756901041877}
{"symbol":"TONUSDT","bids":[["3.1496","465.0"]],"asks":[],"timestamp":1756901041850,"update_id":50200555,"fetch_time":1756901041897}
{"symbol":"TONUSDT","bids":[["3.1492","2039.6"]],"asks":[],"timestamp":1756901041870,"update_id":50200556,"fetch_time":1756901041917}
{"symbol":"TONUSDT","bids":[["3.1483","1163.6"]],"asks":[],"timestamp":1756901041949,"update_id":50200557,"fetch_time":1756901041997}
{"symbol":"TONUSDT","bids":[["3.1496","484.3"]],"asks":[],"timestamp":1756901042129,"update_id":50200559,"fetch_time":1756901042177}
{"symbol":"TONUSDT","bids":[],"asks":[["3.1508","1806.5"]],"timestamp":1756901042210,"update_id":50200560,"fetch_time":1756901042261}
{"symbol":"TONUSDT","bids":[],"asks":[["3.1536","5341.2"]],"timestamp":1756901042270,"update_id":50200562,"fetch_time":1756901042317}
{"symbol":"TONUSDT","bids":[["3.1497","0"],["3.1448","11747.4"]],"asks":[],"timestamp":1756901042409,"update_id":50200563,"fetch_time":1756901042457}
{"symbol":"TONUSDT","bids":[["3.1496","471.4"],["3.1495","312.1"]],"asks":[],"timestamp":1756901042450,"update_id":50200565,"fetch_time":1756901042497}
{"symbol":"TONUSDT","bids":[],"asks":[["3.1549","2788.2"],["3.1550","2399.4"]],"timestamp":1756901042470,"update_id":50200566,"fetch_time":1756901042517}
{"symbol":"TONUSDT","bids":[["3.1489","1466.6"]],"asks":[],"timestamp":1756901042489,"update_id":50200567,"fetch_time":1756901042541}
{"symbol":"TONUSDT","bids":[["3.1492","2000.4"],["3.1490","2521.9"]],"asks":[],"timestamp":1756901042509,"update_id":50200568,"fetch_time":1756901042557}
{"symbol":"TONUSDT","bids":[["3.1495","321.5"],["3.1493","233.6"],["3.1492","2039.6"]],"asks":[],"timestamp":1756901042529,"update_id":50200569,"fetch_time":1756901042581}
{"symbol":"TONUSDT","bids":[],"asks":[["3.1504","6.1"]],"timestamp":1756901042549,"update_id":50200570,"fetch_time":1756901042601}
{"symbol":"TONUSDT","bids":[["3.1493","272.8"]],"asks":[],"timestamp":1756901042629,"update_id":50200571,"fetch_time":1756901042677}
{"symbol":"TONUSDT","bids":[],"asks":[["3.1549","1520.6"],["3.1550","3667.0"]],"timestamp":1756901042710,"update_id":50200572,"fetch_time":1756901042761}
{"symbol":"TONUSDT","bids":[["3.1495","480.2"]],"asks":[],"timestamp":1756901042750,"update_id":50200574,"fetch_time":1756901042797}
{"symbol":"TONUSDT","bids":[["3.1495","176.1"]],"asks":[],"timestamp":1756901042829,"update_id":50200575,"fetch_time":1756901042877}
{"symbol":"TONUSDT","bids":[["3.1496","775.5"],["3.1494","951.0"]],"asks":[],"timestamp":1756901042850,"update_id":50200576,"fetch_time":1756901042897}
{"symbol":"TONUSDT","bids":[["3.1497","158.0"],["3.1448","0"]],"asks":[["3.1506","83.4"]],"timestamp":1756901042869,"update_id":50200577,"fetch_time":1756901042917}
{"symbol":"TONUSDT","bids":[],"asks":[["3.1504","6.1"]],"timestamp":1756901042889,"update_id":50200578,"fetch_time":1756901042941}
{"symbol":"TONUSDT","bids":[],"asks":[["3.1536","5771.6"]],"timestamp":1756901043069,"update_id":50200579,"fetch_time":1756901043117}
{"symbol":"TONUSDT","bids":[["3.1493","233.6"],["3.1492","2000.4"],["3.1491","543.3"],["3.1490","2482.7"],["3.1489","1427.4"]],"asks":[],"timestamp":1756901043089,"update_id":50200580,"fetch_time":1756901043137}
{"symbol":"TONUSDT","bids":[],"asks":[["3.1504","164.8"]],"timestamp":1756901043110,"update_id":50200581,"fetch_time":1756901043157}
{"symbol":"TONUSDT","bids":[["3.1491","582.5"],["3.1490","2521.9"]],"asks":[],"timestamp":1756901043250,"update_id":50200582,"fetch_time":1756901043297}
{"symbol":"TONUSDT","bids":[],"asks":[["3.1504","6.1"]],"timestamp":1756901043610,"update_id":50200584,"fetch_time":1756901043657}
{"symbol":"TONUSDT","bids":[["3.1493","272.8"]],"asks":[],"timestamp":1756901043629,"update_id":50200585,"fetch_time":1756901043681}
{"symbol":"TONUSDT","bids":[],"asks":[["3.1549","1520.6"],["3.1550","3667.0"]],"timestamp":1756901044350,"update_id":50200586,"fetch_time":1756901044397}
{"symbol":"TONUSDT","bids":[["3.1470","2927.1"]],"asks":[],"timestamp":1756901044449,"update_id":50200587,"fetch_time":1756901044497}
{"symbol":"TONUSDT","bids":[["3.1496","635.5"],["3.1492","2198.3"]],"asks":[],"timestamp":1756901044469,"update_id":50200588,"fetch_time":1756901044517}
{"symbol":"TONUSDT","bids":[["3.1497","0"],["3.1496","331.4"],["3.1494","1104.5"],["3.1493","194.4"],["3.1492","2119.9"],["3.1491","504.1"],["3.1490","2443.5"],["3.1489","1388.2"],["3.1448","11747.4"]],"asks":[["3.1504","45.3"],["3.1505","2610.3"]],"timestamp":1756901044489,"update_id":50200589,"fetch_time":1756901044541}
{"symbol":"TONUSDT","bids":[],"asks":[["3.1504","204.0"],["3.1549","2788.2"],["3.1550","2399.4"]],"timestamp":1756901044510,"update_id":50200590,"fetch_time":1756901044557}
{"symbol":"TONUSDT","bids":[],"asks":[["3.1499","140.0"],["3.1550","0"]],"timestamp":1756901044569,"update_id":50200591,"fetch_time":1756901044617}
{"symbol":"TONUSDT","bids":[],"asks":[["3.1504","1213.6"],["3.1505","2326.8"]],"timestamp":1756901044629,"update_id":50200594,"fetch_time":1756901044677}
{"symbol":"TONUSDT","bids":[],"asks":[["3.1503","294.3"]],"timestamp":1756901044669,"update_id":50200595,"fetch_time":1756901044717}
{"symbol":"TONUSDT","bids":[],"asks":[["3.1502","157.1"],["3.1503","255.1"],["3.1505","2043.5"]],"timestamp":1756901044690,"update_id":50200596,"fetch_time":1756901044737}
{"symbol":"TONUSDT","bids":[],"asks":[["3.1502","3.2"],["3.1505","1665.8"],["3.1548","5296.6"],["3.1549","1520.6"]],"timestamp":1756901044709,"update_id":50200597,"fetch_time":1756901044761}
{"symbol":"TONUSDT","bids":[],"asks":[["3.1505","1602.4"]],"timestamp":1756901044729,"update_id":50200598,"fetch_time":1756901044777}
{"symbol":"TONUSDT","bids":[],"asks":[["3.1499","0"],["3.1550","2399.4"]],"timestamp":1756901044790,"update_id":50200599,"fetch_time":1756901044837}
{"symbol":"TONUSDT","bids":[],"asks":[["3.1503","96.4"],["3.1504","221.6"],["3.1505","2023.6"]],"timestamp":1756901044829,"update_id":50200601,"fetch_time":1756901044877}
{"symbol":"TONUSDT","bids":[],"asks":[["3.1505","2591.5"]],"timestamp":1756901044849,"update_id":50200602,"fetch_time":1756901044897}
{"symbol":"TONUSDT","bids":[],"asks":[["3.1503","255.1"]],"timestamp":1756901044870,"update_id":50200603,"fetch_time":1756901044917}
{"symbol":"TONUSDT","bids":[["3.1492","2121.5"]],"asks":[],"timestamp":1756901045029,"update_id":50200604,"fetch_time":1756901045081}
{"symbol":"TONUSDT","bids":[["3.1491","543.3"],["3.1490","2482.7"]],"asks":[],"timestamp":1756901045050,"update_id":50200605,"fetch_time":1756901045097}
{"symbol":"TONUSDT","bids":[["3.1495","581.7"],["3.1494","909.1"],["3.1492","2160.7"]],"asks":[],"timestamp":1756901045130,"update_id":50200606,"fetch_time":1756901045177}
{"symbol":"TONUSDT","bids":[["3.1496","347.6"],["3.1495","368.8"]],"asks":[],"timestamp":1756901045150,"update_id":50200607,"fetch_time":1756901045197}
{"symbol":"TONUSDT","bids":[],"asks":[["3.1548","4029.0"],["3.1549","2788.2"]],"timestamp":1756901045430,"update_id":50200609,"fetch_time":1756901045477}
{"symbol":"TONUSDT","bids":[],"asks":[["3.1505","2630.7"]],"timestamp":1756901045690,"update_id":50200610,"fetch_time":1756901045737}
{"symbol":"TONUSDT","bids":[["3.1495","201.6"],["3.1494","987.5"]],"asks":[],"timestamp":1756901045950,"update_id":50200614,"fetch_time":1756901046001}
{"symbol":"TONUSDT","bids":[],"asks":[["3.1499","39.3"],["3.1500","0"]],"timestamp":1756901046190,"update_id":50200616,"fetch_time":1756901046237}
{"symbol":"TONUSDT","bids":[],"asks":[["3.1503","255.1"],["3.1504","1128.8"]],"timestamp":1756901046229,"update_id":50200618,"fetch_time":1756901046277}
{"symbol":"TONUSDT","bids":[],"asks":[["3.1507","669.0"]],"timestamp":1756901046250,"update_id":50200619,"fetch_time":1756901046297}
{"symbol":"TONUSDT","bids":[],"asks":[["3.1504","970.1"],["3.1505","1645.3"]],"timestamp":1756901046329,"update_id":50200621,"fetch_time":1756901046377}
{"symbol":"TONUSDT","bids":[],"asks":[["3.1503","96.4"]],"timestamp":1756901046349,"update_id":50200622,"fetch_time":1756901046397}
{"symbol":"TONUSDT","bids":[],"asks":[["3.1504","1033.5"]],"timestamp":1756901046389,"update_id":50200623,"fetch_time":1756901046437}
{"symbol":"TONUSDT","bids":[],"asks":[["3.1505","1581.9"]],"timestamp":1756901046450,"update_id":50200624,"fetch_time":1756901046497}
{"symbol":"TONUSDT","bids":[],"asks":[["3.1512","3744.7"]],"timestamp":1756901046549,"update_id":50200625,"fetch_time":1756901046597}
{"symbol":"TONUSDT","bids":[],"asks":[["3.1506","83.4"],["3.1512","3516.4"]],"timestamp":1756901046690,"update_id":50200626,"fetch_time":1756901046737}
{"symbol":"TONUSDT","bids":[],"asks":[["3.1509","1623.7"],["3.1522","1039.3"]],"timestamp":1756901046770,"update_id":50200627,"fetch_time":1756901046817}
{"symbol":"TONUSDT","bids":[["3.1496","358.1"],["3.1494","806.1"],["3.1493","474.3"]],"asks":[],"timestamp":1756901046910,"update_id":50200628,"fetch_time":1756901046957}
{"symbol":"TONUSDT","bids":[["3.1494","981.7"]],"asks":[],"timestamp":1756901046930,"update_id":50200629,"fetch_time":1756901046977}
{"symbol":"TONUSDT","bids":[["3.1494","1020.9"],["3.1493","513.5"]],"asks":[],"timestamp":1756901046949,"update_id":50200630,"fetch_time":1756901046997}
{"symbol":"TONUSDT","bids":[["3.1498","0"],["3.1496","541.6"],["3.1495","176.1"],["3.1494","981.7"],["3.1493","474.3"],["3.1492","1563.9"],["3.1488","897.9"],["3.1447","440.4"]],"asks":[["3.1499","370.9"],["3.1503","284.6"],["3.1505","1883.0"],["3.1507","1083.0"],["3.1509","2150.6"],["3.1511","1261.7"],["3.1513","3009.2"],["3.1514","4007.9"],["3.1517","2886.1"],["3.1520","1790.7"],["3.1523","3079.8"],["3.1526","1112.2"],["3.1529","997.6"]],"timestamp":1756901046989,"update_id":50200631,"fetch_time":1756901047042}
{"symbol":"TONUSDT","bids":[["3.1460","3924.3"],["3.1456","1993.6"]],"asks":[["3.1497","28.8"],["3.1498","331.6"],["3.1501","3.2"],["3.1502","5.0"],["3.1503","506.7"],["3.1522","1037.5"],["3.1533","482.5"],["3.1534","3583.9"],["3.1548","0"],["3.1549","0"],["3.1550","0"]],"timestamp":1756901047050,"update_id":50200634,"fetch_time":1756901047101}
{"symbol":"TONUSDT","bids":[],"asks":[["3.1500","3.2"],["3.1501","157.1"],["3.1502","700.3"],["3.1503","1825.5"],["3.1504","1345.5"],["3.1526","2098.6"],["3.1547","0"]],"timestamp":1756901047110,"update_id":50200637,"fetch_time":1756901047161}
{"symbol":"TONUSDT","bids":[],"asks":[["3.1502","1173.7"],["3.1504","683.2"],["3.1506","832.8"],["3.1507","741.3"]],"timestamp":1756901047129,"update_id":50200638,"fetch_time":1756901047177}
{"symbol":"TONUSDT","bids":[],"asks":[["3.1503","1762.1"],["3.1504","619.8"]],"timestamp":1756901047150,"update_id":50200639,"fetch_time":1756901047197}
{"symbol":"TONUSDT","bids":[],"asks":[["3.1497","360.4"],["3.1498","0"],["3.1503","1477.9"],["3.1504","335.7"],["3.1547","1111.3"]],"timestamp":1756901047169,"update_id":50200640,"fetch_time":1756901047217}
{"symbol":"TONUSDT","bids":[],"asks":[["3.1504","374.6"]],"timestamp":1756901047190,"update_id":50200641,"fetch_time":1756901047237}
{"symbol":"TONUSDT","bids":[["3.1488","936.8"],["3.1487","820.8"]],"asks":[],"timestamp":1756901047209,"update_id":50200642,"fetch_time":1756901047261}
{"symbol":"TONUSDT","bids":[],"asks":[["3.1503","1288.7"],["3.1524","1001.8"]],"timestamp":1756901047230,"update_id":50200643,"fetch_time":1756901047277}
{"symbol":"TONUSDT","bids":[["3.1496","69.3"]],"asks":[],"timestamp":1756901047269,"update_id":50200644,"fetch_time":1756901047321}
{"symbol":"TONUSDT","bids":[["3.1495","387.8"],["3.1494","1111.1"],["3.1491","732.2"],["3.1490","2521.6"]],"asks":[],"timestamp":1756901047330,"update_id":50200646,"fetch_time":1756901047382}
{"symbol":"TONUSDT","bids":[],"asks":[["3.1497","361.8"]],"timestamp":1756901047350,"update_id":50200647,"fetch_time":1756901047397}
{"symbol":"TONUSDT","bids":[["3.1487","781.9"]],"asks":[],"timestamp":1756901047450,"update_id":50200650,"fetch_time":1756901047497}
{"symbol":"TONUSDT","bids":[["3.1496","67.4"]],"asks":[],"timestamp":1756901047509,"update_id":50200651,"fetch_time":1756901047557}
{"symbol":"TONUSDT","bids":[["3.1495","14.2"],["3.1489","1426.0"]],"asks":[],"timestamp":1756901047550,"update_id":50200653,"fetch_time":1756901047597}
{"symbol":"TONUSDT","bids":[["3.1491","731.1"],["3.1490","2481.3"],["3.1487","819.7"]],"asks":[],"timestamp":1756901047589,"update_id":50200654,"fetch_time":1756901047637}
{"symbol":"TONUSDT","bids":[["3.1492","1438.7"],["3.1490","2519.1"]],"asks":[],"timestamp":1756901047689,"update_id":50200657,"fetch_time":1756901047741}
{"symbol":"TONUSDT","bids":[["3.1493","284.1"],["3.1491","768.9"]],"asks":[["3.1497","517.8"],["3.1499","0"],["3.1548","4915.6"]],"timestamp":1756901047749,"update_id":50200658,"fetch_time":1756901047801}
{"symbol":"TONUSDT","bids":[["3.1494","699.1"]],"asks":[],"timestamp":1756901047849,"update_id":50200659,"fetch_time":1756901047902}
{"symbol":"TONUSDT","bids":[],"asks":[["3.1507","572.1"],["3.1510","2208.8"]],"timestamp":1756901047950,"update_id":50200662,"fetch_time":1756901047997}
{"symbol":"TONUSDT","bids":[],"asks":[["3.1497","186.2"]],"timestamp":1756901047969,"update_id":50200663,"fetch_time":1756901048021}
{"symbol":"TONUSDT","bids":[],"asks":[["3.1532","1890.2"]],"timestamp":1756901048029,"update_id":50200666,"fetch_time":1756901048081}
{"symbol":"TONUSDT","bids":[["3.1491","579.7"],["3.1490","2338.9"],["3.1460","2118.5"],["3.1454","3026.1"]],"asks":[],"timestamp":1756901048050,"update_id":50200667,"fetch_time":1756901048097}
{"symbol":"TONUSDT","bids":[["3.1462","1251.9"]],"asks":[],"timestamp":1756901048070,"update_id":50200668,"fetch_time":1756901048122}
{"symbol":"TONUSDT","bids":[],"asks":[["3.1497","184.8"],["3.1504","399.0"]],"timestamp":1756901048109,"update_id":50200670,"fetch_time":1756901048157}
{"symbol":"TONUSDT","bids":[],"asks":[["3.1505","1701.3"],["3.1506","754.4"],["3.1507","532.9"],["3.1508","2036.6"],["3.1509","1522.1"]],"timestamp":1756901048409,"update_id":50200673,"fetch_time":1756901048461}
{"symbol":"TONUSDT","bids":[],"asks":[["3.1506","792.2"]],"timestamp":1756901048530,"update_id":50200674,"fetch_time":1756901048577}
{"symbol":"TONUSDT","bids":[],"asks":[["3.1503","1005.2"]],"timestamp":1756901048570,"update_id":50200675,"fetch_time":1756901048621}
{"symbol":"TONUSDT","bids":[],"asks":[["3.1504","335.6"]],"timestamp":1756901048669,"update_id":50200676,"fetch_time":1756901048721}
{"symbol":"TONUSDT","bids":[["3.1480","4099.4"],["3.1458","262.6"]],"asks":[],"timestamp":1756901049050,"update_id":50200679,"fetch_time":1756901049101}
{"symbol":"TONUSDT","bids":[],"asks":[["3.1506","830.0"]],"timestamp":1756901049270,"update_id":50200682,"fetch_time":1756901049317}
{"symbol":"TONUSDT","bids":[["3.1492","1400.9"],["3.1491","693.3"]],"asks":[],"timestamp":1756901049529,"update_id":50200683,"fetch_time":1756901049577}
{"symbol":"TONUSDT","bids":[],"asks":[["3.1501","198.7"],["3.1502","1070.8"]],"timestamp":1756901049729,"update_id":50200688,"fetch_time":1756901049777}
{"symbol":"TONUSDT","bids":[["3.1488","827.1"]],"asks":[],"timestamp":1756901049750,"update_id":50200689,"fetch_time":1756901049797}
{"symbol":"TONUSDT","bids":[],"asks":[["3.1503","1017.4"]],"timestamp":1756901049790,"update_id":50200690,"fetch_time":1756901049837}
{"symbol":"TONUSDT","bids":[["3.1495","0"],["3.1494","475.1"],["3.1491","587.5"],["3.1488","1304.2"],["3.1446","2021.6"]],"asks":[],"timestamp":1756901050210,"update_id":50200692,"fetch_time":1756901050258}
{"symbol":"TONUSDT","bids":[],"asks":[["3.1500","161.9"]],"timestamp":1756901050230,"update_id":50200693,"fetch_time":1756901050277}
{"symbol":"TONUSDT","bids":[["3.1478","1650.4"]],"asks":[],"timestamp":1756901050389,"update_id":50200694,"fetch_time":1756901050437}
{"symbol":"TONUSDT","bids":[],"asks":[["3.1500","175.4"]],"timestamp":1756901050409,"update_id":50200695,"fetch_time":1756901050458}
{"symbol":"TONUSDT","bids":[["3.1494","749.6"]],"asks":[],"timestamp":1756901050570,"update_id":50200696,"fetch_time":1756901050617}
{"symbol":"TONUSDT","bids":[["3.1478","1831.2"]],"asks":[],"timestamp":1756901050590,"update_id":50200697,"fetch_time":1756901050638}
{"symbol":"TONUSDT","bids":[["3.1488","1266.4"],["3.1486","1501.8"],["3.1484","1400.9"],["3.1482","2953.8"],["3.1480","3467.1"],["3.1478","1110.7"],["3.1476","1233.8"]],"asks":[["3.1499","9.7"],["3.1501","233.5"],["3.1502","1110.8"],["3.1548","0"]],"timestamp":1756901050630,"update_id":50200698,"fetch_time":1756901050682}
{"symbol":"TONUSDT","bids":[["3.1466","884.0"],["3.1465","655.3"]],"asks":[],"timestamp":1756901050670,"update_id":50200700,"fetch_time":1756901050717}
{"symbol":"TONUSDT","bids":[],"asks":[["3.1546","2574.8"],["3.1547","1111.3"]],"timestamp":1756901050710,"update_id":50200702,"fetch_time":1756901050757}
{"symbol":"TONUSDT","bids":[["3.1493","246.3"],["3.1492","1100.6"]],"asks":[],"timestamp":1756901050729,"update_id":50200703,"fetch_time":1756901050777}
{"symbol":"TONUSDT","bids":[["3.1494","301.9"]],"asks":[],"timestamp":1756901050749,"update_id":50200704,"fetch_time":1756901050797}
{"symbol":"TONUSDT","bids":[["3.1487","780.8"]],"asks":[],"timestamp":1756901050770,"update_id":50200705,"fetch_time":1756901050817}
{"symbol":"TONUSDT","bids":[],"asks":[["3.1502","1864.6"]],"timestamp":1756901050790,"update_id":50200706,"fetch_time":1756901050841}
{"symbol":"TONUSDT","bids":[],"asks":[["3.1547","2379.0"]],"timestamp":1756901050809,"update_id":50200707,"fetch_time":1756901050857}
{"symbol":"TONUSDT","bids":[["3.1493","520.8"]],"asks":[],"timestamp":1756901050909,"update_id":50200708,"fetch_time":1756901050957}
{"symbol":"TONUSDT","bids":[],"asks":[["3.1500","161.9"]],"timestamp":1756901051130,"update_id":50200710,"fetch_time":1756901051177}
{"symbol":"TONUSDT","bids":[["3.1492","959.8"],["3.1490","1825.0"],["3.1488","1455.2"],["3.1487","1123.5"]],"asks":[],"timestamp":1756901051190,"update_id":50200711,"fetch_time":1756901051237}
{"symbol":"TONUSDT","bids":[],"asks":[["3.1500","188.6"]],"timestamp":1756901051329,"update_id":50200713,"fetch_time":1756901051381}
{"symbol":"TONUSDT","bids":[["3.1496","61.2"],["3.1488","1417.4"],["3.1487","1350.8"]],"asks":[],"timestamp":1756901051510,"update_id":50200714,"fetch_time":1756901051558}
{"symbol":"TONUSDT","bids":[["3.1494","312.8"],["3.1493","280.1"],["3.1489","1516.0"]],"asks":[],"timestamp":1756901051610,"update_id":50200716,"fetch_time":1756901051658}
{"symbol":"TONUSDT","bids":[],"asks":[["3.1504","995.2"]],"timestamp":1756901051789,"update_id":50200718,"fetch_time":1756901051837}
{"symbol":"TONUSDT","bids":[],"asks":[["3.1526","1112.2"]],"timestamp":1756901051869,"update_id":50200719,"fetch_time":1756901051917}
{"symbol":"TONUSDT","bids":[],"asks":[["3.1524","754.3"]],"timestamp":1756901051889,"update_id":50200720,"fetch_time":1756901051994}
{"symbol":"TONUSDT","bids":[],"asks":[["3.1518","2001.0"]],"timestamp":1756901051970,"update_id":50200721,"fetch_time":1756901052018}
