{"symbol":"TONUSDT","bids":[["3.1488","19.8"],["3.1440","0"]],"asks":[],"timestamp":1756900801529,"update_id":50195533,"fetch_time":1756900801629}
{"symbol":"TONUSDT","bids":[["3.1468","3872.4"]],"asks":[],"timestamp":1756900801569,"update_id":50195535,"fetch_time":1756900801629}
{"symbol":"TONUSDT","bids":[["3.1467","1805.0"]],"asks":[],"timestamp":1756900801729,"update_id":50195537,"fetch_time":1756900801769}
{"symbol":"TONUSDT","bids":[["3.1489","8.6"],["3.1475","1715.8"]],"asks":[],"timestamp":1756900801769,"update_id":50195538,"fetch_time":1756900801809}
{"symbol":"TONUSDT","bids":[],"asks":[["3.1497","206.2"],["3.1498","1383.1"],["3.1499","329.4"],["3.1500","2116.2"],["3.1501","577.5"]],"timestamp":1756900801789,"update_id":50195539,"fetch_time":1756900801829}
{"symbol":"TONUSDT","bids":[],"asks":[["3.1539","2368.7"],["3.1540","7536.0"]],"timestamp":1756900801829,"update_id":50195540,"fetch_time":1756900801869}
{"symbol":"TONUSDT","bids":[["3.1465","3418.0"]],"asks":[],"timestamp":1756900801849,"update_id":50195541,"fetch_time":1756900801889}
{"symbol":"TONUSDT","bids":[["3.1462","963.2"]],"asks":[],"timestamp":1756900801870,"update_id":50195542,"fetch_time":1756900801918}
{"symbol":"TONUSDT","bids":[],"asks":[["3.1500","2159.4"]],"timestamp":1756900801909,"update_id":50195544,"fetch_time":1756900801953}
{"symbol":"TONUSDT","bids":[["3.1467","1789.2"]],"asks":[],"timestamp":1756900802010,"update_id":50195545,"fetch_time":1756900802053}
{"symbol":"TONUSDT","bids":[["3.1475","1745.8"],["3.1474","1807.6"],["3.1470","2733.5"],["3.1469","714.2"],["3.1465","3227.0"]],"asks":[],"timestamp":1756900802029,"update_id":50195546,"fetch_time":1756900802069}
{"symbol":"TONUSDT","bids":[],"asks":[["3.1495","59.7"]],"timestamp":1756900802210,"update_id":50195549,"fetch_time":1756900802253}
{"symbol":"TONUSDT","bids":[],"asks":[["3.1503","2694.6"],["3.1504","3354.0"]],"timestamp":1756900802250,"update_id":50195551,"fetch_time":1756900802297}
{"symbol":"TONUSDT","bids":[["3.1460","1679.2"],["3.1444","1193.4"]],"asks":[],"timestamp":1756900802310,"update_id":50195552,"fetch_time":1756900802353}
{"symbol":"TONUSDT","bids":[["3.1472","2732.2"],["3.1471","2833.5"],["3.1470","4603.5"],["3.1466","2865.4"],["3.1465","1357.0"]],"asks":[],"timestamp":1756900802329,"update_id":50195553,"fetch_time":1756900802373}
{"symbol":"TONUSDT","bids":[["3.1458","1022.1"]],"asks":[],"timestamp":1756900802389,"update_id":50195554,"fetch_time":1756900802429}
{"symbol":"TONUSDT","bids":[["3.1485","1167.0"]],"asks":[],"timestamp":1756900802549,"update_id":50195555,"fetch_time":1756900802593}
{"symbol":"TONUSDT","bids":[],"asks":[["3.1513","2246.7"]],"timestamp":1756900802609,"update_id":50195558,"fetch_time":1756900802649}
{"symbol":"TONUSDT","bids":[["3.1491","118.3"],["3.1490","922.0"],["3.1489","15.3"],["3.1486","457.3"],["3.1441","0"]],"asks":[["3.1491","0"],["3.1493","5.5"],["3.1496","1616.9"],["3.1503","2495.3"],["3.1504","3354.0"],["3.1542","1861.8"]],"timestamp":1756900802629,"update_id":50195559,"fetch_time":1756900802677}
{"symbol":"TONUSDT","bids":[["3.1492","59.2"],["3.1490","926.6"],["3.1485","1188.0"],["3.1483","641.9"],["3.1482","1255.3"],["3.1472","2795.7"],["3.1442","0"]],"asks":[["3.1493","2.3"],["3.1494","559.7"],["3.1496","27.7"],["3.1498","495.3"],["3.1499","34.8"],["3.1500","2621.4"],["3.1501","601.0"],["3.1503","2695.9"],["3.1505","1205.5"],["3.1507","775.6"],["3.1509","3450.8"],["3.1526","1475.6"],["3.1527","1770.2"],["3.1539","2368.7"],["3.1541","3416.3"]],"timestamp":1756900802650,"update_id":50195560,"fetch_time":1756900802697}
{"symbol":"TONUSDT","bids":[],"asks":[["3.1504","3791.5"],["3.1513","1294.3"],["3.1515","1801.8"],["3.1524","4686.9"]],"timestamp":1756900802729,"update_id":50195564,"fetch_time":1756900802769}
{"symbol":"TONUSDT","bids":[],"asks":[["3.1512","1336.3"],["3.1513","808.8"],["3.1514","1488.1"],["3.1521","734.0"],["3.1523","822.5"],["3.1526","1811.7"],["3.1527","1183.2"]],"timestamp":1756900802749,"update_id":50195565,"fetch_time":1756900802797}
{"symbol":"TONUSDT","bids":[],"asks":[["3.1510","586.2"]],"timestamp":1756900802770,"update_id":50195566,"fetch_time":1756900802813}
{"symbol":"TONUSDT","bids":[],"asks":[["3.1510","868.5"]],"timestamp":1756900802789,"update_id":50195567,"fetch_time":1756900802829}
{"symbol":"TONUSDT","bids":[],"asks":[["3.1514","1210.3"],["3.1521","1079.6"],["3.1528","3337.4"]],"timestamp":1756900802829,"update_id":50195568,"fetch_time":1756900802874}
{"symbol":"TONUSDT","bids":[],"asks":[["3.1520","1115.8"]],"timestamp":1756900802869,"update_id":50195570,"fetch_time":1756900802909}
{"symbol":"TONUSDT","bids":[],"asks":[["3.1532","1911.2"]],"timestamp":1756900802929,"update_id":50195571,"fetch_time":1756900802969}
{"symbol":"TONUSDT","bids":[["3.1491","396.3"]],"asks":[],"timestamp":1756900803029,"update_id":50195573,"fetch_time":1756900803077}
{"symbol":"TONUSDT","bids":[],"asks":[["3.1521","1397.8"]],"timestamp":1756900803070,"update_id":50195574,"fetch_time":1756900803109}
{"symbol":"TONUSDT","bids":[["3.1490","924.3"],["3.1489","11.8"]],"asks":[],"timestamp":1756900803149,"update_id":50195576,"fetch_time":1756900803193}
{"symbol":"TONUSDT","bids":[],"asks":[["3.1525","439.6"],["3.1527","827.4"],["3.1530","3197.4"]],"timestamp":1756900803250,"update_id":50195577,"fetch_time":1756900803290}
{"symbol":"TONUSDT","bids":[],"asks":[["3.1524","4545.8"]],"timestamp":1756900803270,"update_id":50195578,"fetch_time":1756900803309}
{"symbol":"TONUSDT","bids":[["3.1489","55.1"]],"asks":[],"timestamp":1756900803290,"update_id":50195579,"fetch_time":1756900803333}
{"symbol":"TONUSDT","bids":[["3.1490","944.4"]],"asks":[],"timestamp":1756900803309,"update_id":50195580,"fetch_time":1756900803349}
{"symbol":"TONUSDT","bids":[],"asks":[["3.1499","3.2"]],"timestamp":1756900803370,"update_id":50195581,"fetch_time":1756900803413}
{"symbol":"TONUSDT","bids":[["3.1474","3647.6"],["3.1473","3050.4"],["3.1471","1279.2"],["3.1470","2733.5"]],"asks":[],"timestamp":1756900803389,"update_id":50195582,"fetch_time":1756900803433}
{"symbol":"TONUSDT","bids":[["3.1476","3661.2"],["3.1475","1745.8"],["3.1474","3677.6"],["3.1472","1580.4"],["3.1471","1249.2"],["3.1465","1327.0"],["3.1456","1650.7"]],"asks":[],"timestamp":1756900803410,"update_id":50195583,"fetch_time":1756900803453}
{"symbol":"TONUSDT","bids":[["3.1474","4226.2"]],"asks":[],"timestamp":1756900803429,"update_id":50195584,"fetch_time":1756900803477}
{"symbol":"TONUSDT","bids":[["3.1455","1197.2"]],"asks":[],"timestamp":1756900803489,"update_id":50195586,"fetch_time":1756900803538}
{"symbol":"TONUSDT","bids":[["3.1477","908.9"]],"asks":[],"timestamp":1756900803509,"update_id":50195587,"fetch_time":1756900803553}
{"symbol":"TONUSDT","bids":[["3.1492","61.5"],["3.1491","409.6"],["3.1467","2640.3"]],"asks":[],"timestamp":1756900803529,"update_id":50195588,"fetch_time":1756900803573}
{"symbol":"TONUSDT","bids":[],"asks":[["3.1509","3189.9"],["3.1511","1043.4"]],"timestamp":1756900803610,"update_id":50195589,"fetch_time":1756900803653}
{"symbol":"TONUSDT","bids":[["3.1493","31.9"],["3.1443","0"]],"asks":[["3.1493","0"],["3.1543","1940.1"]],"timestamp":1756900803629,"update_id":50195590,"fetch_time":1756900803673}
{"symbol":"TONUSDT","bids":[["3.1494","20.0"],["3.1493","34.2"],["3.1492","2.3"],["3.1490","946.8"],["3.1489","694.2"],["3.1488","1380.1"],["3.1486","1176.7"],["3.1485","886.8"],["3.1484","1087.6"],["3.1483","589.8"],["3.1482","1887.6"],["3.1480","1712.0"],["3.1478","2398.0"],["3.1476","3293.4"],["3.1474","3770.2"],["3.1472","1036.2"],["3.1470","2101.1"],["3.1468","3151.8"],["3.1467","2695.5"],["3.1466","2056.6"],["3.1457","1201.0"],["3.1444","0"]],"asks":[["3.1494","0"],["3.1495","57.3"],["3.1500","2962.2"],["3.1502","2571.4"],["3.1503","595.3"],["3.1518","2804.0"],["3.1528","3335.4"],["3.1530","3199.4"],["3.1544","3400.6"]],"timestamp":1756900803649,"update_id":50195591,"fetch_time":1756900803690}
{"symbol":"TONUSDT","bids":[["3.1494","0"],["3.1493","31.9"],["3.1466","496.7"],["3.1444","1193.4"]],"asks":[["3.1504","3834.7"],["3.1515","849.4"],["3.1518","2714.2"],["3.1533","1600.5"]],"timestamp":1756900803789,"update_id":50195598,"fetch_time":1756900803834}
{"symbol":"TONUSDT","bids":[["3.1494","13.3"],["3.1490","1783.8"],["3.1471","1541.2"],["3.1469","1418.9"],["3.1444","0"]],"asks":[],"timestamp":1756900803869,"update_id":50195602,"fetch_time":1756900803914}
{"symbol":"TONUSDT","bids":[],"asks":[["3.1504","3804.7"],["3.1506","995.2"]],"timestamp":1756900803889,"update_id":50195603,"fetch_time":1756900803937}
{"symbol":"TONUSDT","bids":[],"asks":[["3.1500","2105.9"]],"timestamp":1756900803909,"update_id":50195604,"fetch_time":1756900803949}
{"symbol":"TONUSDT","bids":[["3.1489","1453.4"]],"asks":[],"timestamp":1756900803929,"update_id":50195605,"fetch_time":1756900803969}
{"symbol":"TONUSDT","bids":[["3.1493","38.6"]],"asks":[],"timestamp":1756900803950,"update_id":50195606,"fetch_time":1756900803994}
{"symbol":"TONUSDT","bids":[["3.1488","1564.6"]],"asks":[],"timestamp":1756900804029,"update_id":50195608,"fetch_time":1756900804078}
{"symbol":"TONUSDT","bids":[["3.1493","31.9"]],"asks":[],"timestamp":1756900804170,"update_id":50195611,"fetch_time":1756900804214}
{"symbol":"TONUSDT","bids":[],"asks":[["3.1502","1839.1"],["3.1504","1047.8"]],"timestamp":1756900804289,"update_id":50195613,"fetch_time":1756900804329}
{"symbol":"TONUSDT","bids":[],"asks":[["3.1500","1694.6"],["3.1502","1573.1"],["3.1504","1341.6"]],"timestamp":1756900804329,"update_id":50195615,"fetch_time":1756900804373}
{"symbol":"TONUSDT","bids":[],"asks":[["3.1501","746.0"]],"timestamp":1756900804369,"update_id":50195617,"fetch_time":1756900804409}
{"symbol":"TONUSDT","bids":[],"asks":[["3.1510","1409.2"]],"timestamp":1756900804509,"update_id":50195620,"fetch_time":1756900804554}
{"symbol":"TONUSDT","bids":[["3.1490","2116.4"]],"asks":[],"timestamp":1756900804529,"update_id":50195621,"fetch_time":1756900804569}
{"symbol":"TONUSDT","bids":[["3.1493","0"],["3.1490","1781.5"],["3.1489","1446.8"],["3.1488","1836.5"],["3.1477","912.2"],["3.1469","1415.6"],["3.1444","1193.4"]],"asks":[],"timestamp":1756900804709,"update_id":50195623,"fetch_time":1756900804757}
{"symbol":"TONUSDT","bids":[["3.1490","1824.7"]],"asks":[],"timestamp":1756900804830,"update_id":50195626,"fetch_time":1756900804873}
{"symbol":"TONUSDT","bids":[["3.1490","2116.4"]],"asks":[],"timestamp":1756900804849,"update_id":50195627,"fetch_time":1756900804894}
{"symbol":"TONUSDT","bids":[["3.1491","433.9"]],"asks":[],"timestamp":1756900804989,"update_id":50195628,"fetch_time":1756900805029}
{"symbol":"TONUSDT","bids":[["3.1444","1207.3"]],"asks":[],"timestamp":1756900805029,"update_id":50195630,"fetch_time":1756900805070}
{"symbol":"TONUSDT","bids":[["3.1488","1151.0"],["3.1480","991.5"]],"asks":[],"timestamp":1756900805089,"update_id":50195633,"fetch_time":1756900805137}
{"symbol":"TONUSDT","bids":[["3.1484","1088.1"],["3.1482","1711.2"],["3.1480","1535.6"],["3.1478","2221.6"],["3.1476","4013.9"],["3.1474","4578.9"],["3.1455","1197.2"],["3.1453","891.7"],["3.1451","1504.6"],["3.1449","2089.3"],["3.1447","619.7"],["3.1445","1133.3"]],"asks":[],"timestamp":1756900805110,"update_id":50195634,"fetch_time":1756900805154}
{"symbol":"TONUSDT","bids":[["3.1493","6.6"],["3.1492","734.9"],["3.1491","469.0"],["3.1490","1838.4"],["3.1444","0"]],"asks":[["3.1501","746.0"],["3.1502","1836.7"],["3.1506","786.8"]],"timestamp":1756900805289,"update_id":50195636,"fetch_time":1756900805333}
{"symbol":"TONUSDT","bids":[["3.1488","1171.5"],["3.1487","111.8"],["3.1483","934.4"],["3.1481","634.0"],["3.1473","3365.4"],["3.1471","1289.0"]],"asks":[],"timestamp":1756900805409,"update_id":50195638,"fetch_time":1756900805454}
{"symbol":"TONUSDT","bids":[["3.1490","1806.8"],["3.1489","982.1"]],"asks":[],"timestamp":1756900805470,"update_id":50195639,"fetch_time":1756900805514}
{"symbol":"TONUSDT","bids":[["3.1476","4043.9"],["3.1474","4548.9"]],"asks":[],"timestamp":1756900805510,"update_id":50195640,"fetch_time":1756900805558}
{"symbol":"TONUSDT","bids":[["3.1495","726.9"],["3.1490","1024.8"],["3.1445","0"]],"asks":[["3.1495","0"],["3.1545","1476.0"]],"timestamp":1756900805590,"update_id":50195642,"fetch_time":1756900805634}
{"symbol":"TONUSDT","bids":[["3.1493","0"],["3.1492","877.1"],["3.1490","1449.2"],["3.1488","1686.9"],["3.1487","80.3"],["3.1486","1333.0"],["3.1480","1021.5"],["3.1478","1559.3"],["3.1476","4393.4"],["3.1475","4657.9"],["3.1474","1870.2"],["3.1473","1495.4"],["3.1467","1653.4"],["3.1445","1133.3"]],"asks":[["3.1496","0"],["3.1497","0"],["3.1500","655.6"],["3.1501","672.3"],["3.1504","1703.0"],["3.1509","4908.1"],["3.1510","1386.1"],["3.1518","1561.3"],["3.1520","3366.0"],["3.1530","1708.3"],["3.1532","2224.9"],["3.1533","1412.2"],["3.1535","2541.8"],["3.1537","1623.2"],["3.1539","1841.7"],["3.1541","1864.3"],["3.1543","1187.3"],["3.1546","2252.8"],["3.1547","535.1"]],"timestamp":1756900805609,"update_id":50195643,"fetch_time":1756900805650}
{"symbol":"TONUSDT","bids":[["3.1493","130.4"],["3.1490","1637.0"],["3.1488","1842.6"],["3.1474","741.6"],["3.1472","1227.5"],["3.1469","1459.8"],["3.1468","1589.8"],["3.1466","540.9"],["3.1463","479.6"],["3.1456","1606.5"],["3.1451","1460.4"],["3.1445","0"]],"asks":[["3.1498","28.4"],["3.1499","0"],["3.1502","1112.8"],["3.1503","1296.3"],["3.1520","3165.4"],["3.1521","1598.4"],["3.1532","2222.9"],["3.1533","1414.2"],["3.1547","723.3"],["3.1548","1285.6"]],"timestamp":1756900805629,"update_id":50195644,"fetch_time":1756900805674}
{"symbol":"TONUSDT","bids":[],"asks":[["3.1542","1861.8"],["3.1543","2455.1"]],"timestamp":1756900805669,"update_id":50195646,"fetch_time":1756900805713}
{"symbol":"TONUSDT","bids":[],"asks":[["3.1505","972.9"],["3.1510","1088.9"],["3.1535","1901.1"],["3.1540","7802.7"]],"timestamp":1756900805689,"update_id":50195647,"fetch_time":1756900805729}
{"symbol":"TONUSDT","bids":[],"asks":[["3.1534","1424.0"]],"timestamp":1756900805709,"update_id":50195648,"fetch_time":1756900805758}
{"symbol":"TONUSDT","bids":[["3.1489","794.2"],["3.1485","834.5"]],"asks":[],"timestamp":1756900805730,"update_id":50195649,"fetch_time":1756900805774}
{"symbol":"TONUSDT","bids":[["3.1489","730.8"]],"asks":[],"timestamp":1756900805749,"update_id":50195650,"fetch_time":1756900805789}
{"symbol":"TONUSDT","bids":[],"asks":[["3.1508","5949.5"]],"timestamp":1756900805789,"update_id":50195651,"fetch_time":1756900805834}
{"symbol":"TONUSDT","bids":[],"asks":[["3.1542","3129.6"],["3.1543","1187.3"]],"timestamp":1756900805810,"update_id":50195652,"fetch_time":1756900805853}
{"symbol":"TONUSDT","bids":[["3.1493","0"],["3.1492","609.0"],["3.1491","413.2"],["3.1490","852.7"],["3.1489","644.3"],["3.1488","1476.2"],["3.1487","9.0"],["3.1486","1270.3"],["3.1485","791.3"],["3.1445","1133.3"]],"asks":[["3.1497","28.8"],["3.1499","10.6"],["3.1500","327.1"],["3.1501","697.2"],["3.1502","1403.7"],["3.1505","1148.5"],["3.1547","0"],["3.1548","0"]],"timestamp":1756900805849,"update_id":50195653,"fetch_time":1756900805894}
{"symbol":"TONUSDT","bids":[["3.1492","3.2"],["3.1491","121.5"],["3.1490","396.8"],["3.1489","834.9"],["3.1488","932.1"],["3.1486","638.0"],["3.1484","720.4"],["3.1482","1255.3"],["3.1471","649.9"],["3.1469","1415.6"],["3.1467","2021.1"],["3.1465","830.5"],["3.1463","1023.7"],["3.1461","1629.0"],["3.1459","2597.0"],["3.1457","2009.7"]],"asks":[["3.1496","262.9"],["3.1497","0"],["3.1498","73.2"],["3.1499","37.9"],["3.1500","532.8"],["3.1501","740.5"],["3.1502","1485.5"],["3.1503","1621.7"],["3.1506","830.1"],["3.1508","5652.3"],["3.1513","997.0"],["3.1515","1296.8"],["3.1517","1014.7"],["3.1519","1624.5"],["3.1521","2238.2"],["3.1523","1575.2"],["3.1529","1011.8"],["3.1531","666.8"],["3.1533","1412.2"],["3.1535","2364.9"]],"timestamp":1756900805870,"update_id":50195654,"fetch_time":1756900805913}
{"symbol":"TONUSDT","bids":[["3.1490","145.6"],["3.1478","1467.7"],["3.1475","3615.8"]],"asks":[["3.1497","6.8"],["3.1499","199.8"],["3.1501","1680.2"],["3.1502","2149.1"],["3.1520","2464.3"],["3.1528","3301.2"],["3.1546","0"]],"timestamp":1756900805889,"update_id":50195655,"fetch_time":1756900805929}
{"symbol":"TONUSDT","bids":[],"asks":[["3.1496","265.2"],["3.1500","1011.4"],["3.1502","2327.2"],["3.1503","1499.9"],["3.1540","9070.6"],["3.1542","1861.8"]],"timestamp":1756900805929,"update_id":50195657,"fetch_time":1756900805982}
{"symbol":"TONUSDT","bids":[["3.1490","145.6"],["3.1489","898.3"]],"asks":[["3.1496","262.9"],["3.1497","0"],["3.1546","2252.8"]],"timestamp":1756900806009,"update_id":50195661,"fetch_time":1756900806050}
{"symbol":"TONUSDT","bids":[["3.1490","907.1"],["3.1487","95.5"],["3.1473","2537.5"],["3.1466","540.9"]],"asks":[],"timestamp":1756900806110,"update_id":50195665,"fetch_time":1756900806154}
{"symbol":"TONUSDT","bids":[["3.1490","1094.9"],["3.1488","975.3"]],"asks":[],"timestamp":1756900806149,"update_id":50195667,"fetch_time":1756900806194}
{"symbol":"TONUSDT","bids":[["3.1491","278.7"],["3.1490","1158.3"],["3.1488","1018.6"]],"asks":[],"timestamp":1756900806170,"update_id":50195668,"fetch_time":1756900806210}
{"symbol":"TONUSDT","bids":[["3.1489","730.8"]],"asks":[],"timestamp":1756900806270,"update_id":50195670,"fetch_time":1756900806314}
{"symbol":"TONUSDT","bids":[],"asks":[["3.1504","2015.3"]],"timestamp":1756900806389,"update_id":50195674,"fetch_time":1756900806446}
{"symbol":"TONUSDT","bids":[],"asks":[["3.1500","1122.6"],["3.1506","1437.5"],["3.1507","1072.8"]],"timestamp":1756900806409,"update_id":50195675,"fetch_time":1756900806454}
{"symbol":"TONUSDT","bids":[],"asks":[["3.1499","3.2"],["3.1500","963.8"],["3.1504","1703.0"]],"timestamp":1756900806429,"update_id":50195676,"fetch_time":1756900806474}
{"symbol":"TONUSDT","bids":[],"asks":[["3.1540","7802.7"],["3.1541","2776.4"]],"timestamp":1756900806469,"update_id":50195678,"fetch_time":1756900806518}
{"symbol":"TONUSDT","bids":[],"asks":[["3.1498","3.3"],["3.1499","26.0"]],"timestamp":1756900806510,"update_id":50195679,"fetch_time":1756900806550}
{"symbol":"TONUSDT","bids":[["3.1492","241.8"],["3.1491","312.1"],["3.1490","967.7"],["3.1486","681.2"]],"asks":[],"timestamp":1756900806530,"update_id":50195680,"fetch_time":1756900806574}
{"symbol":"TONUSDT","bids":[["3.1488","1149.2"]],"asks":[],"timestamp":1756900806550,"update_id":50195681,"fetch_time":1756900806594}
{"symbol":"TONUSDT","bids":[],"asks":[["3.1500","1007.0"]],"timestamp":1756900806569,"update_id":50195682,"fetch_time":1756900806609}
{"symbol":"TONUSDT","bids":[],"asks":[["3.1500","1050.3"]],"timestamp":1756900806670,"update_id":50195683,"fetch_time":1756900806714}
{"symbol":"TONUSDT","bids":[],"asks":[["3.1514","1213.6"]],"timestamp":1756900806689,"update_id":50195684,"fetch_time":1756900806734}
{"symbol":"TONUSDT","bids":[["3.1491","355.3"],["3.1490","1010.9"]],"asks":[],"timestamp":1756900806829,"update_id":50195685,"fetch_time":1756900806870}
{"symbol":"TONUSDT","bids":[["3.1484","720.4"]],"asks":[],"timestamp":1756900807069,"update_id":50195686,"fetch_time":1756900807114}
{"symbol":"TONUSDT","bids":[],"asks":[["3.1496","122.9"]],"timestamp":1756900807210,"update_id":50195688,"fetch_time":1756900807250}
{"symbol":"TONUSDT","bids":[],"asks":[["3.1500","963.8"],["3.1507","1116.0"]],"timestamp":1756900807250,"update_id":50195690,"fetch_time":1756900807294}
{"symbol":"TONUSDT","bids":[["3.1493","19.8"],["3.1486","1048.9"],["3.1484","1176.3"],["3.1482","1799.4"],["3.1480","1653.8"],["3.1478","2535.2"],["3.1476","5202.1"],["3.1467","1653.4"],["3.1465","1326.9"],["3.1463","479.6"],["3.1461","996.7"],["3.1459","1876.5"],["3.1457","1201.0"],["3.1445","0"]],"asks":[["3.1502","2239.8"],["3.1503","704.7"],["3.1504","1659.7"],["3.1505","1105.2"],["3.1506","1394.2"]],"timestamp":1756900807309,"update_id":50195692,"fetch_time":1756900807354}
{"symbol":"TONUSDT","bids":[["3.1492","460.1"],["3.1491","164.7"],["3.1488","1018.6"],["3.1487","307.8"]],"asks":[],"timestamp":1756900807330,"update_id":50195693,"fetch_time":1756900807374}
{"symbol":"TONUSDT","bids":[],"asks":[["3.1524","4824.2"],["3.1541","1508.5"],["3.1542","3129.7"]],"timestamp":1756900807349,"update_id":50195694,"fetch_time":1756900807390}
{"symbol":"TONUSDT","bids":[["3.1471","1602.2"],["3.1465","374.6"]],"asks":[],"timestamp":1756900807389,"update_id":50195695,"fetch_time":1756900807434}
{"symbol":"TONUSDT","bids":[["3.1466","540.9"]],"asks":[],"timestamp":1756900807409,"update_id":50195696,"fetch_time":1756900807450}
{"symbol":"TONUSDT","bids":[],"asks":[["3.1542","3129.6"]],"timestamp":1756900807529,"update_id":50195697,"fetch_time":1756900807574}
{"symbol":"TONUSDT","bids":[],"asks":[["3.1504","1703.0"],["3.1505","1148.5"]],"timestamp":1756900807549,"update_id":50195698,"fetch_time":1756900807590}
{"symbol":"TONUSDT","bids":[["3.1495","728.9"]],"asks":[["3.1496","0"],["3.1547","535.1"]],"timestamp":1756900807629,"update_id":50195699,"fetch_time":1756900807678}
{"symbol":"TONUSDT","bids":[],"asks":[["3.1501","672.3"],["3.1502","1332.9"],["3.1503","892.5"],["3.1531","664.8"],["3.1533","1414.2"]],"timestamp":1756900807650,"update_id":50195700,"fetch_time":1756900807694}
{"symbol":"TONUSDT","bids":[],"asks":[["3.1500","431.1"],["3.1503","1456.4"]],"timestamp":1756900807669,"update_id":50195701,"fetch_time":1756900807718}
{"symbol":"TONUSDT","bids":[],"asks":[["3.1503","1644.4"]],"timestamp":1756900807690,"update_id":50195702,"fetch_time":1756900807734}
{"symbol":"TONUSDT","bids":[["3.1489","751.9"],["3.1488","998.1"],["3.1484","1238.0"],["3.1483","872.1"]],"asks":[],"timestamp":1756900807910,"update_id":50195703,"fetch_time":1756900807954}
{"symbol":"TONUSDT","bids":[["3.1493","0"],["3.1492","432.4"],["3.1491","121.5"],["3.1481","493.1"],["3.1445","1133.3"]],"asks":[["3.1503","1687.7"],["3.1506","1437.5"]],"timestamp":1756900807930,"update_id":50195704,"fetch_time":1756900807974}
{"symbol":"TONUSDT","bids":[],"asks":[["3.1500","37.7"],["3.1501","669.9"]],"timestamp":1756900808129,"update_id":50195705,"fetch_time":1756900808175}
{"symbol":"TONUSDT","bids":[["3.1491","205.0"],["3.1487","264.5"]],"asks":[],"timestamp":1756900808189,"update_id":50195707,"fetch_time":1756900808230}
{"symbol":"TONUSDT","bids":[],"asks":[["3.1507","818.8"],["3.1513","984.6"],["3.1515","995.7"],["3.1517","600.7"],["3.1519","1097.6"],["3.1521","1598.4"],["3.1523","822.5"],["3.1534","2363.0"],["3.1539","2197.5"]],"timestamp":1756900808209,"update_id":50195708,"fetch_time":1756900808254}
{"symbol":"TONUSDT","bids":[],"asks":[["3.1500","405.8"],["3.1508","5835.9"],["3.1540","8164.1"],["3.1542","1861.8"],["3.1543","2455.1"]],"timestamp":1756900808229,"update_id":50195709,"fetch_time":1756900808274}
{"symbol":"TONUSDT","bids":[["3.1493","260.7"],["3.1492","277.4"],["3.1473","1495.4"],["3.1465","1416.7"],["3.1445","0"]],"asks":[["3.1508","5652.3"],["3.1520","2464.3"],["3.1529","2053.9"],["3.1540","7802.7"]],"timestamp":1756900808250,"update_id":50195710,"fetch_time":1756900808294}
{"symbol":"TONUSDT","bids":[["3.1465","1225.7"],["3.1448","8127.9"]],"asks":[],"timestamp":1756900808309,"update_id":50195712,"fetch_time":1756900808354}
{"symbol":"TONUSDT","bids":[["3.1496","122.9"],["3.1470","2449.3"],["3.1466","540.9"],["3.1446","0"]],"asks":[["3.1501","547.0"],["3.1521","2722.3"],["3.1543","1187.3"],["3.1544","4668.4"]],"timestamp":1756900808350,"update_id":50195714,"fetch_time":1756900808394}
{"symbol":"TONUSDT","bids":[["3.1493","266.3"],["3.1491","268.4"],["3.1490","1477.7"]],"asks":[],"timestamp":1756900808389,"update_id":50195716,"fetch_time":1756900808434}
{"symbol":"TONUSDT","bids":[["3.1490","1774.0"]],"asks":[],"timestamp":1756900808450,"update_id":50195719,"fetch_time":1756900808494}
{"symbol":"TONUSDT","bids":[["3.1490","1710.6"]],"asks":[],"timestamp":1756900808489,"update_id":50195720,"fetch_time":1756900808534}
{"symbol":"TONUSDT","bids":[],"asks":[["3.1532","1957.3"],["3.1536","2535.0"],["3.1543","394.9"]],"timestamp":1756900808509,"update_id":50195721,"fetch_time":1756900808555}
{"symbol":"TONUSDT","bids":[],"asks":[["3.1546","2450.1"]],"timestamp":1756900808529,"update_id":50195722,"fetch_time":1756900808574}
{"symbol":"TONUSDT","bids":[["3.1493","309.5"]],"asks":[],"timestamp":1756900808630,"update_id":50195723,"fetch_time":1756900808674}
{"symbol":"TONUSDT","bids":[],"asks":[["3.1509","4908.1"]],"timestamp":1756900808649,"update_id":50195724,"fetch_time":1756900808690}
{"symbol":"TONUSDT","bids":[["3.1486","955.7"]],"asks":[],"timestamp":1756900808709,"update_id":50195726,"fetch_time":1756900808754}
{"symbol":"TONUSDT","bids":[["3.1493","266.3"],["3.1492","527.5"],["3.1491","416.0"]],"asks":[],"timestamp":1756900808770,"update_id":50195728,"fetch_time":1756900808814}
{"symbol":"TONUSDT","bids":[["3.1495","778.7"]],"asks":[],"timestamp":1756900808850,"update_id":50195730,"fetch_time":1756900808894}
{"symbol":"TONUSDT","bids":[],"asks":[["3.1499","3.2"],["3.1500","428.7"]],"timestamp":1756900808910,"update_id":50195731,"fetch_time":1756900808954}
{"symbol":"TONUSDT","bids":[],"asks":[["3.1506","1519.3"]],"timestamp":1756900808929,"update_id":50195732,"fetch_time":1756900808974}
{"symbol":"TONUSDT","bids":[["3.1492","831.5"],["3.1491","459.2"]],"asks":[],"timestamp":1756900809010,"update_id":50195733,"fetch_time":1756900809054}
{"symbol":"TONUSDT","bids":[],"asks":[["3.1509","5066.7"]],"timestamp":1756900809049,"update_id":50195734,"fetch_time":1756900809098}
{"symbol":"TONUSDT","bids":[["3.1493","48.8"],["3.1487","221.3"]],"asks":[],"timestamp":1756900809070,"update_id":50195735,"fetch_time":1756900809118}
{"symbol":"TONUSDT","bids":[["3.1497","66.4"],["3.1492","614.0"],["3.1490","1731.7"],["3.1489","730.8"],["3.1485","854.2"],["3.1484","1176.3"],["3.1475","3866.1"],["3.1474","1746.5"],["3.1473","2286.0"],["3.1447","0"]],"asks":[["3.1500","405.8"],["3.1501","403.4"],["3.1503","638.5"],["3.1504","1691.3"],["3.1506","1463.5"],["3.1508","5588.8"],["3.1513","677.2"],["3.1516","2813.3"]],"timestamp":1756900809190,"update_id":50195736,"fetch_time":1756900809234}
{"symbol":"TONUSDT","bids":[],"asks":[["3.1507","1006.8"]],"timestamp":1756900809369,"update_id":50195745,"fetch_time":1756900809410}
{"symbol":"TONUSDT","bids":[],"asks":[["3.1502","209.9"],["3.1510","1155.1"],["3.1511","907.6"],["3.1546","2450.1"],["3.1547","1802.8"]],"timestamp":1756900809390,"update_id":50195746,"fetch_time":1756900809434}
{"symbol":"TONUSDT","bids":[],"asks":[["3.1506","1889.3"],["3.1511","1232.3"],["3.1540","7354.8"],["3.1545","2122.2"],["3.1546","2805.8"],["3.1547","535.1"]],"timestamp":1756900809410,"update_id":50195747,"fetch_time":1756900809458}
{"symbol":"TONUSDT","bids":[["3.1493","123.7"]],"asks":[],"timestamp":1756900809489,"update_id":50195749,"fetch_time":1756900809534}
{"symbol":"TONUSDT","bids":[["3.1499","29.2"],["3.1498","93.4"],["3.1497","639.1"],["3.1496","611.4"],["3.1493","311.4"],["3.1492","1349.2"],["3.1488","1487.8"],["3.1449","0"],["3.1448","0"]],"asks":[["3.1498","0"],["3.1499","0"],["3.1501","127.1"],["3.1505","135.5"],["3.1506","1419.8"],["3.1507","162.0"],["3.1508","2142.5"],["3.1509","1129.6"],["3.1510","1095.1"],["3.1511","724.0"],["3.1513","2547.2"],["3.1514","3207.1"],["3.1515","737.4"],["3.1521","2521.7"],["3.1522","1861.9"],["3.1533","1227.1"],["3.1534","5340.6"],["3.1548","3345.4"],["3.1549","426.7"]],"timestamp":1756900809510,"update_id":50195750,"fetch_time":1756900809558}
{"symbol":"TONUSDT","bids":[],"asks":[["3.1507","725.7"],["3.1524","1764.0"]],"timestamp":1756900809649,"update_id":50195757,"fetch_time":1756900809694}
{"symbol":"TONUSDT","bids":[],"asks":[["3.1505","25.5"],["3.1506","179.6"]],"timestamp":1756900809710,"update_id":50195760,"fetch_time":1756900809754}
{"symbol":"TONUSDT","bids":[],"asks":[["3.1524","1905.8"]],"timestamp":1756900809729,"update_id":50195761,"fetch_time":1756900809770}
{"symbol":"TONUSDT","bids":[],"asks":[["3.1508","1222.3"],["3.1526","1939.3"],["3.1527","2764.9"]],"timestamp":1756900809750,"update_id":50195762,"fetch_time":1756900809790}
{"symbol":"TONUSDT","bids":[],"asks":[["3.1508","1222.5"],["3.1511","724.0"],["3.1526","2469.5"]],"timestamp":1756900809769,"update_id":50195763,"fetch_time":1756900809814}
{"symbol":"TONUSDT","bids":[],"asks":[["3.1510","829.2"],["3.1523","822.5"]],"timestamp":1756900809790,"update_id":50195764,"fetch_time":1756900809834}
{"symbol":"TONUSDT","bids":[["3.1486","1206.6"]],"asks":[],"timestamp":1756900809830,"update_id":50195766,"fetch_time":1756900809871}
{"symbol":"TONUSDT","bids":[],"asks":[["3.1506","796.8"]],"timestamp":1756900809849,"update_id":50195767,"fetch_time":1756900809891}
{"symbol":"TONUSDT","bids":[],"asks":[["3.1509","702.8"]],"timestamp":1756900809870,"update_id":50195768,"fetch_time":1756900809915}
{"symbol":"TONUSDT","bids":[],"asks":[["3.1508","1062.8"]],"timestamp":1756900809890,"update_id":50195769,"fetch_time":1756900809934}
{"symbol":"TONUSDT","bids":[],"asks":[["3.1507","631.5"],["3.1526","3144.4"],["3.1527","1779.5"]],"timestamp":1756900809910,"update_id":50195770,"fetch_time":1756900809954}
{"symbol":"TONUSDT","bids":[],"asks":[["3.1510","962.7"],["3.1524","2097.2"]],"timestamp":1756900809929,"update_id":50195771,"fetch_time":1756900809974}
{"symbol":"TONUSDT","bids":[],"asks":[["3.1510","1042.9"],["3.1525","1480.2"],["3.1526","2469.5"]],"timestamp":1756900810050,"update_id":50195772,"fetch_time":1756900810094}
{"symbol":"TONUSDT","bids":[],"asks":[["3.1505","668.9"],["3.1537","1623.2"],["3.1540","7784.3"]],"timestamp":1756900810189,"update_id":50195775,"fetch_time":1756900810243}
{"symbol":"TONUSDT","bids":[],"asks":[["3.1507","537.6"]],"timestamp":1756900810250,"update_id":50195778,"fetch_time":1756900810294}
{"symbol":"TONUSDT","bids":[],"asks":[["3.1507","162.0"],["3.1508","874.9"]],"timestamp":1756900810269,"update_id":50195779,"fetch_time":1756900810314}
{"symbol":"TONUSDT","bids":[],"asks":[["3.1506","1744.0"]],"timestamp":1756900810290,"update_id":50195780,"fetch_time":1756900810334}
{"symbol":"TONUSDT","bids":[],"asks":[["3.1519","3539.1"],["3.1525","1186.7"],["3.1546","2511.9"]],"timestamp":1756900810349,"update_id":50195781,"fetch_time":1756900810395}
{"symbol":"TONUSDT","bids":[["3.1496","815.2"]],"asks":[],"timestamp":1756900810429,"update_id":50195782,"fetch_time":1756900810474}
{"symbol":"TONUSDT","bids":[],"asks":[["3.1516","2885.4"]],"timestamp":1756900810590,"update_id":50195784,"fetch_time":1756900810634}
{"symbol":"TONUSDT","bids":[],"asks":[["3.1516","3133.7"]],"timestamp":1756900810610,"update_id":50195785,"fetch_time":1756900810654}
{"symbol":"TONUSDT","bids":[],"asks":[["3.1545","1835.7"]],"timestamp":1756900810689,"update_id":50195786,"fetch_time":1756900810730}
{"symbol":"TONUSDT","bids":[["3.1500","692.4"],["3.1495","170.3"],["3.1484","4398.5"],["3.1450","0"]],"asks":[["3.1500","0"],["3.1550","1105.5"]],"timestamp":1756900810830,"update_id":50195789,"fetch_time":1756900810874}
{"symbol":"TONUSDT","bids":[["3.1500","815.3"],["3.1499","0"],["3.1496","684.6"],["3.1485","821.3"],["3.1484","4428.5"],["3.1476","3493.1"],["3.1475","1715.8"],["3.1474","2690.3"],["3.1469","573.7"],["3.1461","897.3"],["3.1456","1496.1"],["3.1450","1442.2"]],"asks":[["3.1501","123.9"],["3.1502","0"],["3.1504","323.7"],["3.1505","548.1"],["3.1506","1375.9"],["3.1535","1916.9"],["3.1536","2276.4"],["3.1551","1095.3"]],"timestamp":1756900810850,"update_id":50195790,"fetch_time":1756900810894}
{"symbol":"TONUSDT","bids":[],"asks":[["3.1546","2222.3"],["3.1548","2534.7"]],"timestamp":1756900810929,"update_id":50195794,"fetch_time":1756900810974}
{"symbol":"TONUSDT","bids":[],"asks":[["3.1501","28.8"]],"timestamp":1756900810950,"update_id":50195795,"fetch_time":1756900810994}
{"symbol":"TONUSDT","bids":[],"asks":[["3.1506","410.8"],["3.1508","1775.3"],["3.1510","1004.8"],["3.1515","2607.4"]],"timestamp":1756900811029,"update_id":50195799,"fetch_time":1756900811074}
{"symbol":"TONUSDT","bids":[["3.1503","90.9"],["3.1498","667.9"],["3.1497","947.7"],["3.1491","164.7"],["3.1483","2619.2"],["3.1450","0"]],"asks":[["3.1501","0"],["3.1503","0"],["3.1508","1592.1"],["3.1524","1913.2"],["3.1552","2016.7"],["3.1553","1179.9"]],"timestamp":1756900811150,"update_id":50195804,"fetch_time":1756900811195}
{"symbol":"TONUSDT","bids":[["3.1503","169.2"],["3.1501","173.1"],["3.1500","909.4"],["3.1499","83.3"],["3.1498","1395.6"],["3.1496","795.5"],["3.1495","588.4"],["3.1494","1262.6"],["3.1493","287.5"],["3.1492","1071.1"],["3.1491","403.4"],["3.1490","1702.9"],["3.1483","2863.0"],["3.1480","1807.6"],["3.1479","302.6"],["3.1478","2590.4"],["3.1477","654.9"],["3.1476","3548.3"],["3.1467","1598.2"],["3.1466","1235.9"],["3.1464","1868.5"],["3.1452","0"],["3.1451","0"]],"asks":[["3.1504","318.1"],["3.1505","0"],["3.1507","118.8"],["3.1508","691.7"],["3.1509","3.2"],["3.1510","1083.5"],["3.1511","543.8"],["3.1513","1575.2"],["3.1514","3414.1"],["3.1516","3447.5"],["3.1519","3281.8"],["3.1520","1130.5"],["3.1523","1079.4"],["3.1535","785.9"],["3.1536","1907.3"],["3.1539","2199.5"],["3.1540","6899.9"],["3.1548","2077.8"],["3.1549","1694.3"],["3.1554","1540.7"]],"timestamp":1756900811169,"update_id":50195805,"fetch_time":1756900811214}
{"symbol":"TONUSDT","bids":[],"asks":[["3.1511","825.6"],["3.1523","974.9"],["3.1524","1783.7"],["3.1528","2142.7"],["3.1530","3735.8"],["3.1548","1285.6"]],"timestamp":1756900811249,"update_id":50195809,"fetch_time":1756900811298}
{"symbol":"TONUSDT","bids":[],"asks":[["3.1516","3447.5"],["3.1550","1727.2"],["3.1551","1603.5"],["3.1552","3284.2"]],"timestamp":1756900811289,"update_id":50195811,"fetch_time":1756900811330}
{"symbol":"TONUSDT","bids":[],"asks":[["3.1512","1682.1"],["3.1535","785.9"],["3.1536","2365.4"]],"timestamp":1756900811350,"update_id":50195814,"fetch_time":1756900811395}
{"symbol":"TONUSDT","bids":[],"asks":[["3.1513","1359.4"],["3.1534","5096.6"],["3.1538","2422.6"],["3.1539","3192.1"],["3.1551","2871.0"],["3.1552","2016.7"]],"timestamp":1756900811370,"update_id":50195815,"fetch_time":1756900811414}
{"symbol":"TONUSDT","bids":[],"asks":[["3.1529","426.7"],["3.1535","770.1"],["3.1551","1603.5"],["3.1553","2447.3"]],"timestamp":1756900811390,"update_id":50195816,"fetch_time":1756900811435}
{"symbol":"TONUSDT","bids":[],"asks":[["3.1552","2304.1"]],"timestamp":1756900811429,"update_id":50195818,"fetch_time":1756900811475}
{"symbol":"TONUSDT","bids":[],"asks":[["3.1510","1933.6"]],"timestamp":1756900811490,"update_id":50195819,"fetch_time":1756900811534}
{"symbol":"TONUSDT","bids":[["3.1501","408.1"]],"asks":[],"timestamp":1756900811509,"update_id":50195820,"fetch_time":1756900811554}
{"symbol":"TONUSDT","bids":[],"asks":[["3.1511","543.8"],["3.1530","2750.4"],["3.1531","1470.5"]],"timestamp":1756900811550,"update_id":50195821,"fetch_time":1756900811594}
{"symbol":"TONUSDT","bids":[],"asks":[["3.1511","911.8"],["3.1528","2142.7"]],"timestamp":1756900811569,"update_id":50195822,"fetch_time":1756900811614}
{"symbol":"TONUSDT","bids":[],"asks":[["3.1512","1494.3"],["3.1517","926.7"]],"timestamp":1756900811669,"update_id":50195823,"fetch_time":1756900811710}
{"symbol":"TONUSDT","bids":[["3.1498","1888.8"]],"asks":[],"timestamp":1756900811729,"update_id":50195824,"fetch_time":1756900811774}
{"symbol":"TONUSDT","bids":[["3.1502","199.1"],["3.1501","140.0"],["3.1453","0"]],"asks":[["3.1517","600.7"]],"timestamp":1756900811750,"update_id":50195825,"fetch_time":1756900811794}
{"symbol":"TONUSDT","bids":[],"asks":[["3.1539","2836.3"],["3.1540","7129.6"]],"timestamp":1756900811789,"update_id":50195827,"fetch_time":1756900811830}
{"symbol":"TONUSDT","bids":[],"asks":[["3.1504","0"],["3.1555","586.9"]],"timestamp":1756900811809,"update_id":50195828,"fetch_time":1756900811854}
{"symbol":"TONUSDT","bids":[["3.1504","20.0"],["3.1502","230.6"],["3.1500","870.7"],["3.1499","360.8"],["3.1498","2256.4"],["3.1496","1251.3"],["3.1494","1969.2"],["3.1492","1643.8"],["3.1490","2423.3"],["3.1488","2328.8"],["3.1486","1368.6"],["3.1484","3972.6"],["3.1482","2568.2"],["3.1480","1219.5"],["3.1478","1869.9"],["3.1476","2739.6"],["3.1474","2734.5"],["3.1472","2538.3"],["3.1466","1191.7"],["3.1454","0"]],"asks":[["3.1506","0"],["3.1507","115.6"],["3.1508","0"],["3.1510","939.2"],["3.1511","67.2"],["3.1512","1775.9"],["3.1517","801.3"],["3.1539","1703.4"],["3.1542","1333.4"],["3.1556","3180.5"],["3.1557","2043.9"]],"timestamp":1756900811829,"update_id":50195829,"fetch_time":1756900811870}
{"symbol":"TONUSDT","bids":[["3.1499","580.8"],["3.1495","464.7"],["3.1488","1972.6"],["3.1482","1878.9"],["3.1480","1035.7"],["3.1478","1522.9"]],"asks":[["3.1508","196.0"],["3.1509","231.6"],["3.1510","421.6"],["3.1512","2057.7"],["3.1520","1075.3"],["3.1522","1561.9"],["3.1528","2098.5"],["3.1530","2849.8"],["3.1532","2754.8"],["3.1536","2409.6"],["3.1557","0"]],"timestamp":1756900811850,"update_id":50195830,"fetch_time":1756900811895}
{"symbol":"TONUSDT","bids":[],"asks":[["3.1512","2098.3"]],"timestamp":1756900811909,"update_id":50195833,"fetch_time":1756900812004}
{"symbol":"TONUSDT","bids":[],"asks":[["3.1527","827.4"],["3.1529","1378.7"]],"timestamp":1756900811950,"update_id":50195835,"fetch_time":1756900812016}
{"symbol":"TONUSDT","bids":[],"asks":[["3.1526","1468.2"]],"timestamp":1756900811970,"update_id":50195836,"fetch_time":1756900812019}
{"symbol":"TONUSDT","bids":[["3.1498","2005.4"]],"asks":[],"timestamp":1756900811989,"update_id":50195837,"fetch_time":1756900812032}
{"symbol":"TONUSDT","bids":[["3.1501","654.5"],["3.1495","444.9"]],"asks":[],"timestamp":1756900812090,"update_id":50195841,"fetch_time":1756900812135}
{"symbol":"TONUSDT","bids":[],"asks":[["3.1512","2129.9"]],"timestamp":1756900812149,"update_id":50195842,"fetch_time":1756900812191}
{"symbol":"TONUSDT","bids":[],"asks":[["3.1513","718.7"]],"timestamp":1756900812169,"update_id":50195843,"fetch_time":1756900812215}
{"symbol":"TONUSDT","bids":[["3.1505","2.6"],["3.1495","442.9"],["3.1455","0"]],"asks":[["3.1516","3133.7"]],"timestamp":1756900812190,"update_id":50195844,"fetch_time":1756900812239}
{"symbol":"TONUSDT","bids":[["3.1504","0"],["3.1502","512.5"],["3.1501","455.4"],["3.1498","1946.1"],["3.1495","724.8"],["3.1494","1936.8"],["3.1483","2336.9"],["3.1455","1197.2"]],"asks":[["3.1512","2088.4"],["3.1516","3175.2"],["3.1517","801.3"],["3.1518","2942.5"]],"timestamp":1756900812210,"update_id":50195845,"fetch_time":1756900812259}
{"symbol":"TONUSDT","bids":[["3.1502","484.2"],["3.1500","1121.7"],["3.1496","1674.8"],["3.1487","606.3"],["3.1477","651.6"]],"asks":[],"timestamp":1756900812229,"update_id":50195846,"fetch_time":1756900812283}
{"symbol":"TONUSDT","bids":[["3.1498","2092.4"],["3.1496","2158.7"]],"asks":[],"timestamp":1756900812249,"update_id":50195847,"fetch_time":1756900812299}
{"symbol":"TONUSDT","bids":[["3.1499","644.2"]],"asks":[],"timestamp":1756900812290,"update_id":50195848,"fetch_time":1756900812331}
{"symbol":"TONUSDT","bids":[],"asks":[["3.1518","3267.2"]],"timestamp":1756900812310,"update_id":50195849,"fetch_time":1756900812355}
{"symbol":"TONUSDT","bids":[],"asks":[["3.1519","2440.3"]],"timestamp":1756900812449,"update_id":50195853,"fetch_time":1756900812503}
{"symbol":"TONUSDT","bids":[],"asks":[["3.1546","2927.7"]],"timestamp":1756900812490,"update_id":50195854,"fetch_time":1756900812535}
{"symbol":"TONUSDT","bids":[["3.1501","455.4"]],"asks":[],"timestamp":1756900812510,"update_id":50195855,"fetch_time":1756900812558}
{"symbol":"TONUSDT","bids":[],"asks":[["3.1517","1129.3"]],"timestamp":1756900812550,"update_id":50195856,"fetch_time":1756900812595}
{"symbol":"TONUSDT","bids":[["3.1486","1432.1"]],"asks":[],"timestamp":1756900812570,"update_id":50195857,"fetch_time":1756900812611}
{"symbol":"TONUSDT","bids":[],"asks":[["3.1544","3114.1"]],"timestamp":1756900812589,"update_id":50195858,"fetch_time":1756900812630}
{"symbol":"TONUSDT","bids":[],"asks":[["3.1514","3493.8"]],"timestamp":1756900812769,"update_id":50195860,"fetch_time":1756900812811}
{"symbol":"TONUSDT","bids":[],"asks":[["3.1518","3859.3"]],"timestamp":1756900812809,"update_id":50195861,"fetch_time":1756900812855}
{"symbol":"TONUSDT","bids":[],"asks":[["3.1531","1732.4"]],"timestamp":1756900812830,"update_id":50195862,"fetch_time":1756900812875}
{"symbol":"TONUSDT","bids":[["3.1484","3172.6"]],"asks":[["3.1507","0"],["3.1522","1565.2"],["3.1557","2043.9"]],"timestamp":1756900812889,"update_id":50195863,"fetch_time":1756900812939}
{"symbol":"TONUSDT","bids":[["3.1503","227.5"]],"asks":[],"timestamp":1756900813010,"update_id":50195867,"fetch_time":1756900813051}
{"symbol":"TONUSDT","bids":[["3.1501","413.9"]],"asks":[],"timestamp":1756900813029,"update_id":50195868,"fetch_time":1756900813075}
{"symbol":"TONUSDT","bids":[["3.1502","450.5"]],"asks":[],"timestamp":1756900813049,"update_id":50195869,"fetch_time":1756900813091}
{"symbol":"TONUSDT","bids":[["3.1500","1090.8"],["3.1499","311.5"],["3.1498","1744.2"],["3.1497","642.3"],["3.1496","1640.3"]],"asks":[],"timestamp":1756900813129,"update_id":50195870,"fetch_time":1756900813171}
{"symbol":"TONUSDT","bids":[],"asks":[["3.1512","946.5"]],"timestamp":1756900813149,"update_id":50195871,"fetch_time":1756900813195}
{"symbol":"TONUSDT","bids":[],"asks":[["3.1526","1656.4"],["3.1529","1679.8"],["3.1532","3168.8"],["3.1535","1297.0"],["3.1538","3666.8"],["3.1541","2627.3"]],"timestamp":1756900813170,"update_id":50195872,"fetch_time":1756900813219}
{"symbol":"TONUSDT","bids":[],"asks":[["3.1530","3169.3"]],"timestamp":1756900813189,"update_id":50195873,"fetch_time":1756900813235}
{"symbol":"TONUSDT","bids":[["3.1506","10.3"],["3.1498","1784.3"],["3.1494","1379.5"],["3.1455","0"]],"asks":[["3.1512","906.4"],["3.1513","1616.0"],["3.1514","3410.8"],["3.1515","2572.1"]],"timestamp":1756900813310,"update_id":50195874,"fetch_time":1756900813356}
{"symbol":"TONUSDT","bids":[["3.1503","230.7"],["3.1500","1130.9"],["3.1499","351.6"]],"asks":[],"timestamp":1756900813329,"update_id":50195875,"fetch_time":1756900813379}
{"symbol":"TONUSDT","bids":[],"asks":[["3.1512","938.0"],["3.1548","1815.8"]],"timestamp":1756900813369,"update_id":50195877,"fetch_time":1756900813415}
{"symbol":"TONUSDT","bids":[["3.1503","262.4"]],"asks":[],"timestamp":1756900813389,"update_id":50195878,"fetch_time":1756900813431}
{"symbol":"TONUSDT","bids":[["3.1480","1364.0"]],"asks":[],"timestamp":1756900813469,"update_id":50195880,"fetch_time":1756900813511}
{"symbol":"TONUSDT","bids":[],"asks":[["3.1508","0"],["3.1510","418.4"],["3.1513","37.3"],["3.1515","2288.3"],["3.1519","2737.9"],["3.1526","1468.2"],["3.1529","1378.7"],["3.1532","2754.8"],["3.1535","770.1"],["3.1538","3027.0"],["3.1541","1874.6"],["3.1543","299.8"],["3.1544","3116.1"],["3.1554","2023.1"],["3.1555","868.7"],["3.1558","1403.3"]],"timestamp":1756900813510,"update_id":50195881,"fetch_time":1756900813559}
{"symbol":"TONUSDT","bids":[],"asks":[["3.1517","1127.9"],["3.1530","2127.2"],["3.1537","2665.3"]],"timestamp":1756900813609,"update_id":50195886,"fetch_time":1756900813651}
{"symbol":"TONUSDT","bids":[["3.1503","262.4"]],"asks":[["3.1507","28.8"],["3.1508","194.0"],["3.1513","288.5"],["3.1535","738.4"],["3.1536","2732.3"],["3.1543","301.8"],["3.1544","3114.1"],["3.1557","0"],["3.1558","0"]],"timestamp":1756900813629,"update_id":50195887,"fetch_time":1756900813671}
{"symbol":"TONUSDT","bids":[],"asks":[["3.1512","1458.0"],["3.1515","2286.9"]],"timestamp":1756900813669,"update_id":50195889,"fetch_time":1756900813719}
{"symbol":"TONUSDT","bids":[],"asks":[["3.1510","421.6"],["3.1511","243.1"],["3.1512","1927.6"],["3.1513","952.6"],["3.1514","3974.2"]],"timestamp":1756900813689,"update_id":50195890,"fetch_time":1756900813743}
{"symbol":"TONUSDT","bids":[],"asks":[["3.1546","1660.0"],["3.1550","3261.3"]],"timestamp":1756900813750,"update_id":50195892,"fetch_time":1756900813803}
{"symbol":"TONUSDT","bids":[],"asks":[["3.1544","2784.4"]],"timestamp":1756900813769,"update_id":50195893,"fetch_time":1756900813815}
{"symbol":"TONUSDT","bids":[],"asks":[["3.1513","764.8"],["3.1514","3410.8"],["3.1542","1074.0"]],"timestamp":1756900813789,"update_id":50195894,"fetch_time":1756900813835}
{"symbol":"TONUSDT","bids":[],"asks":[["3.1511","464.1"]],"timestamp":1756900813850,"update_id":50195897,"fetch_time":1756900813895}
{"symbol":"TONUSDT","bids":[["3.1500","880.1"]],"asks":[],"timestamp":1756900813970,"update_id":50195899,"fetch_time":1756900814015}
{"symbol":"TONUSDT","bids":[],"asks":[["3.1519","2766.9"]],"timestamp":1756900813990,"update_id":50195900,"fetch_time":1756900814039}
{"symbol":"TONUSDT","bids":[],"asks":[["3.1512","1927.6"]],"timestamp":1756900814329,"update_id":50195901,"fetch_time":1756900814375}
{"symbol":"TONUSDT","bids":[],"asks":[["3.1521","405.7"]],"timestamp":1756900814490,"update_id":50195904,"fetch_time":1756900814535}
{"symbol":"TONUSDT","bids":[],"asks":[["3.1508","0"],["3.1557","2043.9"]],"timestamp":1756900814690,"update_id":50195905,"fetch_time":1756900814731}
{"symbol":"TONUSDT","bids":[["3.1504","19.8"],["3.1503","501.4"],["3.1502","731.4"],["3.1499","391.1"],["3.1456","0"]],"asks":[["3.1508","188.3"],["3.1513","828.2"],["3.1557","0"]],"timestamp":1756900814710,"update_id":50195906,"fetch_time":1756900814755}
{"symbol":"TONUSDT","bids":[["3.1504","0"],["3.1503","473.7"],["3.1502","691.9"],["3.1497","681.8"],["3.1456","1496.1"]],"asks":[["3.1513","796.5"],["3.1514","3450.3"],["3.1515","2286.3"]],"timestamp":1756900814929,"update_id":50195908,"fetch_time":1756900814975}
{"symbol":"TONUSDT","bids":[["3.1498","1546.3"]],"asks":[],"timestamp":1756900815009,"update_id":50195909,"fetch_time":1756900815051}
{"symbol":"TONUSDT","bids":[],"asks":[["3.1508","0"],["3.1557","2043.9"]],"timestamp":1756900815309,"update_id":50195912,"fetch_time":1756900815355}
{"symbol":"TONUSDT","bids":[["3.1503","501.4"]],"asks":[],"timestamp":1756900815330,"update_id":50195913,"fetch_time":1756900815376}
{"symbol":"TONUSDT","bids":[],"asks":[["3.1514","3410.8"],["3.1515","2246.8"]],"timestamp":1756900815349,"update_id":50195914,"fetch_time":1756900815391}
{"symbol":"TONUSDT","bids":[["3.1506","150.3"]],"asks":[["3.1508","188.3"],["3.1542","1074.0"],["3.1547","1043.3"],["3.1557","0"]],"timestamp":1756900815369,"update_id":50195915,"fetch_time":1756900815416}
{"symbol":"TONUSDT","bids":[["3.1501","1342.3"],["3.1500","879.5"],["3.1499","390.5"]],"asks":[],"timestamp":1756900815550,"update_id":50195917,"fetch_time":1756900815591}
{"symbol":"TONUSDT","bids":[],"asks":[["3.1512","1281.5"],["3.1514","1194.6"],["3.1516","3904.7"]],"timestamp":1756900815590,"update_id":50195919,"fetch_time":1756900815636}
{"symbol":"TONUSDT","bids":[["3.1477","2044.8"]],"asks":[],"timestamp":1756900815629,"update_id":50195920,"fetch_time":1756900815676}
{"symbol":"TONUSDT","bids":[["3.1504","19.8"],["3.1503","238.6"],["3.1502","731.4"],["3.1501","1381.8"],["3.1500","919.0"],["3.1486","1368.6"],["3.1456","0"]],"asks":[["3.1507","0"],["3.1508","0"],["3.1509","0"],["3.1512","342.7"],["3.1513","100.7"],["3.1514","911.8"],["3.1515","136.6"],["3.1518","5617.5"],["3.1519","4183.0"],["3.1520","1145.7"],["3.1525","566.2"],["3.1557","2325.5"],["3.1558","1403.3"],["3.1559","915.4"]],"timestamp":1756900815689,"update_id":50195921,"fetch_time":1756900815735}
{"symbol":"TONUSDT","bids":[["3.1508","20.0"],["3.1505","30.2"],["3.1502","1041.1"],["3.1486","1104.8"],["3.1480","1188.0"],["3.1474","1541.2"],["3.1457","0"]],"asks":[["3.1513","164.2"],["3.1516","3606.6"],["3.1520","1500.8"],["3.1521","253.6"],["3.1540","6470.4"],["3.1543","428.2"],["3.1546","1967.5"],["3.1550","3420.9"],["3.1552","2016.7"],["3.1557","2705.0"]],"timestamp":1756900815729,"update_id":50195923,"fetch_time":1756900815780}
{"symbol":"TONUSDT","bids":[["3.1508","0"],["3.1501","1194.2"],["3.1493","569.3"],["3.1486","3165.8"],["3.1485","2691.3"],["3.1484","1272.6"],["3.1483","466.9"],["3.1457","7992.4"]],"asks":[["3.1517","1408.8"]],"timestamp":1756900815810,"update_id":50195927,"fetch_time":1756900815856}
{"symbol":"TONUSDT","bids":[["3.1505","30.2"],["3.1503","238.6"],["3.1484","720.4"]],"asks":[],"timestamp":1756900815830,"update_id":50195928,"fetch_time":1756900815872}
{"symbol":"TONUSDT","bids":[["3.1510","296.4"],["3.1500","639.3"],["3.1482","3268.6"],["3.1477","460.6"],["3.1457","0"]],"asks":[["3.1510","0"],["3.1517","1127.3"],["3.1560","1510.0"]],"timestamp":1756900815849,"update_id":50195929,"fetch_time":1756900815895}
{"symbol":"TONUSDT","bids":[["3.1507","122.9"],["3.1506","170.1"],["3.1505","1038.4"],["3.1502","731.4"],["3.1501","1381.7"],["3.1500","599.8"],["3.1499","632.7"],["3.1498","1962.0"],["3.1488","1993.0"],["3.1487","643.8"],["3.1485","2568.4"],["3.1472","2745.2"],["3.1465","183.6"],["3.1458","0"]],"asks":[["3.1511","0"],["3.1512","0"],["3.1513","132.5"],["3.1515","67.1"],["3.1516","2918.3"],["3.1517","1325.9"],["3.1518","6178.4"],["3.1519","4500.2"],["3.1521","454.2"],["3.1523","1288.7"],["3.1525","814.0"],["3.1529","867.0"],["3.1531","1938.3"],["3.1533","694.3"],["3.1536","2890.9"],["3.1539","1747.6"],["3.1543","709.9"],["3.1545","922.1"],["3.1547","1409.7"],["3.1548","2236.0"],["3.1555","586.9"],["3.1556","4606.4"],["3.1560","1224.8"],["3.1561","1096.8"],["3.1562","2083.8"]],"timestamp":1756900815870,"update_id":50195930,"fetch_time":1756900815915}
{"symbol":"TONUSDT","bids":[["3.1510","0"],["3.1507","3.2"],["3.1506","153.5"],["3.1505","1190.0"],["3.1504","159.7"],["3.1503","230.7"],["3.1500","599.8"],["3.1476","1814.0"],["3.1458","2850.4"]],"asks":[["3.1512","262.9"],["3.1514","295.8"],["3.1515","161.7"],["3.1518","7489.4"],["3.1519","4414.9"],["3.1520","1341.8"],["3.1521","253.6"],["3.1543","709.9"],["3.1562","0"]],"timestamp":1756900815949,"update_id":50195934,"fetch_time":1756900815991}
{"symbol":"TONUSDT","bids":[["3.1507","0"],["3.1506","150.3"],["3.1505","30.2"],["3.1504","286.6"],["3.1503","172.4"],["3.1502","493.4"],["3.1500","232.2"],["3.1498","1506.2"],["3.1496","1640.3"],["3.1494","1379.5"],["3.1492","1435.1"],["3.1490","1975.3"],["3.1482","3185.6"],["3.1479","802.5"],["3.1478","1282.0"],["3.1477","301.8"],["3.1476","2357.9"],["3.1473","1529.0"],["3.1470","3169.6"],["3.1467","2559.9"],["3.1457","7992.4"]],"asks":[["3.1510","44.4"],["3.1513","160.9"],["3.1516","3064.5"],["3.1517","1672.9"],["3.1520","1500.8"],["3.1521","535.3"],["3.1524","2003.1"],["3.1545","924.1"],["3.1548","2236.0"],["3.1561","0"]],"timestamp":1756900815970,"update_id":50195935,"fetch_time":1756900816011}
{"symbol":"TONUSDT","bids":[["3.1508","2.7"],["3.1504","288.7"],["3.1457","0"]],"asks":[["3.1513","192.4"],["3.1514","505.0"],["3.1515","818.4"],["3.1516","4426.2"],["3.1517","1609.7"],["3.1518","7426.0"]],"timestamp":1756900816010,"update_id":50195937,"fetch_time":1756900816055}
{"symbol":"TONUSDT","bids":[],"asks":[["3.1517","1296.3"]],"timestamp":1756900816129,"update_id":50195943,"fetch_time":1756900816175}
{"symbol":"TONUSDT","bids":[],"asks":[["3.1515","1131.8"],["3.1538","3074.6"]],"timestamp":1756900816150,"update_id":50195944,"fetch_time":1756900816199}
{"symbol":"TONUSDT","bids":[["3.1505","62.5"],["3.1504","466.5"],["3.1503","475.4"],["3.1497","642.3"]],"asks":[],"timestamp":1756900816170,"update_id":50195945,"fetch_time":1756900816220}
{"symbol":"TONUSDT","bids":[["3.1506","10.3"]],"asks":[],"timestamp":1756900816189,"update_id":50195946,"fetch_time":1756900816235}
{"symbol":"TONUSDT","bids":[["3.1478","1623.0"],["3.1459","1286.3"]],"asks":[],"timestamp":1756900816210,"update_id":50195947,"fetch_time":1756900816259}
{"symbol":"TONUSDT","bids":[],"asks":[["3.1512","441.7"]],"timestamp":1756900816229,"update_id":50195948,"fetch_time":1756900816275}
{"symbol":"TONUSDT","bids":[["3.1505","279.0"]],"asks":[],"timestamp":1756900816269,"update_id":50195949,"fetch_time":1756900816311}
{"symbol":"TONUSDT","bids":[],"asks":[["3.1524","2318.5"]],"timestamp":1756900816429,"update_id":50195953,"fetch_time":1756900816472}
{"symbol":"TONUSDT","bids":[["3.1505","30.8"]],"asks":[],"timestamp":1756900816449,"update_id":50195954,"fetch_time":1756900816496}
{"symbol":"TONUSDT","bids":[["3.1506","226.8"]],"asks":[],"timestamp":1756900816470,"update_id":50195955,"fetch_time":1756900816515}
{"symbol":"TONUSDT","bids":[["3.1488","2184.0"]],"asks":[],"timestamp":1756900816630,"update_id":50195958,"fetch_time":1756900816671}
{"symbol":"TONUSDT","bids":[["3.1476","2166.9"]],"asks":[],"timestamp":1756900816729,"update_id":50195960,"fetch_time":1756900816775}
{"symbol":"TONUSDT","bids":[["3.1485","2950.4"],["3.1478","1432.0"]],"asks":[],"timestamp":1756900816809,"update_id":50195961,"fetch_time":1756900816859}
{"symbol":"TONUSDT","bids":[["3.1506","10.3"]],"asks":[],"timestamp":1756900816889,"update_id":50195963,"fetch_time":1756900816935}
{"symbol":"TONUSDT","bids":[["3.1504","429.2"],["3.1503","81.5"],["3.1502","641.4"],["3.1501","1091.3"],["3.1500","267.9"],["3.1498","1474.3"],["3.1496","1517.4"],["3.1491","285.1"],["3.1475","1333.8"]],"asks":[["3.1509","48.8"],["3.1510","0"],["3.1514","1357.5"],["3.1515","1239.7"],["3.1516","4452.5"],["3.1517","1338.6"],["3.1518","6059.1"],["3.1519","4551.7"],["3.1521","700.8"],["3.1522","1565.2"],["3.1523","974.9"],["3.1526","2497.9"],["3.1529","1429.8"],["3.1532","4102.6"],["3.1535","1320.5"],["3.1538","3714.4"],["3.1541","2261.2"],["3.1544","2519.0"],["3.1545","922.1"]],"timestamp":1756900816909,"update_id":50195964,"fetch_time":1756900816959}
{"symbol":"TONUSDT","bids":[["3.1504","288.7"],["3.1502","704.8"],["3.1486","3603.0"]],"asks":[["3.1511","177.4"],["3.1512","423.4"],["3.1514","1963.1"],["3.1515","1413.9"],["3.1560","0"]],"timestamp":1756900816929,"update_id":50195965,"fetch_time":1756900816980}
{"symbol":"TONUSDT","bids":[],"asks":[["3.1510","180.2"],["3.1513","237.9"],["3.1515","1921.6"],["3.1516","4484.0"],["3.1559","0"]],"timestamp":1756900816949,"update_id":50195966,"fetch_time":1756900817004}
{"symbol":"TONUSDT","bids":[],"asks":[["3.1511","0"],["3.1512","598.1"],["3.1514","2182.5"],["3.1515","1640.1"],["3.1516","4515.7"],["3.1559","915.4"]],"timestamp":1756900816969,"update_id":50195967,"fetch_time":1756900817020}
{"symbol":"TONUSDT","bids":[],"asks":[["3.1510","0"],["3.1513","713.9"],["3.1560","1224.8"]],"timestamp":1756900816989,"update_id":50195968,"fetch_time":1756900817036}
{"symbol":"TONUSDT","bids":[],"asks":[["3.1511","177.4"],["3.1512","847.0"],["3.1514","2309.1"],["3.1515","1296.6"],["3.1516","4547.3"],["3.1560","0"]],"timestamp":1756900817010,"update_id":50195969,"fetch_time":1756900817056}
{"symbol":"TONUSDT","bids":[],"asks":[["3.1510","254.9"],["3.1516","4578.8"],["3.1559","0"]],"timestamp":1756900817029,"update_id":50195970,"fetch_time":1756900817072}
{"symbol":"TONUSDT","bids":[],"asks":[["3.1511","0"],["3.1515","1014.9"],["3.1559","915.4"]],"timestamp":1756900817050,"update_id":50195971,"fetch_time":1756900817096}
{"symbol":"TONUSDT","bids":[],"asks":[["3.1512","1352.9"],["3.1514","2340.8"]],"timestamp":1756900817130,"update_id":50195973,"fetch_time":1756900817172}
{"symbol":"TONUSDT","bids":[],"asks":[["3.1513","703.3"]],"timestamp":1756900817170,"update_id":50195975,"fetch_time":1756900817216}
{"symbol":"TONUSDT","bids":[],"asks":[["3.1512","1447.3"]],"timestamp":1756900817249,"update_id":50195979,"fetch_time":1756900817300}
{"symbol":"TONUSDT","bids":[],"asks":[["3.1513","914.7"],["3.1514","2416.7"]],"timestamp":1756900817269,"update_id":50195980,"fetch_time":1756900817316}
{"symbol":"TONUSDT","bids":[["3.1505","179.3"]],"asks":[],"timestamp":1756900817330,"update_id":50195981,"fetch_time":1756900817376}
{"symbol":"TONUSDT","bids":[],"asks":[["3.1515","1753.5"]],"timestamp":1756900817349,"update_id":50195982,"fetch_time":1756900817395}
{"symbol":"TONUSDT","bids":[],"asks":[["3.1513","1097.4"],["3.1522","2365.2"]],"timestamp":1756900817369,"update_id":50195983,"fetch_time":1756900817416}
{"symbol":"TONUSDT","bids":[],"asks":[["3.1515","1768.6"]],"timestamp":1756900817410,"update_id":50195984,"fetch_time":1756900817451}
{"symbol":"TONUSDT","bids":[],"asks":[["3.1513","1065.7"]],"timestamp":1756900817450,"update_id":50195985,"fetch_time":1756900817495}
{"symbol":"TONUSDT","bids":[],"asks":[["3.1510","286.5"],["3.1511","282.1"],["3.1512","1478.6"],["3.1514","2901.3"],["3.1515","2085.9"],["3.1518","6278.3"],["3.1559","0"]],"timestamp":1756900817489,"update_id":50195987,"fetch_time":1756900817535}
{"symbol":"TONUSDT","bids":[],"asks":[["3.1512","1776.4"],["3.1513","1097.3"]],"timestamp":1756900817509,"update_id":50195988,"fetch_time":1756900817551}
{"symbol":"TONUSDT","bids":[],"asks":[["3.1514","2933.0"]],"timestamp":1756900817550,"update_id":50195989,"fetch_time":1756900817591}
{"symbol":"TONUSDT","bids":[],"asks":[["3.1513","1985.7"],["3.1515","2267.2"]],"timestamp":1756900817589,"update_id":50195990,"fetch_time":1756900817635}
{"symbol":"TONUSDT","bids":[],"asks":[["3.1514","2964.6"]],"timestamp":1756900817609,"update_id":50195991,"fetch_time":1756900817651}
{"symbol":"TONUSDT","bids":[],"asks":[["3.1515","2298.9"]],"timestamp":1756900817629,"update_id":50195992,"fetch_time":1756900817671}
{"symbol":"TONUSDT","bids":[],"asks":[["3.1512","1713.6"],["3.1513","1901.1"],["3.1514","2922.3"],["3.1515","2256.6"],["3.1518","6320.6"]],"timestamp":1756900817689,"update_id":50195993,"fetch_time":1756900817731}
{"symbol":"TONUSDT","bids":[["3.1500","270.7"]],"asks":[],"timestamp":1756900817709,"update_id":50195994,"fetch_time":1756900817751}
{"symbol":"TONUSDT","bids":[],"asks":[["3.1512","1745.2"],["3.1513","1869.4"]],"timestamp":1756900817729,"update_id":50195995,"fetch_time":1756900817771}
{"symbol":"TONUSDT","bids":[],"asks":[["3.1512","1713.6"],["3.1515","2288.3"]],"timestamp":1756900817749,"update_id":50195996,"fetch_time":1756900817799}
{"symbol":"TONUSDT","bids":[],"asks":[["3.1509","80.4"],["3.1512","1745.1"]],"timestamp":1756900817929,"update_id":50195997,"fetch_time":1756900817971}
{"symbol":"TONUSDT","bids":[],"asks":[["3.1514","2964.6"],["3.1515","2330.6"],["3.1538","3666.8"]],"timestamp":1756900817950,"update_id":50195998,"fetch_time":1756900817999}
{"symbol":"TONUSDT","bids":[["3.1492","1435.1"]],"asks":[],"timestamp":1756900818050,"update_id":50195999,"fetch_time":1756900818092}
{"symbol":"TONUSDT","bids":[],"asks":[["3.1516","4578.8"],["3.1517","1338.6"]],"timestamp":1756900818250,"update_id":50196001,"fetch_time":1756900818296}
{"symbol":"TONUSDT","bids":[["3.1501","1094.1"]],"asks":[],"timestamp":1756900818329,"update_id":50196002,"fetch_time":1756900818372}
{"symbol":"TONUSDT","bids":[],"asks":[["3.1509","81.6"]],"timestamp":1756900818449,"update_id":50196003,"fetch_time":1756900818496}
{"symbol":"TONUSDT","bids":[],"asks":[["3.1513","1911.7"]],"timestamp":1756900818470,"update_id":50196004,"fetch_time":1756900818512}
{"symbol":"TONUSDT","bids":[],"asks":[["3.1512","1787.4"]],"timestamp":1756900818630,"update_id":50196007,"fetch_time":1756900818676}
{"symbol":"TONUSDT","bids":[],"asks":[["3.1513","1975.1"]],"timestamp":1756900818649,"update_id":50196008,"fetch_time":1756900818691}
{"symbol":"TONUSDT","bids":[],"asks":[["3.1513","2109.7"]],"timestamp":1756900818689,"update_id":50196010,"fetch_time":1756900818735}
{"symbol":"TONUSDT","bids":[],"asks":[["3.1513","2152.0"]],"timestamp":1756900818730,"update_id":50196011,"fetch_time":1756900818776}
{"symbol":"TONUSDT","bids":[],"asks":[["3.1511","304.2"],["3.1512","2126.6"]],"timestamp":1756900818750,"update_id":50196012,"fetch_time":1756900818792}
{"symbol":"TONUSDT","bids":[],"asks":[["3.1510","484.0"]],"timestamp":1756900818769,"update_id":50196013,"fetch_time":1756900818812}
{"symbol":"TONUSDT","bids":[],"asks":[["3.1510","31.6"],["3.1512","1002.4"],["3.1513","2149.6"],["3.1514","1935.7"],["3.1516","2336.2"]],"timestamp":1756900818869,"update_id":50196014,"fetch_time":1756900818911}
{"symbol":"TONUSDT","bids":[],"asks":[["3.1514","1893.4"]],"timestamp":1756900818970,"update_id":50196019,"fetch_time":1756900819015}
{"symbol":"TONUSDT","bids":[["3.1503","311.5"]],"asks":[],"timestamp":1756900818990,"update_id":50196020,"fetch_time":1756900819035}
{"symbol":"TONUSDT","bids":[["3.1504","497.1"],["3.1503","123.8"],["3.1502","496.2"]],"asks":[],"timestamp":1756900819009,"update_id":50196021,"fetch_time":1756900819052}
{"symbol":"TONUSDT","bids":[],"asks":[["3.1512","1586.9"]],"timestamp":1756900819050,"update_id":50196023,"fetch_time":1756900819096}
{"symbol":"TONUSDT","bids":[["3.1503","332.6"],["3.1502","453.9"],["3.1501","1094.1"],["3.1500","228.4"]],"asks":[],"timestamp":1756900819070,"update_id":50196024,"fetch_time":1756900819123}
{"symbol":"TONUSDT","bids":[],"asks":[["3.1513","1115.6"]],"timestamp":1756900819089,"update_id":50196025,"fetch_time":1756900819131}
{"symbol":"TONUSDT","bids":[],"asks":[["3.1544","2706.6"],["3.1548","1880.2"]],"timestamp":1756900819110,"update_id":50196026,"fetch_time":1756900819155}
{"symbol":"TONUSDT","bids":[],"asks":[["3.1546","1660.0"]],"timestamp":1756900819129,"update_id":50196027,"fetch_time":1756900819176}
{"symbol":"TONUSDT","bids":[],"asks":[["3.1510","385.7"],["3.1514","3187.9"]],"timestamp":1756900819229,"update_id":50196028,"fetch_time":1756900819275}
{"symbol":"TONUSDT","bids":[],"asks":[["3.1510","31.6"],["3.1512","898.1"],["3.1513","1113.2"],["3.1514","1893.4"],["3.1516","2291.5"],["3.1544","2519.0"],["3.1551","1451.1"]],"timestamp":1756900819250,"update_id":50196029,"fetch_time":1756900819299}
{"symbol":"TONUSDT","bids":[["3.1503","374.9"],["3.1502","496.2"],["3.1501","1136.4"]],"asks":[],"timestamp":1756900819269,"update_id":50196030,"fetch_time":1756900819311}
{"symbol":"TONUSDT","bids":[],"asks":[["3.1512","866.6"],["3.1516","3147.3"]],"timestamp":1756900819329,"update_id":50196032,"fetch_time":1756900819371}
{"symbol":"TONUSDT","bids":[],"asks":[["3.1509","30.0"],["3.1516","3935.2"]],"timestamp":1756900819350,"update_id":50196033,"fetch_time":1756900819396}
{"symbol":"TONUSDT","bids":[],"asks":[["3.1509","23.7"],["3.1514","2809.9"]],"timestamp":1756900819370,"update_id":50196034,"fetch_time":1756900819411}
{"symbol":"TONUSDT","bids":[],"asks":[["3.1512","1367.5"],["3.1522","1565.2"]],"timestamp":1756900819390,"update_id":50196035,"fetch_time":1756900819435}
{"symbol":"TONUSDT","bids":[],"asks":[["3.1516","3937.6"],["3.1517","1296.3"],["3.1520","1835.5"]],"timestamp":1756900819410,"update_id":50196036,"fetch_time":1756900819459}
{"symbol":"TONUSDT","bids":[],"asks":[["3.1510","376.2"]],"timestamp":1756900819429,"update_id":50196037,"fetch_time":1756900819476}
{"symbol":"TONUSDT","bids":[],"asks":[["3.1512","1336.2"]],"timestamp":1756900819590,"update_id":50196039,"fetch_time":1756900819635}
{"symbol":"TONUSDT","bids":[["3.1504","314.0"],["3.1503","332.6"],["3.1495","1418.6"]],"asks":[["3.1510","0"],["3.1514","2851.5"],["3.1559","1163.7"]],"timestamp":1756900819609,"update_id":50196040,"fetch_time":1756900819663}
{"symbol":"TONUSDT","bids":[["3.1496","1693.6"]],"asks":[["3.1511","0"],["3.1512","1168.6"],["3.1560","1511.3"]],"timestamp":1756900819629,"update_id":50196041,"fetch_time":1756900819679}
{"symbol":"TONUSDT","bids":[["3.1503","374.2"]],"asks":[["3.1511","200.3"],["3.1560","0"]],"timestamp":1756900819650,"update_id":50196042,"fetch_time":1756900819695}
{"symbol":"TONUSDT","bids":[["3.1504","355.6"]],"asks":[],"timestamp":1756900819670,"update_id":50196043,"fetch_time":1756900819711}
{"symbol":"TONUSDT","bids":[],"asks":[["3.1540","2262.4"],["3.1551","6068.0"]],"timestamp":1756900819690,"update_id":50196044,"fetch_time":1756900819739}
{"symbol":"TONUSDT","bids":[],"asks":[["3.1538","2409.5"]],"timestamp":1756900819710,"update_id":50196045,"fetch_time":1756900819755}
{"symbol":"TONUSDT","bids":[["3.1503","332.6"],["3.1502","453.9"],["3.1501","1094.1"],["3.1500","228.4"]],"asks":[],"timestamp":1756900819770,"update_id":50196047,"fetch_time":1756900819815}
{"symbol":"TONUSDT","bids":[],"asks":[["3.1513","1115.6"]],"timestamp":1756900819790,"update_id":50196048,"fetch_time":1756900819840}
{"symbol":"TONUSDT","bids":[],"asks":[["3.1515","1999.2"]],"timestamp":1756900819810,"update_id":50196049,"fetch_time":1756900819851}
{"symbol":"TONUSDT","bids":[],"asks":[["3.1513","1157.2"]],"timestamp":1756900819829,"update_id":50196050,"fetch_time":1756900819871}
{"symbol":"TONUSDT","bids":[["3.1502","495.5"],["3.1501","1135.7"],["3.1458","2864.4"]],"asks":[["3.1511","0"],["3.1560","1511.3"]],"timestamp":1756900820030,"update_id":50196052,"fetch_time":1756900820075}
{"symbol":"TONUSDT","bids":[],"asks":[["3.1512","1137.0"]],"timestamp":1756900820329,"update_id":50196055,"fetch_time":1756900820372}
{"symbol":"TONUSDT","bids":[],"asks":[["3.1517","1337.9"]],"timestamp":1756900820470,"update_id":50196056,"fetch_time":1756900820516}
{"symbol":"TONUSDT","bids":[],"asks":[["3.1515","1894.2"]],"timestamp":1756900820490,"update_id":50196057,"fetch_time":1756900820532}
{"symbol":"TONUSDT","bids":[["3.1507","219.4"],["3.1506","451.4"],["3.1505","50.3"],["3.1484","2068.8"],["3.1480","800.2"],["3.1479","302.6"],["3.1478","1092.8"],["3.1472","1653.8"],["3.1469","507.5"],["3.1468","9385.3"],["3.1464","1531.2"],["3.1461","897.3"],["3.1458","0"]],"asks":[["3.1513","957.1"],["3.1514","1798.9"],["3.1516","2361.3"],["3.1518","4605.3"],["3.1519","5050.7"],["3.1521","623.9"],["3.1526","3399.4"],["3.1534","2121.0"],["3.1542","4348.7"]],"timestamp":1756900820750,"update_id":50196061,"fetch_time":1756900820791}
{"symbol":"TONUSDT","bids":[],"asks":[["3.1512","3.2"],["3.1514","577.7"],["3.1516","1210.1"],["3.1517","429.7"],["3.1520","3763.0"],["3.1543","709.9"],["3.1548","3212.8"]],"timestamp":1756900820869,"update_id":50196067,"fetch_time":1756900820916}
{"symbol":"TONUSDT","bids":[],"asks":[["3.1513","34.8"],["3.1519","2459.8"]],"timestamp":1756900820889,"update_id":50196068,"fetch_time":1756900820940}
{"symbol":"TONUSDT","bids":[],"asks":[["3.1519","2741.8"],["3.1521","2681.5"]],"timestamp":1756900820909,"update_id":50196069,"fetch_time":1756900820955}
{"symbol":"TONUSDT","bids":[],"asks":[["3.1531","1525.7"],["3.1533","1646.2"],["3.1542","4348.7"],["3.1551","7034.3"]],"timestamp":1756900820930,"update_id":50196070,"fetch_time":1756900820972}
{"symbol":"TONUSDT","bids":[],"asks":[["3.1539","1002.0"],["3.1549","470.9"]],"timestamp":1756900820969,"update_id":50196072,"fetch_time":1756900821016}
{"symbol":"TONUSDT","bids":[["3.1512","29.2"],["3.1511","160.1"],["3.1509","145.6"],["3.1508","490.9"],["3.1507","235.8"],["3.1506","639.2"],["3.1505","114.2"],["3.1500","595.9"],["3.1498","2116.9"],["3.1497","800.8"],["3.1495","1736.9"],["3.1461","0"],["3.1460","0"],["3.1459","0"]],"asks":[["3.1509","0"],["3.1512","0"],["3.1513","3.2"],["3.1514","3.2"],["3.1515","26.4"],["3.1516","1146.8"],["3.1517","289.7"],["3.1518","1654.9"],["3.1519","102.6"],["3.1520","2852.3"],["3.1521","183.4"],["3.1522","1753.0"],["3.1523","335.8"],["3.1524","4018.3"],["3.1525","2557.0"],["3.1526","2772.4"],["3.1528","1462.9"],["3.1544","2931.0"],["3.1547","1129.6"],["3.1561","1430.6"],["3.1562","2875.7"]],"timestamp":1756900820989,"update_id":50196073,"fetch_time":1756900821032}
{"symbol":"TONUSDT","bids":[["3.1513","20.0"],["3.1511","0"],["3.1508","627.7"],["3.1507","402.8"],["3.1506","628.2"],["3.1505","809.0"],["3.1504","1313.8"],["3.1503","374.2"],["3.1502","777.6"],["3.1501","1390.0"],["3.1495","936.9"],["3.1491","66.7"],["3.1484","1462.1"],["3.1469","463.3"]],"asks":[["3.1513","0"],["3.1514","0"],["3.1515","200.6"],["3.1516","538.4"],["3.1518","454.6"],["3.1520","1659.6"],["3.1521","371.4"],["3.1523","465.5"],["3.1526","2717.2"],["3.1530","2028.4"],["3.1531","1415.3"],["3.1535","1483.2"],["3.1536","1880.4"],["3.1538","832.1"],["3.1539","1057.2"],["3.1544","3085.6"],["3.1547","1127.6"],["3.1549","472.9"],["3.1550","4045.4"],["3.1552","2016.7"],["3.1563","1147.9"],["3.1564","1693.1"]],"timestamp":1756900821009,"update_id":50196074,"fetch_time":1756900821063}
{"symbol":"TONUSDT","bids":[["3.1512","0"],["3.1509","185.7"],["3.1508","504.9"],["3.1507","507.8"],["3.1506","834.6"],["3.1504","1272.2"],["3.1503","332.6"],["3.1489","1815.8"],["3.1488","2239.2"],["3.1487","922.4"],["3.1483","1463.0"],["3.1480","1025.9"],["3.1478","542.0"],["3.1477","246.6"],["3.1476","1376.8"],["3.1474","1441.8"],["3.1461","897.3"]],"asks":[["3.1515","23.2"],["3.1516","253.9"],["3.1518","423.0"],["3.1521","403.0"],["3.1522","2136.3"],["3.1524","3954.8"],["3.1531","1564.5"],["3.1535","793.6"],["3.1537","2882.5"],["3.1542","4853.8"],["3.1545","1972.6"],["3.1548","2173.3"],["3.1549","470.9"],["3.1550","4047.4"],["3.1551","6068.0"],["3.1553","3.2"]],"timestamp":1756900821029,"update_id":50196075,"fetch_time":1756900821076}
{"symbol":"TONUSDT","bids":[["3.1514","20.0"],["3.1513","0"],["3.1511","2.4"],["3.1510","21.0"],["3.1509","210.9"],["3.1508","545.8"],["3.1507","736.5"],["3.1506","861.0"],["3.1504","1246.9"],["3.1503","427.0"],["3.1502","736.0"],["3.1493","287.4"],["3.1492","2459.3"],["3.1490","2541.8"],["3.1482","1274.6"],["3.1480","873.6"],["3.1462","0"],["3.1461","0"]],"asks":[["3.1515","0"],["3.1516","2.4"],["3.1517","31.0"],["3.1518","98.3"],["3.1520","1123.3"],["3.1521","654.2"],["3.1522","2207.4"],["3.1529","708.4"],["3.1531","1817.8"],["3.1534","930.2"],["3.1538","227.7"],["3.1550","4271.4"],["3.1551","5714.2"],["3.1556","2464.4"],["3.1558","1972.9"],["3.1560","2778.5"],["3.1565","710.9"]],"timestamp":1756900821049,"update_id":50196076,"fetch_time":1756900821091}
{"symbol":"TONUSDT","bids":[["3.1515","20.0"],["3.1511","5.6"],["3.1510","198.4"],["3.1508","745.5"],["3.1506","837.8"],["3.1505","836.2"],["3.1489","1967.1"],["3.1463","0"]],"asks":[["3.1517","30.9"],["3.1519","261.1"],["3.1520","1186.5"],["3.1521","2208.6"],["3.1522","2302.4"],["3.1525","2620.9"],["3.1530","1973.2"],["3.1532","1116.1"],["3.1533","694.3"],["3.1537","3834.3"],["3.1538","415.6"],["3.1540","1753.1"],["3.1542","4909.0"],["3.1547","1729.6"]],"timestamp":1756900821070,"update_id":50196077,"fetch_time":1756900821111}
{"symbol":"TONUSDT","bids":[["3.1514","0"],["3.1510","21.0"],["3.1509","398.7"],["3.1508","808.9"],["3.1463","479.6"]],"asks":[["3.1520","1841.2"],["3.1521","2335.4"],["3.1522","2644.0"]],"timestamp":1756900821089,"update_id":50196078,"fetch_time":1756900821139}
{"symbol":"TONUSDT","bids":[],"asks":[["3.1518","3.2"],["3.1519","292.7"],["3.1520","1507.9"],["3.1521","2648.9"],["3.1547","1365.2"],["3.1551","6073.9"]],"timestamp":1756900821109,"update_id":50196079,"fetch_time":1756900821155}
{"symbol":"TONUSDT","bids":[["3.1515","15.0"],["3.1512","15.5"],["3.1507","515.7"],["3.1506","638.9"],["3.1505","792.0"],["3.1502","799.4"],["3.1500","529.3"],["3.1494","2075.1"],["3.1491","3.2"],["3.1468","8774.8"],["3.1463","0"]],"asks":[["3.1518","3.2"],["3.1519","324.7"],["3.1520","1571.3"],["3.1522","2448.5"],["3.1524","4021.6"],["3.1527","715.4"],["3.1528","1526.4"],["3.1531","1564.5"],["3.1532","1034.3"],["3.1533","940.2"],["3.1537","2455.2"],["3.1542","5383.4"],["3.1545","1438.7"],["3.1547","857.0"],["3.1550","5237.7"],["3.1553","1042.7"],["3.1562","2874.1"]],"timestamp":1756900821150,"update_id":50196081,"fetch_time":1756900821192}
{"symbol":"TONUSDT","bids":[["3.1509","1039.0"]],"asks":[],"timestamp":1756900821189,"update_id":50196083,"fetch_time":1756900821231}
{"symbol":"TONUSDT","bids":[["3.1510","442.1"],["3.1503","606.8"]],"asks":[],"timestamp":1756900821209,"update_id":50196084,"fetch_time":1756900821251}
{"symbol":"TONUSDT","bids":[],"asks":[["3.1516","0"],["3.1517","122.9"],["3.1521","1842.7"],["3.1522","2607.1"],["3.1523","215.1"],["3.1524","4807.4"],["3.1527","713.6"],["3.1547","858.8"],["3.1551","6071.9"],["3.1552","2018.7"],["3.1566","6808.8"]],"timestamp":1756900821249,"update_id":50196086,"fetch_time":1756900821295}
{"symbol":"TONUSDT","bids":[["3.1515","0"],["3.1463","479.6"]],"asks":[["3.1522","2889.0"],["3.1561","1430.6"],["3.1562","4141.2"]],"timestamp":1756900821269,"update_id":50196087,"fetch_time":1756900821315}
{"symbol":"TONUSDT","bids":[["3.1512","15.5"],["3.1509","65.3"],["3.1507","703.5"]],"asks":[["3.1517","262.9"],["3.1518","0"],["3.1520","1668.8"],["3.1522","3264.8"],["3.1538","766.0"],["3.1542","4403.9"],["3.1547","1279.4"],["3.1548","2618.0"],["3.1550","4271.4"],["3.1552","2016.7"],["3.1553","995.1"],["3.1567","10061.8"]],"timestamp":1756900821289,"update_id":50196088,"fetch_time":1756900821335}
{"symbol":"TONUSDT","bids":[["3.1512","0"],["3.1511","25.6"],["3.1510","21.0"],["3.1509","43.3"],["3.1508","504.9"],["3.1507","484.1"],["3.1506","678.5"],["3.1505","831.6"],["3.1466","1521.4"],["3.1462","682.2"]],"asks":[["3.1516","28.8"],["3.1518","317.3"],["3.1521","2124.6"],["3.1529","927.5"],["3.1550","4701.6"],["3.1553","3.2"],["3.1554","2023.1"],["3.1558","3240.1"],["3.1566","0"],["3.1567","0"]],"timestamp":1756900821310,"update_id":50196089,"fetch_time":1756900821351}
{"symbol":"TONUSDT","bids":[],"asks":[["3.1522","2982.9"]],"timestamp":1756900821410,"update_id":50196093,"fetch_time":1756900821452}
{"symbol":"TONUSDT","bids":[],"asks":[["3.1528","2270.4"]],"timestamp":1756900821550,"update_id":50196098,"fetch_time":1756900821596}
{"symbol":"TONUSDT","bids":[],"asks":[["3.1522","2324.1"]],"timestamp":1756900821569,"update_id":50196099,"fetch_time":1756900821612}
{"symbol":"TONUSDT","bids":[],"asks":[["3.1520","1637.1"],["3.1551","6350.9"]],"timestamp":1756900821690,"update_id":50196100,"fetch_time":1756900821732}
{"symbol":"TONUSDT","bids":[["3.1512","20.0"],["3.1462","0"]],"asks":[],"timestamp":1756900821769,"update_id":50196103,"fetch_time":1756900821811}
{"symbol":"TONUSDT","bids":[["3.1507","359.6"]],"asks":[],"timestamp":1756900821790,"update_id":50196104,"fetch_time":1756900821832}
{"symbol":"TONUSDT","bids":[["3.1507","547.4"]],"asks":[],"timestamp":1756900821810,"update_id":50196105,"fetch_time":1756900821861}
{"symbol":"TONUSDT","bids":[["3.1511","33.2"],["3.1506","678.5"]],"asks":[],"timestamp":1756900821849,"update_id":50196106,"fetch_time":1756900821892}
{"symbol":"TONUSDT","bids":[],"asks":[["3.1531","1567.8"]],"timestamp":1756900822089,"update_id":50196109,"fetch_time":1756900822131}
{"symbol":"TONUSDT","bids":[],"asks":[["3.1519","261.1"],["3.1520","1510.6"],["3.1521","2718.8"]],"timestamp":1756900822109,"update_id":50196110,"fetch_time":1756900822156}
{"symbol":"TONUSDT","bids":[],"asks":[["3.1526","1875.7"]],"timestamp":1756900822189,"update_id":50196111,"fetch_time":1756900822236}
{"symbol":"TONUSDT","bids":[["3.1512","0"],["3.1511","0"],["3.1504","1559.9"],["3.1462","682.2"],["3.1461","897.3"]],"asks":[],"timestamp":1756900822230,"update_id":50196112,"fetch_time":1756900822272}
{"symbol":"TONUSDT","bids":[["3.1508","408.3"],["3.1492","1453.3"]],"asks":[],"timestamp":1756900822270,"update_id":50196114,"fetch_time":1756900822316}
{"symbol":"TONUSDT","bids":[],"asks":[["3.1518","195.2"],["3.1521","2158.3"],["3.1522","2197.5"]],"timestamp":1756900822329,"update_id":50196116,"fetch_time":1756900822376}
{"symbol":"TONUSDT","bids":[],"asks":[["3.1518","226.9"]],"timestamp":1756900822369,"update_id":50196117,"fetch_time":1756900822416}
{"symbol":"TONUSDT","bids":[["3.1517","11.5"],["3.1515","66.4"],["3.1514","15.4"],["3.1513","24.4"],["3.1512","4.4"],["3.1511","122.9"],["3.1510","248.6"],["3.1509","814.0"],["3.1507","218.3"],["3.1506","1075.6"],["3.1505","1043.2"],["3.1504","1521.8"],["3.1503","1007.8"],["3.1501","1812.5"],["3.1499","814.8"],["3.1498","2682.2"],["3.1497","1098.0"],["3.1493","894.8"],["3.1490","2007.9"],["3.1489","2569.2"],["3.1485","3670.7"],["3.1481","2369.4"],["3.1479","341.4"],["3.1476","1376.8"],["3.1472","1669.6"],["3.1468","9323.6"],["3.1466","0"],["3.1465","0"],["3.1464","0"],["3.1463","0"],["3.1462","0"],["3.1461","0"]],"asks":[["3.1516","0"],["3.1517","0"],["3.1518","0"],["3.1519","0"],["3.1520","909.6"],["3.1521","34.3"],["3.1522","1418.7"],["3.1523","896.0"],["3.1524","4104.6"],["3.1525","2252.6"],["3.1526","2447.4"],["3.1528","1968.8"],["3.1529","1357.8"],["3.1549","755.3"],["3.1551","6348.9"],["3.1555","1235.0"],["3.1558","2670.5"],["3.1566","6300.6"],["3.1567","10061.8"],["3.1568","2524.3"],["3.1569","964.9"]],"timestamp":1756900822530,"update_id":50196118,"fetch_time":1756900822576}
{"symbol":"TONUSDT","bids":[["3.1518","20.0"],["3.1514","17.8"],["3.1513","4.4"],["3.1512","369.5"],["3.1511","1007.6"],["3.1510","615.3"],["3.1508","651.5"],["3.1507","500.3"],["3.1505","979.8"],["3.1498","1882.2"],["3.1496","1917.9"],["3.1495","876.0"],["3.1494","1506.9"],["3.1491","642.3"],["3.1486","3696.9"],["3.1485","3640.7"],["3.1482","1290.4"],["3.1479","402.2"],["3.1478","557.8"],["3.1470","2465.1"],["3.1467","0"]],"asks":[["3.1520","0"],["3.1522","1228.3"],["3.1523","256.9"],["3.1524","4199.6"],["3.1525","3646.1"],["3.1526","2666.8"],["3.1527","748.9"],["3.1529","1401.0"],["3.1530","3508.2"],["3.1532","1529.9"],["3.1537","1413.1"],["3.1540","2508.1"],["3.1556","2466.4"],["3.1566","7145.3"],["3.1570","884.9"]],"timestamp":1756900822550,"update_id":50196119,"fetch_time":1756900822596}
{"symbol":"TONUSDT","bids":[["3.1514","5.6"],["3.1513","187.7"],["3.1512","628.0"],["3.1510","430.1"],["3.1509","662.6"],["3.1508","609.0"],["3.1507","285.2"],["3.1506","1036.0"],["3.1501","1770.2"],["3.1496","2108.9"],["3.1486","4648.5"],["3.1483","511.1"]],"asks":[["3.1520","34.4"],["3.1521","157.1"],["3.1522","2049.2"],["3.1524","5531.3"],["3.1525","3928.1"],["3.1526","4365.0"],["3.1527","886.7"],["3.1528","2298.5"],["3.1535","738.4"],["3.1541","1938.1"],["3.1551","6071.9"],["3.1556","2464.4"],["3.1560","2019.5"],["3.1570","0"]],"timestamp":1756900822610,"update_id":50196122,"fetch_time":1756900822660}
{"symbol":"TONUSDT","bids":[["3.1518","0"],["3.1514","137.2"],["3.1513","3.2"],["3.1512","631.2"],["3.1510","473.3"],["3.1509","705.8"],["3.1508","830.0"],["3.1502","932.3"],["3.1467","1560.4"]],"asks":[["3.1519","28.8"],["3.1523","414.2"],["3.1524","6443.2"],["3.1525","4035.2"],["3.1530","3508.2"],["3.1534","930.2"],["3.1542","4949.1"],["3.1546","2589.8"],["3.1554","2025.1"],["3.1569","0"]],"timestamp":1756900822630,"update_id":50196123,"fetch_time":1756900822671}
{"symbol":"TONUSDT","bids":[["3.1514","5.6"],["3.1511","1187.7"],["3.1510","409.9"],["3.1505","792.0"],["3.1488","2409.2"]],"asks":[["3.1520","0"],["3.1521","191.5"],["3.1522","2462.7"],["3.1524","6818.9"],["3.1525","4215.3"],["3.1569","964.9"]],"timestamp":1756900822649,"update_id":50196124,"fetch_time":1756900822696}
{"symbol":"TONUSDT","bids":[],"asks":[["3.1526","3425.7"]],"timestamp":1756900822770,"update_id":50196130,"fetch_time":1756900822820}
{"symbol":"TONUSDT","bids":[],"asks":[["3.1538","1085.1"],["3.1542","5630.3"],["3.1547","858.8"],["3.1552","2085.5"]],"timestamp":1756900822810,"update_id":50196131,"fetch_time":1756900822857}
{"symbol":"TONUSDT","bids":[],"asks":[["3.1541","1405.4"],["3.1542","4949.1"],["3.1549","1250.5"],["3.1552","1274.0"]],"timestamp":1756900822949,"update_id":50196132,"fetch_time":1756900822992}
{"symbol":"TONUSDT","bids":[],"asks":[["3.1521","191.5"],["3.1548","2958.9"]],"timestamp":1756900822969,"update_id":50196133,"fetch_time":1756900823016}
{"symbol":"TONUSDT","bids":[["3.1509","705.8"],["3.1498","2280.4"]],"asks":[],"timestamp":1756900823129,"update_id":50196137,"fetch_time":1756900823176}
{"symbol":"TONUSDT","bids":[["3.1494","3376.9"],["3.1493","2764.8"],["3.1486","2587.5"],["3.1485","1770.7"]],"asks":[],"timestamp":1756900823150,"update_id":50196138,"fetch_time":1756900823200}
{"symbol":"TONUSDT","bids":[["3.1494","4053.9"]],"asks":[],"timestamp":1756900823190,"update_id":50196140,"fetch_time":1756900823236}
{"symbol":"TONUSDT","bids":[["3.1496","2502.3"]],"asks":[],"timestamp":1756900823210,"update_id":50196141,"fetch_time":1756900823252}
{"symbol":"TONUSDT","bids":[["3.1487","728.1"]],"asks":[],"timestamp":1756900823249,"update_id":50196143,"fetch_time":1756900823292}
{"symbol":"TONUSDT","bids":[],"asks":[["3.1524","6773.2"]],"timestamp":1756900823270,"update_id":50196144,"fetch_time":1756900823311}
{"symbol":"TONUSDT","bids":[],"asks":[["3.1522","2580.7"]],"timestamp":1756900823430,"update_id":50196146,"fetch_time":1756900823476}
{"symbol":"TONUSDT","bids":[],"asks":[["3.1521","349.6"]],"timestamp":1756900823450,"update_id":50196147,"fetch_time":1756900823497}
{"symbol":"TONUSDT","bids":[["3.1517","0"],["3.1515","0"],["3.1514","0"],["3.1513","0"],["3.1512","376.9"],["3.1511","950.3"],["3.1509","3.2"],["3.1508","370.3"],["3.1507","38.7"],["3.1506","778.1"],["3.1501","1347.7"],["3.1497","833.3"],["3.1493","2220.9"],["3.1489","1937.1"],["3.1485","1050.4"],["3.1481","1560.9"],["3.1466","282.1"],["3.1465","660.4"],["3.1464","1531.2"],["3.1463","479.6"]],"asks":[["3.1518","218.1"],["3.1520","43.8"],["3.1522","2623.9"],["3.1529","1559.7"],["3.1542","5043.9"],["3.1568","0"],["3.1569","0"]],"timestamp":1756900823470,"update_id":50196148,"fetch_time":1756900823513}
{"symbol":"TONUSDT","bids":[["3.1512","0"],["3.1511","122.9"],["3.1492","1389.8"],["3.1462","942.4"]],"asks":[["3.1518","749.5"],["3.1519","824.9"],["3.1520","813.2"],["3.1521","2817.6"],["3.1523","1565.2"],["3.1524","5638.3"],["3.1528","2541.8"]],"timestamp":1756900823510,"update_id":50196150,"fetch_time":1756900823553}
{"symbol":"TONUSDT","bids":[["3.1510","0"],["3.1508","146.9"],["3.1507","38.7"],["3.1506","193.6"],["3.1505","814.6"],["3.1501","1128.3"],["3.1461","2168.2"]],"asks":[["3.1516","268.2"],["3.1517","203.8"],["3.1518","654.3"],["3.1519","884.9"],["3.1520","1886.7"],["3.1521","2854.5"],["3.1522","1823.2"],["3.1523","1795.2"],["3.1524","5800.4"],["3.1525","2765.5"],["3.1529","1658.7"],["3.1533","1353.9"],["3.1537","1939.6"],["3.1540","2552.3"],["3.1544","3713.7"],["3.1546","2062.9"],["3.1548","2319.1"],["3.1549","1206.3"],["3.1550","3948.9"],["3.1552","1276.0"],["3.1553","367.1"],["3.1566","0"],["3.1567","0"]],"timestamp":1756900823529,"update_id":50196151,"fetch_time":1756900823576}
{"symbol":"TONUSDT","bids":[["3.1505","771.3"]],"asks":[["3.1514","28.8"],["3.1515","20.0"],["3.1517","140.0"],["3.1518","958.2"],["3.1519","887.3"],["3.1520","2106.3"],["3.1521","3316.6"],["3.1522","2270.8"],["3.1524","5298.9"],["3.1546","1660.0"],["3.1550","3950.9"],["3.1552","1274.0"],["3.1564","0"],["3.1565","0"]],"timestamp":1756900823549,"update_id":50196152,"fetch_time":1756900823592}
{"symbol":"TONUSDT","bids":[["3.1508","6.9"],["3.1506","444.7"],["3.1505","725.7"],["3.1504","1151.2"],["3.1502","346.1"],["3.1500","608.6"],["3.1497","1024.3"]],"asks":[["3.1515","0"],["3.1516","122.9"],["3.1520","2580.5"],["3.1521","3359.9"],["3.1524","5111.2"],["3.1527","1362.6"],["3.1549","1208.3"],["3.1550","3948.9"],["3.1564","1693.1"]],"timestamp":1756900823569,"update_id":50196153,"fetch_time":1756900823617}
{"symbol":"TONUSDT","bids":[["3.1490","1928.7"],["3.1484","1650.0"]],"asks":[["3.1515","11.4"],["3.1516","303.6"],["3.1519","1381.3"],["3.1520","3826.8"],["3.1523","1975.3"],["3.1527","1117.5"],["3.1564","0"]],"timestamp":1756900823609,"update_id":50196155,"fetch_time":1756900823656}
{"symbol":"TONUSDT","bids":[["3.1505","768.9"],["3.1504","1488.2"],["3.1503","1051.0"],["3.1494","4142.3"],["3.1479","417.6"]],"asks":[["3.1515","0"],["3.1516","443.3"],["3.1517","143.2"],["3.1518","1591.9"],["3.1519","1266.3"],["3.1520","3332.9"],["3.1521","2380.6"],["3.1523","1317.6"],["3.1525","2180.6"],["3.1529","1357.8"],["3.1533","694.3"],["3.1537","1413.1"],["3.1540","2364.1"],["3.1542","4742.8"],["3.1564","1693.1"]],"timestamp":1756900823669,"update_id":50196158,"fetch_time":1756900823717}
{"symbol":"TONUSDT","bids":[["3.1511","0"],["3.1507","531.5"],["3.1506","487.9"],["3.1460","1679.2"]],"asks":[["3.1523","1035.8"],["3.1525","2440.9"],["3.1528","2729.9"],["3.1532","1907.7"],["3.1536","2922.9"],["3.1540","2890.6"],["3.1544","4353.0"],["3.1548","3071.2"],["3.1561","2697.7"],["3.1562","2082.2"]],"timestamp":1756900823689,"update_id":50196159,"fetch_time":1756900823736}
{"symbol":"TONUSDT","bids":[["3.1510","78.3"],["3.1509","20.0"],["3.1508","540.3"],["3.1507","549.8"],["3.1506","13.5"],["3.1505","5.6"],["3.1504","962.5"],["3.1503","976.8"],["3.1502","490.8"],["3.1498","2121.9"],["3.1494","4300.8"],["3.1491","285.3"],["3.1486","1321.0"],["3.1483","1689.3"],["3.1479","699.7"],["3.1460","0"]],"asks":[["3.1513","28.8"],["3.1514","31.6"],["3.1516","609.7"],["3.1517","1185.1"],["3.1518","3010.2"],["3.1519","1095.1"],["3.1520","2712.8"],["3.1521","358.2"],["3.1522","2395.0"],["3.1523","992.5"],["3.1524","4822.8"],["3.1531","2747.9"],["3.1536","1971.4"],["3.1546","1970.4"],["3.1550","3518.7"],["3.1551","6686.9"],["3.1564","0"]],"timestamp":1756900823709,"update_id":50196160,"fetch_time":1756900823760}
{"symbol":"TONUSDT","bids":[["3.1509","0"],["3.1507","391.2"],["3.1492","1282.5"],["3.1488","1555.5"],["3.1487","537.1"],["3.1484","1912.1"],["3.1475","1125.7"],["3.1460","1679.2"]],"asks":[["3.1515","131.8"],["3.1516","1278.4"],["3.1518","3041.8"],["3.1520","1737.6"],["3.1521","637.3"],["3.1522","2638.2"],["3.1548","2923.1"],["3.1549","1206.3"],["3.1563","0"]],"timestamp":1756900823729,"update_id":50196161,"fetch_time":1756900823784}
{"symbol":"TONUSDT","bids":[["3.1509","162.1"],["3.1503","1020.0"],["3.1502","577.3"],["3.1499","829.6"],["3.1460","0"]],"asks":[["3.1515","131.8"],["3.1516","908.1"],["3.1517","1126.2"],["3.1518","2676.1"],["3.1520","1455.8"],["3.1535","1285.6"],["3.1541","1015.0"],["3.1548","3569.5"],["3.1549","711.1"]],"timestamp":1756900823789,"update_id":50196164,"fetch_time":1756900823832}
{"symbol":"TONUSDT","bids":[["3.1506","261.7"],["3.1505","480.0"],["3.1504","1342.0"],["3.1503","1063.3"]],"asks":[["3.1513","0"],["3.1519","1582.3"],["3.1563","1147.9"]],"timestamp":1756900823809,"update_id":50196165,"fetch_time":1756900823852}
{"symbol":"TONUSDT","bids":[["3.1511","20.0"],["3.1510","91.5"],["3.1509","180.6"],["3.1508","774.4"],["3.1507","446.5"],["3.1505","766.5"],["3.1500","847.5"],["3.1494","4078.8"],["3.1461","0"]],"asks":[["3.1514","0"],["3.1516","809.8"],["3.1518","2300.4"],["3.1519","608.3"],["3.1520","1412.6"],["3.1521","594.1"],["3.1522","2376.0"],["3.1525","2484.1"],["3.1527","959.0"],["3.1548","3567.5"],["3.1550","3520.7"],["3.1564","1693.1"]],"timestamp":1756900823829,"update_id":50196166,"fetch_time":1756900823876}
{"symbol":"TONUSDT","bids":[["3.1509","0"],["3.1508","542.7"],["3.1507","394.4"],["3.1506","307.8"],["3.1503","812.2"],["3.1495","1067.0"],["3.1461","2168.2"]],"asks":[["3.1519","694.8"],["3.1520","2296.9"],["3.1521","640.0"],["3.1530","3811.8"],["3.1548","2932.0"],["3.1550","4407.1"],["3.1561","1430.6"],["3.1564","2960.2"]],"timestamp":1756900823869,"update_id":50196168,"fetch_time":1756900823916}
{"symbol":"TONUSDT","bids":[["3.1509","162.8"],["3.1508","545.9"],["3.1506","264.6"],["3.1505","1202.6"],["3.1500","1066.5"],["3.1461","0"]],"asks":[["3.1518","1892.7"],["3.1519","758.2"],["3.1560","1350.8"]],"timestamp":1756900823890,"update_id":50196169,"fetch_time":1756900823936}
{"symbol":"TONUSDT","bids":[["3.1509","194.5"],["3.1508","988.8"],["3.1505","994.7"],["3.1498","2330.0"]],"asks":[["3.1515","0"],["3.1516","502.6"],["3.1517","329.7"],["3.1518","1912.7"],["3.1519","1190.8"],["3.1520","543.4"],["3.1550","4405.1"],["3.1551","6073.9"],["3.1565","710.9"]],"timestamp":1756900823970,"update_id":50196173,"fetch_time":1756900824012}
{"symbol":"TONUSDT","bids":[],"asks":[["3.1520","618.2"],["3.1525","2223.8"],["3.1526","2707.6"]],"timestamp":1756900824030,"update_id":50196176,"fetch_time":1756900824080}
{"symbol":"TONUSDT","bids":[["3.1509","234.5"]],"asks":[],"timestamp":1756900824150,"update_id":50196180,"fetch_time":1756900824192}
{"symbol":"TONUSDT","bids":[],"asks":[["3.1516","599.2"]],"timestamp":1756900824169,"update_id":50196181,"fetch_time":1756900824216}
{"symbol":"TONUSDT","bids":[["3.1504","1181.9"]],"asks":[],"timestamp":1756900824229,"update_id":50196183,"fetch_time":1756900824277}
{"symbol":"TONUSDT","bids":[["3.1508","778.5"],["3.1504","1225.2"],["3.1494","3990.4"],["3.1486","1112.2"]],"asks":[],"timestamp":1756900824250,"update_id":50196184,"fetch_time":1756900824300}
{"symbol":"TONUSDT","bids":[["3.1509","0"],["3.1508","819.4"],["3.1506","307.9"],["3.1504","1005.8"],["3.1461","2168.2"]],"asks":[],"timestamp":1756900824329,"update_id":50196188,"fetch_time":1756900824376}
{"symbol":"TONUSDT","bids":[],"asks":[["3.1561","2697.7"],["3.1562","2082.2"]],"timestamp":1756900824410,"update_id":50196190,"fetch_time":1756900824460}
{"symbol":"TONUSDT","bids":[["3.1509","170.5"],["3.1506","803.7"],["3.1504","1225.2"],["3.1490","1928.7"],["3.1461","0"]],"asks":[],"timestamp":1756900824429,"update_id":50196191,"fetch_time":1756900824481}
{"symbol":"TONUSDT","bids":[["3.1511","20.0"]],"asks":[["3.1515","141.6"],["3.1516","945.8"],["3.1518","2743.1"],["3.1548","1533.5"],["3.1551","7759.6"],["3.1565","0"]],"timestamp":1756900824449,"update_id":50196192,"fetch_time":1756900824492}
{"symbol":"TONUSDT","bids":[["3.1508","778.5"],["3.1498","2330.0"]],"asks":[["3.1514","28.8"],["3.1516","1666.8"],["3.1517","363.7"],["3.1520","996.5"],["3.1521","1329.3"],["3.1546","2299.3"],["3.1551","7757.6"],["3.1561","1430.6"],["3.1562","3349.3"],["3.1564","0"]],"timestamp":1756900824470,"update_id":50196193,"fetch_time":1756900824520}
{"symbol":"TONUSDT","bids":[],"asks":[["3.1518","3218.6"],["3.1519","1962.1"],["3.1520","2838.7"]],"timestamp":1756900824529,"update_id":50196196,"fetch_time":1756900824572}
{"symbol":"TONUSDT","bids":[["3.1509","0"],["3.1461","2168.2"]],"asks":[["3.1521","389.8"],["3.1522","2419.2"],["3.1560","3453.9"],["3.1561","1430.6"]],"timestamp":1756900824609,"update_id":50196199,"fetch_time":1756900824656}
{"symbol":"TONUSDT","bids":[],"asks":[["3.1558","3234.0"]],"timestamp":1756900824629,"update_id":50196200,"fetch_time":1756900824684}
{"symbol":"TONUSDT","bids":[["3.1511","0"],["3.1509","163.8"],["3.1502","490.8"]],"asks":[["3.1516","1387.2"],["3.1518","3221.0"],["3.1519","1959.7"],["3.1520","2216.8"],["3.1524","4822.8"]],"timestamp":1756900824730,"update_id":50196201,"fetch_time":1756900824780}
{"symbol":"TONUSDT","bids":[["3.1506","552.6"]],"asks":[],"timestamp":1756900824749,"update_id":50196202,"fetch_time":1756900824796}
{"symbol":"TONUSDT","bids":[["3.1505","1095.9"]],"asks":[],"timestamp":1756900824769,"update_id":50196203,"fetch_time":1756900824817}
{"symbol":"TONUSDT","bids":[["3.1505","1202.6"],["3.1503","769.0"],["3.1502","534.1"],["3.1501","1095.0"]],"asks":[],"timestamp":1756900824809,"update_id":50196205,"fetch_time":1756900824857}
{"symbol":"TONUSDT","bids":[],"asks":[["3.1560","2186.8"],["3.1561","2697.7"]],"timestamp":1756900824950,"update_id":50196206,"fetch_time":1756900824992}
{"symbol":"TONUSDT","bids":[],"asks":[["3.1558","2880.0"]],"timestamp":1756900824970,"update_id":50196207,"fetch_time":1756900825016}
{"symbol":"TONUSDT","bids":[],"asks":[["3.1516","1625.2"]],"timestamp":1756900825009,"update_id":50196208,"fetch_time":1756900825052}
{"symbol":"TONUSDT","bids":[["3.1508","778.5"]],"asks":[],"timestamp":1756900825329,"update_id":50196209,"fetch_time":1756900825372}
{"symbol":"TONUSDT","bids":[],"asks":[["3.1518","3177.7"],["3.1519","1916.4"],["3.1520","2173.5"],["3.1521","346.5"],["3.1522","2375.9"]],"timestamp":1756900825390,"update_id":50196210,"fetch_time":1756900825440}
{"symbol":"TONUSDT","bids":[],"asks":[["3.1513","122.9"],["3.1563","0"]],"timestamp":1756900825409,"update_id":50196211,"fetch_time":1756900825456}
{"symbol":"TONUSDT","bids":[["3.1505","1159.3"],["3.1504","1181.9"],["3.1503","725.7"],["3.1502","490.8"],["3.1501","1051.8"]],"asks":[["3.1512","28.8"],["3.1514","10.6"],["3.1515","161.9"],["3.1516","1088.1"],["3.1518","2893.7"],["3.1519","2209.7"],["3.1520","2216.8"],["3.1521","389.8"],["3.1525","2440.8"],["3.1542","4648.0"],["3.1547","860.8"],["3.1549","711.1"],["3.1562","0"]],"timestamp":1756900825429,"update_id":50196212,"fetch_time":1756900825476}
{"symbol":"TONUSDT","bids":[],"asks":[["3.1518","3136.9"]],"timestamp":1756900825449,"update_id":50196213,"fetch_time":1756900825492}
{"symbol":"TONUSDT","bids":[],"asks":[["3.1516","1431.1"],["3.1517","671.9"],["3.1518","3645.3"],["3.1519","1546.1"],["3.1520","1934.8"],["3.1523","1212.3"]],"timestamp":1756900825489,"update_id":50196215,"fetch_time":1756900825536}
{"symbol":"TONUSDT","bids":[["3.1509","0"],["3.1460","1679.2"]],"asks":[["3.1518","3187.4"],["3.1519","915.5"],["3.1520","1653.0"],["3.1558","3234.0"]],"timestamp":1756900825530,"update_id":50196217,"fetch_time":1756900825577}
{"symbol":"TONUSDT","bids":[],"asks":[["3.1514","516.2"]],"timestamp":1756900825550,"update_id":50196218,"fetch_time":1756900825593}
{"symbol":"TONUSDT","bids":[],"asks":[["3.1518","2774.2"],["3.1531","1111.0"]],"timestamp":1756900825590,"update_id":50196220,"fetch_time":1756900825632}
{"symbol":"TONUSDT","bids":[],"asks":[["3.1516","1091.3"],["3.1537","3164.6"],["3.1544","2671.6"]],"timestamp":1756900825609,"update_id":50196221,"fetch_time":1756900825660}
{"symbol":"TONUSDT","bids":[],"asks":[["3.1511","31.6"],["3.1514","547.8"],["3.1515","196.3"],["3.1536","2332.2"],["3.1542","4102.8"],["3.1561","0"]],"timestamp":1756900825629,"update_id":50196222,"fetch_time":1756900825676}
{"symbol":"TONUSDT","bids":[],"asks":[["3.1512","140.0"],["3.1514","551.0"],["3.1518","2710.9"],["3.1520","1621.5"],["3.1521","872.4"],["3.1546","2301.3"],["3.1547","858.8"]],"timestamp":1756900825650,"update_id":50196223,"fetch_time":1756900825692}
{"symbol":"TONUSDT","bids":[],"asks":[["3.1516","1279.2"]],"timestamp":1756900825669,"update_id":50196224,"fetch_time":1756900825720}
{"symbol":"TONUSDT","bids":[],"asks":[["3.1516","1748.9"],["3.1517","953.6"]],"timestamp":1756900825690,"update_id":50196225,"fetch_time":1756900825744}
{"symbol":"TONUSDT","bids":[],"asks":[["3.1515","354.9"],["3.1560","2186.8"]],"timestamp":1756900825710,"update_id":50196226,"fetch_time":1756900825760}
{"symbol":"TONUSDT","bids":[],"asks":[["3.1518","2429.2"],["3.1558","2880.0"]],"timestamp":1756900825729,"update_id":50196227,"fetch_time":1756900825784}
{"symbol":"TONUSDT","bids":[],"asks":[["3.1517","765.6"]],"timestamp":1756900825770,"update_id":50196228,"fetch_time":1756900825812}
{"symbol":"TONUSDT","bids":[],"asks":[["3.1516","1551.9"],["3.1523","1246.4"],["3.1524","4786.2"]],"timestamp":1756900825809,"update_id":50196230,"fetch_time":1756900825852}
{"symbol":"TONUSDT","bids":[["3.1510","0"],["3.1508","0"],["3.1507","0"],["3.1505","5.6"],["3.1504","896.4"],["3.1499","829.6"],["3.1495","748.7"],["3.1494","3926.5"],["3.1459","1477.3"],["3.1458","795.9"],["3.1457","576.5"]],"asks":[["3.1508","29.2"],["3.1510","28.8"],["3.1511","154.5"],["3.1512","163.8"],["3.1513","309.4"],["3.1514","584.3"],["3.1515","430.1"],["3.1516","1595.2"],["3.1522","2332.7"],["3.1523","1203.2"],["3.1525","2180.6"],["3.1528","2796.6"],["3.1559","0"],["3.1560","0"]],"timestamp":1756900825829,"update_id":50196231,"fetch_time":1756900825880}
{"symbol":"TONUSDT","bids":[["3.1506","10.3"],["3.1505","205.5"],["3.1503","3.2"],["3.1501","638.8"],["3.1500","565.4"],["3.1498","2101.6"],["3.1491","348.7"]],"asks":[["3.1507","29.2"],["3.1508","0"],["3.1510","706.4"],["3.1511","230.5"],["3.1512","184.8"],["3.1513","1314.8"],["3.1514","981.3"],["3.1515","398.9"],["3.1516","2124.7"],["3.1517","765.1"],["3.1518","1628.1"],["3.1519","507.0"],["3.1520","1546.6"],["3.1521","797.5"],["3.1522","3042.6"],["3.1525","2820.4"],["3.1531","627.4"],["3.1533","1701.2"],["3.1536","1918.5"],["3.1541","1015.0"],["3.1542","4104.8"],["3.1545","1160.8"],["3.1546","1660.0"],["3.1551","7005.5"],["3.1558","5116.7"]],"timestamp":1756900825849,"update_id":50196232,"fetch_time":1756900825904}
{"symbol":"TONUSDT","bids":[["3.1500","406.8"],["3.1484","1867.9"],["3.1474","1119.1"],["3.1471","694.1"]],"asks":[["3.1509","169.2"],["3.1510","540.4"],["3.1511","233.7"],["3.1515","545.8"],["3.1516","1835.1"],["3.1524","4850.1"],["3.1558","0"]],"timestamp":1756900825889,"update_id":50196234,"fetch_time":1756900825936}
{"symbol":"TONUSDT","bids":[["3.1493","2957.4"]],"asks":[["3.1509","0"],["3.1516","2891.1"],["3.1556","3731.7"],["3.1558","3849.5"]],"timestamp":1756900825910,"update_id":50196235,"fetch_time":1756900825956}
{"symbol":"TONUSDT","bids":[],"asks":[["3.1509","162.1"],["3.1558","0"]],"timestamp":1756900825990,"update_id":50196239,"fetch_time":1756900826032}
{"symbol":"TONUSDT","bids":[],"asks":[["3.1512","1018.3"],["3.1549","784.9"],["3.1550","4179.1"]],"timestamp":1756900826029,"update_id":50196241,"fetch_time":1756900826072}
{"symbol":"TONUSDT","bids":[],"asks":[["3.1510","903.0"]],"timestamp":1756900826050,"update_id":50196242,"fetch_time":1756900826092}
{"symbol":"TONUSDT","bids":[["3.1494","1379.5"],["3.1492","2358.8"],["3.1482","852.6"]],"asks":[],"timestamp":1756900826269,"update_id":50196253,"fetch_time":1756900826312}
{"symbol":"TONUSDT","bids":[["3.1484","1305.6"],["3.1478","853.6"],["3.1476","2313.9"]],"asks":[],"timestamp":1756900826309,"update_id":50196255,"fetch_time":1756900826352}
{"symbol":"TONUSDT","bids":[["3.1478","1102.2"]],"asks":[],"timestamp":1756900826330,"update_id":50196256,"fetch_time":1756900826388}
{"symbol":"TONUSDT","bids":[["3.1499","517.9"],["3.1495","810.9"],["3.1479","602.5"],["3.1462","1320.1"]],"asks":[["3.1507","94.6"],["3.1508","6.8"],["3.1509","283.6"],["3.1516","2886.2"],["3.1519","453.7"],["3.1520","1500.8"],["3.1521","754.3"],["3.1557","0"]],"timestamp":1756900826370,"update_id":50196258,"fetch_time":1756900826429}
{"symbol":"TONUSDT","bids":[["3.1506","0"],["3.1505","0"],["3.1498","1198.1"],["3.1497","1212.0"],["3.1495","556.0"],["3.1492","2328.8"],["3.1491","285.3"],["3.1490","1624.1"],["3.1487","567.1"],["3.1486","3012.2"],["3.1485","2729.4"],["3.1480","873.6"],["3.1464","1704.0"],["3.1456","1615.7"],["3.1455","1495.6"]],"asks":[["3.1506","122.9"],["3.1508","13.2"],["3.1509","273.0"],["3.1515","801.7"],["3.1516","2703.2"],["3.1556","0"]],"timestamp":1756900826389,"update_id":50196259,"fetch_time":1756900826441}
{"symbol":"TONUSDT","bids":[["3.1504","0"],["3.1503","0"],["3.1499","151.3"],["3.1498","1007.1"],["3.1497","642.3"],["3.1496","1734.1"],["3.1495","335.0"],["3.1492","1412.7"],["3.1491","315.3"],["3.1490","1654.1"],["3.1454","3576.8"],["3.1453","10997.8"]],"asks":[["3.1504","20.0"],["3.1505","178.2"],["3.1506","151.7"],["3.1507","231.1"],["3.1508","724.7"],["3.1509","250.2"],["3.1510","431.0"],["3.1511","195.4"],["3.1512","2232.1"],["3.1530","2372.4"],["3.1540","2366.1"],["3.1542","4102.8"],["3.1550","5148.8"],["3.1551","8273.0"],["3.1553","3.2"],["3.1554","0"],["3.1555","0"]],"timestamp":1756900826410,"update_id":50196260,"fetch_time":1756900826456}
{"symbol":"TONUSDT","bids":[["3.1502","0"],["3.1499","20.4"],["3.1497","893.4"],["3.1496","1543.1"],["3.1494","1158.3"],["3.1492","1641.1"],["3.1491","285.3"],["3.1490","1624.1"],["3.1489","953.4"],["3.1488","2076.4"],["3.1487","346.1"],["3.1486","1421.5"],["3.1485","698.4"],["3.1484","3175.6"],["3.1483","2336.9"],["3.1452","1711.1"]],"asks":[["3.1504","27.9"],["3.1505","63.2"],["3.1506","409.6"],["3.1507","279.9"],["3.1508","555.5"],["3.1509","907.7"],["3.1510","1451.1"],["3.1511","163.8"],["3.1513","912.0"],["3.1514","1878.4"],["3.1516","2667.8"],["3.1520","2300.8"],["3.1528","3847.9"],["3.1530","3469.7"],["3.1534","974.4"],["3.1537","2122.5"],["3.1538","1040.9"],["3.1539","1059.2"],["3.1540","2308.9"],["3.1541","1445.2"],["3.1542","4047.6"],["3.1544","2627.4"],["3.1548","3136.5"],["3.1549","429.1"],["3.1552","2131.5"]],"timestamp":1756900826429,"update_id":50196261,"fetch_time":1756900826481}
{"symbol":"TONUSDT","bids":[["3.1498","557.8"],["3.1495","274.6"],["3.1488","1245.5"],["3.1484","2084.2"],["3.1476","1362.0"],["3.1474","2210.5"],["3.1473","1848.9"],["3.1468","3405.8"],["3.1459","8004.0"]],"asks":[["3.1502","20.0"],["3.1504","195.1"],["3.1508","1776.9"],["3.1512","1856.5"],["3.1521","1844.0"],["3.1526","3861.4"],["3.1537","2364.5"],["3.1539","1057.2"],["3.1553","0"]],"timestamp":1756900826489,"update_id":50196264,"fetch_time":1756900826537}
{"symbol":"TONUSDT","bids":[["3.1484","2622.5"],["3.1476","1719.1"],["3.1472","801.1"]],"asks":[["3.1503","322.0"],["3.1504","531.3"],["3.1505","14.6"],["3.1506","707.6"],["3.1507","191.1"],["3.1508","2449.0"],["3.1509","1352.5"],["3.1510","2015.8"],["3.1512","1396.2"],["3.1522","2343.4"],["3.1552","0"]],"timestamp":1756900826530,"update_id":50196266,"fetch_time":1756900826581}
{"symbol":"TONUSDT","bids":[],"asks":[["3.1520","3788.6"],["3.1547","2651.5"],["3.1549","429.1"]],"timestamp":1756900826709,"update_id":50196274,"fetch_time":1756900826757}
{"symbol":"TONUSDT","bids":[["3.1489","905.7"]],"asks":[],"timestamp":1756900826749,"update_id":50196276,"fetch_time":1756900826792}
{"symbol":"TONUSDT","bids":[],"asks":[["3.1547","1383.8"],["3.1548","4404.1"]],"timestamp":1756900826770,"update_id":50196277,"fetch_time":1756900826812}
{"symbol":"TONUSDT","bids":[],"asks":[["3.1510","1269.5"],["3.1511","443.5"]],"timestamp":1756900826850,"update_id":50196280,"fetch_time":1756900826892}
{"symbol":"TONUSDT","bids":[],"asks":[["3.1502","102.7"],["3.1504","648.7"],["3.1539","1356.1"],["3.1541","1015.0"],["3.1544","3612.0"]],"timestamp":1756900826870,"update_id":50196281,"fetch_time":1756900826925}
{"symbol":"TONUSDT","bids":[],"asks":[["3.1523","1172.4"],["3.1531","474.9"]],"timestamp":1756900826929,"update_id":50196283,"fetch_time":1756900827145}
{"symbol":"TONUSDT","bids":[],"asks":[["3.1544","3777.2"]],"timestamp":1756900826950,"update_id":50196284,"fetch_time":1756900827145}
{"symbol":"TONUSDT","bids":[],"asks":[["3.1512","1579.2"]],"timestamp":1756900827049,"update_id":50196285,"fetch_time":1756900827145}
{"symbol":"TONUSDT","bids":[["3.1486","1157.0"]],"asks":[],"timestamp":1756900827129,"update_id":50196286,"fetch_time":1756900827191}
{"symbol":"TONUSDT","bids":[],"asks":[["3.1513","663.7"],["3.1514","1834.5"]],"timestamp":1756900827310,"update_id":50196289,"fetch_time":1756900827367}
{"symbol":"TONUSDT","bids":[["3.1492","1455.9"]],"asks":[],"timestamp":1756900827409,"update_id":50196293,"fetch_time":1756900827463}
{"symbol":"TONUSDT","bids":[],"asks":[["3.1504","594.3"]],"timestamp":1756900827430,"update_id":50196294,"fetch_time":1756900827479}
{"symbol":"TONUSDT","bids":[],"asks":[["3.1502","51.6"]],"timestamp":1756900827509,"update_id":50196298,"fetch_time":1756900827561}
{"symbol":"TONUSDT","bids":[["3.1486","1318.0"],["3.1484","2652.5"]],"asks":[],"timestamp":1756900827610,"update_id":50196302,"fetch_time":1756900827665}
{"symbol":"TONUSDT","bids":[],"asks":[["3.1506","688.0"],["3.1518","2004.9"]],"timestamp":1756900827649,"update_id":50196304,"fetch_time":1756900827705}
{"symbol":"TONUSDT","bids":[],"asks":[["3.1529","2673.6"]],"timestamp":1756900827670,"update_id":50196305,"fetch_time":1756900827738}
{"symbol":"TONUSDT","bids":[],"asks":[["3.1524","2834.9"],["3.1528","3345.8"]],"timestamp":1756900827689,"update_id":50196306,"fetch_time":1756900827751}
{"symbol":"TONUSDT","bids":[],"asks":[["3.1525","1553.6"],["3.1529","1694.7"]],"timestamp":1756900827750,"update_id":50196308,"fetch_time":1756900827799}
{"symbol":"TONUSDT","bids":[],"asks":[["3.1531","506.6"],["3.1541","986.5"]],"timestamp":1756900827929,"update_id":50196310,"fetch_time":1756900827983}
{"symbol":"TONUSDT","bids":[["3.1489","683.2"]],"asks":[],"timestamp":1756900827989,"update_id":50196312,"fetch_time":1756900828039}
{"symbol":"TONUSDT","bids":[],"asks":[["3.1516","2416.5"]],"timestamp":1756900828010,"update_id":50196313,"fetch_time":1756900828066}
{"symbol":"TONUSDT","bids":[["3.1493","326.5"]],"asks":[],"timestamp":1756900828069,"update_id":50196314,"fetch_time":1756900828126}
{"symbol":"TONUSDT","bids":[],"asks":[["3.1527","530.6"]],"timestamp":1756900828149,"update_id":50196317,"fetch_time":1756900828199}
{"symbol":"TONUSDT","bids":[],"asks":[["3.1526","1515.8"]],"timestamp":1756900828169,"update_id":50196318,"fetch_time":1756900828220}
{"symbol":"TONUSDT","bids":[["3.1478","837.8"]],"asks":[],"timestamp":1756900828189,"update_id":50196319,"fetch_time":1756900828242}
{"symbol":"TONUSDT","bids":[],"asks":[["3.1506","965.8"],["3.1532","1725.9"],["3.1537","2167.2"],["3.1538","1646.7"]],"timestamp":1756900828369,"update_id":50196328,"fetch_time":1756900828425}
{"symbol":"TONUSDT","bids":[],"asks":[["3.1507","643.9"]],"timestamp":1756900828390,"update_id":50196329,"fetch_time":1756900828436}
{"symbol":"TONUSDT","bids":[],"asks":[["3.1503","435.0"]],"timestamp":1756900828430,"update_id":50196331,"fetch_time":1756900828487}
{"symbol":"TONUSDT","bids":[],"asks":[["3.1502","188.4"],["3.1503","460.2"],["3.1504","702.4"],["3.1506","1719.0"],["3.1508","2926.6"],["3.1509","1040.2"]],"timestamp":1756900828450,"update_id":50196332,"fetch_time":1756900828497}
{"symbol":"TONUSDT","bids":[],"asks":[["3.1507","675.5"]],"timestamp":1756900828489,"update_id":50196333,"fetch_time":1756900828543}
{"symbol":"TONUSDT","bids":[["3.1492","1384.7"]],"asks":[],"timestamp":1756900828510,"update_id":50196334,"fetch_time":1756900828559}
{"symbol":"TONUSDT","bids":[["3.1494","373.1"]],"asks":[],"timestamp":1756900828550,"update_id":50196336,"fetch_time":1756900828601}
{"symbol":"TONUSDT","bids":[],"asks":[["3.1515","3406.2"]],"timestamp":1756900828609,"update_id":50196337,"fetch_time":1756900828662}
{"symbol":"TONUSDT","bids":[],"asks":[["3.1508","2958.3"]],"timestamp":1756900828670,"update_id":50196339,"fetch_time":1756900828724}
{"symbol":"TONUSDT","bids":[["3.1501","11.6"]],"asks":[],"timestamp":1756900828729,"update_id":50196340,"fetch_time":1756900828785}
{"symbol":"TONUSDT","bids":[],"asks":[["3.1528","3059.3"]],"timestamp":1756900828769,"update_id":50196341,"fetch_time":1756900828817}
{"symbol":"TONUSDT","bids":[],"asks":[["3.1505","358.8"],["3.1510","1089.8"]],"timestamp":1756900829009,"update_id":50196343,"fetch_time":1756900829063}
{"symbol":"TONUSDT","bids":[["3.1487","431.9"],["3.1486","1509.0"]],"asks":[],"timestamp":1756900829250,"update_id":50196344,"fetch_time":1756900829300}
{"symbol":"TONUSDT","bids":[],"asks":[["3.1507","861.6"],["3.1508","3707.3"]],"timestamp":1756900829370,"update_id":50196345,"fetch_time":1756900829423}
{"symbol":"TONUSDT","bids":[],"asks":[["3.1506","2067.8"]],"timestamp":1756900829389,"update_id":50196346,"fetch_time":1756900829444}
{"symbol":"TONUSDT","bids":[],"asks":[["3.1505","1309.1"],["3.1507","924.9"]],"timestamp":1756900829490,"update_id":50196347,"fetch_time":1756900829537}
{"symbol":"TONUSDT","bids":[],"asks":[["3.1503","881.7"],["3.1505","1340.8"],["3.1506","2099.4"],["3.1507","956.6"],["3.1509","1071.8"]],"timestamp":1756900829510,"update_id":50196348,"fetch_time":1756900829567}
{"symbol":"TONUSDT","bids":[],"asks":[["3.1506","2131.0"],["3.1507","988.3"]],"timestamp":1756900829529,"update_id":50196349,"fetch_time":1756900829577}
{"symbol":"TONUSDT","bids":[],"asks":[["3.1505","1372.5"],["3.1506","2162.7"],["3.1507","1019.9"],["3.1508","3770.7"],["3.1509","1103.4"]],"timestamp":1756900829549,"update_id":50196350,"fetch_time":1756900829599}
{"symbol":"TONUSDT","bids":[],"asks":[["3.1507","1051.6"],["3.1516","2480.0"]],"timestamp":1756900829569,"update_id":50196351,"fetch_time":1756900829623}
{"symbol":"TONUSDT","bids":[],"asks":[["3.1506","3051.3"]],"timestamp":1756900829589,"update_id":50196352,"fetch_time":1756900829639}
{"symbol":"TONUSDT","bids":[],"asks":[["3.1507","1083.2"],["3.1508","3833.9"]],"timestamp":1756900829610,"update_id":50196353,"fetch_time":1756900829660}
{"symbol":"TONUSDT","bids":[],"asks":[["3.1505","1848.6"],["3.1508","3865.6"]],"timestamp":1756900829690,"update_id":50196354,"fetch_time":1756900829743}
{"symbol":"TONUSDT","bids":[],"asks":[["3.1503","1285.9"]],"timestamp":1756900829709,"update_id":50196355,"fetch_time":1756900829766}
{"symbol":"TONUSDT","bids":[],"asks":[["3.1519","2288.5"],["3.1523","1794.7"]],"timestamp":1756900829729,"update_id":50196356,"fetch_time":1756900829783}
{"symbol":"TONUSDT","bids":[],"asks":[["3.1507","1372.7"],["3.1508","3624.4"]],"timestamp":1756900829850,"update_id":50196357,"fetch_time":1756900829897}
{"symbol":"TONUSDT","bids":[],"asks":[["3.1505","1794.0"],["3.1506","2987.7"],["3.1507","1037.7"],["3.1508","3654.5"]],"timestamp":1756900829889,"update_id":50196359,"fetch_time":1756900829937}
{"symbol":"TONUSDT","bids":[["3.1492","1364.5"]],"asks":[],"timestamp":1756900829910,"update_id":50196360,"fetch_time":1756900829959}
{"symbol":"TONUSDT","bids":[],"asks":[["3.1504","979.0"]],"timestamp":1756900829929,"update_id":50196361,"fetch_time":1756900829999}
{"symbol":"TONUSDT","bids":[],"asks":[["3.1504","915.6"],["3.1507","1080.9"],["3.1508","3697.7"]],"timestamp":1756900829950,"update_id":50196362,"fetch_time":1756900830010}
{"symbol":"TONUSDT","bids":[],"asks":[["3.1508","3729.4"]],"timestamp":1756900829989,"update_id":50196363,"fetch_time":1756900830041}
{"symbol":"TONUSDT","bids":[["3.1486","1982.3"]],"asks":[],"timestamp":1756900830049,"update_id":50196366,"fetch_time":1756900830103}
{"symbol":"TONUSDT","bids":[],"asks":[["3.1504","943.6"],["3.1509","1392.9"]],"timestamp":1756900830069,"update_id":50196367,"fetch_time":1756900830127}
{"symbol":"TONUSDT","bids":[["3.1474","2072.4"]],"asks":[],"timestamp":1756900830229,"update_id":50196368,"fetch_time":1756900830287}
{"symbol":"TONUSDT","bids":[["3.1485","2124.2"]],"asks":[],"timestamp":1756900830250,"update_id":50196369,"fetch_time":1756900830297}
{"symbol":"TONUSDT","bids":[],"asks":[["3.1508","4018.9"],["3.1509","1103.4"]],"timestamp":1756900830269,"update_id":50196370,"fetch_time":1756900830319}
{"symbol":"TONUSDT","bids":[],"asks":[["3.1503","1288.0"],["3.1504","971.1"]],"timestamp":1756900830330,"update_id":50196371,"fetch_time":1756900830380}
{"symbol":"TONUSDT","bids":[],"asks":[["3.1508","3729.4"]],"timestamp":1756900830389,"update_id":50196372,"fetch_time":1756900830441}
{"symbol":"TONUSDT","bids":[],"asks":[["3.1506","3137.6"]],"timestamp":1756900830589,"update_id":50196373,"fetch_time":1756900830647}
{"symbol":"TONUSDT","bids":[["3.1497","3.2"],["3.1494","710.4"],["3.1491","362.4"],["3.1487","497.6"]],"asks":[["3.1502","0"],["3.1504","852.2"],["3.1505","1732.6"],["3.1512","2377.4"],["3.1537","2165.2"],["3.1538","1648.7"],["3.1552","1274.0"]],"timestamp":1756900830710,"update_id":50196377,"fetch_time":1756900830762}
{"symbol":"TONUSDT","bids":[["3.1496","194.1"]],"asks":[["3.1502","28.8"],["3.1504","820.9"],["3.1505","1161.4"],["3.1510","1070.2"],["3.1548","4404.1"],["3.1552","0"]],"timestamp":1756900830729,"update_id":50196378,"fetch_time":1756900830791}
{"symbol":"TONUSDT","bids":[],"asks":[["3.1504","346.6"],["3.1511","520.2"],["3.1514","4090.2"],["3.1519","3330.1"]],"timestamp":1756900830789,"update_id":50196380,"fetch_time":1756900830847}
{"symbol":"TONUSDT","bids":[["3.1494","1361.1"]],"asks":[["3.1503","0"],["3.1505","241.2"],["3.1506","2138.8"],["3.1509","1425.8"],["3.1552","1274.0"]],"timestamp":1756900830950,"update_id":50196388,"fetch_time":1756900831008}
{"symbol":"TONUSDT","bids":[],"asks":[["3.1513","426.2"],["3.1516","2178.9"],["3.1519","1874.5"],["3.1522","2236.3"],["3.1525","250.6"],["3.1526","1327.7"],["3.1535","926.6"],["3.1537","2708.3"],["3.1539","1770.1"],["3.1541","1513.4"],["3.1543","1218.7"],["3.1545","1674.8"]],"timestamp":1756900830970,"update_id":50196389,"fetch_time":1756900831018}
{"symbol":"TONUSDT","bids":[],"asks":[["3.1507","911.0"],["3.1524","2284.5"],["3.1525","719.6"],["3.1548","4404.1"]],"timestamp":1756900830990,"update_id":50196390,"fetch_time":1756900831045}
{"symbol":"TONUSDT","bids":[["3.1496","542.4"]],"asks":[],"timestamp":1756900831009,"update_id":50196391,"fetch_time":1756900831063}
{"symbol":"TONUSDT","bids":[["3.1490","2970.1"]],"asks":[],"timestamp":1756900831069,"update_id":50196393,"fetch_time":1756900831116}
{"symbol":"TONUSDT","bids":[["3.1501","0"],["3.1500","0"],["3.1499","0"],["3.1498","0"],["3.1497","122.9"],["3.1496","293.1"],["3.1495","217.4"],["3.1494","416.3"],["3.1492","742.3"],["3.1491","302.4"],["3.1490","3056.6"],["3.1451","1460.4"],["3.1450","1633.2"],["3.1449","2579.8"],["3.1448","1080.3"]],"asks":[["3.1501","48.8"],["3.1502","168.8"],["3.1507","954.3"],["3.1513","614.4"],["3.1517","1517.4"],["3.1519","1449.3"],["3.1521","3435.9"],["3.1523","1925.1"],["3.1534","974.4"],["3.1535","738.4"],["3.1536","2534.2"],["3.1537","1415.1"],["3.1539","1356.1"],["3.1540","3286.9"],["3.1541","986.5"],["3.1545","922.1"],["3.1548","3136.5"],["3.1550","6416.3"],["3.1552","0"]],"timestamp":1756900831089,"update_id":50196394,"fetch_time":1756900831152}
{"symbol":"TONUSDT","bids":[["3.1496","0"],["3.1495","58.7"],["3.1494","68.4"],["3.1491","331.1"],["3.1490","2752.2"],["3.1485","1082.6"],["3.1483","2473.0"],["3.1481","966.0"],["3.1479","502.9"],["3.1477","528.3"],["3.1475","1169.9"],["3.1469","744.9"],["3.1451","1828.1"],["3.1449","3035.7"],["3.1447","1175.5"]],"asks":[["3.1502","140.0"],["3.1504","499.3"],["3.1505","1288.4"],["3.1506","1821.4"],["3.1507","780.6"],["3.1508","3987.2"],["3.1509","184.6"],["3.1510","1081.9"],["3.1511","801.8"],["3.1515","3948.9"],["3.1516","2474.7"],["3.1524","2339.7"],["3.1527","1095.7"],["3.1529","1805.1"],["3.1532","1529.9"],["3.1536","2175.4"],["3.1537","1413.1"],["3.1539","1300.9"],["3.1540","3242.7"],["3.1543","578.9"],["3.1544","3666.8"]],"timestamp":1756900831109,"update_id":50196395,"fetch_time":1756900831157}
{"symbol":"TONUSDT","bids":[["3.1497","262.9"],["3.1491","489.8"]],"asks":[["3.1502","0"],["3.1542","4637.2"],["3.1552","1274.0"]],"timestamp":1756900831170,"update_id":50196398,"fetch_time":1756900831224}
{"symbol":"TONUSDT","bids":[["3.1498","42.8"],["3.1495","233.3"],["3.1471","694.1"],["3.1466","791.5"],["3.1447","0"]],"asks":[["3.1500","28.8"],["3.1508","3275.4"],["3.1549","429.1"],["3.1550","6416.3"],["3.1552","0"]],"timestamp":1756900831189,"update_id":50196399,"fetch_time":1756900831239}
{"symbol":"TONUSDT","bids":[["3.1499","122.9"],["3.1498","0"],["3.1496","2.4"],["3.1493","319.2"],["3.1492","1229.2"],["3.1487","779.2"],["3.1486","1927.1"],["3.1481","855.6"],["3.1473","952.1"],["3.1468","3516.2"],["3.1448","0"]],"asks":[["3.1501","0"],["3.1505","1129.7"],["3.1506","1625.2"],["3.1508","2766.3"],["3.1512","2337.8"],["3.1535","740.4"],["3.1536","2173.4"],["3.1552","1274.0"]],"timestamp":1756900831209,"update_id":50196400,"fetch_time":1756900831260}
{"symbol":"TONUSDT","bids":[["3.1494","736.3"]],"asks":[],"timestamp":1756900831270,"update_id":50196403,"fetch_time":1756900831316}
{"symbol":"TONUSDT","bids":[],"asks":[["3.1506","1106.4"],["3.1540","2612.6"],["3.1543","2332.7"]],"timestamp":1756900831370,"update_id":50196408,"fetch_time":1756900831423}
{"symbol":"TONUSDT","bids":[["3.1496","358.6"]],"asks":[],"timestamp":1756900831429,"update_id":50196409,"fetch_time":1756900831481}
{"symbol":"TONUSDT","bids":[],"asks":[["3.1536","1557.7"],["3.1539","2190.9"]],"timestamp":1756900831449,"update_id":50196410,"fetch_time":1756900831511}
{"symbol":"TONUSDT","bids":[],"asks":[["3.1504","439.4"],["3.1509","121.4"],["3.1529","818.8"]],"timestamp":1756900831569,"update_id":50196413,"fetch_time":1756900831625}
{"symbol":"TONUSDT","bids":[],"asks":[["3.1527","1051.5"],["3.1535","784.6"]],"timestamp":1756900831589,"update_id":50196414,"fetch_time":1756900831639}
{"symbol":"TONUSDT","bids":[["3.1498","268.6"],["3.1489","1221.6"],["3.1488","1786.8"],["3.1449","0"]],"asks":[["3.1500","29.8"]],"timestamp":1756900831630,"update_id":50196416,"fetch_time":1756900831676}
{"symbol":"TONUSDT","bids":[["3.1493","53.8"],["3.1488","1830.1"]],"asks":[],"timestamp":1756900831730,"update_id":50196417,"fetch_time":1756900831783}
{"symbol":"TONUSDT","bids":[],"asks":[["3.1504","198.4"],["3.1505","66.6"],["3.1524","1497.9"]],"timestamp":1756900831770,"update_id":50196419,"fetch_time":1756900831820}
{"symbol":"TONUSDT","bids":[["3.1489","982.2"]],"asks":[],"timestamp":1756900831810,"update_id":50196420,"fetch_time":1756900831871}
{"symbol":"TONUSDT","bids":[["3.1492","1209.1"],["3.1491","282.3"],["3.1490","2991.6"],["3.1489","1025.5"]],"asks":[],"timestamp":1756900831829,"update_id":50196421,"fetch_time":1756900831882}
{"symbol":"TONUSDT","bids":[],"asks":[["3.1509","89.7"],["3.1548","4404.1"],["3.1549","429.1"]],"timestamp":1756900831910,"update_id":50196422,"fetch_time":1756900831964}
{"symbol":"TONUSDT","bids":[],"asks":[["3.1527","530.6"],["3.1528","3371.6"]],"timestamp":1756900831950,"update_id":50196424,"fetch_time":1756900831999}
{"symbol":"TONUSDT","bids":[],"asks":[["3.1548","3136.5"],["3.1549","1696.7"]],"timestamp":1756900831989,"update_id":50196425,"fetch_time":1756900832036}
{"symbol":"TONUSDT","bids":[],"asks":[["3.1507","751.6"],["3.1508","1967.5"]],"timestamp":1756900832069,"update_id":50196426,"fetch_time":1756900832119}
{"symbol":"TONUSDT","bids":[["3.1494","698.9"]],"asks":[],"timestamp":1756900832190,"update_id":50196427,"fetch_time":1756900832242}
{"symbol":"TONUSDT","bids":[["3.1494","742.2"]],"asks":[],"timestamp":1756900832210,"update_id":50196428,"fetch_time":1756900832263}
{"symbol":"TONUSDT","bids":[["3.1498","0"],["3.1449","3035.7"]],"asks":[],"timestamp":1756900832229,"update_id":50196429,"fetch_time":1756900832279}
{"symbol":"TONUSDT","bids":[["3.1498","278.1"],["3.1449","0"]],"asks":[],"timestamp":1756900832269,"update_id":50196431,"fetch_time":1756900832324}
{"symbol":"TONUSDT","bids":[["3.1495","263.8"],["3.1494","742.2"],["3.1493","97.1"],["3.1492","1209.1"],["3.1491","282.3"]],"asks":[],"timestamp":1756900832289,"update_id":50196432,"fetch_time":1756900832345}
{"symbol":"TONUSDT","bids":[],"asks":[["3.1547","2651.4"],["3.1549","429.1"]],"timestamp":1756900832310,"update_id":50196433,"fetch_time":1756900832359}
{"symbol":"TONUSDT","bids":[["3.1494","713.0"]],"asks":[],"timestamp":1756900832329,"update_id":50196434,"fetch_time":1756900832385}
{"symbol":"TONUSDT","bids":[],"asks":[["3.1547","1383.8"],["3.1548","4404.1"]],"timestamp":1756900832410,"update_id":50196435,"fetch_time":1756900832458}
{"symbol":"TONUSDT","bids":[],"asks":[["3.1510","994.0"],["3.1548","4513.7"]],"timestamp":1756900832469,"update_id":50196437,"fetch_time":1756900832519}
{"symbol":"TONUSDT","bids":[["3.1484","2366.3"],["3.1476","1744.3"]],"asks":[],"timestamp":1756900832630,"update_id":50196440,"fetch_time":1756900832684}
{"symbol":"TONUSDT","bids":[],"asks":[["3.1505","3.2"]],"timestamp":1756900832790,"update_id":50196441,"fetch_time":1756900832839}
{"symbol":"TONUSDT","bids":[],"asks":[["3.1508","1967.5"],["3.1550","4179.1"]],"timestamp":1756900832890,"update_id":50196442,"fetch_time":1756900832951}
{"symbol":"TONUSDT","bids":[],"asks":[["3.1510","1544.9"],["3.1511","478.8"],["3.1543","3180.7"],["3.1548","4178.3"]],"timestamp":1756900832910,"update_id":50196443,"fetch_time":1756900832962}
{"symbol":"TONUSDT","bids":[],"asks":[["3.1524","1940.6"],["3.1542","5122.1"],["3.1548","2910.7"],["3.1549","1696.7"]],"timestamp":1756900832930,"update_id":50196444,"fetch_time":1756900832983}
{"symbol":"TONUSDT","bids":[],"asks":[["3.1515","3978.9"],["3.1516","2504.7"],["3.1526","1297.7"],["3.1527","500.6"]],"timestamp":1756900833189,"update_id":50196445,"fetch_time":1756900833239}
{"symbol":"TONUSDT","bids":[["3.1491","521.7"],["3.1490","2752.2"]],"asks":[],"timestamp":1756900833369,"update_id":50196446,"fetch_time":1756900833425}
{"symbol":"TONUSDT","bids":[],"asks":[["3.1506","688.1"]],"timestamp":1756900833489,"update_id":50196450,"fetch_time":1756900833537}
{"symbol":"TONUSDT","bids":[],"asks":[["3.1521","1844.0"],["3.1523","2124.5"]],"timestamp":1756900833510,"update_id":50196451,"fetch_time":1756900833559}
{"symbol":"TONUSDT","bids":[],"asks":[["3.1508","1763.6"],["3.1520","2286.7"]],"timestamp":1756900833529,"update_id":50196452,"fetch_time":1756900833583}
{"symbol":"TONUSDT","bids":[],"asks":[["3.1508","1656.8"]],"timestamp":1756900833569,"update_id":50196454,"fetch_time":1756900833620}
{"symbol":"TONUSDT","bids":[],"asks":[["3.1523","1172.4"],["3.1525","1671.7"]],"timestamp":1756900833610,"update_id":50196455,"fetch_time":1756900833671}
{"symbol":"TONUSDT","bids":[],"asks":[["3.1509","46.5"],["3.1528","4358.0"]],"timestamp":1756900833629,"update_id":50196456,"fetch_time":1756900833681}
{"symbol":"TONUSDT","bids":[],"asks":[["3.1507","938.9"]],"timestamp":1756900833790,"update_id":50196458,"fetch_time":1756900833836}
{"symbol":"TONUSDT","bids":[],"asks":[["3.1509","247.5"]],"timestamp":1756900833829,"update_id":50196459,"fetch_time":1756900833887}
{"symbol":"TONUSDT","bids":[["3.1499","154.5"],["3.1494","774.9"],["3.1477","682.8"]],"asks":[],"timestamp":1756900833909,"update_id":50196460,"fetch_time":1756900833959}
{"symbol":"TONUSDT","bids":[],"asks":[["3.1520","3144.1"]],"timestamp":1756900833950,"update_id":50196462,"fetch_time":1756900834002}
{"symbol":"TONUSDT","bids":[],"asks":[["3.1549","1696.7"],["3.1550","4706.0"]],"timestamp":1756900834150,"update_id":50196464,"fetch_time":1756900834202}
{"symbol":"TONUSDT","bids":[["3.1495","211.8"]],"asks":[],"timestamp":1756900834170,"update_id":50196465,"fetch_time":1756900834218}
{"symbol":"TONUSDT","bids":[],"asks":[["3.1523","2014.1"],["3.1549","429.1"],["3.1550","5973.6"]],"timestamp":1756900834189,"update_id":50196466,"fetch_time":1756900834247}
{"symbol":"TONUSDT","bids":[],"asks":[["3.1521","2002.6"]],"timestamp":1756900834409,"update_id":50196467,"fetch_time":1756900834463}
{"symbol":"TONUSDT","bids":[["3.1495","168.5"],["3.1494","791.8"]],"asks":[],"timestamp":1756900834489,"update_id":50196468,"fetch_time":1756900834540}
{"symbol":"TONUSDT","bids":[],"asks":[["3.1506","731.4"]],"timestamp":1756900834509,"update_id":50196469,"fetch_time":1756900834556}
{"symbol":"TONUSDT","bids":[["3.1496","465.0"]],"asks":[],"timestamp":1756900834629,"update_id":50196470,"fetch_time":1756900834679}
{"symbol":"TONUSDT","bids":[],"asks":[["3.1535","784.6"]],"timestamp":1756900834670,"update_id":50196472,"fetch_time":1756900834721}
{"symbol":"TONUSDT","bids":[],"asks":[["3.1549","429.1"],["3.1550","5973.6"]],"timestamp":1756900834770,"update_id":50196474,"fetch_time":1756900834823}
{"symbol":"TONUSDT","bids":[],"asks":[["3.1526","1795.2"]],"timestamp":1756900835050,"update_id":50196475,"fetch_time":1756900835111}
{"symbol":"TONUSDT","bids":[],"asks":[["3.1508","1017.7"],["3.1509","3.2"],["3.1510","1659.4"]],"timestamp":1756900835089,"update_id":50196476,"fetch_time":1756900835143}
{"symbol":"TONUSDT","bids":[["3.1492","1209.1"]],"asks":[],"timestamp":1756900835109,"update_id":50196477,"fetch_time":1756900835159}
{"symbol":"TONUSDT","bids":[["3.1497","1267.3"]],"asks":[],"timestamp":1756900835150,"update_id":50196479,"fetch_time":1756900835204}
{"symbol":"TONUSDT","bids":[["3.1498","430.3"],["3.1495","676.2"]],"asks":[],"timestamp":1756900835169,"update_id":50196480,"fetch_time":1756900835226}
{"symbol":"TONUSDT","bids":[["3.1499","188.4"]],"asks":[],"timestamp":1756900835210,"update_id":50196482,"fetch_time":1756900835260}
{"symbol":"TONUSDT","bids":[],"asks":[["3.1507","755.6"]],"timestamp":1756900835269,"update_id":50196484,"fetch_time":1756900835327}
{"symbol":"TONUSDT","bids":[["3.1497","1679.8"],["3.1496","1256.8"]],"asks":[],"timestamp":1756900835390,"update_id":50196488,"fetch_time":1756900835442}
{"symbol":"TONUSDT","bids":[["3.1498","716.2"],["3.1497","2318.9"]],"asks":[],"timestamp":1756900835409,"update_id":50196489,"fetch_time":1756900835471}
{"symbol":"TONUSDT","bids":[],"asks":[["3.1524","1596.8"],["3.1551","6979.7"],["3.1552","1913.8"]],"timestamp":1756900835470,"update_id":50196491,"fetch_time":1756900835519}
{"symbol":"TONUSDT","bids":[],"asks":[["3.1510","1659.4"],["3.1511","443.4"]],"timestamp":1756900835529,"update_id":50196492,"fetch_time":1756900835580}
{"symbol":"TONUSDT","bids":[["3.1494","866.8"]],"asks":[],"timestamp":1756900835570,"update_id":50196494,"fetch_time":1756900835620}
{"symbol":"TONUSDT","bids":[["3.1495","751.2"]],"asks":[],"timestamp":1756900835610,"update_id":50196495,"fetch_time":1756900835658}
{"symbol":"TONUSDT","bids":[["3.1474","2284.4"]],"asks":[],"timestamp":1756900835650,"update_id":50196497,"fetch_time":1756900835698}
{"symbol":"TONUSDT","bids":[["3.1495","1068.6"]],"asks":[],"timestamp":1756900835670,"update_id":50196498,"fetch_time":1756900835724}
{"symbol":"TONUSDT","bids":[["3.1494","1342.9"]],"asks":[],"timestamp":1756900835690,"update_id":50196499,"fetch_time":1756900835743}
{"symbol":"TONUSDT","bids":[["3.1496","1735.6"]],"asks":[],"timestamp":1756900835710,"update_id":50196500,"fetch_time":1756900835759}
{"symbol":"TONUSDT","bids":[["3.1498","1010.0"]],"asks":[],"timestamp":1756900835729,"update_id":50196501,"fetch_time":1756900835781}
{"symbol":"TONUSDT","bids":[["3.1496","1842.2"],["3.1494","1374.5"]],"asks":[],"timestamp":1756900835950,"update_id":50196505,"fetch_time":1756900835996}
{"symbol":"TONUSDT","bids":[],"asks":[["3.1539","2653.8"]],"timestamp":1756900835989,"update_id":50196506,"fetch_time":1756900836047}
{"symbol":"TONUSDT","bids":[["3.1496","2080.2"]],"asks":[],"timestamp":1756900836010,"update_id":50196507,"fetch_time":1756900836058}
{"symbol":"TONUSDT","bids":[["3.1495","1088.7"]],"asks":[],"timestamp":1756900836069,"update_id":50196510,"fetch_time":1756900836119}
{"symbol":"TONUSDT","bids":[["3.1498","0"],["3.1449","2579.8"]],"asks":[],"timestamp":1756900836290,"update_id":50196511,"fetch_time":1756900836340}
{"symbol":"TONUSDT","bids":[],"asks":[["3.1509","89.7"]],"timestamp":1756900836310,"update_id":50196512,"fetch_time":1756900836356}
{"symbol":"TONUSDT","bids":[["3.1498","1128.5"],["3.1449","0"]],"asks":[],"timestamp":1756900836389,"update_id":50196514,"fetch_time":1756900836439}
{"symbol":"TONUSDT","bids":[["3.1494","1529.6"]],"asks":[],"timestamp":1756900836489,"update_id":50196515,"fetch_time":1756900836551}
{"symbol":"TONUSDT","bids":[["3.1497","2318.9"],["3.1495","1120.1"],["3.1494","1592.9"],["3.1487","779.2"]],"asks":[],"timestamp":1756900836509,"update_id":50196516,"fetch_time":1756900836556}
{"symbol":"TONUSDT","bids":[["3.1483","834.6"]],"asks":[],"timestamp":1756900836569,"update_id":50196517,"fetch_time":1756900836623}
{"symbol":"TONUSDT","bids":[["3.1489","830.0"]],"asks":[],"timestamp":1756900836590,"update_id":50196518,"fetch_time":1756900836644}
{"symbol":"TONUSDT","bids":[["3.1489","1058.4"]],"asks":[],"timestamp":1756900836689,"update_id":50196519,"fetch_time":1756900836737}
{"symbol":"TONUSDT","bids":[["3.1493","128.8"],["3.1480","1284.5"]],"asks":[],"timestamp":1756900836710,"update_id":50196520,"fetch_time":1756900836767}
{"symbol":"TONUSDT","bids":[["3.1493","160.5"]],"asks":[],"timestamp":1756900836730,"update_id":50196521,"fetch_time":1756900836783}
{"symbol":"TONUSDT","bids":[["3.1496","2111.7"],["3.1492","1552.3"]],"asks":[],"timestamp":1756900836749,"update_id":50196522,"fetch_time":1756900836804}
{"symbol":"TONUSDT","bids":[["3.1493","636.6"]],"asks":[],"timestamp":1756900836770,"update_id":50196523,"fetch_time":1756900836823}
{"symbol":"TONUSDT","bids":[["3.1494","1827.7"],["3.1493","954.0"]],"asks":[],"timestamp":1756900836789,"update_id":50196524,"fetch_time":1756900836839}
{"symbol":"TONUSDT","bids":[["3.1493","985.7"]],"asks":[],"timestamp":1756900836850,"update_id":50196525,"fetch_time":1756900836911}
{"symbol":"TONUSDT","bids":[["3.1482","1432.0"]],"asks":[],"timestamp":1756900836949,"update_id":50196526,"fetch_time":1756900837004}
{"symbol":"TONUSDT","bids":[["3.1498","1159.9"]],"asks":[],"timestamp":1756900837010,"update_id":50196527,"fetch_time":1756900837060}
{"symbol":"TONUSDT","bids":[["3.1496","2175.1"]],"asks":[],"timestamp":1756900837209,"update_id":50196529,"fetch_time":1756900837271}
{"symbol":"TONUSDT","bids":[],"asks":[["3.1550","4229.0"],["3.1551","6979.7"]],"timestamp":1756900837289,"update_id":50196532,"fetch_time":1756900837343}
{"symbol":"TONUSDT","bids":[["3.1496","2682.9"]],"asks":[],"timestamp":1756900837409,"update_id":50196533,"fetch_time":1756900837457}
{"symbol":"TONUSDT","bids":[["3.1479","1999.1"],["3.1475","1890.4"]],"asks":[],"timestamp":1756900837429,"update_id":50196534,"fetch_time":1756900837487}
{"symbol":"TONUSDT","bids":[],"asks":[["3.1550","5496.5"],["3.1551","5712.2"]],"timestamp":1756900837469,"update_id":50196535,"fetch_time":1756900837519}
{"symbol":"TONUSDT","bids":[["3.1480","1548.5"]],"asks":[],"timestamp":1756900837750,"update_id":50196536,"fetch_time":1756900837796}
{"symbol":"TONUSDT","bids":[["3.1452","2113.8"]],"asks":[],"timestamp":1756900837830,"update_id":50196537,"fetch_time":1756900837879}
{"symbol":"TONUSDT","bids":[["3.1493","1017.4"]],"asks":[],"timestamp":1756900838109,"update_id":50196538,"fetch_time":1756900838167}
{"symbol":"TONUSDT","bids":[["3.1499","208.1"],["3.1498","1159.9"],["3.1494","1762.4"]],"asks":[],"timestamp":1756900838129,"update_id":50196539,"fetch_time":1756900838177}
{"symbol":"TONUSDT","bids":[["3.1493","974.1"],["3.1477","1160.6"]],"asks":[],"timestamp":1756900838149,"update_id":50196540,"fetch_time":1756900838207}
{"symbol":"TONUSDT","bids":[["3.1497","2301.0"]],"asks":[],"timestamp":1756900838169,"update_id":50196541,"fetch_time":1756900838217}
{"symbol":"TONUSDT","bids":[],"asks":[["3.1506","651.7"]],"timestamp":1756900838449,"update_id":50196544,"fetch_time":1756900838505}
{"symbol":"TONUSDT","bids":[["3.1496","2682.9"]],"asks":[],"timestamp":1756900838529,"update_id":50196545,"fetch_time":1756900838578}
{"symbol":"TONUSDT","bids":[],"asks":[["3.1506","608.5"],["3.1507","798.9"],["3.1508","1061.0"],["3.1509","233.0"]],"timestamp":1756900838629,"update_id":50196546,"fetch_time":1756900838682}
{"symbol":"TONUSDT","bids":[],"asks":[["3.1509","276.2"]],"timestamp":1756900838650,"update_id":50196547,"fetch_time":1756900838711}
{"symbol":"TONUSDT","bids":[],"asks":[["3.1500","2.0"]],"timestamp":1756900838750,"update_id":50196548,"fetch_time":1756900838804}
{"symbol":"TONUSDT","bids":[["3.1472","1031.1"]],"asks":[],"timestamp":1756900838829,"update_id":50196551,"fetch_time":1756900838887}
{"symbol":"TONUSDT","bids":[["3.1495","1120.1"]],"asks":[],"timestamp":1756900839229,"update_id":50196552,"fetch_time":1756900839287}
{"symbol":"TONUSDT","bids":[["3.1485","3302.2"]],"asks":[],"timestamp":1756900839330,"update_id":50196554,"fetch_time":1756900839380}
{"symbol":"TONUSDT","bids":[["3.1499","210.8"]],"asks":[],"timestamp":1756900839470,"update_id":50196555,"fetch_time":1756900839524}
{"symbol":"TONUSDT","bids":[["3.1495","1056.7"]],"asks":[],"timestamp":1756900839509,"update_id":50196556,"fetch_time":1756900839560}
{"symbol":"TONUSDT","bids":[["3.1502","260.9"],["3.1500","1319.2"],["3.1499","315.0"],["3.1498","1264.5"],["3.1497","1575.2"],["3.1496","1745.0"],["3.1495","148.4"],["3.1494","1222.9"],["3.1493","97.1"],["3.1492","1753.1"],["3.1491","856.6"],["3.1490","3384.4"],["3.1489","944.5"],["3.1488","2898.2"],["3.1486","3726.7"],["3.1483","466.9"],["3.1481","927.6"],["3.1479","1455.0"],["3.1477","528.3"],["3.1475","1169.9"],["3.1473","952.1"],["3.1469","463.3"],["3.1466","509.9"],["3.1451","0"],["3.1450","0"]],"asks":[["3.1500","0"],["3.1504","2.4"],["3.1506","565.2"],["3.1507","5.6"],["3.1508","587.0"],["3.1509","189.7"],["3.1511","529.9"],["3.1512","2374.6"],["3.1516","2441.2"],["3.1535","782.6"],["3.1539","2655.8"],["3.1550","4229.0"],["3.1551","6979.7"],["3.1553","592.9"]],"timestamp":1756900839569,"update_id":50196557,"fetch_time":1756900839618}
{"symbol":"TONUSDT","bids":[["3.1502","324.0"],["3.1501","317.4"],["3.1500","2311.4"],["3.1499","441.3"],["3.1498","1019.7"],["3.1497","1618.5"],["3.1496","952.0"],["3.1493","577.7"],["3.1478","837.8"],["3.1474","2072.4"],["3.1452","0"]],"asks":[["3.1506","3.2"],["3.1509","3.2"],["3.1511","764.1"],["3.1515","2636.2"],["3.1519","2256.8"],["3.1523","2014.1"]],"timestamp":1756900839589,"update_id":50196558,"fetch_time":1756900839647}
{"symbol":"TONUSDT","bids":[["3.1503","20.0"],["3.1502","355.5"],["3.1500","2332.8"],["3.1499","449.1"],["3.1498","1648.3"],["3.1497","1745.3"],["3.1495","369.4"],["3.1490","3297.9"],["3.1453","0"]],"asks":[["3.1508","276.4"],["3.1511","1232.4"],["3.1518","2954.2"],["3.1520","3487.9"]],"timestamp":1756900839610,"update_id":50196559,"fetch_time":1756900839659}
{"symbol":"TONUSDT","bids":[["3.1503","51.6"],["3.1502","292.4"],["3.1496","1470.2"]],"asks":[],"timestamp":1756900839710,"update_id":50196564,"fetch_time":1756900839763}
{"symbol":"TONUSDT","bids":[["3.1497","1685.1"],["3.1494","1709.5"],["3.1480","841.5"]],"asks":[],"timestamp":1756900839750,"update_id":50196566,"fetch_time":1756900839813}
{"symbol":"TONUSDT","bids":[["3.1500","2411.1"],["3.1492","2072.8"]],"asks":[],"timestamp":1756900839769,"update_id":50196567,"fetch_time":1756900839823}
{"symbol":"TONUSDT","bids":[["3.1501","699.8"],["3.1500","1903.3"]],"asks":[],"timestamp":1756900839809,"update_id":50196568,"fetch_time":1756900839864}
{"symbol":"TONUSDT","bids":[],"asks":[["3.1518","3175.2"]],"timestamp":1756900839869,"update_id":50196571,"fetch_time":1756900839919}
{"symbol":"TONUSDT","bids":[["3.1500","2168.2"]],"asks":[],"timestamp":1756900839910,"update_id":50196573,"fetch_time":1756900839962}
{"symbol":"TONUSDT","bids":[["3.1497","1635.5"]],"asks":[],"timestamp":1756900839929,"update_id":50196574,"fetch_time":1756900839979}
{"symbol":"TONUSDT","bids":[["3.1497","1663.8"],["3.1496","1470.9"]],"asks":[],"timestamp":1756900839969,"update_id":50196576,"fetch_time":1756900840018}
{"symbol":"TONUSDT","bids":[["3.1500","1898.4"]],"asks":[],"timestamp":1756900840010,"update_id":50196577,"fetch_time":1756900840063}
{"symbol":"TONUSDT","bids":[["3.1498","1683.8"]],"asks":[],"timestamp":1756900840030,"update_id":50196578,"fetch_time":1756900840079}
{"symbol":"TONUSDT","bids":[],"asks":[["3.1508","3.2"]],"timestamp":1756900840049,"update_id":50196579,"fetch_time":1756900840100}
{"symbol":"TONUSDT","bids":[["3.1499","489.2"]],"asks":[],"timestamp":1756900840070,"update_id":50196580,"fetch_time":1756900840122}
{"symbol":"TONUSDT","bids":[],"asks":[["3.1510","1120.0"]],"timestamp":1756900840089,"update_id":50196581,"fetch_time":1756900840151}
{"symbol":"TONUSDT","bids":[],"asks":[["3.1509","3.2"]],"timestamp":1756900840150,"update_id":50196584,"fetch_time":1756900840199}
{"symbol":"TONUSDT","bids":[["3.1498","1652.2"]],"asks":[],"timestamp":1756900840189,"update_id":50196585,"fetch_time":1756900840239}
{"symbol":"TONUSDT","bids":[["3.1503","84.2"]],"asks":[],"timestamp":1756900840210,"update_id":50196586,"fetch_time":1756900840260}
{"symbol":"TONUSDT","bids":[["3.1500","1941.6"]],"asks":[],"timestamp":1756900840229,"update_id":50196587,"fetch_time":1756900840279}
{"symbol":"TONUSDT","bids":[["3.1499","524.7"]],"asks":[],"timestamp":1756900840250,"update_id":50196588,"fetch_time":1756900840300}
{"symbol":"TONUSDT","bids":[],"asks":[["3.1510","833.6"],["3.1511","1383.4"],["3.1512","2436.0"],["3.1513","410.5"]],"timestamp":1756900840289,"update_id":50196589,"fetch_time":1756900840338}
{"symbol":"TONUSDT","bids":[["3.1501","537.8"]],"asks":[],"timestamp":1756900840430,"update_id":50196590,"fetch_time":1756900840476}
{"symbol":"TONUSDT","bids":[["3.1501","403.8"],["3.1500","1329.7"]],"asks":[["3.1504","0"],["3.1511","871.6"],["3.1554","2286.1"]],"timestamp":1756900840510,"update_id":50196593,"fetch_time":1756900840559}
{"symbol":"TONUSDT","bids":[["3.1505","20.0"],["3.1504","20.0"],["3.1503","1.0"],["3.1501","239.3"],["3.1500","1429.2"],["3.1499","430.0"],["3.1486","2926.7"],["3.1469","2269.1"],["3.1455","0"],["3.1454","0"]],"asks":[["3.1505","0"],["3.1506","0"],["3.1511","684.5"],["3.1513","597.6"],["3.1514","4382.0"],["3.1539","2653.8"],["3.1540","2614.6"],["3.1555","586.9"],["3.1556","1836.2"]],"timestamp":1756900840530,"update_id":50196594,"fetch_time":1756900840583}
{"symbol":"TONUSDT","bids":[["3.1504","0"],["3.1502","263.3"],["3.1501","270.9"],["3.1500","794.6"],["3.1499","398.4"],["3.1498","913.9"],["3.1496","1951.1"],["3.1455","1495.6"]],"asks":[["3.1507","2.4"],["3.1511","126.1"],["3.1513","917.4"],["3.1515","2679.4"],["3.1533","1197.7"],["3.1540","2612.6"],["3.1542","5124.1"],["3.1553","874.1"]],"timestamp":1756900840550,"update_id":50196595,"fetch_time":1756900840604}
{"symbol":"TONUSDT","bids":[["3.1505","0"],["3.1500","334.7"],["3.1498","1123.4"],["3.1497","1135.6"],["3.1495","526.2"],["3.1454","3576.8"]],"asks":[["3.1509","36.2"],["3.1512","2105.0"],["3.1513","1182.9"],["3.1514","4238.0"]],"timestamp":1756900840670,"update_id":50196601,"fetch_time":1756900840727}
{"symbol":"TONUSDT","bids":[["3.1498","1028.1"]],"asks":[["3.1508","0"],["3.1509","334.5"],["3.1523","2014.1"],["3.1526","3014.4"],["3.1557","2778.6"]],"timestamp":1756900840709,"update_id":50196603,"fetch_time":1756900840759}
{"symbol":"TONUSDT","bids":[["3.1497","1135.5"]],"asks":[["3.1508","17.1"],["3.1510","456.3"],["3.1511","371.2"],["3.1557","0"]],"timestamp":1756900840729,"update_id":50196604,"fetch_time":1756900840783}
{"symbol":"TONUSDT","bids":[["3.1470","3166.7"]],"asks":[],"timestamp":1756900840829,"update_id":50196607,"fetch_time":1756900840876}
{"symbol":"TONUSDT","bids":[["3.1494","1709.5"],["3.1493","858.9"]],"asks":[],"timestamp":1756900840870,"update_id":50196608,"fetch_time":1756900840919}
{"symbol":"TONUSDT","bids":[["3.1490","4097.9"]],"asks":[],"timestamp":1756900841169,"update_id":50196610,"fetch_time":1756900841231}
{"symbol":"TONUSDT","bids":[],"asks":[["3.1510","488.0"],["3.1511","1188.2"],["3.1512","2136.7"]],"timestamp":1756900841350,"update_id":50196611,"fetch_time":1756900841402}
{"symbol":"TONUSDT","bids":[["3.1492","1587.0"]],"asks":[],"timestamp":1756900841429,"update_id":50196613,"fetch_time":1756900841484}
{"symbol":"TONUSDT","bids":[["3.1490","2665.7"]],"asks":[["3.1506","28.8"],["3.1511","1569.0"],["3.1512","2417.7"],["3.1541","988.5"],["3.1542","5122.1"],["3.1556","0"]],"timestamp":1756900841450,"update_id":50196614,"fetch_time":1756900841503}
{"symbol":"TONUSDT","bids":[],"asks":[["3.1511","1600.7"],["3.1512","2792.0"]],"timestamp":1756900841490,"update_id":50196616,"fetch_time":1756900841540}
{"symbol":"TONUSDT","bids":[],"asks":[["3.1510","1098.6"],["3.1512","3388.3"]],"timestamp":1756900841510,"update_id":50196617,"fetch_time":1756900841562}
{"symbol":"TONUSDT","bids":[],"asks":[["3.1507","156.6"],["3.1508","403.9"],["3.1515","2636.2"],["3.1522","2768.5"],["3.1526","2062.4"]],"timestamp":1756900841530,"update_id":50196618,"fetch_time":1756900841591}
{"symbol":"TONUSDT","bids":[],"asks":[["3.1511","2225.3"],["3.1513","246.5"]],"timestamp":1756900841610,"update_id":50196622,"fetch_time":1756900841663}
{"symbol":"TONUSDT","bids":[],"asks":[["3.1550","4229.0"],["3.1551","6979.7"]],"timestamp":1756900841649,"update_id":50196623,"fetch_time":1756900841705}
{"symbol":"TONUSDT","bids":[],"asks":[["3.1510","1224.9"],["3.1519","3056.8"]],"timestamp":1756900841689,"update_id":50196624,"fetch_time":1756900841740}
{"symbol":"TONUSDT","bids":[],"asks":[["3.1508","260.6"],["3.1509","853.9"]],"timestamp":1756900841709,"update_id":50196625,"fetch_time":1756900841757}
{"symbol":"TONUSDT","bids":[["3.1478","1614.9"]],"asks":[],"timestamp":1756900841829,"update_id":50196627,"fetch_time":1756900841879}
{"symbol":"TONUSDT","bids":[],"asks":[["3.1551","5712.2"]],"timestamp":1756900842009,"update_id":50196628,"fetch_time":1756900842058}
{"symbol":"TONUSDT","bids":[],"asks":[["3.1551","6979.7"]],"timestamp":1756900842070,"update_id":50196629,"fetch_time":1756900842118}
{"symbol":"TONUSDT","bids":[["3.1496","1748.7"]],"asks":[],"timestamp":1756900842190,"update_id":50196635,"fetch_time":1756900842242}
{"symbol":"TONUSDT","bids":[],"asks":[["3.1551","5712.2"],["3.1552","3181.3"]],"timestamp":1756900842250,"update_id":50196638,"fetch_time":1756900842293}
{"symbol":"TONUSDT","bids":[],"asks":[["3.1513","246.5"]],"timestamp":1756900842330,"update_id":50196639,"fetch_time":1756900842378}
{"symbol":"TONUSDT","bids":[],"asks":[["3.1508","31.7"]],"timestamp":1756900842449,"update_id":50196642,"fetch_time":1756900842498}
{"symbol":"TONUSDT","bids":[],"asks":[["3.1533","749.5"]],"timestamp":1756900842530,"update_id":50196643,"fetch_time":1756900842581}
{"symbol":"TONUSDT","bids":[],"asks":[["3.1511","1967.9"]],"timestamp":1756900842550,"update_id":50196644,"fetch_time":1756900842598}
{"symbol":"TONUSDT","bids":[],"asks":[["3.1551","6979.7"],["3.1552","1913.8"]],"timestamp":1756900842569,"update_id":50196645,"fetch_time":1756900842613}
{"symbol":"TONUSDT","bids":[],"asks":[["3.1511","1999.4"]],"timestamp":1756900842690,"update_id":50196646,"fetch_time":1756900842733}
{"symbol":"TONUSDT","bids":[],"asks":[["3.1551","5712.2"],["3.1552","3181.3"]],"timestamp":1756900842810,"update_id":50196647,"fetch_time":1756900842857}
{"symbol":"TONUSDT","bids":[["3.1474","2775.4"]],"asks":[],"timestamp":1756900842829,"update_id":50196648,"fetch_time":1756900842873}
{"symbol":"TONUSDT","bids":[],"asks":[["3.1551","6979.7"],["3.1552","1913.8"]],"timestamp":1756900842950,"update_id":50196649,"fetch_time":1756900843002}
{"symbol":"TONUSDT","bids":[],"asks":[["3.1551","5712.2"],["3.1552","3181.3"]],"timestamp":1756900842970,"update_id":50196650,"fetch_time":1756900843013}
{"symbol":"TONUSDT","bids":[["3.1486","2576.7"],["3.1484","2590.8"]],"asks":[],"timestamp":1756900843070,"update_id":50196652,"fetch_time":1756900843113}
{"symbol":"TONUSDT","bids":[["3.1500","386.8"],["3.1499","369.3"]],"asks":[],"timestamp":1756900843270,"update_id":50196653,"fetch_time":1756900843313}
{"symbol":"TONUSDT","bids":[["3.1496","1213.5"],["3.1495","509.5"]],"asks":[],"timestamp":1756900843289,"update_id":50196654,"fetch_time":1756900843333}
{"symbol":"TONUSDT","bids":[],"asks":[["3.1510","1568.3"]],"timestamp":1756900843329,"update_id":50196656,"fetch_time":1756900843373}
{"symbol":"TONUSDT","bids":[["3.1498","695.2"]],"asks":[],"timestamp":1756900843430,"update_id":50196657,"fetch_time":1756900843473}
{"symbol":"TONUSDT","bids":[],"asks":[["3.1511","2031.1"]],"timestamp":1756900843970,"update_id":50196659,"fetch_time":1756900844013}
{"symbol":"TONUSDT","bids":[["3.1500","581.5"]],"asks":[],"timestamp":1756900844009,"update_id":50196661,"fetch_time":1756900844057}
{"symbol":"TONUSDT","bids":[["3.1501","138.2"]],"asks":[],"timestamp":1756900844030,"update_id":50196662,"fetch_time":1756900844073}
{"symbol":"TONUSDT","bids":[],"asks":[["3.1511","2272.3"],["3.1512","3451.5"]],"timestamp":1756900844049,"update_id":50196663,"fetch_time":1756900844094}
{"symbol":"TONUSDT","bids":[["3.1496","1213.5"],["3.1495","509.5"],["3.1494","939.8"]],"asks":[],"timestamp":1756900844149,"update_id":50196664,"fetch_time":1756900844202}
{"symbol":"TONUSDT","bids":[["3.1499","326.0"]],"asks":[],"timestamp":1756900844449,"update_id":50196665,"fetch_time":1756900844497}
{"symbol":"TONUSDT","bids":[["3.1498","738.4"]],"asks":[],"timestamp":1756900844630,"update_id":50196667,"fetch_time":1756900844673}
{"symbol":"TONUSDT","bids":[["3.1500","624.7"],["3.1499","369.2"]],"asks":[],"timestamp":1756900844730,"update_id":50196668,"fetch_time":1756900844773}
{"symbol":"TONUSDT","bids":[],"asks":[["3.1511","2031.1"]],"timestamp":1756900844810,"update_id":50196669,"fetch_time":1756900844853}
{"symbol":"TONUSDT","bids":[],"asks":[["3.1512","3692.6"]],"timestamp":1756900844829,"update_id":50196670,"fetch_time":1756900844873}
{"symbol":"TONUSDT","bids":[],"asks":[["3.1510","1525.1"]],"timestamp":1756900844930,"update_id":50196671,"fetch_time":1756900844977}
{"symbol":"TONUSDT","bids":[],"asks":[["3.1511","1967.7"]],"timestamp":1756900844970,"update_id":50196672,"fetch_time":1756900845013}
{"symbol":"TONUSDT","bids":[],"asks":[["3.1511","1825.2"],["3.1512","3661.0"]],"timestamp":1756900845010,"update_id":50196673,"fetch_time":1756900845057}
{"symbol":"TONUSDT","bids":[],"asks":[["3.1553","991.3"]],"timestamp":1756900845030,"update_id":50196674,"fetch_time":1756900845073}
{"symbol":"TONUSDT","bids":[],"asks":[["3.1511","1793.5"],["3.1545","1008.7"],["3.1554","2372.7"]],"timestamp":1756900845110,"update_id":50196675,"fetch_time":1756900845153}
{"symbol":"TONUSDT","bids":[],"asks":[["3.1510","1568.3"]],"timestamp":1756900845670,"update_id":50196677,"fetch_time":1756900845714}
{"symbol":"TONUSDT","bids":[["3.1469","463.3"],["3.1468","6130.6"]],"asks":[],"timestamp":1756900845769,"update_id":50196678,"fetch_time":1756900845813}
{"symbol":"TONUSDT","bids":[],"asks":[["3.1510","1536.6"],["3.1511","979.9"]],"timestamp":1756900846369,"update_id":50196679,"fetch_time":1756900846413}
{"symbol":"TONUSDT","bids":[],"asks":[["3.1551","5712.2"],["3.1552","3181.3"]],"timestamp":1756900846529,"update_id":50196681,"fetch_time":1756900846574}
{"symbol":"TONUSDT","bids":[],"asks":[["3.1513","246.5"]],"timestamp":1756900846589,"update_id":50196682,"fetch_time":1756900846633}
{"symbol":"TONUSDT","bids":[],"asks":[["3.1511","905.0"]],"timestamp":1756900846950,"update_id":50196683,"fetch_time":1756900846993}
{"symbol":"TONUSDT","bids":[["3.1501","138.2"]],"asks":[],"timestamp":1756900847010,"update_id":50196684,"fetch_time":1756900847053}
{"symbol":"TONUSDT","bids":[],"asks":[["3.1511","873.3"]],"timestamp":1756900847029,"update_id":50196685,"fetch_time":1756900847073}
{"symbol":"TONUSDT","bids":[],"asks":[["3.1510","1536.7"]],"timestamp":1756900847189,"update_id":50196686,"fetch_time":1756900847233}
{"symbol":"TONUSDT","bids":[["3.1499","413.3"]],"asks":[],"timestamp":1756900847249,"update_id":50196687,"fetch_time":1756900847293}
{"symbol":"TONUSDT","bids":[],"asks":[["3.1511","798.3"]],"timestamp":1756900847369,"update_id":50196689,"fetch_time":1756900847413}
{"symbol":"TONUSDT","bids":[["3.1496","1522.2"],["3.1495","212.3"]],"asks":[],"timestamp":1756900847470,"update_id":50196691,"fetch_time":1756900847513}
{"symbol":"TONUSDT","bids":[],"asks":[["3.1510","1536.7"]],"timestamp":1756900847549,"update_id":50196692,"fetch_time":1756900847593}
{"symbol":"TONUSDT","bids":[["3.1485","3365.7"]],"asks":[],"timestamp":1756900847570,"update_id":50196693,"fetch_time":1756900847613}
{"symbol":"TONUSDT","bids":[["3.1500","581.5"],["3.1499","326.0"]],"asks":[],"timestamp":1756900847669,"update_id":50196694,"fetch_time":1756900847713}
{"symbol":"TONUSDT","bids":[],"asks":[["3.1509","64.2"],["3.1511","884.8"]],"timestamp":1756900847689,"update_id":50196695,"fetch_time":1756900847733}
{"symbol":"TONUSDT","bids":[],"asks":[["3.1551","6979.7"],["3.1552","1913.8"]],"timestamp":1756900848009,"update_id":50196696,"fetch_time":1756900848053}
{"symbol":"TONUSDT","bids":[],"asks":[["3.1510","1579.9"]],"timestamp":1756900848030,"update_id":50196697,"fetch_time":1756900848073}
{"symbol":"TONUSDT","bids":[],"asks":[["3.1508","70.9"],["3.1551","5712.2"],["3.1552","3181.3"]],"timestamp":1756900848049,"update_id":50196698,"fetch_time":1756900848093}
{"symbol":"TONUSDT","bids":[],"asks":[["3.1551","6979.7"],["3.1552","1913.8"]],"timestamp":1756900848130,"update_id":50196700,"fetch_time":1756900848178}
{"symbol":"TONUSDT","bids":[["3.1505","41.2"],["3.1499","304.0"],["3.1496","1522.2"],["3.1454","0"]],"asks":[],"timestamp":1756900848350,"update_id":50196702,"fetch_time":1756900848393}
{"symbol":"TONUSDT","bids":[],"asks":[["3.1508","565.1"],["3.1512","3594.1"],["3.1513","278.1"]],"timestamp":1756900848470,"update_id":50196708,"fetch_time":1756900848513}
{"symbol":"TONUSDT","bids":[],"asks":[["3.1507","575.1"],["3.1508","596.4"],["3.1509","173.5"]],"timestamp":1756900848489,"update_id":50196709,"fetch_time":1756900848533}
{"symbol":"TONUSDT","bids":[],"asks":[["3.1507","592.5"],["3.1508","624.4"]],"timestamp":1756900848510,"update_id":50196710,"fetch_time":1756900848553}
{"symbol":"TONUSDT","bids":[],"asks":[["3.1511","1124.3"]],"timestamp":1756900848530,"update_id":50196711,"fetch_time":1756900848585}
{"symbol":"TONUSDT","bids":[["3.1483","492.1"]],"asks":[],"timestamp":1756900848569,"update_id":50196712,"fetch_time":1756900848618}
{"symbol":"TONUSDT","bids":[],"asks":[["3.1510","2500.2"],["3.1550","5496.5"],["3.1551","5712.2"]],"timestamp":1756900848669,"update_id":50196713,"fetch_time":1756900848713}
{"symbol":"TONUSDT","bids":[],"asks":[["3.1550","4229.0"],["3.1551","6979.7"]],"timestamp":1756900848690,"update_id":50196714,"fetch_time":1756900848733}
{"symbol":"TONUSDT","bids":[],"asks":[["3.1510","2531.9"],["3.1519","3050.5"],["3.1550","5496.5"],["3.1551","5712.2"]],"timestamp":1756900848710,"update_id":50196715,"fetch_time":1756900848761}
{"symbol":"TONUSDT","bids":[["3.1500","403.0"]],"asks":[],"timestamp":1756900848790,"update_id":50196717,"fetch_time":1756900848837}
{"symbol":"TONUSDT","bids":[],"asks":[["3.1508","939.4"],["3.1511","1155.0"]],"timestamp":1756900848809,"update_id":50196718,"fetch_time":1756900848853}
{"symbol":"TONUSDT","bids":[],"asks":[["3.1510","2595.3"]],"timestamp":1756900848829,"update_id":50196719,"fetch_time":1756900848873}
{"symbol":"TONUSDT","bids":[],"asks":[["3.1550","4229.0"],["3.1551","6979.7"]],"timestamp":1756900849250,"update_id":50196720,"fetch_time":1756900849293}
{"symbol":"TONUSDT","bids":[],"asks":[["3.1509","236.5"],["3.1511","1340.3"],["3.1512","4165.3"]],"timestamp":1756900849349,"update_id":50196721,"fetch_time":1756900849393}
{"symbol":"TONUSDT","bids":[],"asks":[["3.1511","1403.7"]],"timestamp":1756900849369,"update_id":50196722,"fetch_time":1756900849413}
{"symbol":"TONUSDT","bids":[],"asks":[["3.1507","584.0"],["3.1515","2722.7"]],"timestamp":1756900849390,"update_id":50196723,"fetch_time":1756900849438}
{"symbol":"TONUSDT","bids":[],"asks":[["3.1506","232.0"],["3.1507","615.5"],["3.1508","971.1"],["3.1509","807.7"],["3.1510","2658.4"],["3.1511","2355.6"]],"timestamp":1756900849469,"update_id":50196724,"fetch_time":1756900849513}
{"symbol":"TONUSDT","bids":[["3.1499","632.2"],["3.1498","775.3"]],"asks":[],"timestamp":1756900849529,"update_id":50196726,"fetch_time":1756900849573}
{"symbol":"TONUSDT","bids":[],"asks":[["3.1510","3547.0"],["3.1511","2450.6"],["3.1512","4666.8"]],"timestamp":1756900849589,"update_id":50196728,"fetch_time":1756900849633}
{"symbol":"TONUSDT","bids":[],"asks":[["3.1518","3363.4"],["3.1520","4838.2"],["3.1522","3182.5"],["3.1524","2123.7"],["3.1526","2702.2"],["3.1528","4475.5"],["3.1544","3025.2"],["3.1546","2209.8"],["3.1548","3386.8"],["3.1550","3702.1"],["3.1552","1274.0"],["3.1554","1620.0"]],"timestamp":1756900849630,"update_id":50196729,"fetch_time":1756900849674}
{"symbol":"TONUSDT","bids":[],"asks":[["3.1509","839.3"],["3.1512","4730.2"],["3.1518","3929.7"],["3.1548","2910.7"],["3.1553","401.6"]],"timestamp":1756900849649,"update_id":50196730,"fetch_time":1756900849693}
{"symbol":"TONUSDT","bids":[],"asks":[["3.1552","1784.4"]],"timestamp":1756900849669,"update_id":50196731,"fetch_time":1756900849713}
{"symbol":"TONUSDT","bids":[],"asks":[["3.1510","3578.7"]],"timestamp":1756900849690,"update_id":50196732,"fetch_time":1756900849733}
{"symbol":"TONUSDT","bids":[],"asks":[["3.1511","2926.7"]],"timestamp":1756900849709,"update_id":50196733,"fetch_time":1756900849757}
{"symbol":"TONUSDT","bids":[],"asks":[["3.1510","4123.1"]],"timestamp":1756900849729,"update_id":50196734,"fetch_time":1756900849773}
{"symbol":"TONUSDT","bids":[],"asks":[["3.1507","1324.6"]],"timestamp":1756900849750,"update_id":50196735,"fetch_time":1756900849793}
{"symbol":"TONUSDT","bids":[],"asks":[["3.1509","821.6"],["3.1510","4143.6"],["3.1514","4176.7"],["3.1516","2505.7"]],"timestamp":1756900849809,"update_id":50196736,"fetch_time":1756900849857}
{"symbol":"TONUSDT","bids":[],"asks":[["3.1508","943.6"],["3.1509","773.9"]],"timestamp":1756900849829,"update_id":50196737,"fetch_time":1756900849877}
{"symbol":"TONUSDT","bids":[],"asks":[["3.1510","4111.9"]],"timestamp":1756900849850,"update_id":50196738,"fetch_time":1756900849893}
{"symbol":"TONUSDT","bids":[],"asks":[["3.1510","4080.2"]],"timestamp":1756900849869,"update_id":50196739,"fetch_time":1756900849913}
{"symbol":"TONUSDT","bids":[["3.1488","1900.3"],["3.1487","588.2"],["3.1486","1812.7"],["3.1485","2983.7"],["3.1484","2399.8"]],"asks":[],"timestamp":1756900849929,"update_id":50196740,"fetch_time":1756900849977}
{"symbol":"TONUSDT","bids":[["3.1488","1431.0"]],"asks":[],"timestamp":1756900849950,"update_id":50196741,"fetch_time":1756900849993}
{"symbol":"TONUSDT","bids":[["3.1495","668.3"],["3.1494","853.3"],["3.1490","2824.3"],["3.1485","2825.1"]],"asks":[],"timestamp":1756900850049,"update_id":50196742,"fetch_time":1756900850093}
{"symbol":"TONUSDT","bids":[],"asks":[["3.1507","1315.7"],["3.1508","915.6"],["3.1509","730.6"]],"timestamp":1756900850069,"update_id":50196743,"fetch_time":1756900850113}
{"symbol":"TONUSDT","bids":[],"asks":[["3.1506","222.9"]],"timestamp":1756900850149,"update_id":50196744,"fetch_time":1756900850193}
{"symbol":"TONUSDT","bids":[],"asks":[["3.1520","3776.1"],["3.1523","1172.4"]],"timestamp":1756900850170,"update_id":50196745,"fetch_time":1756900850213}
{"symbol":"TONUSDT","bids":[["3.1495","406.6"]],"asks":[],"timestamp":1756900850190,"update_id":50196746,"fetch_time":1756900850237}
{"symbol":"TONUSDT","bids":[["3.1503","3.0"]],"asks":[],"timestamp":1756900850229,"update_id":50196747,"fetch_time":1756900850273}
{"symbol":"TONUSDT","bids":[],"asks":[["3.1511","2718.8"]],"timestamp":1756900850289,"update_id":50196749,"fetch_time":1756900850333}
{"symbol":"TONUSDT","bids":[],"asks":[["3.1507","1324.2"],["3.1508","962.5"],["3.1509","815.2"]],"timestamp":1756900850329,"update_id":50196751,"fetch_time":1756900850373}
{"symbol":"TONUSDT","bids":[],"asks":[["3.1508","994.2"]],"timestamp":1756900850430,"update_id":50196752,"fetch_time":1756900850473}
{"symbol":"TONUSDT","bids":[],"asks":[["3.1512","5047.6"]],"timestamp":1756900850470,"update_id":50196753,"fetch_time":1756900850513}
{"symbol":"TONUSDT","bids":[],"asks":[["3.1507","1333.1"],["3.1512","5381.2"]],"timestamp":1756900850490,"update_id":50196754,"fetch_time":1756900850534}
{"symbol":"TONUSDT","bids":[],"asks":[["3.1509","910.3"]],"timestamp":1756900850690,"update_id":50196755,"fetch_time":1756900850733}
{"symbol":"TONUSDT","bids":[["3.1505","0"],["3.1500","3.2"],["3.1499","22.3"],["3.1498","588.5"],["3.1497","765.2"],["3.1480","1200.1"],["3.1454","3576.8"]],"asks":[["3.1504","272.9"],["3.1505","58.5"],["3.1506","226.9"],["3.1507","907.6"],["3.1508","1091.7"],["3.1509","562.9"],["3.1510","3387.5"],["3.1511","3019.9"],["3.1513","723.7"],["3.1514","4090.2"],["3.1515","3163.1"],["3.1517","1968.5"],["3.1520","3475.0"],["3.1522","2768.5"],["3.1524","1596.8"],["3.1526","2062.4"],["3.1528","3722.8"],["3.1539","2655.8"],["3.1541","986.5"],["3.1554","0"],["3.1555","0"]],"timestamp":1756900851009,"update_id":50196756,"fetch_time":1756900851054}
{"symbol":"TONUSDT","bids":[["3.1495","192.0"],["3.1486","1782.7"],["3.1484","2366.3"],["3.1479","666.3"]],"asks":[],"timestamp":1756900851169,"update_id":50196764,"fetch_time":1756900851217}
{"symbol":"TONUSDT","bids":[["3.1480","1391.1"]],"asks":[],"timestamp":1756900851190,"update_id":50196765,"fetch_time":1756900851237}
{"symbol":"TONUSDT","bids":[["3.1490","2665.7"]],"asks":[],"timestamp":1756900851230,"update_id":50196766,"fetch_time":1756900851273}
{"symbol":"TONUSDT","bids":[["3.1495","378.8"],["3.1493","772.4"],["3.1491","704.9"]],"asks":[],"timestamp":1756900851249,"update_id":50196767,"fetch_time":1756900851293}
{"symbol":"TONUSDT","bids":[["3.1496","210.3"],["3.1495","248.7"]],"asks":[],"timestamp":1756900851269,"update_id":50196768,"fetch_time":1756900851313}
{"symbol":"TONUSDT","bids":[["3.1495","312.1"],["3.1479","857.3"]],"asks":[],"timestamp":1756900851290,"update_id":50196769,"fetch_time":1756900851333}
{"symbol":"TONUSDT","bids":[["3.1494","673.4"]],"asks":[],"timestamp":1756900851349,"update_id":50196770,"fetch_time":1756900851397}
{"symbol":"TONUSDT","bids":[["3.1494","610.0"],["3.1478","1396.4"]],"asks":[],"timestamp":1756900851390,"update_id":50196771,"fetch_time":1756900851433}
{"symbol":"TONUSDT","bids":[["3.1496","154.3"]],"asks":[],"timestamp":1756900851409,"update_id":50196772,"fetch_time":1756900851453}
{"symbol":"TONUSDT","bids":[],"asks":[["3.1506","1276.4"],["3.1507","963.1"]],"timestamp":1756900851470,"update_id":50196775,"fetch_time":1756900851521}
{"symbol":"TONUSDT","bids":[["3.1503","0"],["3.1502","0"],["3.1498","3.2"],["3.1453","12269.2"],["3.1452","1711.1"]],"asks":[],"timestamp":1756900851629,"update_id":50196778,"fetch_time":1756900851673}
{"symbol":"TONUSDT","bids":[["3.1501","0"],["3.1500","0"],["3.1478","1219.8"],["3.1476","1719.1"],["3.1474","2497.1"],["3.1472","1031.1"],["3.1470","3166.7"],["3.1468","3516.2"],["3.1451","1460.4"],["3.1450","1633.2"]],"asks":[["3.1501","140.0"],["3.1502","147.7"],["3.1503","54.9"],["3.1504","252.5"],["3.1505","814.5"],["3.1506","829.8"],["3.1507","1710.1"],["3.1508","1717.6"],["3.1509","1792.5"],["3.1510","3261.7"],["3.1511","698.8"],["3.1512","2408.9"],["3.1513","629.0"],["3.1517","1328.7"],["3.1518","3238.7"],["3.1537","1415.1"],["3.1539","2653.8"],["3.1549","2344.7"],["3.1550","3702.1"],["3.1551","0"],["3.1552","0"],["3.1553","0"]],"timestamp":1756900851650,"update_id":50196779,"fetch_time":1756900851693}
{"symbol":"TONUSDT","bids":[["3.1499","2.4"],["3.1495","61.9"],["3.1493","491.2"],["3.1491","443.1"],["3.1489","911.5"],["3.1488","1632.2"],["3.1483","747.7"],["3.1480","1483.1"],["3.1470","2465.1"],["3.1465","715.6"]],"asks":[["3.1501","276.5"],["3.1502","0"],["3.1503","399.8"],["3.1504","289.8"],["3.1505","1603.2"],["3.1506","1206.9"],["3.1507","2018.0"],["3.1508","1780.9"],["3.1510","1138.6"],["3.1512","2377.2"],["3.1536","1948.6"],["3.1537","1413.1"],["3.1551","5712.2"]],"timestamp":1756900851669,"update_id":50196780,"fetch_time":1756900851713}
{"symbol":"TONUSDT","bids":[["3.1499","0"],["3.1496","5.6"],["3.1494","438.6"],["3.1467","3272.6"],["3.1449","3436.4"]],"asks":[["3.1501","140.0"],["3.1502","395.1"],["3.1504","560.9"],["3.1505","1634.8"],["3.1507","2261.3"],["3.1510","1620.8"],["3.1512","2597.9"],["3.1513","215.0"],["3.1515","3677.8"],["3.1519","1272.4"],["3.1549","1077.1"],["3.1550","5826.3"],["3.1551","0"]],"timestamp":1756900851689,"update_id":50196781,"fetch_time":1756900851733}
{"symbol":"TONUSDT","bids":[],"asks":[["3.1502","206.9"],["3.1504","940.5"],["3.1506","1749.5"],["3.1507","1995.5"],["3.1508","425.8"]],"timestamp":1756900851789,"update_id":50196786,"fetch_time":1756900851833}
{"symbol":"TONUSDT","bids":[],"asks":[["3.1504","803.2"],["3.1508","589.5"]],"timestamp":1756900851829,"update_id":50196788,"fetch_time":1756900851877}
{"symbol":"TONUSDT","bids":[["3.1474","1694.9"]],"asks":[],"timestamp":1756900851870,"update_id":50196790,"fetch_time":1756900851913}
{"symbol":"TONUSDT","bids":[],"asks":[["3.1549","1077.1"]],"timestamp":1756900851889,"update_id":50196791,"fetch_time":1756900851933}
{"symbol":"TONUSDT","bids":[],"asks":[["3.1504","771.5"]],"timestamp":1756900851929,"update_id":50196792,"fetch_time":1756900851973}
{"symbol":"TONUSDT","bids":[],"asks":[["3.1549","2344.7"]],"timestamp":1756900851950,"update_id":50196793,"fetch_time":1756900851998}
{"symbol":"TONUSDT","bids":[],"asks":[["3.1504","951.3"]],"timestamp":1756900852010,"update_id":50196795,"fetch_time":1756900852054}
{"symbol":"TONUSDT","bids":[],"asks":[["3.1508","894.0"]],"timestamp":1756900852030,"update_id":50196796,"fetch_time":1756900852073}
{"symbol":"TONUSDT","bids":[],"asks":[["3.1517","1170.1"]],"timestamp":1756900852070,"update_id":50196797,"fetch_time":1756900852114}
{"symbol":"TONUSDT","bids":[["3.1480","1674.1"]],"asks":[],"timestamp":1756900852109,"update_id":50196798,"fetch_time":1756900852153}
{"symbol":"TONUSDT","bids":[],"asks":[["3.1504","1086.0"]],"timestamp":1756900852130,"update_id":50196799,"fetch_time":1756900852173}
{"symbol":"TONUSDT","bids":[["3.1449","3245.4"]],"asks":[],"timestamp":1756900852169,"update_id":50196800,"fetch_time":1756900852214}
{"symbol":"TONUSDT","bids":[],"asks":[["3.1507","1963.8"],["3.1509","514.0"]],"timestamp":1756900852389,"update_id":50196801,"fetch_time":1756900852433}
{"symbol":"TONUSDT","bids":[["3.1478","1410.8"]],"asks":[],"timestamp":1756900852429,"update_id":50196802,"fetch_time":1756900852473}
{"symbol":"TONUSDT","bids":[],"asks":[["3.1503","23.3"],["3.1504","1054.3"],["3.1505","343.7"],["3.1507","1869.8"]],"timestamp":1756900852489,"update_id":50196804,"fetch_time":1756900852534}
{"symbol":"TONUSDT","bids":[],"asks":[["3.1505","312.0"]],"timestamp":1756900852529,"update_id":50196806,"fetch_time":1756900852573}
{"symbol":"TONUSDT","bids":[],"asks":[["3.1505","280.5"]],"timestamp":1756900852549,"update_id":50196807,"fetch_time":1756900852593}
{"symbol":"TONUSDT","bids":[["3.1484","2429.8"]],"asks":[],"timestamp":1756900852570,"update_id":50196808,"fetch_time":1756900852613}
{"symbol":"TONUSDT","bids":[["3.1473","1035.3"]],"asks":[],"timestamp":1756900852610,"update_id":50196810,"fetch_time":1756900852653}
{"symbol":"TONUSDT","bids":[["3.1492","1543.7"],["3.1489","954.8"]],"asks":[],"timestamp":1756900852710,"update_id":50196812,"fetch_time":1756900852754}
{"symbol":"TONUSDT","bids":[],"asks":[["3.1503","11.4"]],"timestamp":1756900852729,"update_id":50196813,"fetch_time":1756900852773}
{"symbol":"TONUSDT","bids":[],"asks":[["3.1549","1077.1"]],"timestamp":1756900852770,"update_id":50196814,"fetch_time":1756900852821}
{"symbol":"TONUSDT","bids":[],"asks":[["3.1549","2344.7"]],"timestamp":1756900852809,"update_id":50196815,"fetch_time":1756900852853}
{"symbol":"TONUSDT","bids":[],"asks":[["3.1549","1077.1"]],"timestamp":1756900852830,"update_id":50196816,"fetch_time":1756900852873}
{"symbol":"TONUSDT","bids":[["3.1474","2113.9"]],"asks":[],"timestamp":1756900853630,"update_id":50196817,"fetch_time":1756900853673}
{"symbol":"TONUSDT","bids":[],"asks":[["3.1549","2344.7"]],"timestamp":1756900853710,"update_id":50196818,"fetch_time":1756900853757}
{"symbol":"TONUSDT","bids":[],"asks":[["3.1549","1077.1"]],"timestamp":1756900853870,"update_id":50196819,"fetch_time":1756900853913}
{"symbol":"TONUSDT","bids":[["3.1490","2752.2"]],"asks":[],"timestamp":1756900853890,"update_id":50196820,"fetch_time":1756900853937}
{"symbol":"TONUSDT","bids":[["3.1493","784.6"],["3.1491","730.8"],["3.1489","998.0"]],"asks":[["3.1503","0"],["3.1551","6979.8"]],"timestamp":1756900853929,"update_id":50196821,"fetch_time":1756900853973}
{"symbol":"TONUSDT","bids":[["3.1499","1.7"],["3.1485","2844.8"],["3.1449","0"]],"asks":[["3.1550","5826.3"],["3.1551","5712.2"]],"timestamp":1756900853989,"update_id":50196822,"fetch_time":1756900854033}
{"symbol":"TONUSDT","bids":[],"asks":[["3.1502","0"],["3.1504","618.5"],["3.1509","514.0"],["3.1512","2899.0"],["3.1515","4091.8"],["3.1518","3765.6"],["3.1521","2484.6"],["3.1524","2349.5"],["3.1527","506.9"],["3.1530","2826.0"],["3.1533","749.5"],["3.1534","1238.2"],["3.1536","1948.6"],["3.1539","2653.8"],["3.1542","5122.1"],["3.1552","1784.4"]],"timestamp":1756900854029,"update_id":50196824,"fetch_time":1756900854074}
{"symbol":"TONUSDT","bids":[],"asks":[["3.1504","616.2"],["3.1520","3782.1"]],"timestamp":1756900854050,"update_id":50196825,"fetch_time":1756900854093}
{"symbol":"TONUSDT","bids":[["3.1493","721.2"]],"asks":[],"timestamp":1756900854110,"update_id":50196826,"fetch_time":1756900854153}
{"symbol":"TONUSDT","bids":[["3.1466","266.3"]],"asks":[],"timestamp":1756900854210,"update_id":50196827,"fetch_time":1756900854257}
{"symbol":"TONUSDT","bids":[],"asks":[["3.1501","0"],["3.1504","613.0"],["3.1505","89.1"],["3.1507","721.7"],["3.1509","325.8"],["3.1512","2377.2"],["3.1515","3677.8"],["3.1518","3238.7"],["3.1527","695.1"],["3.1530","3127.1"],["3.1533","1163.5"],["3.1536","2475.5"],["3.1539","2655.8"],["3.1553","120.4"]],"timestamp":1756900854270,"update_id":50196828,"fetch_time":1756900854317}
{"symbol":"TONUSDT","bids":[["3.1497","762.0"],["3.1496","22.3"],["3.1493","678.0"],["3.1492","1442.3"],["3.1491","528.9"],["3.1490","1725.5"],["3.1489","726.5"],["3.1485","2761.6"],["3.1484","2366.3"]],"asks":[["3.1502","43.0"],["3.1503","91.8"],["3.1504","520.1"],["3.1506","1093.4"],["3.1507","704.1"],["3.1508","694.7"],["3.1509","514.0"],["3.1510","2744.3"],["3.1512","2696.3"],["3.1514","4090.2"],["3.1515","4091.8"],["3.1517","1233.6"],["3.1518","3765.6"],["3.1523","1445.8"],["3.1526","1795.2"],["3.1527","506.9"],["3.1530","2826.0"],["3.1533","749.5"],["3.1536","1946.6"],["3.1538","1936.5"],["3.1539","2653.8"],["3.1552","0"],["3.1553","0"]],"timestamp":1756900854329,"update_id":50196831,"fetch_time":1756900854377}
{"symbol":"TONUSDT","bids":[["3.1492","940.7"],["3.1486","2824.3"]],"asks":[["3.1503","0"],["3.1508","1499.0"],["3.1522","1816.5"],["3.1524","3301.6"],["3.1537","1415.1"],["3.1538","1934.5"],["3.1552","1784.4"]],"timestamp":1756900854350,"update_id":50196832,"fetch_time":1756900854402}
{"symbol":"TONUSDT","bids":[],"asks":[["3.1505","92.3"]],"timestamp":1756900854389,"update_id":50196834,"fetch_time":1756900854434}
{"symbol":"TONUSDT","bids":[],"asks":[["3.1508","2182.7"],["3.1510","2463.9"],["3.1520","4734.2"],["3.1524","2349.5"]],"timestamp":1756900854409,"update_id":50196835,"fetch_time":1756900854453}
{"symbol":"TONUSDT","bids":[],"asks":[["3.1510","2183.3"]],"timestamp":1756900854450,"update_id":50196836,"fetch_time":1756900854493}
{"symbol":"TONUSDT","bids":[],"asks":[["3.1510","1809.5"]],"timestamp":1756900854470,"update_id":50196837,"fetch_time":1756900854513}
{"symbol":"TONUSDT","bids":[],"asks":[["3.1508","2017.3"]],"timestamp":1756900854489,"update_id":50196838,"fetch_time":1756900854537}
{"symbol":"TONUSDT","bids":[],"asks":[["3.1503","14.2"],["3.1513","733.3"],["3.1552","0"]],"timestamp":1756900854549,"update_id":50196840,"fetch_time":1756900854593}
{"symbol":"TONUSDT","bids":[["3.1478","1574.5"]],"asks":[],"timestamp":1756900854630,"update_id":50196841,"fetch_time":1756900854673}
{"symbol":"TONUSDT","bids":[["3.1491","284.4"]],"asks":[],"timestamp":1756900854770,"update_id":50196843,"fetch_time":1756900854813}
{"symbol":"TONUSDT","bids":[["3.1492","1260.0"]],"asks":[],"timestamp":1756900854789,"update_id":50196844,"fetch_time":1756900854833}
{"symbol":"TONUSDT","bids":[["3.1464","3230.8"]],"asks":[],"timestamp":1756900854850,"update_id":50196846,"fetch_time":1756900854893}
{"symbol":"TONUSDT","bids":[["3.1486","3624.3"]],"asks":[],"timestamp":1756900854950,"update_id":50196847,"fetch_time":1756900854997}
{"symbol":"TONUSDT","bids":[],"asks":[["3.1509","276.0"]],"timestamp":1756900855010,"update_id":50196848,"fetch_time":1756900855053}
{"symbol":"TONUSDT","bids":[["3.1491","327.6"],["3.1490","1725.5"]],"asks":[["3.1503","0"],["3.1552","1784.4"]],"timestamp":1756900855169,"update_id":50196849,"fetch_time":1756900855213}
{"symbol":"TONUSDT","bids":[["3.1492","940.7"],["3.1489","1230.8"]],"asks":[["3.1503","14.2"],["3.1552","0"]],"timestamp":1756900855329,"update_id":50196850,"fetch_time":1756900855373}
{"symbol":"TONUSDT","bids":[],"asks":[["3.1503","29.1"],["3.1511","565.5"]],"timestamp":1756900855350,"update_id":50196851,"fetch_time":1756900855397}
{"symbol":"TONUSDT","bids":[],"asks":[["3.1502","45.3"]],"timestamp":1756900855369,"update_id":50196852,"fetch_time":1756900855413}
{"symbol":"TONUSDT","bids":[["3.1491","284.4"],["3.1486","2824.3"]],"asks":[["3.1501","140.0"],["3.1502","2.3"],["3.1503","60.7"],["3.1536","1948.6"],["3.1537","1413.1"],["3.1551","0"]],"timestamp":1756900855389,"update_id":50196853,"fetch_time":1756900855433}
{"symbol":"TONUSDT","bids":[],"asks":[["3.1503","566.3"]],"timestamp":1756900855410,"update_id":50196854,"fetch_time":1756900855454}
{"symbol":"TONUSDT","bids":[],"asks":[["3.1502","265.2"],["3.1506","1566.8"],["3.1507","1638.9"],["3.1512","2916.8"]],"timestamp":1756900855429,"update_id":50196855,"fetch_time":1756900855473}
{"symbol":"TONUSDT","bids":[],"asks":[["3.1508","1394.6"],["3.1550","4558.7"]],"timestamp":1756900855470,"update_id":50196857,"fetch_time":1756900855513}
{"symbol":"TONUSDT","bids":[],"asks":[["3.1550","5826.3"]],"timestamp":1756900855489,"update_id":50196858,"fetch_time":1756900855533}
{"symbol":"TONUSDT","bids":[["3.1490","2044.8"]],"asks":[],"timestamp":1756900855510,"update_id":50196859,"fetch_time":1756900855557}
{"symbol":"TONUSDT","bids":[],"asks":[["3.1508","1114.2"],["3.1549","2344.7"],["3.1550","4558.7"]],"timestamp":1756900855530,"update_id":50196860,"fetch_time":1756900855573}
{"symbol":"TONUSDT","bids":[["3.1488","1941.5"]],"asks":[],"timestamp":1756900855629,"update_id":50196862,"fetch_time":1756900855677}
{"symbol":"TONUSDT","bids":[["3.1494","500.1"]],"asks":[],"timestamp":1756900856450,"update_id":50196864,"fetch_time":1756900856493}
{"symbol":"TONUSDT","bids":[],"asks":[["3.1549","1077.1"],["3.1550","5826.3"]],"timestamp":1756900856549,"update_id":50196865,"fetch_time":1756900856593}
{"symbol":"TONUSDT","bids":[["3.1483","747.7"]],"asks":[],"timestamp":1756900856569,"update_id":50196866,"fetch_time":1756900856613}
{"symbol":"TONUSDT","bids":[["3.1491","647.0"],["3.1490","1768.7"]],"asks":[],"timestamp":1756900856610,"update_id":50196868,"fetch_time":1756900856653}
{"symbol":"TONUSDT","bids":[["3.1470","2814.6"]],"asks":[],"timestamp":1756900856650,"update_id":50196869,"fetch_time":1756900856694}
{"symbol":"TONUSDT","bids":[],"asks":[["3.1506","1598.5"]],"timestamp":1756900856689,"update_id":50196870,"fetch_time":1756900856733}
{"symbol":"TONUSDT","bids":[],"asks":[["3.1503","552.1"]],"timestamp":1756900856729,"update_id":50196871,"fetch_time":1756900856773}
{"symbol":"TONUSDT","bids":[["3.1491","690.2"]],"asks":[["3.1501","0"],["3.1551","5712.2"]],"timestamp":1756900857069,"update_id":50196872,"fetch_time":1756900857116}
{"symbol":"TONUSDT","bids":[["3.1464","5036.6"],["3.1462","1574.0"]],"asks":[],"timestamp":1756900857150,"update_id":50196876,"fetch_time":1756900857196}
{"symbol":"TONUSDT","bids":[["3.1464","3337.0"]],"asks":[],"timestamp":1756900857170,"update_id":50196877,"fetch_time":1756900857216}
{"symbol":"TONUSDT","bids":[["3.1494","586.6"],["3.1493","764.5"],["3.1492","1027.2"]],"asks":[],"timestamp":1756900857189,"update_id":50196878,"fetch_time":1756900857236}
{"symbol":"TONUSDT","bids":[["3.1490","2239.4"]],"asks":[["3.1502","0"],["3.1503","0"],["3.1504","128.5"],["3.1507","390.3"],["3.1508","1946.8"],["3.1509","87.8"],["3.1512","2395.2"],["3.1515","3677.8"],["3.1518","3238.7"],["3.1521","1844.8"],["3.1524","1596.8"],["3.1530","3014.2"],["3.1533","1050.6"],["3.1536","2360.6"],["3.1537","1413.1"],["3.1538","1936.5"],["3.1539","3180.7"],["3.1542","5761.9"],["3.1545","1761.4"],["3.1552","2016.5"],["3.1553","1387.9"]],"timestamp":1756900857250,"update_id":50196881,"fetch_time":1756900857301}
{"symbol":"TONUSDT","bids":[],"asks":[["3.1506","1400.5"],["3.1510","2463.9"]],"timestamp":1756900857290,"update_id":50196883,"fetch_time":1756900857336}
{"symbol":"TONUSDT","bids":[],"asks":[["3.1505","258.7"],["3.1507","422.0"],["3.1508","1329.0"],["3.1510","2744.6"]],"timestamp":1756900857309,"update_id":50196884,"fetch_time":1756900857360}
{"symbol":"TONUSDT","bids":[],"asks":[["3.1552","1784.4"]],"timestamp":1756900857349,"update_id":50196886,"fetch_time":1756900857392}
{"symbol":"TONUSDT","bids":[],"asks":[["3.1509","274.9"]],"timestamp":1756900857390,"update_id":50196887,"fetch_time":1756900857436}
{"symbol":"TONUSDT","bids":[["3.1498","249.2"],["3.1497","826.8"],["3.1493","1063.3"],["3.1492","1027.2"]],"asks":[["3.1504","0"],["3.1505","50.0"],["3.1506","816.7"],["3.1508","1727.5"],["3.1509","46.4"],["3.1510","2933.7"],["3.1511","327.9"],["3.1513","409.3"],["3.1539","3180.7"],["3.1540","2614.6"],["3.1554","1620.0"]],"timestamp":1756900857449,"update_id":50196889,"fetch_time":1756900857496}
{"symbol":"TONUSDT","bids":[["3.1500","43.0"],["3.1450","0"]],"asks":[["3.1508","1790.9"],["3.1510","2732.2"]],"timestamp":1756900857469,"update_id":50196890,"fetch_time":1756900857512}
{"symbol":"TONUSDT","bids":[["3.1496","274.4"],["3.1495","168.6"],["3.1494","1090.3"],["3.1493","833.3"],["3.1492","984.0"],["3.1491","327.7"]],"asks":[],"timestamp":1756900857589,"update_id":50196896,"fetch_time":1756900857640}
{"symbol":"TONUSDT","bids":[],"asks":[["3.1510","2807.1"]],"timestamp":1756900857610,"update_id":50196897,"fetch_time":1756900857656}
{"symbol":"TONUSDT","bids":[["3.1494","1133.5"],["3.1493","876.5"]],"asks":[],"timestamp":1756900857629,"update_id":50196898,"fetch_time":1756900857680}
{"symbol":"TONUSDT","bids":[["3.1464","4485.4"]],"asks":[],"timestamp":1756900857650,"update_id":50196899,"fetch_time":1756900857696}
{"symbol":"TONUSDT","bids":[],"asks":[["3.1509","617.6"]],"timestamp":1756900857709,"update_id":50196901,"fetch_time":1756900857757}
{"symbol":"TONUSDT","bids":[],"asks":[["3.1509","660.9"]],"timestamp":1756900857930,"update_id":50196902,"fetch_time":1756900857977}
{"symbol":"TONUSDT","bids":[],"asks":[["3.1508","2044.1"],["3.1551","6979.7"],["3.1553","120.4"]],"timestamp":1756900857950,"update_id":50196903,"fetch_time":1756900858001}
{"symbol":"TONUSDT","bids":[],"asks":[["3.1503","1.0"],["3.1554","0"]],"timestamp":1756900857969,"update_id":50196904,"fetch_time":1756900858017}
{"symbol":"TONUSDT","bids":[],"asks":[["3.1509","1662.8"],["3.1510","2489.3"]],"timestamp":1756900858009,"update_id":50196906,"fetch_time":1756900858060}
{"symbol":"TONUSDT","bids":[["3.1497","1003.2"]],"asks":[],"timestamp":1756900858030,"update_id":50196907,"fetch_time":1756900858076}
{"symbol":"TONUSDT","bids":[],"asks":[["3.1510","2208.8"]],"timestamp":1756900858070,"update_id":50196908,"fetch_time":1756900858121}
{"symbol":"TONUSDT","bids":[],"asks":[["3.1507","447.9"],["3.1510","1554.2"]],"timestamp":1756900858109,"update_id":50196910,"fetch_time":1756900858152}
{"symbol":"TONUSDT","bids":[],"asks":[["3.1506","828.2"],["3.1507","491.1"],["3.1511","328.0"]],"timestamp":1756900858129,"update_id":50196911,"fetch_time":1756900858180}
{"symbol":"TONUSDT","bids":[],"asks":[["3.1505","69.9"],["3.1510","1637.4"]],"timestamp":1756900858149,"update_id":50196912,"fetch_time":1756900858196}
{"symbol":"TONUSDT","bids":[["3.1499","122.5"],["3.1494","1090.3"],["3.1493","833.3"]],"asks":[],"timestamp":1756900858189,"update_id":50196913,"fetch_time":1756900858237}
{"symbol":"TONUSDT","bids":[["3.1497","765.2"],["3.1494","1047.0"],["3.1493","790.0"],["3.1492","940.7"],["3.1491","284.4"],["3.1490","2152.9"]],"asks":[["3.1504","14.2"],["3.1506","871.5"],["3.1553","0"]],"timestamp":1756900858209,"update_id":50196914,"fetch_time":1756900858256}
{"symbol":"TONUSDT","bids":[],"asks":[["3.1550","5826.2"],["3.1551","5712.2"]],"timestamp":1756900858270,"update_id":50196915,"fetch_time":1756900858320}
{"symbol":"TONUSDT","bids":[],"asks":[["3.1507","459.4"],["3.1508","2242.8"],["3.1509","1091.6"]],"timestamp":1756900858370,"update_id":50196916,"fetch_time":1756900858417}
{"symbol":"TONUSDT","bids":[["3.1495","168.5"],["3.1494","1090.2"],["3.1493","833.2"],["3.1492","983.9"],["3.1491","327.7"]],"asks":[["3.1504","0"],["3.1505","50.0"],["3.1506","828.3"],["3.1507","416.2"],["3.1553","120.4"]],"timestamp":1756900858390,"update_id":50196917,"fetch_time":1756900858440}
{"symbol":"TONUSDT","bids":[],"asks":[["3.1506","871.5"],["3.1507","459.4"]],"timestamp":1756900858409,"update_id":50196918,"fetch_time":1756900858457}
{"symbol":"TONUSDT","bids":[],"asks":[["3.1506","808.3"]],"timestamp":1756900858490,"update_id":50196919,"fetch_time":1756900858540}
{"symbol":"TONUSDT","bids":[["3.1483","811.2"]],"asks":[],"timestamp":1756900858570,"update_id":50196920,"fetch_time":1756900858616}
{"symbol":"TONUSDT","bids":[],"asks":[["3.1550","4558.7"],["3.1551","6979.7"]],"timestamp":1756900858670,"update_id":50196921,"fetch_time":1756900858720}
{"symbol":"TONUSDT","bids":[["3.1490","2776.5"]],"asks":[],"timestamp":1756900858690,"update_id":50196922,"fetch_time":1756900858736}
{"symbol":"TONUSDT","bids":[],"asks":[["3.1550","5826.2"],["3.1551","5712.2"]],"timestamp":1756900858709,"update_id":50196923,"fetch_time":1756900858760}
{"symbol":"TONUSDT","bids":[],"asks":[["3.1508","2211.2"]],"timestamp":1756900858910,"update_id":50196924,"fetch_time":1756900858956}
{"symbol":"TONUSDT","bids":[],"asks":[["3.1510","1605.8"]],"timestamp":1756900858969,"update_id":50196925,"fetch_time":1756900859016}
{"symbol":"TONUSDT","bids":[],"asks":[["3.1550","4558.7"],["3.1551","6979.7"]],"timestamp":1756900859209,"update_id":50196926,"fetch_time":1756900859256}
{"symbol":"TONUSDT","bids":[],"asks":[["3.1550","5826.2"],["3.1551","5712.2"]],"timestamp":1756900859230,"update_id":50196927,"fetch_time":1756900859277}
{"symbol":"TONUSDT","bids":[["3.1496","274.3"],["3.1493","876.5"],["3.1492","1027.2"],["3.1491","370.9"]],"asks":[],"timestamp":1756900859530,"update_id":50196928,"fetch_time":1756900859576}
{"symbol":"TONUSDT","bids":[["3.1488","1422.0"],["3.1465","1800.9"]],"asks":[],"timestamp":1756900859829,"update_id":50196929,"fetch_time":1756900859876}
{"symbol":"TONUSDT","bids":[["3.1489","909.5"]],"asks":[],"timestamp":1756900860029,"update_id":50196930,"fetch_time":1756900860072}
{"symbol":"TONUSDT","bids":[["3.1496","231.1"],["3.1495","125.3"]],"asks":[],"timestamp":1756900860289,"update_id":50196931,"fetch_time":1756900860341}
{"symbol":"TONUSDT","bids":[["3.1495","168.5"]],"asks":[],"timestamp":1756900860629,"update_id":50196932,"fetch_time":1756900860672}
{"symbol":"TONUSDT","bids":[["3.1497","1003.2"]],"asks":[],"timestamp":1756900861009,"update_id":50196933,"fetch_time":1756900861060}
{"symbol":"TONUSDT","bids":[],"asks":[["3.1521","1844.8"]],"timestamp":1756900861029,"update_id":50196934,"fetch_time":1756900861076}
{"symbol":"TONUSDT","bids":[],"asks":[["3.1521","2686.4"]],"timestamp":1756900861430,"update_id":50196935,"fetch_time":1756900861476}
{"symbol":"TONUSDT","bids":[["3.1500","49.2"]],"asks":[],"timestamp":1756900861530,"update_id":50196936,"fetch_time":1756900861576}
{"symbol":"TONUSDT","bids":[["3.1498","0"],["3.1494","1064.4"],["3.1450","1840.6"]],"asks":[["3.1508","2440.6"],["3.1509","837.6"]],"timestamp":1756900861549,"update_id":50196937,"fetch_time":1756900861596}
{"symbol":"TONUSDT","bids":[["3.1502","25.8"],["3.1500","6.2"],["3.1499","124.9"],["3.1498","466.4"],["3.1451","0"],["3.1450","0"]],"asks":[["3.1505","68.2"],["3.1508","2206.7"]],"timestamp":1756900861569,"update_id":50196938,"fetch_time":1756900861616}
{"symbol":"TONUSDT","bids":[["3.1496","841.4"],["3.1493","577.7"],["3.1492","1235.7"]],"asks":[],"timestamp":1756900861609,"update_id":50196940,"fetch_time":1756900861660}
{"symbol":"TONUSDT","bids":[["3.1499","286.8"],["3.1498","633.2"]],"asks":[],"timestamp":1756900861630,"update_id":50196941,"fetch_time":1756900861676}
{"symbol":"TONUSDT","bids":[],"asks":[["3.1505","81.8"]],"timestamp":1756900861649,"update_id":50196942,"fetch_time":1756900861696}
{"symbol":"TONUSDT","bids":[["3.1495","105.1"],["3.1494","877.6"]],"asks":[],"timestamp":1756900861709,"update_id":50196943,"fetch_time":1756900861752}
{"symbol":"TONUSDT","bids":[],"asks":[["3.1549","2344.7"],["3.1550","4558.7"]],"timestamp":1756900861730,"update_id":50196944,"fetch_time":1756900861776}
{"symbol":"TONUSDT","bids":[],"asks":[["3.1507","73.2"],["3.1508","1375.6"]],"timestamp":1756900861910,"update_id":50196949,"fetch_time":1756900861956}
{"symbol":"TONUSDT","bids":[],"asks":[["3.1506","317.0"]],"timestamp":1756900861929,"update_id":50196950,"fetch_time":1756900861976}
{"symbol":"TONUSDT","bids":[["3.1500","6.2"],["3.1498","205.1"]],"asks":[],"timestamp":1756900861949,"update_id":50196951,"fetch_time":1756900861996}
{"symbol":"TONUSDT","bids":[["3.1498","740.9"]],"asks":[],"timestamp":1756900861971,"update_id":50196952,"fetch_time":1756900862016}
{"symbol":"TONUSDT","bids":[["3.1499","549.1"]],"asks":[["3.1503","0"],["3.1554","1620.0"]],"timestamp":1756900862010,"update_id":50196953,"fetch_time":1756900862056}
{"symbol":"TONUSDT","bids":[],"asks":[["3.1508","900.2"]],"timestamp":1756900862050,"update_id":50196955,"fetch_time":1756900862096}
{"symbol":"TONUSDT","bids":[],"asks":[["3.1506","55.0"],["3.1510","1666.4"],["3.1511","1118.7"],["3.1515","2636.2"],["3.1519","2250.5"]],"timestamp":1756900862070,"update_id":50196956,"fetch_time":1756900862116}
{"symbol":"TONUSDT","bids":[["3.1503","8.8"],["3.1452","0"]],"asks":[["3.1510","1941.8"]],"timestamp":1756900862090,"update_id":50196957,"fetch_time":1756900862136}
{"symbol":"TONUSDT","bids":[["3.1497","1313.5"]],"asks":[],"timestamp":1756900862130,"update_id":50196959,"fetch_time":1756900862176}
{"symbol":"TONUSDT","bids":[["3.1498","645.6"]],"asks":[],"timestamp":1756900862150,"update_id":50196960,"fetch_time":1756900862200}
{"symbol":"TONUSDT","bids":[["3.1500","332.8"]],"asks":[],"timestamp":1756900862169,"update_id":50196961,"fetch_time":1756900862212}
{"symbol":"TONUSDT","bids":[],"asks":[["3.1510","1985.0"]],"timestamp":1756900862190,"update_id":50196962,"fetch_time":1756900862240}
{"symbol":"TONUSDT","bids":[["3.1497","1250.1"]],"asks":[],"timestamp":1756900862210,"update_id":50196963,"fetch_time":1756900862256}
{"symbol":"TONUSDT","bids":[["3.1496","681.1"]],"asks":[],"timestamp":1756900862229,"update_id":50196964,"fetch_time":1756900862272}
{"symbol":"TONUSDT","bids":[],"asks":[["3.1507","241.5"],["3.1508","805.2"],["3.1513","495.8"]],"timestamp":1756900862429,"update_id":50196967,"fetch_time":1756900862476}
{"symbol":"TONUSDT","bids":[["3.1498","602.4"]],"asks":[],"timestamp":1756900862470,"update_id":50196968,"fetch_time":1756900862516}
{"symbol":"TONUSDT","bids":[],"asks":[["3.1508","848.4"]],"timestamp":1756900862489,"update_id":50196969,"fetch_time":1756900862536}
{"symbol":"TONUSDT","bids":[],"asks":[["3.1505","0"],["3.1555","586.9"]],"timestamp":1756900862549,"update_id":50196971,"fetch_time":1756900862596}
{"symbol":"TONUSDT","bids":[],"asks":[["3.1506","51.8"],["3.1508","825.9"],["3.1510","923.9"],["3.1511","1305.7"],["3.1514","4191.4"],["3.1531","3875.4"],["3.1540","2612.6"],["3.1541","988.5"]],"timestamp":1756900862569,"update_id":50196972,"fetch_time":1756900862620}
{"symbol":"TONUSDT","bids":[],"asks":[["3.1511","1369.1"]],"timestamp":1756900862610,"update_id":50196974,"fetch_time":1756900862656}
{"symbol":"TONUSDT","bids":[],"asks":[["3.1509","3.2"],["3.1510","880.6"],["3.1514","4234.7"]],"timestamp":1756900862650,"update_id":50196975,"fetch_time":1756900862696}
{"symbol":"TONUSDT","bids":[],"asks":[["3.1511","1400.7"]],"timestamp":1756900862709,"update_id":50196976,"fetch_time":1756900862756}
{"symbol":"TONUSDT","bids":[["3.1500","9.4"],["3.1499","128.1"]],"asks":[],"timestamp":1756900862869,"update_id":50196979,"fetch_time":1756900862916}
{"symbol":"TONUSDT","bids":[["3.1497","971.6"]],"asks":[],"timestamp":1756900862890,"update_id":50196980,"fetch_time":1756900862941}
{"symbol":"TONUSDT","bids":[["3.1496","846.4"],["3.1495","105.2"]],"asks":[],"timestamp":1756900862910,"update_id":50196981,"fetch_time":1756900862956}
{"symbol":"TONUSDT","bids":[["3.1495","61.9"],["3.1494","1055.5"],["3.1493","771.8"],["3.1492","940.7"],["3.1491","284.4"],["3.1484","2366.3"]],"asks":[["3.1505","168.8"],["3.1506","62.7"],["3.1540","2614.6"],["3.1541","986.5"],["3.1555","0"]],"timestamp":1756900863050,"update_id":50196982,"fetch_time":1756900863100}
{"symbol":"TONUSDT","bids":[["3.1496","1266.9"]],"asks":[["3.1504","122.9"],["3.1505","173.4"],["3.1509","229.2"],["3.1514","4191.5"],["3.1554","0"]],"timestamp":1756900863089,"update_id":50196984,"fetch_time":1756900863136}
{"symbol":"TONUSDT","bids":[],"asks":[["3.1509","416.1"],["3.1510","1846.2"],["3.1511","1213.7"]],"timestamp":1756900863129,"update_id":50196986,"fetch_time":1756900863172}
{"symbol":"TONUSDT","bids":[],"asks":[["3.1509","582.9"],["3.1510","2407.0"]],"timestamp":1756900863149,"update_id":50196987,"fetch_time":1756900863196}
{"symbol":"TONUSDT","bids":[],"asks":[["3.1511","933.2"]],"timestamp":1756900863190,"update_id":50196989,"fetch_time":1756900863236}
{"symbol":"TONUSDT","bids":[["3.1453","10997.8"]],"asks":[],"timestamp":1756900863209,"update_id":50196990,"fetch_time":1756900863256}
{"symbol":"TONUSDT","bids":[],"asks":[["3.1510","2220.1"],["3.1511","746.5"]],"timestamp":1756900863230,"update_id":50196991,"fetch_time":1756900863277}
{"symbol":"TONUSDT","bids":[],"asks":[["3.1511","466.2"]],"timestamp":1756900863250,"update_id":50196992,"fetch_time":1756900863296}
{"symbol":"TONUSDT","bids":[],"asks":[["3.1504","122.9"],["3.1505","142.3"]],"timestamp":1756900863330,"update_id":50196993,"fetch_time":1756900863380}
{"symbol":"TONUSDT","bids":[],"asks":[["3.1509","762.0"],["3.1510","2759.6"],["3.1511","497.9"]],"timestamp":1756900863349,"update_id":50196994,"fetch_time":1756900863397}
{"symbol":"TONUSDT","bids":[],"asks":[["3.1509","1079.4"],["3.1510","2791.3"]],"timestamp":1756900863370,"update_id":50196995,"fetch_time":1756900863416}
{"symbol":"TONUSDT","bids":[],"asks":[["3.1508","1434.4"],["3.1509","634.5"]],"timestamp":1756900863389,"update_id":50196996,"fetch_time":1756900863440}
{"symbol":"TONUSDT","bids":[],"asks":[["3.1508","2188.2"]],"timestamp":1756900863410,"update_id":50196997,"fetch_time":1756900863456}
{"symbol":"TONUSDT","bids":[],"asks":[["3.1507","468.1"],["3.1512","2420.5"],["3.1548","4804.6"],["3.1549","1077.1"]],"timestamp":1756900863430,"update_id":50196998,"fetch_time":1756900863480}
{"symbol":"TONUSDT","bids":[],"asks":[["3.1510","2515.9"],["3.1511","757.6"]],"timestamp":1756900863449,"update_id":50196999,"fetch_time":1756900863500}
{"symbol":"TONUSDT","bids":[],"asks":[["3.1507","498.3"]],"timestamp":1756900863470,"update_id":50197000,"fetch_time":1756900863516}
{"symbol":"TONUSDT","bids":[],"asks":[["3.1507","529.9"],["3.1548","3537.0"],["3.1549","2344.7"]],"timestamp":1756900863510,"update_id":50197001,"fetch_time":1756900863556}
{"symbol":"TONUSDT","bids":[],"asks":[["3.1510","2611.0"]],"timestamp":1756900863529,"update_id":50197002,"fetch_time":1756900863572}
{"symbol":"TONUSDT","bids":[],"asks":[["3.1510","2642.7"],["3.1511","789.2"]],"timestamp":1756900863549,"update_id":50197003,"fetch_time":1756900863600}
{"symbol":"TONUSDT","bids":[],"asks":[["3.1518","4040.5"],["3.1548","4804.6"],["3.1549","1077.1"]],"timestamp":1756900863570,"update_id":50197004,"fetch_time":1756900863616}
{"symbol":"TONUSDT","bids":[["3.1495","61.9"],["3.1493","1077.2"]],"asks":[],"timestamp":1756900863709,"update_id":50197006,"fetch_time":1756900863756}
{"symbol":"TONUSDT","bids":[],"asks":[["3.1504","125.2"],["3.1505","147.8"],["3.1506","570.9"]],"timestamp":1756900863730,"update_id":50197007,"fetch_time":1756900863776}
{"symbol":"TONUSDT","bids":[],"asks":[["3.1510","3578.5"]],"timestamp":1756900863770,"update_id":50197009,"fetch_time":1756900863816}
{"symbol":"TONUSDT","bids":[],"asks":[["3.1504","122.9"],["3.1505","773.2"]],"timestamp":1756900863789,"update_id":50197010,"fetch_time":1756900863836}
{"symbol":"TONUSDT","bids":[],"asks":[["3.1508","2283.3"]],"timestamp":1756900863810,"update_id":50197011,"fetch_time":1756900863860}
{"symbol":"TONUSDT","bids":[],"asks":[["3.1509","729.3"]],"timestamp":1756900863830,"update_id":50197012,"fetch_time":1756900863876}
{"symbol":"TONUSDT","bids":[],"asks":[["3.1504","154.5"],["3.1507","175.6"],["3.1539","3180.7"]],"timestamp":1756900863850,"update_id":50197013,"fetch_time":1756900863897}
{"symbol":"TONUSDT","bids":[],"asks":[["3.1539","3182.7"],["3.1548","3537.0"],["3.1549","2344.7"]],"timestamp":1756900863869,"update_id":50197014,"fetch_time":1756900863921}
{"symbol":"TONUSDT","bids":[],"asks":[["3.1512","2641.3"]],"timestamp":1756900863889,"update_id":50197015,"fetch_time":1756900863937}
{"symbol":"TONUSDT","bids":[],"asks":[["3.1505","781.0"]],"timestamp":1756900863909,"update_id":50197016,"fetch_time":1756900863957}
{"symbol":"TONUSDT","bids":[],"asks":[["3.1504","156.8"],["3.1514","4148.2"]],"timestamp":1756900863929,"update_id":50197017,"fetch_time":1756900863981}
{"symbol":"TONUSDT","bids":[],"asks":[["3.1504","159.1"]],"timestamp":1756900863949,"update_id":50197018,"fetch_time":1756900863997}
{"symbol":"TONUSDT","bids":[["3.1495","367.3"]],"asks":[],"timestamp":1756900863969,"update_id":50197019,"fetch_time":1756900864013}
{"symbol":"TONUSDT","bids":[],"asks":[["3.1508","2315.0"]],"timestamp":1756900863990,"update_id":50197020,"fetch_time":1756900864036}
{"symbol":"TONUSDT","bids":[],"asks":[["3.1504","154.5"],["3.1505","770.9"]],"timestamp":1756900864050,"update_id":50197022,"fetch_time":1756900864097}
{"symbol":"TONUSDT","bids":[],"asks":[["3.1509","792.5"]],"timestamp":1756900864089,"update_id":50197023,"fetch_time":1756900864148}
{"symbol":"TONUSDT","bids":[],"asks":[["3.1508","2251.6"]],"timestamp":1756900864170,"update_id":50197024,"fetch_time":1756900864217}
{"symbol":"TONUSDT","bids":[],"asks":[["3.1507","383.4"]],"timestamp":1756900864190,"update_id":50197025,"fetch_time":1756900864240}
{"symbol":"TONUSDT","bids":[],"asks":[["3.1508","2280.4"],["3.1509","855.9"]],"timestamp":1756900864369,"update_id":50197027,"fetch_time":1756900864416}
{"symbol":"TONUSDT","bids":[],"asks":[["3.1508","2312.1"]],"timestamp":1756900864409,"update_id":50197028,"fetch_time":1756900864456}
{"symbol":"TONUSDT","bids":[],"asks":[["3.1505","639.0"]],"timestamp":1756900864429,"update_id":50197029,"fetch_time":1756900864480}
{"symbol":"TONUSDT","bids":[],"asks":[["3.1508","1558.3"],["3.1509","887.6"],["3.1510","3610.0"],["3.1549","1077.1"],["3.1550","5826.3"]],"timestamp":1756900864470,"update_id":50197030,"fetch_time":1756900864520}
{"symbol":"TONUSDT","bids":[],"asks":[["3.1508","1962.9"]],"timestamp":1756900864510,"update_id":50197032,"fetch_time":1756900864556}
{"symbol":"TONUSDT","bids":[],"asks":[["3.1505","670.6"]],"timestamp":1756900864529,"update_id":50197033,"fetch_time":1756900864576}
{"symbol":"TONUSDT","bids":[],"asks":[["3.1509","1309.3"]],"timestamp":1756900864569,"update_id":50197034,"fetch_time":1756900864612}
{"symbol":"TONUSDT","bids":[],"asks":[["3.1510","3641.7"]],"timestamp":1756900864630,"update_id":50197036,"fetch_time":1756900864676}
{"symbol":"TONUSDT","bids":[],"asks":[["3.1504","156.8"]],"timestamp":1756900864649,"update_id":50197037,"fetch_time":1756900864701}
{"symbol":"TONUSDT","bids":[],"asks":[["3.1549","2344.7"],["3.1550","4558.7"]],"timestamp":1756900864710,"update_id":50197038,"fetch_time":1756900864757}
{"symbol":"TONUSDT","bids":[],"asks":[["3.1508","3541.9"]],"timestamp":1756900864730,"update_id":50197039,"fetch_time":1756900864777}
{"symbol":"TONUSDT","bids":[],"asks":[["3.1505","965.4"]],"timestamp":1756900864749,"update_id":50197040,"fetch_time":1756900864801}
{"symbol":"TONUSDT","bids":[],"asks":[["3.1506","755.6"]],"timestamp":1756900864990,"update_id":50197041,"fetch_time":1756900865036}
{"symbol":"TONUSDT","bids":[],"asks":[["3.1509","1372.5"]],"timestamp":1756900865089,"update_id":50197042,"fetch_time":1756900865140}
{"symbol":"TONUSDT","bids":[],"asks":[["3.1504","154.5"],["3.1505","949.5"],["3.1511","592.7"],["3.1549","1077.1"],["3.1550","5826.3"]],"timestamp":1756900865330,"update_id":50197043,"fetch_time":1756900865380}
{"symbol":"TONUSDT","bids":[],"asks":[["3.1506","744.7"],["3.1507","369.8"]],"timestamp":1756900865629,"update_id":50197045,"fetch_time":1756900865676}
{"symbol":"TONUSDT","bids":[],"asks":[["3.1507","413.1"]],"timestamp":1756900865689,"update_id":50197046,"fetch_time":1756900865737}
{"symbol":"TONUSDT","bids":[],"asks":[["3.1531","3427.3"]],"timestamp":1756900865830,"update_id":50197047,"fetch_time":1756900865876}
{"symbol":"TONUSDT","bids":[["3.1493","815.1"]],"asks":[],"timestamp":1756900865849,"update_id":50197048,"fetch_time":1756900865896}
{"symbol":"TONUSDT","bids":[["3.1468","5311.7"],["3.1461","897.3"]],"asks":[],"timestamp":1756900865890,"update_id":50197049,"fetch_time":1756900865936}
{"symbol":"TONUSDT","bids":[],"asks":[["3.1508","3065.9"]],"timestamp":1756900866009,"update_id":50197050,"fetch_time":1756900866056}
{"symbol":"TONUSDT","bids":[],"asks":[["3.1505","951.1"],["3.1512","2648.9"]],"timestamp":1756900866030,"update_id":50197051,"fetch_time":1756900866076}
{"symbol":"TONUSDT","bids":[],"asks":[["3.1519","2256.8"],["3.1527","500.6"]],"timestamp":1756900866110,"update_id":50197052,"fetch_time":1756900866157}
{"symbol":"TONUSDT","bids":[],"asks":[["3.1506","742.4"]],"timestamp":1756900866210,"update_id":50197053,"fetch_time":1756900866252}
{"symbol":"TONUSDT","bids":[],"asks":[["3.1509","1404.2"]],"timestamp":1756900866369,"update_id":50197055,"fetch_time":1756900866412}
{"symbol":"TONUSDT","bids":[],"asks":[["3.1508","3097.6"],["3.1509","1880.3"]],"timestamp":1756900866429,"update_id":50197056,"fetch_time":1756900866476}
{"symbol":"TONUSDT","bids":[],"asks":[["3.1504","122.9"],["3.1507","356.8"],["3.1539","3182.7"]],"timestamp":1756900866490,"update_id":50197059,"fetch_time":1756900866536}
{"symbol":"TONUSDT","bids":[],"asks":[["3.1505","664.1"],["3.1550","5826.2"],["3.1551","5712.2"]],"timestamp":1756900866529,"update_id":50197061,"fetch_time":1756900866580}
{"symbol":"TONUSDT","bids":[],"asks":[["3.1507","325.2"]],"timestamp":1756900866550,"update_id":50197062,"fetch_time":1756900866597}
{"symbol":"TONUSDT","bids":[["3.1502","0"],["3.1497","1015.3"],["3.1496","1058.4"],["3.1495","105.2"],["3.1494","877.7"],["3.1452","1711.1"]],"asks":[["3.1505","632.5"],["3.1550","4558.7"],["3.1551","6979.7"]],"timestamp":1756900866570,"update_id":50197063,"fetch_time":1756900866616}
{"symbol":"TONUSDT","bids":[["3.1497","828.6"]],"asks":[],"timestamp":1756900866609,"update_id":50197065,"fetch_time":1756900866656}
{"symbol":"TONUSDT","bids":[["3.1494","920.9"]],"asks":[],"timestamp":1756900866630,"update_id":50197066,"fetch_time":1756900866680}
{"symbol":"TONUSDT","bids":[["3.1496","1245.1"]],"asks":[],"timestamp":1756900866649,"update_id":50197067,"fetch_time":1756900866696}
{"symbol":"TONUSDT","bids":[],"asks":[["3.1511","561.1"]],"timestamp":1756900866689,"update_id":50197068,"fetch_time":1756900866740}
{"symbol":"TONUSDT","bids":[],"asks":[["3.1507","368.4"],["3.1550","5826.2"],["3.1551","5712.2"]],"timestamp":1756900866710,"update_id":50197069,"fetch_time":1756900866757}
{"symbol":"TONUSDT","bids":[],"asks":[["3.1506","79.3"],["3.1507","411.7"]],"timestamp":1756900866729,"update_id":50197070,"fetch_time":1756900866777}
{"symbol":"TONUSDT","bids":[],"asks":[["3.1512","2643.6"],["3.1513","495.8"]],"timestamp":1756900866790,"update_id":50197071,"fetch_time":1756900866836}
{"symbol":"TONUSDT","bids":[["3.1485","2952.6"]],"asks":[],"timestamp":1756900866829,"update_id":50197072,"fetch_time":1756900866876}
{"symbol":"TONUSDT","bids":[["3.1477","669.4"]],"asks":[],"timestamp":1756900866949,"update_id":50197074,"fetch_time":1756900866996}
{"symbol":"TONUSDT","bids":[["3.1486","1973.7"]],"asks":[],"timestamp":1756900866989,"update_id":50197075,"fetch_time":1756900867036}
{"symbol":"TONUSDT","bids":[["3.1479","1048.3"]],"asks":[],"timestamp":1756900867009,"update_id":50197076,"fetch_time":1756900867056}
{"symbol":"TONUSDT","bids":[["3.1488","1614.8"]],"asks":[],"timestamp":1756900867130,"update_id":50197077,"fetch_time":1756900867176}
{"symbol":"TONUSDT","bids":[],"asks":[["3.1505","648.4"]],"timestamp":1756900867150,"update_id":50197078,"fetch_time":1756900867200}
{"symbol":"TONUSDT","bids":[],"asks":[["3.1539","3182.7"]],"timestamp":1756900867229,"update_id":50197080,"fetch_time":1756900867281}
{"symbol":"TONUSDT","bids":[["3.1480","1483.1"]],"asks":[],"timestamp":1756900867270,"update_id":50197081,"fetch_time":1756900867316}
{"symbol":"TONUSDT","bids":[["3.1486","2164.7"]],"asks":[],"timestamp":1756900867429,"update_id":50197082,"fetch_time":1756900867472}
{"symbol":"TONUSDT","bids":[["3.1498","556.0"],["3.1497","1121.7"]],"asks":[],"timestamp":1756900867450,"update_id":50197083,"fetch_time":1756900867501}
{"symbol":"TONUSDT","bids":[["3.1478","1383.5"]],"asks":[],"timestamp":1756900867510,"update_id":50197084,"fetch_time":1756900867560}
{"symbol":"TONUSDT","bids":[],"asks":[["3.1509","1848.7"]],"timestamp":1756900867550,"update_id":50197085,"fetch_time":1756900867596}
{"symbol":"TONUSDT","bids":[["3.1452","1712.9"]],"asks":[],"timestamp":1756900867590,"update_id":50197086,"fetch_time":1756900867636}
{"symbol":"TONUSDT","bids":[["3.1487","779.2"]],"asks":[],"timestamp":1756900867689,"update_id":50197087,"fetch_time":1756900867736}
{"symbol":"TONUSDT","bids":[["3.1488","1754.8"],["3.1479","857.3"]],"asks":[],"timestamp":1756900867709,"update_id":50197088,"fetch_time":1756900867752}
{"symbol":"TONUSDT","bids":[["3.1488","1945.8"]],"asks":[],"timestamp":1756900867729,"update_id":50197089,"fetch_time":1756900867776}
{"symbol":"TONUSDT","bids":[["3.1480","1292.1"]],"asks":[],"timestamp":1756900867769,"update_id":50197090,"fetch_time":1756900867812}
{"symbol":"TONUSDT","bids":[["3.1487","970.2"]],"asks":[],"timestamp":1756900867809,"update_id":50197091,"fetch_time":1756900867852}
{"symbol":"TONUSDT","bids":[],"asks":[["3.1505","640.6"],["3.1506","79.7"]],"timestamp":1756900867889,"update_id":50197092,"fetch_time":1756900867932}
{"symbol":"TONUSDT","bids":[["3.1479","666.3"]],"asks":[],"timestamp":1756900867989,"update_id":50197093,"fetch_time":1756900868036}
{"symbol":"TONUSDT","bids":[],"asks":[["3.1508","2821.6"]],"timestamp":1756900868589,"update_id":50197094,"fetch_time":1756900868632}
{"symbol":"TONUSDT","bids":[],"asks":[["3.1506","107.2"]],"timestamp":1756900868610,"update_id":50197095,"fetch_time":1756900868656}
{"symbol":"TONUSDT","bids":[],"asks":[["3.1539","3182.7"]],"timestamp":1756900868710,"update_id":50197097,"fetch_time":1756900868756}
{"symbol":"TONUSDT","bids":[],"asks":[["3.1508","3575.4"]],"timestamp":1756900868870,"update_id":50197098,"fetch_time":1756900868917}
{"symbol":"TONUSDT","bids":[["3.1498","20.2"]],"asks":[],"timestamp":1756900869010,"update_id":50197099,"fetch_time":1756900869056}
{"symbol":"TONUSDT","bids":[],"asks":[["3.1517","2033.6"]],"timestamp":1756900869109,"update_id":50197100,"fetch_time":1756900869152}
{"symbol":"TONUSDT","bids":[],"asks":[["3.1507","443.3"]],"timestamp":1756900869230,"update_id":50197101,"fetch_time":1756900869276}
{"symbol":"TONUSDT","bids":[["3.1498","686.1"]],"asks":[],"timestamp":1756900869250,"update_id":50197102,"fetch_time":1756900869301}
{"symbol":"TONUSDT","bids":[["3.1486","2355.7"]],"asks":[],"timestamp":1756900869410,"update_id":50197103,"fetch_time":1756900869460}
{"symbol":"TONUSDT","bids":[["3.1478","1192.5"]],"asks":[],"timestamp":1756900869489,"update_id":50197104,"fetch_time":1756900869536}
{"symbol":"TONUSDT","bids":[["3.1488","2100.2"],["3.1486","2546.7"]],"asks":[],"timestamp":1756900869530,"update_id":50197105,"fetch_time":1756900869576}
{"symbol":"TONUSDT","bids":[["3.1478","1001.5"]],"asks":[],"timestamp":1756900869690,"update_id":50197107,"fetch_time":1756900869736}
{"symbol":"TONUSDT","bids":[["3.1480","1144.9"]],"asks":[],"timestamp":1756900869710,"update_id":50197108,"fetch_time":1756900869756}
{"symbol":"TONUSDT","bids":[["3.1458","632.8"]],"asks":[],"timestamp":1756900870010,"update_id":50197109,"fetch_time":1756900870057}
{"symbol":"TONUSDT","bids":[],"asks":[["3.1506","138.8"]],"timestamp":1756900870429,"update_id":50197110,"fetch_time":1756900870480}
{"symbol":"TONUSDT","bids":[],"asks":[["3.1515","3677.8"],["3.1519","1215.2"]],"timestamp":1756900870510,"update_id":50197113,"fetch_time":1756900870556}
{"symbol":"TONUSDT","bids":[],"asks":[["3.1539","3184.7"]],"timestamp":1756900870609,"update_id":50197115,"fetch_time":1756900870656}
{"symbol":"TONUSDT","bids":[],"asks":[["3.1539","3182.7"]],"timestamp":1756900870629,"update_id":50197116,"fetch_time":1756900870676}
{"symbol":"TONUSDT","bids":[["3.1484","2449.5"]],"asks":[],"timestamp":1756900870749,"update_id":50197117,"fetch_time":1756900870796}
{"symbol":"TONUSDT","bids":[["3.1499","164.3"],["3.1498","1056.6"],["3.1497","871.8"],["3.1496","1290.1"],["3.1494","920.9"]],"asks":[],"timestamp":1756900871190,"update_id":50197120,"fetch_time":1756900871237}
{"symbol":"TONUSDT","bids":[],"asks":[["3.1550","5826.2"],["3.1551","5712.2"]],"timestamp":1756900871210,"update_id":50197121,"fetch_time":1756900871256}
{"symbol":"TONUSDT","bids":[],"asks":[["3.1506","507.7"],["3.1550","4558.7"],["3.1551","6979.7"]],"timestamp":1756900871249,"update_id":50197123,"fetch_time":1756900871301}
{"symbol":"TONUSDT","bids":[["3.1503","183.8"],["3.1497","1101.9"],["3.1496","1442.2"],["3.1478","1120.1"]],"asks":[["3.1504","0"],["3.1507","37.2"],["3.1509","1090.4"],["3.1510","3431.8"],["3.1514","4505.6"],["3.1517","1233.6"],["3.1518","3019.5"],["3.1539","3180.7"],["3.1540","2614.6"],["3.1554","1621.8"]],"timestamp":1756900871409,"update_id":50197129,"fetch_time":1756900871452}
{"symbol":"TONUSDT","bids":[],"asks":[["3.1540","2732.0"]],"timestamp":1756900871449,"update_id":50197131,"fetch_time":1756900871492}
{"symbol":"TONUSDT","bids":[["3.1498","794.5"],["3.1479","475.3"]],"asks":[],"timestamp":1756900871469,"update_id":50197132,"fetch_time":1756900871516}
{"symbol":"TONUSDT","bids":[],"asks":[["3.1508","1837.5"],["3.1509","995.4"],["3.1551","5712.2"],["3.1553","1387.9"]],"timestamp":1756900871490,"update_id":50197133,"fetch_time":1756900871533}
{"symbol":"TONUSDT","bids":[],"asks":[["3.1509","964.2"],["3.1510","3476.3"]],"timestamp":1756900871550,"update_id":50197135,"fetch_time":1756900871597}
