{"symbol":"TONUSDT","bids":[],"asks":[["3.1510","602.6"],["3.1511","1502.9"],["3.1512","1186.7"],["3.1513","1005.2"],["3.1514","2094.6"],["3.1515","498.0"]],"timestamp":1756900938609,"update_id":50198763,"fetch_time":1756900938655}
{"symbol":"TONUSDT","bids":[],"asks":[["3.1508","0"],["3.1556","2215.3"]],"timestamp":1756900938909,"update_id":50198764,"fetch_time":1756900938956}
{"symbol":"TONUSDT","bids":[],"asks":[["3.1509","1153.8"]],"timestamp":1756900939010,"update_id":50198765,"fetch_time":1756900939058}
{"symbol":"TONUSDT","bids":[["3.1486","591.6"],["3.1477","966.7"]],"asks":[],"timestamp":1756900939069,"update_id":50198766,"fetch_time":1756900939118}
{"symbol":"TONUSDT","bids":[["3.1498","1450.0"],["3.1497","1236.7"],["3.1494","1221.1"]],"asks":[],"timestamp":1756900939090,"update_id":50198767,"fetch_time":1756900939139}
{"symbol":"TONUSDT","bids":[],"asks":[["3.1509","677.7"]],"timestamp":1756900939110,"update_id":50198768,"fetch_time":1756900939160}
{"symbol":"TONUSDT","bids":[],"asks":[["3.1509","399.9"]],"timestamp":1756900939129,"update_id":50198769,"fetch_time":1756900939178}
{"symbol":"TONUSDT","bids":[["3.1499","1023.3"]],"asks":[],"timestamp":1756900939230,"update_id":50198770,"fetch_time":1756900939280}
{"symbol":"TONUSDT","bids":[],"asks":[["3.1511","999.5"],["3.1512","998.5"],["3.1514","1853.2"],["3.1515","466.4"],["3.1516","1389.7"],["3.1518","648.0"],["3.1520","1405.0"],["3.1522","1588.7"],["3.1526","2039.6"],["3.1528","4832.1"],["3.1530","2556.0"],["3.1532","1981.7"],["3.1534","2311.6"],["3.1536","2958.4"]],"timestamp":1756900939310,"update_id":50198774,"fetch_time":1756900939362}
{"symbol":"TONUSDT","bids":[],"asks":[["3.1511","340.8"],["3.1512","1807.7"],["3.1513","971.3"],["3.1514","1846.6"],["3.1515","450.3"],["3.1516","1383.1"],["3.1517","959.2"],["3.1520","1181.5"]],"timestamp":1756900939370,"update_id":50198777,"fetch_time":1756900939422}
{"symbol":"TONUSDT","bids":[],"asks":[["3.1512","1995.2"],["3.1513","907.9"],["3.1516","961.7"],["3.1555","2254.5"]],"timestamp":1756900939389,"update_id":50198778,"fetch_time":1756900939443}
{"symbol":"TONUSDT","bids":[],"asks":[["3.1510","166.1"],["3.1555","987.2"],["3.1556","3482.6"]],"timestamp":1756900939410,"update_id":50198779,"fetch_time":1756900939460}
{"symbol":"TONUSDT","bids":[],"asks":[["3.1511","499.5"],["3.1530","2557.8"],["3.1555","2254.5"],["3.1556","2215.3"]],"timestamp":1756900939430,"update_id":50198780,"fetch_time":1756900939481}
{"symbol":"TONUSDT","bids":[],"asks":[["3.1530","2831.9"]],"timestamp":1756900939469,"update_id":50198782,"fetch_time":1756900939513}
{"symbol":"TONUSDT","bids":[["3.1500","524.2"],["3.1492","3105.6"]],"asks":[],"timestamp":1756900939489,"update_id":50198783,"fetch_time":1756900939541}
{"symbol":"TONUSDT","bids":[],"asks":[["3.1514","1815.0"]],"timestamp":1756900939529,"update_id":50198784,"fetch_time":1756900939573}
{"symbol":"TONUSDT","bids":[["3.1489","1018.8"]],"asks":[],"timestamp":1756900939570,"update_id":50198785,"fetch_time":1756900939623}
{"symbol":"TONUSDT","bids":[],"asks":[["3.1513","431.9"]],"timestamp":1756900939589,"update_id":50198786,"fetch_time":1756900939645}
{"symbol":"TONUSDT","bids":[["3.1491","3205.1"]],"asks":[],"timestamp":1756900939630,"update_id":50198787,"fetch_time":1756900939683}
{"symbol":"TONUSDT","bids":[["3.1499","1023.3"]],"asks":[],"timestamp":1756900939750,"update_id":50198788,"fetch_time":1756900939796}
{"symbol":"TONUSDT","bids":[["3.1502","7.4"],["3.1493","862.6"]],"asks":[],"timestamp":1756900939789,"update_id":50198789,"fetch_time":1756900939835}
{"symbol":"TONUSDT","bids":[],"asks":[["3.1512","1963.5"]],"timestamp":1756900939889,"update_id":50198790,"fetch_time":1756900939937}
{"symbol":"TONUSDT","bids":[],"asks":[["3.1513","475.2"]],"timestamp":1756900939910,"update_id":50198791,"fetch_time":1756900939955}
{"symbol":"TONUSDT","bids":[],"asks":[["3.1513","411.8"],["3.1514","1783.3"]],"timestamp":1756900940370,"update_id":50198793,"fetch_time":1756900940416}
{"symbol":"TONUSDT","bids":[["3.1488","1414.8"]],"asks":[],"timestamp":1756900940409,"update_id":50198794,"fetch_time":1756900940460}
{"symbol":"TONUSDT","bids":[["3.1504","1.8"],["3.1499","117.4"],["3.1498","1313.2"],["3.1497","597.6"],["3.1496","1539.3"],["3.1494","1264.4"],["3.1491","2924.6"],["3.1488","1256.3"],["3.1487","461.4"],["3.1477","1052.3"],["3.1469","467.1"],["3.1456","1983.1"]],"asks":[["3.1505","137.7"],["3.1556","0"]],"timestamp":1756900940449,"update_id":50198795,"fetch_time":1756900940497}
{"symbol":"TONUSDT","bids":[["3.1502","5.0"],["3.1501","126.1"],["3.1500","5.0"],["3.1499","74.2"],["3.1498","844.7"],["3.1497","142.6"],["3.1496","310.1"],["3.1495","240.4"],["3.1494","1114.0"],["3.1493","776.1"],["3.1492","3086.2"],["3.1491","36.5"],["3.1490","1609.3"],["3.1489","651.2"],["3.1487","35.6"],["3.1486","2491.6"],["3.1485","3133.1"],["3.1483","522.1"],["3.1481","910.8"],["3.1480","1232.7"],["3.1479","1501.9"],["3.1478","910.8"],["3.1477","1068.1"],["3.1469","482.9"],["3.1464","3808.9"],["3.1463","9668.5"],["3.1458","2362.5"],["3.1456","2438.9"]],"asks":[["3.1505","105.8"],["3.1506","146.6"],["3.1507","48.3"],["3.1508","87.9"],["3.1509","906.1"],["3.1510","366.8"],["3.1511","1028.3"],["3.1512","2050.0"],["3.1513","946.8"],["3.1514","1945.4"],["3.1515","945.0"],["3.1517","902.4"],["3.1519","3009.2"],["3.1520","3111.5"],["3.1521","2277.0"],["3.1522","1525.3"],["3.1523","1724.1"],["3.1524","910.1"],["3.1525","1182.6"],["3.1526","1734.1"],["3.1528","5113.2"],["3.1529","3523.7"],["3.1533","579.9"],["3.1540","1655.0"],["3.1541","2119.7"],["3.1548","2296.4"],["3.1550","1759.6"],["3.1554","5365.9"],["3.1555","0"]],"timestamp":1756900940470,"update_id":50198796,"fetch_time":1756900940520}
{"symbol":"TONUSDT","bids":[],"asks":[["3.1510","2224.7"]],"timestamp":1756900940670,"update_id":50198805,"fetch_time":1756900940715}
{"symbol":"TONUSDT","bids":[],"asks":[["3.1510","2855.2"]],"timestamp":1756900940690,"update_id":50198806,"fetch_time":1756900940743}
{"symbol":"TONUSDT","bids":[],"asks":[["3.1505","334.1"],["3.1506","154.3"]],"timestamp":1756900940769,"update_id":50198809,"fetch_time":1756900940814}
{"symbol":"TONUSDT","bids":[["3.1496","538.6"],["3.1494","609.3"]],"asks":[],"timestamp":1756900940829,"update_id":50198810,"fetch_time":1756900940873}
{"symbol":"TONUSDT","bids":[["3.1496","323.7"]],"asks":[],"timestamp":1756900940850,"update_id":50198811,"fetch_time":1756900940895}
{"symbol":"TONUSDT","bids":[],"asks":[["3.1529","3313.6"]],"timestamp":1756900940889,"update_id":50198812,"fetch_time":1756900940945}
{"symbol":"TONUSDT","bids":[["3.1492","823.7"]],"asks":[],"timestamp":1756900940950,"update_id":50198813,"fetch_time":1756900940995}
{"symbol":"TONUSDT","bids":[],"asks":[["3.1506","167.2"],["3.1507","356.9"]],"timestamp":1756900940989,"update_id":50198815,"fetch_time":1756900941037}
{"symbol":"TONUSDT","bids":[],"asks":[["3.1508","862.6"],["3.1512","1198.3"]],"timestamp":1756900941029,"update_id":50198817,"fetch_time":1756900941076}
{"symbol":"TONUSDT","bids":[],"asks":[["3.1505","368.0"],["3.1508","894.0"],["3.1531","1549.3"]],"timestamp":1756900941070,"update_id":50198819,"fetch_time":1756900941118}
{"symbol":"TONUSDT","bids":[],"asks":[["3.1506","154.3"]],"timestamp":1756900941250,"update_id":50198822,"fetch_time":1756900941296}
{"symbol":"TONUSDT","bids":[],"asks":[["3.1510","2886.9"],["3.1512","1832.9"]],"timestamp":1756900941350,"update_id":50198825,"fetch_time":1756900941400}
{"symbol":"TONUSDT","bids":[],"asks":[["3.1512","1864.5"],["3.1529","2778.8"]],"timestamp":1756900941370,"update_id":50198826,"fetch_time":1756900941422}
{"symbol":"TONUSDT","bids":[["3.1494","796.6"]],"asks":[],"timestamp":1756900941430,"update_id":50198828,"fetch_time":1756900941481}
{"symbol":"TONUSDT","bids":[["3.1496","510.2"]],"asks":[],"timestamp":1756900941449,"update_id":50198829,"fetch_time":1756900941499}
{"symbol":"TONUSDT","bids":[["3.1490","2005.9"]],"asks":[],"timestamp":1756900941470,"update_id":50198830,"fetch_time":1756900941520}
{"symbol":"TONUSDT","bids":[],"asks":[["3.1531","1224.6"]],"timestamp":1756900941510,"update_id":50198832,"fetch_time":1756900941563}
{"symbol":"TONUSDT","bids":[["3.1490","2273.9"]],"asks":[],"timestamp":1756900941550,"update_id":50198834,"fetch_time":1756900941602}
{"symbol":"TONUSDT","bids":[],"asks":[["3.1528","3084.5"]],"timestamp":1756900941610,"update_id":50198837,"fetch_time":1756900941663}
{"symbol":"TONUSDT","bids":[],"asks":[["3.1519","3167.5"]],"timestamp":1756900941729,"update_id":50198838,"fetch_time":1756900941775}
{"symbol":"TONUSDT","bids":[],"asks":[["3.1508","1132.0"]],"timestamp":1756900942009,"update_id":50198839,"fetch_time":1756900942058}
{"symbol":"TONUSDT","bids":[["3.1473","1971.5"]],"asks":[],"timestamp":1756900942109,"update_id":50198840,"fetch_time":1756900942156}
{"symbol":"TONUSDT","bids":[],"asks":[["3.1506","146.3"]],"timestamp":1756900942290,"update_id":50198842,"fetch_time":1756900942341}
{"symbol":"TONUSDT","bids":[["3.1504","0"],["3.1503","0"],["3.1502","1.8"],["3.1494","614.9"],["3.1490","2022.5"],["3.1488","2583.8"],["3.1484","2486.7"],["3.1463","7862.7"],["3.1461","2703.1"],["3.1454","2955.6"],["3.1453","1645.5"]],"asks":[["3.1503","299.4"],["3.1504","8.3"],["3.1505","284.5"],["3.1506","341.0"],["3.1507","561.8"],["3.1508","1318.7"],["3.1509","1436.8"],["3.1510","2962.4"],["3.1511","786.3"],["3.1512","2110.1"],["3.1513","1730.3"],["3.1514","4472.3"],["3.1519","2527.7"],["3.1521","1846.6"],["3.1528","3082.7"],["3.1539","2605.9"],["3.1540","1653.0"],["3.1549","663.9"],["3.1553","0"],["3.1554","0"]],"timestamp":1756900942509,"update_id":50198844,"fetch_time":1756900942559}
{"symbol":"TONUSDT","bids":[["3.1478","542.0"]],"asks":[],"timestamp":1756900942589,"update_id":50198848,"fetch_time":1756900942636}
{"symbol":"TONUSDT","bids":[],"asks":[["3.1503","360.3"],["3.1504","35.9"],["3.1518","1448.0"]],"timestamp":1756900942709,"update_id":50198852,"fetch_time":1756900942765}
{"symbol":"TONUSDT","bids":[],"asks":[["3.1504","42.2"]],"timestamp":1756900942750,"update_id":50198853,"fetch_time":1756900942803}
{"symbol":"TONUSDT","bids":[],"asks":[["3.1519","3479.8"],["3.1524","316.2"]],"timestamp":1756900942829,"update_id":50198854,"fetch_time":1756900942884}
{"symbol":"TONUSDT","bids":[],"asks":[["3.1510","3347.4"]],"timestamp":1756900942869,"update_id":50198855,"fetch_time":1756900942923}
{"symbol":"TONUSDT","bids":[["3.1494","1038.4"]],"asks":[],"timestamp":1756900942950,"update_id":50198856,"fetch_time":1756900942994}
{"symbol":"TONUSDT","bids":[],"asks":[["3.1506","1276.5"]],"timestamp":1756900943009,"update_id":50198857,"fetch_time":1756900943054}
{"symbol":"TONUSDT","bids":[["3.1488","1713.4"]],"asks":[],"timestamp":1756900943070,"update_id":50198858,"fetch_time":1756900943118}
{"symbol":"TONUSDT","bids":[],"asks":[["3.1531","899.9"]],"timestamp":1756900943329,"update_id":50198860,"fetch_time":1756900943379}
{"symbol":"TONUSDT","bids":[],"asks":[["3.1507","596.2"]],"timestamp":1756900943489,"update_id":50198864,"fetch_time":1756900943536}
{"symbol":"TONUSDT","bids":[],"asks":[["3.1508","3668.7"],["3.1509","2103.6"],["3.1518","2237.1"],["3.1532","792.9"]],"timestamp":1756900943529,"update_id":50198865,"fetch_time":1756900943575}
{"symbol":"TONUSDT","bids":[],"asks":[["3.1503","331.1"],["3.1530","1678.6"]],"timestamp":1756900943549,"update_id":50198866,"fetch_time":1756900943602}
{"symbol":"TONUSDT","bids":[],"asks":[["3.1503","302.3"],["3.1506","1308.2"],["3.1538","888.2"]],"timestamp":1756900943570,"update_id":50198867,"fetch_time":1756900943619}
{"symbol":"TONUSDT","bids":[],"asks":[["3.1530","1392.1"],["3.1538","890.2"]],"timestamp":1756900943590,"update_id":50198868,"fetch_time":1756900943635}
{"symbol":"TONUSDT","bids":[["3.1456","2596.2"]],"asks":[],"timestamp":1756900943730,"update_id":50198869,"fetch_time":1756900943776}
{"symbol":"TONUSDT","bids":[],"asks":[["3.1503","300.0"],["3.1504","37.9"]],"timestamp":1756900943950,"update_id":50198870,"fetch_time":1756900944004}
{"symbol":"TONUSDT","bids":[["3.1502","0"],["3.1501","0"],["3.1500","1.8"],["3.1496","503.1"],["3.1495","427.6"],["3.1491","6.5"],["3.1452","4580.6"],["3.1451","5215.1"]],"asks":[["3.1501","28.8"],["3.1502","20.0"],["3.1503","117.9"],["3.1504","15.1"],["3.1505","587.4"],["3.1506","1881.2"],["3.1507","529.5"],["3.1508","3976.1"],["3.1509","1949.7"],["3.1510","2363.7"],["3.1512","1016.9"],["3.1526","1544.1"],["3.1537","4363.5"],["3.1538","888.2"],["3.1551","0"],["3.1552","0"]],"timestamp":1756900944049,"update_id":50198871,"fetch_time":1756900944097}
{"symbol":"TONUSDT","bids":[],"asks":[["3.1504","1063.8"],["3.1505","453.0"],["3.1506","2245.8"],["3.1507","1183.7"],["3.1528","3875.9"]],"timestamp":1756900944090,"update_id":50198873,"fetch_time":1756900944135}
{"symbol":"TONUSDT","bids":[],"asks":[["3.1506","2337.9"],["3.1508","1836.4"]],"timestamp":1756900944170,"update_id":50198876,"fetch_time":1756900944217}
{"symbol":"TONUSDT","bids":[],"asks":[["3.1504","1063.7"]],"timestamp":1756900944210,"update_id":50198877,"fetch_time":1756900944255}
{"symbol":"TONUSDT","bids":[["3.1498","137.0"]],"asks":[],"timestamp":1756900944229,"update_id":50198878,"fetch_time":1756900944276}
{"symbol":"TONUSDT","bids":[],"asks":[["3.1504","1061.9"]],"timestamp":1756900944250,"update_id":50198879,"fetch_time":1756900944298}
{"symbol":"TONUSDT","bids":[],"asks":[["3.1507","1424.8"]],"timestamp":1756900944330,"update_id":50198880,"fetch_time":1756900944379}
{"symbol":"TONUSDT","bids":[["3.1463","7006.3"]],"asks":[],"timestamp":1756900944349,"update_id":50198881,"fetch_time":1756900944396}
{"symbol":"TONUSDT","bids":[["3.1500","2.8"]],"asks":[],"timestamp":1756900944370,"update_id":50198882,"fetch_time":1756900944418}
{"symbol":"TONUSDT","bids":[["3.1481","1250.7"]],"asks":[],"timestamp":1756900944490,"update_id":50198886,"fetch_time":1756900944538}
{"symbol":"TONUSDT","bids":[["3.1500","0"],["3.1499","0"],["3.1498","0"],["3.1497","3.2"],["3.1495","254.3"],["3.1494","427.6"],["3.1493","494.3"],["3.1483","748.0"],["3.1478","552.3"],["3.1450","5400.6"],["3.1449","2843.4"],["3.1448","12186.0"]],"asks":[["3.1500","72.0"],["3.1501","388.6"],["3.1503","464.1"],["3.1505","881.6"],["3.1513","1429.2"],["3.1515","2875.0"],["3.1517","965.8"],["3.1550","0"]],"timestamp":1756900944629,"update_id":50198887,"fetch_time":1756900944679}
{"symbol":"TONUSDT","bids":[["3.1497","0"],["3.1496","297.9"],["3.1494","294.1"],["3.1493","13.7"],["3.1489","681.2"],["3.1487","1117.9"],["3.1486","2362.2"],["3.1485","4227.3"],["3.1480","1001.6"],["3.1447","631.4"]],"asks":[["3.1501","328.2"],["3.1503","1098.9"],["3.1504","179.4"],["3.1505","1380.7"],["3.1506","1932.2"],["3.1507","1379.3"],["3.1510","606.2"],["3.1523","1823.5"],["3.1524","755.8"],["3.1525","1518.2"],["3.1526","1588.3"],["3.1529","1659.0"],["3.1533","480.5"],["3.1535","753.7"],["3.1536","2790.4"],["3.1539","2015.2"],["3.1548","4230.2"]],"timestamp":1756900944650,"update_id":50198888,"fetch_time":1756900944701}
{"symbol":"TONUSDT","bids":[["3.1480","1180.1"],["3.1478","654.3"]],"asks":[["3.1501","0"],["3.1503","1078.8"],["3.1506","1306.7"],["3.1513","1617.4"],["3.1515","3176.1"],["3.1550","1759.6"]],"timestamp":1756900944750,"update_id":50198893,"fetch_time":1756900944803}
{"symbol":"TONUSDT","bids":[],"asks":[["3.1508","1472.4"]],"timestamp":1756900944789,"update_id":50198895,"fetch_time":1756900944842}
{"symbol":"TONUSDT","bids":[],"asks":[["3.1508","1409.3"]],"timestamp":1756900944830,"update_id":50198896,"fetch_time":1756900944884}
{"symbol":"TONUSDT","bids":[],"asks":[["3.1502","6.6"]],"timestamp":1756900944849,"update_id":50198897,"fetch_time":1756900944902}
{"symbol":"TONUSDT","bids":[["3.1497","130.4"],["3.1447","0"]],"asks":[["3.1518","1437.1"]],"timestamp":1756900944929,"update_id":50198898,"fetch_time":1756900944983}
{"symbol":"TONUSDT","bids":[],"asks":[["3.1516","2539.7"]],"timestamp":1756900944949,"update_id":50198899,"fetch_time":1756900944994}
{"symbol":"TONUSDT","bids":[],"asks":[["3.1519","2814.2"],["3.1521","4213.2"]],"timestamp":1756900945029,"update_id":50198901,"fetch_time":1756900945086}
{"symbol":"TONUSDT","bids":[],"asks":[["3.1524","757.6"]],"timestamp":1756900945050,"update_id":50198902,"fetch_time":1756900945096}
{"symbol":"TONUSDT","bids":[["3.1497","0"],["3.1491","230.4"],["3.1488","1927.7"],["3.1447","822.4"]],"asks":[["3.1502","21.4"],["3.1508","1374.8"]],"timestamp":1756900945069,"update_id":50198903,"fetch_time":1756900945124}
{"symbol":"TONUSDT","bids":[["3.1492","400.2"]],"asks":[],"timestamp":1756900945090,"update_id":50198904,"fetch_time":1756900945135}
{"symbol":"TONUSDT","bids":[],"asks":[["3.1501","13.2"],["3.1507","1155.1"],["3.1508","1338.9"],["3.1550","0"]],"timestamp":1756900945129,"update_id":50198906,"fetch_time":1756900945174}
{"symbol":"TONUSDT","bids":[],"asks":[["3.1532","1107.3"],["3.1537","4361.5"]],"timestamp":1756900945169,"update_id":50198908,"fetch_time":1756900945217}
{"symbol":"TONUSDT","bids":[],"asks":[["3.1546","4415.5"],["3.1548","2962.6"]],"timestamp":1756900945209,"update_id":50198909,"fetch_time":1756900945255}
{"symbol":"TONUSDT","bids":[["3.1487","578.6"]],"asks":[["3.1499","28.8"],["3.1500","196.0"],["3.1502","175.3"],["3.1505","1650.1"],["3.1508","1894.3"],["3.1509","2072.0"],["3.1534","1666.2"],["3.1535","751.7"],["3.1544","8782.4"],["3.1549","0"]],"timestamp":1756900945229,"update_id":50198910,"fetch_time":1756900945276}
{"symbol":"TONUSDT","bids":[],"asks":[["3.1504","1115.8"],["3.1505","2546.8"]],"timestamp":1756900945270,"update_id":50198912,"fetch_time":1756900945315}
{"symbol":"TONUSDT","bids":[],"asks":[["3.1502","178.5"],["3.1504","1179.2"]],"timestamp":1756900945289,"update_id":50198913,"fetch_time":1756900945336}
{"symbol":"TONUSDT","bids":[],"asks":[["3.1537","4712.2"],["3.1547","1337.7"]],"timestamp":1756900945310,"update_id":50198914,"fetch_time":1756900945358}
{"symbol":"TONUSDT","bids":[],"asks":[["3.1501","57.5"],["3.1505","2483.4"]],"timestamp":1756900945329,"update_id":50198915,"fetch_time":1756900945373}
{"symbol":"TONUSDT","bids":[],"asks":[["3.1506","830.1"],["3.1508","1323.1"]],"timestamp":1756900945350,"update_id":50198916,"fetch_time":1756900945397}
{"symbol":"TONUSDT","bids":[],"asks":[["3.1505","1546.8"]],"timestamp":1756900945370,"update_id":50198917,"fetch_time":1756900945418}
{"symbol":"TONUSDT","bids":[],"asks":[["3.1508","1259.9"],["3.1512","1762.5"]],"timestamp":1756900945489,"update_id":50198918,"fetch_time":1756900945538}
{"symbol":"TONUSDT","bids":[],"asks":[["3.1528","1663.4"]],"timestamp":1756900945529,"update_id":50198920,"fetch_time":1756900945580}
{"symbol":"TONUSDT","bids":[],"asks":[["3.1526","1112.2"]],"timestamp":1756900945550,"update_id":50198921,"fetch_time":1756900945598}
{"symbol":"TONUSDT","bids":[],"asks":[["3.1506","457.0"]],"timestamp":1756900945589,"update_id":50198922,"fetch_time":1756900945640}
{"symbol":"TONUSDT","bids":[],"asks":[["3.1506","393.6"]],"timestamp":1756900945670,"update_id":50198924,"fetch_time":1756900945722}
{"symbol":"TONUSDT","bids":[["3.1486","2532.3"],["3.1485","4248.7"]],"asks":[],"timestamp":1756900945770,"update_id":50198926,"fetch_time":1756900945820}
{"symbol":"TONUSDT","bids":[],"asks":[["3.1502","416.6"],["3.1508","1021.9"]],"timestamp":1756900946009,"update_id":50198927,"fetch_time":1756900946065}
{"symbol":"TONUSDT","bids":[],"asks":[["3.1500","183.2"],["3.1504","1181.0"]],"timestamp":1756900946050,"update_id":50198929,"fetch_time":1756900946103}
{"symbol":"TONUSDT","bids":[["3.1486","2362.2"]],"asks":[],"timestamp":1756900946129,"update_id":50198930,"fetch_time":1756900946174}
{"symbol":"TONUSDT","bids":[],"asks":[["3.1505","1568.3"],["3.1507","1411.7"]],"timestamp":1756900946169,"update_id":50198932,"fetch_time":1756900946216}
{"symbol":"TONUSDT","bids":[],"asks":[["3.1507","1115.0"]],"timestamp":1756900946230,"update_id":50198933,"fetch_time":1756900946276}
{"symbol":"TONUSDT","bids":[],"asks":[["3.1498","1.0"],["3.1499","0"],["3.1501","249.1"],["3.1503","605.8"],["3.1504","1022.3"],["3.1506","387.3"],["3.1512","1012.8"],["3.1522","981.9"],["3.1528","1665.2"],["3.1533","482.5"],["3.1534","1664.2"],["3.1547","1335.9"],["3.1548","4085.6"]],"timestamp":1756900946470,"update_id":50198934,"fetch_time":1756900946516}
{"symbol":"TONUSDT","bids":[],"asks":[["3.1503","1137.3"]],"timestamp":1756900946489,"update_id":50198935,"fetch_time":1756900946538}
{"symbol":"TONUSDT","bids":[],"asks":[["3.1500","195.9"],["3.1501","252.3"],["3.1504","1332.6"]],"timestamp":1756900946509,"update_id":50198936,"fetch_time":1756900946559}
{"symbol":"TONUSDT","bids":[],"asks":[["3.1503","1324.4"],["3.1506","684.0"]],"timestamp":1756900946530,"update_id":50198937,"fetch_time":1756900946580}
{"symbol":"TONUSDT","bids":[],"asks":[["3.1504","1269.2"]],"timestamp":1756900946550,"update_id":50198938,"fetch_time":1756900946598}
{"symbol":"TONUSDT","bids":[],"asks":[["3.1504","1082.0"],["3.1517","902.4"]],"timestamp":1756900946570,"update_id":50198939,"fetch_time":1756900946619}
{"symbol":"TONUSDT","bids":[],"asks":[["3.1504","332.8"]],"timestamp":1756900946589,"update_id":50198940,"fetch_time":1756900946640}
{"symbol":"TONUSDT","bids":[],"asks":[["3.1501","239.1"],["3.1502","410.0"]],"timestamp":1756900946630,"update_id":50198941,"fetch_time":1756900946679}
{"symbol":"TONUSDT","bids":[["3.1493","10.6"]],"asks":[],"timestamp":1756900946649,"update_id":50198942,"fetch_time":1756900946701}
{"symbol":"TONUSDT","bids":[],"asks":[["3.1498","2.0"]],"timestamp":1756900946850,"update_id":50198943,"fetch_time":1756900946902}
{"symbol":"TONUSDT","bids":[],"asks":[["3.1501","513.6"],["3.1506","446.0"]],"timestamp":1756900947010,"update_id":50198946,"fetch_time":1756900947055}
{"symbol":"TONUSDT","bids":[],"asks":[["3.1500","209.1"]],"timestamp":1756900947030,"update_id":50198947,"fetch_time":1756900947078}
{"symbol":"TONUSDT","bids":[],"asks":[["3.1502","459.2"]],"timestamp":1756900947070,"update_id":50198948,"fetch_time":1756900947114}
{"symbol":"TONUSDT","bids":[["3.1493","60.6"],["3.1454","1684.2"],["3.1450","6672.1"]],"asks":[],"timestamp":1756900947129,"update_id":50198949,"fetch_time":1756900947174}
{"symbol":"TONUSDT","bids":[],"asks":[["3.1515","3273.7"]],"timestamp":1756900947209,"update_id":50198951,"fetch_time":1756900947254}
{"symbol":"TONUSDT","bids":[],"asks":[["3.1519","2966.6"]],"timestamp":1756900947549,"update_id":50198953,"fetch_time":1756900947593}
{"symbol":"TONUSDT","bids":[["3.1490","1579.3"],["3.1489","701.7"],["3.1478","744.7"],["3.1472","4426.2"],["3.1469","734.5"]],"asks":[["3.1498","45.2"],["3.1499","17.2"],["3.1502","480.7"],["3.1503","1324.4"],["3.1504","589.8"],["3.1505","1546.8"],["3.1509","2087.6"],["3.1510","606.2"],["3.1511","806.4"],["3.1515","3592.0"],["3.1522","1247.0"],["3.1525","1163.4"],["3.1548","0"]],"timestamp":1756900947689,"update_id":50198954,"fetch_time":1756900947734}
{"symbol":"TONUSDT","bids":[["3.1486","2532.3"],["3.1485","4184.1"]],"asks":[["3.1497","20.0"],["3.1500","371.0"],["3.1503","1165.7"],["3.1530","1962.6"],["3.1532","1183.8"],["3.1533","480.5"],["3.1541","1005.3"],["3.1547","0"]],"timestamp":1756900947710,"update_id":50198955,"fetch_time":1756900947758}
{"symbol":"TONUSDT","bids":[["3.1486","2319.0"],["3.1484","2673.9"]],"asks":[],"timestamp":1756900947749,"update_id":50198957,"fetch_time":1756900947794}
{"symbol":"TONUSDT","bids":[],"asks":[["3.1545","3029.1"],["3.1546","2758.9"]],"timestamp":1756900947790,"update_id":50198958,"fetch_time":1756900947839}
{"symbol":"TONUSDT","bids":[],"asks":[["3.1545","1761.4"]],"timestamp":1756900947829,"update_id":50198959,"fetch_time":1756900947875}
{"symbol":"TONUSDT","bids":[["3.1485","2437.8"],["3.1484","773.9"],["3.1482","1384.5"],["3.1481","3084.6"],["3.1480","3050.1"]],"asks":[],"timestamp":1756900947890,"update_id":50198962,"fetch_time":1756900947933}
{"symbol":"TONUSDT","bids":[["3.1492","13.9"]],"asks":[],"timestamp":1756900947950,"update_id":50198964,"fetch_time":1756900947998}
{"symbol":"TONUSDT","bids":[],"asks":[["3.1500","609.1"],["3.1503","1422.7"],["3.1504","332.8"]],"timestamp":1756900948009,"update_id":50198966,"fetch_time":1756900948058}
{"symbol":"TONUSDT","bids":[["3.1483","590.0"],["3.1458","1673.3"]],"asks":[],"timestamp":1756900948050,"update_id":50198968,"fetch_time":1756900948097}
{"symbol":"TONUSDT","bids":[],"asks":[["3.1544","9669.2"],["3.1545","1761.4"]],"timestamp":1756900948090,"update_id":50198969,"fetch_time":1756900948134}
{"symbol":"TONUSDT","bids":[],"asks":[["3.1544","9669.1"]],"timestamp":1756900948210,"update_id":50198970,"fetch_time":1756900948257}
{"symbol":"TONUSDT","bids":[],"asks":[["3.1544","8401.4"],["3.1545","3029.1"]],"timestamp":1756900948230,"update_id":50198971,"fetch_time":1756900948273}
{"symbol":"TONUSDT","bids":[],"asks":[["3.1514","4470.6"],["3.1516","1408.0"]],"timestamp":1756900948250,"update_id":50198972,"fetch_time":1756900948293}
{"symbol":"TONUSDT","bids":[],"asks":[["3.1514","4500.6"],["3.1516","1378.0"]],"timestamp":1756900948270,"update_id":50198973,"fetch_time":1756900948317}
{"symbol":"TONUSDT","bids":[],"asks":[["3.1544","9669.1"],["3.1545","1761.4"]],"timestamp":1756900948309,"update_id":50198974,"fetch_time":1756900948354}
{"symbol":"TONUSDT","bids":[],"asks":[["3.1544","8401.4"],["3.1545","3029.1"]],"timestamp":1756900948330,"update_id":50198975,"fetch_time":1756900948378}
{"symbol":"TONUSDT","bids":[],"asks":[["3.1544","9669.1"],["3.1545","1761.4"]],"timestamp":1756900948350,"update_id":50198976,"fetch_time":1756900948394}
{"symbol":"TONUSDT","bids":[],"asks":[["3.1544","8401.4"],["3.1545","3029.1"]],"timestamp":1756900948369,"update_id":50198977,"fetch_time":1756900948414}
{"symbol":"TONUSDT","bids":[],"asks":[["3.1544","9669.1"],["3.1545","1761.4"]],"timestamp":1756900948470,"update_id":50198978,"fetch_time":1756900948518}
{"symbol":"TONUSDT","bids":[],"asks":[["3.1544","8401.4"],["3.1545","3029.1"]],"timestamp":1756900948490,"update_id":50198979,"fetch_time":1756900948534}
{"symbol":"TONUSDT","bids":[["3.1497","20.0"],["3.1488","1515.5"],["3.1487","665.1"],["3.1486","1255.9"],["3.1485","2830.1"],["3.1484","554.6"],["3.1447","0"]],"asks":[["3.1497","0"],["3.1499","0"],["3.1500","596.4"],["3.1501","470.4"],["3.1502","465.9"],["3.1503","1165.7"],["3.1504","589.8"],["3.1532","1181.8"],["3.1533","482.5"],["3.1547","1335.9"],["3.1548","4085.6"]],"timestamp":1756900948569,"update_id":50198980,"fetch_time":1756900948614}
{"symbol":"TONUSDT","bids":[["3.1492","250.9"],["3.1488","1558.8"],["3.1484","835.4"],["3.1483","802.0"],["3.1481","3029.4"],["3.1471","1657.2"],["3.1467","1292.6"],["3.1461","663.9"]],"asks":[],"timestamp":1756900948590,"update_id":50198981,"fetch_time":1756900948638}
{"symbol":"TONUSDT","bids":[],"asks":[["3.1498","49.0"],["3.1501","434.0"],["3.1507","1091.3"],["3.1545","1761.4"]],"timestamp":1756900948630,"update_id":50198983,"fetch_time":1756900948678}
{"symbol":"TONUSDT","bids":[],"asks":[["3.1546","4026.6"]],"timestamp":1756900948649,"update_id":50198984,"fetch_time":1756900948698}
{"symbol":"TONUSDT","bids":[["3.1497","0"],["3.1491","319.7"],["3.1467","1504.6"],["3.1461","875.9"],["3.1447","822.4"]],"asks":[["3.1513","3487.4"],["3.1515","1722.0"]],"timestamp":1756900948689,"update_id":50198985,"fetch_time":1756900948734}
{"symbol":"TONUSDT","bids":[],"asks":[["3.1502","444.4"],["3.1503","1187.2"]],"timestamp":1756900948810,"update_id":50198988,"fetch_time":1756900948854}
{"symbol":"TONUSDT","bids":[["3.1483","1602.0"]],"asks":[],"timestamp":1756900948850,"update_id":50198989,"fetch_time":1756900948893}
{"symbol":"TONUSDT","bids":[],"asks":[["3.1501","470.4"]],"timestamp":1756900948870,"update_id":50198990,"fetch_time":1756900948918}
{"symbol":"TONUSDT","bids":[["3.1496","288.6"]],"asks":[],"timestamp":1756900948890,"update_id":50198991,"fetch_time":1756900948938}
{"symbol":"TONUSDT","bids":[["3.1496","0"],["3.1490","1579.3"],["3.1489","715.0"],["3.1486","1255.9"],["3.1483","845.2"],["3.1460","1724.7"],["3.1459","3092.1"],["3.1446","2403.6"]],"asks":[["3.1499","10.5"],["3.1500","609.1"],["3.1501","493.5"],["3.1502","489.9"],["3.1548","0"]],"timestamp":1756900948909,"update_id":50198992,"fetch_time":1756900948954}
{"symbol":"TONUSDT","bids":[["3.1491","319.7"],["3.1490","1766.3"],["3.1489","671.7"],["3.1486","1787.0"],["3.1484","1141.2"],["3.1483","888.5"],["3.1462","643.7"]],"asks":[["3.1497","28.8"],["3.1502","676.9"],["3.1503","1661.2"],["3.1504","589.8"],["3.1505","1546.8"],["3.1527","1668.6"],["3.1532","1183.8"],["3.1533","480.5"],["3.1539","2051.6"],["3.1547","0"]],"timestamp":1756900948929,"update_id":50198993,"fetch_time":1756900948982}
{"symbol":"TONUSDT","bids":[],"asks":[["3.1502","864.0"],["3.1503","2084.7"],["3.1522","1302.2"],["3.1534","1609.0"],["3.1545","3029.1"],["3.1546","2758.9"]],"timestamp":1756900948950,"update_id":50198994,"fetch_time":1756900948998}
{"symbol":"TONUSDT","bids":[],"asks":[["3.1503","1429.4"],["3.1544","9669.1"],["3.1545","1761.4"]],"timestamp":1756900949009,"update_id":50198997,"fetch_time":1756900949058}
{"symbol":"TONUSDT","bids":[],"asks":[["3.1503","1085.1"]],"timestamp":1756900949069,"update_id":50198999,"fetch_time":1756900949114}
{"symbol":"TONUSDT","bids":[],"asks":[["3.1506","819.1"]],"timestamp":1756900949090,"update_id":50199000,"fetch_time":1756900949134}
{"symbol":"TONUSDT","bids":[["3.1491","369.7"],["3.1484","835.4"]],"asks":[],"timestamp":1756900949110,"update_id":50199001,"fetch_time":1756900949158}
{"symbol":"TONUSDT","bids":[],"asks":[["3.1499","0"],["3.1547","344.3"]],"timestamp":1756900949129,"update_id":50199002,"fetch_time":1756900949174}
{"symbol":"TONUSDT","bids":[["3.1483","782.6"],["3.1474","1334.6"]],"asks":[],"timestamp":1756900949229,"update_id":50199005,"fetch_time":1756900949274}
{"symbol":"TONUSDT","bids":[],"asks":[["3.1500","424.5"],["3.1501","311.7"],["3.1502","1974.1"],["3.1516","1378.0"],["3.1520","3280.9"],["3.1527","1668.6"],["3.1528","2631.5"],["3.1530","1962.6"],["3.1531","1892.6"]],"timestamp":1756900949329,"update_id":50199006,"fetch_time":1756900949374}
{"symbol":"TONUSDT","bids":[["3.1490","1809.5"]],"asks":[],"timestamp":1756900949429,"update_id":50199007,"fetch_time":1756900949474}
{"symbol":"TONUSDT","bids":[],"asks":[["3.1516","1723.1"],["3.1520","2340.4"],["3.1526","1951.8"],["3.1528","1665.2"]],"timestamp":1756900949470,"update_id":50199008,"fetch_time":1756900949518}
{"symbol":"TONUSDT","bids":[],"asks":[["3.1501","280.1"],["3.1524","958.5"],["3.1530","2380.1"],["3.1531","899.9"]],"timestamp":1756900949489,"update_id":50199009,"fetch_time":1756900949534}
{"symbol":"TONUSDT","bids":[["3.1496","140.0"],["3.1486","2092.8"],["3.1485","2524.3"],["3.1446","0"]],"asks":[["3.1500","284.5"],["3.1544","7435.6"],["3.1545","3029.1"]],"timestamp":1756900949549,"update_id":50199010,"fetch_time":1756900949594}
{"symbol":"TONUSDT","bids":[["3.1496","0"],["3.1491","599.9"],["3.1483","739.4"],["3.1446","2403.6"]],"asks":[["3.1502","1787.1"],["3.1512","3683.2"],["3.1513","2426.7"]],"timestamp":1756900949589,"update_id":50199012,"fetch_time":1756900949634}
{"symbol":"TONUSDT","bids":[["3.1491","369.7"],["3.1483","782.6"]],"asks":[],"timestamp":1756900949629,"update_id":50199014,"fetch_time":1756900949678}
{"symbol":"TONUSDT","bids":[],"asks":[["3.1502","1974.0"]],"timestamp":1756900949650,"update_id":50199015,"fetch_time":1756900949697}
{"symbol":"TONUSDT","bids":[],"asks":[["3.1520","3182.1"]],"timestamp":1756900949670,"update_id":50199016,"fetch_time":1756900949713}
{"symbol":"TONUSDT","bids":[],"asks":[["3.1500","320.3"],["3.1501","325.6"],["3.1505","1801.5"]],"timestamp":1756900949750,"update_id":50199018,"fetch_time":1756900949794}
{"symbol":"TONUSDT","bids":[["3.1473","2103.5"]],"asks":[],"timestamp":1756900949909,"update_id":50199019,"fetch_time":1756900949954}
{"symbol":"TONUSDT","bids":[["3.1484","1124.4"]],"asks":[],"timestamp":1756900949950,"update_id":50199021,"fetch_time":1756900949993}
{"symbol":"TONUSDT","bids":[],"asks":[["3.1501","87.5"],["3.1502","1735.9"]],"timestamp":1756900950010,"update_id":50199022,"fetch_time":1756900950063}
{"symbol":"TONUSDT","bids":[],"asks":[["3.1500","284.5"]],"timestamp":1756900950129,"update_id":50199023,"fetch_time":1756900950173}
{"symbol":"TONUSDT","bids":[],"asks":[["3.1501","246.2"]],"timestamp":1756900950329,"update_id":50199024,"fetch_time":1756900950378}
{"symbol":"TONUSDT","bids":[["3.1496","140.0"],["3.1446","0"]],"asks":[["3.1500","443.2"]],"timestamp":1756900950349,"update_id":50199025,"fetch_time":1756900950402}
{"symbol":"TONUSDT","bids":[],"asks":[["3.1497","0"],["3.1500","400.0"],["3.1501","164.3"],["3.1502","644.1"],["3.1503","1040.0"],["3.1504","317.7"],["3.1505","1385.2"],["3.1506","603.1"],["3.1507","903.1"],["3.1509","1786.5"],["3.1511","618.2"],["3.1513","2238.5"],["3.1515","1420.9"],["3.1532","1181.8"],["3.1533","482.5"],["3.1544","7435.6"],["3.1545","3029.1"],["3.1548","3030.8"]],"timestamp":1756900950369,"update_id":50199026,"fetch_time":1756900950418}
{"symbol":"TONUSDT","bids":[],"asks":[["3.1500","241.3"],["3.1503","1664.7"]],"timestamp":1756900950391,"update_id":50199027,"fetch_time":1756900950442}
{"symbol":"TONUSDT","bids":[],"asks":[["3.1504","360.9"]],"timestamp":1756900950430,"update_id":50199029,"fetch_time":1756900950482}
{"symbol":"TONUSDT","bids":[["3.1490","1579.3"]],"asks":[],"timestamp":1756900950489,"update_id":50199030,"fetch_time":1756900950534}
{"symbol":"TONUSDT","bids":[],"asks":[["3.1501","5.6"],["3.1516","1378.0"],["3.1522","2242.6"]],"timestamp":1756900950550,"update_id":50199033,"fetch_time":1756900950598}
{"symbol":"TONUSDT","bids":[["3.1497","20.0"],["3.1494","67.6"],["3.1484","1081.2"],["3.1447","0"]],"asks":[["3.1504","317.7"],["3.1533","480.5"]],"timestamp":1756900950569,"update_id":50199034,"fetch_time":1756900950622}
{"symbol":"TONUSDT","bids":[],"asks":[["3.1526","1112.2"],["3.1530","2928.9"],["3.1533","1475.2"]],"timestamp":1756900950629,"update_id":50199037,"fetch_time":1756900950678}
{"symbol":"TONUSDT","bids":[],"asks":[["3.1509","2027.6"]],"timestamp":1756900950670,"update_id":50199039,"fetch_time":1756900950718}
{"symbol":"TONUSDT","bids":[],"asks":[["3.1546","3678.3"],["3.1547","344.3"]],"timestamp":1756900950729,"update_id":50199041,"fetch_time":1756900950774}
{"symbol":"TONUSDT","bids":[],"asks":[["3.1546","2410.6"],["3.1547","1611.9"]],"timestamp":1756900950750,"update_id":50199042,"fetch_time":1756900950798}
{"symbol":"TONUSDT","bids":[["3.1494","169.7"]],"asks":[],"timestamp":1756900950770,"update_id":50199043,"fetch_time":1756900950814}
{"symbol":"TONUSDT","bids":[["3.1496","0"],["3.1494","5.0"],["3.1493","60.6"],["3.1492","294.1"],["3.1489","737.7"],["3.1447","822.4"]],"asks":[],"timestamp":1756900950850,"update_id":50199044,"fetch_time":1756900950899}
{"symbol":"TONUSDT","bids":[["3.1497","0"],["3.1493","58.2"],["3.1492","250.8"],["3.1491","53.2"],["3.1490","1579.3"],["3.1489","694.4"],["3.1446","2403.6"]],"asks":[["3.1501","194.5"],["3.1502","727.4"],["3.1503","229.0"],["3.1504","1402.8"],["3.1505","1214.7"],["3.1508","1210.1"],["3.1510","907.3"],["3.1512","4097.2"],["3.1514","4450.1"],["3.1516","2017.8"],["3.1518","2189.8"]],"timestamp":1756900950870,"update_id":50199045,"fetch_time":1756900950915}
{"symbol":"TONUSDT","bids":[],"asks":[["3.1504","841.5"]],"timestamp":1756900950950,"update_id":50199048,"fetch_time":1756900950993}
{"symbol":"TONUSDT","bids":[],"asks":[["3.1504","778.1"]],"timestamp":1756900950989,"update_id":50199049,"fetch_time":1756900951034}
{"symbol":"TONUSDT","bids":[["3.1460","3234.9"]],"asks":[],"timestamp":1756900951029,"update_id":50199051,"fetch_time":1756900951078}
{"symbol":"TONUSDT","bids":[["3.1496","140.0"],["3.1446","0"]],"asks":[],"timestamp":1756900951109,"update_id":50199053,"fetch_time":1756900951159}
{"symbol":"TONUSDT","bids":[["3.1491","556.6"]],"asks":[],"timestamp":1756900951150,"update_id":50199055,"fetch_time":1756900951197}
{"symbol":"TONUSDT","bids":[["3.1490","1579.3"]],"asks":[],"timestamp":1756900951209,"update_id":50199056,"fetch_time":1756900951253}
{"symbol":"TONUSDT","bids":[["3.1496","0"],["3.1446","2403.6"]],"asks":[],"timestamp":1756900951249,"update_id":50199057,"fetch_time":1756900951293}
{"symbol":"TONUSDT","bids":[["3.1489","674.3"],["3.1488","1677.1"],["3.1487","621.9"],["3.1486","1928.4"],["3.1485","2481.1"],["3.1478","642.7"]],"asks":[],"timestamp":1756900951290,"update_id":50199059,"fetch_time":1756900951341}
{"symbol":"TONUSDT","bids":[["3.1486","1971.6"]],"asks":[],"timestamp":1756900951529,"update_id":50199062,"fetch_time":1756900951573}
{"symbol":"TONUSDT","bids":[],"asks":[["3.1510","1162.6"]],"timestamp":1756900951629,"update_id":50199063,"fetch_time":1756900951673}
{"symbol":"TONUSDT","bids":[],"asks":[["3.1498","6.1"]],"timestamp":1756900951650,"update_id":50199064,"fetch_time":1756900951698}
{"symbol":"TONUSDT","bids":[["3.1488","1633.8"],["3.1487","578.6"],["3.1486","1928.3"],["3.1485","2481.0"],["3.1484","1037.9"]],"asks":[],"timestamp":1756900951730,"update_id":50199065,"fetch_time":1756900951774}
{"symbol":"TONUSDT","bids":[],"asks":[["3.1502","888.2"]],"timestamp":1756900951930,"update_id":50199066,"fetch_time":1756900951973}
{"symbol":"TONUSDT","bids":[],"asks":[["3.1545","3029.1"],["3.1546","2410.6"]],"timestamp":1756900952090,"update_id":50199067,"fetch_time":1756900952134}
{"symbol":"TONUSDT","bids":[],"asks":[["3.1500","16.6"],["3.1522","1732.5"]],"timestamp":1756900952110,"update_id":50199068,"fetch_time":1756900952154}
{"symbol":"TONUSDT","bids":[],"asks":[["3.1531","1593.5"],["3.1533","482.5"]],"timestamp":1756900952130,"update_id":50199069,"fetch_time":1756900952178}
{"symbol":"TONUSDT","bids":[],"asks":[["3.1500","16.6"]],"timestamp":1756900952549,"update_id":50199072,"fetch_time":1756900952593}
{"symbol":"TONUSDT","bids":[],"asks":[["3.1516","2385.7"]],"timestamp":1756900952649,"update_id":50199073,"fetch_time":1756900952698}
{"symbol":"TONUSDT","bids":[["3.1484","1081.2"]],"asks":[],"timestamp":1756900952689,"update_id":50199074,"fetch_time":1756900952734}
{"symbol":"TONUSDT","bids":[["3.1485","2768.1"]],"asks":[],"timestamp":1756900952709,"update_id":50199075,"fetch_time":1756900952758}
{"symbol":"TONUSDT","bids":[],"asks":[["3.1498","5.1"]],"timestamp":1756900952850,"update_id":50199076,"fetch_time":1756900952893}
{"symbol":"TONUSDT","bids":[["3.1495","59.9"]],"asks":[],"timestamp":1756900952869,"update_id":50199077,"fetch_time":1756900952917}
{"symbol":"TONUSDT","bids":[["3.1490","1816.2"],["3.1489","724.3"]],"asks":[],"timestamp":1756900953070,"update_id":50199078,"fetch_time":1756900953113}
{"symbol":"TONUSDT","bids":[],"asks":[["3.1544","8703.3"],["3.1545","1761.4"]],"timestamp":1756900953169,"update_id":50199079,"fetch_time":1756900953217}
{"symbol":"TONUSDT","bids":[],"asks":[["3.1498","145.1"]],"timestamp":1756900953310,"update_id":50199080,"fetch_time":1756900953353}
{"symbol":"TONUSDT","bids":[],"asks":[["3.1499","9.6"],["3.1548","0"]],"timestamp":1756900953350,"update_id":50199082,"fetch_time":1756900953393}
{"symbol":"TONUSDT","bids":[],"asks":[["3.1543","1682.9"],["3.1544","7435.6"]],"timestamp":1756900953390,"update_id":50199083,"fetch_time":1756900953438}
{"symbol":"TONUSDT","bids":[],"asks":[["3.1497","28.8"],["3.1500","184.7"],["3.1532","1183.8"],["3.1533","480.5"],["3.1547","0"]],"timestamp":1756900953449,"update_id":50199084,"fetch_time":1756900953493}
{"symbol":"TONUSDT","bids":[],"asks":[["3.1543","1682.9"],["3.1544","7435.6"]],"timestamp":1756900953570,"update_id":50199090,"fetch_time":1756900953614}
{"symbol":"TONUSDT","bids":[],"asks":[["3.1503","1108.1"]],"timestamp":1756900953589,"update_id":50199091,"fetch_time":1756900953638}
{"symbol":"TONUSDT","bids":[],"asks":[["3.1511","1478.3"]],"timestamp":1756900953669,"update_id":50199092,"fetch_time":1756900953714}
{"symbol":"TONUSDT","bids":[],"asks":[["3.1520","2914.3"]],"timestamp":1756900953689,"update_id":50199093,"fetch_time":1756900953738}
{"symbol":"TONUSDT","bids":[],"asks":[["3.1500","422.8"]],"timestamp":1756900954009,"update_id":50199094,"fetch_time":1756900954054}
{"symbol":"TONUSDT","bids":[],"asks":[["3.1528","2600.5"],["3.1529","997.6"]],"timestamp":1756900954129,"update_id":50199095,"fetch_time":1756900954174}
{"symbol":"TONUSDT","bids":[],"asks":[["3.1528","2161.4"]],"timestamp":1756900954149,"update_id":50199096,"fetch_time":1756900954194}
{"symbol":"TONUSDT","bids":[],"asks":[["3.1503","1356.5"],["3.1504","431.1"]],"timestamp":1756900954230,"update_id":50199097,"fetch_time":1756900954274}
{"symbol":"TONUSDT","bids":[["3.1485","2806.0"],["3.1484","792.2"]],"asks":[],"timestamp":1756900954389,"update_id":50199098,"fetch_time":1756900954433}
{"symbol":"TONUSDT","bids":[],"asks":[["3.1545","2617.9"]],"timestamp":1756900954550,"update_id":50199099,"fetch_time":1756900954597}
{"symbol":"TONUSDT","bids":[],"asks":[["3.1536","5766.0"],["3.1544","4460.0"]],"timestamp":1756900954690,"update_id":50199100,"fetch_time":1756900954738}
{"symbol":"TONUSDT","bids":[["3.1484","792.2"]],"asks":[],"timestamp":1756900954769,"update_id":50199102,"fetch_time":1756900954813}
{"symbol":"TONUSDT","bids":[["3.1471","705.1"],["3.1469","1686.7"]],"asks":[],"timestamp":1756900954789,"update_id":50199103,"fetch_time":1756900954837}
{"symbol":"TONUSDT","bids":[["3.1470","2960.6"]],"asks":[],"timestamp":1756900954810,"update_id":50199104,"fetch_time":1756900954853}
{"symbol":"TONUSDT","bids":[],"asks":[["3.1498","5.1"]],"timestamp":1756900955010,"update_id":50199105,"fetch_time":1756900955058}
{"symbol":"TONUSDT","bids":[["3.1486","1787.0"],["3.1485","2806.0"]],"asks":[],"timestamp":1756900955029,"update_id":50199106,"fetch_time":1756900955074}
{"symbol":"TONUSDT","bids":[],"asks":[["3.1499","0"],["3.1500","409.4"],["3.1547","344.3"]],"timestamp":1756900955050,"update_id":50199107,"fetch_time":1756900955097}
{"symbol":"TONUSDT","bids":[["3.1482","2800.4"]],"asks":[],"timestamp":1756900955090,"update_id":50199109,"fetch_time":1756900955137}
{"symbol":"TONUSDT","bids":[],"asks":[["3.1543","415.1"],["3.1544","5727.8"]],"timestamp":1756900955569,"update_id":50199110,"fetch_time":1756900955614}
{"symbol":"TONUSDT","bids":[["3.1487","665.1"],["3.1484","835.4"]],"asks":[],"timestamp":1756900955590,"update_id":50199111,"fetch_time":1756900955638}
{"symbol":"TONUSDT","bids":[["3.1496","73.9"],["3.1478","617.5"],["3.1476","1255.4"],["3.1446","0"]],"asks":[["3.1511","678.3"]],"timestamp":1756900955729,"update_id":50199112,"fetch_time":1756900955773}
{"symbol":"TONUSDT","bids":[["3.1491","556.6"]],"asks":[],"timestamp":1756900955790,"update_id":50199113,"fetch_time":1756900955833}
{"symbol":"TONUSDT","bids":[["3.1490","1629.3"]],"asks":[],"timestamp":1756900955830,"update_id":50199114,"fetch_time":1756900955878}
{"symbol":"TONUSDT","bids":[],"asks":[["3.1543","1682.9"],["3.1544","4460.0"]],"timestamp":1756900956229,"update_id":50199115,"fetch_time":1756900956274}
{"symbol":"TONUSDT","bids":[],"asks":[["3.1543","415.1"],["3.1544","5727.8"]],"timestamp":1756900956310,"update_id":50199116,"fetch_time":1756900956354}
{"symbol":"TONUSDT","bids":[],"asks":[["3.1543","1682.9"],["3.1544","4460.0"]],"timestamp":1756900956369,"update_id":50199117,"fetch_time":1756900956414}
{"symbol":"TONUSDT","bids":[],"asks":[["3.1521","4213.2"]],"timestamp":1756900956389,"update_id":50199118,"fetch_time":1756900956438}
{"symbol":"TONUSDT","bids":[],"asks":[["3.1543","415.1"],["3.1544","5727.8"]],"timestamp":1756900956410,"update_id":50199119,"fetch_time":1756900956454}
{"symbol":"TONUSDT","bids":[],"asks":[["3.1543","1682.9"],["3.1544","4460.0"]],"timestamp":1756900956450,"update_id":50199120,"fetch_time":1756900956494}
{"symbol":"TONUSDT","bids":[],"asks":[["3.1543","415.1"],["3.1544","5727.8"]],"timestamp":1756900956470,"update_id":50199121,"fetch_time":1756900956514}
{"symbol":"TONUSDT","bids":[],"asks":[["3.1500","439.2"]],"timestamp":1756900956570,"update_id":50199122,"fetch_time":1756900956614}
{"symbol":"TONUSDT","bids":[],"asks":[["3.1543","1682.9"],["3.1544","4460.0"]],"timestamp":1756900956790,"update_id":50199123,"fetch_time":1756900956838}
{"symbol":"TONUSDT","bids":[],"asks":[["3.1543","415.1"],["3.1544","5727.8"]],"timestamp":1756900956830,"update_id":50199124,"fetch_time":1756900956874}
{"symbol":"TONUSDT","bids":[],"asks":[["3.1543","1682.9"],["3.1544","4460.0"]],"timestamp":1756900956870,"update_id":50199125,"fetch_time":1756900956914}
{"symbol":"TONUSDT","bids":[],"asks":[["3.1543","415.1"],["3.1544","5727.8"]],"timestamp":1756900956909,"update_id":50199126,"fetch_time":1756900956954}
{"symbol":"TONUSDT","bids":[],"asks":[["3.1503","1108.1"],["3.1504","756.3"]],"timestamp":1756900957490,"update_id":50199127,"fetch_time":1756900957534}
{"symbol":"TONUSDT","bids":[["3.1477","490.5"]],"asks":[],"timestamp":1756900957870,"update_id":50199128,"fetch_time":1756900957914}
{"symbol":"TONUSDT","bids":[["3.1496","67.8"]],"asks":[],"timestamp":1756900957890,"update_id":50199129,"fetch_time":1756900957934}
{"symbol":"TONUSDT","bids":[],"asks":[["3.1544","4460.0"],["3.1545","3885.6"]],"timestamp":1756900958150,"update_id":50199131,"fetch_time":1756900958198}
{"symbol":"TONUSDT","bids":[],"asks":[["3.1500","47.1"]],"timestamp":1756900958230,"update_id":50199135,"fetch_time":1756900958274}
{"symbol":"TONUSDT","bids":[],"asks":[["3.1500","17.3"],["3.1506","603.1"]],"timestamp":1756900958249,"update_id":50199136,"fetch_time":1756900958293}
{"symbol":"TONUSDT","bids":[],"asks":[["3.1500","47.1"]],"timestamp":1756900958290,"update_id":50199137,"fetch_time":1756900958333}
{"symbol":"TONUSDT","bids":[],"asks":[["3.1500","205.8"]],"timestamp":1756900958309,"update_id":50199138,"fetch_time":1756900958358}
{"symbol":"TONUSDT","bids":[["3.1480","3034.3"]],"asks":[],"timestamp":1756900958390,"update_id":50199139,"fetch_time":1756900958438}
{"symbol":"TONUSDT","bids":[],"asks":[["3.1498","4.1"]],"timestamp":1756900958509,"update_id":50199140,"fetch_time":1756900958554}
{"symbol":"TONUSDT","bids":[["3.1485","2578.8"]],"asks":[],"timestamp":1756900958730,"update_id":50199141,"fetch_time":1756900958782}
{"symbol":"TONUSDT","bids":[["3.1486","1976.5"]],"asks":[],"timestamp":1756900958749,"update_id":50199142,"fetch_time":1756900958798}
{"symbol":"TONUSDT","bids":[],"asks":[["3.1500","176.0"]],"timestamp":1756900958770,"update_id":50199143,"fetch_time":1756900958814}
{"symbol":"TONUSDT","bids":[["3.1464","3793.1"]],"asks":[],"timestamp":1756900958830,"update_id":50199144,"fetch_time":1756900958882}
{"symbol":"TONUSDT","bids":[["3.1489","744.5"]],"asks":[],"timestamp":1756900958950,"update_id":50199146,"fetch_time":1756900958994}
{"symbol":"TONUSDT","bids":[["3.1489","787.7"]],"asks":[],"timestamp":1756900958969,"update_id":50199147,"fetch_time":1756900959018}
{"symbol":"TONUSDT","bids":[["3.1490","1672.6"]],"asks":[],"timestamp":1756900959049,"update_id":50199148,"fetch_time":1756900959093}
{"symbol":"TONUSDT","bids":[],"asks":[["3.1497","0"],["3.1548","3030.8"]],"timestamp":1756900959150,"update_id":50199149,"fetch_time":1756900959198}
{"symbol":"TONUSDT","bids":[["3.1460","5040.7"],["3.1459","1286.3"]],"asks":[],"timestamp":1756900959630,"update_id":50199154,"fetch_time":1756900959674}
{"symbol":"TONUSDT","bids":[],"asks":[["3.1498","4.2"],["3.1500","14.1"],["3.1503","210.6"],["3.1508","1021.9"],["3.1510","861.5"],["3.1512","3683.2"],["3.1514","3923.2"],["3.1516","2143.0"],["3.1518","1437.1"],["3.1523","2992.1"],["3.1527","2326.1"],["3.1529","1298.7"],["3.1531","1313.9"],["3.1533","1009.4"],["3.1535","1393.5"],["3.1537","5464.9"]],"timestamp":1756900959669,"update_id":50199155,"fetch_time":1756900959719}
{"symbol":"TONUSDT","bids":[],"asks":[["3.1503","554.4"],["3.1505","1495.0"],["3.1507","1148.7"],["3.1509","2022.0"],["3.1511","1032.2"],["3.1513","2765.4"],["3.1515","1963.1"],["3.1516","1775.1"],["3.1517","1655.1"],["3.1521","5054.9"],["3.1527","2137.9"],["3.1529","997.6"],["3.1531","899.9"],["3.1533","482.5"],["3.1535","751.7"],["3.1537","4712.2"],["3.1539","2029.5"]],"timestamp":1756900959690,"update_id":50199156,"fetch_time":1756900959734}
{"symbol":"TONUSDT","bids":[],"asks":[["3.1503","927.9"],["3.1516","1947.7"]],"timestamp":1756900959709,"update_id":50199157,"fetch_time":1756900959754}
{"symbol":"TONUSDT","bids":[],"asks":[["3.1503","1208.2"]],"timestamp":1756900959730,"update_id":50199158,"fetch_time":1756900959774}
{"symbol":"TONUSDT","bids":[],"asks":[["3.1505","1214.7"]],"timestamp":1756900959789,"update_id":50199159,"fetch_time":1756900959834}
{"symbol":"TONUSDT","bids":[["3.1493","119.2"]],"asks":[],"timestamp":1756900960009,"update_id":50199160,"fetch_time":1756900960054}
{"symbol":"TONUSDT","bids":[],"asks":[["3.1544","4971.8"]],"timestamp":1756900960029,"update_id":50199161,"fetch_time":1756900960074}
{"symbol":"TONUSDT","bids":[["3.1490","1629.3"],["3.1489","744.4"]],"asks":[],"timestamp":1756900960250,"update_id":50199162,"fetch_time":1756900960294}
{"symbol":"TONUSDT","bids":[["3.1497","67.4"],["3.1447","0"]],"asks":[["3.1498","0"],["3.1500","0"],["3.1501","339.2"],["3.1502","743.5"],["3.1503","210.6"],["3.1505","318.0"],["3.1506","646.4"],["3.1507","960.5"],["3.1508","1065.2"],["3.1509","1720.9"],["3.1511","618.2"],["3.1513","2238.5"],["3.1515","1323.3"],["3.1517","902.4"],["3.1524","936.5"],["3.1526","1300.4"],["3.1528","2462.5"],["3.1530","2856.7"],["3.1532","1708.7"],["3.1533","480.5"],["3.1534","3037.1"],["3.1536","6520.7"],["3.1549","663.9"],["3.1550","1759.6"]],"timestamp":1756900960350,"update_id":50199164,"fetch_time":1756900960394}
{"symbol":"TONUSDT","bids":[["3.1497","0"],["3.1493","60.6"],["3.1447","822.4"]],"asks":[["3.1499","28.8"],["3.1500","65.5"],["3.1501","349.0"],["3.1504","404.2"],["3.1505","523.1"],["3.1506","1019.9"],["3.1507","1079.1"],["3.1516","1775.1"],["3.1535","753.7"],["3.1536","6518.7"],["3.1549","0"],["3.1550","0"]],"timestamp":1756900960369,"update_id":50199165,"fetch_time":1756900960413}
{"symbol":"TONUSDT","bids":[],"asks":[["3.1500","55.1"],["3.1502","746.7"],["3.1504","1028.3"],["3.1505","766.4"],["3.1506","1096.8"],["3.1524","754.3"],["3.1534","3039.1"],["3.1535","751.7"]],"timestamp":1756900960389,"update_id":50199166,"fetch_time":1756900960434}
{"symbol":"TONUSDT","bids":[],"asks":[["3.1504","904.7"]],"timestamp":1756900960409,"update_id":50199167,"fetch_time":1756900960454}
{"symbol":"TONUSDT","bids":[["3.1474","1334.6"],["3.1472","2646.3"]],"asks":[],"timestamp":1756900960450,"update_id":50199169,"fetch_time":1756900960494}
{"symbol":"TONUSDT","bids":[],"asks":[["3.1506","723.3"]],"timestamp":1756900960469,"update_id":50199170,"fetch_time":1756900960514}
{"symbol":"TONUSDT","bids":[["3.1489","744.5"],["3.1484","748.9"]],"asks":[],"timestamp":1756900960509,"update_id":50199171,"fetch_time":1756900960554}
{"symbol":"TONUSDT","bids":[],"asks":[["3.1516","1979.3"],["3.1527","1668.6"],["3.1528","1966.3"],["3.1529","2459.5"],["3.1530","2376.6"],["3.1532","2435.5"]],"timestamp":1756900960590,"update_id":50199172,"fetch_time":1756900960633}
{"symbol":"TONUSDT","bids":[["3.1479","1380.9"],["3.1468","2715.7"]],"asks":[],"timestamp":1756900960829,"update_id":50199174,"fetch_time":1756900960873}
{"symbol":"TONUSDT","bids":[],"asks":[["3.1503","323.0"]],"timestamp":1756900960869,"update_id":50199176,"fetch_time":1756900960918}
{"symbol":"TONUSDT","bids":[],"asks":[["3.1504","1296.6"],["3.1505","1214.1"]],"timestamp":1756900961089,"update_id":50199179,"fetch_time":1756900961138}
{"symbol":"TONUSDT","bids":[],"asks":[["3.1523","2957.9"]],"timestamp":1756900961170,"update_id":50199180,"fetch_time":1756900961218}
{"symbol":"TONUSDT","bids":[],"asks":[["3.1501","220.9"]],"timestamp":1756900961229,"update_id":50199181,"fetch_time":1756900961274}
{"symbol":"TONUSDT","bids":[["3.1492","147.9"],["3.1487","860.7"],["3.1486","1743.8"]],"asks":[],"timestamp":1756900961270,"update_id":50199183,"fetch_time":1756900961314}
{"symbol":"TONUSDT","bids":[["3.1497","140.0"],["3.1447","0"]],"asks":[["3.1501","2.2"],["3.1503","121.1"],["3.1521","3261.0"]],"timestamp":1756900961309,"update_id":50199184,"fetch_time":1756900961358}
{"symbol":"TONUSDT","bids":[],"asks":[["3.1507","1003.8"]],"timestamp":1756900961349,"update_id":50199186,"fetch_time":1756900961394}
{"symbol":"TONUSDT","bids":[["3.1492","334.6"],["3.1487","665.1"]],"asks":[],"timestamp":1756900961370,"update_id":50199187,"fetch_time":1756900961418}
{"symbol":"TONUSDT","bids":[],"asks":[["3.1545","2617.9"],["3.1546","3678.3"]],"timestamp":1756900961389,"update_id":50199188,"fetch_time":1756900961442}
{"symbol":"TONUSDT","bids":[],"asks":[["3.1507","960.5"]],"timestamp":1756900961429,"update_id":50199190,"fetch_time":1756900961474}
{"symbol":"TONUSDT","bids":[["3.1484","1768.9"]],"asks":[["3.1499","0"],["3.1516","1378.0"],["3.1517","1287.1"],["3.1528","2421.0"],["3.1529","1748.9"],["3.1531","1365.0"],["3.1532","1708.7"],["3.1549","663.9"]],"timestamp":1756900961449,"update_id":50199191,"fetch_time":1756900961494}
{"symbol":"TONUSDT","bids":[["3.1493","137.4"],["3.1491","503.3"],["3.1485","2860.0"],["3.1484","968.9"]],"asks":[["3.1500","0"],["3.1504","7.4"],["3.1505","231.5"],["3.1506","789.9"],["3.1524","936.5"],["3.1528","2704.5"],["3.1530","2232.8"],["3.1534","3037.1"],["3.1536","6520.7"],["3.1550","1347.0"]],"timestamp":1756900961469,"update_id":50199192,"fetch_time":1756900961534}
{"symbol":"TONUSDT","bids":[],"asks":[["3.1506","1600.7"]],"timestamp":1756900961509,"update_id":50199194,"fetch_time":1756900961554}
{"symbol":"TONUSDT","bids":[["3.1498","20.0"],["3.1496","80.7"],["3.1494","212.3"],["3.1448","0"]],"asks":[["3.1508","919.9"]],"timestamp":1756900961529,"update_id":50199195,"fetch_time":1756900961574}
{"symbol":"TONUSDT","bids":[["3.1493","324.1"],["3.1492","758.1"]],"asks":[],"timestamp":1756900961569,"update_id":50199197,"fetch_time":1756900961618}
{"symbol":"TONUSDT","bids":[["3.1494","377.7"],["3.1492","1230.7"]],"asks":[],"timestamp":1756900961589,"update_id":50199198,"fetch_time":1756900961670}
{"symbol":"TONUSDT","bids":[],"asks":[["3.1511","404.9"]],"timestamp":1756900961609,"update_id":50199199,"fetch_time":1756900961670}
{"symbol":"TONUSDT","bids":[["3.1492","1044.0"]],"asks":[],"timestamp":1756900961669,"update_id":50199201,"fetch_time":1756900961714}
{"symbol":"TONUSDT","bids":[],"asks":[["3.1507","1003.7"]],"timestamp":1756900961789,"update_id":50199204,"fetch_time":1756900961834}
{"symbol":"TONUSDT","bids":[["3.1496","69.2"]],"asks":[],"timestamp":1756900961810,"update_id":50199205,"fetch_time":1756900961854}
{"symbol":"TONUSDT","bids":[],"asks":[["3.1508","1006.4"]],"timestamp":1756900961830,"update_id":50199206,"fetch_time":1756900961874}
{"symbol":"TONUSDT","bids":[["3.1479","1349.4"],["3.1464","3824.6"]],"asks":[],"timestamp":1756900961870,"update_id":50199207,"fetch_time":1756900961915}
{"symbol":"TONUSDT","bids":[],"asks":[["3.1506","1896.3"]],"timestamp":1756900961950,"update_id":50199211,"fetch_time":1756900962036}
{"symbol":"TONUSDT","bids":[["3.1495","120.4"]],"asks":[],"timestamp":1756900962010,"update_id":50199212,"fetch_time":1756900962056}
{"symbol":"TONUSDT","bids":[],"asks":[["3.1533","559.5"],["3.1536","7865.4"]],"timestamp":1756900962030,"update_id":50199213,"fetch_time":1756900962076}
{"symbol":"TONUSDT","bids":[],"asks":[["3.1528","1966.3"],["3.1530","3014.8"]],"timestamp":1756900962090,"update_id":50199215,"fetch_time":1756900962136}
{"symbol":"TONUSDT","bids":[],"asks":[["3.1505","433.5"]],"timestamp":1756900962129,"update_id":50199216,"fetch_time":1756900962175}
{"symbol":"TONUSDT","bids":[],"asks":[["3.1504","166.1"]],"timestamp":1756900962190,"update_id":50199218,"fetch_time":1756900962235}
{"symbol":"TONUSDT","bids":[],"asks":[["3.1546","2740.3"]],"timestamp":1756900962249,"update_id":50199220,"fetch_time":1756900962296}
{"symbol":"TONUSDT","bids":[["3.1492","973.9"]],"asks":[],"timestamp":1756900962329,"update_id":50199221,"fetch_time":1756900962376}
{"symbol":"TONUSDT","bids":[],"asks":[["3.1505","433.5"],["3.1506","1896.3"],["3.1507","1003.8"],["3.1508","1065.2"]],"timestamp":1756900962369,"update_id":50199223,"fetch_time":1756900962415}
{"symbol":"TONUSDT","bids":[],"asks":[["3.1507","1047.0"]],"timestamp":1756900962410,"update_id":50199225,"fetch_time":1756900962455}
{"symbol":"TONUSDT","bids":[],"asks":[["3.1525","2149.8"]],"timestamp":1756900962510,"update_id":50199226,"fetch_time":1756900962555}
{"symbol":"TONUSDT","bids":[],"asks":[["3.1521","4102.7"]],"timestamp":1756900962630,"update_id":50199229,"fetch_time":1756900962675}
{"symbol":"TONUSDT","bids":[["3.1493","290.5"]],"asks":[],"timestamp":1756900962650,"update_id":50199230,"fetch_time":1756900962695}
{"symbol":"TONUSDT","bids":[],"asks":[["3.1502","5.0"],["3.1503","138.2"],["3.1507","989.6"],["3.1509","1824.7"]],"timestamp":1756900962809,"update_id":50199231,"fetch_time":1756900962855}
{"symbol":"TONUSDT","bids":[["3.1497","0"],["3.1493","247.3"],["3.1492","973.9"],["3.1491","413.0"],["3.1490","1672.6"],["3.1489","744.5"],["3.1488","1677.1"],["3.1487","911.9"],["3.1448","11377.4"]],"asks":[["3.1503","168.4"],["3.1504","249.4"],["3.1505","729.0"],["3.1506","1687.2"]],"timestamp":1756900963209,"update_id":50199233,"fetch_time":1756900963260}
{"symbol":"TONUSDT","bids":[["3.1480","3034.3"],["3.1478","617.5"],["3.1477","530.9"],["3.1476","782.2"]],"asks":[],"timestamp":1756900963250,"update_id":50199235,"fetch_time":1756900963300}
{"symbol":"TONUSDT","bids":[["3.1488","1720.3"]],"asks":[],"timestamp":1756900963350,"update_id":50199237,"fetch_time":1756900963395}
{"symbol":"TONUSDT","bids":[],"asks":[["3.1504","252.6"]],"timestamp":1756900963410,"update_id":50199238,"fetch_time":1756900963460}
{"symbol":"TONUSDT","bids":[["3.1489","787.7"]],"asks":[],"timestamp":1756900963430,"update_id":50199239,"fetch_time":1756900963475}
{"symbol":"TONUSDT","bids":[["3.1487","621.9"]],"asks":[],"timestamp":1756900963509,"update_id":50199240,"fetch_time":1756900963555}
{"symbol":"TONUSDT","bids":[["3.1486","2111.5"],["3.1483","1142.3"],["3.1480","3578.4"],["3.1477","1163.2"],["3.1474","2055.1"],["3.1471","1513.8"],["3.1452","3948.4"],["3.1449","2843.4"]],"asks":[],"timestamp":1756900963610,"update_id":50199243,"fetch_time":1756900963655}
{"symbol":"TONUSDT","bids":[["3.1495","120.4"],["3.1487","665.1"]],"asks":[],"timestamp":1756900963650,"update_id":50199244,"fetch_time":1756900963696}
{"symbol":"TONUSDT","bids":[],"asks":[["3.1500","28.2"],["3.1550","0"]],"timestamp":1756900963730,"update_id":50199245,"fetch_time":1756900963775}
{"symbol":"TONUSDT","bids":[["3.1498","140.0"]],"asks":[],"timestamp":1756900963909,"update_id":50199248,"fetch_time":1756900963960}
{"symbol":"TONUSDT","bids":[],"asks":[["3.1535","753.7"]],"timestamp":1756900963949,"update_id":50199250,"fetch_time":1756900963999}
{"symbol":"TONUSDT","bids":[],"asks":[["3.1518","2029.4"],["3.1524","1241.2"]],"timestamp":1756900964050,"update_id":50199251,"fetch_time":1756900964095}
{"symbol":"TONUSDT","bids":[["3.1494","312.0"]],"asks":[],"timestamp":1756900964289,"update_id":50199253,"fetch_time":1756900964340}
{"symbol":"TONUSDT","bids":[],"asks":[["3.1505","820.5"],["3.1546","4008.0"],["3.1547","344.3"]],"timestamp":1756900964349,"update_id":50199255,"fetch_time":1756900964399}
{"symbol":"TONUSDT","bids":[["3.1489","787.7"],["3.1488","2010.3"]],"asks":[],"timestamp":1756900964370,"update_id":50199256,"fetch_time":1756900964416}
{"symbol":"TONUSDT","bids":[],"asks":[["3.1506","1500.4"]],"timestamp":1756900964389,"update_id":50199257,"fetch_time":1756900964440}
{"symbol":"TONUSDT","bids":[],"asks":[["3.1506","1437.0"]],"timestamp":1756900964450,"update_id":50199258,"fetch_time":1756900964500}
{"symbol":"TONUSDT","bids":[["3.1491","456.2"],["3.1490","1715.8"]],"asks":[],"timestamp":1756900964470,"update_id":50199259,"fetch_time":1756900964516}
{"symbol":"TONUSDT","bids":[],"asks":[["3.1502","5.0"]],"timestamp":1756900964509,"update_id":50199261,"fetch_time":1756900964560}
{"symbol":"TONUSDT","bids":[],"asks":[["3.1511","621.9"]],"timestamp":1756900964570,"update_id":50199262,"fetch_time":1756900964616}
{"symbol":"TONUSDT","bids":[],"asks":[["3.1520","3755.9"]],"timestamp":1756900964650,"update_id":50199263,"fetch_time":1756900964695}
{"symbol":"TONUSDT","bids":[],"asks":[["3.1506","1716.4"]],"timestamp":1756900964909,"update_id":50199266,"fetch_time":1756900964955}
{"symbol":"TONUSDT","bids":[["3.1495","146.0"]],"asks":[],"timestamp":1756900964930,"update_id":50199267,"fetch_time":1756900964979}
{"symbol":"TONUSDT","bids":[["3.1498","0"],["3.1496","0"],["3.1495","0"],["3.1494","124.7"],["3.1493","314.9"],["3.1492","60.7"],["3.1491","369.7"],["3.1490","848.6"],["3.1489","744.5"],["3.1488","1863.8"],["3.1487","676.3"],["3.1486","2036.4"],["3.1485","2524.3"],["3.1484","1055.4"],["3.1483","729.6"],["3.1482","2573.6"],["3.1480","3034.3"],["3.1479","637.8"],["3.1477","530.9"],["3.1474","1334.6"],["3.1471","705.1"],["3.1451","5582.8"],["3.1448","12156.3"],["3.1447","822.4"],["3.1446","2403.6"],["3.1445","1430.1"]],"asks":[["3.1499","116.2"],["3.1500","168.2"],["3.1502","384.3"],["3.1504","252.6"],["3.1505","1135.2"],["3.1506","1437.0"],["3.1507","946.4"],["3.1508","1065.2"],["3.1509","1824.7"],["3.1522","1776.7"],["3.1524","1059.0"],["3.1534","3039.1"],["3.1535","751.7"],["3.1549","0"]],"timestamp":1756900964970,"update_id":50199268,"fetch_time":1756900965015}
{"symbol":"TONUSDT","bids":[["3.1495","140.0"],["3.1493","0"],["3.1488","1907.0"],["3.1487","665.1"],["3.1484","1088.7"],["3.1473","2175.7"],["3.1472","1428.3"],["3.1455","1526.8"]],"asks":[["3.1500","28.2"],["3.1503","311.6"],["3.1505","2004.0"],["3.1506","1644.5"],["3.1509","1764.2"],["3.1511","657.0"],["3.1512","3955.2"],["3.1522","1587.7"],["3.1540","1481.1"],["3.1545","2971.8"],["3.1546","2740.3"]],"timestamp":1756900965050,"update_id":50199272,"fetch_time":1756900965103}
{"symbol":"TONUSDT","bids":[["3.1496","79.7"],["3.1490","891.8"],["3.1489","974.4"],["3.1486","1787.0"],["3.1482","2530.4"],["3.1445","0"]],"asks":[["3.1502","163.7"],["3.1503","275.0"],["3.1504","1207.0"],["3.1505","1400.8"],["3.1506","1040.5"],["3.1507","946.3"],["3.1508","1021.9"],["3.1509","1720.9"],["3.1520","3307.4"],["3.1545","1704.1"],["3.1546","4008.0"]],"timestamp":1756900965069,"update_id":50199273,"fetch_time":1756900965115}
{"symbol":"TONUSDT","bids":[["3.1493","5.6"],["3.1492","107.1"],["3.1491","283.1"],["3.1488","1720.3"],["3.1446","0"]],"asks":[["3.1506","853.8"]],"timestamp":1756900965089,"update_id":50199274,"fetch_time":1756900965139}
{"symbol":"TONUSDT","bids":[["3.1490","1787.9"]],"asks":[["3.1498","28.8"],["3.1499","0"],["3.1501","5.4"],["3.1503","121.1"],["3.1504","1005.1"],["3.1533","561.5"],["3.1534","3037.1"],["3.1546","2740.3"],["3.1547","1612.0"]],"timestamp":1756900965129,"update_id":50199276,"fetch_time":1756900965175}
{"symbol":"TONUSDT","bids":[],"asks":[["3.1503","1118.8"]],"timestamp":1756900965169,"update_id":50199278,"fetch_time":1756900965215}
{"symbol":"TONUSDT","bids":[],"asks":[["3.1517","1839.2"],["3.1518","1437.1"]],"timestamp":1756900965229,"update_id":50199281,"fetch_time":1756900965275}
{"symbol":"TONUSDT","bids":[],"asks":[["3.1504","879.5"]],"timestamp":1756900965249,"update_id":50199282,"fetch_time":1756900965295}
{"symbol":"TONUSDT","bids":[],"asks":[["3.1504","318.7"]],"timestamp":1756900965269,"update_id":50199283,"fetch_time":1756900965320}
{"symbol":"TONUSDT","bids":[["3.1476","1301.0"]],"asks":[],"timestamp":1756900965330,"update_id":50199284,"fetch_time":1756900965375}
{"symbol":"TONUSDT","bids":[],"asks":[["3.1506","853.9"]],"timestamp":1756900965350,"update_id":50199285,"fetch_time":1756900965395}
{"symbol":"TONUSDT","bids":[["3.1494","124.7"]],"asks":[],"timestamp":1756900965369,"update_id":50199286,"fetch_time":1756900965419}
{"symbol":"TONUSDT","bids":[],"asks":[["3.1505","1170.9"]],"timestamp":1756900965390,"update_id":50199287,"fetch_time":1756900965435}
{"symbol":"TONUSDT","bids":[],"asks":[["3.1546","4008.0"],["3.1547","344.3"]],"timestamp":1756900965490,"update_id":50199288,"fetch_time":1756900965539}
{"symbol":"TONUSDT","bids":[],"asks":[["3.1546","2740.3"],["3.1547","1612.0"]],"timestamp":1756900965509,"update_id":50199289,"fetch_time":1756900965555}
{"symbol":"TONUSDT","bids":[["3.1495","147.7"],["3.1494","136.2"]],"asks":[],"timestamp":1756900965610,"update_id":50199290,"fetch_time":1756900965655}
{"symbol":"TONUSDT","bids":[],"asks":[["3.1502","5.0"]],"timestamp":1756900965630,"update_id":50199291,"fetch_time":1756900965675}
{"symbol":"TONUSDT","bids":[],"asks":[["3.1506","646.4"]],"timestamp":1756900965650,"update_id":50199292,"fetch_time":1756900965695}
{"symbol":"TONUSDT","bids":[["3.1496","80.7"]],"asks":[],"timestamp":1756900965690,"update_id":50199293,"fetch_time":1756900965735}
{"symbol":"TONUSDT","bids":[],"asks":[["3.1546","4008.0"],["3.1547","344.3"]],"timestamp":1756900965750,"update_id":50199294,"fetch_time":1756900965796}
{"symbol":"TONUSDT","bids":[],"asks":[["3.1504","362.0"]],"timestamp":1756900965770,"update_id":50199295,"fetch_time":1756900965816}
{"symbol":"TONUSDT","bids":[],"asks":[["3.1546","2740.3"],["3.1547","1612.0"]],"timestamp":1756900965810,"update_id":50199296,"fetch_time":1756900965860}
{"symbol":"TONUSDT","bids":[],"asks":[["3.1546","2740.3"],["3.1547","1612.0"]],"timestamp":1756900966050,"update_id":50199299,"fetch_time":1756900966095}
{"symbol":"TONUSDT","bids":[],"asks":[["3.1546","4008.0"],["3.1547","344.3"]],"timestamp":1756900966090,"update_id":50199300,"fetch_time":1756900966135}
{"symbol":"TONUSDT","bids":[],"asks":[["3.1546","2740.3"],["3.1547","1612.0"]],"timestamp":1756900966229,"update_id":50199301,"fetch_time":1756900966279}
{"symbol":"TONUSDT","bids":[["3.1494","124.7"]],"asks":[],"timestamp":1756900966249,"update_id":50199302,"fetch_time":1756900966295}
{"symbol":"TONUSDT","bids":[],"asks":[["3.1546","4008.0"],["3.1547","344.3"]],"timestamp":1756900966270,"update_id":50199303,"fetch_time":1756900966315}
{"symbol":"TONUSDT","bids":[],"asks":[["3.1546","2740.3"],["3.1547","1612.0"]],"timestamp":1756900966290,"update_id":50199304,"fetch_time":1756900966335}
{"symbol":"TONUSDT","bids":[],"asks":[["3.1546","4008.0"],["3.1547","344.3"]],"timestamp":1756900966330,"update_id":50199305,"fetch_time":1756900966375}
{"symbol":"TONUSDT","bids":[],"asks":[["3.1505","1462.2"],["3.1506","646.4"]],"timestamp":1756900966370,"update_id":50199307,"fetch_time":1756900966415}
{"symbol":"TONUSDT","bids":[],"asks":[["3.1534","3638.9"]],"timestamp":1756900966489,"update_id":50199311,"fetch_time":1756900966535}
{"symbol":"TONUSDT","bids":[["3.1492","546.7"]],"asks":[],"timestamp":1756900966569,"update_id":50199312,"fetch_time":1756900966615}
{"symbol":"TONUSDT","bids":[["3.1494","143.9"],["3.1493","36.1"]],"asks":[],"timestamp":1756900966590,"update_id":50199313,"fetch_time":1756900966635}
{"symbol":"TONUSDT","bids":[["3.1491","326.4"]],"asks":[],"timestamp":1756900966670,"update_id":50199314,"fetch_time":1756900966715}
{"symbol":"TONUSDT","bids":[["3.1494","124.7"],["3.1491","283.1"],["3.1483","772.9"]],"asks":[],"timestamp":1756900966729,"update_id":50199315,"fetch_time":1756900966775}
{"symbol":"TONUSDT","bids":[["3.1488","2162.2"]],"asks":[],"timestamp":1756900966810,"update_id":50199316,"fetch_time":1756900966855}
{"symbol":"TONUSDT","bids":[["3.1478","1162.1"]],"asks":[],"timestamp":1756900967110,"update_id":50199317,"fetch_time":1756900967155}
{"symbol":"TONUSDT","bids":[],"asks":[["3.1502","5.0"],["3.1503","1118.8"],["3.1508","919.9"],["3.1522","1467.4"]],"timestamp":1756900967229,"update_id":50199319,"fetch_time":1756900967276}
{"symbol":"TONUSDT","bids":[["3.1492","590.0"],["3.1491","326.4"]],"asks":[],"timestamp":1756900967249,"update_id":50199320,"fetch_time":1756900967296}
{"symbol":"TONUSDT","bids":[],"asks":[["3.1498","0"],["3.1503","121.1"],["3.1505","1127.6"],["3.1533","559.5"],["3.1535","753.7"],["3.1546","2740.3"],["3.1547","1612.0"],["3.1549","663.9"]],"timestamp":1756900967270,"update_id":50199321,"fetch_time":1756900967315}
{"symbol":"TONUSDT","bids":[],"asks":[["3.1506","894.4"],["3.1546","4008.0"],["3.1547","344.3"]],"timestamp":1756900967289,"update_id":50199322,"fetch_time":1756900967336}
{"symbol":"TONUSDT","bids":[],"asks":[["3.1504","166.1"],["3.1505","2125.0"],["3.1546","2740.3"],["3.1547","1612.0"]],"timestamp":1756900967329,"update_id":50199324,"fetch_time":1756900967375}
{"symbol":"TONUSDT","bids":[],"asks":[["3.1546","4008.0"],["3.1547","344.3"]],"timestamp":1756900967350,"update_id":50199325,"fetch_time":1756900967395}
{"symbol":"TONUSDT","bids":[],"asks":[["3.1546","4008.0"],["3.1547","344.3"]],"timestamp":1756900967450,"update_id":50199327,"fetch_time":1756900967496}
{"symbol":"TONUSDT","bids":[],"asks":[["3.1507","946.4"]],"timestamp":1756900967529,"update_id":50199328,"fetch_time":1756900967575}
{"symbol":"TONUSDT","bids":[],"asks":[["3.1503","3.2"]],"timestamp":1756900967589,"update_id":50199329,"fetch_time":1756900967635}
{"symbol":"TONUSDT","bids":[["3.1499","20.0"],["3.1498","20.0"],["3.1497","61.9"],["3.1496","92.8"],["3.1495","168.5"],["3.1494","155.8"],["3.1493","175.6"],["3.1491","605.9"],["3.1490","2176.8"],["3.1488","1946.7"],["3.1485","2437.8"],["3.1484","968.9"],["3.1479","1157.2"],["3.1476","1845.1"],["3.1449","0"],["3.1448","0"],["3.1447","0"]],"asks":[["3.1505","3.2"],["3.1506","603.1"],["3.1507","429.1"],["3.1508","1571.5"],["3.1512","3891.7"],["3.1546","2740.3"],["3.1547","1612.0"]],"timestamp":1756900967609,"update_id":50199330,"fetch_time":1756900967655}
{"symbol":"TONUSDT","bids":[["3.1498","0"],["3.1497","19.3"],["3.1492","773.0"],["3.1490","1933.2"],["3.1488","2153.5"],["3.1480","3269.3"],["3.1479","1229.7"],["3.1449","2843.4"]],"asks":[["3.1504","7.4"],["3.1507","492.5"],["3.1508","1335.0"],["3.1511","621.9"],["3.1513","2276.1"],["3.1515","1386.8"],["3.1517","902.4"],["3.1519","2966.6"],["3.1522","1544.9"],["3.1523","3894.8"],["3.1530","2584.0"],["3.1536","7748.5"],["3.1538","1226.4"],["3.1541","1318.4"]],"timestamp":1756900967629,"update_id":50199331,"fetch_time":1756900967675}
{"symbol":"TONUSDT","bids":[],"asks":[["3.1506","853.3"]],"timestamp":1756900967790,"update_id":50199337,"fetch_time":1756900967835}
{"symbol":"TONUSDT","bids":[],"asks":[["3.1507","1239.7"]],"timestamp":1756900967829,"update_id":50199338,"fetch_time":1756900967876}
{"symbol":"TONUSDT","bids":[],"asks":[["3.1537","5217.2"],["3.1541","1685.5"]],"timestamp":1756900967929,"update_id":50199341,"fetch_time":1756900967975}
{"symbol":"TONUSDT","bids":[["3.1494","1241.7"]],"asks":[],"timestamp":1756900967950,"update_id":50199342,"fetch_time":1756900967995}
{"symbol":"TONUSDT","bids":[["3.1496","473.2"]],"asks":[],"timestamp":1756900967969,"update_id":50199343,"fetch_time":1756900968020}
{"symbol":"TONUSDT","bids":[["3.1497","161.3"]],"asks":[],"timestamp":1756900967990,"update_id":50199344,"fetch_time":1756900968036}
{"symbol":"TONUSDT","bids":[],"asks":[["3.1505","161.9"],["3.1506","1600.5"]],"timestamp":1756900968029,"update_id":50199346,"fetch_time":1756900968075}
{"symbol":"TONUSDT","bids":[],"asks":[["3.1507","709.5"]],"timestamp":1756900968110,"update_id":50199347,"fetch_time":1756900968155}
{"symbol":"TONUSDT","bids":[],"asks":[["3.1507","429.1"]],"timestamp":1756900968129,"update_id":50199348,"fetch_time":1756900968179}
{"symbol":"TONUSDT","bids":[],"asks":[["3.1506","1142.4"]],"timestamp":1756900968149,"update_id":50199349,"fetch_time":1756900968200}
{"symbol":"TONUSDT","bids":[],"asks":[["3.1507","901.7"]],"timestamp":1756900968210,"update_id":50199351,"fetch_time":1756900968255}
{"symbol":"TONUSDT","bids":[["3.1499","34.0"]],"asks":[],"timestamp":1756900968289,"update_id":50199352,"fetch_time":1756900968336}
{"symbol":"TONUSDT","bids":[["3.1476","2065.8"]],"asks":[],"timestamp":1756900968550,"update_id":50199353,"fetch_time":1756900968596}
{"symbol":"TONUSDT","bids":[["3.1497","0"],["3.1496","457.4"],["3.1495","154.8"],["3.1485","2481.1"],["3.1448","11700.4"]],"asks":[["3.1507","945.0"],["3.1508","1234.7"]],"timestamp":1756900968770,"update_id":50199354,"fetch_time":1756900968815}
{"symbol":"TONUSDT","bids":[],"asks":[["3.1520","2465.8"]],"timestamp":1756900968810,"update_id":50199356,"fetch_time":1756900968855}
{"symbol":"TONUSDT","bids":[],"asks":[["3.1506","1228.9"],["3.1507","988.2"],["3.1508","1336.7"]],"timestamp":1756900968829,"update_id":50199357,"fetch_time":1756900968875}
{"symbol":"TONUSDT","bids":[],"asks":[["3.1505","592.2"]],"timestamp":1756900968889,"update_id":50199360,"fetch_time":1756900968939}
{"symbol":"TONUSDT","bids":[],"asks":[["3.1506","885.1"]],"timestamp":1756900968990,"update_id":50199363,"fetch_time":1756900969035}
{"symbol":"TONUSDT","bids":[],"asks":[["3.1505","1087.1"],["3.1506","231.5"]],"timestamp":1756900969029,"update_id":50199365,"fetch_time":1756900969075}
{"symbol":"TONUSDT","bids":[["3.1478","1011.4"]],"asks":[],"timestamp":1756900969129,"update_id":50199366,"fetch_time":1756900969176}
{"symbol":"TONUSDT","bids":[["3.1495","143.2"]],"asks":[],"timestamp":1756900969150,"update_id":50199367,"fetch_time":1756900969196}
{"symbol":"TONUSDT","bids":[["3.1491","139.7"]],"asks":[],"timestamp":1756900969169,"update_id":50199368,"fetch_time":1756900969220}
{"symbol":"TONUSDT","bids":[["3.1492","584.4"]],"asks":[],"timestamp":1756900969190,"update_id":50199369,"fetch_time":1756900969236}
{"symbol":"TONUSDT","bids":[],"asks":[["3.1547","1611.9"],["3.1548","3030.8"]],"timestamp":1756900969290,"update_id":50199370,"fetch_time":1756900969340}
{"symbol":"TONUSDT","bids":[],"asks":[["3.1547","1611.9"],["3.1548","3030.8"]],"timestamp":1756900969410,"update_id":50199373,"fetch_time":1756900969455}
{"symbol":"TONUSDT","bids":[],"asks":[["3.1503","46.5"],["3.1504","252.6"],["3.1547","344.3"],["3.1548","4298.4"]],"timestamp":1756900969429,"update_id":50199374,"fetch_time":1756900969480}
{"symbol":"TONUSDT","bids":[],"asks":[["3.1504","50.7"]],"timestamp":1756900969510,"update_id":50199376,"fetch_time":1756900969555}
{"symbol":"TONUSDT","bids":[["3.1478","948.0"]],"asks":[],"timestamp":1756900969550,"update_id":50199377,"fetch_time":1756900969595}
{"symbol":"TONUSDT","bids":[["3.1499","22.3"]],"asks":[],"timestamp":1756900969650,"update_id":50199379,"fetch_time":1756900969700}
{"symbol":"TONUSDT","bids":[["3.1482","3105.3"]],"asks":[],"timestamp":1756900969669,"update_id":50199380,"fetch_time":1756900969715}
{"symbol":"TONUSDT","bids":[["3.1493","317.1"],["3.1492","584.4"],["3.1461","1469.3"],["3.1453","891.7"]],"asks":[],"timestamp":1756900969690,"update_id":50199381,"fetch_time":1756900969735}
{"symbol":"TONUSDT","bids":[["3.1494","1390.4"]],"asks":[],"timestamp":1756900969710,"update_id":50199382,"fetch_time":1756900969768}
{"symbol":"TONUSDT","bids":[],"asks":[["3.1547","344.3"],["3.1548","4298.4"]],"timestamp":1756900969850,"update_id":50199383,"fetch_time":1756900969895}
{"symbol":"TONUSDT","bids":[],"asks":[["3.1504","7.4"]],"timestamp":1756900969870,"update_id":50199384,"fetch_time":1756900969919}
{"symbol":"TONUSDT","bids":[],"asks":[["3.1513","3076.1"]],"timestamp":1756900969910,"update_id":50199385,"fetch_time":1756900969955}
{"symbol":"TONUSDT","bids":[["3.1493","94.7"]],"asks":[],"timestamp":1756900969950,"update_id":50199386,"fetch_time":1756900969995}
{"symbol":"TONUSDT","bids":[["3.1494","1472.5"]],"asks":[],"timestamp":1756900969970,"update_id":50199387,"fetch_time":1756900970015}
{"symbol":"TONUSDT","bids":[],"asks":[["3.1503","46.4"],["3.1504","93.9"]],"timestamp":1756900970330,"update_id":50199389,"fetch_time":1756900970375}
{"symbol":"TONUSDT","bids":[["3.1499","20.0"]],"asks":[],"timestamp":1756900970369,"update_id":50199390,"fetch_time":1756900970415}
{"symbol":"TONUSDT","bids":[["3.1492","584.4"]],"asks":[],"timestamp":1756900970409,"update_id":50199392,"fetch_time":1756900970460}
{"symbol":"TONUSDT","bids":[["3.1494","1476.2"],["3.1493","92.1"]],"asks":[],"timestamp":1756900970430,"update_id":50199393,"fetch_time":1756900970479}
{"symbol":"TONUSDT","bids":[],"asks":[["3.1505","1043.9"],["3.1506","188.3"]],"timestamp":1756900970449,"update_id":50199394,"fetch_time":1756900970496}
{"symbol":"TONUSDT","bids":[["3.1495","172.0"]],"asks":[],"timestamp":1756900970469,"update_id":50199395,"fetch_time":1756900970519}
{"symbol":"TONUSDT","bids":[["3.1499","16.6"],["3.1495","143.2"],["3.1494","1433.0"],["3.1493","48.9"]],"asks":[],"timestamp":1756900970550,"update_id":50199396,"fetch_time":1756900970595}
{"symbol":"TONUSDT","bids":[["3.1494","1476.2"],["3.1493","92.1"]],"asks":[],"timestamp":1756900970649,"update_id":50199398,"fetch_time":1756900970696}
{"symbol":"TONUSDT","bids":[],"asks":[["3.1547","344.3"],["3.1548","4298.4"]],"timestamp":1756900970770,"update_id":50199399,"fetch_time":1756900970815}
{"symbol":"TONUSDT","bids":[],"asks":[["3.1547","1611.9"],["3.1548","3030.8"]],"timestamp":1756900970789,"update_id":50199400,"fetch_time":1756900970839}
{"symbol":"TONUSDT","bids":[],"asks":[["3.1547","344.3"],["3.1548","4298.4"]],"timestamp":1756900970870,"update_id":50199401,"fetch_time":1756900970915}
{"symbol":"TONUSDT","bids":[["3.1463","8812.1"],["3.1460","3234.9"]],"asks":[],"timestamp":1756900971009,"update_id":50199402,"fetch_time":1756900971060}
{"symbol":"TONUSDT","bids":[["3.1462","643.7"]],"asks":[],"timestamp":1756900971029,"update_id":50199403,"fetch_time":1756900971075}
{"symbol":"TONUSDT","bids":[["3.1495","379.0"],["3.1494","1253.8"]],"asks":[],"timestamp":1756900971050,"update_id":50199404,"fetch_time":1756900971095}
{"symbol":"TONUSDT","bids":[["3.1472","1327.4"],["3.1468","2861.5"],["3.1455","1197.2"]],"asks":[],"timestamp":1756900971109,"update_id":50199405,"fetch_time":1756900971155}
{"symbol":"TONUSDT","bids":[],"asks":[["3.1504","209.4"]],"timestamp":1756900971389,"update_id":50199407,"fetch_time":1756900971439}
{"symbol":"TONUSDT","bids":[["3.1495","407.8"],["3.1494","1250.1"],["3.1493","94.7"]],"asks":[],"timestamp":1756900971430,"update_id":50199408,"fetch_time":1756900971476}
{"symbol":"TONUSDT","bids":[],"asks":[["3.1504","50.7"]],"timestamp":1756900971450,"update_id":50199409,"fetch_time":1756900971499}
{"symbol":"TONUSDT","bids":[["3.1495","379.0"]],"asks":[],"timestamp":1756900971770,"update_id":50199410,"fetch_time":1756900971819}
{"symbol":"TONUSDT","bids":[["3.1491","435.7"],["3.1488","1720.3"]],"asks":[],"timestamp":1756900971830,"update_id":50199411,"fetch_time":1756900971875}
{"symbol":"TONUSDT","bids":[["3.1494","1210.6"],["3.1493","48.9"]],"asks":[],"timestamp":1756900971989,"update_id":50199412,"fetch_time":1756900972035}
{"symbol":"TONUSDT","bids":[["3.1463","7006.3"],["3.1458","6109.3"]],"asks":[],"timestamp":1756900972309,"update_id":50199413,"fetch_time":1756900972360}
{"symbol":"TONUSDT","bids":[["3.1494","1253.9"],["3.1485","2437.8"]],"asks":[],"timestamp":1756900972490,"update_id":50199414,"fetch_time":1756900972535}
{"symbol":"TONUSDT","bids":[["3.1493","92.1"]],"asks":[],"timestamp":1756900972529,"update_id":50199415,"fetch_time":1756900972580}
{"symbol":"TONUSDT","bids":[],"asks":[["3.1504","7.4"],["3.1505","1014.8"],["3.1506","188.2"],["3.1548","4542.6"],["3.1549","663.9"]],"timestamp":1756900972590,"update_id":50199417,"fetch_time":1756900972635}
{"symbol":"TONUSDT","bids":[],"asks":[["3.1548","3030.8"],["3.1549","1931.5"]],"timestamp":1756900972610,"update_id":50199418,"fetch_time":1756900972664}
{"symbol":"TONUSDT","bids":[],"asks":[["3.1505","17.4"],["3.1507","272.3"],["3.1508","1171.8"],["3.1510","1122.7"]],"timestamp":1756900972830,"update_id":50199419,"fetch_time":1756900972875}
{"symbol":"TONUSDT","bids":[],"asks":[["3.1506","375.0"],["3.1508","1358.4"],["3.1510","1403.0"],["3.1521","4102.6"]],"timestamp":1756900972849,"update_id":50199420,"fetch_time":1756900972895}
{"symbol":"TONUSDT","bids":[],"asks":[["3.1510","1166.6"],["3.1511","905.3"]],"timestamp":1756900972870,"update_id":50199421,"fetch_time":1756900972915}
{"symbol":"TONUSDT","bids":[],"asks":[["3.1507","1794.6"]],"timestamp":1756900972890,"update_id":50199422,"fetch_time":1756900972935}
{"symbol":"TONUSDT","bids":[],"asks":[["3.1505","176.1"],["3.1510","1394.9"]],"timestamp":1756900972910,"update_id":50199423,"fetch_time":1756900972955}
{"symbol":"TONUSDT","bids":[],"asks":[["3.1506","761.8"],["3.1508","1295.0"]],"timestamp":1756900972929,"update_id":50199424,"fetch_time":1756900972976}
{"symbol":"TONUSDT","bids":[],"asks":[["3.1504","166.1"]],"timestamp":1756900972970,"update_id":50199426,"fetch_time":1756900973019}
{"symbol":"TONUSDT","bids":[],"asks":[["3.1505","1073.0"],["3.1507","1234.2"],["3.1510","834.5"]],"timestamp":1756900972989,"update_id":50199427,"fetch_time":1756900973035}
{"symbol":"TONUSDT","bids":[],"asks":[["3.1505","1259.8"]],"timestamp":1756900973009,"update_id":50199428,"fetch_time":1756900973055}
{"symbol":"TONUSDT","bids":[],"asks":[["3.1506","1165.3"],["3.1507","1170.8"]],"timestamp":1756900973029,"update_id":50199429,"fetch_time":1756900973079}
{"symbol":"TONUSDT","bids":[],"asks":[["3.1506","791.9"],["3.1507","984.2"]],"timestamp":1756900973049,"update_id":50199430,"fetch_time":1756900973096}
{"symbol":"TONUSDT","bids":[["3.1493","92.1"],["3.1492","584.4"],["3.1491","435.7"]],"asks":[],"timestamp":1756900973229,"update_id":50199433,"fetch_time":1756900973276}
{"symbol":"TONUSDT","bids":[],"asks":[["3.1504","7.4"],["3.1512","3008.7"]],"timestamp":1756900973249,"update_id":50199434,"fetch_time":1756900973296}
{"symbol":"TONUSDT","bids":[],"asks":[["3.1548","4298.4"],["3.1549","663.9"]],"timestamp":1756900973309,"update_id":50199435,"fetch_time":1756900973356}
{"symbol":"TONUSDT","bids":[["3.1495","185.5"]],"asks":[],"timestamp":1756900973350,"update_id":50199437,"fetch_time":1756900973400}
{"symbol":"TONUSDT","bids":[],"asks":[["3.1548","4298.4"],["3.1549","663.9"]],"timestamp":1756900973370,"update_id":50199438,"fetch_time":1756900973416}
{"symbol":"TONUSDT","bids":[],"asks":[["3.1548","3030.8"],["3.1549","1931.5"]],"timestamp":1756900973390,"update_id":50199439,"fetch_time":1756900973435}
{"symbol":"TONUSDT","bids":[],"asks":[["3.1548","4298.4"],["3.1549","663.9"]],"timestamp":1756900973430,"update_id":50199440,"fetch_time":1756900973475}
{"symbol":"TONUSDT","bids":[],"asks":[["3.1548","3030.8"],["3.1549","1931.5"]],"timestamp":1756900973449,"update_id":50199441,"fetch_time":1756900973499}
{"symbol":"TONUSDT","bids":[],"asks":[["3.1548","4298.4"],["3.1549","663.9"]],"timestamp":1756900973470,"update_id":50199442,"fetch_time":1756900973519}
{"symbol":"TONUSDT","bids":[],"asks":[["3.1548","3030.8"],["3.1549","1931.5"]],"timestamp":1756900973490,"update_id":50199443,"fetch_time":1756900973535}
{"symbol":"TONUSDT","bids":[],"asks":[["3.1548","4298.4"],["3.1549","663.9"]],"timestamp":1756900973530,"update_id":50199444,"fetch_time":1756900973575}
{"symbol":"TONUSDT","bids":[],"asks":[["3.1548","3030.8"],["3.1549","1931.5"]],"timestamp":1756900973550,"update_id":50199445,"fetch_time":1756900973595}
{"symbol":"TONUSDT","bids":[],"asks":[["3.1548","4298.4"],["3.1549","663.9"]],"timestamp":1756900973570,"update_id":50199446,"fetch_time":1756900973620}
{"symbol":"TONUSDT","bids":[],"asks":[["3.1548","4298.4"],["3.1549","663.9"]],"timestamp":1756900973610,"update_id":50199448,"fetch_time":1756900973656}
{"symbol":"TONUSDT","bids":[],"asks":[["3.1548","3030.8"],["3.1549","1931.5"]],"timestamp":1756900973709,"update_id":50199449,"fetch_time":1756900973756}
{"symbol":"TONUSDT","bids":[],"asks":[["3.1530","5582.4"],["3.1537","2220.3"]],"timestamp":1756900973750,"update_id":50199450,"fetch_time":1756900973796}
{"symbol":"TONUSDT","bids":[],"asks":[["3.1528","2705.7"],["3.1536","6825.9"]],"timestamp":1756900973770,"update_id":50199451,"fetch_time":1756900973816}
{"symbol":"TONUSDT","bids":[["3.1499","27.1"]],"asks":[],"timestamp":1756900973929,"update_id":50199452,"fetch_time":1756900973975}
{"symbol":"TONUSDT","bids":[],"asks":[["3.1513","2238.5"],["3.1548","3275.0"]],"timestamp":1756900973950,"update_id":50199453,"fetch_time":1756900973995}
{"symbol":"TONUSDT","bids":[["3.1486","2587.0"]],"asks":[],"timestamp":1756900974510,"update_id":50199454,"fetch_time":1756900974555}
{"symbol":"TONUSDT","bids":[["3.1495","185.5"]],"asks":[],"timestamp":1756900974710,"update_id":50199457,"fetch_time":1756900974755}
{"symbol":"TONUSDT","bids":[["3.1495","156.7"]],"asks":[],"timestamp":1756900975050,"update_id":50199458,"fetch_time":1756900975096}
{"symbol":"TONUSDT","bids":[["3.1491","321.4"]],"asks":[],"timestamp":1756900975229,"update_id":50199460,"fetch_time":1756900975276}
{"symbol":"TONUSDT","bids":[],"asks":[["3.1548","4542.6"],["3.1549","663.9"]],"timestamp":1756900975350,"update_id":50199461,"fetch_time":1756900975399}
{"symbol":"TONUSDT","bids":[],"asks":[["3.1548","4298.4"]],"timestamp":1756900975369,"update_id":50199462,"fetch_time":1756900975415}
{"symbol":"TONUSDT","bids":[],"asks":[["3.1548","3030.8"],["3.1549","1931.5"]],"timestamp":1756900975469,"update_id":50199463,"fetch_time":1756900975515}
{"symbol":"TONUSDT","bids":[],"asks":[["3.1548","3275.0"]],"timestamp":1756900975490,"update_id":50199464,"fetch_time":1756900975535}
{"symbol":"TONUSDT","bids":[],"asks":[["3.1548","4542.6"],["3.1549","663.9"]],"timestamp":1756900975509,"update_id":50199465,"fetch_time":1756900975555}
{"symbol":"TONUSDT","bids":[],"asks":[["3.1548","4298.4"]],"timestamp":1756900975529,"update_id":50199466,"fetch_time":1756900975579}
{"symbol":"TONUSDT","bids":[],"asks":[["3.1548","3030.8"],["3.1549","1931.5"]],"timestamp":1756900975570,"update_id":50199467,"fetch_time":1756900975619}
{"symbol":"TONUSDT","bids":[],"asks":[["3.1548","4298.4"],["3.1549","663.9"]],"timestamp":1756900975589,"update_id":50199468,"fetch_time":1756900975635}
{"symbol":"TONUSDT","bids":[],"asks":[["3.1548","3030.8"],["3.1549","1931.5"]],"timestamp":1756900975650,"update_id":50199469,"fetch_time":1756900975696}
{"symbol":"TONUSDT","bids":[],"asks":[["3.1548","4298.4"],["3.1549","663.9"]],"timestamp":1756900975749,"update_id":50199470,"fetch_time":1756900975795}
{"symbol":"TONUSDT","bids":[],"asks":[["3.1548","3030.8"],["3.1549","1931.5"]],"timestamp":1756900975769,"update_id":50199471,"fetch_time":1756900975815}
{"symbol":"TONUSDT","bids":[],"asks":[["3.1548","4298.4"],["3.1549","663.9"]],"timestamp":1756900975810,"update_id":50199472,"fetch_time":1756900975856}
{"symbol":"TONUSDT","bids":[],"asks":[["3.1504","7.4"],["3.1505","262.6"],["3.1506","390.2"],["3.1507","1264.6"],["3.1510","890.9"],["3.1511","678.4"],["3.1541","1372.4"]],"timestamp":1756900975949,"update_id":50199474,"fetch_time":1756900976000}
{"symbol":"TONUSDT","bids":[],"asks":[["3.1505","449.2"],["3.1506","920.6"]],"timestamp":1756900975970,"update_id":50199475,"fetch_time":1756900976015}
{"symbol":"TONUSDT","bids":[],"asks":[["3.1504","161.3"],["3.1506","1201.0"],["3.1548","3030.8"],["3.1549","1931.5"]],"timestamp":1756900975989,"update_id":50199476,"fetch_time":1756900976036}
{"symbol":"TONUSDT","bids":[],"asks":[["3.1505","965.4"],["3.1509","2035.7"]],"timestamp":1756900976029,"update_id":50199478,"fetch_time":1756900976075}
{"symbol":"TONUSDT","bids":[],"asks":[["3.1505","1245.8"],["3.1507","984.2"]],"timestamp":1756900976050,"update_id":50199479,"fetch_time":1756900976095}
{"symbol":"TONUSDT","bids":[],"asks":[["3.1505","1087.1"]],"timestamp":1756900976110,"update_id":50199482,"fetch_time":1756900976160}
{"symbol":"TONUSDT","bids":[],"asks":[["3.1506","684.8"]],"timestamp":1756900976130,"update_id":50199483,"fetch_time":1756900976180}
{"symbol":"TONUSDT","bids":[],"asks":[["3.1548","3030.8"],["3.1549","1931.5"]],"timestamp":1756900976189,"update_id":50199486,"fetch_time":1756900976235}
{"symbol":"TONUSDT","bids":[],"asks":[["3.1548","4298.4"],["3.1549","663.9"]],"timestamp":1756900976209,"update_id":50199487,"fetch_time":1756900976256}
{"symbol":"TONUSDT","bids":[],"asks":[["3.1548","3030.8"],["3.1549","1931.5"]],"timestamp":1756900976229,"update_id":50199488,"fetch_time":1756900976279}
{"symbol":"TONUSDT","bids":[],"asks":[["3.1548","4298.4"],["3.1549","663.9"]],"timestamp":1756900976250,"update_id":50199489,"fetch_time":1756900976295}
{"symbol":"TONUSDT","bids":[],"asks":[["3.1548","3030.8"],["3.1549","1931.5"]],"timestamp":1756900976270,"update_id":50199490,"fetch_time":1756900976315}
{"symbol":"TONUSDT","bids":[],"asks":[["3.1548","4298.4"],["3.1549","663.9"]],"timestamp":1756900976310,"update_id":50199491,"fetch_time":1756900976356}
{"symbol":"TONUSDT","bids":[],"asks":[["3.1503","46.5"],["3.1504","204.6"]],"timestamp":1756900976510,"update_id":50199492,"fetch_time":1756900976555}
{"symbol":"TONUSDT","bids":[["3.1499","18.3"]],"asks":[],"timestamp":1756900976549,"update_id":50199493,"fetch_time":1756900976595}
{"symbol":"TONUSDT","bids":[["3.1499","21.3"],["3.1493","48.8"],["3.1492","541.1"]],"asks":[],"timestamp":1756900976570,"update_id":50199494,"fetch_time":1756900976616}
{"symbol":"TONUSDT","bids":[["3.1494","1267.3"]],"asks":[],"timestamp":1756900976650,"update_id":50199495,"fetch_time":1756900976696}
{"symbol":"TONUSDT","bids":[],"asks":[["3.1506","245.7"]],"timestamp":1756900976689,"update_id":50199497,"fetch_time":1756900976735}
{"symbol":"TONUSDT","bids":[["3.1496","770.0"],["3.1495","143.2"]],"asks":[],"timestamp":1756900976810,"update_id":50199498,"fetch_time":1756900976855}
{"symbol":"TONUSDT","bids":[],"asks":[["3.1500","0"],["3.1501","0"],["3.1502","0"],["3.1503","0"],["3.1504","0"],["3.1505","429.1"],["3.1550","1943.3"],["3.1551","1181.0"],["3.1552","3704.4"],["3.1553","1371.9"],["3.1554","2510.9"]],"timestamp":1756900976870,"update_id":50199499,"fetch_time":1756900976915}
{"symbol":"TONUSDT","bids":[["3.1500","140.0"],["3.1498","1.8"],["3.1497","315.9"],["3.1496","457.4"],["3.1495","186.4"],["3.1491","601.7"],["3.1489","1046.6"],["3.1488","1677.1"],["3.1486","1743.8"],["3.1483","405.3"],["3.1478","1123.6"],["3.1476","2260.2"],["3.1465","592.1"],["3.1450","0"],["3.1449","0"],["3.1448","0"]],"asks":[["3.1504","51.1"],["3.1505","0"],["3.1506","156.0"],["3.1507","48.8"],["3.1508","1065.1"],["3.1509","1054.4"],["3.1510","1675.5"],["3.1511","484.5"],["3.1512","3171.4"],["3.1513","2325.0"],["3.1518","1625.3"],["3.1520","2913.1"],["3.1522","1881.4"],["3.1524","1585.9"],["3.1526","1752.0"],["3.1528","3339.5"],["3.1530","5168.4"],["3.1532","1447.8"],["3.1534","3583.9"],["3.1535","767.5"],["3.1536","5488.5"],["3.1539","2031.5"],["3.1551","980.4"]],"timestamp":1756900976890,"update_id":50199500,"fetch_time":1756900976993}
{"symbol":"TONUSDT","bids":[["3.1497","359.1"],["3.1496","575.8"],["3.1495","373.1"],["3.1489","996.6"],["3.1487","621.9"]],"asks":[["3.1503","28.8"],["3.1507","207.5"],["3.1508","924.0"],["3.1509","1828.3"],["3.1510","1899.0"],["3.1522","2311.1"],["3.1538","1228.4"],["3.1539","2029.5"],["3.1554","0"]],"timestamp":1756900976909,"update_id":50199501,"fetch_time":1756900976993}
{"symbol":"TONUSDT","bids":[],"asks":[["3.1509","1434.7"]],"timestamp":1756900976989,"update_id":50199505,"fetch_time":1756900977032}
{"symbol":"TONUSDT","bids":[],"asks":[["3.1505","29.7"],["3.1507","250.8"],["3.1553","0"]],"timestamp":1756900977030,"update_id":50199507,"fetch_time":1756900977076}
{"symbol":"TONUSDT","bids":[],"asks":[["3.1509","1154.3"],["3.1510","1338.4"],["3.1518","1911.8"]],"timestamp":1756900977049,"update_id":50199508,"fetch_time":1756900977092}
{"symbol":"TONUSDT","bids":[["3.1495","329.9"]],"asks":[],"timestamp":1756900977110,"update_id":50199511,"fetch_time":1756900977162}
{"symbol":"TONUSDT","bids":[["3.1484","1127.5"]],"asks":[],"timestamp":1756900977149,"update_id":50199512,"fetch_time":1756900977196}
{"symbol":"TONUSDT","bids":[["3.1489","694.5"]],"asks":[],"timestamp":1756900977189,"update_id":50199514,"fetch_time":1756900977236}
{"symbol":"TONUSDT","bids":[],"asks":[["3.1505","59.9"]],"timestamp":1756900977350,"update_id":50199515,"fetch_time":1756900977396}
{"symbol":"TONUSDT","bids":[["3.1490","1831.2"]],"asks":[],"timestamp":1756900977390,"update_id":50199517,"fetch_time":1756900977436}
{"symbol":"TONUSDT","bids":[["3.1491","784.0"]],"asks":[],"timestamp":1756900977469,"update_id":50199518,"fetch_time":1756900977516}
{"symbol":"TONUSDT","bids":[],"asks":[["3.1548","3030.8"],["3.1549","1931.5"]],"timestamp":1756900977530,"update_id":50199519,"fetch_time":1756900977577}
{"symbol":"TONUSDT","bids":[],"asks":[["3.1548","3275.0"]],"timestamp":1756900977549,"update_id":50199520,"fetch_time":1756900977592}
{"symbol":"TONUSDT","bids":[["3.1490","1781.2"]],"asks":[],"timestamp":1756900977790,"update_id":50199521,"fetch_time":1756900977836}
{"symbol":"TONUSDT","bids":[["3.1499","4.8"]],"asks":[],"timestamp":1756900977870,"update_id":50199523,"fetch_time":1756900977921}
{"symbol":"TONUSDT","bids":[["3.1501","5.9"],["3.1476","2262.0"],["3.1451","0"]],"asks":[["3.1522","2312.9"]],"timestamp":1756900977890,"update_id":50199524,"fetch_time":1756900977936}
{"symbol":"TONUSDT","bids":[["3.1496","644.1"],["3.1492","1500.7"]],"asks":[],"timestamp":1756900977929,"update_id":50199525,"fetch_time":1756900977981}
{"symbol":"TONUSDT","bids":[["3.1498","180.5"]],"asks":[],"timestamp":1756900977950,"update_id":50199526,"fetch_time":1756900977997}
{"symbol":"TONUSDT","bids":[["3.1495","143.2"]],"asks":[],"timestamp":1756900977969,"update_id":50199527,"fetch_time":1756900978017}
{"symbol":"TONUSDT","bids":[["3.1493","48.9"],["3.1492","1457.5"],["3.1491","740.8"],["3.1490","1738.0"]],"asks":[],"timestamp":1756900977990,"update_id":50199528,"fetch_time":1756900978037}
{"symbol":"TONUSDT","bids":[["3.1493","356.0"]],"asks":[],"timestamp":1756900978010,"update_id":50199529,"fetch_time":1756900978057}
{"symbol":"TONUSDT","bids":[],"asks":[["3.1508","1778.1"],["3.1509","1183.1"]],"timestamp":1756900978310,"update_id":50199531,"fetch_time":1756900978357}
{"symbol":"TONUSDT","bids":[],"asks":[["3.1511","712.7"]],"timestamp":1756900978570,"update_id":50199533,"fetch_time":1756900978632}
{"symbol":"TONUSDT","bids":[],"asks":[["3.1505","0"],["3.1553","1371.9"]],"timestamp":1756900978610,"update_id":50199535,"fetch_time":1756900978656}
{"symbol":"TONUSDT","bids":[["3.1491","734.0"]],"asks":[],"timestamp":1756900978790,"update_id":50199536,"fetch_time":1756900978836}
{"symbol":"TONUSDT","bids":[],"asks":[["3.1506","381.0"]],"timestamp":1756900978810,"update_id":50199537,"fetch_time":1756900978856}
{"symbol":"TONUSDT","bids":[["3.1492","1500.7"]],"asks":[],"timestamp":1756900978830,"update_id":50199538,"fetch_time":1756900978876}
{"symbol":"TONUSDT","bids":[["3.1496","645.9"]],"asks":[],"timestamp":1756900978889,"update_id":50199539,"fetch_time":1756900978936}
{"symbol":"TONUSDT","bids":[["3.1493","355.9"]],"asks":[],"timestamp":1756900978909,"update_id":50199540,"fetch_time":1756900978952}
{"symbol":"TONUSDT","bids":[["3.1498","190.8"]],"asks":[],"timestamp":1756900979009,"update_id":50199542,"fetch_time":1756900979061}
{"symbol":"TONUSDT","bids":[],"asks":[["3.1539","1993.5"]],"timestamp":1756900979029,"update_id":50199543,"fetch_time":1756900979076}
{"symbol":"TONUSDT","bids":[["3.1484","968.9"]],"asks":[],"timestamp":1756900979110,"update_id":50199544,"fetch_time":1756900979157}
{"symbol":"TONUSDT","bids":[["3.1501","0"],["3.1500","149.8"],["3.1451","5215.1"]],"asks":[],"timestamp":1756900979610,"update_id":50199545,"fetch_time":1756900979657}
{"symbol":"TONUSDT","bids":[],"asks":[["3.1533","1013.1"],["3.1538","890.2"]],"timestamp":1756900979650,"update_id":50199547,"fetch_time":1756900979701}
{"symbol":"TONUSDT","bids":[["3.1492","1473.4"],["3.1490","1777.0"],["3.1485","2437.8"],["3.1483","461.8"]],"asks":[["3.1505","30.2"],["3.1509","1154.3"],["3.1511","784.7"],["3.1515","1386.8"],["3.1518","1971.3"],["3.1553","0"]],"timestamp":1756900979689,"update_id":50199548,"fetch_time":1756900979740}
{"symbol":"TONUSDT","bids":[],"asks":[["3.1505","59.9"],["3.1513","2510.1"]],"timestamp":1756900979890,"update_id":50199549,"fetch_time":1756900979936}
{"symbol":"TONUSDT","bids":[["3.1500","140.0"]],"asks":[],"timestamp":1756900979949,"update_id":50199550,"fetch_time":1756900979997}
{"symbol":"TONUSDT","bids":[["3.1500","9.5"]],"asks":[],"timestamp":1756900979970,"update_id":50199551,"fetch_time":1756900980016}
{"symbol":"TONUSDT","bids":[],"asks":[["3.1525","2147.2"]],"timestamp":1756900980009,"update_id":50199552,"fetch_time":1756900980057}
{"symbol":"TONUSDT","bids":[["3.1496","81.0"]],"asks":[],"timestamp":1756900980069,"update_id":50199554,"fetch_time":1756900980116}
{"symbol":"TONUSDT","bids":[["3.1496","487.2"],["3.1492","1386.9"],["3.1491","647.5"],["3.1490","1733.7"],["3.1479","907.0"]],"asks":[["3.1502","28.8"],["3.1503","14.5"],["3.1504","69.3"],["3.1505","213.8"],["3.1507","437.7"],["3.1508","2423.8"],["3.1513","2466.8"],["3.1537","2222.3"],["3.1538","888.2"],["3.1548","4542.6"],["3.1549","663.9"],["3.1552","0"]],"timestamp":1756900980090,"update_id":50199555,"fetch_time":1756900980136}
{"symbol":"TONUSDT","bids":[],"asks":[["3.1507","781.7"],["3.1508","2753.4"],["3.1548","4298.4"]],"timestamp":1756900980109,"update_id":50199556,"fetch_time":1756900980156}
{"symbol":"TONUSDT","bids":[],"asks":[["3.1507","1248.9"]],"timestamp":1756900980130,"update_id":50199557,"fetch_time":1756900980177}
{"symbol":"TONUSDT","bids":[],"asks":[["3.1505","217.0"]],"timestamp":1756900980150,"update_id":50199558,"fetch_time":1756900980197}
{"symbol":"TONUSDT","bids":[],"asks":[["3.1508","2099.7"]],"timestamp":1756900980189,"update_id":50199559,"fetch_time":1756900980233}
{"symbol":"TONUSDT","bids":[],"asks":[["3.1508","1755.9"]],"timestamp":1756900980210,"update_id":50199560,"fetch_time":1756900980257}
{"symbol":"TONUSDT","bids":[["3.1495","190.0"],["3.1482","2737.6"],["3.1479","451.1"],["3.1476","1717.9"],["3.1473","2103.5"],["3.1470","2609.8"],["3.1467","1504.6"]],"asks":[["3.1501","140.0"],["3.1502","5.3"],["3.1504","233.6"],["3.1507","1090.2"],["3.1512","3048.5"],["3.1537","2220.3"],["3.1551","0"]],"timestamp":1756900980269,"update_id":50199561,"fetch_time":1756900980316}
{"symbol":"TONUSDT","bids":[["3.1491","690.7"],["3.1490","1776.9"]],"asks":[["3.1501","0"],["3.1502","0"],["3.1515","2435.1"],["3.1551","980.4"],["3.1552","3704.4"]],"timestamp":1756900980469,"update_id":50199570,"fetch_time":1756900980521}
{"symbol":"TONUSDT","bids":[["3.1493","312.7"],["3.1479","818.7"],["3.1477","986.7"],["3.1475","1724.9"],["3.1473","2735.7"],["3.1471","1425.5"],["3.1469","1291.5"]],"asks":[["3.1502","28.8"],["3.1503","7.4"],["3.1506","381.0"],["3.1507","279.0"],["3.1508","2223.1"],["3.1512","2933.1"],["3.1515","1635.1"],["3.1536","5488.5"],["3.1537","2222.3"],["3.1552","0"]],"timestamp":1756900980489,"update_id":50199571,"fetch_time":1756900980536}
{"symbol":"TONUSDT","bids":[["3.1495","190.0"]],"asks":[],"timestamp":1756900980569,"update_id":50199575,"fetch_time":1756900980616}
{"symbol":"TONUSDT","bids":[],"asks":[["3.1508","1755.9"]],"timestamp":1756900980589,"update_id":50199576,"fetch_time":1756900980636}
{"symbol":"TONUSDT","bids":[],"asks":[["3.1503","0"],["3.1552","3704.4"]],"timestamp":1756900980610,"update_id":50199577,"fetch_time":1756900980657}
{"symbol":"TONUSDT","bids":[],"asks":[["3.1521","3491.4"]],"timestamp":1756900980630,"update_id":50199578,"fetch_time":1756900980677}
{"symbol":"TONUSDT","bids":[],"asks":[["3.1548","3275.0"]],"timestamp":1756900980790,"update_id":50199582,"fetch_time":1756900980836}
{"symbol":"TONUSDT","bids":[],"asks":[["3.1505","188.4"],["3.1506","390.2"]],"timestamp":1756900980809,"update_id":50199583,"fetch_time":1756900980856}
{"symbol":"TONUSDT","bids":[],"asks":[["3.1548","4542.6"],["3.1549","663.9"]],"timestamp":1756900980829,"update_id":50199584,"fetch_time":1756900980876}
{"symbol":"TONUSDT","bids":[],"asks":[["3.1521","3166.7"]],"timestamp":1756900980869,"update_id":50199586,"fetch_time":1756900980916}
{"symbol":"TONUSDT","bids":[],"asks":[["3.1518","2639.8"]],"timestamp":1756900980949,"update_id":50199587,"fetch_time":1756900980996}
{"symbol":"TONUSDT","bids":[["3.1487","1378.6"]],"asks":[],"timestamp":1756900980989,"update_id":50199588,"fetch_time":1756900981036}
{"symbol":"TONUSDT","bids":[],"asks":[["3.1522","1969.1"]],"timestamp":1756900981029,"update_id":50199589,"fetch_time":1756900981072}
{"symbol":"TONUSDT","bids":[["3.1498","188.8"],["3.1495","276.5"]],"asks":[["3.1502","0"],["3.1505","3.2"],["3.1513","2782.4"],["3.1546","2410.6"],["3.1553","579.8"]],"timestamp":1756900981109,"update_id":50199592,"fetch_time":1756900981156}
{"symbol":"TONUSDT","bids":[["3.1501","20.0"],["3.1451","0"]],"asks":[["3.1508","493.3"],["3.1509","2109.2"],["3.1512","2728.1"]],"timestamp":1756900981169,"update_id":50199595,"fetch_time":1756900981216}
{"symbol":"TONUSDT","bids":[],"asks":[["3.1508","206.9"]],"timestamp":1756900981209,"update_id":50199597,"fetch_time":1756900981256}
{"symbol":"TONUSDT","bids":[["3.1501","0"],["3.1496","674.0"],["3.1495","233.3"],["3.1451","5215.1"]],"asks":[["3.1507","207.5"],["3.1509","2152.5"],["3.1510","1338.4"]],"timestamp":1756900981229,"update_id":50199598,"fetch_time":1756900981276}
{"symbol":"TONUSDT","bids":[],"asks":[["3.1505","13.9"],["3.1509","1098.0"],["3.1513","2597.4"],["3.1516","3090.1"]],"timestamp":1756900981269,"update_id":50199600,"fetch_time":1756900981316}
{"symbol":"TONUSDT","bids":[],"asks":[["3.1509","1284.8"],["3.1512","3043.7"],["3.1513","2281.8"]],"timestamp":1756900981290,"update_id":50199601,"fetch_time":1756900981338}
{"symbol":"TONUSDT","bids":[["3.1498","5.0"],["3.1496","671.0"]],"asks":[],"timestamp":1756900981349,"update_id":50199604,"fetch_time":1756900981401}
{"symbol":"TONUSDT","bids":[["3.1496","487.2"]],"asks":[],"timestamp":1756900981390,"update_id":50199605,"fetch_time":1756900981437}
{"symbol":"TONUSDT","bids":[],"asks":[["3.1512","3247.5"],["3.1519","2355.8"]],"timestamp":1756900981429,"update_id":50199606,"fetch_time":1756900981477}
{"symbol":"TONUSDT","bids":[],"asks":[["3.1518","1850.7"]],"timestamp":1756900981450,"update_id":50199607,"fetch_time":1756900981497}
{"symbol":"TONUSDT","bids":[],"asks":[["3.1548","3648.0"],["3.1549","663.9"]],"timestamp":1756900981530,"update_id":50199608,"fetch_time":1756900981581}
{"symbol":"TONUSDT","bids":[["3.1502","1.0"],["3.1451","0"]],"asks":[],"timestamp":1756900981689,"update_id":50199609,"fetch_time":1756900981737}
{"symbol":"TONUSDT","bids":[["3.1488","1837.7"]],"asks":[],"timestamp":1756900981729,"update_id":50199611,"fetch_time":1756900981777}
{"symbol":"TONUSDT","bids":[["3.1496","674.0"]],"asks":[],"timestamp":1756900981749,"update_id":50199612,"fetch_time":1756900981797}
{"symbol":"TONUSDT","bids":[],"asks":[["3.1551","1012.1"]],"timestamp":1756900981829,"update_id":50199615,"fetch_time":1756900981880}
{"symbol":"TONUSDT","bids":[["3.1496","1381.8"]],"asks":[],"timestamp":1756900981869,"update_id":50199616,"fetch_time":1756900981917}
{"symbol":"TONUSDT","bids":[["3.1496","1375.2"],["3.1492","1800.3"],["3.1486","1169.4"]],"asks":[],"timestamp":1756900981910,"update_id":50199618,"fetch_time":1756900981957}
{"symbol":"TONUSDT","bids":[],"asks":[["3.1516","3369.4"],["3.1546","2735.8"]],"timestamp":1756900982229,"update_id":50199621,"fetch_time":1756900982277}
{"symbol":"TONUSDT","bids":[],"asks":[["3.1510","1433.4"]],"timestamp":1756900982270,"update_id":50199622,"fetch_time":1756900982320}
{"symbol":"TONUSDT","bids":[["3.1502","3.9"],["3.1484","805.4"]],"asks":[],"timestamp":1756900982310,"update_id":50199623,"fetch_time":1756900982356}
{"symbol":"TONUSDT","bids":[["3.1463","8812.1"],["3.1458","3721.5"]],"asks":[],"timestamp":1756900982389,"update_id":50199624,"fetch_time":1756900982440}
{"symbol":"TONUSDT","bids":[["3.1460","2422.8"]],"asks":[],"timestamp":1756900982410,"update_id":50199625,"fetch_time":1756900982456}
{"symbol":"TONUSDT","bids":[],"asks":[["3.1516","3655.9"]],"timestamp":1756900982509,"update_id":50199626,"fetch_time":1756900982557}
{"symbol":"TONUSDT","bids":[["3.1492","1843.5"],["3.1491","370.0"]],"asks":[],"timestamp":1756900982550,"update_id":50199627,"fetch_time":1756900982600}
{"symbol":"TONUSDT","bids":[],"asks":[["3.1519","2069.3"]],"timestamp":1756900982569,"update_id":50199628,"fetch_time":1756900982616}
{"symbol":"TONUSDT","bids":[],"asks":[["3.1505","45.2"]],"timestamp":1756900982610,"update_id":50199629,"fetch_time":1756900982656}
{"symbol":"TONUSDT","bids":[["3.1492","1800.3"],["3.1491","326.8"]],"asks":[],"timestamp":1756900982670,"update_id":50199631,"fetch_time":1756900982716}
{"symbol":"TONUSDT","bids":[["3.1499","5.0"]],"asks":[],"timestamp":1756900982730,"update_id":50199632,"fetch_time":1756900982776}
{"symbol":"TONUSDT","bids":[["3.1491","370.0"]],"asks":[],"timestamp":1756900982790,"update_id":50199634,"fetch_time":1756900982836}
{"symbol":"TONUSDT","bids":[],"asks":[["3.1520","2091.8"]],"timestamp":1756900982909,"update_id":50199636,"fetch_time":1756900982961}
{"symbol":"TONUSDT","bids":[["3.1494","1024.0"],["3.1493","312.7"],["3.1492","1800.2"],["3.1491","326.7"],["3.1490","2775.3"],["3.1489","651.2"],["3.1481","3092.9"]],"asks":[],"timestamp":1756900983069,"update_id":50199637,"fetch_time":1756900983116}
{"symbol":"TONUSDT","bids":[["3.1502","19.9"]],"asks":[],"timestamp":1756900983169,"update_id":50199638,"fetch_time":1756900983221}
{"symbol":"TONUSDT","bids":[],"asks":[["3.1514","4521.5"]],"timestamp":1756900983229,"update_id":50199639,"fetch_time":1756900983277}
{"symbol":"TONUSDT","bids":[],"asks":[["3.1517","2581.0"]],"timestamp":1756900983329,"update_id":50199640,"fetch_time":1756900983372}
{"symbol":"TONUSDT","bids":[["3.1492","1757.0"],["3.1491","283.5"],["3.1463","11810.6"],["3.1458","723.7"]],"asks":[],"timestamp":1756900983350,"update_id":50199641,"fetch_time":1756900983400}
{"symbol":"TONUSDT","bids":[["3.1464","4778.2"],["3.1460","1193.2"]],"asks":[],"timestamp":1756900983369,"update_id":50199642,"fetch_time":1756900983416}
{"symbol":"TONUSDT","bids":[["3.1495","46.4"],["3.1494","1067.2"]],"asks":[],"timestamp":1756900983449,"update_id":50199645,"fetch_time":1756900983497}
{"symbol":"TONUSDT","bids":[],"asks":[["3.1548","3648.0"]],"timestamp":1756900983470,"update_id":50199646,"fetch_time":1756900983517}
{"symbol":"TONUSDT","bids":[],"asks":[["3.1510","1401.8"]],"timestamp":1756900983530,"update_id":50199647,"fetch_time":1756900983577}
{"symbol":"TONUSDT","bids":[],"asks":[["3.1506","36.8"]],"timestamp":1756900983590,"update_id":50199648,"fetch_time":1756900983641}
{"symbol":"TONUSDT","bids":[["3.1491","472.0"]],"asks":[],"timestamp":1756900983629,"update_id":50199650,"fetch_time":1756900983677}
{"symbol":"TONUSDT","bids":[],"asks":[["3.1548","2380.4"],["3.1549","1931.5"]],"timestamp":1756900983650,"update_id":50199651,"fetch_time":1756900983697}
{"symbol":"TONUSDT","bids":[],"asks":[["3.1511","749.5"],["3.1512","2728.1"],["3.1548","2624.6"]],"timestamp":1756900983670,"update_id":50199652,"fetch_time":1756900983717}
{"symbol":"TONUSDT","bids":[],"asks":[["3.1510","1401.8"]],"timestamp":1756900983690,"update_id":50199653,"fetch_time":1756900983737}
{"symbol":"TONUSDT","bids":[],"asks":[["3.1508","207.0"],["3.1509","1909.2"]],"timestamp":1756900983709,"update_id":50199654,"fetch_time":1756900983753}
{"symbol":"TONUSDT","bids":[["3.1498","682.4"],["3.1497","190.0"]],"asks":[],"timestamp":1756900983769,"update_id":50199655,"fetch_time":1756900983821}
{"symbol":"TONUSDT","bids":[["3.1492","1843.5"]],"asks":[],"timestamp":1756900983949,"update_id":50199656,"fetch_time":1756900983997}
{"symbol":"TONUSDT","bids":[["3.1502","29.3"],["3.1500","0"],["3.1464","4762.4"],["3.1451","5215.1"]],"asks":[],"timestamp":1756900983969,"update_id":50199657,"fetch_time":1756900984017}
{"symbol":"TONUSDT","bids":[],"asks":[["3.1548","3892.2"],["3.1549","663.9"]],"timestamp":1756900984150,"update_id":50199658,"fetch_time":1756900984196}
{"symbol":"TONUSDT","bids":[],"asks":[["3.1548","3648.0"]],"timestamp":1756900984170,"update_id":50199659,"fetch_time":1756900984216}
{"symbol":"TONUSDT","bids":[],"asks":[["3.1512","2973.2"],["3.1513","2553.3"]],"timestamp":1756900984290,"update_id":50199660,"fetch_time":1756900984341}
{"symbol":"TONUSDT","bids":[],"asks":[["3.1508","250.2"]],"timestamp":1756900984310,"update_id":50199661,"fetch_time":1756900984357}
{"symbol":"TONUSDT","bids":[],"asks":[["3.1518","2930.9"]],"timestamp":1756900984350,"update_id":50199663,"fetch_time":1756900984396}
{"symbol":"TONUSDT","bids":[],"asks":[["3.1516","4259.8"]],"timestamp":1756900984370,"update_id":50199664,"fetch_time":1756900984416}
{"symbol":"TONUSDT","bids":[["3.1491","472.0"]],"asks":[],"timestamp":1756900984409,"update_id":50199665,"fetch_time":1756900984456}
{"symbol":"TONUSDT","bids":[["3.1492","1843.5"]],"asks":[],"timestamp":1756900984430,"update_id":50199666,"fetch_time":1756900984476}
{"symbol":"TONUSDT","bids":[],"asks":[["3.1506","5.0"],["3.1512","3176.4"]],"timestamp":1756900984450,"update_id":50199667,"fetch_time":1756900984497}
{"symbol":"TONUSDT","bids":[["3.1493","355.9"]],"asks":[],"timestamp":1756900984470,"update_id":50199668,"fetch_time":1756900984517}
{"symbol":"TONUSDT","bids":[["3.1479","857.2"]],"asks":[],"timestamp":1756900984569,"update_id":50199669,"fetch_time":1756900984621}
{"symbol":"TONUSDT","bids":[["3.1498","392.8"],["3.1491","370.0"]],"asks":[],"timestamp":1756900984670,"update_id":50199670,"fetch_time":1756900984720}
{"symbol":"TONUSDT","bids":[],"asks":[["3.1508","250.2"],["3.1509","1909.2"]],"timestamp":1756900984910,"update_id":50199673,"fetch_time":1756900984957}
{"symbol":"TONUSDT","bids":[],"asks":[["3.1507","250.8"]],"timestamp":1756900985050,"update_id":50199674,"fetch_time":1756900985101}
{"symbol":"TONUSDT","bids":[],"asks":[["3.1507","207.6"]],"timestamp":1756900985110,"update_id":50199675,"fetch_time":1756900985156}
{"symbol":"TONUSDT","bids":[["3.1498","5.0"],["3.1497","292.8"],["3.1493","312.7"],["3.1492","1800.3"],["3.1491","326.8"],["3.1490","1733.7"],["3.1479","755.2"],["3.1460","1662.6"]],"asks":[["3.1503","151.7"],["3.1504","146.6"],["3.1505","22.8"],["3.1506","206.3"],["3.1507","241.4"],["3.1508","1344.7"],["3.1515","1635.1"],["3.1538","1235.8"],["3.1539","1993.5"],["3.1553","0"]],"timestamp":1756900985490,"update_id":50199676,"fetch_time":1756900985536}
{"symbol":"TONUSDT","bids":[["3.1480","4155.2"]],"asks":[],"timestamp":1756900985610,"update_id":50199682,"fetch_time":1756900985657}
{"symbol":"TONUSDT","bids":[],"asks":[["3.1509","1154.3"]],"timestamp":1756900985629,"update_id":50199683,"fetch_time":1756900985680}
{"symbol":"TONUSDT","bids":[["3.1490","1776.9"],["3.1484","805.4"]],"asks":[],"timestamp":1756900985670,"update_id":50199685,"fetch_time":1756900985716}
{"symbol":"TONUSDT","bids":[["3.1484","1847.0"]],"asks":[],"timestamp":1756900985689,"update_id":50199686,"fetch_time":1756900985740}
{"symbol":"TONUSDT","bids":[["3.1497","240.7"]],"asks":[],"timestamp":1756900985810,"update_id":50199687,"fetch_time":1756900985858}
{"symbol":"TONUSDT","bids":[],"asks":[["3.1504","234.9"]],"timestamp":1756900985829,"update_id":50199688,"fetch_time":1756900985876}
{"symbol":"TONUSDT","bids":[["3.1495","191.7"],["3.1491","370.0"]],"asks":[],"timestamp":1756900986030,"update_id":50199689,"fetch_time":1756900986076}
{"symbol":"TONUSDT","bids":[["3.1478","1209.8"]],"asks":[],"timestamp":1756900986050,"update_id":50199690,"fetch_time":1756900986096}
{"symbol":"TONUSDT","bids":[["3.1498","279.2"],["3.1496","1420.1"]],"asks":[],"timestamp":1756900986210,"update_id":50199695,"fetch_time":1756900986256}
{"symbol":"TONUSDT","bids":[["3.1497","277.6"]],"asks":[],"timestamp":1756900986289,"update_id":50199698,"fetch_time":1756900986333}
{"symbol":"TONUSDT","bids":[["3.1496","1607.1"]],"asks":[],"timestamp":1756900986330,"update_id":50199700,"fetch_time":1756900986376}
{"symbol":"TONUSDT","bids":[["3.1486","1705.3"]],"asks":[],"timestamp":1756900986529,"update_id":50199703,"fetch_time":1756900986576}
{"symbol":"TONUSDT","bids":[["3.1489","1596.4"]],"asks":[],"timestamp":1756900986669,"update_id":50199704,"fetch_time":1756900986722}
{"symbol":"TONUSDT","bids":[["3.1492","1538.7"],["3.1490","1737.9"],["3.1485","2496.7"],["3.1484","748.9"]],"asks":[],"timestamp":1756900986710,"update_id":50199706,"fetch_time":1756900986757}
{"symbol":"TONUSDT","bids":[],"asks":[["3.1505","23.1"]],"timestamp":1756900986790,"update_id":50199707,"fetch_time":1756900986837}
{"symbol":"TONUSDT","bids":[["3.1502","0"],["3.1498","5.0"],["3.1489","694.4"],["3.1485","2496.8"],["3.1450","5951.7"]],"asks":[["3.1502","122.9"],["3.1504","246.0"],["3.1505","54.4"],["3.1511","953.5"],["3.1513","2279.5"],["3.1518","3306.5"],["3.1520","2169.7"],["3.1552","0"]],"timestamp":1756900986810,"update_id":50199708,"fetch_time":1756900986857}
{"symbol":"TONUSDT","bids":[["3.1499","1.8"],["3.1497","349.9"],["3.1496","487.2"],["3.1495","242.3"],["3.1494","1211.0"],["3.1493","312.7"],["3.1488","1353.2"]],"asks":[["3.1501","28.8"],["3.1503","0"],["3.1504","289.2"],["3.1505","208.3"],["3.1507","841.2"],["3.1510","1603.9"],["3.1511","708.4"],["3.1512","2887.8"],["3.1536","5490.5"],["3.1538","1233.8"]],"timestamp":1756900986829,"update_id":50199709,"fetch_time":1756900986876}
{"symbol":"TONUSDT","bids":[],"asks":[["3.1504","451.1"],["3.1506","1062.5"],["3.1507","1569.5"]],"timestamp":1756900986870,"update_id":50199711,"fetch_time":1756900986916}
{"symbol":"TONUSDT","bids":[],"asks":[["3.1507","1420.4"],["3.1508","1462.4"],["3.1531","3568.3"],["3.1533","559.5"]],"timestamp":1756900986910,"update_id":50199713,"fetch_time":1756900986956}
{"symbol":"TONUSDT","bids":[["3.1499","142.8"],["3.1494","1254.2"],["3.1493","388.1"]],"asks":[],"timestamp":1756900986990,"update_id":50199717,"fetch_time":1756900987040}
{"symbol":"TONUSDT","bids":[],"asks":[["3.1504","249.2"]],"timestamp":1756900987010,"update_id":50199718,"fetch_time":1756900987056}
{"symbol":"TONUSDT","bids":[],"asks":[["3.1508","1088.4"],["3.1514","4478.3"]],"timestamp":1756900987450,"update_id":50199722,"fetch_time":1756900987497}
{"symbol":"TONUSDT","bids":[["3.1496","487.2"],["3.1488","1193.3"]],"asks":[],"timestamp":1756900987470,"update_id":50199723,"fetch_time":1756900987516}
{"symbol":"TONUSDT","bids":[],"asks":[["3.1511","944.4"],["3.1512","2887.8"]],"timestamp":1756900987510,"update_id":50199724,"fetch_time":1756900987557}
{"symbol":"TONUSDT","bids":[["3.1488","1881.3"]],"asks":[],"timestamp":1756900987529,"update_id":50199725,"fetch_time":1756900987576}
{"symbol":"TONUSDT","bids":[],"asks":[["3.1507","1129.5"]],"timestamp":1756900987550,"update_id":50199726,"fetch_time":1756900987596}
{"symbol":"TONUSDT","bids":[["3.1500","3.1"],["3.1486","1768.6"],["3.1450","0"]],"asks":[],"timestamp":1756900987590,"update_id":50199727,"fetch_time":1756900987640}
{"symbol":"TONUSDT","bids":[["3.1488","1193.3"]],"asks":[],"timestamp":1756900987609,"update_id":50199728,"fetch_time":1756900987657}
{"symbol":"TONUSDT","bids":[["3.1495","235.1"],["3.1493","431.4"],["3.1490","1781.2"],["3.1489","737.7"]],"asks":[],"timestamp":1756900987629,"update_id":50199729,"fetch_time":1756900987676}
{"symbol":"TONUSDT","bids":[["3.1497","3.2"],["3.1496","697.3"]],"asks":[],"timestamp":1756900987649,"update_id":50199730,"fetch_time":1756900987701}
{"symbol":"TONUSDT","bids":[],"asks":[["3.1506","1249.5"]],"timestamp":1756900987729,"update_id":50199731,"fetch_time":1756900987776}
{"symbol":"TONUSDT","bids":[["3.1494","1067.2"]],"asks":[],"timestamp":1756900987750,"update_id":50199732,"fetch_time":1756900987796}
{"symbol":"TONUSDT","bids":[["3.1499","2.8"]],"asks":[],"timestamp":1756900987870,"update_id":50199733,"fetch_time":1756900987917}
{"symbol":"TONUSDT","bids":[["3.1494","1254.3"]],"asks":[],"timestamp":1756900987949,"update_id":50199735,"fetch_time":1756900987996}
{"symbol":"TONUSDT","bids":[["3.1494","1297.6"],["3.1489","839.0"],["3.1471","1202.9"]],"asks":[],"timestamp":1756900988089,"update_id":50199737,"fetch_time":1756900988136}
{"symbol":"TONUSDT","bids":[["3.1500","0"],["3.1499","0"],["3.1498","141.6"],["3.1494","1211.1"],["3.1493","388.1"],["3.1487","665.1"],["3.1473","2938.1"],["3.1450","5951.7"],["3.1449","2843.4"]],"asks":[["3.1500","28.8"],["3.1504","443.1"],["3.1508","1151.6"],["3.1512","2887.8"],["3.1536","5488.5"],["3.1551","0"]],"timestamp":1756900988469,"update_id":50199740,"fetch_time":1756900988517}
{"symbol":"TONUSDT","bids":[["3.1494","127.9"],["3.1493","575.2"],["3.1492","1502.1"],["3.1486","958.0"]],"asks":[["3.1499","28.8"],["3.1500","0"],["3.1501","0"],["3.1504","630.2"],["3.1505","501.2"],["3.1510","1596.9"],["3.1511","742.3"],["3.1528","3157.3"],["3.1534","3585.9"],["3.1551","1012.1"]],"timestamp":1756900988489,"update_id":50199741,"fetch_time":1756900988536}
{"symbol":"TONUSDT","bids":[["3.1486","1795.0"]],"asks":[["3.1503","158.7"],["3.1505","1025.6"],["3.1506","1090.8"],["3.1517","2822.6"],["3.1521","4152.9"],["3.1551","0"]],"timestamp":1756900988529,"update_id":50199743,"fetch_time":1756900988577}
{"symbol":"TONUSDT","bids":[],"asks":[["3.1502","126.1"],["3.1503","161.9"],["3.1504","443.1"],["3.1506","435.7"],["3.1510","1628.2"],["3.1511","708.4"]],"timestamp":1756900988550,"update_id":50199744,"fetch_time":1756900988597}
{"symbol":"TONUSDT","bids":[],"asks":[["3.1505","1212.7"]],"timestamp":1756900988590,"update_id":50199745,"fetch_time":1756900988636}
{"symbol":"TONUSDT","bids":[],"asks":[["3.1506","91.5"]],"timestamp":1756900988630,"update_id":50199747,"fetch_time":1756900988676}
{"symbol":"TONUSDT","bids":[],"asks":[["3.1503","3.2"]],"timestamp":1756900988670,"update_id":50199749,"fetch_time":1756900988721}
{"symbol":"TONUSDT","bids":[],"asks":[["3.1499","31.1"],["3.1504","440.7"]],"timestamp":1756900988730,"update_id":50199750,"fetch_time":1756900988776}
{"symbol":"TONUSDT","bids":[["3.1485","2196.2"]],"asks":[],"timestamp":1756900988769,"update_id":50199751,"fetch_time":1756900988816}
{"symbol":"TONUSDT","bids":[],"asks":[["3.1499","2.3"]],"timestamp":1756900988810,"update_id":50199752,"fetch_time":1756900988857}
{"symbol":"TONUSDT","bids":[],"asks":[["3.1504","246.8"]],"timestamp":1756900988850,"update_id":50199754,"fetch_time":1756900988897}
{"symbol":"TONUSDT","bids":[["3.1494","681.4"]],"asks":[],"timestamp":1756900989290,"update_id":50199759,"fetch_time":1756900989337}
{"symbol":"TONUSDT","bids":[["3.1488","1680.2"]],"asks":[],"timestamp":1756900989529,"update_id":50199761,"fetch_time":1756900989576}
{"symbol":"TONUSDT","bids":[],"asks":[["3.1504","235.7"]],"timestamp":1756900989790,"update_id":50199762,"fetch_time":1756900989836}
{"symbol":"TONUSDT","bids":[["3.1484","748.9"]],"asks":[],"timestamp":1756900990110,"update_id":50199764,"fetch_time":1756900990161}
{"symbol":"TONUSDT","bids":[["3.1477","2028.3"]],"asks":[],"timestamp":1756900990130,"update_id":50199765,"fetch_time":1756900990177}
{"symbol":"TONUSDT","bids":[["3.1492","1473.4"],["3.1490","2082.3"],["3.1477","986.7"]],"asks":[],"timestamp":1756900990430,"update_id":50199766,"fetch_time":1756900990476}
{"symbol":"TONUSDT","bids":[["3.1482","3779.2"]],"asks":[],"timestamp":1756900990449,"update_id":50199767,"fetch_time":1756900990497}
{"symbol":"TONUSDT","bids":[["3.1484","1059.3"]],"asks":[],"timestamp":1756900990530,"update_id":50199768,"fetch_time":1756900990577}
{"symbol":"TONUSDT","bids":[["3.1459","1286.3"],["3.1458","2529.5"]],"asks":[],"timestamp":1756900990929,"update_id":50199769,"fetch_time":1756900990976}
{"symbol":"TONUSDT","bids":[],"asks":[["3.1508","1088.4"]],"timestamp":1756900991329,"update_id":50199770,"fetch_time":1756900991380}
{"symbol":"TONUSDT","bids":[],"asks":[["3.1504","862.6"]],"timestamp":1756900991370,"update_id":50199772,"fetch_time":1756900991416}
{"symbol":"TONUSDT","bids":[],"asks":[["3.1504","1207.1"],["3.1505","1909.1"]],"timestamp":1756900991390,"update_id":50199773,"fetch_time":1756900991441}
{"symbol":"TONUSDT","bids":[["3.1494","638.1"],["3.1491","407.8"]],"asks":[],"timestamp":1756900991429,"update_id":50199775,"fetch_time":1756900991476}
{"symbol":"TONUSDT","bids":[],"asks":[["3.1505","1845.7"]],"timestamp":1756900991450,"update_id":50199776,"fetch_time":1756900991501}
{"symbol":"TONUSDT","bids":[],"asks":[["3.1505","1190.6"]],"timestamp":1756900991469,"update_id":50199777,"fetch_time":1756900991517}
{"symbol":"TONUSDT","bids":[],"asks":[["3.1505","909.6"]],"timestamp":1756900991490,"update_id":50199778,"fetch_time":1756900991542}
{"symbol":"TONUSDT","bids":[["3.1482","2737.6"]],"asks":[],"timestamp":1756900991510,"update_id":50199779,"fetch_time":1756900991556}
{"symbol":"TONUSDT","bids":[["3.1484","748.9"]],"asks":[],"timestamp":1756900991529,"update_id":50199780,"fetch_time":1756900991576}
{"symbol":"TONUSDT","bids":[["3.1476","2316.4"]],"asks":[],"timestamp":1756900991550,"update_id":50199781,"fetch_time":1756900991601}
{"symbol":"TONUSDT","bids":[["3.1478","1420.2"]],"asks":[],"timestamp":1756900991570,"update_id":50199782,"fetch_time":1756900991616}
{"symbol":"TONUSDT","bids":[["3.1493","279.2"],["3.1492","1503.2"],["3.1480","4155.2"],["3.1476","1274.8"]],"asks":[],"timestamp":1756900991610,"update_id":50199783,"fetch_time":1756900991657}
{"symbol":"TONUSDT","bids":[["3.1480","3774.9"]],"asks":[],"timestamp":1756900991650,"update_id":50199785,"fetch_time":1756900991696}
{"symbol":"TONUSDT","bids":[],"asks":[["3.1504","1394.3"],["3.1505","446.6"]],"timestamp":1756900991790,"update_id":50199788,"fetch_time":1756900991837}
{"symbol":"TONUSDT","bids":[],"asks":[["3.1502","126.1"],["3.1503","161.9"],["3.1505","908.5"]],"timestamp":1756900991809,"update_id":50199789,"fetch_time":1756900991857}
{"symbol":"TONUSDT","bids":[],"asks":[["3.1502","284.8"],["3.1504","1235.6"],["3.1519","3021.5"]],"timestamp":1756900991829,"update_id":50199790,"fetch_time":1756900991877}
{"symbol":"TONUSDT","bids":[],"asks":[["3.1547","2378.9"],["3.1548","2380.4"]],"timestamp":1756900991869,"update_id":50199791,"fetch_time":1756900991917}
{"symbol":"TONUSDT","bids":[],"asks":[["3.1547","1111.3"],["3.1548","3648.0"]],"timestamp":1756900992030,"update_id":50199792,"fetch_time":1756900992075}
{"symbol":"TONUSDT","bids":[],"asks":[["3.1547","2378.9"],["3.1548","2380.4"]],"timestamp":1756900992050,"update_id":50199793,"fetch_time":1756900992099}
{"symbol":"TONUSDT","bids":[],"asks":[["3.1547","1111.3"],["3.1548","3648.0"]],"timestamp":1756900992090,"update_id":50199794,"fetch_time":1756900992139}
{"symbol":"TONUSDT","bids":[],"asks":[["3.1547","2378.9"],["3.1548","2380.4"]],"timestamp":1756900992170,"update_id":50199796,"fetch_time":1756900992219}
{"symbol":"TONUSDT","bids":[],"asks":[["3.1547","1111.3"],["3.1548","3648.0"]],"timestamp":1756900992190,"update_id":50199797,"fetch_time":1756900992235}
{"symbol":"TONUSDT","bids":[],"asks":[["3.1505","1568.5"],["3.1527","1008.6"]],"timestamp":1756900992589,"update_id":50199798,"fetch_time":1756900992635}
{"symbol":"TONUSDT","bids":[["3.1486","1482.5"]],"asks":[],"timestamp":1756900992610,"update_id":50199799,"fetch_time":1756900992659}
{"symbol":"TONUSDT","bids":[],"asks":[["3.1515","1635.1"]],"timestamp":1756900993189,"update_id":50199801,"fetch_time":1756900993239}
{"symbol":"TONUSDT","bids":[],"asks":[["3.1506","245.4"],["3.1510","1735.9"]],"timestamp":1756900993209,"update_id":50199802,"fetch_time":1756900993255}
{"symbol":"TONUSDT","bids":[["3.1495","4.8"]],"asks":[],"timestamp":1756900993230,"update_id":50199803,"fetch_time":1756900993275}
{"symbol":"TONUSDT","bids":[],"asks":[["3.1505","1611.7"],["3.1511","665.2"]],"timestamp":1756900993249,"update_id":50199804,"fetch_time":1756900993299}
{"symbol":"TONUSDT","bids":[["3.1495","44.8"]],"asks":[],"timestamp":1756900993289,"update_id":50199805,"fetch_time":1756900993335}
{"symbol":"TONUSDT","bids":[["3.1478","653.6"]],"asks":[],"timestamp":1756900993629,"update_id":50199806,"fetch_time":1756900993679}
{"symbol":"TONUSDT","bids":[["3.1492","1661.8"]],"asks":[],"timestamp":1756900993670,"update_id":50199808,"fetch_time":1756900993723}
{"symbol":"TONUSDT","bids":[],"asks":[["3.1499","5.0"],["3.1505","1568.5"],["3.1506","202.2"],["3.1507","1086.3"],["3.1508","1045.2"],["3.1509","1139.9"]],"timestamp":1756900993690,"update_id":50199809,"fetch_time":1756900993739}
{"symbol":"TONUSDT","bids":[],"asks":[["3.1507","1129.5"],["3.1508","1088.4"]],"timestamp":1756900993729,"update_id":50199810,"fetch_time":1756900993779}
{"symbol":"TONUSDT","bids":[],"asks":[["3.1502","284.8"]],"timestamp":1756900993750,"update_id":50199811,"fetch_time":1756900993799}
{"symbol":"TONUSDT","bids":[],"asks":[["3.1508","1117.2"],["3.1509","1111.1"],["3.1528","3408.8"],["3.1531","3335.1"]],"timestamp":1756900993810,"update_id":50199812,"fetch_time":1756900993855}
{"symbol":"TONUSDT","bids":[["3.1492","1503.2"]],"asks":[],"timestamp":1756900994050,"update_id":50199813,"fetch_time":1756900994103}
{"symbol":"TONUSDT","bids":[["3.1493","279.2"]],"asks":[],"timestamp":1756900994129,"update_id":50199814,"fetch_time":1756900994180}
{"symbol":"TONUSDT","bids":[["3.1489","694.4"],["3.1488","1636.9"],["3.1487","621.8"],["3.1486","1439.2"],["3.1480","3774.9"],["3.1478","1075.1"],["3.1476","1274.8"]],"asks":[["3.1501","9.3"],["3.1550","0"]],"timestamp":1756900994209,"update_id":50199817,"fetch_time":1756900994256}
{"symbol":"TONUSDT","bids":[],"asks":[["3.1547","2379.0"],["3.1548","2380.4"]],"timestamp":1756900994230,"update_id":50199818,"fetch_time":1756900994280}
{"symbol":"TONUSDT","bids":[["3.1496","7.4"]],"asks":[],"timestamp":1756900994449,"update_id":50199819,"fetch_time":1756900994499}
{"symbol":"TONUSDT","bids":[],"asks":[["3.1506","729.7"]],"timestamp":1756900994570,"update_id":50199820,"fetch_time":1756900994615}
{"symbol":"TONUSDT","bids":[],"asks":[["3.1506","793.1"]],"timestamp":1756900994590,"update_id":50199821,"fetch_time":1756900994635}
{"symbol":"TONUSDT","bids":[["3.1488","1680.2"],["3.1487","665.1"]],"asks":[],"timestamp":1756900994609,"update_id":50199822,"fetch_time":1756900994655}
{"symbol":"TONUSDT","bids":[["3.1490","2039.0"]],"asks":[],"timestamp":1756900994629,"update_id":50199823,"fetch_time":1756900994675}
{"symbol":"TONUSDT","bids":[["3.1495","220.5"],["3.1480","4227.8"]],"asks":[["3.1499","6.0"],["3.1501","0"],["3.1502","297.8"],["3.1509","1422.9"],["3.1550","1943.3"]],"timestamp":1756900994770,"update_id":50199825,"fetch_time":1756900994815}
{"symbol":"TONUSDT","bids":[["3.1491","364.5"],["3.1489","737.7"]],"asks":[],"timestamp":1756900995050,"update_id":50199826,"fetch_time":1756900995099}
{"symbol":"TONUSDT","bids":[["3.1490","2082.3"]],"asks":[],"timestamp":1756900995129,"update_id":50199828,"fetch_time":1756900995175}
{"symbol":"TONUSDT","bids":[["3.1480","3186.2"]],"asks":[],"timestamp":1756900995190,"update_id":50199829,"fetch_time":1756900995235}
{"symbol":"TONUSDT","bids":[["3.1476","2316.4"]],"asks":[],"timestamp":1756900995250,"update_id":50199830,"fetch_time":1756900995295}
{"symbol":"TONUSDT","bids":[],"asks":[["3.1512","3644.5"]],"timestamp":1756900995270,"update_id":50199831,"fetch_time":1756900995319}
{"symbol":"TONUSDT","bids":[["3.1476","1274.8"]],"asks":[],"timestamp":1756900995349,"update_id":50199832,"fetch_time":1756900995395}
{"symbol":"TONUSDT","bids":[["3.1476","2316.4"]],"asks":[],"timestamp":1756900995369,"update_id":50199833,"fetch_time":1756900995415}
{"symbol":"TONUSDT","bids":[["3.1491","407.8"],["3.1480","4227.8"],["3.1476","1274.8"]],"asks":[],"timestamp":1756900995430,"update_id":50199834,"fetch_time":1756900995475}
{"symbol":"TONUSDT","bids":[["3.1492","1430.1"],["3.1491","437.6"],["3.1486","1375.9"],["3.1484","814.6"]],"asks":[],"timestamp":1756900995510,"update_id":50199835,"fetch_time":1756900995556}
{"symbol":"TONUSDT","bids":[],"asks":[["3.1506","1142.1"]],"timestamp":1756900995570,"update_id":50199836,"fetch_time":1756900995619}
{"symbol":"TONUSDT","bids":[],"asks":[["3.1499","7.0"],["3.1503","232.9"],["3.1504","1322.5"]],"timestamp":1756900995730,"update_id":50199837,"fetch_time":1756900995779}
{"symbol":"TONUSDT","bids":[],"asks":[["3.1499","7.9"]],"timestamp":1756900995770,"update_id":50199838,"fetch_time":1756900995815}
{"symbol":"TONUSDT","bids":[],"asks":[["3.1506","1618.2"]],"timestamp":1756900995850,"update_id":50199839,"fetch_time":1756900995899}
{"symbol":"TONUSDT","bids":[],"asks":[["3.1502","284.8"],["3.1503","197.1"],["3.1504","1279.2"]],"timestamp":1756900995869,"update_id":50199840,"fetch_time":1756900995915}
{"symbol":"TONUSDT","bids":[],"asks":[["3.1502","522.9"]],"timestamp":1756900996009,"update_id":50199842,"fetch_time":1756900996055}
{"symbol":"TONUSDT","bids":[],"asks":[["3.1508","1117.2"]],"timestamp":1756900996229,"update_id":50199847,"fetch_time":1756900996275}
{"symbol":"TONUSDT","bids":[],"asks":[["3.1528","3802.9"],["3.1529","997.6"]],"timestamp":1756900996589,"update_id":50199851,"fetch_time":1756900996635}
{"symbol":"TONUSDT","bids":[["3.1458","723.7"]],"asks":[],"timestamp":1756900996610,"update_id":50199852,"fetch_time":1756900996659}
{"symbol":"TONUSDT","bids":[["3.1462","3057.7"],["3.1460","1662.6"]],"asks":[],"timestamp":1756900996630,"update_id":50199853,"fetch_time":1756900996675}
{"symbol":"TONUSDT","bids":[["3.1493","235.9"],["3.1492","1430.1"]],"asks":[],"timestamp":1756900996729,"update_id":50199854,"fetch_time":1756900996779}
{"symbol":"TONUSDT","bids":[["3.1492","1473.4"]],"asks":[],"timestamp":1756900997030,"update_id":50199855,"fetch_time":1756900997075}
{"symbol":"TONUSDT","bids":[],"asks":[["3.1516","3448.7"]],"timestamp":1756900997049,"update_id":50199856,"fetch_time":1756900997095}
{"symbol":"TONUSDT","bids":[],"asks":[["3.1503","161.9"],["3.1509","1154.3"]],"timestamp":1756900997189,"update_id":50199857,"fetch_time":1756900997235}
{"symbol":"TONUSDT","bids":[],"asks":[["3.1509","1362.4"],["3.1510","1477.4"]],"timestamp":1756900997349,"update_id":50199858,"fetch_time":1756900997395}
{"symbol":"TONUSDT","bids":[],"asks":[["3.1502","554.5"]],"timestamp":1756900997490,"update_id":50199860,"fetch_time":1756900997535}
{"symbol":"TONUSDT","bids":[["3.1493","192.7"],["3.1486","1462.4"]],"asks":[],"timestamp":1756900997510,"update_id":50199861,"fetch_time":1756900997555}
{"symbol":"TONUSDT","bids":[["3.1488","1195.4"]],"asks":[],"timestamp":1756900997589,"update_id":50199862,"fetch_time":1756900997639}
{"symbol":"TONUSDT","bids":[["3.1498","0"],["3.1497","0"],["3.1496","145.0"],["3.1493","5.6"],["3.1492","1386.9"],["3.1491","157.3"],["3.1485","1482.7"],["3.1481","2608.0"],["3.1478","1076.9"],["3.1448","11700.4"],["3.1447","822.4"]],"asks":[["3.1499","57.2"],["3.1501","169.2"],["3.1502","570.5"],["3.1505","1831.0"],["3.1507","1280.2"],["3.1509","1733.2"],["3.1511","1148.8"],["3.1512","2844.5"],["3.1513","2878.3"],["3.1515","2387.8"],["3.1518","2898.2"],["3.1520","1790.7"],["3.1522","1555.1"],["3.1524","1059.0"],["3.1526","1112.2"],["3.1528","3050.2"],["3.1550","0"]],"timestamp":1756900997609,"update_id":50199863,"fetch_time":1756900997655}
{"symbol":"TONUSDT","bids":[["3.1496","141.8"],["3.1495","205.2"],["3.1492","497.9"]],"asks":[["3.1501","0"],["3.1522","1221.5"],["3.1524","754.3"],["3.1550","1943.3"]],"timestamp":1756900997629,"update_id":50199864,"fetch_time":1756900997675}
{"symbol":"TONUSDT","bids":[["3.1494","127.9"],["3.1491","344.7"],["3.1487","1120.9"]],"asks":[["3.1501","169.2"],["3.1550","0"]],"timestamp":1756900997650,"update_id":50199865,"fetch_time":1756900997695}
{"symbol":"TONUSDT","bids":[],"asks":[["3.1501","0"],["3.1550","1943.3"]],"timestamp":1756900997670,"update_id":50199866,"fetch_time":1756900997723}
{"symbol":"TONUSDT","bids":[["3.1494","143.6"],["3.1491","314.9"],["3.1488","1252.1"],["3.1484","748.9"]],"asks":[["3.1501","169.2"],["3.1502","554.5"],["3.1503","161.9"],["3.1505","1847.5"],["3.1508","1088.4"],["3.1511","1208.6"],["3.1516","3376.8"],["3.1525","1436.7"],["3.1528","2798.7"],["3.1550","0"]],"timestamp":1756900997690,"update_id":50199867,"fetch_time":1756900997735}
{"symbol":"TONUSDT","bids":[],"asks":[["3.1501","0"],["3.1550","1943.3"]],"timestamp":1756900997709,"update_id":50199868,"fetch_time":1756900997755}
{"symbol":"TONUSDT","bids":[],"asks":[["3.1534","3585.9"]],"timestamp":1756900997810,"update_id":50199872,"fetch_time":1756900997856}
{"symbol":"TONUSDT","bids":[],"asks":[["3.1502","284.8"],["3.1505","1753.3"],["3.1506","1531.7"],["3.1507","1193.7"],["3.1508","1001.9"],["3.1509","1689.9"],["3.1510","1434.1"]],"timestamp":1756900997850,"update_id":50199874,"fetch_time":1756900997895}
{"symbol":"TONUSDT","bids":[["3.1497","20.0"],["3.1496","382.1"],["3.1495","27.8"],["3.1485","1439.5"],["3.1447","0"]],"asks":[],"timestamp":1756900997910,"update_id":50199877,"fetch_time":1756900997959}
{"symbol":"TONUSDT","bids":[["3.1495","10.3"],["3.1491","127.5"]],"asks":[],"timestamp":1756900998010,"update_id":50199879,"fetch_time":1756900998055}
{"symbol":"TONUSDT","bids":[],"asks":[["3.1507","1237.0"],["3.1508","1088.4"]],"timestamp":1756900998129,"update_id":50199880,"fetch_time":1756900998179}
{"symbol":"TONUSDT","bids":[],"asks":[["3.1506","1575.0"],["3.1527","1293.3"],["3.1528","2404.6"]],"timestamp":1756900998150,"update_id":50199881,"fetch_time":1756900998199}
{"symbol":"TONUSDT","bids":[],"asks":[["3.1548","3237.1"],["3.1549","1931.5"]],"timestamp":1756900998229,"update_id":50199883,"fetch_time":1756900998275}
{"symbol":"TONUSDT","bids":[["3.1498","122.9"],["3.1497","258.0"],["3.1496","155.7"],["3.1469","2236.5"],["3.1461","891.7"],["3.1448","0"]],"asks":[["3.1502","3.2"],["3.1503","3.2"],["3.1510","1434.1"],["3.1511","976.5"],["3.1518","3138.3"],["3.1550","3152.1"]],"timestamp":1756900998310,"update_id":50199886,"fetch_time":1756900998359}
{"symbol":"TONUSDT","bids":[["3.1497","238.0"],["3.1495","24.0"],["3.1470","3085.8"]],"asks":[],"timestamp":1756900998330,"update_id":50199887,"fetch_time":1756900998375}
{"symbol":"TONUSDT","bids":[],"asks":[["3.1506","1659.3"]],"timestamp":1756900998389,"update_id":50199890,"fetch_time":1756900998435}
{"symbol":"TONUSDT","bids":[],"asks":[["3.1506","2379.1"]],"timestamp":1756900998430,"update_id":50199892,"fetch_time":1756900998475}
{"symbol":"TONUSDT","bids":[],"asks":[["3.1506","2347.5"]],"timestamp":1756900998449,"update_id":50199893,"fetch_time":1756900998495}
{"symbol":"TONUSDT","bids":[["3.1483","1205.3"]],"asks":[],"timestamp":1756900998469,"update_id":50199894,"fetch_time":1756900998515}
{"symbol":"TONUSDT","bids":[["3.1484","986.8"]],"asks":[],"timestamp":1756900998490,"update_id":50199895,"fetch_time":1756900998535}
{"symbol":"TONUSDT","bids":[],"asks":[["3.1506","1554.1"]],"timestamp":1756900998589,"update_id":50199896,"fetch_time":1756900998635}
{"symbol":"TONUSDT","bids":[],"asks":[["3.1548","4483.8"]],"timestamp":1756900998850,"update_id":50199898,"fetch_time":1756900998899}
{"symbol":"TONUSDT","bids":[],"asks":[["3.1509","1111.1"]],"timestamp":1756900998870,"update_id":50199899,"fetch_time":1756900998916}
{"symbol":"TONUSDT","bids":[],"asks":[["3.1508","987.1"]],"timestamp":1756900998989,"update_id":50199900,"fetch_time":1756900999035}
{"symbol":"TONUSDT","bids":[["3.1484","2028.4"],["3.1480","3642.0"]],"asks":[],"timestamp":1756900999030,"update_id":50199901,"fetch_time":1756900999075}
{"symbol":"TONUSDT","bids":[["3.1497","233.4"],["3.1496","148.8"]],"asks":[],"timestamp":1756900999150,"update_id":50199902,"fetch_time":1756900999199}
{"symbol":"TONUSDT","bids":[["3.1499","1.3"],["3.1449","0"]],"asks":[["3.1499","0"],["3.1551","1012.1"]],"timestamp":1756900999170,"update_id":50199903,"fetch_time":1756900999215}
{"symbol":"TONUSDT","bids":[["3.1500","122.9"],["3.1499","0"],["3.1496","194.4"],["3.1488","1411.3"],["3.1483","405.3"]],"asks":[["3.1502","0"],["3.1503","0"],["3.1506","457.7"],["3.1507","5.6"],["3.1508","1643.8"],["3.1512","2641.6"],["3.1526","1294.4"],["3.1534","3583.9"],["3.1538","1235.8"],["3.1546","2342.3"],["3.1552","3336.7"],["3.1553","579.8"]],"timestamp":1756900999189,"update_id":50199904,"fetch_time":1756900999236}
{"symbol":"TONUSDT","bids":[],"asks":[["3.1509","2401.1"],["3.1519","2069.3"],["3.1521","4263.4"],["3.1546","2797.9"]],"timestamp":1756900999269,"update_id":50199908,"fetch_time":1756900999319}
{"symbol":"TONUSDT","bids":[],"asks":[["3.1508","989.0"],["3.1518","2684.8"]],"timestamp":1756900999289,"update_id":50199909,"fetch_time":1756900999335}
{"symbol":"TONUSDT","bids":[["3.1493","92.1"]],"asks":[],"timestamp":1756900999310,"update_id":50199910,"fetch_time":1756900999355}
{"symbol":"TONUSDT","bids":[],"asks":[["3.1507","48.8"],["3.1509","2444.3"],["3.1510","1477.3"],["3.1511","1019.7"]],"timestamp":1756900999350,"update_id":50199911,"fetch_time":1756900999396}
{"symbol":"TONUSDT","bids":[],"asks":[["3.1527","1190.8"],["3.1531","3306.6"]],"timestamp":1756900999430,"update_id":50199912,"fetch_time":1756900999480}
{"symbol":"TONUSDT","bids":[["3.1487","1877.7"]],"asks":[],"timestamp":1756900999490,"update_id":50199915,"fetch_time":1756900999535}
{"symbol":"TONUSDT","bids":[],"asks":[["3.1504","233.5"],["3.1505","686.7"],["3.1506","57.4"]],"timestamp":1756900999510,"update_id":50199916,"fetch_time":1756900999556}
{"symbol":"TONUSDT","bids":[],"asks":[["3.1509","2412.7"]],"timestamp":1756900999589,"update_id":50199917,"fetch_time":1756900999635}
{"symbol":"TONUSDT","bids":[],"asks":[["3.1509","2219.2"]],"timestamp":1756900999630,"update_id":50199919,"fetch_time":1756900999676}
{"symbol":"TONUSDT","bids":[["3.1493","92.1"]],"asks":[],"timestamp":1756900999690,"update_id":50199921,"fetch_time":1756900999736}
{"symbol":"TONUSDT","bids":[],"asks":[["3.1506","36.8"],["3.1507","48.9"]],"timestamp":1756900999850,"update_id":50199922,"fetch_time":1756900999900}
{"symbol":"TONUSDT","bids":[["3.1488","2543.6"]],"asks":[],"timestamp":1756900999870,"update_id":50199923,"fetch_time":1756900999920}
{"symbol":"TONUSDT","bids":[["3.1494","1826.2"]],"asks":[],"timestamp":1756900999889,"update_id":50199924,"fetch_time":1756900999935}
{"symbol":"TONUSDT","bids":[],"asks":[["3.1506","5.0"],["3.1513","2281.8"]],"timestamp":1756900999910,"update_id":50199925,"fetch_time":1756900999956}
{"symbol":"TONUSDT","bids":[],"asks":[["3.1511","1221.6"],["3.1516","3218.2"]],"timestamp":1756901000070,"update_id":50199926,"fetch_time":1756901000116}
{"symbol":"TONUSDT","bids":[["3.1488","3585.2"],["3.1484","1557.5"]],"asks":[],"timestamp":1756901000090,"update_id":50199927,"fetch_time":1756901000140}
{"symbol":"TONUSDT","bids":[["3.1489","792.8"],["3.1456","1449.5"]],"asks":[],"timestamp":1756901000110,"update_id":50199928,"fetch_time":1756901000156}
{"symbol":"TONUSDT","bids":[["3.1460","2145.7"]],"asks":[],"timestamp":1756901000130,"update_id":50199929,"fetch_time":1756901000175}
{"symbol":"TONUSDT","bids":[],"asks":[["3.1509","2250.8"]],"timestamp":1756901000390,"update_id":50199930,"fetch_time":1756901000436}
{"symbol":"TONUSDT","bids":[["3.1488","3394.2"],["3.1487","1304.7"],["3.1486","1566.6"],["3.1485","823.2"]],"asks":[],"timestamp":1756901000769,"update_id":50199932,"fetch_time":1756901000824}
{"symbol":"TONUSDT","bids":[["3.1488","2894.1"],["3.1480","3833.0"],["3.1479","780.6"]],"asks":[],"timestamp":1756901000790,"update_id":50199933,"fetch_time":1756901000840}
{"symbol":"TONUSDT","bids":[["3.1490","2953.3"]],"asks":[],"timestamp":1756901000949,"update_id":50199934,"fetch_time":1756901000999}
{"symbol":"TONUSDT","bids":[["3.1486","321.7"],["3.1478","1041.5"]],"asks":[],"timestamp":1756901001049,"update_id":50199936,"fetch_time":1756901001095}
{"symbol":"TONUSDT","bids":[["3.1486","603.3"],["3.1481","2766.6"],["3.1478","1232.5"]],"asks":[],"timestamp":1756901001070,"update_id":50199937,"fetch_time":1756901001120}
{"symbol":"TONUSDT","bids":[["3.1489","694.5"],["3.1450","6069.6"]],"asks":[],"timestamp":1756901001109,"update_id":50199938,"fetch_time":1756901001156}
{"symbol":"TONUSDT","bids":[["3.1491","89.7"]],"asks":[],"timestamp":1756901001190,"update_id":50199939,"fetch_time":1756901001235}
{"symbol":"TONUSDT","bids":[["3.1487","504.7"]],"asks":[["3.1502","28.8"],["3.1503","140.0"],["3.1508","1270.5"],["3.1512","2930.3"],["3.1515","1823.3"],["3.1519","2370.4"],["3.1523","3356.6"],["3.1527","1717.7"],["3.1531","3946.4"],["3.1535","1520.2"],["3.1538","1235.8"],["3.1539","1993.5"],["3.1540","1240.1"],["3.1542","1714.7"],["3.1544","4185.9"],["3.1546","1815.4"],["3.1548","3844.0"],["3.1550","2399.4"],["3.1552","0"],["3.1553","0"]],"timestamp":1756901001210,"update_id":50199940,"fetch_time":1756901001259}
{"symbol":"TONUSDT","bids":[],"asks":[["3.1503","0"],["3.1505","763.5"],["3.1507","1091.2"],["3.1552","3336.7"]],"timestamp":1756901001269,"update_id":50199943,"fetch_time":1756901001315}
{"symbol":"TONUSDT","bids":[],"asks":[["3.1508","2328.1"]],"timestamp":1756901001309,"update_id":50199944,"fetch_time":1756901001355}
{"symbol":"TONUSDT","bids":[],"asks":[["3.1508","2046.6"],["3.1509","1594.3"]],"timestamp":1756901001330,"update_id":50199945,"fetch_time":1756901001379}
{"symbol":"TONUSDT","bids":[],"asks":[["3.1509","1249.3"]],"timestamp":1756901001350,"update_id":50199946,"fetch_time":1756901001395}
{"symbol":"TONUSDT","bids":[["3.1480","4024.0"]],"asks":[],"timestamp":1756901001370,"update_id":50199947,"fetch_time":1756901001415}
{"symbol":"TONUSDT","bids":[],"asks":[["3.1504","242.3"],["3.1548","5111.6"],["3.1549","663.9"]],"timestamp":1756901001730,"update_id":50199948,"fetch_time":1756901001775}
{"symbol":"TONUSDT","bids":[["3.1495","892.5"],["3.1493","48.8"],["3.1492","1601.0"],["3.1491","46.4"],["3.1490","2366.0"],["3.1489","651.2"],["3.1488","1529.3"],["3.1487","743.0"],["3.1486","560.0"]],"asks":[["3.1503","7.4"],["3.1504","253.0"],["3.1547","2379.0"],["3.1548","3237.1"],["3.1552","0"]],"timestamp":1756901001769,"update_id":50199950,"fetch_time":1756901001819}
{"symbol":"TONUSDT","bids":[],"asks":[["3.1508","1736.3"],["3.1509","1445.8"]],"timestamp":1756901001810,"update_id":50199952,"fetch_time":1756901001855}
{"symbol":"TONUSDT","bids":[],"asks":[["3.1547","1111.3"],["3.1548","4504.7"]],"timestamp":1756901001829,"update_id":50199953,"fetch_time":1756901001875}
{"symbol":"TONUSDT","bids":[["3.1478","1423.5"]],"asks":[],"timestamp":1756901001970,"update_id":50199954,"fetch_time":1756901002024}
{"symbol":"TONUSDT","bids":[["3.1488","1920.2"]],"asks":[],"timestamp":1756901001990,"update_id":50199955,"fetch_time":1756901002039}
{"symbol":"TONUSDT","bids":[["3.1487","901.6"],["3.1481","2608.0"]],"asks":[],"timestamp":1756901002050,"update_id":50199956,"fetch_time":1756901002095}
{"symbol":"TONUSDT","bids":[["3.1492","1435.9"],["3.1490","1694.7"]],"asks":[],"timestamp":1756901002309,"update_id":50199957,"fetch_time":1756901002355}
{"symbol":"TONUSDT","bids":[["3.1496","459.9"],["3.1495","623.2"],["3.1493","92.1"],["3.1492","1479.2"],["3.1491","89.7"],["3.1490","1781.2"]],"asks":[["3.1503","0"],["3.1504","231.2"],["3.1505","677.0"],["3.1506","677.1"],["3.1507","1007.5"],["3.1508","1649.8"],["3.1509","1162.8"],["3.1510","1630.6"],["3.1548","3237.1"],["3.1549","1931.5"],["3.1552","3336.7"]],"timestamp":1756901002430,"update_id":50199958,"fetch_time":1756901002475}
{"symbol":"TONUSDT","bids":[["3.1497","164.3"],["3.1496","494.0"]],"asks":[],"timestamp":1756901002449,"update_id":50199959,"fetch_time":1756901002495}
{"symbol":"TONUSDT","bids":[],"asks":[["3.1548","4504.7"],["3.1549","663.9"]],"timestamp":1756901002469,"update_id":50199960,"fetch_time":1756901002519}
{"symbol":"TONUSDT","bids":[],"asks":[["3.1509","1131.2"]],"timestamp":1756901002509,"update_id":50199961,"fetch_time":1756901002555}
{"symbol":"TONUSDT","bids":[["3.1483","590.6"]],"asks":[],"timestamp":1756901002650,"update_id":50199964,"fetch_time":1756901002699}
{"symbol":"TONUSDT","bids":[],"asks":[["3.1505","740.1"]],"timestamp":1756901002710,"update_id":50199966,"fetch_time":1756901002755}
{"symbol":"TONUSDT","bids":[["3.1481","2799.0"]],"asks":[],"timestamp":1756901002889,"update_id":50199967,"fetch_time":1756901002935}
{"symbol":"TONUSDT","bids":[["3.1500","0"],["3.1449","2843.4"]],"asks":[],"timestamp":1756901002910,"update_id":50199968,"fetch_time":1756901002955}
{"symbol":"TONUSDT","bids":[["3.1497","138.0"],["3.1495","435.7"],["3.1494","566.0"],["3.1493","279.7"],["3.1456","1610.5"]],"asks":[],"timestamp":1756901002929,"update_id":50199969,"fetch_time":1756901002975}
{"symbol":"TONUSDT","bids":[["3.1480","4215.0"]],"asks":[],"timestamp":1756901002970,"update_id":50199971,"fetch_time":1756901003015}
{"symbol":"TONUSDT","bids":[],"asks":[["3.1505","964.3"]],"timestamp":1756901003009,"update_id":50199973,"fetch_time":1756901003055}
{"symbol":"TONUSDT","bids":[["3.1479","804.8"]],"asks":[],"timestamp":1756901003050,"update_id":50199974,"fetch_time":1756901003095}
{"symbol":"TONUSDT","bids":[["3.1487","778.3"],["3.1483","749.2"]],"asks":[],"timestamp":1756901003070,"update_id":50199975,"fetch_time":1756901003120}
{"symbol":"TONUSDT","bids":[],"asks":[["3.1505","933.0"]],"timestamp":1756901003089,"update_id":50199976,"fetch_time":1756901003135}
{"symbol":"TONUSDT","bids":[["3.1496","483.0"]],"asks":[],"timestamp":1756901003130,"update_id":50199977,"fetch_time":1756901003175}
{"symbol":"TONUSDT","bids":[["3.1479","995.8"]],"asks":[],"timestamp":1756901003210,"update_id":50199978,"fetch_time":1756901003255}
{"symbol":"TONUSDT","bids":[],"asks":[["3.1504","245.4"]],"timestamp":1756901003329,"update_id":50199980,"fetch_time":1756901003375}
{"symbol":"TONUSDT","bids":[],"asks":[["3.1504","260.3"],["3.1512","2843.8"]],"timestamp":1756901003369,"update_id":50199981,"fetch_time":1756901003416}
{"symbol":"TONUSDT","bids":[["3.1480","4406.0"]],"asks":[],"timestamp":1756901003530,"update_id":50199982,"fetch_time":1756901003575}
{"symbol":"TONUSDT","bids":[["3.1493","279.7"]],"asks":[],"timestamp":1756901003630,"update_id":50199984,"fetch_time":1756901003675}
{"symbol":"TONUSDT","bids":[["3.1501","160.0"],["3.1488","865.1"],["3.1484","1509.7"],["3.1449","0"]],"asks":[["3.1502","0"],["3.1528","2690.7"],["3.1531","3545.9"],["3.1553","579.8"]],"timestamp":1756901003829,"update_id":50199990,"fetch_time":1756901003879}
{"symbol":"TONUSDT","bids":[],"asks":[["3.1510","1705.6"]],"timestamp":1756901003929,"update_id":50199995,"fetch_time":1756901003975}
{"symbol":"TONUSDT","bids":[["3.1493","92.1"]],"asks":[],"timestamp":1756901003949,"update_id":50199996,"fetch_time":1756901003995}
{"symbol":"TONUSDT","bids":[["3.1490","2022.1"]],"asks":[],"timestamp":1756901004009,"update_id":50199999,"fetch_time":1756901004055}
{"symbol":"TONUSDT","bids":[],"asks":[["3.1508","48.2"],["3.1509","2113.3"],["3.1511","867.0"],["3.1512","2728.1"]],"timestamp":1756901004050,"update_id":50200000,"fetch_time":1756901004100}
{"symbol":"TONUSDT","bids":[],"asks":[["3.1510","1748.9"]],"timestamp":1756901004090,"update_id":50200002,"fetch_time":1756901004135}
{"symbol":"TONUSDT","bids":[["3.1497","45.5"],["3.1488","1024.2"]],"asks":[],"timestamp":1756901004410,"update_id":50200004,"fetch_time":1756901004455}
{"symbol":"TONUSDT","bids":[],"asks":[["3.1509","2156.6"]],"timestamp":1756901004569,"update_id":50200005,"fetch_time":1756901004615}
{"symbol":"TONUSDT","bids":[["3.1480","4227.5"],["3.1478","1413.2"]],"asks":[],"timestamp":1756901004829,"update_id":50200006,"fetch_time":1756901004875}
{"symbol":"TONUSDT","bids":[["3.1486","719.7"]],"asks":[],"timestamp":1756901004850,"update_id":50200007,"fetch_time":1756901004895}
{"symbol":"TONUSDT","bids":[],"asks":[["3.1535","1074.7"]],"timestamp":1756901005089,"update_id":50200008,"fetch_time":1756901005135}
{"symbol":"TONUSDT","bids":[],"asks":[["3.1518","3074.8"]],"timestamp":1756901005110,"update_id":50200009,"fetch_time":1756901005155}
{"symbol":"TONUSDT","bids":[["3.1502","122.9"],["3.1499","12.2"],["3.1498","735.5"],["3.1489","1821.2"],["3.1487","743.0"],["3.1482","2826.3"],["3.1480","4236.3"],["3.1477","530.9"],["3.1476","1249.6"],["3.1451","0"],["3.1450","0"]],"asks":[["3.1508","971.0"],["3.1509","2070.1"],["3.1510","1662.4"],["3.1511","823.7"],["3.1512","2901.9"],["3.1513","2281.7"],["3.1515","1288.5"],["3.1517","1844.5"]],"timestamp":1756901005170,"update_id":50200010,"fetch_time":1756901005215}
{"symbol":"TONUSDT","bids":[["3.1502","0"],["3.1496","1093.0"],["3.1451","5215.1"]],"asks":[["3.1539","1995.5"],["3.1542","854.4"]],"timestamp":1756901005250,"update_id":50200014,"fetch_time":1756901005295}
{"symbol":"TONUSDT","bids":[["3.1497","45.5"]],"asks":[],"timestamp":1756901005269,"update_id":50200015,"fetch_time":1756901005315}
{"symbol":"TONUSDT","bids":[["3.1498","462.0"]],"asks":[],"timestamp":1756901005289,"update_id":50200016,"fetch_time":1756901005335}
{"symbol":"TONUSDT","bids":[["3.1496","1280.7"]],"asks":[],"timestamp":1756901005310,"update_id":50200017,"fetch_time":1756901005355}
{"symbol":"TONUSDT","bids":[["3.1460","3951.5"],["3.1459","2006.7"]],"asks":[],"timestamp":1756901005369,"update_id":50200020,"fetch_time":1756901005420}
{"symbol":"TONUSDT","bids":[["3.1462","1713.5"],["3.1460","3468.4"]],"asks":[],"timestamp":1756901005390,"update_id":50200021,"fetch_time":1756901005435}
{"symbol":"TONUSDT","bids":[],"asks":[["3.1510","1705.7"],["3.1511","867.0"]],"timestamp":1756901005489,"update_id":50200022,"fetch_time":1756901005535}
{"symbol":"TONUSDT","bids":[],"asks":[["3.1511","867.0"],["3.1512","2728.1"]],"timestamp":1756901005730,"update_id":50200024,"fetch_time":1756901005779}
{"symbol":"TONUSDT","bids":[["3.1498","751.5"],["3.1496","1401.8"],["3.1493","342.0"],["3.1492","1463.7"]],"asks":[],"timestamp":1756901005869,"update_id":50200026,"fetch_time":1756901005915}
{"symbol":"TONUSDT","bids":[["3.1499","136.6"]],"asks":[],"timestamp":1756901005889,"update_id":50200027,"fetch_time":1756901005939}
{"symbol":"TONUSDT","bids":[],"asks":[["3.1508","1014.2"]],"timestamp":1756901005949,"update_id":50200028,"fetch_time":1756901005995}
{"symbol":"TONUSDT","bids":[],"asks":[["3.1508","1057.5"]],"timestamp":1756901005970,"update_id":50200029,"fetch_time":1756901006019}
{"symbol":"TONUSDT","bids":[],"asks":[["3.1507","48.9"]],"timestamp":1756901006010,"update_id":50200030,"fetch_time":1756901006055}
{"symbol":"TONUSDT","bids":[],"asks":[["3.1507","5.6"],["3.1513","2542.1"]],"timestamp":1756901006389,"update_id":50200034,"fetch_time":1756901006435}
{"symbol":"TONUSDT","bids":[["3.1501","133.9"],["3.1499","148.8"]],"asks":[],"timestamp":1756901006410,"update_id":50200035,"fetch_time":1756901006456}
{"symbol":"TONUSDT","bids":[["3.1489","1692.8"]],"asks":[],"timestamp":1756901006429,"update_id":50200036,"fetch_time":1756901006475}
{"symbol":"TONUSDT","bids":[],"asks":[["3.1521","3277.2"]],"timestamp":1756901006549,"update_id":50200038,"fetch_time":1756901006595}
{"symbol":"TONUSDT","bids":[["3.1483","654.1"]],"asks":[],"timestamp":1756901006570,"update_id":50200039,"fetch_time":1756901006615}
{"symbol":"TONUSDT","bids":[["3.1481","2735.5"]],"asks":[],"timestamp":1756901006749,"update_id":50200040,"fetch_time":1756901006795}
{"symbol":"TONUSDT","bids":[["3.1485","1089.4"]],"asks":[],"timestamp":1756901006790,"update_id":50200041,"fetch_time":1756901006835}
{"symbol":"TONUSDT","bids":[],"asks":[["3.1509","2156.6"],["3.1518","2233.1"]],"timestamp":1756901006829,"update_id":50200043,"fetch_time":1756901006879}
{"symbol":"TONUSDT","bids":[],"asks":[["3.1516","2614.3"]],"timestamp":1756901006849,"update_id":50200044,"fetch_time":1756901006895}
{"symbol":"TONUSDT","bids":[["3.1480","3973.0"]],"asks":[],"timestamp":1756901006890,"update_id":50200045,"fetch_time":1756901006987}
{"symbol":"TONUSDT","bids":[["3.1498","761.8"]],"asks":[],"timestamp":1756901006909,"update_id":50200046,"fetch_time":1756901006999}
{"symbol":"TONUSDT","bids":[["3.1499","148.8"]],"asks":[],"timestamp":1756901006930,"update_id":50200047,"fetch_time":1756901007003}
{"symbol":"TONUSDT","bids":[["3.1477","526.8"]],"asks":[],"timestamp":1756901006950,"update_id":50200048,"fetch_time":1756901007011}
{"symbol":"TONUSDT","bids":[],"asks":[["3.1504","3.9"]],"timestamp":1756901006990,"update_id":50200049,"fetch_time":1756901007035}
{"symbol":"TONUSDT","bids":[["3.1485","1093.5"]],"asks":[],"timestamp":1756901007009,"update_id":50200050,"fetch_time":1756901007054}
{"symbol":"TONUSDT","bids":[],"asks":[["3.1543","1071.7"]],"timestamp":1756901007230,"update_id":50200052,"fetch_time":1756901007278}
{"symbol":"TONUSDT","bids":[],"asks":[["3.1507","5.6"]],"timestamp":1756901007290,"update_id":50200053,"fetch_time":1756901007338}
{"symbol":"TONUSDT","bids":[],"asks":[["3.1507","48.9"]],"timestamp":1756901007650,"update_id":50200054,"fetch_time":1756901007698}
{"symbol":"TONUSDT","bids":[],"asks":[["3.1520","2711.7"]],"timestamp":1756901007770,"update_id":50200057,"fetch_time":1756901007818}
{"symbol":"TONUSDT","bids":[],"asks":[["3.1512","2917.5"]],"timestamp":1756901007809,"update_id":50200059,"fetch_time":1756901007859}
{"symbol":"TONUSDT","bids":[],"asks":[["3.1522","2207.7"]],"timestamp":1756901007830,"update_id":50200060,"fetch_time":1756901007874}
{"symbol":"TONUSDT","bids":[["3.1497","56.9"]],"asks":[],"timestamp":1756901008011,"update_id":50200061,"fetch_time":1756901008058}
{"symbol":"TONUSDT","bids":[["3.1485","1284.5"]],"asks":[],"timestamp":1756901008029,"update_id":50200062,"fetch_time":1756901008078}
{"symbol":"TONUSDT","bids":[["3.1486","881.8"],["3.1480","3782.0"]],"asks":[],"timestamp":1756901008049,"update_id":50200063,"fetch_time":1756901008094}
{"symbol":"TONUSDT","bids":[["3.1497","46.4"],["3.1496","1378.5"]],"asks":[],"timestamp":1756901008070,"update_id":50200064,"fetch_time":1756901008114}
{"symbol":"TONUSDT","bids":[],"asks":[["3.1550","4193.8"],["3.1551","1012.1"]],"timestamp":1756901008250,"update_id":50200066,"fetch_time":1756901008298}
{"symbol":"TONUSDT","bids":[],"asks":[["3.1506","5.0"],["3.1507","5.6"],["3.1508","1014.3"],["3.1550","2926.3"],["3.1551","2279.6"]],"timestamp":1756901008269,"update_id":50200067,"fetch_time":1756901008314}
{"symbol":"TONUSDT","bids":[["3.1499","148.8"]],"asks":[],"timestamp":1756901008310,"update_id":50200069,"fetch_time":1756901008358}
{"symbol":"TONUSDT","bids":[["3.1496","1421.8"],["3.1490","1935.6"]],"asks":[],"timestamp":1756901008389,"update_id":50200070,"fetch_time":1756901008434}
{"symbol":"TONUSDT","bids":[["3.1499","136.6"],["3.1498","735.8"],["3.1497","3.2"]],"asks":[],"timestamp":1756901008949,"update_id":50200071,"fetch_time":1756901008998}
{"symbol":"TONUSDT","bids":[["3.1484","812.0"]],"asks":[],"timestamp":1756901008970,"update_id":50200072,"fetch_time":1756901009018}
{"symbol":"TONUSDT","bids":[["3.1486","1040.4"],["3.1482","2826.3"]],"asks":[],"timestamp":1756901009129,"update_id":50200073,"fetch_time":1756901009174}
{"symbol":"TONUSDT","bids":[],"asks":[["3.1507","48.9"]],"timestamp":1756901009150,"update_id":50200074,"fetch_time":1756901009202}
{"symbol":"TONUSDT","bids":[],"asks":[["3.1508","1057.5"]],"timestamp":1756901009309,"update_id":50200075,"fetch_time":1756901009355}
{"symbol":"TONUSDT","bids":[["3.1501","0"],["3.1450","6069.6"]],"asks":[["3.1504","266.8"],["3.1506","32.8"],["3.1507","92.1"]],"timestamp":1756901009589,"update_id":50200076,"fetch_time":1756901009634}
{"symbol":"TONUSDT","bids":[],"asks":[["3.1504","126.8"]],"timestamp":1756901009650,"update_id":50200079,"fetch_time":1756901009694}
{"symbol":"TONUSDT","bids":[],"asks":[["3.1506","270.8"]],"timestamp":1756901010010,"update_id":50200080,"fetch_time":1756901010062}
{"symbol":"TONUSDT","bids":[],"asks":[["3.1535","767.5"],["3.1538","1315.1"]],"timestamp":1756901010029,"update_id":50200081,"fetch_time":1756901010074}
{"symbol":"TONUSDT","bids":[["3.1499","124.9"],["3.1497","3.2"],["3.1496","311.8"],["3.1490","2137.4"]],"asks":[],"timestamp":1756901010130,"update_id":50200083,"fetch_time":1756901010182}
{"symbol":"TONUSDT","bids":[["3.1498","417.7"]],"asks":[],"timestamp":1756901010149,"update_id":50200084,"fetch_time":1756901010198}
{"symbol":"TONUSDT","bids":[],"asks":[["3.1517","2906.4"]],"timestamp":1756901010329,"update_id":50200087,"fetch_time":1756901010374}
{"symbol":"TONUSDT","bids":[],"asks":[["3.1516","3179.1"]],"timestamp":1756901010350,"update_id":50200088,"fetch_time":1756901010398}
{"symbol":"TONUSDT","bids":[],"asks":[["3.1509","2209.5"]],"timestamp":1756901010410,"update_id":50200089,"fetch_time":1756901010458}
{"symbol":"TONUSDT","bids":[["3.1492","1463.7"]],"asks":[],"timestamp":1756901010429,"update_id":50200090,"fetch_time":1756901010474}
{"symbol":"TONUSDT","bids":[["3.1496","375.3"]],"asks":[],"timestamp":1756901010550,"update_id":50200092,"fetch_time":1756901010598}
{"symbol":"TONUSDT","bids":[],"asks":[["3.1506","281.2"],["3.1514","3911.4"]],"timestamp":1756901010570,"update_id":50200093,"fetch_time":1756901010614}
{"symbol":"TONUSDT","bids":[["3.1488","980.4"]],"asks":[],"timestamp":1756901010629,"update_id":50200095,"fetch_time":1756901010674}
{"symbol":"TONUSDT","bids":[["3.1490","2148.4"]],"asks":[],"timestamp":1756901010889,"update_id":50200098,"fetch_time":1756901010942}
{"symbol":"TONUSDT","bids":[["3.1482","3017.3"]],"asks":[],"timestamp":1756901010969,"update_id":50200099,"fetch_time":1756901011019}
{"symbol":"TONUSDT","bids":[["3.1496","273.8"],["3.1494","889.2"],["3.1493","92.1"],["3.1491","608.4"]],"asks":[],"timestamp":1756901011030,"update_id":50200100,"fetch_time":1756901011079}
{"symbol":"TONUSDT","bids":[["3.1495","239.6"]],"asks":[],"timestamp":1756901011050,"update_id":50200101,"fetch_time":1756901011103}
{"symbol":"TONUSDT","bids":[["3.1478","1220.4"]],"asks":[],"timestamp":1756901011090,"update_id":50200103,"fetch_time":1756901011134}
{"symbol":"TONUSDT","bids":[["3.1494","992.2"],["3.1492","1733.0"]],"asks":[],"timestamp":1756901011369,"update_id":50200104,"fetch_time":1756901011414}
{"symbol":"TONUSDT","bids":[["3.1483","845.1"]],"asks":[],"timestamp":1756901011570,"update_id":50200105,"fetch_time":1756901011618}
{"symbol":"TONUSDT","bids":[["3.1478","1029.4"]],"asks":[],"timestamp":1756901011649,"update_id":50200106,"fetch_time":1756901011694}
{"symbol":"TONUSDT","bids":[],"asks":[["3.1503","140.0"],["3.1553","0"]],"timestamp":1756901011729,"update_id":50200107,"fetch_time":1756901011778}
{"symbol":"TONUSDT","bids":[["3.1498","417.7"],["3.1497","3.2"],["3.1496","187.3"],["3.1495","153.1"],["3.1491","651.6"],["3.1490","2076.3"],["3.1486","881.8"]],"asks":[["3.1502","28.8"],["3.1506","286.2"],["3.1508","1332.6"],["3.1512","3062.5"],["3.1517","1844.5"],["3.1520","1790.7"],["3.1537","2222.3"],["3.1539","1993.5"],["3.1546","1815.4"],["3.1550","3667.0"],["3.1551","1012.1"],["3.1552","0"]],"timestamp":1756901011749,"update_id":50200108,"fetch_time":1756901011794}
{"symbol":"TONUSDT","bids":[["3.1499","0"],["3.1494","1150.9"],["3.1488","821.9"],["3.1449","2843.4"]],"asks":[["3.1503","0"],["3.1504","156.2"],["3.1505","695.3"],["3.1506","329.5"],["3.1507","437.5"],["3.1508","1788.2"],["3.1512","3019.2"],["3.1544","2642.0"],["3.1548","4885.7"],["3.1552","3336.7"]],"timestamp":1756901011769,"update_id":50200109,"fetch_time":1756901011814}
{"symbol":"TONUSDT","bids":[],"asks":[["3.1505","741.0"],["3.1507","1095.1"],["3.1508","2279.3"],["3.1509","1743.1"]],"timestamp":1756901011810,"update_id":50200111,"fetch_time":1756901011854}
{"symbol":"TONUSDT","bids":[["3.1496","211.6"],["3.1495","196.3"],["3.1493","280.0"]],"asks":[],"timestamp":1756901011849,"update_id":50200113,"fetch_time":1756901011898}
{"symbol":"TONUSDT","bids":[["3.1497","296.1"],["3.1496","233.5"],["3.1480","3591.0"]],"asks":[],"timestamp":1756901011929,"update_id":50200117,"fetch_time":1756901011974}
{"symbol":"TONUSDT","bids":[],"asks":[["3.1506","48.3"]],"timestamp":1756901011950,"update_id":50200118,"fetch_time":1756901011998}
{"symbol":"TONUSDT","bids":[["3.1484","1194.0"]],"asks":[],"timestamp":1756901011970,"update_id":50200119,"fetch_time":1756901012018}
{"symbol":"TONUSDT","bids":[["3.1481","2544.5"]],"asks":[],"timestamp":1756901011989,"update_id":50200120,"fetch_time":1756901012034}
{"symbol":"TONUSDT","bids":[["3.1480","3400.0"]],"asks":[],"timestamp":1756901012010,"update_id":50200121,"fetch_time":1756901012054}
{"symbol":"TONUSDT","bids":[["3.1498","148.5"],["3.1497","284.1"],["3.1496","209.2"],["3.1489","1915.4"],["3.1483","1036.1"]],"asks":[],"timestamp":1756901012050,"update_id":50200122,"fetch_time":1756901012098}
{"symbol":"TONUSDT","bids":[["3.1479","613.8"]],"asks":[],"timestamp":1756901012110,"update_id":50200123,"fetch_time":1756901012158}
{"symbol":"TONUSDT","bids":[["3.1483","1227.1"],["3.1449","2652.4"]],"asks":[],"timestamp":1756901012210,"update_id":50200125,"fetch_time":1756901012258}
{"symbol":"TONUSDT","bids":[["3.1496","184.7"]],"asks":[],"timestamp":1756901012250,"update_id":50200127,"fetch_time":1756901012302}
{"symbol":"TONUSDT","bids":[],"asks":[["3.1516","2614.3"],["3.1536","5750.6"]],"timestamp":1756901012330,"update_id":50200130,"fetch_time":1756901012378}
{"symbol":"TONUSDT","bids":[["3.1480","2947.1"]],"asks":[],"timestamp":1756901012369,"update_id":50200132,"fetch_time":1756901012418}
{"symbol":"TONUSDT","bids":[["3.1497","91.3"],["3.1496","233.5"],["3.1484","1400.9"]],"asks":[],"timestamp":1756901012429,"update_id":50200133,"fetch_time":1756901012478}
{"symbol":"TONUSDT","bids":[["3.1496","209.2"]],"asks":[],"timestamp":1756901012589,"update_id":50200135,"fetch_time":1756901012638}
{"symbol":"TONUSDT","bids":[["3.1498","207.4"],["3.1497","91.3"],["3.1496","221.5"]],"asks":[["3.1502","0"],["3.1504","124.4"],["3.1506","5.0"],["3.1508","1016.5"],["3.1509","1111.0"],["3.1510","1635.9"],["3.1511","621.9"],["3.1553","579.8"]],"timestamp":1756901012929,"update_id":50200136,"fetch_time":1756901012979}
{"symbol":"TONUSDT","bids":[],"asks":[["3.1509","1443.7"]],"timestamp":1756901012969,"update_id":50200138,"fetch_time":1756901013014}
{"symbol":"TONUSDT","bids":[],"asks":[["3.1507","3.2"],["3.1509","1725.8"],["3.1546","2271.0"]],"timestamp":1756901012989,"update_id":50200139,"fetch_time":1756901013038}
{"symbol":"TONUSDT","bids":[],"asks":[["3.1508","26.6"],["3.1509","2007.7"],["3.1512","962.5"],["3.1514","4300.5"]],"timestamp":1756901013010,"update_id":50200140,"fetch_time":1756901013063}
{"symbol":"TONUSDT","bids":[],"asks":[["3.1509","2071.1"],["3.1550","2399.4"],["3.1551","2279.6"]],"timestamp":1756901013029,"update_id":50200141,"fetch_time":1756901013078}
{"symbol":"TONUSDT","bids":[],"asks":[["3.1548","4504.7"]],"timestamp":1756901013049,"update_id":50200142,"fetch_time":1756901013094}
{"symbol":"TONUSDT","bids":[],"asks":[["3.1512","2698.3"],["3.1536","5334.1"]],"timestamp":1756901013069,"update_id":50200143,"fetch_time":1756901013114}
{"symbol":"TONUSDT","bids":[],"asks":[["3.1521","2325.1"],["3.1523","3712.5"]],"timestamp":1756901013110,"update_id":50200144,"fetch_time":1756901013162}
{"symbol":"TONUSDT","bids":[["3.1499","67.5"],["3.1498","207.4"],["3.1449","0"]],"asks":[["3.1508","766.5"],["3.1510","1223.7"]],"timestamp":1756901013130,"update_id":50200145,"fetch_time":1756901013178}
{"symbol":"TONUSDT","bids":[],"asks":[["3.1509","2114.3"],["3.1511","665.1"]],"timestamp":1756901013169,"update_id":50200147,"fetch_time":1756901013214}
{"symbol":"TONUSDT","bids":[["3.1493","92.1"]],"asks":[],"timestamp":1756901013209,"update_id":50200148,"fetch_time":1756901013254}
{"symbol":"TONUSDT","bids":[["3.1499","70.8"],["3.1498","221.4"],["3.1497","128.4"],["3.1490","1989.8"],["3.1489","1958.2"]],"asks":[],"timestamp":1756901013310,"update_id":50200149,"fetch_time":1756901013358}
{"symbol":"TONUSDT","bids":[],"asks":[["3.1551","2279.6"]],"timestamp":1756901013410,"update_id":50200153,"fetch_time":1756901013458}
{"symbol":"TONUSDT","bids":[["3.1480","3266.9"]],"asks":[],"timestamp":1756901013429,"update_id":50200154,"fetch_time":1756901013474}
{"symbol":"TONUSDT","bids":[],"asks":[["3.1513","2507.4"],["3.1514","3983.3"]],"timestamp":1756901013629,"update_id":50200155,"fetch_time":1756901013678}
{"symbol":"TONUSDT","bids":[],"asks":[["3.1508","26.6"]],"timestamp":1756901013669,"update_id":50200156,"fetch_time":1756901013714}
{"symbol":"TONUSDT","bids":[],"asks":[["3.1533","496.3"]],"timestamp":1756901013749,"update_id":50200160,"fetch_time":1756901013798}
{"symbol":"TONUSDT","bids":[],"asks":[["3.1508","832.5"]],"timestamp":1756901013809,"update_id":50200162,"fetch_time":1756901013854}
{"symbol":"TONUSDT","bids":[["3.1476","1522.6"]],"asks":[],"timestamp":1756901013889,"update_id":50200164,"fetch_time":1756901013934}
{"symbol":"TONUSDT","bids":[["3.1498","2.6"]],"asks":[],"timestamp":1756901013950,"update_id":50200166,"fetch_time":1756901013998}
{"symbol":"TONUSDT","bids":[["3.1458","707.9"]],"asks":[],"timestamp":1756901014149,"update_id":50200167,"fetch_time":1756901014194}
{"symbol":"TONUSDT","bids":[["3.1498","16.6"]],"asks":[],"timestamp":1756901014210,"update_id":50200168,"fetch_time":1756901014254}
{"symbol":"TONUSDT","bids":[],"asks":[["3.1509","2071.1"],["3.1510","1482.2"],["3.1511","621.9"]],"timestamp":1756901014229,"update_id":50200169,"fetch_time":1756901014274}
{"symbol":"TONUSDT","bids":[],"asks":[["3.1511","665.2"]],"timestamp":1756901014449,"update_id":50200170,"fetch_time":1756901014494}
{"symbol":"TONUSDT","bids":[],"asks":[["3.1513","2507.4"],["3.1514","3983.3"],["3.1550","3666.9"],["3.1551","1012.1"]],"timestamp":1756901015090,"update_id":50200172,"fetch_time":1756901015138}
{"symbol":"TONUSDT","bids":[["3.1486","1040.4"],["3.1482","3017.3"]],"asks":[],"timestamp":1756901015110,"update_id":50200173,"fetch_time":1756901015158}
{"symbol":"TONUSDT","bids":[],"asks":[["3.1550","2399.4"],["3.1551","2279.6"]],"timestamp":1756901015170,"update_id":50200174,"fetch_time":1756901015222}
{"symbol":"TONUSDT","bids":[["3.1497","128.4"]],"asks":[],"timestamp":1756901015189,"update_id":50200175,"fetch_time":1756901015234}
{"symbol":"TONUSDT","bids":[],"asks":[["3.1550","3666.9"],["3.1551","1012.1"]],"timestamp":1756901015210,"update_id":50200176,"fetch_time":1756901015258}
{"symbol":"TONUSDT","bids":[],"asks":[["3.1550","2399.4"],["3.1551","2279.6"]],"timestamp":1756901015249,"update_id":50200177,"fetch_time":1756901015294}
{"symbol":"TONUSDT","bids":[["3.1496","200.5"]],"asks":[],"timestamp":1756901015949,"update_id":50200180,"fetch_time":1756901015998}
{"symbol":"TONUSDT","bids":[["3.1495","258.2"],["3.1492","1996.9"],["3.1490","2320.8"]],"asks":[],"timestamp":1756901016109,"update_id":50200181,"fetch_time":1756901016158}
{"symbol":"TONUSDT","bids":[["3.1492","2170.8"]],"asks":[],"timestamp":1756901016129,"update_id":50200182,"fetch_time":1756901016174}
{"symbol":"TONUSDT","bids":[["3.1489","1955.4"]],"asks":[],"timestamp":1756901016189,"update_id":50200183,"fetch_time":1756901016234}
{"symbol":"TONUSDT","bids":[],"asks":[["3.1518","3295.0"]],"timestamp":1756901016250,"update_id":50200185,"fetch_time":1756901016294}
{"symbol":"TONUSDT","bids":[],"asks":[["3.1516","2989.5"]],"timestamp":1756901016270,"update_id":50200186,"fetch_time":1756901016318}
{"symbol":"TONUSDT","bids":[["3.1489","1872.2"]],"asks":[],"timestamp":1756901016329,"update_id":50200187,"fetch_time":1756901016374}
{"symbol":"TONUSDT","bids":[["3.1489","1955.4"]],"asks":[],"timestamp":1756901016470,"update_id":50200188,"fetch_time":1756901016518}
{"symbol":"TONUSDT","bids":[["3.1498","293.3"],["3.1497","120.3"]],"asks":[],"timestamp":1756901016490,"update_id":50200189,"fetch_time":1756901016538}
{"symbol":"TONUSDT","bids":[],"asks":[["3.1548","3648.0"],["3.1551","3136.3"]],"timestamp":1756901016950,"update_id":50200190,"fetch_time":1756901016998}
{"symbol":"TONUSDT","bids":[["3.1498","279.3"],["3.1497","106.9"],["3.1496","200.5"]],"asks":[],"timestamp":1756901016969,"update_id":50200191,"fetch_time":1756901017014}
{"symbol":"TONUSDT","bids":[["3.1497","134.3"],["3.1496","237.1"]],"asks":[],"timestamp":1756901017030,"update_id":50200192,"fetch_time":1756901017078}
{"symbol":"TONUSDT","bids":[["3.1489","1955.4"]],"asks":[],"timestamp":1756901017190,"update_id":50200194,"fetch_time":1756901017238}
{"symbol":"TONUSDT","bids":[["3.1498","293.3"],["3.1497","92.7"]],"asks":[],"timestamp":1756901017209,"update_id":50200195,"fetch_time":1756901017254}
{"symbol":"TONUSDT","bids":[],"asks":[["3.1510","1410.1"],["3.1514","4141.9"]],"timestamp":1756901017230,"update_id":50200196,"fetch_time":1756901017282}
{"symbol":"TONUSDT","bids":[],"asks":[["3.1512","2802.9"],["3.1513","2525.4"]],"timestamp":1756901017250,"update_id":50200197,"fetch_time":1756901017298}
{"symbol":"TONUSDT","bids":[["3.1498","164.2"],["3.1497","290.3"],["3.1496","176.0"],["3.1495","258.1"]],"asks":[],"timestamp":1756901017590,"update_id":50200199,"fetch_time":1756901017638}
{"symbol":"TONUSDT","bids":[["3.1496","219.2"]],"asks":[],"timestamp":1756901017610,"update_id":50200200,"fetch_time":1756901017654}
{"symbol":"TONUSDT","bids":[["3.1496","262.5"]],"asks":[],"timestamp":1756901017650,"update_id":50200202,"fetch_time":1756901017694}
{"symbol":"TONUSDT","bids":[["3.1498","164.2"]],"asks":[],"timestamp":1756901017790,"update_id":50200203,"fetch_time":1756901017838}
{"symbol":"TONUSDT","bids":[["3.1497","290.3"],["3.1496","219.3"]],"asks":[],"timestamp":1756901017950,"update_id":50200204,"fetch_time":1756901017998}
{"symbol":"TONUSDT","bids":[],"asks":[["3.1505","674.7"],["3.1506","28.0"]],"timestamp":1756901017970,"update_id":50200205,"fetch_time":1756901018014}
{"symbol":"TONUSDT","bids":[],"asks":[["3.1506","66.2"],["3.1513","2444.7"],["3.1518","3596.1"],["3.1523","4126.5"],["3.1528","2931.5"],["3.1542","553.3"],["3.1547","1111.3"],["3.1552","3336.7"]],"timestamp":1756901017990,"update_id":50200206,"fetch_time":1756901018038}
{"symbol":"TONUSDT","bids":[["3.1498","0"],["3.1449","2652.4"]],"asks":[["3.1504","141.5"]],"timestamp":1756901018169,"update_id":50200207,"fetch_time":1756901018214}
{"symbol":"TONUSDT","bids":[["3.1496","176.0"],["3.1495","214.9"],["3.1494","1064.6"],["3.1493","48.9"],["3.1492","2127.6"],["3.1491","608.4"]],"asks":[["3.1503","48.8"],["3.1504","154.1"],["3.1505","689.9"],["3.1508","1085.6"],["3.1512","3231.0"],["3.1538","1317.1"],["3.1539","1993.5"],["3.1546","1815.4"],["3.1553","0"]],"timestamp":1756901018189,"update_id":50200208,"fetch_time":1756901018238}
{"symbol":"TONUSDT","bids":[],"asks":[["3.1508","1451.1"],["3.1550","3666.9"],["3.1551","1868.8"]],"timestamp":1756901018210,"update_id":50200209,"fetch_time":1756901018258}
{"symbol":"TONUSDT","bids":[],"asks":[["3.1507","440.9"],["3.1509","1969.6"]],"timestamp":1756901018250,"update_id":50200211,"fetch_time":1756901018298}
{"symbol":"TONUSDT","bids":[],"asks":[["3.1509","1687.7"],["3.1511","972.4"]],"timestamp":1756901018289,"update_id":50200213,"fetch_time":1756901018338}
{"symbol":"TONUSDT","bids":[["3.1499","0"],["3.1493","5.6"],["3.1492","2084.3"],["3.1491","565.1"],["3.1448","11349.9"]],"asks":[["3.1503","53.4"]],"timestamp":1756901018309,"update_id":50200214,"fetch_time":1756901018354}
{"symbol":"TONUSDT","bids":[["3.1496","172.8"],["3.1494","876.7"],["3.1493","323.0"],["3.1492","2272.4"],["3.1491","283.4"],["3.1489","830.6"],["3.1485","2441.9"],["3.1478","1031.2"]],"asks":[["3.1502","28.8"],["3.1503","4.6"],["3.1507","974.6"],["3.1509","1154.3"],["3.1531","2906.1"],["3.1532","2136.8"],["3.1537","1667.7"],["3.1538","1315.1"],["3.1552","0"]],"timestamp":1756901018330,"update_id":50200215,"fetch_time":1756901018378}
{"symbol":"TONUSDT","bids":[["3.1499","1.1"],["3.1498","20.0"],["3.1494","1028.7"],["3.1490","1555.6"],["3.1486","1482.7"],["3.1449","0"],["3.1448","0"]],"asks":[["3.1507","1162.8"],["3.1508","2165.0"]],"timestamp":1756901018349,"update_id":50200216,"fetch_time":1756901018398}
{"symbol":"TONUSDT","bids":[["3.1498","0"],["3.1496","176.0"],["3.1478","929.9"],["3.1449","2652.4"]],"asks":[["3.1505","693.1"],["3.1507","1445.1"],["3.1508","2620.6"]],"timestamp":1756901018369,"update_id":50200217,"fetch_time":1756901018414}
{"symbol":"TONUSDT","bids":[],"asks":[["3.1508","1925.2"]],"timestamp":1756901018450,"update_id":50200221,"fetch_time":1756901018494}
{"symbol":"TONUSDT","bids":[],"asks":[["3.1507","1451.4"]],"timestamp":1756901018469,"update_id":50200222,"fetch_time":1756901018519}
{"symbol":"TONUSDT","bids":[],"asks":[["3.1503","0"],["3.1552","3336.7"]],"timestamp":1756901018529,"update_id":50200223,"fetch_time":1756901018579}
{"symbol":"TONUSDT","bids":[],"asks":[["3.1508","1925.2"],["3.1512","3225.4"]],"timestamp":1756901019030,"update_id":50200226,"fetch_time":1756901019082}
{"symbol":"TONUSDT","bids":[],"asks":[["3.1506","207.0"],["3.1507","1451.4"]],"timestamp":1756901019070,"update_id":50200227,"fetch_time":1756901019118}
{"symbol":"TONUSDT","bids":[],"asks":[["3.1510","1568.7"],["3.1514","3983.3"]],"timestamp":1756901019089,"update_id":50200228,"fetch_time":1756901019134}
{"symbol":"TONUSDT","bids":[["3.1497","310.3"]],"asks":[],"timestamp":1756901019469,"update_id":50200231,"fetch_time":1756901019514}
{"symbol":"TONUSDT","bids":[["3.1498","145.9"],["3.1449","0"]],"asks":[],"timestamp":1756901019489,"update_id":50200232,"fetch_time":1756901019534}
{"symbol":"TONUSDT","bids":[],"asks":[["3.1550","2399.4"],["3.1551","3136.3"]],"timestamp":1756901019769,"update_id":50200233,"fetch_time":1756901019814}
{"symbol":"TONUSDT","bids":[],"asks":[["3.1505","663.2"],["3.1506","207.0"],["3.1548","3648.0"],["3.1550","3666.9"],["3.1551","1868.8"]],"timestamp":1756901019790,"update_id":50200234,"fetch_time":1756901019838}
{"symbol":"TONUSDT","bids":[],"asks":[["3.1548","4029.0"]],"timestamp":1756901019810,"update_id":50200235,"fetch_time":1756901019858}
{"symbol":"TONUSDT","bids":[],"asks":[["3.1550","2399.4"],["3.1551","3136.3"]],"timestamp":1756901020049,"update_id":50200236,"fetch_time":1756901020094}
{"symbol":"TONUSDT","bids":[],"asks":[["3.1548","3648.0"]],"timestamp":1756901020070,"update_id":50200237,"fetch_time":1756901020118}
{"symbol":"TONUSDT","bids":[["3.1486","1324.1"]],"asks":[],"timestamp":1756901020129,"update_id":50200238,"fetch_time":1756901020174}
{"symbol":"TONUSDT","bids":[["3.1490","1977.4"]],"asks":[],"timestamp":1756901020150,"update_id":50200239,"fetch_time":1756901020198}
{"symbol":"TONUSDT","bids":[],"asks":[["3.1536","5776.9"]],"timestamp":1756901020170,"update_id":50200240,"fetch_time":1756901020218}
{"symbol":"TONUSDT","bids":[],"asks":[["3.1519","3952.5"],["3.1521","3277.2"]],"timestamp":1756901020290,"update_id":50200241,"fetch_time":1756901020338}
{"symbol":"TONUSDT","bids":[],"asks":[["3.1506","163.7"]],"timestamp":1756901020309,"update_id":50200242,"fetch_time":1756901020358}
{"symbol":"TONUSDT","bids":[],"asks":[["3.1505","700.9"],["3.1506","248.2"]],"timestamp":1756901020490,"update_id":50200243,"fetch_time":1756901020534}
{"symbol":"TONUSDT","bids":[["3.1494","1359.3"]],"asks":[],"timestamp":1756901020510,"update_id":50200244,"fetch_time":1756901020558}
{"symbol":"TONUSDT","bids":[["3.1495","66.6"]],"asks":[],"timestamp":1756901020529,"update_id":50200245,"fetch_time":1756901020574}
{"symbol":"TONUSDT","bids":[["3.1498","0"],["3.1495","231.4"],["3.1494","1316.0"],["3.1493","323.0"],["3.1492","2084.3"],["3.1491","283.4"],["3.1490","1934.1"],["3.1449","2652.4"]],"asks":[["3.1504","31.4"],["3.1505","739.1"]],"timestamp":1756901020650,"update_id":50200247,"fetch_time":1756901020698}
{"symbol":"TONUSDT","bids":[],"asks":[["3.1503","21.4"],["3.1549","1931.5"],["3.1551","1868.8"],["3.1552","0"]],"timestamp":1756901020669,"update_id":50200248,"fetch_time":1756901020714}
{"symbol":"TONUSDT","bids":[["3.1497","0"],["3.1494","1157.3"],["3.1493","5.6"],["3.1448","11349.9"]],"asks":[["3.1548","4915.6"],["3.1549","663.9"]],"timestamp":1756901020750,"update_id":50200249,"fetch_time":1756901020799}
{"symbol":"TONUSDT","bids":[["3.1495","4.8"]],"asks":[],"timestamp":1756901020790,"update_id":50200250,"fetch_time":1756901020838}
{"symbol":"TONUSDT","bids":[["3.1494","1157.3"]],"asks":[],"timestamp":1756901020890,"update_id":50200252,"fetch_time":1756901020939}
{"symbol":"TONUSDT","bids":[["3.1491","326.7"]],"asks":[],"timestamp":1756901021210,"update_id":50200253,"fetch_time":1756901021258}
{"symbol":"TONUSDT","bids":[["3.1496","587.2"]],"asks":[],"timestamp":1756901021469,"update_id":50200254,"fetch_time":1756901021514}
{"symbol":"TONUSDT","bids":[["3.1492","2170.8"],["3.1491","369.9"]],"asks":[["3.1503","0"],["3.1504","1.5"],["3.1505","701.4"],["3.1506","207.0"],["3.1507","1408.2"],["3.1508","1882.0"],["3.1552","3336.7"]],"timestamp":1756901021490,"update_id":50200255,"fetch_time":1756901021542}
{"symbol":"TONUSDT","bids":[],"asks":[["3.1506","250.2"],["3.1507","1451.4"],["3.1508","1925.2"]],"timestamp":1756901021530,"update_id":50200256,"fetch_time":1756901021578}
{"symbol":"TONUSDT","bids":[],"asks":[["3.1505","739.1"]],"timestamp":1756901021550,"update_id":50200257,"fetch_time":1756901021598}
{"symbol":"TONUSDT","bids":[],"asks":[["3.1504","16.2"]],"timestamp":1756901021730,"update_id":50200258,"fetch_time":1756901021778}
{"symbol":"TONUSDT","bids":[],"asks":[["3.1504","31.4"]],"timestamp":1756901021749,"update_id":50200259,"fetch_time":1756901021794}
{"symbol":"TONUSDT","bids":[],"asks":[["3.1503","10.5"],["3.1552","0"]],"timestamp":1756901021769,"update_id":50200260,"fetch_time":1756901021818}
{"symbol":"TONUSDT","bids":[["3.1492","2127.6"],["3.1491","326.7"]],"asks":[],"timestamp":1756901021790,"update_id":50200261,"fetch_time":1756901021834}
{"symbol":"TONUSDT","bids":[],"asks":[["3.1505","897.8"],["3.1519","3110.9"]],"timestamp":1756901021809,"update_id":50200262,"fetch_time":1756901021854}
{"symbol":"TONUSDT","bids":[],"asks":[["3.1518","3676.5"]],"timestamp":1756901021830,"update_id":50200263,"fetch_time":1756901021879}
{"symbol":"TONUSDT","bids":[["3.1463","10637.0"],["3.1452","5754.2"]],"asks":[],"timestamp":1756901021889,"update_id":50200264,"fetch_time":1756901021986}
{"symbol":"TONUSDT","bids":[["3.1500","1.2"],["3.1499","0"],["3.1497","43.0"],["3.1496","664.1"],["3.1475","1180.9"],["3.1471","482.5"],["3.1467","1149.5"],["3.1463","10004.8"],["3.1459","1286.3"],["3.1455","1197.2"],["3.1448","0"]],"asks":[],"timestamp":1756901022209,"update_id":50200265,"fetch_time":1756901022259}
{"symbol":"TONUSDT","bids":[["3.1497","190.1"],["3.1494","1400.6"],["3.1454","1628.0"]],"asks":[],"timestamp":1756901022250,"update_id":50200267,"fetch_time":1756901022296}
{"symbol":"TONUSDT","bids":[["3.1495","193.0"],["3.1494","2036.4"]],"asks":[],"timestamp":1756901022270,"update_id":50200268,"fetch_time":1756901022319}
{"symbol":"TONUSDT","bids":[["3.1496","963.6"],["3.1472","1327.4"],["3.1470","4038.0"]],"asks":[],"timestamp":1756901022290,"update_id":50200269,"fetch_time":1756901022335}
{"symbol":"TONUSDT","bids":[["3.1474","1334.6"]],"asks":[],"timestamp":1756901022310,"update_id":50200270,"fetch_time":1756901022356}
{"symbol":"TONUSDT","bids":[["3.1494","1848.3"]],"asks":[],"timestamp":1756901022370,"update_id":50200271,"fetch_time":1756901022416}
{"symbol":"TONUSDT","bids":[],"asks":[["3.1510","1568.7"]],"timestamp":1756901022449,"update_id":50200272,"fetch_time":1756901022498}
{"symbol":"TONUSDT","bids":[["3.1496","737.0"],["3.1495","279.5"],["3.1494","1934.8"],["3.1493","92.1"],["3.1492","2170.8"],["3.1491","369.9"],["3.1484","1484.1"]],"asks":[["3.1503","0"],["3.1504","1.5"],["3.1505","821.9"],["3.1506","163.7"],["3.1507","1364.9"],["3.1508","1881.9"],["3.1509","1111.0"],["3.1511","981.9"],["3.1512","3004.7"],["3.1552","3336.7"]],"timestamp":1756901022470,"update_id":50200273,"fetch_time":1756901022520}
{"symbol":"TONUSDT","bids":[["3.1498","146.9"],["3.1449","0"]],"asks":[],"timestamp":1756901022510,"update_id":50200275,"fetch_time":1756901022558}
{"symbol":"TONUSDT","bids":[["3.1497","306.2"]],"asks":[],"timestamp":1756901022529,"update_id":50200276,"fetch_time":1756901022580}
{"symbol":"TONUSDT","bids":[["3.1500","0"],["3.1498","142.0"],["3.1497","274.1"],["3.1496","751.6"],["3.1490","2020.6"],["3.1489","873.8"],["3.1449","3372.8"]],"asks":[],"timestamp":1756901022630,"update_id":50200277,"fetch_time":1756901022677}
{"symbol":"TONUSDT","bids":[["3.1497","270.9"],["3.1495","91.3"],["3.1494","1055.7"]],"asks":[],"timestamp":1756901022649,"update_id":50200278,"fetch_time":1756901022699}
{"symbol":"TONUSDT","bids":[["3.1499","20.0"],["3.1496","454.5"],["3.1493","280.3"],["3.1449","0"]],"asks":[],"timestamp":1756901022670,"update_id":50200279,"fetch_time":1756901022721}
{"symbol":"TONUSDT","bids":[["3.1484","1400.9"]],"asks":[],"timestamp":1756901022729,"update_id":50200281,"fetch_time":1756901022780}
{"symbol":"TONUSDT","bids":[["3.1475","2133.0"],["3.1470","3085.8"]],"asks":[],"timestamp":1756901022749,"update_id":50200282,"fetch_time":1756901022796}
{"symbol":"TONUSDT","bids":[["3.1493","92.1"],["3.1476","1743.3"],["3.1475","1180.9"],["3.1473","3242.2"]],"asks":[],"timestamp":1756901022770,"update_id":50200283,"fetch_time":1756901022820}
{"symbol":"TONUSDT","bids":[["3.1476","1522.6"]],"asks":[],"timestamp":1756901022789,"update_id":50200284,"fetch_time":1756901022836}
{"symbol":"TONUSDT","bids":[["3.1485","3241.9"]],"asks":[],"timestamp":1756901022969,"update_id":50200286,"fetch_time":1756901023019}
{"symbol":"TONUSDT","bids":[["3.1500","0.6"],["3.1497","335.2"],["3.1496","483.1"],["3.1489","918.1"],["3.1483","1307.7"],["3.1450","0"]],"asks":[["3.1510","1410.1"],["3.1514","4070.0"],["3.1537","1669.7"]],"timestamp":1756901023069,"update_id":50200287,"fetch_time":1756901023123}
{"symbol":"TONUSDT","bids":[["3.1499","0"],["3.1497","338.4"],["3.1450","5951.7"]],"asks":[["3.1537","1667.7"]],"timestamp":1756901023090,"update_id":50200288,"fetch_time":1756901023144}
{"symbol":"TONUSDT","bids":[["3.1495","717.2"]],"asks":[],"timestamp":1756901023150,"update_id":50200291,"fetch_time":1756901023204}
{"symbol":"TONUSDT","bids":[["3.1498","154.1"],["3.1494","1934.8"]],"asks":[],"timestamp":1756901023170,"update_id":50200292,"fetch_time":1756901023215}
{"symbol":"TONUSDT","bids":[["3.1497","295.4"],["3.1496","283.9"]],"asks":[],"timestamp":1756901023489,"update_id":50200294,"fetch_time":1756901023536}
{"symbol":"TONUSDT","bids":[["3.1500","0"],["3.1449","3372.8"]],"asks":[],"timestamp":1756901024010,"update_id":50200296,"fetch_time":1756901024063}
{"symbol":"TONUSDT","bids":[["3.1499","43.0"],["3.1497","270.9"],["3.1496","277.2"],["3.1495","528.9"],["3.1494","1055.7"],["3.1485","2441.9"],["3.1449","0"]],"asks":[["3.1511","1004.9"],["3.1512","3070.3"]],"timestamp":1756901024029,"update_id":50200297,"fetch_time":1756901024079}
{"symbol":"TONUSDT","bids":[["3.1495","246.8"]],"asks":[],"timestamp":1756901024050,"update_id":50200298,"fetch_time":1756901024096}
{"symbol":"TONUSDT","bids":[["3.1494","1244.0"]],"asks":[],"timestamp":1756901024070,"update_id":50200299,"fetch_time":1756901024117}
{"symbol":"TONUSDT","bids":[["3.1496","252.9"]],"asks":[],"timestamp":1756901024189,"update_id":50200300,"fetch_time":1756901024238}
{"symbol":"TONUSDT","bids":[],"asks":[["3.1536","5334.1"]],"timestamp":1756901024370,"update_id":50200301,"fetch_time":1756901024416}
{"symbol":"TONUSDT","bids":[],"asks":[["3.1506","223.5"],["3.1512","3027.0"]],"timestamp":1756901024430,"update_id":50200302,"fetch_time":1756901024482}
{"symbol":"TONUSDT","bids":[["3.1486","2124.1"]],"asks":[],"timestamp":1756901024550,"update_id":50200303,"fetch_time":1756901024596}
{"symbol":"TONUSDT","bids":[["3.1488","1182.2"]],"asks":[],"timestamp":1756901024570,"update_id":50200304,"fetch_time":1756901024617}
{"symbol":"TONUSDT","bids":[],"asks":[["3.1536","5775.9"]],"timestamp":1756901024869,"update_id":50200305,"fetch_time":1756901024921}
{"symbol":"TONUSDT","bids":[],"asks":[["3.1504","174.9"]],"timestamp":1756901025009,"update_id":50200307,"fetch_time":1756901025057}
{"symbol":"TONUSDT","bids":[["3.1491","369.7"]],"asks":[],"timestamp":1756901025030,"update_id":50200308,"fetch_time":1756901025080}
{"symbol":"TONUSDT","bids":[["3.1497","0"],["3.1496","546.0"],["3.1483","1385.7"],["3.1449","3372.8"]],"asks":[["3.1504","174.9"],["3.1505","724.4"]],"timestamp":1756901025310,"update_id":50200310,"fetch_time":1756901025358}
{"symbol":"TONUSDT","bids":[["3.1488","980.4"]],"asks":[],"timestamp":1756901025330,"update_id":50200311,"fetch_time":1756901025384}
{"symbol":"TONUSDT","bids":[["3.1493","48.6"],["3.1492","2127.3"]],"asks":[],"timestamp":1756901025410,"update_id":50200312,"fetch_time":1756901025455}
{"symbol":"TONUSDT","bids":[],"asks":[["3.1504","160.2"]],"timestamp":1756901025430,"update_id":50200313,"fetch_time":1756901025476}
{"symbol":"TONUSDT","bids":[["3.1494","1200.5"],["3.1492","2170.3"],["3.1478","1010.5"]],"asks":[],"timestamp":1756901025650,"update_id":50200314,"fetch_time":1756901025699}
{"symbol":"TONUSDT","bids":[["3.1488","821.9"]],"asks":[],"timestamp":1756901026209,"update_id":50200318,"fetch_time":1756901026254}
{"symbol":"TONUSDT","bids":[["3.1492","2126.0"]],"asks":[],"timestamp":1756901026530,"update_id":50200320,"fetch_time":1756901026575}
{"symbol":"TONUSDT","bids":[["3.1495","195.8"]],"asks":[],"timestamp":1756901026590,"update_id":50200321,"fetch_time":1756901026635}
{"symbol":"TONUSDT","bids":[["3.1496","557.2"]],"asks":[],"timestamp":1756901026769,"update_id":50200322,"fetch_time":1756901026820}
{"symbol":"TONUSDT","bids":[["3.1492","2167.7"]],"asks":[],"timestamp":1756901026790,"update_id":50200323,"fetch_time":1756901026836}
{"symbol":"TONUSDT","bids":[["3.1493","47.3"]],"asks":[],"timestamp":1756901026910,"update_id":50200324,"fetch_time":1756901026961}
{"symbol":"TONUSDT","bids":[["3.1500","0.6"],["3.1449","0"]],"asks":[],"timestamp":1756901027069,"update_id":50200325,"fetch_time":1756901027118}
{"symbol":"TONUSDT","bids":[["3.1495","384.3"],["3.1494","1400.8"]],"asks":[],"timestamp":1756901027090,"update_id":50200326,"fetch_time":1756901027141}
{"symbol":"TONUSDT","bids":[["3.1497","3.2"],["3.1496","882.0"],["3.1495","228.8"],["3.1494","2036.6"],["3.1450","0"]],"asks":[],"timestamp":1756901027110,"update_id":50200327,"fetch_time":1756901027162}
{"symbol":"TONUSDT","bids":[["3.1496","1032.2"]],"asks":[],"timestamp":1756901027129,"update_id":50200328,"fetch_time":1756901027178}
{"symbol":"TONUSDT","bids":[["3.1494","1848.3"]],"asks":[],"timestamp":1756901027189,"update_id":50200329,"fetch_time":1756901027243}
{"symbol":"TONUSDT","bids":[["3.1494","1890.0"],["3.1493","89.0"]],"asks":[],"timestamp":1756901027389,"update_id":50200330,"fetch_time":1756901027444}
{"symbol":"TONUSDT","bids":[],"asks":[["3.1505","663.2"],["3.1512","3025.5"]],"timestamp":1756901027629,"update_id":50200331,"fetch_time":1756901027677}
{"symbol":"TONUSDT","bids":[["3.1495","270.5"]],"asks":[],"timestamp":1756901027650,"update_id":50200332,"fetch_time":1756901027700}
{"symbol":"TONUSDT","bids":[],"asks":[["3.1506","223.5"],["3.1512","3067.2"]],"timestamp":1756901027850,"update_id":50200333,"fetch_time":1756901027895}
{"symbol":"TONUSDT","bids":[["3.1500","0"],["3.1450","5951.7"]],"asks":[],"timestamp":1756901028009,"update_id":50200334,"fetch_time":1756901028059}
{"symbol":"TONUSDT","bids":[["3.1500","61.3"],["3.1499","0"],["3.1495","123.7"],["3.1494","1931.7"]],"asks":[["3.1504","1.5"]],"timestamp":1756901028030,"update_id":50200335,"fetch_time":1756901028075}
{"symbol":"TONUSDT","bids":[["3.1489","837.6"],["3.1457","1117.1"],["3.1450","6053.2"]],"asks":[],"timestamp":1756901028070,"update_id":50200337,"fetch_time":1756901028119}
{"symbol":"TONUSDT","bids":[["3.1501","140.0"],["3.1450","0"]],"asks":[],"timestamp":1756901028109,"update_id":50200338,"fetch_time":1756901028156}
{"symbol":"TONUSDT","bids":[],"asks":[["3.1508","2554.0"]],"timestamp":1756901028190,"update_id":50200342,"fetch_time":1756901028238}
{"symbol":"TONUSDT","bids":[["3.1501","141.0"],["3.1488","1231.0"]],"asks":[],"timestamp":1756901028309,"update_id":50200344,"fetch_time":1756901028364}
{"symbol":"TONUSDT","bids":[],"asks":[["3.1550","2399.4"],["3.1551","3136.3"]],"timestamp":1756901028349,"update_id":50200345,"fetch_time":1756901028402}
{"symbol":"TONUSDT","bids":[],"asks":[["3.1548","3648.0"]],"timestamp":1756901028370,"update_id":50200346,"fetch_time":1756901028423}
{"symbol":"TONUSDT","bids":[["3.1501","17.3"],["3.1500","0"],["3.1497","3.2"],["3.1495","368.3"],["3.1494","1890.0"],["3.1493","47.3"],["3.1492","2126.0"],["3.1491","608.0"],["3.1489","2002.8"],["3.1488","431.0"],["3.1450","6053.2"]],"asks":[["3.1502","360.4"],["3.1504","160.2"],["3.1505","692.6"],["3.1506","106.5"],["3.1507","710.3"],["3.1510","1657.1"],["3.1511","708.4"]],"timestamp":1756901028630,"update_id":50200347,"fetch_time":1756901028684}
{"symbol":"TONUSDT","bids":[],"asks":[["3.1509","1439.2"],["3.1548","4029.0"]],"timestamp":1756901028730,"update_id":50200352,"fetch_time":1756901028776}
{"symbol":"TONUSDT","bids":[],"asks":[["3.1508","1924.9"]],"timestamp":1756901028749,"update_id":50200353,"fetch_time":1756901028798}
{"symbol":"TONUSDT","bids":[],"asks":[["3.1515","2053.3"]],"timestamp":1756901028830,"update_id":50200354,"fetch_time":1756901028880}
{"symbol":"TONUSDT","bids":[],"asks":[["3.1514","4236.2"]],"timestamp":1756901028850,"update_id":50200355,"fetch_time":1756901028897}
{"symbol":"TONUSDT","bids":[],"asks":[["3.1550","2399.4"],["3.1551","3136.3"]],"timestamp":1756901028870,"update_id":50200356,"fetch_time":1756901028918}
{"symbol":"TONUSDT","bids":[],"asks":[["3.1548","3648.0"]],"timestamp":1756901028889,"update_id":50200357,"fetch_time":1756901028939}
{"symbol":"TONUSDT","bids":[["3.1501","1.0"]],"asks":[],"timestamp":1756901028949,"update_id":50200358,"fetch_time":1756901028999}
{"symbol":"TONUSDT","bids":[],"asks":[["3.1550","3666.9"],["3.1551","1868.8"]],"timestamp":1756901029129,"update_id":50200359,"fetch_time":1756901029179}
{"symbol":"TONUSDT","bids":[],"asks":[["3.1505","876.2"]],"timestamp":1756901029209,"update_id":50200360,"fetch_time":1756901029261}
{"symbol":"TONUSDT","bids":[["3.1488","789.3"]],"asks":[],"timestamp":1756901029230,"update_id":50200361,"fetch_time":1756901029276}
{"symbol":"TONUSDT","bids":[["3.1478","929.9"]],"asks":[],"timestamp":1756901029330,"update_id":50200362,"fetch_time":1756901029379}
{"symbol":"TONUSDT","bids":[],"asks":[["3.1509","1470.9"]],"timestamp":1756901029370,"update_id":50200363,"fetch_time":1756901029417}
{"symbol":"TONUSDT","bids":[["3.1496","1025.4"]],"asks":[],"timestamp":1756901029450,"update_id":50200365,"fetch_time":1756901029504}
{"symbol":"TONUSDT","bids":[["3.1501","0"],["3.1493","87.7"],["3.1491","648.4"],["3.1480","3326.7"],["3.1449","3372.8"]],"asks":[["3.1509","2542.5"],["3.1512","3295.5"],["3.1515","1253.3"],["3.1536","5513.8"]],"timestamp":1756901029489,"update_id":50200367,"fetch_time":1756901029543}
{"symbol":"TONUSDT","bids":[["3.1498","0"],["3.1494","1051.3"],["3.1493","276.3"],["3.1492","2485.1"],["3.1490","2036.8"],["3.1448","11026.9"]],"asks":[],"timestamp":1756901029510,"update_id":50200368,"fetch_time":1756901029559}
{"symbol":"TONUSDT","bids":[["3.1498","20.0"],["3.1497","0"],["3.1495","109.4"]],"asks":[["3.1501","331.6"],["3.1502","0"],["3.1504","163.4"],["3.1507","1676.9"],["3.1509","2510.9"],["3.1536","5515.8"],["3.1537","1665.7"]],"timestamp":1756901029549,"update_id":50200370,"fetch_time":1756901029603}
{"symbol":"TONUSDT","bids":[],"asks":[["3.1506","1230.0"]],"timestamp":1756901029589,"update_id":50200372,"fetch_time":1756901029635}
{"symbol":"TONUSDT","bids":[],"asks":[["3.1507","1488.4"]],"timestamp":1756901029609,"update_id":50200373,"fetch_time":1756901029656}
{"symbol":"TONUSDT","bids":[],"asks":[["3.1507","1299.8"]],"timestamp":1756901029629,"update_id":50200374,"fetch_time":1756901029679}
{"symbol":"TONUSDT","bids":[],"asks":[["3.1501","0"],["3.1503","61.6"],["3.1504","162.6"],["3.1505","843.6"],["3.1506","223.5"],["3.1507","710.3"],["3.1508","1289.1"],["3.1536","5513.8"],["3.1539","1995.5"]],"timestamp":1756901029669,"update_id":50200375,"fetch_time":1756901029716}
{"symbol":"TONUSDT","bids":[],"asks":[["3.1502","28.8"],["3.1507","236.6"],["3.1537","1667.7"],["3.1539","1993.5"],["3.1546","1815.4"],["3.1552","0"]],"timestamp":1756901029690,"update_id":50200376,"fetch_time":1756901029739}
{"symbol":"TONUSDT","bids":[],"asks":[["3.1505","689.7"],["3.1507","1054.5"]],"timestamp":1756901029710,"update_id":50200377,"fetch_time":1756901029755}
{"symbol":"TONUSDT","bids":[],"asks":[["3.1507","1243.1"],["3.1508","1926.1"]],"timestamp":1756901029729,"update_id":50200378,"fetch_time":1756901029776}
{"symbol":"TONUSDT","bids":[],"asks":[["3.1505","692.9"],["3.1507","1416.0"]],"timestamp":1756901029750,"update_id":50200379,"fetch_time":1756901029797}
{"symbol":"TONUSDT","bids":[["3.1498","17.7"],["3.1497","164.2"],["3.1496","411.1"],["3.1495","40.3"],["3.1494","969.2"],["3.1493","352.9"],["3.1492","2401.7"],["3.1491","283.4"],["3.1490","1996.4"],["3.1480","3251.1"],["3.1448","0"]],"asks":[["3.1500","28.8"],["3.1501","122.9"],["3.1502","0"],["3.1504","195.2"],["3.1505","731.1"],["3.1506","272.9"],["3.1510","1410.1"],["3.1511","665.2"],["3.1512","3253.8"],["3.1535","751.7"],["3.1536","5515.8"],["3.1537","2056.6"],["3.1551","0"]],"timestamp":1756901030030,"update_id":50200381,"fetch_time":1756901030080}
{"symbol":"TONUSDT","bids":[["3.1497","0"],["3.1495","280.5"],["3.1491","322.6"],["3.1490","2035.6"],["3.1448","11026.9"]],"asks":[["3.1505","1014.1"],["3.1509","2748.4"],["3.1522","2025.5"],["3.1535","753.7"],["3.1536","5513.8"]],"timestamp":1756901030050,"update_id":50200382,"fetch_time":1756901030097}
{"symbol":"TONUSDT","bids":[],"asks":[["3.1505","1737.7"],["3.1506","1153.2"],["3.1537","2974.0"],["3.1545","847.6"]],"timestamp":1756901030069,"update_id":50200383,"fetch_time":1756901030119}
{"symbol":"TONUSDT","bids":[],"asks":[["3.1503","252.3"],["3.1507","970.6"],["3.1510","1366.9"],["3.1531","2906.1"],["3.1532","2076.4"],["3.1550","2399.4"]],"timestamp":1756901030110,"update_id":50200385,"fetch_time":1756901030156}
{"symbol":"TONUSDT","bids":[],"asks":[["3.1507","782.0"]],"timestamp":1756901030129,"update_id":50200386,"fetch_time":1756901030179}
{"symbol":"TONUSDT","bids":[],"asks":[["3.1507","435.7"],["3.1536","5341.2"]],"timestamp":1756901030170,"update_id":50200387,"fetch_time":1756901030216}
{"symbol":"TONUSDT","bids":[["3.1490","2237.9"]],"asks":[],"timestamp":1756901030229,"update_id":50200388,"fetch_time":1756901030282}
{"symbol":"TONUSDT","bids":[["3.1496","373.7"],["3.1495","245.0"],["3.1492","2137.8"],["3.1490","1852.7"],["3.1489","1987.6"]],"asks":[],"timestamp":1756901030309,"update_id":50200389,"fetch_time":1756901030358}
{"symbol":"TONUSDT","bids":[],"asks":[["3.1509","2716.7"],["3.1536","5761.8"]],"timestamp":1756901030370,"update_id":50200390,"fetch_time":1756901030423}
{"symbol":"TONUSDT","bids":[],"asks":[["3.1509","2685.1"],["3.1550","3667.0"]],"timestamp":1756901030389,"update_id":50200391,"fetch_time":1756901030439}
{"symbol":"TONUSDT","bids":[],"asks":[["3.1548","4029.0"]],"timestamp":1756901030410,"update_id":50200392,"fetch_time":1756901030462}
{"symbol":"TONUSDT","bids":[],"asks":[["3.1509","2622.1"]],"timestamp":1756901030490,"update_id":50200393,"fetch_time":1756901030543}
{"symbol":"TONUSDT","bids":[],"asks":[["3.1509","2580.6"]],"timestamp":1756901030530,"update_id":50200394,"fetch_time":1756901030575}
{"symbol":"TONUSDT","bids":[],"asks":[["3.1509","2263.2"]],"timestamp":1756901030590,"update_id":50200395,"fetch_time":1756901030635}
{"symbol":"TONUSDT","bids":[],"asks":[["3.1503","218.7"]],"timestamp":1756901030609,"update_id":50200396,"fetch_time":1756901030658}
{"symbol":"TONUSDT","bids":[],"asks":[["3.1509","1882.5"]],"timestamp":1756901030650,"update_id":50200397,"fetch_time":1756901030695}
{"symbol":"TONUSDT","bids":[["3.1496","613.9"],["3.1495","4.8"],["3.1462","3057.7"],["3.1452","3948.4"]],"asks":[],"timestamp":1756901030770,"update_id":50200399,"fetch_time":1756901030815}
{"symbol":"TONUSDT","bids":[["3.1497","139.1"],["3.1492","2177.0"],["3.1454","68.1"],["3.1448","0"]],"asks":[["3.1503","64.8"]],"timestamp":1756901030790,"update_id":50200400,"fetch_time":1756901030836}
{"symbol":"TONUSDT","bids":[["3.1499","0.6"],["3.1490","1891.9"],["3.1489","2146.2"],["3.1483","1227.1"],["3.1449","0"]],"asks":[["3.1509","1581.4"],["3.1514","4166.5"],["3.1535","755.7"]],"timestamp":1756901031070,"update_id":50200402,"fetch_time":1756901031119}
{"symbol":"TONUSDT","bids":[["3.1494","1182.7"]],"asks":[],"timestamp":1756901031129,"update_id":50200404,"fetch_time":1756901031179}
{"symbol":"TONUSDT","bids":[["3.1496","617.1"],["3.1491","361.8"]],"asks":[],"timestamp":1756901031150,"update_id":50200405,"fetch_time":1756901031200}
{"symbol":"TONUSDT","bids":[["3.1493","363.9"],["3.1490","2293.7"],["3.1489","2037.9"]],"asks":[],"timestamp":1756901031190,"update_id":50200406,"fetch_time":1756901031240}
{"symbol":"TONUSDT","bids":[["3.1493","175.3"]],"asks":[],"timestamp":1756901031230,"update_id":50200407,"fetch_time":1756901031276}
{"symbol":"TONUSDT","bids":[["3.1492","2137.8"],["3.1491","322.6"],["3.1490","2254.5"]],"asks":[],"timestamp":1756901031650,"update_id":50200408,"fetch_time":1756901031695}
{"symbol":"TONUSDT","bids":[],"asks":[["3.1503","252.9"],["3.1549","1931.5"],["3.1550","2399.4"]],"timestamp":1756901031670,"update_id":50200409,"fetch_time":1756901031718}
{"symbol":"TONUSDT","bids":[["3.1496","477.1"]],"asks":[],"timestamp":1756901031770,"update_id":50200410,"fetch_time":1756901031815}
{"symbol":"TONUSDT","bids":[["3.1497","0"],["3.1449","3151.2"]],"asks":[],"timestamp":1756901031789,"update_id":50200411,"fetch_time":1756901031837}
{"symbol":"TONUSDT","bids":[],"asks":[["3.1502","153.9"],["3.1519","2069.3"],["3.1550","0"]],"timestamp":1756901031809,"update_id":50200412,"fetch_time":1756901031865}
{"symbol":"TONUSDT","bids":[],"asks":[["3.1518","3364.0"]],"timestamp":1756901031830,"update_id":50200413,"fetch_time":1756901031876}
{"symbol":"TONUSDT","bids":[],"asks":[["3.1549","663.9"]],"timestamp":1756901031889,"update_id":50200414,"fetch_time":1756901031935}
{"symbol":"TONUSDT","bids":[],"asks":[["3.1548","3648.0"]],"timestamp":1756901031910,"update_id":50200415,"fetch_time":1756901031956}
{"symbol":"TONUSDT","bids":[],"asks":[["3.1502","0"],["3.1503","64.8"],["3.1507","718.7"],["3.1510","1406.1"],["3.1550","3667.0"]],"timestamp":1756901031949,"update_id":50200417,"fetch_time":1756901031994}
{"symbol":"TONUSDT","bids":[],"asks":[["3.1507","907.3"]],"timestamp":1756901031970,"update_id":50200418,"fetch_time":1756901032016}
{"symbol":"TONUSDT","bids":[],"asks":[["3.1504","164.8"],["3.1506","1607.2"],["3.1549","1931.5"],["3.1550","2399.4"]],"timestamp":1756901031989,"update_id":50200419,"fetch_time":1756901032037}
{"symbol":"TONUSDT","bids":[["3.1499","20.0"]],"asks":[],"timestamp":1756901032009,"update_id":50200420,"fetch_time":1756901032059}
{"symbol":"TONUSDT","bids":[],"asks":[["3.1506","1795.8"]],"timestamp":1756901032029,"update_id":50200421,"fetch_time":1756901032076}
{"symbol":"TONUSDT","bids":[],"asks":[["3.1505","1511.1"],["3.1507","624.3"]],"timestamp":1756901032110,"update_id":50200424,"fetch_time":1756901032158}
{"symbol":"TONUSDT","bids":[["3.1499","0"],["3.1448","11026.9"]],"asks":[["3.1505","1699.7"],["3.1506","1512.7"],["3.1507","435.7"],["3.1519","2911.0"]],"timestamp":1756901032130,"update_id":50200425,"fetch_time":1756901032179}
{"symbol":"TONUSDT","bids":[["3.1494","994.1"]],"asks":[],"timestamp":1756901032150,"update_id":50200426,"fetch_time":1756901032195}
{"symbol":"TONUSDT","bids":[],"asks":[["3.1506","1449.3"]],"timestamp":1756901032190,"update_id":50200428,"fetch_time":1756901032239}
{"symbol":"TONUSDT","bids":[],"asks":[["3.1506","1166.3"]],"timestamp":1756901032210,"update_id":50200429,"fetch_time":1756901032255}
{"symbol":"TONUSDT","bids":[],"asks":[["3.1506","977.7"],["3.1548","4029.0"]],"timestamp":1756901032229,"update_id":50200430,"fetch_time":1756901032276}
{"symbol":"TONUSDT","bids":[],"asks":[["3.1505","1738.9"],["3.1510","1366.9"]],"timestamp":1756901032810,"update_id":50200431,"fetch_time":1756901032864}
{"symbol":"TONUSDT","bids":[["3.1489","2037.9"],["3.1483","1227.1"]],"asks":[],"timestamp":1756901033070,"update_id":50200432,"fetch_time":1756901033119}
{"symbol":"TONUSDT","bids":[],"asks":[["3.1504","6.1"]],"timestamp":1756901033829,"update_id":50200434,"fetch_time":1756901033875}
{"symbol":"TONUSDT","bids":[],"asks":[["3.1504","204.0"]],"timestamp":1756901034190,"update_id":50200436,"fetch_time":1756901034239}
{"symbol":"TONUSDT","bids":[["3.1498","145.2"],["3.1491","361.8"],["3.1490","2293.7"]],"asks":[],"timestamp":1756901034349,"update_id":50200437,"fetch_time":1756901034396}
{"symbol":"TONUSDT","bids":[],"asks":[["3.1500","0"],["3.1551","1868.8"]],"timestamp":1756901034469,"update_id":50200438,"fetch_time":1756901034516}
