{"symbol":"TONUSDT","bids":[["3.1504","20.0"],["3.1499","182.3"],["3.1452","0"]],"asks":[["3.1505","1.6"],["3.1507","227.0"],["3.1510","2118.3"],["3.1511","798.4"],["3.1551","5712.2"],["3.1553","1387.9"]],"timestamp":1756900871569,"update_id":50197136,"fetch_time":1756900871612}
{"symbol":"TONUSDT","bids":[["3.1503","158.0"],["3.1501","3.2"],["3.1500","508.7"],["3.1499","425.6"],["3.1453","0"]],"asks":[["3.1508","1464.5"],["3.1510","2305.3"],["3.1511","1265.5"],["3.1514","4507.4"],["3.1551","6979.7"],["3.1552","2017.0"],["3.1553","120.4"]],"timestamp":1756900871589,"update_id":50197137,"fetch_time":1756900871636}
{"symbol":"TONUSDT","bids":[["3.1501","186.2"],["3.1499","510.5"],["3.1498","981.3"],["3.1496","1309.4"],["3.1494","1207.8"]],"asks":[],"timestamp":1756900871629,"update_id":50197139,"fetch_time":1756900871672}
{"symbol":"TONUSDT","bids":[],"asks":[["3.1552","3051.9"],["3.1553","120.4"]],"timestamp":1756900871669,"update_id":50197141,"fetch_time":1756900871717}
{"symbol":"TONUSDT","bids":[],"asks":[["3.1507","37.2"],["3.1551","6979.7"],["3.1552","1784.4"]],"timestamp":1756900871729,"update_id":50197144,"fetch_time":1756900871772}
{"symbol":"TONUSDT","bids":[],"asks":[["3.1509","1028.2"]],"timestamp":1756900871850,"update_id":50197145,"fetch_time":1756900871896}
{"symbol":"TONUSDT","bids":[],"asks":[["3.1517","1170.1"]],"timestamp":1756900872070,"update_id":50197146,"fetch_time":1756900872116}
{"symbol":"TONUSDT","bids":[],"asks":[["3.1509","984.9"],["3.1510","2529.1"]],"timestamp":1756900872289,"update_id":50197147,"fetch_time":1756900872336}
{"symbol":"TONUSDT","bids":[["3.1495","599.2"]],"asks":[],"timestamp":1756900872310,"update_id":50197148,"fetch_time":1756900872356}
{"symbol":"TONUSDT","bids":[],"asks":[["3.1509","635.8"],["3.1510","1894.5"],["3.1511","1043.6"]],"timestamp":1756900872370,"update_id":50197149,"fetch_time":1756900872416}
{"symbol":"TONUSDT","bids":[],"asks":[["3.1508","602.9"],["3.1509","604.1"]],"timestamp":1756900872389,"update_id":50197150,"fetch_time":1756900872432}
{"symbol":"TONUSDT","bids":[],"asks":[["3.1515","2700.9"],["3.1519","2256.8"]],"timestamp":1756900872409,"update_id":50197151,"fetch_time":1756900872457}
{"symbol":"TONUSDT","bids":[],"asks":[["3.1510","1862.8"]],"timestamp":1756900872450,"update_id":50197152,"fetch_time":1756900872496}
{"symbol":"TONUSDT","bids":[],"asks":[["3.1509","182.1"]],"timestamp":1756900872469,"update_id":50197153,"fetch_time":1756900872517}
{"symbol":"TONUSDT","bids":[],"asks":[["3.1507","5.6"],["3.1508","457.3"],["3.1509","118.7"]],"timestamp":1756900872489,"update_id":50197154,"fetch_time":1756900872537}
{"symbol":"TONUSDT","bids":[],"asks":[["3.1510","1675.8"]],"timestamp":1756900872550,"update_id":50197155,"fetch_time":1756900872597}
{"symbol":"TONUSDT","bids":[["3.1502","168.6"],["3.1499","553.8"],["3.1492","1393.8"],["3.1454","0"]],"asks":[["3.1511","1187.3"],["3.1516","2763.4"]],"timestamp":1756900872589,"update_id":50197157,"fetch_time":1756900872637}
{"symbol":"TONUSDT","bids":[],"asks":[["3.1510","1581.0"],["3.1515","2700.9"],["3.1551","5712.2"],["3.1553","1387.9"]],"timestamp":1756900872610,"update_id":50197158,"fetch_time":1756900872657}
{"symbol":"TONUSDT","bids":[["3.1500","381.1"]],"asks":[],"timestamp":1756900872649,"update_id":50197160,"fetch_time":1756900872696}
{"symbol":"TONUSDT","bids":[],"asks":[["3.1511","1124.1"]],"timestamp":1756900872850,"update_id":50197161,"fetch_time":1756900872900}
{"symbol":"TONUSDT","bids":[],"asks":[["3.1516","3029.5"]],"timestamp":1756900872910,"update_id":50197162,"fetch_time":1756900872956}
{"symbol":"TONUSDT","bids":[],"asks":[["3.1516","2763.4"]],"timestamp":1756900872950,"update_id":50197163,"fetch_time":1756900873001}
{"symbol":"TONUSDT","bids":[],"asks":[["3.1513","495.8"]],"timestamp":1756900872969,"update_id":50197164,"fetch_time":1756900873012}
{"symbol":"TONUSDT","bids":[],"asks":[["3.1551","6979.7"],["3.1553","120.4"]],"timestamp":1756900873010,"update_id":50197165,"fetch_time":1756900873061}
{"symbol":"TONUSDT","bids":[["3.1503","156.2"]],"asks":[],"timestamp":1756900873109,"update_id":50197167,"fetch_time":1756900873152}
{"symbol":"TONUSDT","bids":[["3.1504","27.7"],["3.1490","3001.9"]],"asks":[],"timestamp":1756900873129,"update_id":50197168,"fetch_time":1756900873172}
{"symbol":"TONUSDT","bids":[["3.1502","168.6"]],"asks":[],"timestamp":1756900873150,"update_id":50197169,"fetch_time":1756900873196}
{"symbol":"TONUSDT","bids":[],"asks":[["3.1515","2967.0"]],"timestamp":1756900873210,"update_id":50197170,"fetch_time":1756900873256}
{"symbol":"TONUSDT","bids":[["3.1501","161.9"]],"asks":[],"timestamp":1756900873310,"update_id":50197172,"fetch_time":1756900873366}
{"symbol":"TONUSDT","bids":[],"asks":[["3.1510","1191.5"]],"timestamp":1756900873389,"update_id":50197174,"fetch_time":1756900873432}
{"symbol":"TONUSDT","bids":[],"asks":[["3.1508","5.0"],["3.1536","2786.3"]],"timestamp":1756900873430,"update_id":50197176,"fetch_time":1756900873477}
{"symbol":"TONUSDT","bids":[],"asks":[["3.1522","1816.5"],["3.1524","2550.6"]],"timestamp":1756900873510,"update_id":50197178,"fetch_time":1756900873556}
{"symbol":"TONUSDT","bids":[],"asks":[["3.1531","3573.2"]],"timestamp":1756900874370,"update_id":50197182,"fetch_time":1756900874416}
{"symbol":"TONUSDT","bids":[["3.1480","982.4"]],"asks":[],"timestamp":1756900874529,"update_id":50197184,"fetch_time":1756900874572}
{"symbol":"TONUSDT","bids":[["3.1501","463.3"],["3.1500","400.3"]],"asks":[],"timestamp":1756900874669,"update_id":50197186,"fetch_time":1756900874712}
{"symbol":"TONUSDT","bids":[["3.1506","119.5"],["3.1504","53.0"],["3.1503","320.5"],["3.1502","237.5"],["3.1501","475.4"],["3.1500","253.3"],["3.1499","643.8"],["3.1495","556.0"],["3.1494","1223.0"],["3.1492","1335.4"],["3.1483","747.7"],["3.1455","0"]],"asks":[["3.1505","0"],["3.1506","0"],["3.1507","2.4"],["3.1509","3.2"],["3.1510","756.0"],["3.1511","21.1"],["3.1512","2153.2"],["3.1513","128.5"],["3.1514","4092.0"],["3.1515","2636.2"],["3.1517","1231.6"],["3.1518","2956.0"],["3.1520","4906.4"],["3.1540","2730.0"],["3.1542","5765.7"],["3.1553","401.0"],["3.1555","586.9"],["3.1556","1953.4"]],"timestamp":1756900874710,"update_id":50197187,"fetch_time":1756900874757}
{"symbol":"TONUSDT","bids":[["3.1506","0"],["3.1503","379.8"],["3.1502","247.7"],["3.1501","136.5"],["3.1500","440.0"],["3.1455","1495.6"]],"asks":[["3.1513","495.7"],["3.1516","2950.1"],["3.1531","3544.7"],["3.1541","1495.2"],["3.1552","2101.2"]],"timestamp":1756900874749,"update_id":50197189,"fetch_time":1756900874793}
{"symbol":"TONUSDT","bids":[["3.1505","20.0"],["3.1503","376.6"],["3.1501","73.1"],["3.1500","253.3"],["3.1455","0"]],"asks":[],"timestamp":1756900874769,"update_id":50197190,"fetch_time":1756900874816}
{"symbol":"TONUSDT","bids":[["3.1506","20.0"],["3.1500","316.7"],["3.1456","0"]],"asks":[["3.1524","1598.6"],["3.1527","1452.5"]],"timestamp":1756900874790,"update_id":50197191,"fetch_time":1756900874836}
{"symbol":"TONUSDT","bids":[["3.1505","0"],["3.1503","355.2"],["3.1502","230.7"],["3.1501","90.1"],["3.1498","757.4"],["3.1456","1424.7"]],"asks":[["3.1512","1855.5"],["3.1514","4098.6"]],"timestamp":1756900874810,"update_id":50197192,"fetch_time":1756900874856}
{"symbol":"TONUSDT","bids":[],"asks":[["3.1514","3998.4"],["3.1516","2763.4"]],"timestamp":1756900874909,"update_id":50197197,"fetch_time":1756900874956}
{"symbol":"TONUSDT","bids":[],"asks":[["3.1515","2722.7"]],"timestamp":1756900874930,"update_id":50197198,"fetch_time":1756900874976}
{"symbol":"TONUSDT","bids":[["3.1503","373.8"],["3.1500","440.0"]],"asks":[],"timestamp":1756900874950,"update_id":50197199,"fetch_time":1756900874996}
{"symbol":"TONUSDT","bids":[],"asks":[["3.1513","1286.5"]],"timestamp":1756900874990,"update_id":50197200,"fetch_time":1756900875036}
{"symbol":"TONUSDT","bids":[["3.1503","349.5"]],"asks":[],"timestamp":1756900875009,"update_id":50197201,"fetch_time":1756900875060}
{"symbol":"TONUSDT","bids":[["3.1502","586.9"]],"asks":[],"timestamp":1756900875089,"update_id":50197202,"fetch_time":1756900875136}
{"symbol":"TONUSDT","bids":[],"asks":[["3.1516","3062.5"]],"timestamp":1756900875110,"update_id":50197203,"fetch_time":1756900875156}
{"symbol":"TONUSDT","bids":[],"asks":[["3.1512","1898.8"]],"timestamp":1756900875130,"update_id":50197204,"fetch_time":1756900875176}
{"symbol":"TONUSDT","bids":[],"asks":[["3.1510","209.3"]],"timestamp":1756900875210,"update_id":50197208,"fetch_time":1756900875256}
{"symbol":"TONUSDT","bids":[["3.1506","23.9"],["3.1503","343.0"]],"asks":[],"timestamp":1756900875269,"update_id":50197209,"fetch_time":1756900875312}
{"symbol":"TONUSDT","bids":[],"asks":[["3.1518","3177.8"]],"timestamp":1756900875290,"update_id":50197210,"fetch_time":1756900875336}
{"symbol":"TONUSDT","bids":[["3.1500","401.2"]],"asks":[],"timestamp":1756900875330,"update_id":50197212,"fetch_time":1756900875376}
{"symbol":"TONUSDT","bids":[["3.1503","311.5"]],"asks":[],"timestamp":1756900875510,"update_id":50197213,"fetch_time":1756900875560}
{"symbol":"TONUSDT","bids":[["3.1506","29.2"],["3.1504","220.9"]],"asks":[],"timestamp":1756900875549,"update_id":50197214,"fetch_time":1756900875596}
{"symbol":"TONUSDT","bids":[["3.1502","424.1"]],"asks":[],"timestamp":1756900875589,"update_id":50197215,"fetch_time":1756900875636}
{"symbol":"TONUSDT","bids":[["3.1501","126.8"],["3.1498","757.4"]],"asks":[],"timestamp":1756900875609,"update_id":50197216,"fetch_time":1756900875661}
{"symbol":"TONUSDT","bids":[],"asks":[["3.1520","3844.5"]],"timestamp":1756900875629,"update_id":50197217,"fetch_time":1756900875676}
{"symbol":"TONUSDT","bids":[["3.1504","27.7"]],"asks":[],"timestamp":1756900875649,"update_id":50197218,"fetch_time":1756900875692}
{"symbol":"TONUSDT","bids":[["3.1504","248.4"]],"asks":[],"timestamp":1756900875710,"update_id":50197220,"fetch_time":1756900875757}
{"symbol":"TONUSDT","bids":[["3.1506","9.2"]],"asks":[],"timestamp":1756900875810,"update_id":50197221,"fetch_time":1756900875857}
{"symbol":"TONUSDT","bids":[["3.1503","549.5"]],"asks":[],"timestamp":1756900876009,"update_id":50197222,"fetch_time":1756900876056}
{"symbol":"TONUSDT","bids":[["3.1499","476.9"]],"asks":[],"timestamp":1756900876489,"update_id":50197223,"fetch_time":1756900876541}
{"symbol":"TONUSDT","bids":[],"asks":[["3.1511","354.2"],["3.1521","2678.3"]],"timestamp":1756900876509,"update_id":50197224,"fetch_time":1756900876557}
{"symbol":"TONUSDT","bids":[["3.1504","222.6"],["3.1503","806.2"],["3.1502","197.5"]],"asks":[],"timestamp":1756900876710,"update_id":50197228,"fetch_time":1756900876761}
{"symbol":"TONUSDT","bids":[],"asks":[["3.1521","2597.2"]],"timestamp":1756900876910,"update_id":50197230,"fetch_time":1756900876961}
{"symbol":"TONUSDT","bids":[["3.1504","222.6"],["3.1468","4358.4"]],"asks":[],"timestamp":1756900877089,"update_id":50197234,"fetch_time":1756900877137}
{"symbol":"TONUSDT","bids":[["3.1486","4418.5"],["3.1483","466.9"]],"asks":[],"timestamp":1756900877170,"update_id":50197235,"fetch_time":1756900877217}
{"symbol":"TONUSDT","bids":[["3.1485","4020.1"],["3.1484","579.5"]],"asks":[],"timestamp":1756900877209,"update_id":50197236,"fetch_time":1756900877253}
{"symbol":"TONUSDT","bids":[],"asks":[["3.1513","1318.1"],["3.1514","1699.5"],["3.1515","749.5"],["3.1516","2719.0"]],"timestamp":1756900877249,"update_id":50197237,"fetch_time":1756900877300}
{"symbol":"TONUSDT","bids":[],"asks":[["3.1521","2678.3"]],"timestamp":1756900877269,"update_id":50197238,"fetch_time":1756900877316}
{"symbol":"TONUSDT","bids":[["3.1504","232.1"]],"asks":[],"timestamp":1756900877329,"update_id":50197239,"fetch_time":1756900877377}
{"symbol":"TONUSDT","bids":[["3.1506","43.6"],["3.1503","821.8"]],"asks":[],"timestamp":1756900877530,"update_id":50197240,"fetch_time":1756900877576}
{"symbol":"TONUSDT","bids":[["3.1499","520.2"]],"asks":[],"timestamp":1756900877550,"update_id":50197241,"fetch_time":1756900877597}
{"symbol":"TONUSDT","bids":[],"asks":[["3.1510","7.4"],["3.1516","2762.3"]],"timestamp":1756900877630,"update_id":50197242,"fetch_time":1756900877681}
{"symbol":"TONUSDT","bids":[["3.1504","470.1"]],"asks":[],"timestamp":1756900878009,"update_id":50197243,"fetch_time":1756900878052}
{"symbol":"TONUSDT","bids":[["3.1494","2162.9"],["3.1490","1992.1"]],"asks":[],"timestamp":1756900878029,"update_id":50197244,"fetch_time":1756900878076}
{"symbol":"TONUSDT","bids":[["3.1492","942.5"]],"asks":[],"timestamp":1756900878050,"update_id":50197245,"fetch_time":1756900878101}
{"symbol":"TONUSDT","bids":[],"asks":[["3.1553","401.0"],["3.1554","2889.2"]],"timestamp":1756900878150,"update_id":50197246,"fetch_time":1756900878192}
{"symbol":"TONUSDT","bids":[],"asks":[["3.1553","1668.4"],["3.1554","1621.8"]],"timestamp":1756900878209,"update_id":50197247,"fetch_time":1756900878256}
{"symbol":"TONUSDT","bids":[],"asks":[["3.1553","401.0"],["3.1554","2889.2"]],"timestamp":1756900878249,"update_id":50197248,"fetch_time":1756900878296}
{"symbol":"TONUSDT","bids":[],"asks":[["3.1553","1668.4"],["3.1554","1621.8"]],"timestamp":1756900878310,"update_id":50197249,"fetch_time":1756900878357}
{"symbol":"TONUSDT","bids":[],"asks":[["3.1553","401.0"],["3.1554","2889.2"]],"timestamp":1756900878350,"update_id":50197250,"fetch_time":1756900878396}
{"symbol":"TONUSDT","bids":[],"asks":[["3.1553","401.0"],["3.1554","2889.2"]],"timestamp":1756900878410,"update_id":50197252,"fetch_time":1756900878457}
{"symbol":"TONUSDT","bids":[],"asks":[["3.1553","1668.4"],["3.1554","1621.8"]],"timestamp":1756900878449,"update_id":50197253,"fetch_time":1756900878493}
{"symbol":"TONUSDT","bids":[],"asks":[["3.1553","401.0"],["3.1554","2889.2"]],"timestamp":1756900878470,"update_id":50197254,"fetch_time":1756900878517}
{"symbol":"TONUSDT","bids":[],"asks":[["3.1553","1668.4"],["3.1554","1621.8"]],"timestamp":1756900878510,"update_id":50197255,"fetch_time":1756900878557}
{"symbol":"TONUSDT","bids":[],"asks":[["3.1553","401.0"],["3.1554","2889.2"]],"timestamp":1756900878549,"update_id":50197256,"fetch_time":1756900878601}
{"symbol":"TONUSDT","bids":[],"asks":[["3.1553","401.0"],["3.1554","2889.2"]],"timestamp":1756900878590,"update_id":50197258,"fetch_time":1756900878640}
{"symbol":"TONUSDT","bids":[],"asks":[["3.1553","1668.4"],["3.1554","1621.8"]],"timestamp":1756900878630,"update_id":50197259,"fetch_time":1756900878677}
{"symbol":"TONUSDT","bids":[],"asks":[["3.1553","401.0"],["3.1554","2889.2"]],"timestamp":1756900878650,"update_id":50197260,"fetch_time":1756900878701}
{"symbol":"TONUSDT","bids":[],"asks":[["3.1553","1668.4"],["3.1554","1621.8"]],"timestamp":1756900878689,"update_id":50197261,"fetch_time":1756900878737}
{"symbol":"TONUSDT","bids":[],"asks":[["3.1553","401.0"],["3.1554","2889.2"]],"timestamp":1756900878709,"update_id":50197262,"fetch_time":1756900878753}
{"symbol":"TONUSDT","bids":[],"asks":[["3.1515","792.7"],["3.1553","1668.4"],["3.1554","1621.8"]],"timestamp":1756900878730,"update_id":50197263,"fetch_time":1756900878777}
{"symbol":"TONUSDT","bids":[],"asks":[["3.1553","401.0"],["3.1554","2889.2"]],"timestamp":1756900878749,"update_id":50197264,"fetch_time":1756900878792}
{"symbol":"TONUSDT","bids":[],"asks":[["3.1553","1668.4"],["3.1554","1621.8"]],"timestamp":1756900878770,"update_id":50197265,"fetch_time":1756900878821}
{"symbol":"TONUSDT","bids":[],"asks":[["3.1553","401.0"],["3.1554","2889.2"]],"timestamp":1756900878789,"update_id":50197266,"fetch_time":1756900878837}
{"symbol":"TONUSDT","bids":[["3.1504","704.8"],["3.1503","565.1"]],"asks":[],"timestamp":1756900878810,"update_id":50197267,"fetch_time":1756900878861}
{"symbol":"TONUSDT","bids":[],"asks":[["3.1553","1668.4"],["3.1554","1621.8"]],"timestamp":1756900878849,"update_id":50197268,"fetch_time":1756900878897}
{"symbol":"TONUSDT","bids":[],"asks":[["3.1553","401.0"],["3.1554","2889.2"]],"timestamp":1756900878869,"update_id":50197269,"fetch_time":1756900878912}
{"symbol":"TONUSDT","bids":[["3.1503","540.8"]],"asks":[],"timestamp":1756900878930,"update_id":50197271,"fetch_time":1756900878982}
{"symbol":"TONUSDT","bids":[],"asks":[["3.1510","50.7"]],"timestamp":1756900878949,"update_id":50197272,"fetch_time":1756900878997}
{"symbol":"TONUSDT","bids":[],"asks":[["3.1553","401.0"],["3.1554","2889.2"]],"timestamp":1756900878969,"update_id":50197273,"fetch_time":1756900879021}
{"symbol":"TONUSDT","bids":[],"asks":[["3.1553","1668.4"],["3.1554","1621.8"]],"timestamp":1756900879010,"update_id":50197274,"fetch_time":1756900879057}
{"symbol":"TONUSDT","bids":[],"asks":[["3.1541","1463.5"]],"timestamp":1756900879290,"update_id":50197276,"fetch_time":1756900879337}
{"symbol":"TONUSDT","bids":[["3.1504","239.9"]],"asks":[],"timestamp":1756900879510,"update_id":50197277,"fetch_time":1756900879557}
{"symbol":"TONUSDT","bids":[["3.1502","166.0"]],"asks":[],"timestamp":1756900879610,"update_id":50197279,"fetch_time":1756900879657}
{"symbol":"TONUSDT","bids":[["3.1496","1741.1"]],"asks":[],"timestamp":1756900879630,"update_id":50197280,"fetch_time":1756900879681}
{"symbol":"TONUSDT","bids":[["3.1503","547.0"]],"asks":[],"timestamp":1756900880009,"update_id":50197281,"fetch_time":1756900880052}
{"symbol":"TONUSDT","bids":[],"asks":[["3.1528","2736.4"]],"timestamp":1756900880210,"update_id":50197282,"fetch_time":1756900880256}
{"symbol":"TONUSDT","bids":[],"asks":[["3.1521","1836.7"]],"timestamp":1756900880469,"update_id":50197284,"fetch_time":1756900880517}
{"symbol":"TONUSDT","bids":[],"asks":[["3.1520","5343.3"]],"timestamp":1756900880490,"update_id":50197285,"fetch_time":1756900880541}
{"symbol":"TONUSDT","bids":[],"asks":[["3.1518","4014.8"]],"timestamp":1756900880510,"update_id":50197286,"fetch_time":1756900880562}
{"symbol":"TONUSDT","bids":[],"asks":[["3.1553","401.0"],["3.1554","2889.2"]],"timestamp":1756900880550,"update_id":50197287,"fetch_time":1756900880600}
{"symbol":"TONUSDT","bids":[],"asks":[["3.1553","1668.4"],["3.1554","1621.8"]],"timestamp":1756900880569,"update_id":50197288,"fetch_time":1756900880612}
{"symbol":"TONUSDT","bids":[],"asks":[["3.1553","401.0"],["3.1554","2889.2"]],"timestamp":1756900880590,"update_id":50197289,"fetch_time":1756900880637}
{"symbol":"TONUSDT","bids":[],"asks":[["3.1553","1668.4"],["3.1554","1621.8"]],"timestamp":1756900880610,"update_id":50197290,"fetch_time":1756900880656}
{"symbol":"TONUSDT","bids":[["3.1506","43.5"]],"asks":[],"timestamp":1756900880630,"update_id":50197291,"fetch_time":1756900880677}
{"symbol":"TONUSDT","bids":[],"asks":[["3.1553","401.0"],["3.1554","2889.2"]],"timestamp":1756900880669,"update_id":50197292,"fetch_time":1756900880720}
{"symbol":"TONUSDT","bids":[],"asks":[["3.1553","1668.4"],["3.1554","1621.8"]],"timestamp":1756900880689,"update_id":50197293,"fetch_time":1756900880736}
{"symbol":"TONUSDT","bids":[],"asks":[["3.1553","401.0"],["3.1554","2889.2"]],"timestamp":1756900880749,"update_id":50197294,"fetch_time":1756900880796}
{"symbol":"TONUSDT","bids":[],"asks":[["3.1553","401.0"],["3.1554","2889.2"]],"timestamp":1756900880789,"update_id":50197296,"fetch_time":1756900880836}
{"symbol":"TONUSDT","bids":[],"asks":[["3.1553","1668.4"],["3.1554","1621.8"]],"timestamp":1756900880829,"update_id":50197297,"fetch_time":1756900880872}
{"symbol":"TONUSDT","bids":[],"asks":[["3.1553","401.0"],["3.1554","2889.2"]],"timestamp":1756900880849,"update_id":50197298,"fetch_time":1756900880896}
{"symbol":"TONUSDT","bids":[],"asks":[["3.1553","1668.4"],["3.1554","1621.8"]],"timestamp":1756900881009,"update_id":50197299,"fetch_time":1756900881061}
{"symbol":"TONUSDT","bids":[],"asks":[["3.1553","401.0"],["3.1554","2889.2"]],"timestamp":1756900881030,"update_id":50197300,"fetch_time":1756900881076}
{"symbol":"TONUSDT","bids":[],"asks":[["3.1553","1668.4"],["3.1554","1621.8"]],"timestamp":1756900881049,"update_id":50197301,"fetch_time":1756900881092}
{"symbol":"TONUSDT","bids":[],"asks":[["3.1553","401.0"],["3.1554","2889.2"]],"timestamp":1756900881069,"update_id":50197302,"fetch_time":1756900881120}
{"symbol":"TONUSDT","bids":[["3.1504","483.9"],["3.1501","170.1"]],"asks":[["3.1507","0"],["3.1510","7.4"],["3.1511","3.2"],["3.1512","881.6"],["3.1513","1274.8"],["3.1514","1699.4"],["3.1515","749.4"],["3.1516","2762.2"],["3.1553","1668.4"],["3.1554","1621.8"],["3.1557","2778.6"]],"timestamp":1756900881109,"update_id":50197303,"fetch_time":1756900881156}
{"symbol":"TONUSDT","bids":[["3.1507","20.0"],["3.1506","166.4"],["3.1505","34.6"],["3.1504","508.5"],["3.1503","603.6"],["3.1502","376.6"],["3.1496","1697.9"],["3.1494","1121.3"],["3.1457","0"],["3.1456","0"]],"asks":[["3.1510","5.0"],["3.1513","347.1"],["3.1514","1413.0"],["3.1516","2719.0"],["3.1517","1577.9"],["3.1519","3145.2"],["3.1521","1755.6"],["3.1542","5763.7"],["3.1543","2901.1"],["3.1553","401.0"]],"timestamp":1756900881129,"update_id":50197304,"fetch_time":1756900881176}
{"symbol":"TONUSDT","bids":[],"asks":[["3.1515","986.7"],["3.1552","1784.4"]],"timestamp":1756900881330,"update_id":50197314,"fetch_time":1756900881376}
{"symbol":"TONUSDT","bids":[],"asks":[["3.1515","1453.7"],["3.1517","1637.5"],["3.1525","532.1"]],"timestamp":1756900881350,"update_id":50197315,"fetch_time":1756900881396}
{"symbol":"TONUSDT","bids":[],"asks":[["3.1517","1357.0"]],"timestamp":1756900881370,"update_id":50197316,"fetch_time":1756900881421}
{"symbol":"TONUSDT","bids":[],"asks":[["3.1516","3186.0"],["3.1519","3204.6"]],"timestamp":1756900881389,"update_id":50197317,"fetch_time":1756900881437}
{"symbol":"TONUSDT","bids":[],"asks":[["3.1518","4990.6"]],"timestamp":1756900881590,"update_id":50197326,"fetch_time":1756900881640}
{"symbol":"TONUSDT","bids":[],"asks":[["3.1515","849.2"]],"timestamp":1756900881610,"update_id":50197327,"fetch_time":1756900881656}
{"symbol":"TONUSDT","bids":[],"asks":[["3.1516","1588.0"],["3.1517","2455.0"],["3.1519","3145.2"]],"timestamp":1756900881649,"update_id":50197329,"fetch_time":1756900881696}
{"symbol":"TONUSDT","bids":[],"asks":[["3.1517","2735.5"]],"timestamp":1756900881689,"update_id":50197330,"fetch_time":1756900881732}
{"symbol":"TONUSDT","bids":[],"asks":[["3.1516","1868.5"]],"timestamp":1756900881730,"update_id":50197331,"fetch_time":1756900881776}
{"symbol":"TONUSDT","bids":[],"asks":[["3.1517","2455.0"],["3.1518","4243.1"]],"timestamp":1756900881789,"update_id":50197334,"fetch_time":1756900881833}
{"symbol":"TONUSDT","bids":[],"asks":[["3.1517","1988.0"]],"timestamp":1756900881849,"update_id":50197335,"fetch_time":1756900881900}
{"symbol":"TONUSDT","bids":[["3.1506","463.0"]],"asks":[],"timestamp":1756900881909,"update_id":50197336,"fetch_time":1756900881952}
{"symbol":"TONUSDT","bids":[],"asks":[["3.1516","1588.0"],["3.1518","4523.6"]],"timestamp":1756900881989,"update_id":50197337,"fetch_time":1756900882037}
{"symbol":"TONUSDT","bids":[],"asks":[["3.1517","2268.4"]],"timestamp":1756900882090,"update_id":50197341,"fetch_time":1756900882136}
{"symbol":"TONUSDT","bids":[],"asks":[["3.1514","364.8"],["3.1515","829.2"],["3.1517","2548.7"]],"timestamp":1756900882109,"update_id":50197342,"fetch_time":1756900882156}
{"symbol":"TONUSDT","bids":[],"asks":[["3.1518","4710.3"],["3.1519","3145.2"]],"timestamp":1756900882150,"update_id":50197343,"fetch_time":1756900882196}
{"symbol":"TONUSDT","bids":[],"asks":[["3.1516","1768.2"]],"timestamp":1756900882210,"update_id":50197345,"fetch_time":1756900882257}
{"symbol":"TONUSDT","bids":[],"asks":[["3.1518","4243.1"]],"timestamp":1756900882349,"update_id":50197348,"fetch_time":1756900882401}
{"symbol":"TONUSDT","bids":[["3.1506","708.2"],["3.1504","814.7"],["3.1503","422.2"],["3.1502","1272.7"]],"asks":[],"timestamp":1756900882489,"update_id":50197349,"fetch_time":1756900882536}
{"symbol":"TONUSDT","bids":[["3.1504","1019.0"]],"asks":[],"timestamp":1756900882510,"update_id":50197350,"fetch_time":1756900882560}
{"symbol":"TONUSDT","bids":[["3.1500","645.9"]],"asks":[],"timestamp":1756900882589,"update_id":50197352,"fetch_time":1756900882637}
{"symbol":"TONUSDT","bids":[["3.1504","1495.0"]],"asks":[],"timestamp":1756900882749,"update_id":50197354,"fetch_time":1756900882797}
{"symbol":"TONUSDT","bids":[["3.1507","347.1"],["3.1506","535.0"],["3.1504","1526.7"],["3.1472","3093.8"],["3.1470","2816.4"]],"asks":[],"timestamp":1756900882770,"update_id":50197355,"fetch_time":1756900882817}
{"symbol":"TONUSDT","bids":[["3.1504","1558.2"],["3.1484","1112.5"]],"asks":[],"timestamp":1756900882790,"update_id":50197356,"fetch_time":1756900882840}
{"symbol":"TONUSDT","bids":[["3.1502","1336.1"]],"asks":[],"timestamp":1756900882810,"update_id":50197357,"fetch_time":1756900882857}
{"symbol":"TONUSDT","bids":[["3.1504","2065.9"]],"asks":[],"timestamp":1756900883069,"update_id":50197358,"fetch_time":1756900883117}
{"symbol":"TONUSDT","bids":[["3.1507","378.7"],["3.1506","688.3"],["3.1504","2097.6"]],"asks":[],"timestamp":1756900883090,"update_id":50197359,"fetch_time":1756900883137}
{"symbol":"TONUSDT","bids":[["3.1504","2129.3"]],"asks":[],"timestamp":1756900883130,"update_id":50197360,"fetch_time":1756900883177}
{"symbol":"TONUSDT","bids":[["3.1507","381.0"],["3.1486","5425.6"],["3.1482","1370.3"]],"asks":[],"timestamp":1756900883149,"update_id":50197361,"fetch_time":1756900883197}
{"symbol":"TONUSDT","bids":[],"asks":[["3.1556","1455.1"],["3.1557","3300.5"]],"timestamp":1756900883170,"update_id":50197362,"fetch_time":1756900883216}
{"symbol":"TONUSDT","bids":[["3.1506","945.2"],["3.1504","2986.0"],["3.1501","308.1"]],"asks":[],"timestamp":1756900883230,"update_id":50197364,"fetch_time":1756900883277}
{"symbol":"TONUSDT","bids":[["3.1502","1367.6"]],"asks":[],"timestamp":1756900883309,"update_id":50197365,"fetch_time":1756900883357}
{"symbol":"TONUSDT","bids":[["3.1501","339.8"]],"asks":[],"timestamp":1756900883349,"update_id":50197366,"fetch_time":1756900883397}
{"symbol":"TONUSDT","bids":[],"asks":[["3.1516","2011.4"]],"timestamp":1756900883490,"update_id":50197367,"fetch_time":1756900883541}
{"symbol":"TONUSDT","bids":[],"asks":[["3.1514","499.1"]],"timestamp":1756900883510,"update_id":50197368,"fetch_time":1756900883557}
{"symbol":"TONUSDT","bids":[],"asks":[["3.1516","2291.7"]],"timestamp":1756900883570,"update_id":50197369,"fetch_time":1756900883617}
{"symbol":"TONUSDT","bids":[],"asks":[["3.1514","793.5"]],"timestamp":1756900883629,"update_id":50197371,"fetch_time":1756900883676}
{"symbol":"TONUSDT","bids":[],"asks":[["3.1512","138.6"],["3.1525","1573.7"],["3.1529","1770.7"]],"timestamp":1756900883650,"update_id":50197372,"fetch_time":1756900883697}
{"symbol":"TONUSDT","bids":[],"asks":[["3.1517","2455.1"]],"timestamp":1756900883669,"update_id":50197373,"fetch_time":1756900883717}
{"symbol":"TONUSDT","bids":[],"asks":[["3.1516","3235.4"],["3.1517","2174.7"]],"timestamp":1756900883710,"update_id":50197374,"fetch_time":1756900883758}
{"symbol":"TONUSDT","bids":[["3.1469","507.5"]],"asks":[],"timestamp":1756900883749,"update_id":50197376,"fetch_time":1756900883793}
{"symbol":"TONUSDT","bids":[],"asks":[["3.1517","1988.0"]],"timestamp":1756900883770,"update_id":50197377,"fetch_time":1756900883822}
{"symbol":"TONUSDT","bids":[["3.1502","1399.2"]],"asks":[],"timestamp":1756900883870,"update_id":50197378,"fetch_time":1756900883921}
{"symbol":"TONUSDT","bids":[],"asks":[["3.1512","5.0"]],"timestamp":1756900883949,"update_id":50197379,"fetch_time":1756900883998}
{"symbol":"TONUSDT","bids":[["3.1505","272.9"]],"asks":[],"timestamp":1756900883969,"update_id":50197380,"fetch_time":1756900884022}
{"symbol":"TONUSDT","bids":[["3.1502","2076.4"]],"asks":[],"timestamp":1756900884150,"update_id":50197388,"fetch_time":1756900884201}
{"symbol":"TONUSDT","bids":[["3.1506","1249.1"],["3.1496","1252.9"],["3.1495","823.3"],["3.1491","1108.9"],["3.1490","1962.1"]],"asks":[],"timestamp":1756900884189,"update_id":50197390,"fetch_time":1756900884241}
{"symbol":"TONUSDT","bids":[],"asks":[["3.1520","1560.9"]],"timestamp":1756900884229,"update_id":50197391,"fetch_time":1756900884277}
{"symbol":"TONUSDT","bids":[["3.1500","989.9"],["3.1491","2978.9"],["3.1490","3832.1"],["3.1486","3555.6"],["3.1485","2120.1"]],"asks":[],"timestamp":1756900884250,"update_id":50197392,"fetch_time":1756900884301}
{"symbol":"TONUSDT","bids":[["3.1502","2139.8"],["3.1486","2716.1"]],"asks":[],"timestamp":1756900884270,"update_id":50197393,"fetch_time":1756900884318}
{"symbol":"TONUSDT","bids":[["3.1488","1775.4"]],"asks":[],"timestamp":1756900884290,"update_id":50197394,"fetch_time":1756900884342}
{"symbol":"TONUSDT","bids":[],"asks":[["3.1518","1486.4"]],"timestamp":1756900884329,"update_id":50197395,"fetch_time":1756900884378}
{"symbol":"TONUSDT","bids":[],"asks":[["3.1516","1269.0"]],"timestamp":1756900884430,"update_id":50197396,"fetch_time":1756900884477}
{"symbol":"TONUSDT","bids":[],"asks":[["3.1522","1818.3"],["3.1523","3255.7"]],"timestamp":1756900884529,"update_id":50197397,"fetch_time":1756900884577}
{"symbol":"TONUSDT","bids":[],"asks":[["3.1518","1766.7"]],"timestamp":1756900884589,"update_id":50197398,"fetch_time":1756900884637}
{"symbol":"TONUSDT","bids":[["3.1503","471.7"]],"asks":[],"timestamp":1756900884610,"update_id":50197399,"fetch_time":1756900884657}
{"symbol":"TONUSDT","bids":[["3.1503","503.4"]],"asks":[],"timestamp":1756900884650,"update_id":50197400,"fetch_time":1756900884701}
{"symbol":"TONUSDT","bids":[["3.1492","972.5"],["3.1491","3008.9"],["3.1487","1690.6"],["3.1486","2686.1"]],"asks":[],"timestamp":1756900884709,"update_id":50197402,"fetch_time":1756900884753}
{"symbol":"TONUSDT","bids":[["3.1506","1717.0"],["3.1505","894.4"],["3.1503","566.8"],["3.1482","1354.5"]],"asks":[],"timestamp":1756900884830,"update_id":50197404,"fetch_time":1756900884878}
{"symbol":"TONUSDT","bids":[["3.1484","549.5"]],"asks":[],"timestamp":1756900884850,"update_id":50197405,"fetch_time":1756900884901}
{"symbol":"TONUSDT","bids":[["3.1503","1360.1"]],"asks":[],"timestamp":1756900884890,"update_id":50197406,"fetch_time":1756900884940}
{"symbol":"TONUSDT","bids":[],"asks":[["3.1516","1455.9"]],"timestamp":1756900884969,"update_id":50197407,"fetch_time":1756900885016}
{"symbol":"TONUSDT","bids":[["3.1505","912.0"]],"asks":[],"timestamp":1756900884989,"update_id":50197408,"fetch_time":1756900885032}
{"symbol":"TONUSDT","bids":[["3.1504","3192.4"]],"asks":[],"timestamp":1756900885010,"update_id":50197409,"fetch_time":1756900885061}
{"symbol":"TONUSDT","bids":[["3.1503","1709.1"],["3.1502","2615.8"]],"asks":[],"timestamp":1756900885030,"update_id":50197410,"fetch_time":1756900885076}
{"symbol":"TONUSDT","bids":[],"asks":[["3.1517","961.1"]],"timestamp":1756900885069,"update_id":50197412,"fetch_time":1756900885112}
{"symbol":"TONUSDT","bids":[],"asks":[["3.1517","1241.4"],["3.1522","3031.0"],["3.1523","3042.4"]],"timestamp":1756900885210,"update_id":50197416,"fetch_time":1756900885257}
{"symbol":"TONUSDT","bids":[],"asks":[["3.1517","1428.1"]],"timestamp":1756900885229,"update_id":50197417,"fetch_time":1756900885272}
{"symbol":"TONUSDT","bids":[],"asks":[["3.1518","1580.0"]],"timestamp":1756900885270,"update_id":50197418,"fetch_time":1756900885321}
{"symbol":"TONUSDT","bids":[],"asks":[["3.1518","1299.7"]],"timestamp":1756900885309,"update_id":50197419,"fetch_time":1756900885352}
{"symbol":"TONUSDT","bids":[["3.1505","1229.3"],["3.1488","1584.4"]],"asks":[],"timestamp":1756900885330,"update_id":50197420,"fetch_time":1756900885376}
{"symbol":"TONUSDT","bids":[["3.1505","1211.7"]],"asks":[],"timestamp":1756900885430,"update_id":50197421,"fetch_time":1756900885476}
{"symbol":"TONUSDT","bids":[["3.1508","93.4"],["3.1458","0"]],"asks":[["3.1508","0"],["3.1558","1612.8"]],"timestamp":1756900885729,"update_id":50197422,"fetch_time":1756900885777}
{"symbol":"TONUSDT","bids":[["3.1509","20.0"],["3.1508","753.0"],["3.1507","358.6"],["3.1506","2224.9"],["3.1505","896.8"],["3.1504","3002.5"],["3.1492","2375.4"],["3.1468","5301.0"],["3.1462","727.6"],["3.1459","0"]],"asks":[["3.1509","0"],["3.1510","1.8"],["3.1528","3167.2"],["3.1530","3616.0"],["3.1533","749.5"],["3.1536","1948.4"],["3.1539","2412.6"],["3.1542","5123.9"],["3.1543","926.0"],["3.1545","1010.7"],["3.1559","1163.7"]],"timestamp":1756900885749,"update_id":50197423,"fetch_time":1756900885796}
{"symbol":"TONUSDT","bids":[["3.1510","91.6"],["3.1508","601.9"],["3.1507","675.9"],["3.1506","3937.5"],["3.1505","959.5"],["3.1504","1353.3"],["3.1503","2309.0"],["3.1462","743.4"],["3.1460","0"]],"asks":[["3.1510","0"],["3.1524","3665.4"],["3.1529","1975.9"],["3.1533","1591.1"],["3.1536","2003.6"],["3.1541","1573.9"],["3.1542","4639.0"],["3.1545","1198.9"],["3.1547","1684.9"],["3.1549","843.1"],["3.1551","2271.7"],["3.1553","1040.8"],["3.1555","1620.1"],["3.1560","1696.1"]],"timestamp":1756900885770,"update_id":50197424,"fetch_time":1756900885816}
{"symbol":"TONUSDT","bids":[["3.1510","149.3"],["3.1509","0"],["3.1508","1318.1"],["3.1507","837.7"],["3.1506","2866.6"],["3.1505","1686.1"],["3.1504","1508.8"],["3.1503","437.0"],["3.1502","1483.0"],["3.1501","276.4"],["3.1500","929.6"],["3.1486","2493.3"],["3.1468","7106.8"],["3.1467","7993.5"],["3.1460","1981.2"]],"asks":[["3.1511","0"],["3.1512","1.8"],["3.1513","5.6"],["3.1516","1088.8"],["3.1523","2822.6"],["3.1526","1544.3"],["3.1528","3123.0"],["3.1534","1194.0"],["3.1536","1658.9"],["3.1542","4683.2"],["3.1545","1196.9"],["3.1547","1686.9"],["3.1548","2397.9"],["3.1561","1547.8"]],"timestamp":1756900885789,"update_id":50197425,"fetch_time":1756900885837}
{"symbol":"TONUSDT","bids":[["3.1512","89.8"],["3.1510","57.7"],["3.1506","3498.0"],["3.1505","1929.3"],["3.1504","893.0"],["3.1502","1049.1"],["3.1486","2548.5"],["3.1485","2175.3"],["3.1484","604.7"],["3.1480","1092.8"],["3.1476","2006.1"],["3.1474","967.3"],["3.1473","980.1"],["3.1469","562.7"],["3.1468","6996.4"],["3.1460","0"]],"asks":[["3.1512","0"],["3.1514","169.8"],["3.1516","755.3"],["3.1518","1542.9"],["3.1534","930.2"],["3.1562","3289.9"]],"timestamp":1756900885809,"update_id":50197426,"fetch_time":1756900885856}
{"symbol":"TONUSDT","bids":[["3.1510","39.5"],["3.1509","173.4"],["3.1508","1320.5"],["3.1507","1061.0"],["3.1506","3529.5"],["3.1505","1992.7"],["3.1504","734.4"],["3.1502","1225.5"],["3.1501","513.7"],["3.1500","1365.2"],["3.1499","1514.0"],["3.1494","1287.8"],["3.1493","1609.6"],["3.1488","2651.6"],["3.1487","1409.0"],["3.1461","0"]],"asks":[["3.1513","2.4"],["3.1514","25.0"],["3.1517","821.1"],["3.1518","1729.8"],["3.1519","11.9"],["3.1522","2817.7"],["3.1528","3067.8"],["3.1529","2243.3"],["3.1530","3560.8"],["3.1535","738.4"],["3.1538","1989.7"],["3.1540","2319.9"],["3.1545","1241.1"],["3.1547","1684.9"],["3.1548","2399.9"],["3.1550","3800.1"],["3.1552","3376.6"],["3.1554","2580.8"],["3.1557","1765.8"],["3.1558","2880.0"]],"timestamp":1756900885829,"update_id":50197427,"fetch_time":1756900885873}
{"symbol":"TONUSDT","bids":[["3.1512","0"],["3.1510","0"],["3.1509","176.6"],["3.1508","1292.1"],["3.1507","849.3"],["3.1506","3570.0"],["3.1505","2073.7"],["3.1502","1405.4"],["3.1501","510.9"],["3.1500","1321.9"],["3.1499","1470.7"],["3.1498","1247.8"],["3.1494","1670.0"],["3.1487","1218.0"],["3.1480","1108.6"],["3.1461","897.3"],["3.1460","1981.2"]],"asks":[["3.1518","1052.8"],["3.1521","958.1"]],"timestamp":1756900885850,"update_id":50197428,"fetch_time":1756900885896}
{"symbol":"TONUSDT","bids":[["3.1510","20.0"],["3.1508","572.7"],["3.1507","591.6"],["3.1506","1378.1"],["3.1505","1540.0"],["3.1504","671.0"],["3.1460","0"]],"asks":[["3.1548","2399.9"]],"timestamp":1756900885889,"update_id":50197430,"fetch_time":1756900885932}
{"symbol":"TONUSDT","bids":[["3.1504","809.8"],["3.1503","232.5"],["3.1486","2357.5"]],"asks":[],"timestamp":1756900885970,"update_id":50197433,"fetch_time":1756900886016}
{"symbol":"TONUSDT","bids":[["3.1509","387.2"],["3.1508","712.6"]],"asks":[],"timestamp":1756900886029,"update_id":50197434,"fetch_time":1756900886076}
{"symbol":"TONUSDT","bids":[["3.1509","173.4"]],"asks":[],"timestamp":1756900886089,"update_id":50197436,"fetch_time":1756900886133}
{"symbol":"TONUSDT","bids":[["3.1508","905.0"],["3.1492","3177.1"],["3.1481","855.6"]],"asks":[],"timestamp":1756900886130,"update_id":50197437,"fetch_time":1756900886177}
{"symbol":"TONUSDT","bids":[["3.1494","1947.0"],["3.1486","2166.5"]],"asks":[],"timestamp":1756900886149,"update_id":50197438,"fetch_time":1756900886192}
{"symbol":"TONUSDT","bids":[["3.1485","1984.3"]],"asks":[],"timestamp":1756900886409,"update_id":50197441,"fetch_time":1756900886460}
{"symbol":"TONUSDT","bids":[["3.1507","563.5"],["3.1500","1362.1"]],"asks":[],"timestamp":1756900886430,"update_id":50197442,"fetch_time":1756900886476}
{"symbol":"TONUSDT","bids":[["3.1508","873.4"],["3.1505","1003.9"]],"asks":[],"timestamp":1756900886469,"update_id":50197443,"fetch_time":1756900886512}
{"symbol":"TONUSDT","bids":[["3.1506","1107.5"],["3.1486","2151.7"]],"asks":[],"timestamp":1756900886490,"update_id":50197444,"fetch_time":1756900886537}
{"symbol":"TONUSDT","bids":[["3.1488","2460.6"]],"asks":[],"timestamp":1756900886510,"update_id":50197445,"fetch_time":1756900886557}
{"symbol":"TONUSDT","bids":[["3.1508","752.6"]],"asks":[],"timestamp":1756900886550,"update_id":50197446,"fetch_time":1756900886597}
{"symbol":"TONUSDT","bids":[["3.1509","158.6"],["3.1504","717.7"],["3.1501","364.4"]],"asks":[],"timestamp":1756900886570,"update_id":50197447,"fetch_time":1756900886616}
{"symbol":"TONUSDT","bids":[["3.1506","1067.0"]],"asks":[],"timestamp":1756900886610,"update_id":50197449,"fetch_time":1756900886656}
{"symbol":"TONUSDT","bids":[["3.1487","1201.9"]],"asks":[],"timestamp":1756900886629,"update_id":50197450,"fetch_time":1756900886672}
{"symbol":"TONUSDT","bids":[["3.1493","1803.7"]],"asks":[],"timestamp":1756900886650,"update_id":50197451,"fetch_time":1756900886692}
{"symbol":"TONUSDT","bids":[["3.1506","1063.1"]],"asks":[],"timestamp":1756900886749,"update_id":50197453,"fetch_time":1756900886796}
{"symbol":"TONUSDT","bids":[["3.1507","494.6"]],"asks":[],"timestamp":1756900886770,"update_id":50197454,"fetch_time":1756900886816}
{"symbol":"TONUSDT","bids":[["3.1512","25.8"],["3.1488","2458.8"],["3.1461","0"]],"asks":[],"timestamp":1756900886789,"update_id":50197455,"fetch_time":1756900886840}
{"symbol":"TONUSDT","bids":[["3.1510","0"],["3.1461","897.3"]],"asks":[],"timestamp":1756900886809,"update_id":50197456,"fetch_time":1756900886852}
{"symbol":"TONUSDT","bids":[["3.1509","161.8"],["3.1508","753.5"],["3.1507","549.4"],["3.1506","1249.8"]],"asks":[],"timestamp":1756900886829,"update_id":50197457,"fetch_time":1756900886876}
{"symbol":"TONUSDT","bids":[["3.1512","34.7"],["3.1506","1229.9"],["3.1505","1026.8"],["3.1504","748.4"],["3.1501","324.2"],["3.1498","1204.6"],["3.1497","808.5"]],"asks":[],"timestamp":1756900886850,"update_id":50197458,"fetch_time":1756900886901}
{"symbol":"TONUSDT","bids":[["3.1505","963.4"],["3.1504","561.7"],["3.1496","1533.9"],["3.1488","2455.5"]],"asks":[],"timestamp":1756900886889,"update_id":50197459,"fetch_time":1756900886984}
{"symbol":"TONUSDT","bids":[["3.1510","58.3"],["3.1504","564.0"],["3.1461","0"]],"asks":[["3.1514","5.0"],["3.1515","22.5"]],"timestamp":1756900887010,"update_id":50197462,"fetch_time":1756900887055}
{"symbol":"TONUSDT","bids":[["3.1507","589.6"]],"asks":[],"timestamp":1756900887029,"update_id":50197463,"fetch_time":1756900887075}
{"symbol":"TONUSDT","bids":[["3.1507","558.1"]],"asks":[],"timestamp":1756900887230,"update_id":50197464,"fetch_time":1756900887275}
{"symbol":"TONUSDT","bids":[["3.1508","753.5"]],"asks":[],"timestamp":1756900887289,"update_id":50197466,"fetch_time":1756900887335}
{"symbol":"TONUSDT","bids":[["3.1506","1491.3"]],"asks":[],"timestamp":1756900887469,"update_id":50197467,"fetch_time":1756900887515}
{"symbol":"TONUSDT","bids":[],"asks":[["3.1519","894.5"]],"timestamp":1756900887710,"update_id":50197468,"fetch_time":1756900887755}
{"symbol":"TONUSDT","bids":[["3.1488","2134.3"]],"asks":[],"timestamp":1756900887750,"update_id":50197469,"fetch_time":1756900887795}
{"symbol":"TONUSDT","bids":[["3.1508","793.7"]],"asks":[],"timestamp":1756900887810,"update_id":50197470,"fetch_time":1756900887859}
{"symbol":"TONUSDT","bids":[],"asks":[["3.1558","1612.8"]],"timestamp":1756900887889,"update_id":50197471,"fetch_time":1756900887943}
{"symbol":"TONUSDT","bids":[],"asks":[["3.1557","3033.0"]],"timestamp":1756900887930,"update_id":50197472,"fetch_time":1756900887975}
{"symbol":"TONUSDT","bids":[],"asks":[["3.1557","1765.8"],["3.1558","2880.0"]],"timestamp":1756900887950,"update_id":50197473,"fetch_time":1756900887996}
{"symbol":"TONUSDT","bids":[["3.1505","725.4"]],"asks":[],"timestamp":1756900888010,"update_id":50197474,"fetch_time":1756900888059}
{"symbol":"TONUSDT","bids":[],"asks":[["3.1545","1597.6"],["3.1546","1585.1"]],"timestamp":1756900888089,"update_id":50197476,"fetch_time":1756900888135}
{"symbol":"TONUSDT","bids":[["3.1507","509.8"],["3.1506","1082.1"]],"asks":[],"timestamp":1756900888289,"update_id":50197477,"fetch_time":1756900888339}
{"symbol":"TONUSDT","bids":[["3.1490","3895.6"]],"asks":[],"timestamp":1756900888570,"update_id":50197478,"fetch_time":1756900888615}
{"symbol":"TONUSDT","bids":[],"asks":[["3.1516","776.4"],["3.1518","1318.1"]],"timestamp":1756900888689,"update_id":50197481,"fetch_time":1756900888736}
{"symbol":"TONUSDT","bids":[],"asks":[["3.1521","1406.6"],["3.1522","2817.7"]],"timestamp":1756900888809,"update_id":50197483,"fetch_time":1756900888855}
{"symbol":"TONUSDT","bids":[["3.1503","216.7"]],"asks":[],"timestamp":1756900888830,"update_id":50197484,"fetch_time":1756900888880}
{"symbol":"TONUSDT","bids":[],"asks":[["3.1524","3885.4"]],"timestamp":1756900888889,"update_id":50197485,"fetch_time":1756900888940}
{"symbol":"TONUSDT","bids":[["3.1508","517.3"]],"asks":[],"timestamp":1756900889009,"update_id":50197486,"fetch_time":1756900889064}
{"symbol":"TONUSDT","bids":[],"asks":[["3.1557","3033.0"],["3.1558","1612.8"]],"timestamp":1756900889029,"update_id":50197487,"fetch_time":1756900889080}
{"symbol":"TONUSDT","bids":[],"asks":[["3.1557","1765.8"],["3.1558","2880.0"]],"timestamp":1756900889069,"update_id":50197488,"fetch_time":1756900889125}
{"symbol":"TONUSDT","bids":[],"asks":[["3.1557","3033.0"],["3.1558","1612.8"]],"timestamp":1756900889110,"update_id":50197489,"fetch_time":1756900889156}
{"symbol":"TONUSDT","bids":[],"asks":[["3.1557","1765.8"],["3.1558","2880.0"]],"timestamp":1756900889229,"update_id":50197491,"fetch_time":1756900889276}
{"symbol":"TONUSDT","bids":[],"asks":[["3.1557","3033.0"],["3.1558","1612.8"]],"timestamp":1756900889290,"update_id":50197492,"fetch_time":1756900889335}
{"symbol":"TONUSDT","bids":[["3.1488","2070.8"]],"asks":[],"timestamp":1756900889450,"update_id":50197493,"fetch_time":1756900889503}
{"symbol":"TONUSDT","bids":[["3.1507","106.8"],["3.1506","1291.1"]],"asks":[],"timestamp":1756900889890,"update_id":50197495,"fetch_time":1756900889936}
{"symbol":"TONUSDT","bids":[["3.1474","1797.7"],["3.1464","1533.0"]],"asks":[],"timestamp":1756900890169,"update_id":50197498,"fetch_time":1756900890216}
{"symbol":"TONUSDT","bids":[["3.1485","1791.1"]],"asks":[],"timestamp":1756900890269,"update_id":50197501,"fetch_time":1756900890316}
{"symbol":"TONUSDT","bids":[["3.1495","1192.8"]],"asks":[],"timestamp":1756900890290,"update_id":50197502,"fetch_time":1756900890340}
{"symbol":"TONUSDT","bids":[["3.1507","275.6"],["3.1506","1041.9"]],"asks":[],"timestamp":1756900890330,"update_id":50197503,"fetch_time":1756900890376}
{"symbol":"TONUSDT","bids":[],"asks":[["3.1518","1318.1"],["3.1519","934.7"],["3.1520","1905.9"],["3.1521","1226.6"]],"timestamp":1756900890709,"update_id":50197508,"fetch_time":1756900890755}
{"symbol":"TONUSDT","bids":[["3.1506","1250.9"],["3.1505","741.2"],["3.1504","420.4"],["3.1503","216.7"]],"asks":[],"timestamp":1756900890809,"update_id":50197509,"fetch_time":1756900890855}
{"symbol":"TONUSDT","bids":[["3.1506","1041.9"]],"asks":[],"timestamp":1756900890890,"update_id":50197511,"fetch_time":1756900890939}
{"symbol":"TONUSDT","bids":[["3.1473","2785.9"],["3.1468","5190.6"]],"asks":[],"timestamp":1756900891290,"update_id":50197512,"fetch_time":1756900891335}
{"symbol":"TONUSDT","bids":[],"asks":[["3.1519","966.4"]],"timestamp":1756900891310,"update_id":50197513,"fetch_time":1756900891355}
{"symbol":"TONUSDT","bids":[],"asks":[["3.1518","1349.7"],["3.1519","971.0"]],"timestamp":1756900891450,"update_id":50197514,"fetch_time":1756900891495}
{"symbol":"TONUSDT","bids":[["3.1510","0"],["3.1461","897.3"]],"asks":[],"timestamp":1756900891490,"update_id":50197516,"fetch_time":1756900891536}
{"symbol":"TONUSDT","bids":[],"asks":[["3.1517","901.5"]],"timestamp":1756900891509,"update_id":50197517,"fetch_time":1756900891555}
{"symbol":"TONUSDT","bids":[],"asks":[["3.1518","1318.1"]],"timestamp":1756900891650,"update_id":50197519,"fetch_time":1756900891699}
{"symbol":"TONUSDT","bids":[],"asks":[["3.1557","1765.8"],["3.1558","2632.9"]],"timestamp":1756900891669,"update_id":50197520,"fetch_time":1756900891715}
{"symbol":"TONUSDT","bids":[],"asks":[["3.1520","1641.3"]],"timestamp":1756900891749,"update_id":50197521,"fetch_time":1756900891799}
{"symbol":"TONUSDT","bids":[],"asks":[["3.1516","434.2"],["3.1517","161.8"]],"timestamp":1756900891810,"update_id":50197524,"fetch_time":1756900891859}
{"symbol":"TONUSDT","bids":[["3.1510","195.9"],["3.1499","1629.2"],["3.1461","0"]],"asks":[],"timestamp":1756900892050,"update_id":50197527,"fetch_time":1756900892095}
{"symbol":"TONUSDT","bids":[["3.1510","0"],["3.1461","897.3"]],"asks":[],"timestamp":1756900892109,"update_id":50197528,"fetch_time":1756900892155}
{"symbol":"TONUSDT","bids":[],"asks":[["3.1519","899.2"]],"timestamp":1756900892389,"update_id":50197529,"fetch_time":1756900892435}
{"symbol":"TONUSDT","bids":[["3.1497","811.5"]],"asks":[],"timestamp":1756900892409,"update_id":50197530,"fetch_time":1756900892455}
{"symbol":"TONUSDT","bids":[],"asks":[["3.1520","2102.3"],["3.1521","2484.7"]],"timestamp":1756900892470,"update_id":50197531,"fetch_time":1756900892515}
{"symbol":"TONUSDT","bids":[],"asks":[["3.1519","894.6"]],"timestamp":1756900892970,"update_id":50197532,"fetch_time":1756900893015}
{"symbol":"TONUSDT","bids":[],"asks":[["3.1519","862.9"]],"timestamp":1756900893029,"update_id":50197533,"fetch_time":1756900893075}
{"symbol":"TONUSDT","bids":[],"asks":[["3.1518","1318.1"],["3.1519","903.1"]],"timestamp":1756900893070,"update_id":50197535,"fetch_time":1756900893115}
{"symbol":"TONUSDT","bids":[],"asks":[["3.1515","44.7"]],"timestamp":1756900893089,"update_id":50197536,"fetch_time":1756900893135}
{"symbol":"TONUSDT","bids":[],"asks":[["3.1557","1765.8"],["3.1558","2632.9"]],"timestamp":1756900893369,"update_id":50197540,"fetch_time":1756900893415}
{"symbol":"TONUSDT","bids":[],"asks":[["3.1557","3033.0"],["3.1558","1365.7"]],"timestamp":1756900893390,"update_id":50197541,"fetch_time":1756900893435}
{"symbol":"TONUSDT","bids":[],"asks":[["3.1557","1765.8"],["3.1558","2632.9"]],"timestamp":1756900893430,"update_id":50197542,"fetch_time":1756900893475}
{"symbol":"TONUSDT","bids":[],"asks":[["3.1524","3821.9"]],"timestamp":1756900893570,"update_id":50197543,"fetch_time":1756900893615}
{"symbol":"TONUSDT","bids":[],"asks":[["3.1557","3033.0"],["3.1558","1365.7"]],"timestamp":1756900893649,"update_id":50197544,"fetch_time":1756900893699}
{"symbol":"TONUSDT","bids":[],"asks":[["3.1557","1765.8"],["3.1558","2632.9"]],"timestamp":1756900893670,"update_id":50197545,"fetch_time":1756900893715}
{"symbol":"TONUSDT","bids":[],"asks":[["3.1518","1318.1"]],"timestamp":1756900893970,"update_id":50197547,"fetch_time":1756900894015}
{"symbol":"TONUSDT","bids":[["3.1499","1470.7"],["3.1494","2105.5"]],"asks":[],"timestamp":1756900894070,"update_id":50197549,"fetch_time":1756900894120}
{"symbol":"TONUSDT","bids":[],"asks":[["3.1557","3033.0"],["3.1558","1365.7"]],"timestamp":1756900894209,"update_id":50197550,"fetch_time":1756900894255}
{"symbol":"TONUSDT","bids":[],"asks":[["3.1557","1765.8"],["3.1558","2632.9"]],"timestamp":1756900894289,"update_id":50197551,"fetch_time":1756900894335}
{"symbol":"TONUSDT","bids":[],"asks":[["3.1520","1567.0"]],"timestamp":1756900894529,"update_id":50197555,"fetch_time":1756900894575}
{"symbol":"TONUSDT","bids":[],"asks":[["3.1520","1848.1"],["3.1523","3351.8"],["3.1545","1052.9"],["3.1548","3330.9"]],"timestamp":1756900894549,"update_id":50197556,"fetch_time":1756900894595}
{"symbol":"TONUSDT","bids":[],"asks":[["3.1517","161.8"],["3.1518","494.9"],["3.1525","863.1"],["3.1544","3025.2"]],"timestamp":1756900894570,"update_id":50197557,"fetch_time":1756900894615}
{"symbol":"TONUSDT","bids":[],"asks":[["3.1519","1052.3"]],"timestamp":1756900894589,"update_id":50197558,"fetch_time":1756900894635}
{"symbol":"TONUSDT","bids":[],"asks":[["3.1518","702.0"],["3.1519","1092.5"],["3.1557","973.8"],["3.1562","4081.8"]],"timestamp":1756900894609,"update_id":50197559,"fetch_time":1756900894655}
{"symbol":"TONUSDT","bids":[],"asks":[["3.1516","326.3"],["3.1520","1660.9"],["3.1522","3139.0"],["3.1546","2004.5"]],"timestamp":1756900894630,"update_id":50197560,"fetch_time":1756900894675}
{"symbol":"TONUSDT","bids":[],"asks":[["3.1518","742.2"],["3.1520","1379.8"],["3.1522","2857.9"]],"timestamp":1756900894649,"update_id":50197561,"fetch_time":1756900894695}
{"symbol":"TONUSDT","bids":[],"asks":[["3.1521","2256.4"]],"timestamp":1756900894689,"update_id":50197562,"fetch_time":1756900894735}
{"symbol":"TONUSDT","bids":[],"asks":[["3.1517","202.0"]],"timestamp":1756900894710,"update_id":50197563,"fetch_time":1756900894755}
{"symbol":"TONUSDT","bids":[["3.1510","300.2"],["3.1508","383.8"],["3.1477","722.4"],["3.1469","463.3"],["3.1461","0"]],"asks":[["3.1525","793.8"],["3.1530","5051.9"],["3.1550","3367.0"],["3.1556","1865.4"],["3.1558","1690.0"]],"timestamp":1756900894790,"update_id":50197565,"fetch_time":1756900894835}
{"symbol":"TONUSDT","bids":[],"asks":[["3.1516","145.9"],["3.1559","2182.6"],["3.1560","1409.6"]],"timestamp":1756900894830,"update_id":50197567,"fetch_time":1756900894875}
{"symbol":"TONUSDT","bids":[],"asks":[["3.1559","915.4"],["3.1560","2676.7"]],"timestamp":1756900894850,"update_id":50197568,"fetch_time":1756900894895}
{"symbol":"TONUSDT","bids":[],"asks":[["3.1521","1964.2"]],"timestamp":1756900894869,"update_id":50197569,"fetch_time":1756900894915}
{"symbol":"TONUSDT","bids":[],"asks":[["3.1520","1339.6"]],"timestamp":1756900894889,"update_id":50197570,"fetch_time":1756900894935}
{"symbol":"TONUSDT","bids":[],"asks":[["3.1519","1065.3"],["3.1520","1379.8"]],"timestamp":1756900894910,"update_id":50197571,"fetch_time":1756900894955}
{"symbol":"TONUSDT","bids":[],"asks":[["3.1519","1105.5"],["3.1560","2676.8"]],"timestamp":1756900894929,"update_id":50197572,"fetch_time":1756900894975}
{"symbol":"TONUSDT","bids":[],"asks":[["3.1517","161.8"],["3.1531","3460.1"],["3.1540","5435.0"]],"timestamp":1756900894950,"update_id":50197573,"fetch_time":1756900894995}
{"symbol":"TONUSDT","bids":[],"asks":[["3.1530","4319.3"],["3.1559","2182.6"],["3.1560","1409.6"]],"timestamp":1756900894970,"update_id":50197574,"fetch_time":1756900895015}
{"symbol":"TONUSDT","bids":[],"asks":[["3.1559","2182.6"],["3.1560","1409.6"]],"timestamp":1756900895029,"update_id":50197576,"fetch_time":1756900895079}
{"symbol":"TONUSDT","bids":[],"asks":[["3.1559","915.4"],["3.1560","2676.8"]],"timestamp":1756900895049,"update_id":50197577,"fetch_time":1756900895095}
{"symbol":"TONUSDT","bids":[],"asks":[["3.1559","2182.6"],["3.1560","1409.6"]],"timestamp":1756900895070,"update_id":50197578,"fetch_time":1756900895115}
{"symbol":"TONUSDT","bids":[],"asks":[["3.1559","915.4"],["3.1560","2676.8"]],"timestamp":1756900895089,"update_id":50197579,"fetch_time":1756900895139}
{"symbol":"TONUSDT","bids":[["3.1510","238.0"]],"asks":[],"timestamp":1756900895109,"update_id":50197580,"fetch_time":1756900895155}
{"symbol":"TONUSDT","bids":[["3.1510","547.2"]],"asks":[],"timestamp":1756900895130,"update_id":50197581,"fetch_time":1756900895175}
{"symbol":"TONUSDT","bids":[],"asks":[["3.1523","3126.2"]],"timestamp":1756900895350,"update_id":50197583,"fetch_time":1756900895395}
{"symbol":"TONUSDT","bids":[["3.1508","324.3"]],"asks":[],"timestamp":1756900895369,"update_id":50197584,"fetch_time":1756900895415}
{"symbol":"TONUSDT","bids":[["3.1510","238.0"]],"asks":[],"timestamp":1756900895409,"update_id":50197586,"fetch_time":1756900895455}
{"symbol":"TONUSDT","bids":[],"asks":[["3.1516","186.1"]],"timestamp":1756900895430,"update_id":50197587,"fetch_time":1756900895475}
{"symbol":"TONUSDT","bids":[],"asks":[["3.1517","242.2"]],"timestamp":1756900895450,"update_id":50197588,"fetch_time":1756900895500}
{"symbol":"TONUSDT","bids":[],"asks":[["3.1513","142.4"]],"timestamp":1756900895510,"update_id":50197590,"fetch_time":1756900895555}
{"symbol":"TONUSDT","bids":[["3.1510","0"],["3.1508","165.7"],["3.1507","577.5"],["3.1506","1041.9"],["3.1505","644.7"],["3.1504","355.6"],["3.1503","144.2"],["3.1502","1325.9"],["3.1501","283.7"],["3.1461","897.3"]],"asks":[["3.1514","12.0"],["3.1515","46.2"],["3.1516","361.1"],["3.1558","2957.2"],["3.1560","1409.6"]],"timestamp":1756900895529,"update_id":50197591,"fetch_time":1756900895580}
{"symbol":"TONUSDT","bids":[],"asks":[["3.1548","3857.4"]],"timestamp":1756900895569,"update_id":50197593,"fetch_time":1756900895619}
{"symbol":"TONUSDT","bids":[["3.1502","1366.1"]],"asks":[],"timestamp":1756900895649,"update_id":50197594,"fetch_time":1756900895695}
{"symbol":"TONUSDT","bids":[],"asks":[["3.1514","12.3"],["3.1521","2004.4"]],"timestamp":1756900895669,"update_id":50197595,"fetch_time":1756900895715}
{"symbol":"TONUSDT","bids":[],"asks":[["3.1514","5.0"],["3.1522","2712.1"]],"timestamp":1756900895690,"update_id":50197596,"fetch_time":1756900895735}
{"symbol":"TONUSDT","bids":[["3.1503","184.4"]],"asks":[],"timestamp":1756900895730,"update_id":50197597,"fetch_time":1756900895776}
{"symbol":"TONUSDT","bids":[["3.1508","612.3"]],"asks":[],"timestamp":1756900895809,"update_id":50197599,"fetch_time":1756900895856}
{"symbol":"TONUSDT","bids":[["3.1512","0"],["3.1507","603.8"],["3.1506","1077.6"],["3.1505","930.6"],["3.1504","411.8"],["3.1502","1406.3"],["3.1501","323.9"],["3.1460","1981.2"]],"asks":[],"timestamp":1756900895889,"update_id":50197600,"fetch_time":1756900895940}
{"symbol":"TONUSDT","bids":[],"asks":[["3.1515","205.8"]],"timestamp":1756900895990,"update_id":50197605,"fetch_time":1756900896035}
{"symbol":"TONUSDT","bids":[],"asks":[["3.1515","67.7"],["3.1520","1339.6"],["3.1538","3019.6"]],"timestamp":1756900896010,"update_id":50197606,"fetch_time":1756900896055}
{"symbol":"TONUSDT","bids":[["3.1510","20.0"],["3.1460","0"]],"asks":[["3.1515","245.1"],["3.1526","1544.3"]],"timestamp":1756900896030,"update_id":50197607,"fetch_time":1756900896075}
{"symbol":"TONUSDT","bids":[],"asks":[["3.1514","146.3"],["3.1515","67.7"]],"timestamp":1756900896050,"update_id":50197608,"fetch_time":1756900896095}
{"symbol":"TONUSDT","bids":[],"asks":[["3.1514","5.0"]],"timestamp":1756900896070,"update_id":50197609,"fetch_time":1756900896115}
{"symbol":"TONUSDT","bids":[],"asks":[["3.1514","146.3"],["3.1515","67.7"]],"timestamp":1756900896109,"update_id":50197611,"fetch_time":1756900896155}
{"symbol":"TONUSDT","bids":[],"asks":[["3.1514","146.3"],["3.1515","67.7"]],"timestamp":1756900896169,"update_id":50197614,"fetch_time":1756900896220}
{"symbol":"TONUSDT","bids":[["3.1503","223.7"],["3.1502","1405.4"],["3.1491","3215.7"]],"asks":[],"timestamp":1756900896289,"update_id":50197616,"fetch_time":1756900896335}
{"symbol":"TONUSDT","bids":[],"asks":[["3.1556","2813.4"]],"timestamp":1756900896330,"update_id":50197617,"fetch_time":1756900896376}
{"symbol":"TONUSDT","bids":[],"asks":[["3.1515","53.2"]],"timestamp":1756900896689,"update_id":50197621,"fetch_time":1756900896739}
{"symbol":"TONUSDT","bids":[],"asks":[["3.1556","1865.4"],["3.1558","1365.7"],["3.1559","2182.6"]],"timestamp":1756900896730,"update_id":50197622,"fetch_time":1756900896779}
{"symbol":"TONUSDT","bids":[["3.1508","909.0"],["3.1507","236.4"]],"asks":[],"timestamp":1756900896889,"update_id":50197623,"fetch_time":1756900896935}
{"symbol":"TONUSDT","bids":[],"asks":[["3.1529","2514.0"]],"timestamp":1756900896989,"update_id":50197624,"fetch_time":1756900897035}
{"symbol":"TONUSDT","bids":[],"asks":[["3.1548","4660.0"]],"timestamp":1756900897029,"update_id":50197625,"fetch_time":1756900897075}
{"symbol":"TONUSDT","bids":[],"asks":[["3.1546","2988.6"],["3.1548","3682.0"]],"timestamp":1756900897069,"update_id":50197626,"fetch_time":1756900897119}
{"symbol":"TONUSDT","bids":[],"asks":[["3.1529","3571.7"]],"timestamp":1756900897150,"update_id":50197627,"fetch_time":1756900897195}
{"symbol":"TONUSDT","bids":[],"asks":[["3.1532","2160.7"]],"timestamp":1756900897169,"update_id":50197628,"fetch_time":1756900897216}
{"symbol":"TONUSDT","bids":[["3.1504","619.6"]],"asks":[],"timestamp":1756900897269,"update_id":50197629,"fetch_time":1756900897315}
{"symbol":"TONUSDT","bids":[["3.1511","3.0"],["3.1461","0"]],"asks":[],"timestamp":1756900897290,"update_id":50197630,"fetch_time":1756900897335}
{"symbol":"TONUSDT","bids":[["3.1510","7.1"]],"asks":[],"timestamp":1756900897309,"update_id":50197631,"fetch_time":1756900897355}
{"symbol":"TONUSDT","bids":[["3.1506","997.2"],["3.1505","974.0"]],"asks":[],"timestamp":1756900897350,"update_id":50197632,"fetch_time":1756900897399}
{"symbol":"TONUSDT","bids":[["3.1508","912.2"]],"asks":[],"timestamp":1756900897370,"update_id":50197633,"fetch_time":1756900897415}
{"symbol":"TONUSDT","bids":[["3.1505","910.6"]],"asks":[],"timestamp":1756900897389,"update_id":50197634,"fetch_time":1756900897435}
{"symbol":"TONUSDT","bids":[["3.1504","432.3"]],"asks":[],"timestamp":1756900897450,"update_id":50197635,"fetch_time":1756900897499}
{"symbol":"TONUSDT","bids":[],"asks":[["3.1531","4301.6"]],"timestamp":1756900897529,"update_id":50197636,"fetch_time":1756900897575}
{"symbol":"TONUSDT","bids":[["3.1511","12.0"],["3.1506","991.9"]],"asks":[],"timestamp":1756900897569,"update_id":50197637,"fetch_time":1756900897615}
{"symbol":"TONUSDT","bids":[["3.1510","0"],["3.1508","889.2"],["3.1506","952.6"],["3.1461","897.3"]],"asks":[["3.1517","240.4"],["3.1520","1378.9"],["3.1522","2671.9"]],"timestamp":1756900897869,"update_id":50197638,"fetch_time":1756900897915}
{"symbol":"TONUSDT","bids":[],"asks":[["3.1536","2198.0"]],"timestamp":1756900897950,"update_id":50197642,"fetch_time":1756900897995}
{"symbol":"TONUSDT","bids":[],"asks":[["3.1515","83.0"],["3.1556","2433.2"]],"timestamp":1756900898029,"update_id":50197643,"fetch_time":1756900898075}
{"symbol":"TONUSDT","bids":[["3.1503","222.7"]],"asks":[],"timestamp":1756900898169,"update_id":50197644,"fetch_time":1756900898215}
{"symbol":"TONUSDT","bids":[["3.1506","913.3"],["3.1501","323.0"]],"asks":[],"timestamp":1756900898249,"update_id":50197645,"fetch_time":1756900898299}
{"symbol":"TONUSDT","bids":[],"asks":[["3.1515","113.3"]],"timestamp":1756900898270,"update_id":50197646,"fetch_time":1756900898315}
{"symbol":"TONUSDT","bids":[["3.1498","1305.5"],["3.1494","2010.5"]],"asks":[],"timestamp":1756900898589,"update_id":50197647,"fetch_time":1756900898635}
{"symbol":"TONUSDT","bids":[],"asks":[["3.1515","83.5"]],"timestamp":1756900898609,"update_id":50197648,"fetch_time":1756900898655}
{"symbol":"TONUSDT","bids":[["3.1506","952.6"]],"asks":[],"timestamp":1756900898770,"update_id":50197649,"fetch_time":1756900898815}
{"symbol":"TONUSDT","bids":[],"asks":[["3.1516","320.4"]],"timestamp":1756900898790,"update_id":50197650,"fetch_time":1756900898835}
{"symbol":"TONUSDT","bids":[],"asks":[["3.1516","359.7"]],"timestamp":1756900898889,"update_id":50197651,"fetch_time":1756900898935}
{"symbol":"TONUSDT","bids":[],"asks":[["3.1558","2632.9"],["3.1559","915.4"]],"timestamp":1756900898909,"update_id":50197652,"fetch_time":1756900898955}
{"symbol":"TONUSDT","bids":[["3.1498","1147.0"]],"asks":[],"timestamp":1756900899070,"update_id":50197653,"fetch_time":1756900899115}
{"symbol":"TONUSDT","bids":[],"asks":[["3.1554","2735.2"]],"timestamp":1756900899090,"update_id":50197654,"fetch_time":1756900899135}
{"symbol":"TONUSDT","bids":[],"asks":[["3.1546","2351.3"]],"timestamp":1756900899110,"update_id":50197655,"fetch_time":1756900899159}
{"symbol":"TONUSDT","bids":[["3.1506","991.9"]],"asks":[],"timestamp":1756900899310,"update_id":50197656,"fetch_time":1756900899355}
{"symbol":"TONUSDT","bids":[],"asks":[["3.1558","1365.7"],["3.1559","2182.6"]],"timestamp":1756900899370,"update_id":50197657,"fetch_time":1756900899419}
{"symbol":"TONUSDT","bids":[],"asks":[["3.1515","53.2"],["3.1558","2632.9"],["3.1559","915.4"]],"timestamp":1756900899470,"update_id":50197658,"fetch_time":1756900899515}
{"symbol":"TONUSDT","bids":[],"asks":[["3.1548","2678.5"],["3.1549","713.4"]],"timestamp":1756900899549,"update_id":50197661,"fetch_time":1756900899595}
{"symbol":"TONUSDT","bids":[],"asks":[["3.1546","2004.5"],["3.1547","2356.3"],["3.1548","3155.4"],["3.1549","429.1"]],"timestamp":1756900899570,"update_id":50197662,"fetch_time":1756900899615}
{"symbol":"TONUSDT","bids":[],"asks":[["3.1546","2510.3"],["3.1547","1383.8"]],"timestamp":1756900899669,"update_id":50197664,"fetch_time":1756900899719}
{"symbol":"TONUSDT","bids":[],"asks":[["3.1516","281.1"],["3.1520","1378.9"]],"timestamp":1756900899770,"update_id":50197666,"fetch_time":1756900899815}
{"symbol":"TONUSDT","bids":[["3.1476","4178.1"],["3.1475","1201.4"]],"asks":[],"timestamp":1756900899830,"update_id":50197667,"fetch_time":1756900899875}
{"symbol":"TONUSDT","bids":[["3.1477","1193.6"],["3.1476","3811.9"]],"asks":[],"timestamp":1756900899849,"update_id":50197668,"fetch_time":1756900899895}
{"symbol":"TONUSDT","bids":[],"asks":[["3.1558","1365.7"],["3.1559","2182.6"]],"timestamp":1756900899910,"update_id":50197669,"fetch_time":1756900899955}
{"symbol":"TONUSDT","bids":[],"asks":[["3.1558","2632.9"],["3.1559","915.4"]],"timestamp":1756900899929,"update_id":50197670,"fetch_time":1756900899975}
{"symbol":"TONUSDT","bids":[],"asks":[["3.1558","1365.7"],["3.1559","2182.6"]],"timestamp":1756900899950,"update_id":50197671,"fetch_time":1756900899995}
{"symbol":"TONUSDT","bids":[["3.1509","710.8"]],"asks":[],"timestamp":1756900900010,"update_id":50197672,"fetch_time":1756900900056}
{"symbol":"TONUSDT","bids":[],"asks":[["3.1558","1690.0"]],"timestamp":1756900900149,"update_id":50197673,"fetch_time":1756900900195}
{"symbol":"TONUSDT","bids":[],"asks":[["3.1558","2957.2"],["3.1559","915.4"]],"timestamp":1756900900290,"update_id":50197674,"fetch_time":1756900900335}
{"symbol":"TONUSDT","bids":[],"asks":[["3.1558","2632.9"]],"timestamp":1756900900310,"update_id":50197675,"fetch_time":1756900900355}
{"symbol":"TONUSDT","bids":[],"asks":[["3.1516","320.4"]],"timestamp":1756900900469,"update_id":50197676,"fetch_time":1756900900519}
{"symbol":"TONUSDT","bids":[],"asks":[["3.1516","359.7"]],"timestamp":1756900900489,"update_id":50197677,"fetch_time":1756900900535}
{"symbol":"TONUSDT","bids":[],"asks":[["3.1558","1365.7"],["3.1559","2182.6"]],"timestamp":1756900900610,"update_id":50197678,"fetch_time":1756900900655}
{"symbol":"TONUSDT","bids":[["3.1507","236.4"]],"asks":[],"timestamp":1756900900629,"update_id":50197679,"fetch_time":1756900900675}
{"symbol":"TONUSDT","bids":[],"asks":[["3.1516","320.4"],["3.1517","201.1"],["3.1521","1644.6"],["3.1522","3041.8"]],"timestamp":1756900900690,"update_id":50197680,"fetch_time":1756900900739}
{"symbol":"TONUSDT","bids":[["3.1512","20.0"],["3.1461","0"]],"asks":[["3.1519","85.1"],["3.1521","1362.6"],["3.1522","2319.3"],["3.1523","2897.9"],["3.1527","782.1"]],"timestamp":1756900900750,"update_id":50197681,"fetch_time":1756900900795}
{"symbol":"TONUSDT","bids":[["3.1510","480.0"],["3.1509","714.0"],["3.1508","609.5"],["3.1507","275.7"],["3.1506","1179.3"],["3.1462","0"]],"asks":[["3.1516","281.1"],["3.1517","3.2"],["3.1518","367.5"],["3.1520","1105.5"],["3.1521","1401.9"],["3.1522","3258.1"]],"timestamp":1756900900770,"update_id":50197682,"fetch_time":1756900900815}
{"symbol":"TONUSDT","bids":[["3.1501","565.2"],["3.1469","185.9"]],"asks":[],"timestamp":1756900900810,"update_id":50197684,"fetch_time":1756900900859}
{"symbol":"TONUSDT","bids":[],"asks":[["3.1523","3050.9"],["3.1559","915.4"],["3.1560","2676.8"]],"timestamp":1756900900850,"update_id":50197686,"fetch_time":1756900900899}
{"symbol":"TONUSDT","bids":[["3.1508","1066.0"],["3.1507","388.4"],["3.1495","1192.7"],["3.1493","1994.6"],["3.1491","3215.6"],["3.1489","1511.6"],["3.1487","1010.8"],["3.1485","1532.1"]],"asks":[],"timestamp":1756900900910,"update_id":50197689,"fetch_time":1756900900955}
{"symbol":"TONUSDT","bids":[],"asks":[["3.1522","2850.6"],["3.1523","3232.7"]],"timestamp":1756900900929,"update_id":50197690,"fetch_time":1756900900975}
{"symbol":"TONUSDT","bids":[],"asks":[["3.1521","1870.8"]],"timestamp":1756900900950,"update_id":50197691,"fetch_time":1756900900995}
{"symbol":"TONUSDT","bids":[],"asks":[["3.1518","184.4"],["3.1519","222.7"],["3.1520","2084.7"],["3.1521","1362.6"]],"timestamp":1756900900969,"update_id":50197692,"fetch_time":1756900901015}
{"symbol":"TONUSDT","bids":[["3.1510","496.4"]],"asks":[],"timestamp":1756900900990,"update_id":50197693,"fetch_time":1756900901035}
{"symbol":"TONUSDT","bids":[["3.1510","734.4"]],"asks":[],"timestamp":1756900901009,"update_id":50197694,"fetch_time":1756900901059}
{"symbol":"TONUSDT","bids":[["3.1488","2289.2"],["3.1484","877.4"]],"asks":[],"timestamp":1756900901029,"update_id":50197695,"fetch_time":1756900901075}
{"symbol":"TONUSDT","bids":[],"asks":[["3.1518","605.1"],["3.1519","1039.4"]],"timestamp":1756900901069,"update_id":50197697,"fetch_time":1756900901115}
{"symbol":"TONUSDT","bids":[],"asks":[["3.1518","778.4"]],"timestamp":1756900901089,"update_id":50197698,"fetch_time":1756900901135}
{"symbol":"TONUSDT","bids":[],"asks":[["3.1518","738.2"],["3.1522","2889.9"],["3.1523","3050.9"],["3.1524","3591.3"]],"timestamp":1756900901109,"update_id":50197699,"fetch_time":1756900901156}
{"symbol":"TONUSDT","bids":[],"asks":[["3.1519","1186.9"],["3.1520","1294.2"]],"timestamp":1756900901170,"update_id":50197702,"fetch_time":1756900901215}
{"symbol":"TONUSDT","bids":[],"asks":[["3.1559","714.8"]],"timestamp":1756900901189,"update_id":50197703,"fetch_time":1756900901235}
{"symbol":"TONUSDT","bids":[],"asks":[["3.1520","1106.6"]],"timestamp":1756900901269,"update_id":50197704,"fetch_time":1756900901315}
{"symbol":"TONUSDT","bids":[],"asks":[["3.1518","564.9"]],"timestamp":1756900901289,"update_id":50197705,"fetch_time":1756900901339}
{"symbol":"TONUSDT","bids":[["3.1480","1092.8"]],"asks":[],"timestamp":1756900901450,"update_id":50197706,"fetch_time":1756900901495}
{"symbol":"TONUSDT","bids":[],"asks":[["3.1523","3232.7"],["3.1524","3409.5"]],"timestamp":1756900901469,"update_id":50197707,"fetch_time":1756900901515}
{"symbol":"TONUSDT","bids":[],"asks":[["3.1521","1361.7"]],"timestamp":1756900901489,"update_id":50197708,"fetch_time":1756900901535}
{"symbol":"TONUSDT","bids":[["3.1506","642.3"]],"asks":[],"timestamp":1756900901710,"update_id":50197709,"fetch_time":1756900901755}
{"symbol":"TONUSDT","bids":[["3.1508","924.0"]],"asks":[],"timestamp":1756900901729,"update_id":50197710,"fetch_time":1756900901775}
{"symbol":"TONUSDT","bids":[],"asks":[["3.1546","2004.5"],["3.1549","1407.1"]],"timestamp":1756900901970,"update_id":50197711,"fetch_time":1756900902015}
{"symbol":"TONUSDT","bids":[],"asks":[["3.1517","161.8"],["3.1548","3702.6"],["3.1549","429.1"]],"timestamp":1756900902129,"update_id":50197712,"fetch_time":1756900902179}
{"symbol":"TONUSDT","bids":[["3.1476","2006.1"],["3.1471","2455.7"]],"asks":[],"timestamp":1756900902210,"update_id":50197713,"fetch_time":1756900902255}
{"symbol":"TONUSDT","bids":[["3.1477","722.4"]],"asks":[],"timestamp":1756900902230,"update_id":50197714,"fetch_time":1756900902275}
{"symbol":"TONUSDT","bids":[["3.1512","0"],["3.1511","12.0"],["3.1510","978.1"],["3.1509","753.3"],["3.1508","884.7"],["3.1501","283.7"],["3.1462","743.4"]],"asks":[["3.1513","10.3"],["3.1519","1226.2"],["3.1520","1185.2"]],"timestamp":1756900902310,"update_id":50197715,"fetch_time":1756900902359}
{"symbol":"TONUSDT","bids":[["3.1510","740.1"],["3.1507","81.8"]],"asks":[["3.1512","28.8"],["3.1513","2.4"],["3.1518","752.6"],["3.1519","1406.3"],["3.1547","1385.8"],["3.1548","3700.6"],["3.1562","0"]],"timestamp":1756900902330,"update_id":50197716,"fetch_time":1756900902375}
{"symbol":"TONUSDT","bids":[],"asks":[["3.1515","53.2"],["3.1518","1394.4"]],"timestamp":1756900902369,"update_id":50197718,"fetch_time":1756900902415}
{"symbol":"TONUSDT","bids":[],"asks":[["3.1519","1445.4"]],"timestamp":1756900902429,"update_id":50197721,"fetch_time":1756900902479}
{"symbol":"TONUSDT","bids":[],"asks":[["3.1515","230.6"]],"timestamp":1756900902449,"update_id":50197722,"fetch_time":1756900902495}
{"symbol":"TONUSDT","bids":[],"asks":[["3.1515","53.2"],["3.1519","1164.0"]],"timestamp":1756900902470,"update_id":50197723,"fetch_time":1756900902519}
{"symbol":"TONUSDT","bids":[],"asks":[["3.1519","976.5"]],"timestamp":1756900902490,"update_id":50197724,"fetch_time":1756900902535}
{"symbol":"TONUSDT","bids":[],"asks":[["3.1517","201.1"],["3.1518","1542.6"],["3.1519","937.2"],["3.1520","1145.9"]],"timestamp":1756900902549,"update_id":50197725,"fetch_time":1756900902595}
{"symbol":"TONUSDT","bids":[],"asks":[["3.1519","976.5"]],"timestamp":1756900902570,"update_id":50197726,"fetch_time":1756900902615}
{"symbol":"TONUSDT","bids":[],"asks":[["3.1515","53.2"]],"timestamp":1756900902610,"update_id":50197728,"fetch_time":1756900902655}
{"symbol":"TONUSDT","bids":[],"asks":[["3.1518","1581.9"]],"timestamp":1756900902669,"update_id":50197729,"fetch_time":1756900902715}
{"symbol":"TONUSDT","bids":[["3.1510","480.0"],["3.1509","1042.8"]],"asks":[],"timestamp":1756900902729,"update_id":50197731,"fetch_time":1756900902775}
{"symbol":"TONUSDT","bids":[],"asks":[["3.1516","570.2"],["3.1526","1617.9"]],"timestamp":1756900902849,"update_id":50197733,"fetch_time":1756900902899}
{"symbol":"TONUSDT","bids":[["3.1500","1480.4"]],"asks":[],"timestamp":1756900903089,"update_id":50197734,"fetch_time":1756900903135}
{"symbol":"TONUSDT","bids":[],"asks":[["3.1522","3173.4"],["3.1523","3269.2"]],"timestamp":1756900903130,"update_id":50197735,"fetch_time":1756900903175}
{"symbol":"TONUSDT","bids":[["3.1511","0"],["3.1510","472.2"],["3.1506","901.1"],["3.1505","1576.3"],["3.1501","362.3"],["3.1500","1519.7"],["3.1498","1147.0"],["3.1461","897.3"]],"asks":[["3.1515","230.6"]],"timestamp":1756900903189,"update_id":50197736,"fetch_time":1756900903235}
{"symbol":"TONUSDT","bids":[["3.1511","20.0"],["3.1508","921.8"],["3.1461","0"]],"asks":[["3.1517","615.8"]],"timestamp":1756900903250,"update_id":50197739,"fetch_time":1756900903295}
{"symbol":"TONUSDT","bids":[],"asks":[["3.1518","1396.9"]],"timestamp":1756900903329,"update_id":50197743,"fetch_time":1756900903379}
{"symbol":"TONUSDT","bids":[],"asks":[["3.1518","1584.7"]],"timestamp":1756900903349,"update_id":50197744,"fetch_time":1756900903395}
{"symbol":"TONUSDT","bids":[["3.1505","1763.9"]],"asks":[],"timestamp":1756900903369,"update_id":50197745,"fetch_time":1756900903415}
{"symbol":"TONUSDT","bids":[],"asks":[["3.1546","2004.5"],["3.1547","1951.6"]],"timestamp":1756900903510,"update_id":50197749,"fetch_time":1756900903559}
{"symbol":"TONUSDT","bids":[],"asks":[["3.1559","1982.0"],["3.1560","1409.6"]],"timestamp":1756900903570,"update_id":50197750,"fetch_time":1756900903615}
{"symbol":"TONUSDT","bids":[],"asks":[["3.1516","454.6"],["3.1559","714.8"],["3.1560","2676.8"]],"timestamp":1756900903590,"update_id":50197751,"fetch_time":1756900903635}
{"symbol":"TONUSDT","bids":[],"asks":[["3.1548","2676.5"]],"timestamp":1756900904590,"update_id":50197752,"fetch_time":1756900904639}
{"symbol":"TONUSDT","bids":[["3.1507","236.9"]],"asks":[],"timestamp":1756900904929,"update_id":50197753,"fetch_time":1756900904979}
{"symbol":"TONUSDT","bids":[["3.1511","22.3"],["3.1510","492.9"],["3.1509","730.4"],["3.1508","670.6"],["3.1507","218.9"],["3.1502","1345.4"],["3.1496","1607.2"],["3.1495","1256.2"],["3.1492","3393.3"],["3.1486","1038.8"],["3.1471","649.9"],["3.1470","4622.2"]],"asks":[["3.1512","0"],["3.1513","0"],["3.1516","145.9"],["3.1517","161.8"],["3.1518","580.2"],["3.1519","5.6"],["3.1520","1106.6"],["3.1521","1322.4"],["3.1522","2850.6"],["3.1523","2822.6"],["3.1528","4423.8"],["3.1562","4363.4"],["3.1563","6271.5"]],"timestamp":1756900905209,"update_id":50197754,"fetch_time":1756900905255}
{"symbol":"TONUSDT","bids":[["3.1513","20.0"],["3.1512","5.3"],["3.1510","745.6"],["3.1509","753.7"],["3.1504","488.7"],["3.1502","1306.1"],["3.1500","1480.4"],["3.1463","0"],["3.1462","0"]],"asks":[["3.1514","1.8"],["3.1515","3.2"],["3.1517","3.2"],["3.1518","159.5"],["3.1521","1341.3"],["3.1522","2662.5"],["3.1523","3104.4"],["3.1524","3619.3"],["3.1525","316.9"],["3.1527","844.8"],["3.1528","4010.1"],["3.1531","3315.4"],["3.1534","930.2"],["3.1537","1881.3"],["3.1544","3213.3"],["3.1546","2305.4"],["3.1547","822.6"],["3.1548","3090.2"],["3.1549","431.1"],["3.1550","3893.5"],["3.1552","2748.4"],["3.1554","3487.3"]],"timestamp":1756900905229,"update_id":50197755,"fetch_time":1756900905280}
{"symbol":"TONUSDT","bids":[],"asks":[["3.1523","2822.6"]],"timestamp":1756900905349,"update_id":50197761,"fetch_time":1756900905399}
{"symbol":"TONUSDT","bids":[["3.1513","0"],["3.1506","906.6"],["3.1463","479.6"]],"asks":[],"timestamp":1756900905390,"update_id":50197762,"fetch_time":1756900905439}
{"symbol":"TONUSDT","bids":[["3.1513","20.0"],["3.1507","567.5"],["3.1463","0"]],"asks":[["3.1518","685.3"],["3.1542","4683.2"]],"timestamp":1756900905430,"update_id":50197764,"fetch_time":1756900905475}
{"symbol":"TONUSDT","bids":[],"asks":[["3.1520","2201.1"],["3.1521","1604.2"]],"timestamp":1756900905509,"update_id":50197768,"fetch_time":1756900905559}
{"symbol":"TONUSDT","bids":[],"asks":[["3.1521","1322.4"]],"timestamp":1756900905549,"update_id":50197770,"fetch_time":1756900905599}
{"symbol":"TONUSDT","bids":[["3.1507","971.5"]],"asks":[],"timestamp":1756900905589,"update_id":50197771,"fetch_time":1756900905635}
{"symbol":"TONUSDT","bids":[],"asks":[["3.1533","694.3"],["3.1549","486.3"]],"timestamp":1756900905690,"update_id":50197773,"fetch_time":1756900905743}
{"symbol":"TONUSDT","bids":[["3.1513","0"],["3.1512","0"],["3.1511","95.3"],["3.1510","498.7"],["3.1509","714.0"],["3.1508","883.4"],["3.1507","3.2"],["3.1506","611.0"],["3.1505","1537.0"],["3.1504","505.5"],["3.1503","465.3"],["3.1501","323.0"],["3.1498","1147.0"],["3.1463","479.6"],["3.1462","743.4"]],"asks":[["3.1517","200.2"],["3.1518","723.7"],["3.1519","419.6"],["3.1520","2239.5"],["3.1521","1359.9"],["3.1525","893.7"]],"timestamp":1756900905889,"update_id":50197774,"fetch_time":1756900905939}
{"symbol":"TONUSDT","bids":[["3.1512","20.0"],["3.1462","0"]],"asks":[["3.1516","145.9"],["3.1520","2482.7"],["3.1549","429.1"]],"timestamp":1756900905929,"update_id":50197776,"fetch_time":1756900905979}
{"symbol":"TONUSDT","bids":[["3.1513","20.0"],["3.1511","172.2"],["3.1507","190.9"],["3.1506","903.1"],["3.1505","1578.0"],["3.1501","283.7"],["3.1463","0"]],"asks":[["3.1549","431.1"]],"timestamp":1756900905950,"update_id":50197777,"fetch_time":1756900905999}
{"symbol":"TONUSDT","bids":[["3.1512","0"],["3.1511","187.9"],["3.1510","549.1"],["3.1509","714.0"],["3.1508","778.4"],["3.1505","1634.2"],["3.1503","465.3"],["3.1463","479.6"]],"asks":[["3.1515","166.4"],["3.1517","41.6"],["3.1520","2523.7"],["3.1521","1376.5"],["3.1523","2822.6"],["3.1527","841.9"],["3.1529","3571.7"]],"timestamp":1756900905970,"update_id":50197778,"fetch_time":1756900906015}
{"symbol":"TONUSDT","bids":[["3.1511","330.5"],["3.1510","552.3"],["3.1508","1029.5"],["3.1507","1080.7"],["3.1506","756.4"]],"asks":[],"timestamp":1756900906010,"update_id":50197780,"fetch_time":1756900906059}
{"symbol":"TONUSDT","bids":[["3.1508","1270.4"]],"asks":[],"timestamp":1756900906049,"update_id":50197782,"fetch_time":1756900906099}
{"symbol":"TONUSDT","bids":[["3.1506","693.0"]],"asks":[],"timestamp":1756900906089,"update_id":50197783,"fetch_time":1756900906135}
{"symbol":"TONUSDT","bids":[["3.1507","975.0"]],"asks":[],"timestamp":1756900906110,"update_id":50197784,"fetch_time":1756900906160}
{"symbol":"TONUSDT","bids":[["3.1512","178.9"],["3.1508","1311.4"],["3.1463","0"]],"asks":[],"timestamp":1756900906129,"update_id":50197785,"fetch_time":1756900906175}
{"symbol":"TONUSDT","bids":[["3.1501","565.6"]],"asks":[],"timestamp":1756900906150,"update_id":50197786,"fetch_time":1756900906199}
{"symbol":"TONUSDT","bids":[],"asks":[["3.1523","1650.6"],["3.1524","4212.3"],["3.1562","4363.4"],["3.1563","7257.4"]],"timestamp":1756900906290,"update_id":50197791,"fetch_time":1756900906336}
{"symbol":"TONUSDT","bids":[],"asks":[["3.1524","4400.1"]],"timestamp":1756900906310,"update_id":50197792,"fetch_time":1756900906360}
{"symbol":"TONUSDT","bids":[],"asks":[["3.1534","930.2"],["3.1536","2728.0"]],"timestamp":1756900906350,"update_id":50197793,"fetch_time":1756900906396}
{"symbol":"TONUSDT","bids":[],"asks":[["3.1547","1147.3"],["3.1558","1873.3"]],"timestamp":1756900906430,"update_id":50197797,"fetch_time":1756900906479}
{"symbol":"TONUSDT","bids":[],"asks":[["3.1523","1577.3"],["3.1524","4628.4"]],"timestamp":1756900906450,"update_id":50197798,"fetch_time":1756900906495}
{"symbol":"TONUSDT","bids":[],"asks":[["3.1523","1408.6"],["3.1547","1424.2"],["3.1554","2373.9"],["3.1558","1365.7"]],"timestamp":1756900906510,"update_id":50197800,"fetch_time":1756900906555}
{"symbol":"TONUSDT","bids":[],"asks":[["3.1522","1843.7"],["3.1562","4838.5"],["3.1563","5990.4"]],"timestamp":1756900906530,"update_id":50197801,"fetch_time":1756900906579}
{"symbol":"TONUSDT","bids":[],"asks":[["3.1522","2031.5"],["3.1524","4346.5"]],"timestamp":1756900906549,"update_id":50197802,"fetch_time":1756900906599}
{"symbol":"TONUSDT","bids":[],"asks":[["3.1521","971.1"]],"timestamp":1756900906570,"update_id":50197803,"fetch_time":1756900906615}
{"symbol":"TONUSDT","bids":[],"asks":[["3.1520","881.5"]],"timestamp":1756900906589,"update_id":50197804,"fetch_time":1756900906639}
{"symbol":"TONUSDT","bids":[],"asks":[["3.1522","2125.5"],["3.1524","4158.7"]],"timestamp":1756900906610,"update_id":50197805,"fetch_time":1756900906656}
{"symbol":"TONUSDT","bids":[],"asks":[["3.1523","844.9"]],"timestamp":1756900906649,"update_id":50197807,"fetch_time":1756900906699}
{"symbol":"TONUSDT","bids":[],"asks":[["3.1547","1147.3"],["3.1559","1222.4"]],"timestamp":1756900906670,"update_id":50197808,"fetch_time":1756900906715}
{"symbol":"TONUSDT","bids":[],"asks":[["3.1522","2166.5"]],"timestamp":1756900906789,"update_id":50197809,"fetch_time":1756900906835}
{"symbol":"TONUSDT","bids":[],"asks":[["3.1519","5.6"]],"timestamp":1756900906809,"update_id":50197810,"fetch_time":1756900906859}
{"symbol":"TONUSDT","bids":[["3.1511","511.7"],["3.1510","579.2"],["3.1509","749.1"]],"asks":[],"timestamp":1756900906849,"update_id":50197811,"fetch_time":1756900906895}
{"symbol":"TONUSDT","bids":[],"asks":[["3.1521","1012.1"]],"timestamp":1756900906870,"update_id":50197812,"fetch_time":1756900906919}
{"symbol":"TONUSDT","bids":[["3.1513","0"],["3.1512","0"],["3.1511","0"],["3.1510","0"],["3.1509","0"],["3.1508","0"],["3.1507","0"],["3.1506","0"],["3.1505","0"],["3.1504","0"],["3.1503","0"],["3.1502","0"],["3.1501","0"],["3.1500","1349.9"],["3.1463","479.6"],["3.1462","743.4"],["3.1461","897.3"],["3.1460","1660.3"],["3.1459","1286.3"],["3.1458","632.8"],["3.1457","194.5"],["3.1456","1627.3"],["3.1455","1495.6"],["3.1454","3588.6"],["3.1453","10997.8"],["3.1452","1712.9"],["3.1451","1460.4"]],"asks":[],"timestamp":1756900906990,"update_id":50197813,"fetch_time":1756900907035}
{"symbol":"TONUSDT","bids":[["3.1508","1.8"],["3.1505","45.6"],["3.1504","684.7"],["3.1503","42.4"],["3.1502","274.8"],["3.1501","2086.9"],["3.1500","1209.6"],["3.1499","1917.1"],["3.1498","1208.5"],["3.1497","890.1"],["3.1496","2368.9"],["3.1495","3251.1"],["3.1494","4318.0"],["3.1493","2435.9"],["3.1491","708.6"],["3.1490","2231.2"],["3.1489","651.2"],["3.1488","2409.6"],["3.1487","290.5"],["3.1485","723.6"],["3.1479","743.2"],["3.1468","5852.5"],["3.1463","2285.4"],["3.1456","0"],["3.1455","0"],["3.1454","0"],["3.1453","0"],["3.1452","0"],["3.1451","0"]],"asks":[["3.1511","122.9"],["3.1512","65.6"],["3.1513","122.9"],["3.1514","401.7"],["3.1515","21.9"],["3.1516","212.5"],["3.1517","439.6"],["3.1518","1018.0"],["3.1519","431.6"],["3.1520","1100.0"],["3.1521","1876.7"],["3.1522","2333.1"],["3.1523","825.7"],["3.1524","4231.5"],["3.1526","1703.7"],["3.1528","4071.6"],["3.1529","4092.1"],["3.1532","1253.0"],["3.1534","1457.1"],["3.1535","1260.8"],["3.1536","2525.2"],["3.1537","1530.5"],["3.1538","2413.8"],["3.1539","4477.0"],["3.1540","5650.5"],["3.1542","4312.4"],["3.1545","1008.7"],["3.1546","1585.1"],["3.1547","1149.3"],["3.1548","2312.4"],["3.1549","429.1"],["3.1550","4896.0"],["3.1552","2461.2"],["3.1554","2000.1"],["3.1561","0"],["3.1562","0"],["3.1563","0"]],"timestamp":1756900907010,"update_id":50197814,"fetch_time":1756900907055}
{"symbol":"TONUSDT","bids":[["3.1506","43.3"],["3.1505","48.0"],["3.1504","642.3"],["3.1503","0"],["3.1502","777.2"],["3.1501","1885.9"],["3.1498","542.6"],["3.1497","933.4"],["3.1496","2412.1"],["3.1494","4099.9"],["3.1488","2218.7"],["3.1486","357.0"],["3.1464","2085.9"]],"asks":[["3.1512","0"],["3.1513","138.8"],["3.1515","175.9"],["3.1516","649.8"],["3.1517","488.5"],["3.1518","1326.5"],["3.1520","1671.8"],["3.1521","2058.9"],["3.1526","1659.5"],["3.1529","4047.9"],["3.1532","1208.8"],["3.1534","1501.3"],["3.1537","1574.7"],["3.1540","5694.7"],["3.1541","896.3"],["3.1546","1587.1"],["3.1547","1147.3"],["3.1552","2136.5"],["3.1561","1547.8"]],"timestamp":1756900907029,"update_id":50197815,"fetch_time":1756900907079}
{"symbol":"TONUSDT","bids":[["3.1505","198.3"],["3.1503","233.2"],["3.1501","1410.0"],["3.1499","1960.4"],["3.1498","585.9"],["3.1484","1516.5"],["3.1457","0"]],"asks":[["3.1517","1076.9"],["3.1518","1459.4"]],"timestamp":1756900907050,"update_id":50197816,"fetch_time":1756900907095}
{"symbol":"TONUSDT","bids":[["3.1509","18.2"],["3.1506","170.2"],["3.1503","944.4"],["3.1502","780.4"],["3.1501","1283.1"],["3.1500","1856.2"],["3.1498","522.4"],["3.1497","976.6"],["3.1496","2408.8"],["3.1458","0"]],"asks":[["3.1510","20.0"],["3.1514","404.9"],["3.1516","932.7"],["3.1517","1358.8"],["3.1520","1691.0"],["3.1521","2017.9"],["3.1522","1993.6"],["3.1527","527.1"],["3.1529","3985.7"],["3.1532","1272.3"],["3.1537","1676.7"],["3.1561","0"]],"timestamp":1756900907069,"update_id":50197817,"fetch_time":1756900907119}
{"symbol":"TONUSDT","bids":[["3.1509","0"],["3.1504","1089.8"],["3.1503","657.5"],["3.1499","1771.8"],["3.1498","492.4"],["3.1496","2438.8"],["3.1495","1381.1"],["3.1494","2199.9"],["3.1493","2173.5"],["3.1492","2181.4"],["3.1491","2681.9"],["3.1490","4101.2"],["3.1488","1266.9"],["3.1484","2468.3"],["3.1474","2023.4"],["3.1464","3891.7"],["3.1463","479.6"],["3.1458","632.8"]],"asks":[["3.1510","27.9"],["3.1512","163.1"],["3.1513","297.3"],["3.1516","1214.5"],["3.1517","1200.2"],["3.1519","243.4"],["3.1520","1671.8"],["3.1522","2236.8"],["3.1523","2695.7"],["3.1524","3990.4"],["3.1525","751.0"],["3.1526","1599.5"],["3.1527","464.9"],["3.1529","3571.7"],["3.1531","3425.7"],["3.1534","974.4"],["3.1536","1573.5"],["3.1537","1753.9"],["3.1539","3837.2"],["3.1540","5424.0"],["3.1544","2517.0"],["3.1545","1010.7"],["3.1546","1585.1"],["3.1554","2426.1"],["3.1559","1523.5"],["3.1560","0"]],"timestamp":1756900907089,"update_id":50197818,"fetch_time":1756900907139}
{"symbol":"TONUSDT","bids":[["3.1503","689.1"],["3.1499","1613.2"],["3.1498","774.4"],["3.1496","874.2"],["3.1490","3723.0"],["3.1468","4581.7"],["3.1464","4609.8"]],"asks":[["3.1509","28.8"],["3.1510","0"],["3.1515","942.3"],["3.1516","1522.3"],["3.1519","337.6"],["3.1521","1830.0"],["3.1522","2049.0"],["3.1524","3409.5"],["3.1527","553.4"],["3.1538","2358.6"],["3.1544","2519.0"],["3.1545","1008.7"],["3.1559","2790.7"]],"timestamp":1756900907109,"update_id":50197819,"fetch_time":1756900907156}
{"symbol":"TONUSDT","bids":[["3.1510","30.0"],["3.1508","229.4"],["3.1507","43.3"],["3.1501","1012.3"],["3.1500","1787.4"],["3.1494","2313.2"],["3.1491","2608.6"],["3.1459","0"],["3.1458","0"]],"asks":[["3.1509","0"],["3.1511","0"],["3.1512","161.8"],["3.1514","68.2"],["3.1515","157.2"],["3.1516","1036.7"],["3.1517","271.3"],["3.1518","569.3"],["3.1560","4447.9"],["3.1561","1547.8"]],"timestamp":1756900907209,"update_id":50197824,"fetch_time":1756900907255}
{"symbol":"TONUSDT","bids":[["3.1512","20.0"],["3.1511","20.0"],["3.1510","0"],["3.1508","144.2"],["3.1507","46.4"],["3.1506","89.6"],["3.1505","522.2"],["3.1504","1176.3"],["3.1503","1018.8"],["3.1502","866.9"],["3.1501","1055.6"],["3.1499","1609.6"],["3.1497","1194.5"],["3.1496","1297.5"],["3.1495","1337.8"],["3.1494","2269.9"],["3.1466","2072.1"],["3.1464","2804.0"],["3.1460","0"]],"asks":[["3.1512","0"],["3.1513","122.9"],["3.1514","36.6"],["3.1515","3.2"],["3.1516","425.9"],["3.1517","53.2"],["3.1518","1067.4"],["3.1519","55.6"],["3.1520","1966.2"],["3.1524","3597.6"],["3.1526","1544.3"],["3.1527","498.2"],["3.1528","4317.3"],["3.1532","1686.0"],["3.1536","2337.4"],["3.1537","1764.9"],["3.1538","2413.8"],["3.1540","6063.3"],["3.1544","3269.1"],["3.1548","2314.4"],["3.1549","473.3"],["3.1550","3994.0"],["3.1551","2097.6"],["3.1554","2237.9"],["3.1559","2489.6"],["3.1562","3571.5"]],"timestamp":1756900907230,"update_id":50197825,"fetch_time":1756900907275}
{"symbol":"TONUSDT","bids":[["3.1511","0"],["3.1508","177.0"],["3.1506","508.3"],["3.1505","932.9"],["3.1502","1047.1"],["3.1497","1224.5"],["3.1495","1307.8"],["3.1493","2362.0"],["3.1492","4051.4"],["3.1491","2578.6"],["3.1490","1853.0"],["3.1467","9799.3"],["3.1466","266.3"],["3.1460","1660.3"]],"asks":[["3.1516","330.8"],["3.1517","241.0"],["3.1519","150.7"],["3.1520","2436.0"],["3.1523","825.7"],["3.1524","1667.6"],["3.1525","2621.0"],["3.1526","3474.3"],["3.1528","3533.5"],["3.1537","2716.8"],["3.1550","3676.6"],["3.1557","1891.8"]],"timestamp":1756900907250,"update_id":50197826,"fetch_time":1756900907299}
{"symbol":"TONUSDT","bids":[],"asks":[["3.1518","1449.0"],["3.1519","1276.6"],["3.1523","1054.0"],["3.1531","2473.9"],["3.1533","1709.6"]],"timestamp":1756900907289,"update_id":50197828,"fetch_time":1756900907339}
{"symbol":"TONUSDT","bids":[],"asks":[["3.1520","1684.4"],["3.1525","2850.3"]],"timestamp":1756900907370,"update_id":50197832,"fetch_time":1756900907415}
{"symbol":"TONUSDT","bids":[],"asks":[["3.1517","399.6"]],"timestamp":1756900907390,"update_id":50197833,"fetch_time":1756900907435}
{"symbol":"TONUSDT","bids":[],"asks":[["3.1517","575.5"],["3.1560","4447.9"],["3.1561","2814.9"]],"timestamp":1756900907430,"update_id":50197835,"fetch_time":1756900907476}
{"symbol":"TONUSDT","bids":[["3.1512","0"],["3.1505","926.6"],["3.1483","1558.3"],["3.1459","1286.3"]],"asks":[["3.1525","2621.0"],["3.1549","714.8"],["3.1551","1744.8"]],"timestamp":1756900907469,"update_id":50197836,"fetch_time":1756900907519}
{"symbol":"TONUSDT","bids":[["3.1502","1003.7"]],"asks":[],"timestamp":1756900907550,"update_id":50197840,"fetch_time":1756900907595}
{"symbol":"TONUSDT","bids":[],"asks":[["3.1518","1668.7"]],"timestamp":1756900907570,"update_id":50197841,"fetch_time":1756900907619}
{"symbol":"TONUSDT","bids":[["3.1511","20.0"],["3.1510","20.0"],["3.1509","43.3"],["3.1508","173.8"],["3.1505","294.8"],["3.1497","1194.5"],["3.1496","3252.0"],["3.1461","0"],["3.1460","0"],["3.1459","0"]],"asks":[["3.1524","3349.5"],["3.1528","3232.6"],["3.1532","1272.3"],["3.1534","1340.2"],["3.1536","1810.9"],["3.1537","2614.8"],["3.1540","5424.0"],["3.1544","2517.0"],["3.1551","1932.9"],["3.1555","1168.3"],["3.1559","1128.5"]],"timestamp":1756900907629,"update_id":50197843,"fetch_time":1756900907679}
{"symbol":"TONUSDT","bids":[["3.1510","0"],["3.1509","0"],["3.1505","538.0"],["3.1498","720.7"],["3.1496","2934.8"],["3.1490","1694.4"],["3.1467","7993.5"],["3.1461","897.3"],["3.1460","1660.3"]],"asks":[["3.1526","1359.5"]],"timestamp":1756900907650,"update_id":50197844,"fetch_time":1756900907695}
{"symbol":"TONUSDT","bids":[],"asks":[["3.1517","243.4"],["3.1521","1612.0"]],"timestamp":1756900907749,"update_id":50197849,"fetch_time":1756900907795}
{"symbol":"TONUSDT","bids":[],"asks":[["3.1516","23.0"],["3.1519","1844.7"],["3.1520","1496.6"],["3.1522","1973.2"]],"timestamp":1756900907770,"update_id":50197850,"fetch_time":1756900907815}
{"symbol":"TONUSDT","bids":[],"asks":[["3.1516","181.6"],["3.1518","970.6"]],"timestamp":1756900907810,"update_id":50197852,"fetch_time":1756900907855}
{"symbol":"TONUSDT","bids":[],"asks":[["3.1519","2212.8"]],"timestamp":1756900907830,"update_id":50197853,"fetch_time":1756900907879}
{"symbol":"TONUSDT","bids":[],"asks":[["3.1519","2025.0"],["3.1520","1433.2"]],"timestamp":1756900907910,"update_id":50197854,"fetch_time":1756900907955}
{"symbol":"TONUSDT","bids":[],"asks":[["3.1518","1158.5"],["3.1522","1785.3"],["3.1537","2639.6"]],"timestamp":1756900907930,"update_id":50197855,"fetch_time":1756900907975}
{"symbol":"TONUSDT","bids":[],"asks":[["3.1519","1837.1"]],"timestamp":1756900908030,"update_id":50197856,"fetch_time":1756900908076}
{"symbol":"TONUSDT","bids":[],"asks":[["3.1517","413.5"]],"timestamp":1756900908050,"update_id":50197857,"fetch_time":1756900908100}
{"symbol":"TONUSDT","bids":[],"asks":[["3.1514","4.6"]],"timestamp":1756900908070,"update_id":50197858,"fetch_time":1756900908120}
{"symbol":"TONUSDT","bids":[["3.1492","2154.7"]],"asks":[],"timestamp":1756900908089,"update_id":50197859,"fetch_time":1756900908135}
{"symbol":"TONUSDT","bids":[["3.1513","30.0"],["3.1509","10.6"],["3.1506","442.4"],["3.1498","467.0"],["3.1495","4007.8"],["3.1461","0"],["3.1460","0"]],"asks":[["3.1513","0"],["3.1518","719.4"],["3.1519","814.5"],["3.1520","1190.0"],["3.1521","1431.9"],["3.1523","1055.0"],["3.1563","6516.9"]],"timestamp":1756900908209,"update_id":50197860,"fetch_time":1756900908259}
{"symbol":"TONUSDT","bids":[["3.1513","0"],["3.1511","0"],["3.1505","989.6"],["3.1500","1958.8"],["3.1495","3207.8"],["3.1485","767.8"],["3.1477","828.6"],["3.1461","897.3"],["3.1460","1660.3"]],"asks":[["3.1514","127.5"],["3.1516","23.0"],["3.1517","238.8"],["3.1518","479.7"],["3.1519","994.6"],["3.1520","1231.8"],["3.1536","1628.7"],["3.1537","2821.8"],["3.1548","2312.4"],["3.1549","716.8"],["3.1560","4447.9"],["3.1561","2814.9"]],"timestamp":1756900908230,"update_id":50197861,"fetch_time":1756900908280}
{"symbol":"TONUSDT","bids":[["3.1508","184.8"],["3.1505","92.1"],["3.1496","3734.8"]],"asks":[["3.1515","0"],["3.1520","1756.9"],["3.1538","2458.0"],["3.1549","672.6"],["3.1560","5715.0"],["3.1561","1547.8"],["3.1564","3570.3"]],"timestamp":1756900908250,"update_id":50197862,"fetch_time":1756900908303}
{"symbol":"TONUSDT","bids":[],"asks":[["3.1517","207.2"],["3.1523","1272.6"],["3.1533","757.8"],["3.1535","2212.6"]],"timestamp":1756900908289,"update_id":50197864,"fetch_time":1756900908335}
{"symbol":"TONUSDT","bids":[["3.1510","20.0"],["3.1460","0"]],"asks":[["3.1514","100.0"],["3.1517","211.8"]],"timestamp":1756900908309,"update_id":50197865,"fetch_time":1756900908355}
{"symbol":"TONUSDT","bids":[["3.1505","272.2"],["3.1498","1113.6"],["3.1496","2934.8"]],"asks":[],"timestamp":1756900908330,"update_id":50197866,"fetch_time":1756900908379}
{"symbol":"TONUSDT","bids":[["3.1498","1356.8"]],"asks":[],"timestamp":1756900908350,"update_id":50197867,"fetch_time":1756900908395}
{"symbol":"TONUSDT","bids":[["3.1504","1059.8"]],"asks":[],"timestamp":1756900908430,"update_id":50197870,"fetch_time":1756900908479}
{"symbol":"TONUSDT","bids":[],"asks":[["3.1522","2048.1"],["3.1523","1043.3"]],"timestamp":1756900908529,"update_id":50197871,"fetch_time":1756900908575}
{"symbol":"TONUSDT","bids":[],"asks":[["3.1513","4.9"],["3.1564","0"]],"timestamp":1756900908550,"update_id":50197872,"fetch_time":1756900908599}
{"symbol":"TONUSDT","bids":[["3.1485","723.6"],["3.1475","1245.6"]],"asks":[["3.1512","28.8"],["3.1515","8.7"],["3.1516","181.6"],["3.1518","1253.0"],["3.1519","1559.5"],["3.1521","1612.0"],["3.1547","1426.3"],["3.1549","670.6"],["3.1562","0"],["3.1563","0"]],"timestamp":1756900908570,"update_id":50197873,"fetch_time":1756900908615}
{"symbol":"TONUSDT","bids":[],"asks":[["3.1515","162.7"],["3.1516","493.0"],["3.1518","1879.0"]],"timestamp":1756900908590,"update_id":50197874,"fetch_time":1756900908639}
{"symbol":"TONUSDT","bids":[],"asks":[["3.1514","296.7"],["3.1517","275.2"],["3.1518","2404.1"],["3.1519","1496.1"],["3.1547","1149.3"],["3.1549","784.3"],["3.1550","4131.2"]],"timestamp":1756900908609,"update_id":50197875,"fetch_time":1756900908659}
{"symbol":"TONUSDT","bids":[],"asks":[["3.1516","822.3"],["3.1517","651.0"],["3.1518","2604.1"],["3.1519","1120.3"]],"timestamp":1756900908630,"update_id":50197876,"fetch_time":1756900908675}
{"symbol":"TONUSDT","bids":[],"asks":[["3.1519","838.4"],["3.1520","1475.0"],["3.1531","3425.7"],["3.1535","1260.8"]],"timestamp":1756900908670,"update_id":50197878,"fetch_time":1756900908716}
{"symbol":"TONUSDT","bids":[],"asks":[["3.1518","2388.7"],["3.1520","1193.0"]],"timestamp":1756900908689,"update_id":50197879,"fetch_time":1756900908735}
{"symbol":"TONUSDT","bids":[],"asks":[["3.1518","1949.5"]],"timestamp":1756900908729,"update_id":50197880,"fetch_time":1756900908775}
{"symbol":"TONUSDT","bids":[["3.1509","0"],["3.1508","147.4"],["3.1507","3.2"],["3.1506","388.9"],["3.1505","373.5"],["3.1496","2978.0"],["3.1495","3251.1"],["3.1460","1660.3"]],"asks":[["3.1521","1976.8"],["3.1522","1785.3"]],"timestamp":1756900908750,"update_id":50197881,"fetch_time":1756900908795}
{"symbol":"TONUSDT","bids":[],"asks":[["3.1536","1938.5"],["3.1559","2395.7"],["3.1560","4447.9"]],"timestamp":1756900908810,"update_id":50197884,"fetch_time":1756900908859}
{"symbol":"TONUSDT","bids":[["3.1501","579.8"],["3.1496","3169.0"]],"asks":[],"timestamp":1756900908849,"update_id":50197886,"fetch_time":1756900908895}
{"symbol":"TONUSDT","bids":[],"asks":[["3.1521","1714.0"]],"timestamp":1756900908890,"update_id":50197887,"fetch_time":1756900908935}
{"symbol":"TONUSDT","bids":[],"asks":[["3.1514","100.0"],["3.1517","770.6"]],"timestamp":1756900908910,"update_id":50197888,"fetch_time":1756900908955}
{"symbol":"TONUSDT","bids":[["3.1503","756.1"]],"asks":[],"timestamp":1756900908969,"update_id":50197889,"fetch_time":1756900909019}
{"symbol":"TONUSDT","bids":[["3.1493","1506.4"]],"asks":[],"timestamp":1756900908989,"update_id":50197890,"fetch_time":1756900909039}
{"symbol":"TONUSDT","bids":[["3.1495","3442.1"]],"asks":[],"timestamp":1756900909070,"update_id":50197891,"fetch_time":1756900909115}
{"symbol":"TONUSDT","bids":[["3.1492","1963.7"]],"asks":[],"timestamp":1756900909189,"update_id":50197892,"fetch_time":1756900909240}
{"symbol":"TONUSDT","bids":[["3.1511","20.0"],["3.1509","7.1"],["3.1508","150.9"],["3.1507","29.5"],["3.1506","424.6"],["3.1505","416.2"],["3.1503","842.7"],["3.1497","1353.0"],["3.1494","3782.6"],["3.1493","1347.9"],["3.1461","0"],["3.1460","0"]],"asks":[["3.1512","0"],["3.1517","288.2"],["3.1518","719.2"],["3.1519","701.6"],["3.1524","3874.1"],["3.1562","3571.5"]],"timestamp":1756900909209,"update_id":50197893,"fetch_time":1756900909259}
{"symbol":"TONUSDT","bids":[["3.1512","20.0"],["3.1510","7.1"],["3.1505","694.9"],["3.1504","1059.8"],["3.1503","799.4"],["3.1501","811.8"],["3.1500","1739.2"],["3.1496","3125.8"],["3.1462","0"]],"asks":[["3.1516","201.8"],["3.1518","970.4"],["3.1519","1450.0"],["3.1520","1381.0"],["3.1547","1147.3"],["3.1548","2756.6"]],"timestamp":1756900909230,"update_id":50197894,"fetch_time":1756900909276}
{"symbol":"TONUSDT","bids":[["3.1511","0"],["3.1493","1067.3"],["3.1462","743.4"]],"asks":[["3.1516","360.3"],["3.1519","1732.0"],["3.1520","1643.8"]],"timestamp":1756900909249,"update_id":50197895,"fetch_time":1756900909299}
{"symbol":"TONUSDT","bids":[["3.1512","0"],["3.1509","10.3"],["3.1506","612.4"],["3.1461","1135.1"]],"asks":[["3.1512","122.9"],["3.1518","1224.5"],["3.1523","1271.6"],["3.1548","2314.4"],["3.1551","2910.9"],["3.1562","0"]],"timestamp":1756900909270,"update_id":50197896,"fetch_time":1756900909316}
{"symbol":"TONUSDT","bids":[],"asks":[["3.1516","501.8"],["3.1518","1749.7"]],"timestamp":1756900909309,"update_id":50197898,"fetch_time":1756900909359}
{"symbol":"TONUSDT","bids":[["3.1505","882.7"]],"asks":[["3.1513","0"],["3.1517","727.4"],["3.1518","2031.6"],["3.1520","1455.8"],["3.1562","3571.5"]],"timestamp":1756900909329,"update_id":50197899,"fetch_time":1756900909375}
{"symbol":"TONUSDT","bids":[],"asks":[["3.1519","1536.2"]],"timestamp":1756900909389,"update_id":50197902,"fetch_time":1756900909435}
{"symbol":"TONUSDT","bids":[],"asks":[["3.1518","1780.4"],["3.1519","1348.2"]],"timestamp":1756900909430,"update_id":50197903,"fetch_time":1756900909476}
{"symbol":"TONUSDT","bids":[["3.1510","129.0"],["3.1509","0"],["3.1496","3169.0"],["3.1460","1660.3"]],"asks":[],"timestamp":1756900909449,"update_id":50197904,"fetch_time":1756900909495}
{"symbol":"TONUSDT","bids":[],"asks":[["3.1515","157.2"]],"timestamp":1756900909510,"update_id":50197905,"fetch_time":1756900909555}
{"symbol":"TONUSDT","bids":[["3.1500","1960.6"],["3.1499","1350.1"],["3.1498","1936.7"]],"asks":[],"timestamp":1756900909550,"update_id":50197906,"fetch_time":1756900909595}
{"symbol":"TONUSDT","bids":[],"asks":[["3.1532","1463.7"]],"timestamp":1756900909750,"update_id":50197907,"fetch_time":1756900909799}
{"symbol":"TONUSDT","bids":[["3.1497","1194.5"]],"asks":[],"timestamp":1756900910070,"update_id":50197908,"fetch_time":1756900910119}
{"symbol":"TONUSDT","bids":[],"asks":[["3.1520","1193.0"],["3.1521","1917.9"]],"timestamp":1756900910170,"update_id":50197910,"fetch_time":1756900910219}
{"symbol":"TONUSDT","bids":[["3.1505","926.0"]],"asks":[],"timestamp":1756900910190,"update_id":50197911,"fetch_time":1756900910235}
{"symbol":"TONUSDT","bids":[["3.1513","30.0"],["3.1511","20.0"],["3.1509","7.1"],["3.1507","56.1"],["3.1506","459.8"],["3.1495","3398.8"],["3.1462","0"],["3.1461","0"],["3.1460","0"]],"asks":[["3.1512","0"],["3.1517","288.2"],["3.1518","930.0"],["3.1519","838.4"],["3.1520","1149.7"],["3.1523","1043.3"],["3.1563","6516.9"]],"timestamp":1756900910210,"update_id":50197912,"fetch_time":1756900910255}
{"symbol":"TONUSDT","bids":[],"asks":[["3.1521","1800.0"]],"timestamp":1756900910249,"update_id":50197914,"fetch_time":1756900910295}
{"symbol":"TONUSDT","bids":[["3.1513","0"],["3.1462","743.4"]],"asks":[["3.1520","1978.4"]],"timestamp":1756900910290,"update_id":50197916,"fetch_time":1756900910339}
{"symbol":"TONUSDT","bids":[["3.1507","56.1"],["3.1505","1169.2"]],"asks":[],"timestamp":1756900910309,"update_id":50197917,"fetch_time":1756900910355}
{"symbol":"TONUSDT","bids":[["3.1506","649.4"]],"asks":[["3.1515","0"],["3.1521","1612.0"],["3.1564","3570.3"]],"timestamp":1756900910329,"update_id":50197918,"fetch_time":1756900910379}
{"symbol":"TONUSDT","bids":[["3.1505","981.4"]],"asks":[],"timestamp":1756900910429,"update_id":50197919,"fetch_time":1756900910475}
{"symbol":"TONUSDT","bids":[],"asks":[["3.1519","1309.2"]],"timestamp":1756900910530,"update_id":50197920,"fetch_time":1756900910576}
{"symbol":"TONUSDT","bids":[],"asks":[["3.1518","872.1"]],"timestamp":1756900910550,"update_id":50197921,"fetch_time":1756900910600}
{"symbol":"TONUSDT","bids":[],"asks":[["3.1520","1790.4"]],"timestamp":1756900910629,"update_id":50197922,"fetch_time":1756900910675}
{"symbol":"TONUSDT","bids":[],"asks":[["3.1520","1833.7"]],"timestamp":1756900910730,"update_id":50197923,"fetch_time":1756900910775}
{"symbol":"TONUSDT","bids":[["3.1511","0"],["3.1497","976.6"],["3.1461","1135.1"]],"asks":[["3.1526","1461.5"],["3.1554","2169.7"]],"timestamp":1756900910749,"update_id":50197924,"fetch_time":1756900910796}
{"symbol":"TONUSDT","bids":[["3.1505","1169.2"],["3.1499","1350.1"]],"asks":[],"timestamp":1756900910789,"update_id":50197926,"fetch_time":1756900910839}
{"symbol":"TONUSDT","bids":[],"asks":[["3.1526","1359.5"]],"timestamp":1756900910810,"update_id":50197927,"fetch_time":1756900910855}
{"symbol":"TONUSDT","bids":[["3.1508","150.9"],["3.1502","1007.0"],["3.1501","811.8"],["3.1496","3125.8"]],"asks":[],"timestamp":1756900910970,"update_id":50197928,"fetch_time":1756900911015}
{"symbol":"TONUSDT","bids":[["3.1497","918.2"]],"asks":[],"timestamp":1756900911009,"update_id":50197929,"fetch_time":1756900911055}
{"symbol":"TONUSDT","bids":[["3.1509","17.8"],["3.1497","874.9"]],"asks":[],"timestamp":1756900911150,"update_id":50197932,"fetch_time":1756900911199}
{"symbol":"TONUSDT","bids":[["3.1466","266.3"]],"asks":[],"timestamp":1756900911209,"update_id":50197933,"fetch_time":1756900911259}
{"symbol":"TONUSDT","bids":[["3.1513","20.0"],["3.1512","8.8"],["3.1511","169.2"],["3.1510","132.7"],["3.1507","273.4"],["3.1505","981.4"],["3.1504","1061.6"],["3.1499","1725.9"],["3.1498","1893.5"],["3.1497","831.7"],["3.1466","1659.7"],["3.1465","1989.4"],["3.1463","0"],["3.1462","0"],["3.1461","0"]],"asks":[["3.1514","0"],["3.1516","17.4"],["3.1519","689.9"],["3.1520","983.2"],["3.1521","1799.8"],["3.1523","1043.3"],["3.1534","1342.0"],["3.1537","2639.6"],["3.1539","3177.8"],["3.1565","710.9"]],"timestamp":1756900911229,"update_id":50197934,"fetch_time":1756900911275}
{"symbol":"TONUSDT","bids":[["3.1514","20.0"],["3.1511","126.4"],["3.1507","920.0"],["3.1490","1738.6"],["3.1484","2968.2"],["3.1481","811.4"],["3.1475","1201.4"],["3.1464","0"]],"asks":[["3.1518","355.6"],["3.1519","658.3"],["3.1521","1863.2"],["3.1522","2255.4"],["3.1523","825.7"],["3.1528","3538.5"],["3.1535","738.4"],["3.1549","632.2"],["3.1551","2912.9"],["3.1561","2404.2"],["3.1562","4838.6"]],"timestamp":1756900911250,"update_id":50197935,"fetch_time":1756900911299}
{"symbol":"TONUSDT","bids":[["3.1513","0"],["3.1509","261.0"],["3.1508","476.3"],["3.1504","1125.5"],["3.1501","1029.1"],["3.1464","2804.0"]],"asks":[["3.1522","2537.5"],["3.1525","2690.8"],["3.1534","976.2"]],"timestamp":1756900911270,"update_id":50197936,"fetch_time":1756900911319}
{"symbol":"TONUSDT","bids":[],"asks":[["3.1517","53.2"],["3.1518","527.1"],["3.1520","1049.4"],["3.1523","822.4"],["3.1533","757.8"],["3.1536","2890.2"]],"timestamp":1756900911309,"update_id":50197938,"fetch_time":1756900911359}
{"symbol":"TONUSDT","bids":[],"asks":[["3.1521","2082.7"]],"timestamp":1756900911430,"update_id":50197942,"fetch_time":1756900911479}
{"symbol":"TONUSDT","bids":[],"asks":[["3.1522","2412.7"]],"timestamp":1756900911450,"update_id":50197943,"fetch_time":1756900911496}
{"symbol":"TONUSDT","bids":[],"asks":[["3.1520","1081.1"]],"timestamp":1756900911470,"update_id":50197944,"fetch_time":1756900911519}
{"symbol":"TONUSDT","bids":[["3.1510","138.3"]],"asks":[],"timestamp":1756900911670,"update_id":50197945,"fetch_time":1756900911715}
{"symbol":"TONUSDT","bids":[["3.1515","121.0"],["3.1470","4272.7"],["3.1465","183.6"],["3.1464","0"]],"asks":[["3.1518","355.6"],["3.1519","118.9"],["3.1522","2952.0"]],"timestamp":1756900911690,"update_id":50197946,"fetch_time":1756900911739}
{"symbol":"TONUSDT","bids":[["3.1514","0"],["3.1512","12.0"],["3.1509","918.5"],["3.1466","266.3"],["3.1464","2804.0"]],"asks":[["3.1517","189.7"],["3.1518","127.9"],["3.1519","150.5"],["3.1522","2983.7"],["3.1537","2584.4"],["3.1539","4019.4"],["3.1549","687.4"]],"timestamp":1756900911710,"update_id":50197947,"fetch_time":1756900911755}
{"symbol":"TONUSDT","bids":[],"asks":[["3.1560","5100.1"],["3.1562","3571.5"],["3.1563","7783.9"]],"timestamp":1756900911770,"update_id":50197950,"fetch_time":1756900911815}
{"symbol":"TONUSDT","bids":[["3.1488","1665.9"],["3.1475","1169.9"]],"asks":[],"timestamp":1756900911810,"update_id":50197952,"fetch_time":1756900911859}
{"symbol":"TONUSDT","bids":[["3.1509","910.8"]],"asks":[],"timestamp":1756900911850,"update_id":50197953,"fetch_time":1756900911899}
{"symbol":"TONUSDT","bids":[["3.1489","1602.9"],["3.1484","2016.4"]],"asks":[],"timestamp":1756900911889,"update_id":50197955,"fetch_time":1756900911943}
{"symbol":"TONUSDT","bids":[["3.1486","1046.8"]],"asks":[],"timestamp":1756900911910,"update_id":50197956,"fetch_time":1756900911959}
{"symbol":"TONUSDT","bids":[["3.1488","1464.1"]],"asks":[],"timestamp":1756900911930,"update_id":50197957,"fetch_time":1756900911975}
{"symbol":"TONUSDT","bids":[["3.1505","1197.1"],["3.1504","1125.5"]],"asks":[],"timestamp":1756900911989,"update_id":50197958,"fetch_time":1756900912035}
{"symbol":"TONUSDT","bids":[["3.1512","70.3"]],"asks":[],"timestamp":1756900912010,"update_id":50197959,"fetch_time":1756900912061}
{"symbol":"TONUSDT","bids":[["3.1505","981.4"]],"asks":[],"timestamp":1756900912050,"update_id":50197960,"fetch_time":1756900912096}
{"symbol":"TONUSDT","bids":[["3.1491","517.6"]],"asks":[],"timestamp":1756900912069,"update_id":50197961,"fetch_time":1756900912119}
{"symbol":"TONUSDT","bids":[],"asks":[["3.1532","1367.3"]],"timestamp":1756900912089,"update_id":50197962,"fetch_time":1756900912135}
{"symbol":"TONUSDT","bids":[],"asks":[["3.1517","186.5"],["3.1521","1532.4"],["3.1523","865.7"]],"timestamp":1756900912129,"update_id":50197964,"fetch_time":1756900912175}
{"symbol":"TONUSDT","bids":[["3.1505","1197.1"]],"asks":[],"timestamp":1756900912169,"update_id":50197966,"fetch_time":1756900912215}
{"symbol":"TONUSDT","bids":[["3.1498","2147.9"],["3.1493","876.3"]],"asks":[],"timestamp":1756900912190,"update_id":50197967,"fetch_time":1756900912239}
{"symbol":"TONUSDT","bids":[],"asks":[["3.1522","3171.6"],["3.1523","873.6"],["3.1563","6516.9"],["3.1564","4837.3"]],"timestamp":1756900912249,"update_id":50197970,"fetch_time":1756900912299}
{"symbol":"TONUSDT","bids":[],"asks":[["3.1522","3701.4"],["3.1526","1587.8"]],"timestamp":1756900912269,"update_id":50197971,"fetch_time":1756900912315}
{"symbol":"TONUSDT","bids":[],"asks":[["3.1520","1115.7"]],"timestamp":1756900912290,"update_id":50197972,"fetch_time":1756900912340}
{"symbol":"TONUSDT","bids":[],"asks":[["3.1532","1212.1"]],"timestamp":1756900912310,"update_id":50197973,"fetch_time":1756900912355}
{"symbol":"TONUSDT","bids":[],"asks":[["3.1521","1002.6"]],"timestamp":1756900912349,"update_id":50197974,"fetch_time":1756900912399}
{"symbol":"TONUSDT","bids":[],"asks":[["3.1521","1066.0"]],"timestamp":1756900912370,"update_id":50197975,"fetch_time":1756900912415}
{"symbol":"TONUSDT","bids":[],"asks":[["3.1522","3513.5"]],"timestamp":1756900912449,"update_id":50197976,"fetch_time":1756900912499}
{"symbol":"TONUSDT","bids":[["3.1492","1747.5"]],"asks":[],"timestamp":1756900912610,"update_id":50197979,"fetch_time":1756900912659}
{"symbol":"TONUSDT","bids":[["3.1494","3505.6"]],"asks":[],"timestamp":1756900912629,"update_id":50197980,"fetch_time":1756900912679}
{"symbol":"TONUSDT","bids":[["3.1497","1047.9"]],"asks":[],"timestamp":1756900912749,"update_id":50197981,"fetch_time":1756900912795}
{"symbol":"TONUSDT","bids":[["3.1513","8.8"],["3.1464","0"]],"asks":[["3.1563","7783.9"],["3.1564","3570.3"]],"timestamp":1756900912809,"update_id":50197984,"fetch_time":1756900912855}
{"symbol":"TONUSDT","bids":[["3.1497","1238.9"]],"asks":[],"timestamp":1756900912870,"update_id":50197986,"fetch_time":1756900912915}
{"symbol":"TONUSDT","bids":[["3.1495","3398.8"]],"asks":[],"timestamp":1756900912890,"update_id":50197987,"fetch_time":1756900912939}
{"symbol":"TONUSDT","bids":[["3.1493","494.3"]],"asks":[],"timestamp":1756900912910,"update_id":50197988,"fetch_time":1756900912955}
{"symbol":"TONUSDT","bids":[["3.1496","3464.5"]],"asks":[],"timestamp":1756900912950,"update_id":50197989,"fetch_time":1756900912999}
{"symbol":"TONUSDT","bids":[["3.1507","1135.7"],["3.1506","617.8"]],"asks":[],"timestamp":1756900913009,"update_id":50197990,"fetch_time":1756900913059}
{"symbol":"TONUSDT","bids":[["3.1492","1556.5"]],"asks":[],"timestamp":1756900913029,"update_id":50197991,"fetch_time":1756900913075}
{"symbol":"TONUSDT","bids":[],"asks":[["3.1537","2742.9"]],"timestamp":1756900913050,"update_id":50197992,"fetch_time":1756900913099}
{"symbol":"TONUSDT","bids":[["3.1513","0"],["3.1512","61.5"],["3.1496","3655.5"],["3.1464","2804.0"]],"asks":[],"timestamp":1756900913110,"update_id":50197993,"fetch_time":1756900913160}
{"symbol":"TONUSDT","bids":[],"asks":[["3.1525","2564.5"]],"timestamp":1756900913150,"update_id":50197994,"fetch_time":1756900913199}
{"symbol":"TONUSDT","bids":[],"asks":[["3.1522","2701.6"]],"timestamp":1756900913290,"update_id":50198000,"fetch_time":1756900913335}
{"symbol":"TONUSDT","bids":[["3.1509","938.2"],["3.1508","558.3"]],"asks":[],"timestamp":1756900913309,"update_id":50198001,"fetch_time":1756900913355}
{"symbol":"TONUSDT","bids":[],"asks":[["3.1522","3171.7"],["3.1523","1219.1"]],"timestamp":1756900913350,"update_id":50198002,"fetch_time":1756900913395}
{"symbol":"TONUSDT","bids":[],"asks":[["3.1520","1115.8"],["3.1563","7783.9"],["3.1564","3570.3"]],"timestamp":1756900913390,"update_id":50198004,"fetch_time":1756900913440}
{"symbol":"TONUSDT","bids":[],"asks":[["3.1523","1031.1"],["3.1563","6516.9"],["3.1564","4837.3"]],"timestamp":1756900913450,"update_id":50198005,"fetch_time":1756900913496}
{"symbol":"TONUSDT","bids":[],"asks":[["3.1523","685.6"]],"timestamp":1756900913469,"update_id":50198006,"fetch_time":1756900913515}
{"symbol":"TONUSDT","bids":[["3.1512","61.5"],["3.1511","128.5"]],"asks":[],"timestamp":1756900913550,"update_id":50198007,"fetch_time":1756900913599}
{"symbol":"TONUSDT","bids":[],"asks":[["3.1523","728.8"]],"timestamp":1756900913589,"update_id":50198008,"fetch_time":1756900913639}
{"symbol":"TONUSDT","bids":[],"asks":[["3.1563","7783.9"],["3.1564","3570.3"]],"timestamp":1756900913629,"update_id":50198010,"fetch_time":1756900913675}
{"symbol":"TONUSDT","bids":[],"asks":[["3.1524","3874.1"]],"timestamp":1756900913649,"update_id":50198011,"fetch_time":1756900913699}
{"symbol":"TONUSDT","bids":[["3.1506","872.8"]],"asks":[],"timestamp":1756900913750,"update_id":50198012,"fetch_time":1756900913795}
{"symbol":"TONUSDT","bids":[["3.1488","1943.9"]],"asks":[],"timestamp":1756900913829,"update_id":50198014,"fetch_time":1756900913875}
{"symbol":"TONUSDT","bids":[["3.1512","73.8"]],"asks":[],"timestamp":1756900914029,"update_id":50198018,"fetch_time":1756900914080}
{"symbol":"TONUSDT","bids":[],"asks":[["3.1537","2584.4"]],"timestamp":1756900914089,"update_id":50198020,"fetch_time":1756900914139}
{"symbol":"TONUSDT","bids":[],"asks":[["3.1521","1002.7"]],"timestamp":1756900914109,"update_id":50198021,"fetch_time":1756900914155}
{"symbol":"TONUSDT","bids":[["3.1465","980.2"]],"asks":[],"timestamp":1756900914129,"update_id":50198022,"fetch_time":1756900914179}
{"symbol":"TONUSDT","bids":[],"asks":[["3.1522","3513.6"],["3.1563","6516.9"],["3.1564","4837.3"]],"timestamp":1756900914149,"update_id":50198023,"fetch_time":1756900914199}
{"symbol":"TONUSDT","bids":[["3.1509","1236.5"]],"asks":[],"timestamp":1756900914170,"update_id":50198024,"fetch_time":1756900914215}
{"symbol":"TONUSDT","bids":[["3.1513","8.8"],["3.1510","587.1"],["3.1509","981.5"],["3.1503","1841.0"],["3.1499","518.2"],["3.1481","1808.6"],["3.1473","980.1"],["3.1464","0"]],"asks":[["3.1521","34.7"],["3.1522","2176.3"],["3.1523","642.3"],["3.1525","2282.4"],["3.1526","1359.5"],["3.1530","3230.5"]],"timestamp":1756900914209,"update_id":50198025,"fetch_time":1756900914255}
{"symbol":"TONUSDT","bids":[],"asks":[["3.1524","4626.3"],["3.1525","3775.8"]],"timestamp":1756900914269,"update_id":50198028,"fetch_time":1756900914315}
{"symbol":"TONUSDT","bids":[["3.1476","1363.8"]],"asks":[],"timestamp":1756900914310,"update_id":50198030,"fetch_time":1756900914359}
{"symbol":"TONUSDT","bids":[],"asks":[["3.1525","3493.7"]],"timestamp":1756900914370,"update_id":50198031,"fetch_time":1756900914415}
{"symbol":"TONUSDT","bids":[],"asks":[["3.1525","3430.3"]],"timestamp":1756900914389,"update_id":50198032,"fetch_time":1756900914435}
{"symbol":"TONUSDT","bids":[],"asks":[["3.1523","1112.5"]],"timestamp":1756900914450,"update_id":50198033,"fetch_time":1756900914495}
{"symbol":"TONUSDT","bids":[],"asks":[["3.1523","1394.6"]],"timestamp":1756900914470,"update_id":50198034,"fetch_time":1756900914519}
{"symbol":"TONUSDT","bids":[],"asks":[["3.1523","1458.0"]],"timestamp":1756900914489,"update_id":50198035,"fetch_time":1756900914535}
{"symbol":"TONUSDT","bids":[],"asks":[["3.1524","4219.6"]],"timestamp":1756900914550,"update_id":50198036,"fetch_time":1756900914595}
{"symbol":"TONUSDT","bids":[],"asks":[["3.1524","3874.1"]],"timestamp":1756900914589,"update_id":50198038,"fetch_time":1756900914635}
{"symbol":"TONUSDT","bids":[],"asks":[["3.1524","4062.2"]],"timestamp":1756900914669,"update_id":50198039,"fetch_time":1756900914719}
{"symbol":"TONUSDT","bids":[["3.1513","0"],["3.1512","61.5"],["3.1511","5.6"],["3.1510","548.5"],["3.1500","2434.7"],["3.1499","518.2"],["3.1464","2804.0"]],"asks":[],"timestamp":1756900914710,"update_id":50198040,"fetch_time":1756900914755}
{"symbol":"TONUSDT","bids":[],"asks":[["3.1523","1501.3"]],"timestamp":1756900914730,"update_id":50198041,"fetch_time":1756900914779}
{"symbol":"TONUSDT","bids":[["3.1509","1236.5"]],"asks":[],"timestamp":1756900914809,"update_id":50198044,"fetch_time":1756900914855}
{"symbol":"TONUSDT","bids":[],"asks":[["3.1520","492.3"]],"timestamp":1756900914849,"update_id":50198046,"fetch_time":1756900914899}
{"symbol":"TONUSDT","bids":[],"asks":[["3.1522","3176.6"],["3.1533","1044.4"]],"timestamp":1756900914870,"update_id":50198047,"fetch_time":1756900914915}
{"symbol":"TONUSDT","bids":[],"asks":[["3.1520","727.1"],["3.1522","3458.8"],["3.1523","1437.9"]],"timestamp":1756900914890,"update_id":50198048,"fetch_time":1756900914939}
{"symbol":"TONUSDT","bids":[["3.1510","591.7"]],"asks":[],"timestamp":1756900914910,"update_id":50198049,"fetch_time":1756900914955}
{"symbol":"TONUSDT","bids":[],"asks":[["3.1523","967.7"]],"timestamp":1756900914970,"update_id":50198050,"fetch_time":1756900915015}
{"symbol":"TONUSDT","bids":[],"asks":[["3.1523","685.6"]],"timestamp":1756900914990,"update_id":50198051,"fetch_time":1756900915035}
{"symbol":"TONUSDT","bids":[],"asks":[["3.1522","3171.9"]],"timestamp":1756900915009,"update_id":50198052,"fetch_time":1756900915059}
{"symbol":"TONUSDT","bids":[],"asks":[["3.1522","3638.9"]],"timestamp":1756900915030,"update_id":50198053,"fetch_time":1756900915075}
{"symbol":"TONUSDT","bids":[],"asks":[["3.1522","3702.3"]],"timestamp":1756900915049,"update_id":50198054,"fetch_time":1756900915099}
{"symbol":"TONUSDT","bids":[],"asks":[["3.1540","5424.0"]],"timestamp":1756900915069,"update_id":50198055,"fetch_time":1756900915119}
{"symbol":"TONUSDT","bids":[["3.1511","260.5"],["3.1509","981.5"]],"asks":[],"timestamp":1756900915109,"update_id":50198056,"fetch_time":1756900915159}
{"symbol":"TONUSDT","bids":[["3.1512","223.4"]],"asks":[],"timestamp":1756900915130,"update_id":50198057,"fetch_time":1756900915175}
{"symbol":"TONUSDT","bids":[],"asks":[["3.1521","98.1"]],"timestamp":1756900915149,"update_id":50198058,"fetch_time":1756900915195}
{"symbol":"TONUSDT","bids":[["3.1511","290.1"]],"asks":[],"timestamp":1756900915169,"update_id":50198059,"fetch_time":1756900915219}
{"symbol":"TONUSDT","bids":[],"asks":[["3.1522","3638.9"]],"timestamp":1756900915190,"update_id":50198060,"fetch_time":1756900915236}
{"symbol":"TONUSDT","bids":[["3.1514","5.3"],["3.1513","8.8"],["3.1512","226.9"],["3.1511","320.0"],["3.1499","474.9"],["3.1465","0"],["3.1464","0"]],"asks":[["3.1516","17.4"],["3.1517","0"],["3.1519","116.5"],["3.1520","176.6"],["3.1521","34.7"],["3.1522","2176.3"],["3.1523","642.3"],["3.1524","3394.8"],["3.1525","3062.1"],["3.1526","1547.6"],["3.1566","6302.4"]],"timestamp":1756900915210,"update_id":50198061,"fetch_time":1756900915255}
{"symbol":"TONUSDT","bids":[["3.1515","124.4"],["3.1514","0"],["3.1512","108.3"],["3.1465","980.2"]],"asks":[["3.1520","144.9"],["3.1527","810.5"]],"timestamp":1756900915250,"update_id":50198063,"fetch_time":1756900915295}
{"symbol":"TONUSDT","bids":[],"asks":[["3.1525","3532.3"],["3.1533","1044.4"]],"timestamp":1756900915270,"update_id":50198064,"fetch_time":1756900915315}
{"symbol":"TONUSDT","bids":[],"asks":[["3.1521","176.9"],["3.1525","3877.9"],["3.1526","1775.9"]],"timestamp":1756900915290,"update_id":50198065,"fetch_time":1756900915339}
{"symbol":"TONUSDT","bids":[],"asks":[["3.1524","3588.0"]],"timestamp":1756900915309,"update_id":50198066,"fetch_time":1756900915355}
{"symbol":"TONUSDT","bids":[],"asks":[["3.1524","4058.2"],["3.1525","4246.1"]],"timestamp":1756900915370,"update_id":50198067,"fetch_time":1756900915415}
{"symbol":"TONUSDT","bids":[],"asks":[["3.1524","4403.8"],["3.1527","464.9"]],"timestamp":1756900915390,"update_id":50198068,"fetch_time":1756900915439}
{"symbol":"TONUSDT","bids":[],"asks":[["3.1522","2056.9"]],"timestamp":1756900915410,"update_id":50198069,"fetch_time":1756900915455}
{"symbol":"TONUSDT","bids":[],"asks":[["3.1519","53.2"],["3.1520","113.3"]],"timestamp":1756900915430,"update_id":50198070,"fetch_time":1756900915479}
{"symbol":"TONUSDT","bids":[],"asks":[["3.1539","3177.8"]],"timestamp":1756900915449,"update_id":50198071,"fetch_time":1756900915499}
{"symbol":"TONUSDT","bids":[],"asks":[["3.1525","3775.9"],["3.1526","1587.8"]],"timestamp":1756900915469,"update_id":50198072,"fetch_time":1756900915515}
{"symbol":"TONUSDT","bids":[],"asks":[["3.1524","4215.8"],["3.1525","3430.3"],["3.1529","2530.1"]],"timestamp":1756900915490,"update_id":50198073,"fetch_time":1756900915539}
{"symbol":"TONUSDT","bids":[],"asks":[["3.1526","2215.6"]],"timestamp":1756900915550,"update_id":50198076,"fetch_time":1756900915599}
{"symbol":"TONUSDT","bids":[],"asks":[["3.1525","3712.5"],["3.1526","2403.6"],["3.1564","4837.3"],["3.1565","710.9"]],"timestamp":1756900915570,"update_id":50198077,"fetch_time":1756900915615}
{"symbol":"TONUSDT","bids":[],"asks":[["3.1521","145.4"],["3.1525","4058.1"]],"timestamp":1756900915590,"update_id":50198078,"fetch_time":1756900915635}
{"symbol":"TONUSDT","bids":[["3.1515","122.1"]],"asks":[],"timestamp":1756900915609,"update_id":50198079,"fetch_time":1756900915655}
{"symbol":"TONUSDT","bids":[],"asks":[["3.1524","3870.2"],["3.1525","4246.1"],["3.1526","2121.4"],["3.1527","464.9"]],"timestamp":1756900915670,"update_id":50198080,"fetch_time":1756900915715}
{"symbol":"TONUSDT","bids":[],"asks":[["3.1524","4152.4"],["3.1526","1775.8"],["3.1564","3570.3"],["3.1566","7569.3"]],"timestamp":1756900915690,"update_id":50198081,"fetch_time":1756900915736}
{"symbol":"TONUSDT","bids":[],"asks":[["3.1536","3731.7"]],"timestamp":1756900915749,"update_id":50198082,"fetch_time":1756900915796}
{"symbol":"TONUSDT","bids":[["3.1514","5.3"],["3.1465","0"]],"asks":[["3.1525","3963.9"],["3.1526","1587.8"]],"timestamp":1756900915769,"update_id":50198083,"fetch_time":1756900915820}
{"symbol":"TONUSDT","bids":[],"asks":[["3.1524","4215.8"],["3.1525","3681.7"]],"timestamp":1756900915790,"update_id":50198084,"fetch_time":1756900915836}
{"symbol":"TONUSDT","bids":[["3.1502","1586.2"]],"asks":[],"timestamp":1756900915830,"update_id":50198085,"fetch_time":1756900915879}
{"symbol":"TONUSDT","bids":[],"asks":[["3.1524","4403.8"]],"timestamp":1756900915869,"update_id":50198086,"fetch_time":1756900915919}
{"symbol":"TONUSDT","bids":[],"asks":[["3.1525","3618.3"]],"timestamp":1756900915910,"update_id":50198087,"fetch_time":1756900915955}
{"symbol":"TONUSDT","bids":[],"asks":[["3.1524","4591.9"],["3.1525","3430.3"]],"timestamp":1756900915969,"update_id":50198088,"fetch_time":1756900916015}
{"symbol":"TONUSDT","bids":[],"asks":[["3.1525","3242.2"]],"timestamp":1756900916069,"update_id":50198089,"fetch_time":1756900916115}
{"symbol":"TONUSDT","bids":[["3.1515","124.4"],["3.1514","0"],["3.1511","704.2"],["3.1498","3325.1"],["3.1465","980.2"]],"asks":[["3.1518","5.0"],["3.1519","3.2"],["3.1521","3.2"],["3.1522","791.6"],["3.1524","3588.0"],["3.1525","3062.1"],["3.1526","640.2"],["3.1528","2908.0"],["3.1532","1517.0"],["3.1534","2329.0"],["3.1565","1977.8"],["3.1566","6302.4"]],"timestamp":1756900916210,"update_id":50198091,"fetch_time":1756900916259}
{"symbol":"TONUSDT","bids":[["3.1514","5.3"],["3.1502","1542.9"],["3.1465","0"]],"asks":[["3.1529","3345.9"]],"timestamp":1756900916250,"update_id":50198093,"fetch_time":1756900916299}
{"symbol":"TONUSDT","bids":[],"asks":[["3.1520","81.7"],["3.1522","1608.0"]],"timestamp":1756900916270,"update_id":50198094,"fetch_time":1756900916315}
{"symbol":"TONUSDT","bids":[],"asks":[["3.1528","3190.2"]],"timestamp":1756900916289,"update_id":50198095,"fetch_time":1756900916336}
{"symbol":"TONUSDT","bids":[["3.1490","1113.2"]],"asks":[],"timestamp":1756900916350,"update_id":50198098,"fetch_time":1756900916395}
{"symbol":"TONUSDT","bids":[],"asks":[["3.1527","1178.3"],["3.1529","3157.9"]],"timestamp":1756900916370,"update_id":50198099,"fetch_time":1756900916419}
{"symbol":"TONUSDT","bids":[],"asks":[["3.1526","1278.4"],["3.1528","3253.6"],["3.1529","2875.7"]],"timestamp":1756900916390,"update_id":50198100,"fetch_time":1756900916436}
{"symbol":"TONUSDT","bids":[],"asks":[["3.1527","1523.9"],["3.1529","2530.1"]],"timestamp":1756900916410,"update_id":50198101,"fetch_time":1756900916459}
{"symbol":"TONUSDT","bids":[["3.1512","435.0"]],"asks":[],"timestamp":1756900916489,"update_id":50198102,"fetch_time":1756900916535}
{"symbol":"TONUSDT","bids":[],"asks":[["3.1528","2908.0"]],"timestamp":1756900916510,"update_id":50198103,"fetch_time":1756900916556}
{"symbol":"TONUSDT","bids":[],"asks":[["3.1528","3441.7"]],"timestamp":1756900916610,"update_id":50198107,"fetch_time":1756900916656}
{"symbol":"TONUSDT","bids":[["3.1510","623.3"]],"asks":[],"timestamp":1756900916629,"update_id":50198108,"fetch_time":1756900916680}
{"symbol":"TONUSDT","bids":[],"asks":[["3.1516","0"],["3.1522","918.8"],["3.1538","2340.6"],["3.1539","3060.4"],["3.1548","1813.9"],["3.1554","1791.4"],["3.1567","13393.0"]],"timestamp":1756900916650,"update_id":50198109,"fetch_time":1756900916699}
{"symbol":"TONUSDT","bids":[["3.1517","99.9"],["3.1516","278.1"],["3.1514","23.7"],["3.1512","405.2"],["3.1501","1006.0"],["3.1500","2348.2"],["3.1496","6334.0"],["3.1494","1063.2"],["3.1492","2315.4"],["3.1467","0"],["3.1466","0"]],"asks":[["3.1518","1.8"],["3.1524","1253.5"],["3.1525","1132.1"],["3.1526","1030.3"],["3.1529","4460.1"],["3.1530","5160.5"],["3.1535","738.4"],["3.1536","3614.3"],["3.1537","2365.0"],["3.1539","2878.2"],["3.1540","5306.6"],["3.1550","2997.6"],["3.1551","2073.3"],["3.1553","285.8"],["3.1555","867.4"],["3.1556","1401.5"],["3.1559","714.8"],["3.1561","2287.0"],["3.1563","5990.4"],["3.1565","932.5"],["3.1567","12753.7"]],"timestamp":1756900916669,"update_id":50198110,"fetch_time":1756900916715}
{"symbol":"TONUSDT","bids":[["3.1514","221.0"],["3.1510","591.7"]],"asks":[],"timestamp":1756900916750,"update_id":50198114,"fetch_time":1756900916799}
{"symbol":"TONUSDT","bids":[],"asks":[["3.1528","3159.5"]],"timestamp":1756900916789,"update_id":50198116,"fetch_time":1756900916839}
{"symbol":"TONUSDT","bids":[],"asks":[["3.1527","1155.7"]],"timestamp":1756900916870,"update_id":50198119,"fetch_time":1756900916915}
{"symbol":"TONUSDT","bids":[],"asks":[["3.1525","786.3"],["3.1526","1500.5"],["3.1539","2209.5"],["3.1547","2113.0"]],"timestamp":1756900916890,"update_id":50198120,"fetch_time":1756900916979}
{"symbol":"TONUSDT","bids":[],"asks":[["3.1526","1846.1"],["3.1538","3248.0"],["3.1546","1629.3"]],"timestamp":1756900916910,"update_id":50198121,"fetch_time":1756900916987}
{"symbol":"TONUSDT","bids":[],"asks":[["3.1523","3.2"],["3.1525","6.6"],["3.1529","5171.0"]],"timestamp":1756900916970,"update_id":50198122,"fetch_time":1756900917019}
{"symbol":"TONUSDT","bids":[],"asks":[["3.1528","1577.5"],["3.1530","1109.4"],["3.1538","4427.7"],["3.1542","2288.4"]],"timestamp":1756900917089,"update_id":50198128,"fetch_time":1756900917135}
{"symbol":"TONUSDT","bids":[],"asks":[["3.1526","590.7"]],"timestamp":1756900917109,"update_id":50198129,"fetch_time":1756900917159}
{"symbol":"TONUSDT","bids":[["3.1520","170.0"],["3.1519","10.6"],["3.1518","437.9"],["3.1517","689.3"],["3.1516","1651.0"],["3.1515","1229.0"],["3.1514","876.1"],["3.1513","606.3"],["3.1512","909.4"],["3.1511","3299.2"],["3.1510","686.1"],["3.1509","1731.3"],["3.1507","2353.7"],["3.1506","2167.1"],["3.1505","3029.1"],["3.1504","3389.9"],["3.1503","1136.7"],["3.1502","1755.8"],["3.1500","1931.5"],["3.1498","3675.2"],["3.1496","5074.9"],["3.1494","1311.4"],["3.1475","2931.5"],["3.1474","2616.9"],["3.1470","0"],["3.1469","0"],["3.1468","0"]],"asks":[["3.1518","0"],["3.1519","0"],["3.1520","0"],["3.1521","0"],["3.1529","599.7"],["3.1530","6.0"],["3.1531","381.8"],["3.1532","1876.3"],["3.1533","931.8"],["3.1535","2911.6"],["3.1537","1467.1"],["3.1538","2110.3"],["3.1540","1675.1"],["3.1541","1190.0"],["3.1548","1272.8"],["3.1553","283.8"],["3.1556","5681.8"],["3.1566","3749.8"],["3.1568","4920.8"],["3.1569","2357.2"],["3.1570","3105.3"],["3.1571","518.5"]],"timestamp":1756900917369,"update_id":50198142,"fetch_time":1756900917422}
{"symbol":"TONUSDT","bids":[["3.1521","87.6"],["3.1519","142.0"],["3.1518","1077.0"],["3.1517","684.8"],["3.1516","1746.1"],["3.1515","1440.7"],["3.1514","309.4"],["3.1512","877.8"],["3.1500","1652.7"],["3.1498","2616.3"],["3.1496","5130.1"],["3.1494","1366.6"],["3.1491","561.8"],["3.1486","923.0"],["3.1484","1232.8"],["3.1483","626.4"],["3.1471","0"]],"asks":[["3.1522","1.8"],["3.1528","519.5"],["3.1531","193.7"],["3.1532","2158.5"],["3.1536","2640.9"],["3.1538","2055.1"],["3.1546","2985.5"],["3.1548","1328.0"],["3.1556","5679.8"],["3.1557","1518.6"],["3.1558","1241.4"],["3.1562","1235.5"]],"timestamp":1756900917389,"update_id":50198143,"fetch_time":1756900917434}
{"symbol":"TONUSDT","bids":[],"asks":[["3.1531","436.4"],["3.1532","2212.5"]],"timestamp":1756900917590,"update_id":50198153,"fetch_time":1756900917638}
{"symbol":"TONUSDT","bids":[["3.1510","854.0"],["3.1496","3796.5"]],"asks":[],"timestamp":1756900917649,"update_id":50198156,"fetch_time":1756900917698}
{"symbol":"TONUSDT","bids":[["3.1494","1368.4"]],"asks":[],"timestamp":1756900917690,"update_id":50198157,"fetch_time":1756900917734}
{"symbol":"TONUSDT","bids":[["3.1520","158.1"],["3.1519","142.0"],["3.1508","1069.2"]],"asks":[],"timestamp":1756900917709,"update_id":50198158,"fetch_time":1756900917754}
{"symbol":"TONUSDT","bids":[],"asks":[["3.1534","3437.2"]],"timestamp":1756900917810,"update_id":50198163,"fetch_time":1756900917859}
{"symbol":"TONUSDT","bids":[],"asks":[["3.1533","1402.6"],["3.1534","3907.4"],["3.1535","3633.3"],["3.1548","1578.0"],["3.1550","2753.1"]],"timestamp":1756900917829,"update_id":50198164,"fetch_time":1756900917878}
{"symbol":"TONUSDT","bids":[],"asks":[["3.1532","1457.2"],["3.1533","774.6"],["3.1534","4249.3"],["3.1546","3407.3"]],"timestamp":1756900917850,"update_id":50198165,"fetch_time":1756900917894}
{"symbol":"TONUSDT","bids":[],"asks":[["3.1534","4124.6"],["3.1535","3257.2"]],"timestamp":1756900917890,"update_id":50198167,"fetch_time":1756900917935}
{"symbol":"TONUSDT","bids":[],"asks":[["3.1535","2975.0"]],"timestamp":1756900917910,"update_id":50198168,"fetch_time":1756900917958}
{"symbol":"TONUSDT","bids":[],"asks":[["3.1535","2911.6"],["3.1536","828.3"],["3.1548","1839.1"]],"timestamp":1756900917929,"update_id":50198169,"fetch_time":1756900917974}
{"symbol":"TONUSDT","bids":[["3.1521","100.4"],["3.1519","136.7"],["3.1508","1303.5"]],"asks":[],"timestamp":1756900917950,"update_id":50198170,"fetch_time":1756900917995}
{"symbol":"TONUSDT","bids":[],"asks":[["3.1543","930.2"]],"timestamp":1756900917970,"update_id":50198171,"fetch_time":1756900918019}
{"symbol":"TONUSDT","bids":[["3.1496","3605.5"]],"asks":[],"timestamp":1756900917990,"update_id":50198172,"fetch_time":1756900918034}
{"symbol":"TONUSDT","bids":[],"asks":[["3.1533","1483.6"],["3.1534","3308.8"],["3.1541","1947.2"]],"timestamp":1756900918129,"update_id":50198179,"fetch_time":1756900918174}
{"symbol":"TONUSDT","bids":[["3.1515","1848.4"]],"asks":[],"timestamp":1756900918150,"update_id":50198180,"fetch_time":1756900918194}
{"symbol":"TONUSDT","bids":[["3.1521","89.9"],["3.1520","152.8"]],"asks":[],"timestamp":1756900918169,"update_id":50198181,"fetch_time":1756900918214}
{"symbol":"TONUSDT","bids":[],"asks":[["3.1534","3779.1"],["3.1536","1169.1"],["3.1556","6891.1"],["3.1566","2019.9"]],"timestamp":1756900918249,"update_id":50198185,"fetch_time":1756900918299}
{"symbol":"TONUSDT","bids":[],"asks":[["3.1534","4124.7"],["3.1561","2287.0"],["3.1563","1741.1"],["3.1566","2945.8"]],"timestamp":1756900918270,"update_id":50198186,"fetch_time":1756900918315}
{"symbol":"TONUSDT","bids":[],"asks":[["3.1544","3249.8"]],"timestamp":1756900918290,"update_id":50198187,"fetch_time":1756900918335}
{"symbol":"TONUSDT","bids":[["3.1516","1066.5"]],"asks":[],"timestamp":1756900918309,"update_id":50198188,"fetch_time":1756900918359}
{"symbol":"TONUSDT","bids":[],"asks":[["3.1532","1224.0"],["3.1535","2919.4"],["3.1551","2317.4"]],"timestamp":1756900918330,"update_id":50198189,"fetch_time":1756900918374}
{"symbol":"TONUSDT","bids":[],"asks":[["3.1533","492.8"],["3.1534","4312.7"]],"timestamp":1756900918389,"update_id":50198190,"fetch_time":1756900918435}
{"symbol":"TONUSDT","bids":[],"asks":[["3.1532","1552.5"]],"timestamp":1756900918410,"update_id":50198191,"fetch_time":1756900918458}
{"symbol":"TONUSDT","bids":[["3.1516","1034.9"]],"asks":[],"timestamp":1756900918429,"update_id":50198192,"fetch_time":1756900918475}
{"symbol":"TONUSDT","bids":[],"asks":[["3.1544","3005.3"]],"timestamp":1756900918470,"update_id":50198193,"fetch_time":1756900918518}
{"symbol":"TONUSDT","bids":[],"asks":[["3.1531","19.2"],["3.1532","1536.8"],["3.1533","958.8"],["3.1542","2342.4"]],"timestamp":1756900918510,"update_id":50198195,"fetch_time":1756900918554}
{"symbol":"TONUSDT","bids":[],"asks":[["3.1533","1241.0"],["3.1541","1804.7"]],"timestamp":1756900918529,"update_id":50198196,"fetch_time":1756900918578}
{"symbol":"TONUSDT","bids":[],"asks":[["3.1531","182.1"]],"timestamp":1756900918550,"update_id":50198197,"fetch_time":1756900918594}
{"symbol":"TONUSDT","bids":[],"asks":[["3.1531","565.0"],["3.1533","1201.9"],["3.1534","3842.4"]],"timestamp":1756900918649,"update_id":50198201,"fetch_time":1756900918695}
{"symbol":"TONUSDT","bids":[["3.1518","1207.4"],["3.1506","2592.4"]],"asks":[],"timestamp":1756900918669,"update_id":50198202,"fetch_time":1756900918714}
{"symbol":"TONUSDT","bids":[],"asks":[["3.1546","4358.8"],["3.1550","1801.6"]],"timestamp":1756900918710,"update_id":50198204,"fetch_time":1756900918755}
{"symbol":"TONUSDT","bids":[],"asks":[["3.1528","337.8"],["3.1534","3308.8"]],"timestamp":1756900918729,"update_id":50198205,"fetch_time":1756900918778}
{"symbol":"TONUSDT","bids":[["3.1519","147.8"],["3.1518","1234.3"],["3.1517","751.7"],["3.1516","1036.7"],["3.1515","1916.6"]],"asks":[],"timestamp":1756900918770,"update_id":50198206,"fetch_time":1756900918814}
{"symbol":"TONUSDT","bids":[],"asks":[["3.1533","1013.9"]],"timestamp":1756900918790,"update_id":50198207,"fetch_time":1756900918839}
{"symbol":"TONUSDT","bids":[["3.1512","1127.1"]],"asks":[],"timestamp":1756900919009,"update_id":50198208,"fetch_time":1756900919059}
{"symbol":"TONUSDT","bids":[["3.1518","1207.4"],["3.1517","716.6"],["3.1505","3411.6"]],"asks":[],"timestamp":1756900919089,"update_id":50198210,"fetch_time":1756900919134}
{"symbol":"TONUSDT","bids":[],"asks":[["3.1563","1844.5"]],"timestamp":1756900919170,"update_id":50198213,"fetch_time":1756900919219}
{"symbol":"TONUSDT","bids":[],"asks":[["3.1534","4124.4"],["3.1535","2919.3"],["3.1563","1373.5"],["3.1565","1545.0"]],"timestamp":1756900919249,"update_id":50198217,"fetch_time":1756900919294}
{"symbol":"TONUSDT","bids":[["3.1521","87.6"],["3.1519","258.2"],["3.1518","1207.4"],["3.1517","749.4"],["3.1505","3454.9"]],"asks":[],"timestamp":1756900919270,"update_id":50198218,"fetch_time":1756900919314}
{"symbol":"TONUSDT","bids":[],"asks":[["3.1534","4030.2"]],"timestamp":1756900919350,"update_id":50198222,"fetch_time":1756900919394}
{"symbol":"TONUSDT","bids":[],"asks":[["3.1540","2422.7"],["3.1550","1347.0"],["3.1560","3557.3"]],"timestamp":1756900919369,"update_id":50198223,"fetch_time":1756900919414}
{"symbol":"TONUSDT","bids":[],"asks":[["3.1533","1547.0"],["3.1535","2731.4"],["3.1548","2450.7"]],"timestamp":1756900919389,"update_id":50198224,"fetch_time":1756900919439}
{"symbol":"TONUSDT","bids":[],"asks":[["3.1533","1829.1"]],"timestamp":1756900919430,"update_id":50198226,"fetch_time":1756900919474}
{"symbol":"TONUSDT","bids":[["3.1478","1343.0"]],"asks":[],"timestamp":1756900919470,"update_id":50198228,"fetch_time":1756900919514}
{"symbol":"TONUSDT","bids":[],"asks":[["3.1534","3590.9"]],"timestamp":1756900919489,"update_id":50198229,"fetch_time":1756900919539}
{"symbol":"TONUSDT","bids":[["3.1520","493.0"],["3.1505","3368.4"]],"asks":[],"timestamp":1756900919629,"update_id":50198233,"fetch_time":1756900919674}
{"symbol":"TONUSDT","bids":[["3.1520","401.4"],["3.1517","510.3"]],"asks":[],"timestamp":1756900919670,"update_id":50198235,"fetch_time":1756900919718}
{"symbol":"TONUSDT","bids":[],"asks":[["3.1530","188.8"],["3.1531","234.0"],["3.1536","1224.5"],["3.1538","1307.7"]],"timestamp":1756900919711,"update_id":50198237,"fetch_time":1756900919758}
{"symbol":"TONUSDT","bids":[["3.1516","842.5"],["3.1514","380.8"]],"asks":[],"timestamp":1756900919729,"update_id":50198238,"fetch_time":1756900919778}
{"symbol":"TONUSDT","bids":[],"asks":[["3.1532","2097.9"],["3.1563","1763.5"],["3.1565","932.5"]],"timestamp":1756900919790,"update_id":50198240,"fetch_time":1756900919842}
{"symbol":"TONUSDT","bids":[],"asks":[["3.1533","1671.5"]],"timestamp":1756900919849,"update_id":50198241,"fetch_time":1756900919894}
{"symbol":"TONUSDT","bids":[],"asks":[["3.1533","1201.5"]],"timestamp":1756900919889,"update_id":50198243,"fetch_time":1756900919939}
{"symbol":"TONUSDT","bids":[["3.1520","406.7"],["3.1519","11.1"],["3.1518","1013.1"],["3.1517","502.1"],["3.1505","3411.7"]],"asks":[],"timestamp":1756900919969,"update_id":50198244,"fetch_time":1756900920023}
{"symbol":"TONUSDT","bids":[["3.1518","1071.3"]],"asks":[],"timestamp":1756900920009,"update_id":50198245,"fetch_time":1756900920055}
{"symbol":"TONUSDT","bids":[["3.1487","875.2"]],"asks":[],"timestamp":1756900920030,"update_id":50198246,"fetch_time":1756900920075}
{"symbol":"TONUSDT","bids":[["3.1520","401.4"],["3.1519","0"],["3.1518","1044.4"],["3.1517","467.0"],["3.1516","842.5"],["3.1515","1719.2"],["3.1514","362.4"],["3.1513","563.4"],["3.1512","1123.6"],["3.1511","3237.9"],["3.1471","649.9"]],"asks":[],"timestamp":1756900920109,"update_id":50198247,"fetch_time":1756900920159}
{"symbol":"TONUSDT","bids":[["3.1515","1687.5"]],"asks":[],"timestamp":1756900920129,"update_id":50198248,"fetch_time":1756900920174}
{"symbol":"TONUSDT","bids":[["3.1516","823.8"]],"asks":[],"timestamp":1756900920150,"update_id":50198249,"fetch_time":1756900920194}
{"symbol":"TONUSDT","bids":[],"asks":[["3.1530","507.9"]],"timestamp":1756900920170,"update_id":50198250,"fetch_time":1756900920215}
{"symbol":"TONUSDT","bids":[["3.1520","407.7"],["3.1519","137.8"],["3.1518","1051.3"],["3.1517","510.2"],["3.1516","910.3"],["3.1515","1730.7"],["3.1514","377.1"],["3.1513","606.6"],["3.1512","1166.8"],["3.1511","3281.1"],["3.1471","0"]],"asks":[["3.1530","119.9"],["3.1531","5.7"],["3.1532","314.6"],["3.1533","590.3"]],"timestamp":1756900920209,"update_id":50198251,"fetch_time":1756900920254}
{"symbol":"TONUSDT","bids":[],"asks":[["3.1533","124.7"]],"timestamp":1756900920230,"update_id":50198252,"fetch_time":1756900920274}
{"symbol":"TONUSDT","bids":[],"asks":[["3.1533","406.7"],["3.1534","3372.2"],["3.1535","2919.3"],["3.1536","1412.5"]],"timestamp":1756900920249,"update_id":50198253,"fetch_time":1756900920294}
{"symbol":"TONUSDT","bids":[],"asks":[["3.1533","1335.8"]],"timestamp":1756900920269,"update_id":50198254,"fetch_time":1756900920314}
{"symbol":"TONUSDT","bids":[],"asks":[["3.1533","1650.2"],["3.1534","3560.1"]],"timestamp":1756900920309,"update_id":50198256,"fetch_time":1756900920358}
{"symbol":"TONUSDT","bids":[],"asks":[["3.1532","1590.7"]],"timestamp":1756900920329,"update_id":50198257,"fetch_time":1756900920374}
{"symbol":"TONUSDT","bids":[],"asks":[["3.1535","2731.4"]],"timestamp":1756900920390,"update_id":50198259,"fetch_time":1756900920434}
{"symbol":"TONUSDT","bids":[],"asks":[["3.1536","1224.5"]],"timestamp":1756900920410,"update_id":50198260,"fetch_time":1756900920454}
{"symbol":"TONUSDT","bids":[["3.1521","376.8"]],"asks":[],"timestamp":1756900920430,"update_id":50198261,"fetch_time":1756900920474}
{"symbol":"TONUSDT","bids":[],"asks":[["3.1532","2594.0"]],"timestamp":1756900920469,"update_id":50198263,"fetch_time":1756900920518}
{"symbol":"TONUSDT","bids":[],"asks":[["3.1529","234.8"],["3.1530","758.8"],["3.1531","821.1"]],"timestamp":1756900920529,"update_id":50198266,"fetch_time":1756900920578}
{"symbol":"TONUSDT","bids":[],"asks":[["3.1527","180.6"],["3.1532","2248.6"],["3.1533","1297.0"]],"timestamp":1756900920550,"update_id":50198267,"fetch_time":1756900920594}
{"symbol":"TONUSDT","bids":[],"asks":[["3.1527","3.2"],["3.1532","1966.5"],["3.1533","1014.9"],["3.1545","1072.1"]],"timestamp":1756900920569,"update_id":50198268,"fetch_time":1756900920614}
{"symbol":"TONUSDT","bids":[],"asks":[["3.1532","1657.1"]],"timestamp":1756900920589,"update_id":50198269,"fetch_time":1756900920634}
{"symbol":"TONUSDT","bids":[["3.1512","1166.8"]],"asks":[],"timestamp":1756900920650,"update_id":50198272,"fetch_time":1756900920694}
{"symbol":"TONUSDT","bids":[["3.1516","910.3"],["3.1515","1757.4"],["3.1514","415.1"],["3.1513","633.3"]],"asks":[],"timestamp":1756900920730,"update_id":50198273,"fetch_time":1756900920774}
{"symbol":"TONUSDT","bids":[],"asks":[["3.1529","3.2"]],"timestamp":1756900920829,"update_id":50198274,"fetch_time":1756900920874}
{"symbol":"TONUSDT","bids":[["3.1517","553.5"]],"asks":[],"timestamp":1756900920869,"update_id":50198275,"fetch_time":1756900920919}
{"symbol":"TONUSDT","bids":[["3.1518","1130.9"],["3.1506","2549.1"]],"asks":[],"timestamp":1756900920910,"update_id":50198276,"fetch_time":1756900920954}
{"symbol":"TONUSDT","bids":[["3.1507","2689.0"]],"asks":[],"timestamp":1756900921070,"update_id":50198277,"fetch_time":1756900921119}
{"symbol":"TONUSDT","bids":[["3.1520","394.9"]],"asks":[],"timestamp":1756900921109,"update_id":50198278,"fetch_time":1756900921154}
{"symbol":"TONUSDT","bids":[["3.1522","30.0"],["3.1521","376.5"],["3.1520","397.0"],["3.1519","174.3"],["3.1508","1451.2"],["3.1507","2645.7"],["3.1472","0"]],"asks":[["3.1522","0"],["3.1530","21.7"],["3.1531","5.7"],["3.1532","314.6"],["3.1533","124.7"],["3.1572","5352.6"]],"timestamp":1756900921210,"update_id":50198279,"fetch_time":1756900921254}
{"symbol":"TONUSDT","bids":[["3.1523","87.6"],["3.1522","487.6"],["3.1521","2.3"],["3.1520","409.7"],["3.1519","332.9"],["3.1518","1132.7"],["3.1517","490.4"],["3.1515","1697.2"],["3.1507","2602.5"],["3.1506","2513.4"],["3.1498","2032.8"],["3.1477","2052.4"],["3.1476","1363.8"],["3.1473","0"]],"asks":[["3.1523","0"],["3.1524","2.9"],["3.1533","406.7"],["3.1538","1307.7"],["3.1540","2422.7"],["3.1542","2342.4"],["3.1543","972.2"],["3.1544","3005.3"],["3.1545","1232.9"],["3.1546","3804.6"],["3.1548","2450.7"],["3.1557","952.0"],["3.1559","1254.1"],["3.1569","1247.1"],["3.1573","550.3"]],"timestamp":1756900921229,"update_id":50198280,"fetch_time":1756900921279}
{"symbol":"TONUSDT","bids":[["3.1520","619.3"],["3.1519","336.2"],["3.1518","2212.1"],["3.1486","684.7"]],"asks":[],"timestamp":1756900921289,"update_id":50198283,"fetch_time":1756900921335}
{"symbol":"TONUSDT","bids":[["3.1518","2130.1"]],"asks":[],"timestamp":1756900921329,"update_id":50198285,"fetch_time":1756900921374}
{"symbol":"TONUSDT","bids":[["3.1520","821.0"]],"asks":[],"timestamp":1756900921350,"update_id":50198286,"fetch_time":1756900921394}
{"symbol":"TONUSDT","bids":[],"asks":[["3.1532","593.3"]],"timestamp":1756900921369,"update_id":50198287,"fetch_time":1756900921414}
{"symbol":"TONUSDT","bids":[],"asks":[["3.1532","875.3"]],"timestamp":1756900921389,"update_id":50198288,"fetch_time":1756900921438}
{"symbol":"TONUSDT","bids":[],"asks":[["3.1532","1063.2"]],"timestamp":1756900921409,"update_id":50198289,"fetch_time":1756900921454}
{"symbol":"TONUSDT","bids":[],"asks":[["3.1531","55.7"],["3.1534","2093.4"]],"timestamp":1756900921430,"update_id":50198290,"fetch_time":1756900921474}
{"symbol":"TONUSDT","bids":[],"asks":[["3.1532","1126.6"],["3.1533","1354.6"],["3.1545","1232.9"]],"timestamp":1756900921469,"update_id":50198291,"fetch_time":1756900921514}
{"symbol":"TONUSDT","bids":[],"asks":[["3.1533","821.3"],["3.1563","1373.5"],["3.1567","2586.1"]],"timestamp":1756900921569,"update_id":50198294,"fetch_time":1756900921614}
{"symbol":"TONUSDT","bids":[["3.1523","96.2"]],"asks":[],"timestamp":1756900921610,"update_id":50198295,"fetch_time":1756900921654}
{"symbol":"TONUSDT","bids":[],"asks":[["3.1524","5.9"],["3.1559","1252.1"]],"timestamp":1756900921710,"update_id":50198296,"fetch_time":1756900921754}
{"symbol":"TONUSDT","bids":[],"asks":[["3.1559","1254.1"]],"timestamp":1756900921729,"update_id":50198297,"fetch_time":1756900921774}
{"symbol":"TONUSDT","bids":[],"asks":[["3.1533","1064.4"]],"timestamp":1756900921970,"update_id":50198299,"fetch_time":1756900922014}
{"symbol":"TONUSDT","bids":[],"asks":[["3.1544","3328.8"],["3.1545","985.5"]],"timestamp":1756900921989,"update_id":50198300,"fetch_time":1756900922034}
{"symbol":"TONUSDT","bids":[["3.1521","17.5"],["3.1520","808.3"]],"asks":[],"timestamp":1756900922030,"update_id":50198302,"fetch_time":1756900922074}
{"symbol":"TONUSDT","bids":[["3.1522","297.8"],["3.1519","318.9"],["3.1518","2086.9"],["3.1517","416.3"],["3.1510","1121.9"]],"asks":[],"timestamp":1756900922050,"update_id":50198303,"fetch_time":1756900922094}
{"symbol":"TONUSDT","bids":[],"asks":[["3.1534","3406.8"]],"timestamp":1756900922070,"update_id":50198304,"fetch_time":1756900922114}
{"symbol":"TONUSDT","bids":[],"asks":[["3.1535","2731.4"]],"timestamp":1756900922109,"update_id":50198305,"fetch_time":1756900922154}
{"symbol":"TONUSDT","bids":[["3.1518","2130.1"],["3.1517","459.5"]],"asks":[],"timestamp":1756900922130,"update_id":50198306,"fetch_time":1756900922174}
{"symbol":"TONUSDT","bids":[],"asks":[["3.1535","3546.7"],["3.1536","1475.8"],["3.1545","1117.0"]],"timestamp":1756900922269,"update_id":50198310,"fetch_time":1756900922318}
{"symbol":"TONUSDT","bids":[],"asks":[["3.1534","3635.1"],["3.1540","2426.0"]],"timestamp":1756900922310,"update_id":50198311,"fetch_time":1756900922354}
{"symbol":"TONUSDT","bids":[],"asks":[["3.1534","3980.5"],["3.1567","2512.3"],["3.1570","3047.8"]],"timestamp":1756900922329,"update_id":50198312,"fetch_time":1756900922374}
{"symbol":"TONUSDT","bids":[],"asks":[["3.1531","235.6"],["3.1533","1229.1"]],"timestamp":1756900922350,"update_id":50198313,"fetch_time":1756900922394}
{"symbol":"TONUSDT","bids":[],"asks":[["3.1533","1480.4"],["3.1535","3671.2"],["3.1536","1412.4"]],"timestamp":1756900922369,"update_id":50198314,"fetch_time":1756900922419}
{"symbol":"TONUSDT","bids":[],"asks":[["3.1535","3389.2"]],"timestamp":1756900922389,"update_id":50198315,"fetch_time":1756900922434}
{"symbol":"TONUSDT","bids":[["3.1523","173.2"],["3.1518","2221.8"],["3.1514","504.5"]],"asks":[],"timestamp":1756900922430,"update_id":50198317,"fetch_time":1756900922478}
{"symbol":"TONUSDT","bids":[],"asks":[["3.1535","2731.4"]],"timestamp":1756900922510,"update_id":50198319,"fetch_time":1756900922554}
{"symbol":"TONUSDT","bids":[["3.1522","304.1"]],"asks":[],"timestamp":1756900922570,"update_id":50198320,"fetch_time":1756900922614}
{"symbol":"TONUSDT","bids":[["3.1520","901.4"]],"asks":[],"timestamp":1756900922630,"update_id":50198321,"fetch_time":1756900922674}
{"symbol":"TONUSDT","bids":[["3.1519","391.2"]],"asks":[],"timestamp":1756900922669,"update_id":50198322,"fetch_time":1756900922715}
{"symbol":"TONUSDT","bids":[],"asks":[["3.1533","1762.4"]],"timestamp":1756900922690,"update_id":50198323,"fetch_time":1756900922738}
{"symbol":"TONUSDT","bids":[["3.1523","204.8"],["3.1516","750.9"]],"asks":[],"timestamp":1756900922749,"update_id":50198324,"fetch_time":1756900922798}
{"symbol":"TONUSDT","bids":[["3.1518","2253.5"]],"asks":[],"timestamp":1756900922810,"update_id":50198326,"fetch_time":1756900922858}
{"symbol":"TONUSDT","bids":[["3.1520","964.8"]],"asks":[],"timestamp":1756900922830,"update_id":50198327,"fetch_time":1756900922874}
{"symbol":"TONUSDT","bids":[["3.1520","1440.6"]],"asks":[],"timestamp":1756900922850,"update_id":50198328,"fetch_time":1756900922894}
{"symbol":"TONUSDT","bids":[["3.1521","260.4"],["3.1520","1432.2"],["3.1509","1794.7"],["3.1508","1494.5"]],"asks":[],"timestamp":1756900922869,"update_id":50198329,"fetch_time":1756900922914}
{"symbol":"TONUSDT","bids":[],"asks":[["3.1533","2028.1"]],"timestamp":1756900922990,"update_id":50198333,"fetch_time":1756900923034}
{"symbol":"TONUSDT","bids":[],"asks":[["3.1533","1558.2"]],"timestamp":1756900923009,"update_id":50198334,"fetch_time":1756900923055}
{"symbol":"TONUSDT","bids":[],"asks":[["3.1534","3447.2"]],"timestamp":1756900923029,"update_id":50198335,"fetch_time":1756900923079}
{"symbol":"TONUSDT","bids":[["3.1522","232.8"]],"asks":[],"timestamp":1756900923129,"update_id":50198336,"fetch_time":1756900923174}
{"symbol":"TONUSDT","bids":[],"asks":[["3.1565","1433.3"],["3.1567","1942.9"]],"timestamp":1756900923150,"update_id":50198337,"fetch_time":1756900923198}
{"symbol":"TONUSDT","bids":[["3.1524","78.5"],["3.1523","207.1"],["3.1521","277.9"],["3.1511","3344.5"],["3.1510","1078.6"],["3.1509","1688.0"],["3.1474","0"]],"asks":[["3.1524","0"],["3.1530","6.0"],["3.1532","311.3"],["3.1533","478.6"],["3.1534","2093.4"],["3.1535","2488.2"],["3.1536","1048.3"],["3.1541","1831.2"],["3.1542","2336.1"],["3.1545","1053.6"],["3.1547","974.9"],["3.1574","4573.5"]],"timestamp":1756900923209,"update_id":50198338,"fetch_time":1756900923254}
{"symbol":"TONUSDT","bids":[["3.1524","400.8"],["3.1522","336.2"],["3.1521","883.7"],["3.1519","428.7"]],"asks":[],"timestamp":1756900923329,"update_id":50198344,"fetch_time":1756900923374}
{"symbol":"TONUSDT","bids":[],"asks":[["3.1536","1330.3"],["3.1546","3899.1"],["3.1553","1341.4"]],"timestamp":1756900923369,"update_id":50198346,"fetch_time":1756900923414}
{"symbol":"TONUSDT","bids":[["3.1521","1050.5"],["3.1519","1284.8"]],"asks":[],"timestamp":1756900923390,"update_id":50198347,"fetch_time":1756900923434}
{"symbol":"TONUSDT","bids":[["3.1520","1768.1"],["3.1519","1316.4"]],"asks":[],"timestamp":1756900923409,"update_id":50198348,"fetch_time":1756900923454}
{"symbol":"TONUSDT","bids":[["3.1485","724.7"],["3.1476","1078.9"]],"asks":[],"timestamp":1756900923550,"update_id":50198353,"fetch_time":1756900923594}
{"symbol":"TONUSDT","bids":[],"asks":[["3.1535","3462.7"]],"timestamp":1756900923589,"update_id":50198354,"fetch_time":1756900923635}
{"symbol":"TONUSDT","bids":[],"asks":[["3.1535","2952.4"]],"timestamp":1756900923610,"update_id":50198355,"fetch_time":1756900923655}
{"symbol":"TONUSDT","bids":[],"asks":[["3.1535","2670.4"],["3.1537","1364.6"]],"timestamp":1756900923629,"update_id":50198356,"fetch_time":1756900923674}
{"symbol":"TONUSDT","bids":[],"asks":[["3.1535","2898.7"]],"timestamp":1756900923669,"update_id":50198357,"fetch_time":1756900923719}
{"symbol":"TONUSDT","bids":[],"asks":[["3.1533","546.5"]],"timestamp":1756900923729,"update_id":50198358,"fetch_time":1756900923779}
{"symbol":"TONUSDT","bids":[],"asks":[["3.1547","1164.8"]],"timestamp":1756900923809,"update_id":50198359,"fetch_time":1756900923854}
{"symbol":"TONUSDT","bids":[],"asks":[["3.1534","2720.8"]],"timestamp":1756900923829,"update_id":50198360,"fetch_time":1756900923874}
{"symbol":"TONUSDT","bids":[["3.1523","119.3"],["3.1511","2316.3"]],"asks":[],"timestamp":1756900923930,"update_id":50198361,"fetch_time":1756900923975}
{"symbol":"TONUSDT","bids":[["3.1522","782.4"],["3.1510","1121.9"]],"asks":[],"timestamp":1756900923950,"update_id":50198362,"fetch_time":1756900923995}
{"symbol":"TONUSDT","bids":[],"asks":[["3.1533","1174.0"]],"timestamp":1756900923989,"update_id":50198364,"fetch_time":1756900924035}
{"symbol":"TONUSDT","bids":[],"asks":[["3.1534","2156.8"],["3.1566","3705.5"],["3.1567","1942.9"]],"timestamp":1756900924029,"update_id":50198366,"fetch_time":1756900924075}
{"symbol":"TONUSDT","bids":[["3.1481","1191.8"]],"asks":[],"timestamp":1756900924050,"update_id":50198367,"fetch_time":1756900924100}
{"symbol":"TONUSDT","bids":[["3.1485","669.5"]],"asks":[],"timestamp":1756900924070,"update_id":50198368,"fetch_time":1756900924119}
{"symbol":"TONUSDT","bids":[],"asks":[["3.1534","2093.4"]],"timestamp":1756900924090,"update_id":50198369,"fetch_time":1756900924135}
{"symbol":"TONUSDT","bids":[["3.1519","1473.8"]],"asks":[],"timestamp":1756900924149,"update_id":50198370,"fetch_time":1756900924195}
{"symbol":"TONUSDT","bids":[],"asks":[["3.1535","2585.4"],["3.1538","1954.6"]],"timestamp":1756900924290,"update_id":50198375,"fetch_time":1756900924339}
{"symbol":"TONUSDT","bids":[],"asks":[["3.1535","3095.7"]],"timestamp":1756900924310,"update_id":50198376,"fetch_time":1756900924355}
{"symbol":"TONUSDT","bids":[],"asks":[["3.1536","726.3"],["3.1539","2013.7"]],"timestamp":1756900924330,"update_id":50198377,"fetch_time":1756900924379}
{"symbol":"TONUSDT","bids":[],"asks":[["3.1535","3159.1"]],"timestamp":1756900924350,"update_id":50198378,"fetch_time":1756900924394}
{"symbol":"TONUSDT","bids":[["3.1517","491.2"]],"asks":[],"timestamp":1756900924370,"update_id":50198379,"fetch_time":1756900924416}
{"symbol":"TONUSDT","bids":[],"asks":[["3.1536","662.9"]],"timestamp":1756900924390,"update_id":50198380,"fetch_time":1756900924436}
{"symbol":"TONUSDT","bids":[],"asks":[["3.1536","380.9"],["3.1537","1552.6"]],"timestamp":1756900924429,"update_id":50198381,"fetch_time":1756900924475}
{"symbol":"TONUSDT","bids":[],"asks":[["3.1533","438.4"]],"timestamp":1756900924450,"update_id":50198382,"fetch_time":1756900924499}
{"symbol":"TONUSDT","bids":[],"asks":[["3.1533","908.3"]],"timestamp":1756900924469,"update_id":50198383,"fetch_time":1756900924515}
{"symbol":"TONUSDT","bids":[],"asks":[["3.1546","3691.7"]],"timestamp":1756900924510,"update_id":50198385,"fetch_time":1756900924555}
{"symbol":"TONUSDT","bids":[["3.1518","2070.8"]],"asks":[],"timestamp":1756900924569,"update_id":50198387,"fetch_time":1756900924615}
{"symbol":"TONUSDT","bids":[["3.1524","398.5"],["3.1523","243.5"],["3.1509","1686.0"]],"asks":[],"timestamp":1756900924589,"update_id":50198388,"fetch_time":1756900924634}
{"symbol":"TONUSDT","bids":[["3.1520","2259.9"]],"asks":[],"timestamp":1756900924629,"update_id":50198389,"fetch_time":1756900924674}
{"symbol":"TONUSDT","bids":[["3.1522","1202.8"]],"asks":[],"timestamp":1756900924650,"update_id":50198390,"fetch_time":1756900924699}
{"symbol":"TONUSDT","bids":[["3.1520","2291.6"]],"asks":[],"timestamp":1756900924670,"update_id":50198391,"fetch_time":1756900924718}
{"symbol":"TONUSDT","bids":[],"asks":[["3.1560","3754.7"]],"timestamp":1756900924729,"update_id":50198394,"fetch_time":1756900924774}
{"symbol":"TONUSDT","bids":[["3.1508","983.7"],["3.1507","2195.3"],["3.1506","2322.4"]],"asks":[],"timestamp":1756900924810,"update_id":50198395,"fetch_time":1756900924859}
{"symbol":"TONUSDT","bids":[["3.1521","1018.0"],["3.1520","2250.0"],["3.1519","1425.3"],["3.1518","1984.3"],["3.1517","447.9"]],"asks":[],"timestamp":1756900924830,"update_id":50198396,"fetch_time":1756900924874}
{"symbol":"TONUSDT","bids":[["3.1519","1468.5"],["3.1518","2027.5"]],"asks":[],"timestamp":1756900924849,"update_id":50198397,"fetch_time":1756900924894}
{"symbol":"TONUSDT","bids":[["3.1524","0"],["3.1522","0"],["3.1518","1922.2"],["3.1517","5.6"],["3.1515","1155.2"],["3.1511","2619.5"],["3.1499","1595.0"],["3.1474","1850.1"],["3.1473","980.1"]],"asks":[["3.1533","358.6"]],"timestamp":1756900925049,"update_id":50198406,"fetch_time":1756900925098}
{"symbol":"TONUSDT","bids":[["3.1516","580.5"],["3.1512","657.1"],["3.1511","2662.8"],["3.1510","578.2"]],"asks":[],"timestamp":1756900925069,"update_id":50198407,"fetch_time":1756900925114}
{"symbol":"TONUSDT","bids":[["3.1518","1890.5"],["3.1512","931.8"]],"asks":[],"timestamp":1756900925089,"update_id":50198408,"fetch_time":1756900925134}
{"symbol":"TONUSDT","bids":[],"asks":[["3.1573","1816.9"],["3.1574","2000.5"]],"timestamp":1756900925109,"update_id":50198409,"fetch_time":1756900925154}
{"symbol":"TONUSDT","bids":[["3.1513","571.4"],["3.1499","643.6"],["3.1497","1922.2"]],"asks":[],"timestamp":1756900925130,"update_id":50198410,"fetch_time":1756900925175}
{"symbol":"TONUSDT","bids":[],"asks":[["3.1528","209.3"]],"timestamp":1756900925170,"update_id":50198412,"fetch_time":1756900925215}
{"symbol":"TONUSDT","bids":[["3.1524","20.0"],["3.1522","80.0"],["3.1519","89.7"],["3.1518","1977.0"],["3.1517","92.1"],["3.1506","2322.4"],["3.1474","0"],["3.1473","0"]],"asks":[["3.1528","5.0"],["3.1530","246.4"],["3.1532","585.7"],["3.1533","589.9"],["3.1538","2008.0"],["3.1544","3899.8"],["3.1566","3597.0"],["3.1570","2634.1"]],"timestamp":1756900925230,"update_id":50198414,"fetch_time":1756900925274}
{"symbol":"TONUSDT","bids":[],"asks":[["3.1529","19.6"],["3.1530","203.1"],["3.1531","1647.6"],["3.1533","633.1"],["3.1568","2161.4"],["3.1574","2000.5"]],"timestamp":1756900925249,"update_id":50198415,"fetch_time":1756900925299}
{"symbol":"TONUSDT","bids":[],"asks":[["3.1546","3534.5"],["3.1574","3267.1"]],"timestamp":1756900925369,"update_id":50198420,"fetch_time":1756900925414}
{"symbol":"TONUSDT","bids":[["3.1497","2113.2"]],"asks":[],"timestamp":1756900925409,"update_id":50198422,"fetch_time":1756900925459}
{"symbol":"TONUSDT","bids":[],"asks":[["3.1544","3709.8"]],"timestamp":1756900925430,"update_id":50198423,"fetch_time":1756900925478}
{"symbol":"TONUSDT","bids":[],"asks":[["3.1529","62.8"],["3.1543","1162.2"]],"timestamp":1756900925449,"update_id":50198424,"fetch_time":1756900925494}
{"symbol":"TONUSDT","bids":[["3.1520","770.1"],["3.1518","1714.3"]],"asks":[],"timestamp":1756900925470,"update_id":50198425,"fetch_time":1756900925514}
{"symbol":"TONUSDT","bids":[["3.1524","0"],["3.1474","1850.1"]],"asks":[],"timestamp":1756900925529,"update_id":50198427,"fetch_time":1756900925579}
{"symbol":"TONUSDT","bids":[["3.1522","0"],["3.1519","3.2"],["3.1473","980.1"]],"asks":[["3.1528","158.9"],["3.1574","2000.5"]],"timestamp":1756900925550,"update_id":50198428,"fetch_time":1756900925594}
{"symbol":"TONUSDT","bids":[],"asks":[["3.1534","4141.9"],["3.1572","4675.3"]],"timestamp":1756900925569,"update_id":50198429,"fetch_time":1756900925619}
{"symbol":"TONUSDT","bids":[["3.1524","136.8"],["3.1518","1798.8"],["3.1517","5.6"],["3.1516","623.7"],["3.1515","1077.1"],["3.1508","739.3"],["3.1473","0"]],"asks":[["3.1528","202.1"],["3.1530","439.0"],["3.1532","585.8"],["3.1533","589.9"]],"timestamp":1756900925590,"update_id":50198430,"fetch_time":1756900925635}
{"symbol":"TONUSDT","bids":[],"asks":[["3.1528","50.6"],["3.1532","765.9"],["3.1533","401.9"]],"timestamp":1756900925649,"update_id":50198433,"fetch_time":1756900925699}
{"symbol":"TONUSDT","bids":[],"asks":[["3.1574","3267.1"]],"timestamp":1756900925670,"update_id":50198434,"fetch_time":1756900925714}
{"symbol":"TONUSDT","bids":[],"asks":[["3.1532","953.8"],["3.1572","5000.6"]],"timestamp":1756900925690,"update_id":50198435,"fetch_time":1756900925734}
{"symbol":"TONUSDT","bids":[["3.1497","2304.2"]],"asks":[],"timestamp":1756900925710,"update_id":50198436,"fetch_time":1756900925754}
{"symbol":"TONUSDT","bids":[["3.1518","1610.9"],["3.1498","2940.4"]],"asks":[],"timestamp":1756900925729,"update_id":50198437,"fetch_time":1756900925774}
{"symbol":"TONUSDT","bids":[],"asks":[["3.1551","1359.7"]],"timestamp":1756900925749,"update_id":50198438,"fetch_time":1756900925799}
{"symbol":"TONUSDT","bids":[["3.1516","580.5"]],"asks":[],"timestamp":1756900925769,"update_id":50198439,"fetch_time":1756900925815}
{"symbol":"TONUSDT","bids":[],"asks":[["3.1538","2808.0"]],"timestamp":1756900925790,"update_id":50198440,"fetch_time":1756900925834}
{"symbol":"TONUSDT","bids":[],"asks":[["3.1536","2064.9"]],"timestamp":1756900925810,"update_id":50198441,"fetch_time":1756900925854}
{"symbol":"TONUSDT","bids":[],"asks":[["3.1549","528.5"]],"timestamp":1756900925930,"update_id":50198442,"fetch_time":1756900925974}
{"symbol":"TONUSDT","bids":[],"asks":[["3.1533","1298.2"],["3.1548","1246.8"]],"timestamp":1756900925949,"update_id":50198443,"fetch_time":1756900926002}
{"symbol":"TONUSDT","bids":[],"asks":[["3.1574","2000.5"]],"timestamp":1756900926070,"update_id":50198444,"fetch_time":1756900926119}
{"symbol":"TONUSDT","bids":[],"asks":[["3.1572","4675.3"]],"timestamp":1756900926089,"update_id":50198445,"fetch_time":1756900926134}
{"symbol":"TONUSDT","bids":[],"asks":[["3.1529","62.8"]],"timestamp":1756900926229,"update_id":50198447,"fetch_time":1756900926279}
{"symbol":"TONUSDT","bids":[],"asks":[["3.1533","1486.2"]],"timestamp":1756900926250,"update_id":50198448,"fetch_time":1756900926295}
{"symbol":"TONUSDT","bids":[],"asks":[["3.1535","2622.5"]],"timestamp":1756900926269,"update_id":50198449,"fetch_time":1756900926314}
{"symbol":"TONUSDT","bids":[["3.1505","3384.2"],["3.1502","747.0"],["3.1494","2127.7"],["3.1492","1742.8"],["3.1490","2712.2"],["3.1485","716.8"]],"asks":[],"timestamp":1756900926329,"update_id":50198451,"fetch_time":1756900926379}
{"symbol":"TONUSDT","bids":[["3.1524","136.7"]],"asks":[],"timestamp":1756900926370,"update_id":50198452,"fetch_time":1756900926414}
{"symbol":"TONUSDT","bids":[["3.1510","780.6"]],"asks":[],"timestamp":1756900926570,"update_id":50198453,"fetch_time":1756900926614}
{"symbol":"TONUSDT","bids":[["3.1498","2885.2"],["3.1485","772.0"]],"asks":[],"timestamp":1756900926589,"update_id":50198454,"fetch_time":1756900926634}
{"symbol":"TONUSDT","bids":[],"asks":[["3.1540","3124.4"],["3.1541","1933.2"]],"timestamp":1756900926649,"update_id":50198455,"fetch_time":1756900926694}
{"symbol":"TONUSDT","bids":[],"asks":[["3.1528","247.8"]],"timestamp":1756900926709,"update_id":50198458,"fetch_time":1756900926758}
{"symbol":"TONUSDT","bids":[],"asks":[["3.1526","9.2"],["3.1527","48.2"]],"timestamp":1756900926730,"update_id":50198459,"fetch_time":1756900926779}
{"symbol":"TONUSDT","bids":[],"asks":[["3.1529","383.3"],["3.1531","1671.8"],["3.1532","1121.4"]],"timestamp":1756900926750,"update_id":50198460,"fetch_time":1756900926795}
{"symbol":"TONUSDT","bids":[],"asks":[["3.1525","143.6"]],"timestamp":1756900926809,"update_id":50198461,"fetch_time":1756900926855}
{"symbol":"TONUSDT","bids":[["3.1524","0"],["3.1523","0"],["3.1521","0"],["3.1518","644.1"],["3.1516","331.2"],["3.1514","705.4"],["3.1513","3.2"],["3.1512","845.3"],["3.1511","2598.8"],["3.1505","3384.2"],["3.1504","3062.4"],["3.1503","1200.1"],["3.1496","4496.2"],["3.1478","2108.7"],["3.1477","2052.4"],["3.1473","980.1"],["3.1472","4270.1"],["3.1471","649.9"]],"asks":[["3.1521","88.9"],["3.1522","147.7"],["3.1523","135.8"],["3.1524","58.6"],["3.1525","249.5"],["3.1526","69.0"],["3.1527","444.8"],["3.1528","512.3"],["3.1529","1504.2"],["3.1530","633.8"],["3.1531","1645.7"],["3.1532","904.6"],["3.1533","1983.2"],["3.1535","3364.4"],["3.1537","1428.0"],["3.1538","2570.5"],["3.1540","2426.0"],["3.1542","2336.1"],["3.1544","3007.1"],["3.1546","2460.2"],["3.1557","954.0"],["3.1560","3752.7"],["3.1568","3131.9"],["3.1571","0"],["3.1572","0"],["3.1573","0"],["3.1574","0"]],"timestamp":1756900926969,"update_id":50198469,"fetch_time":1756900927015}
{"symbol":"TONUSDT","bids":[["3.1520","0"],["3.1519","193.2"],["3.1517","291.1"],["3.1514","463.0"],["3.1492","1111.1"],["3.1480","7130.4"],["3.1470","4104.4"]],"asks":[["3.1522","0"],["3.1524","217.2"],["3.1525","251.9"],["3.1526","257.0"],["3.1527","1338.7"],["3.1529","1345.6"],["3.1538","2812.1"],["3.1542","1294.5"],["3.1556","6734.5"],["3.1557","952.0"],["3.1571","601.6"]],"timestamp":1756900926989,"update_id":50198470,"fetch_time":1756900927034}
{"symbol":"TONUSDT","bids":[["3.1519","0"],["3.1518","640.9"],["3.1515","144.2"],["3.1514","259.2"],["3.1513","246.3"],["3.1507","1402.2"],["3.1498","2517.8"],["3.1496","4040.7"],["3.1494","1584.1"],["3.1490","1992.4"],["3.1488","2025.8"],["3.1471","1017.3"],["3.1469","641.4"]],"asks":[["3.1520","118.9"],["3.1521","0"],["3.1524","222.2"],["3.1525","410.4"],["3.1527","1462.3"],["3.1528","831.9"],["3.1544","3005.3"],["3.1555","916.0"],["3.1556","6732.5"]],"timestamp":1756900927009,"update_id":50198471,"fetch_time":1756900927055}
{"symbol":"TONUSDT","bids":[["3.1513","434.2"],["3.1512","858.9"],["3.1511","2576.3"],["3.1505","3441.0"],["3.1504","3007.7"],["3.1496","3705.6"]],"asks":[["3.1522","14.3"],["3.1525","826.0"],["3.1529","1997.5"],["3.1530","445.8"],["3.1532","847.0"],["3.1545","730.2"],["3.1571","0"]],"timestamp":1756900927049,"update_id":50198473,"fetch_time":1756900927099}
{"symbol":"TONUSDT","bids":[["3.1514","207.1"],["3.1512","845.3"],["3.1509","945.4"],["3.1505","3384.2"],["3.1503","1264.4"],["3.1501","446.6"],["3.1493","494.3"],["3.1490","2239.9"]],"asks":[["3.1522","0"],["3.1523","353.6"],["3.1525","854.6"],["3.1526","821.2"],["3.1529","1487.0"],["3.1530","1367.1"],["3.1531","1363.6"],["3.1532","918.8"],["3.1544","2517.0"],["3.1545","982.0"],["3.1571","601.6"]],"timestamp":1756900927069,"update_id":50198474,"fetch_time":1756900927114}
{"symbol":"TONUSDT","bids":[["3.1509","988.6"]],"asks":[],"timestamp":1756900927090,"update_id":50198475,"fetch_time":1756900927138}
{"symbol":"TONUSDT","bids":[["3.1519","192.3"],["3.1495","1326.6"],["3.1469","0"]],"asks":[["3.1520","0"],["3.1523","135.8"],["3.1524","219.0"],["3.1525","415.3"],["3.1526","69.0"],["3.1527","568.4"],["3.1530","1115.8"],["3.1535","3079.6"],["3.1555","914.0"],["3.1558","3038.1"],["3.1572","5942.0"]],"timestamp":1756900927149,"update_id":50198477,"fetch_time":1756900927194}
{"symbol":"TONUSDT","bids":[],"asks":[["3.1524","60.4"],["3.1525","256.8"],["3.1527","286.3"],["3.1528","895.3"],["3.1529","1686.3"],["3.1536","2290.1"]],"timestamp":1756900927169,"update_id":50198478,"fetch_time":1756900927215}
{"symbol":"TONUSDT","bids":[["3.1513","1086.1"],["3.1507","1636.4"],["3.1501","661.1"],["3.1500","1034.8"]],"asks":[["3.1522","28.8"],["3.1527","256.8"],["3.1528","1233.7"],["3.1557","954.0"],["3.1558","3036.1"],["3.1572","0"]],"timestamp":1756900927210,"update_id":50198480,"fetch_time":1756900927259}
{"symbol":"TONUSDT","bids":[],"asks":[["3.1529","1103.3"]],"timestamp":1756900927270,"update_id":50198483,"fetch_time":1756900927319}
{"symbol":"TONUSDT","bids":[],"asks":[["3.1528","1233.7"],["3.1542","2659.7"],["3.1546","3099.5"]],"timestamp":1756900927289,"update_id":50198484,"fetch_time":1756900927334}
{"symbol":"TONUSDT","bids":[],"asks":[["3.1528","1565.5"]],"timestamp":1756900927309,"update_id":50198485,"fetch_time":1756900927354}
{"symbol":"TONUSDT","bids":[["3.1520","2.1"],["3.1516","506.7"],["3.1470","0"]],"asks":[["3.1534","4141.9"],["3.1535","2725.1"]],"timestamp":1756900927369,"update_id":50198488,"fetch_time":1756900927414}
{"symbol":"TONUSDT","bids":[["3.1515","332.1"]],"asks":[],"timestamp":1756900927389,"update_id":50198489,"fetch_time":1756900927435}
{"symbol":"TONUSDT","bids":[["3.1517","370.4"]],"asks":[],"timestamp":1756900927409,"update_id":50198490,"fetch_time":1756900927455}
{"symbol":"TONUSDT","bids":[["3.1514","381.7"]],"asks":[],"timestamp":1756900927450,"update_id":50198491,"fetch_time":1756900927494}
{"symbol":"TONUSDT","bids":[],"asks":[["3.1527","1072.3"]],"timestamp":1756900927570,"update_id":50198492,"fetch_time":1756900927615}
{"symbol":"TONUSDT","bids":[],"asks":[["3.1535","2440.3"]],"timestamp":1756900927650,"update_id":50198493,"fetch_time":1756900927699}
{"symbol":"TONUSDT","bids":[["3.1516","333.3"]],"asks":[],"timestamp":1756900927689,"update_id":50198495,"fetch_time":1756900927738}
{"symbol":"TONUSDT","bids":[],"asks":[["3.1539","2300.2"]],"timestamp":1756900927769,"update_id":50198496,"fetch_time":1756900927814}
{"symbol":"TONUSDT","bids":[["3.1507","1870.7"]],"asks":[],"timestamp":1756900927789,"update_id":50198497,"fetch_time":1756900927834}
{"symbol":"TONUSDT","bids":[["3.1510","653.2"],["3.1509","966.2"]],"asks":[],"timestamp":1756900927810,"update_id":50198498,"fetch_time":1756900927859}
{"symbol":"TONUSDT","bids":[["3.1506","2238.1"]],"asks":[],"timestamp":1756900927870,"update_id":50198499,"fetch_time":1756900927914}
{"symbol":"TONUSDT","bids":[["3.1510","780.0"],["3.1505","3575.2"]],"asks":[],"timestamp":1756900927969,"update_id":50198500,"fetch_time":1756900928014}
{"symbol":"TONUSDT","bids":[],"asks":[["3.1523","129.5"]],"timestamp":1756900927989,"update_id":50198501,"fetch_time":1756900928034}
{"symbol":"TONUSDT","bids":[["3.1520","0"],["3.1519","0"],["3.1517","687.6"],["3.1516","6.6"],["3.1515","415.8"],["3.1470","4104.4"],["3.1469","641.4"]],"asks":[["3.1520","28.8"],["3.1521","122.9"],["3.1522","0"],["3.1525","410.8"],["3.1527","1503.3"],["3.1528","878.2"],["3.1533","1727.3"],["3.1534","4141.9"],["3.1556","6734.5"],["3.1557","952.0"],["3.1571","0"]],"timestamp":1756900928010,"update_id":50198502,"fetch_time":1756900928055}
{"symbol":"TONUSDT","bids":[["3.1518","640.9"],["3.1517","684.4"],["3.1516","152.7"],["3.1515","144.2"]],"asks":[["3.1519","74.4"],["3.1520","140.0"],["3.1522","43.2"],["3.1523","159.5"],["3.1524","285.5"],["3.1525","692.8"],["3.1527","1344.7"],["3.1528","835.0"],["3.1529","1060.1"],["3.1530","1676.4"],["3.1531","899.9"],["3.1533","1456.7"],["3.1554","3351.6"],["3.1556","6732.5"],["3.1569","0"],["3.1570","0"]],"timestamp":1756900928029,"update_id":50198503,"fetch_time":1756900928079}
{"symbol":"TONUSDT","bids":[["3.1518","0"],["3.1517","0"],["3.1516","0"],["3.1515","127.9"],["3.1514","317.8"],["3.1513","3.2"],["3.1510","497.8"],["3.1509","893.0"],["3.1508","696.0"],["3.1507","1814.2"],["3.1506","2194.9"],["3.1499","663.6"],["3.1496","3066.5"],["3.1488","1262.2"],["3.1477","246.6"],["3.1471","2823.1"],["3.1468","2796.9"],["3.1467","2201.4"],["3.1466","3730.1"]],"asks":[["3.1517","118.9"],["3.1518","147.7"],["3.1519","76.7"],["3.1521","178.7"],["3.1522","390.9"],["3.1523","336.9"],["3.1524","1244.2"],["3.1525","1190.7"],["3.1526","641.2"],["3.1527","1322.4"],["3.1528","1173.5"],["3.1530","2272.5"],["3.1532","1670.9"],["3.1536","1817.2"],["3.1538","2812.1"],["3.1540","2426.0"],["3.1542","2246.0"],["3.1544","2576.2"],["3.1546","2460.2"],["3.1567","0"],["3.1568","0"]],"timestamp":1756900928049,"update_id":50198504,"fetch_time":1756900928095}
{"symbol":"TONUSDT","bids":[["3.1514","162.8"],["3.1511","1686.3"],["3.1508","666.0"],["3.1507","1465.9"],["3.1505","1675.2"],["3.1504","1107.7"],["3.1502","777.0"],["3.1501","691.1"],["3.1500","1515.0"],["3.1499","693.6"],["3.1498","3978.8"],["3.1497","3031.8"],["3.1495","1135.6"],["3.1490","1888.2"],["3.1480","7720.1"],["3.1471","1017.3"],["3.1469","2447.2"]],"asks":[["3.1516","28.8"],["3.1517","0"],["3.1518","0"],["3.1520","298.5"],["3.1522","392.7"],["3.1523","402.6"],["3.1526","482.7"],["3.1527","1272.4"],["3.1528","1955.1"],["3.1534","2271.9"],["3.1536","3687.2"],["3.1539","2482.4"],["3.1540","2424.2"],["3.1542","2244.2"],["3.1551","1097.2"],["3.1554","3349.6"],["3.1561","2605.5"],["3.1566","3347.0"],["3.1567","565.6"]],"timestamp":1756900928070,"update_id":50198505,"fetch_time":1756900928115}
{"symbol":"TONUSDT","bids":[["3.1515","1.0"],["3.1514","4.2"],["3.1512","570.6"],["3.1511","5.6"],["3.1510","348.5"],["3.1509","3.2"],["3.1507","194.2"],["3.1506","546.9"],["3.1505","392.5"],["3.1503","712.9"],["3.1502","747.0"],["3.1501","288.0"],["3.1500","1902.3"],["3.1499","476.3"],["3.1498","2108.8"],["3.1497","1161.8"],["3.1495","2877.0"],["3.1494","3484.1"],["3.1490","1640.7"],["3.1478","838.3"],["3.1474","3120.7"]],"asks":[["3.1516","68.6"],["3.1517","6.6"],["3.1519","269.5"],["3.1520","538.5"],["3.1521","229.9"],["3.1522","824.7"],["3.1523","1068.1"],["3.1525","1223.7"],["3.1526","758.2"],["3.1527","685.5"],["3.1528","1911.8"],["3.1529","1016.8"],["3.1530","2299.3"],["3.1532","2102.5"],["3.1533","401.9"],["3.1534","3313.5"],["3.1537","1364.6"],["3.1538","1707.1"],["3.1539","1463.8"],["3.1567","0"]],"timestamp":1756900928089,"update_id":50198506,"fetch_time":1756900928139}
{"symbol":"TONUSDT","bids":[["3.1515","0"],["3.1514","1.8"],["3.1512","5.0"],["3.1510","5.0"],["3.1509","183.3"],["3.1508","170.4"],["3.1507","191.1"],["3.1506","476.8"],["3.1505","201.5"],["3.1504","1777.5"],["3.1502","600.2"],["3.1501","570.1"],["3.1500","1422.1"],["3.1498","2175.6"],["3.1496","3257.5"],["3.1495","2775.0"],["3.1484","1430.6"],["3.1483","466.9"],["3.1465","10921.4"]],"asks":[["3.1515","310.3"],["3.1516","2.3"],["3.1518","240.1"],["3.1519","256.3"],["3.1520","843.4"],["3.1521","203.1"],["3.1522","1003.2"],["3.1523","1693.6"],["3.1524","1389.2"],["3.1525","1221.4"],["3.1526","1537.4"],["3.1527","753.0"],["3.1530","2229.2"],["3.1531","1224.6"],["3.1533","358.6"],["3.1535","2212.0"],["3.1536","3450.2"],["3.1539","1723.6"],["3.1545","730.2"],["3.1550","1349.0"],["3.1551","1095.2"],["3.1552","2639.5"],["3.1557","1268.8"],["3.1561","2289.4"],["3.1563","2640.5"],["3.1565","0"],["3.1566","0"]],"timestamp":1756900928109,"update_id":50198507,"fetch_time":1756900928155}
{"symbol":"TONUSDT","bids":[["3.1504","2008.4"]],"asks":[["3.1515","308.0"],["3.1516","0"],["3.1518","1056.4"],["3.1522","1167.4"],["3.1524","3127.7"],["3.1525","2809.4"],["3.1535","342.0"],["3.1536","1580.2"],["3.1538","1307.7"],["3.1540","3314.1"],["3.1548","2703.2"],["3.1550","1724.1"],["3.1565","2551.3"]],"timestamp":1756900928250,"update_id":50198514,"fetch_time":1756900928295}
{"symbol":"TONUSDT","bids":[],"asks":[["3.1519","1041.7"],["3.1524","3657.5"],["3.1535","751.7"],["3.1541","1608.5"],["3.1553","956.7"],["3.1562","5578.4"]],"timestamp":1756900928289,"update_id":50198516,"fetch_time":1756900928339}
{"symbol":"TONUSDT","bids":[],"asks":[["3.1519","1073.4"],["3.1540","3042.5"],["3.1544","3542.0"],["3.1550","1349.0"]],"timestamp":1756900928310,"update_id":50198517,"fetch_time":1756900928355}
{"symbol":"TONUSDT","bids":[],"asks":[["3.1526","1852.9"],["3.1545","774.4"],["3.1547","1625.9"],["3.1549","1754.8"],["3.1555","869.8"]],"timestamp":1756900928350,"update_id":50198519,"fetch_time":1756900928394}
{"symbol":"TONUSDT","bids":[],"asks":[["3.1516","6.6"],["3.1520","2496.1"],["3.1565","0"]],"timestamp":1756900928370,"update_id":50198520,"fetch_time":1756900928415}
{"symbol":"TONUSDT","bids":[["3.1507","202.6"]],"asks":[],"timestamp":1756900928429,"update_id":50198523,"fetch_time":1756900928474}
{"symbol":"TONUSDT","bids":[],"asks":[["3.1529","3093.7"]],"timestamp":1756900928450,"update_id":50198524,"fetch_time":1756900928499}
{"symbol":"TONUSDT","bids":[],"asks":[["3.1540","2756.0"]],"timestamp":1756900928469,"update_id":50198525,"fetch_time":1756900928515}
{"symbol":"TONUSDT","bids":[],"asks":[["3.1515","339.6"],["3.1518","1119.1"],["3.1519","1168.5"],["3.1520","2527.5"],["3.1521","1878.0"],["3.1522","1649.2"],["3.1533","1310.3"],["3.1537","1514.6"],["3.1543","628.4"]],"timestamp":1756900928489,"update_id":50198526,"fetch_time":1756900928535}
{"symbol":"TONUSDT","bids":[],"asks":[["3.1532","2629.4"]],"timestamp":1756900928510,"update_id":50198527,"fetch_time":1756900928559}
{"symbol":"TONUSDT","bids":[["3.1503","837.2"]],"asks":[],"timestamp":1756900928630,"update_id":50198529,"fetch_time":1756900928675}
{"symbol":"TONUSDT","bids":[["3.1479","300.1"]],"asks":[],"timestamp":1756900928769,"update_id":50198535,"fetch_time":1756900928815}
{"symbol":"TONUSDT","bids":[["3.1503","837.2"]],"asks":[["3.1516","0"],["3.1524","3928.2"],["3.1565","2551.3"]],"timestamp":1756900928829,"update_id":50198536,"fetch_time":1756900928874}
{"symbol":"TONUSDT","bids":[],"asks":[["3.1540","2545.9"]],"timestamp":1756900928849,"update_id":50198537,"fetch_time":1756900928894}
{"symbol":"TONUSDT","bids":[],"asks":[["3.1519","1208.0"]],"timestamp":1756900928890,"update_id":50198538,"fetch_time":1756900928939}
{"symbol":"TONUSDT","bids":[],"asks":[["3.1518","1357.0"]],"timestamp":1756900929010,"update_id":50198540,"fetch_time":1756900929055}
{"symbol":"TONUSDT","bids":[],"asks":[["3.1516","31.6"],["3.1520","2653.8"],["3.1543","341.9"],["3.1565","0"]],"timestamp":1756900929050,"update_id":50198541,"fetch_time":1756900929099}
{"symbol":"TONUSDT","bids":[["3.1506","1018.9"],["3.1505","444.6"]],"asks":[],"timestamp":1756900929090,"update_id":50198543,"fetch_time":1756900929134}
{"symbol":"TONUSDT","bids":[["3.1496","3471.6"],["3.1486","741.4"]],"asks":[],"timestamp":1756900929130,"update_id":50198544,"fetch_time":1756900929174}
{"symbol":"TONUSDT","bids":[],"asks":[["3.1532","2632.7"],["3.1540","2542.6"]],"timestamp":1756900929150,"update_id":50198545,"fetch_time":1756900929194}
{"symbol":"TONUSDT","bids":[],"asks":[["3.1541","2358.7"]],"timestamp":1756900929170,"update_id":50198546,"fetch_time":1756900929215}
{"symbol":"TONUSDT","bids":[["3.1497","970.8"]],"asks":[],"timestamp":1756900929209,"update_id":50198547,"fetch_time":1756900929254}
{"symbol":"TONUSDT","bids":[["3.1498","2022.3"]],"asks":[],"timestamp":1756900929230,"update_id":50198548,"fetch_time":1756900929274}
{"symbol":"TONUSDT","bids":[],"asks":[["3.1539","2565.0"]],"timestamp":1756900929330,"update_id":50198551,"fetch_time":1756900929380}
{"symbol":"TONUSDT","bids":[],"asks":[["3.1519","1270.7"],["3.1520","3044.3"]],"timestamp":1756900929489,"update_id":50198554,"fetch_time":1756900929540}
{"symbol":"TONUSDT","bids":[],"asks":[["3.1517","187.7"]],"timestamp":1756900929510,"update_id":50198555,"fetch_time":1756900929556}
{"symbol":"TONUSDT","bids":[],"asks":[["3.1540","2275.2"]],"timestamp":1756900929550,"update_id":50198556,"fetch_time":1756900929599}
{"symbol":"TONUSDT","bids":[],"asks":[["3.1518","1142.5"]],"timestamp":1756900929629,"update_id":50198559,"fetch_time":1756900929675}
{"symbol":"TONUSDT","bids":[],"asks":[["3.1541","2034.0"]],"timestamp":1756900929670,"update_id":50198560,"fetch_time":1756900929715}
{"symbol":"TONUSDT","bids":[["3.1505","469.7"],["3.1504","1088.2"]],"asks":[],"timestamp":1756900929710,"update_id":50198561,"fetch_time":1756900929755}
{"symbol":"TONUSDT","bids":[],"asks":[["3.1524","3657.5"]],"timestamp":1756900929729,"update_id":50198562,"fetch_time":1756900929774}
{"symbol":"TONUSDT","bids":[],"asks":[["3.1523","1929.8"]],"timestamp":1756900929750,"update_id":50198563,"fetch_time":1756900929799}
{"symbol":"TONUSDT","bids":[["3.1502","947.8"]],"asks":[],"timestamp":1756900929889,"update_id":50198566,"fetch_time":1756900929934}
{"symbol":"TONUSDT","bids":[],"asks":[["3.1522","1980.3"]],"timestamp":1756900929929,"update_id":50198568,"fetch_time":1756900929974}
{"symbol":"TONUSDT","bids":[],"asks":[["3.1520","3046.1"],["3.1521","2124.3"]],"timestamp":1756900930070,"update_id":50198569,"fetch_time":1756900930114}
{"symbol":"TONUSDT","bids":[["3.1508","7.4"]],"asks":[],"timestamp":1756900930170,"update_id":50198571,"fetch_time":1756900930215}
{"symbol":"TONUSDT","bids":[["3.1514","0"],["3.1501","786.8"],["3.1464","1930.6"]],"asks":[["3.1519","1683.1"]],"timestamp":1756900930250,"update_id":50198573,"fetch_time":1756900930294}
{"symbol":"TONUSDT","bids":[["3.1513","0"],["3.1512","1.8"],["3.1506","359.2"],["3.1501","570.1"],["3.1463","2055.8"]],"asks":[["3.1513","299.0"],["3.1514","31.6"],["3.1515","330.1"],["3.1516","1048.4"],["3.1517","534.4"],["3.1518","481.2"],["3.1519","2109.6"],["3.1520","2909.3"],["3.1521","2538.0"],["3.1522","1744.1"],["3.1523","1666.8"],["3.1524","3607.5"],["3.1528","2529.6"],["3.1530","3654.5"],["3.1532","1880.6"],["3.1538","1305.9"],["3.1548","2705.2"],["3.1550","1534.6"],["3.1553","1351.7"],["3.1561","3556.5"],["3.1563","0"],["3.1564","0"]],"timestamp":1756900930269,"update_id":50198574,"fetch_time":1756900930314}
{"symbol":"TONUSDT","bids":[],"asks":[["3.1516","908.2"],["3.1518","1484.0"],["3.1519","2539.5"],["3.1520","2936.4"],["3.1521","2752.3"],["3.1547","2218.6"],["3.1554","2859.9"]],"timestamp":1756900930329,"update_id":50198577,"fetch_time":1756900930375}
{"symbol":"TONUSDT","bids":[],"asks":[["3.1516","937.7"],["3.1517","1417.5"]],"timestamp":1756900930489,"update_id":50198584,"fetch_time":1756900930535}
{"symbol":"TONUSDT","bids":[],"asks":[["3.1515","495.6"],["3.1516","969.4"]],"timestamp":1756900930510,"update_id":50198585,"fetch_time":1756900930559}
{"symbol":"TONUSDT","bids":[],"asks":[["3.1519","2712.4"]],"timestamp":1756900930530,"update_id":50198586,"fetch_time":1756900930579}
{"symbol":"TONUSDT","bids":[["3.1502","788.0"],["3.1500","1422.1"]],"asks":[],"timestamp":1756900930569,"update_id":50198587,"fetch_time":1756900930615}
{"symbol":"TONUSDT","bids":[["3.1472","5046.0"],["3.1468","2897.8"]],"asks":[],"timestamp":1756900930610,"update_id":50198588,"fetch_time":1756900930655}
{"symbol":"TONUSDT","bids":[["3.1503","216.3"],["3.1501","411.5"]],"asks":[],"timestamp":1756900930670,"update_id":50198589,"fetch_time":1756900930715}
{"symbol":"TONUSDT","bids":[["3.1504","892.7"]],"asks":[],"timestamp":1756900930689,"update_id":50198590,"fetch_time":1756900930734}
{"symbol":"TONUSDT","bids":[["3.1498","2172.2"]],"asks":[],"timestamp":1756900930729,"update_id":50198591,"fetch_time":1756900930779}
{"symbol":"TONUSDT","bids":[["3.1502","600.2"]],"asks":[],"timestamp":1756900930769,"update_id":50198592,"fetch_time":1756900930814}
{"symbol":"TONUSDT","bids":[["3.1504","710.4"]],"asks":[],"timestamp":1756900930790,"update_id":50198593,"fetch_time":1756900930839}
{"symbol":"TONUSDT","bids":[],"asks":[["3.1535","1313.5"],["3.1540","1385.3"]],"timestamp":1756900930870,"update_id":50198594,"fetch_time":1756900930915}
{"symbol":"TONUSDT","bids":[],"asks":[["3.1516","1001.0"]],"timestamp":1756900930910,"update_id":50198595,"fetch_time":1756900930955}
{"symbol":"TONUSDT","bids":[],"asks":[["3.1513","330.6"],["3.1514","37.9"]],"timestamp":1756900930989,"update_id":50198597,"fetch_time":1756900931035}
{"symbol":"TONUSDT","bids":[],"asks":[["3.1516","1239.0"]],"timestamp":1756900931009,"update_id":50198598,"fetch_time":1756900931059}
{"symbol":"TONUSDT","bids":[],"asks":[["3.1518","1512.4"]],"timestamp":1756900931069,"update_id":50198599,"fetch_time":1756900931119}
{"symbol":"TONUSDT","bids":[],"asks":[["3.1513","362.2"],["3.1518","1543.9"],["3.1544","3482.8"]],"timestamp":1756900931090,"update_id":50198600,"fetch_time":1756900931135}
{"symbol":"TONUSDT","bids":[["3.1469","641.4"]],"asks":[],"timestamp":1756900931129,"update_id":50198601,"fetch_time":1756900931175}
{"symbol":"TONUSDT","bids":[],"asks":[["3.1517","1203.2"],["3.1518","1517.3"],["3.1519","2739.0"]],"timestamp":1756900931309,"update_id":50198604,"fetch_time":1756900931355}
{"symbol":"TONUSDT","bids":[],"asks":[["3.1518","1753.6"],["3.1519","2502.7"]],"timestamp":1756900931329,"update_id":50198605,"fetch_time":1756900931379}
{"symbol":"TONUSDT","bids":[],"asks":[["3.1517","1234.9"]],"timestamp":1756900931350,"update_id":50198606,"fetch_time":1756900931395}
{"symbol":"TONUSDT","bids":[["3.1499","817.1"]],"asks":[],"timestamp":1756900931369,"update_id":50198607,"fetch_time":1756900931415}
{"symbol":"TONUSDT","bids":[["3.1497","1014.4"]],"asks":[],"timestamp":1756900931410,"update_id":50198608,"fetch_time":1756900931455}
{"symbol":"TONUSDT","bids":[],"asks":[["3.1529","4754.3"],["3.1532","993.7"],["3.1533","11.0"]],"timestamp":1756900931529,"update_id":50198609,"fetch_time":1756900931583}
{"symbol":"TONUSDT","bids":[["3.1512","24.7"]],"asks":[],"timestamp":1756900931829,"update_id":50198613,"fetch_time":1756900931879}
{"symbol":"TONUSDT","bids":[["3.1501","861.2"]],"asks":[],"timestamp":1756900931909,"update_id":50198614,"fetch_time":1756900932062}
{"symbol":"TONUSDT","bids":[],"asks":[["3.1513","367.8"],["3.1545","968.7"],["3.1550","1347.0"]],"timestamp":1756900931970,"update_id":50198615,"fetch_time":1756900932062}
{"symbol":"TONUSDT","bids":[["3.1499","600.4"],["3.1498","2193.9"]],"asks":[],"timestamp":1756900931989,"update_id":50198616,"fetch_time":1756900932062}
{"symbol":"TONUSDT","bids":[["3.1500","1572.8"]],"asks":[],"timestamp":1756900932009,"update_id":50198617,"fetch_time":1756900932062}
{"symbol":"TONUSDT","bids":[["3.1504","923.5"]],"asks":[],"timestamp":1756900932069,"update_id":50198618,"fetch_time":1756900932116}
{"symbol":"TONUSDT","bids":[],"asks":[["3.1528","2599.6"],["3.1529","4467.8"],["3.1530","2694.9"],["3.1531","1186.4"],["3.1532","649.9"],["3.1546","2629.5"],["3.1549","1817.0"],["3.1551","1181.0"],["3.1555","987.2"]],"timestamp":1756900932089,"update_id":50198619,"fetch_time":1756900932143}
{"symbol":"TONUSDT","bids":[],"asks":[["3.1517","1046.8"],["3.1519","2201.8"],["3.1521","2338.6"],["3.1522","1469.5"],["3.1524","3306.6"],["3.1526","1432.9"],["3.1531","1374.5"],["3.1533","781.4"],["3.1535","1727.2"],["3.1537","2041.1"],["3.1539","2973.0"],["3.1541","2754.4"]],"timestamp":1756900932110,"update_id":50198620,"fetch_time":1756900932159}
{"symbol":"TONUSDT","bids":[],"asks":[["3.1517","1330.2"],["3.1518","1517.3"],["3.1540","1653.0"]],"timestamp":1756900932130,"update_id":50198621,"fetch_time":1756900932176}
{"symbol":"TONUSDT","bids":[["3.1512","0"],["3.1511","0"],["3.1504","859.6"],["3.1501","411.5"],["3.1499","476.3"],["3.1462","1915.4"],["3.1461","1705.2"]],"asks":[["3.1511","242.7"],["3.1512","48.8"],["3.1516","1878.1"],["3.1518","1705.4"],["3.1520","2517.7"],["3.1522","1883.2"],["3.1524","3833.1"],["3.1526","2072.2"],["3.1528","3351.7"],["3.1531","1186.4"],["3.1533","480.5"],["3.1535","1313.5"],["3.1537","1514.6"],["3.1539","2333.7"],["3.1541","2002.3"],["3.1561","0"],["3.1562","0"]],"timestamp":1756900932150,"update_id":50198622,"fetch_time":1756900932203}
{"symbol":"TONUSDT","bids":[["3.1505","19.0"],["3.1477","695.4"],["3.1469","185.9"]],"asks":[],"timestamp":1756900932369,"update_id":50198633,"fetch_time":1756900932415}
{"symbol":"TONUSDT","bids":[["3.1501","652.0"],["3.1497","1150.2"]],"asks":[],"timestamp":1756900932389,"update_id":50198634,"fetch_time":1756900932436}
{"symbol":"TONUSDT","bids":[],"asks":[["3.1538","1473.4"]],"timestamp":1756900932410,"update_id":50198635,"fetch_time":1756900932459}
{"symbol":"TONUSDT","bids":[],"asks":[["3.1517","2779.0"]],"timestamp":1756900932450,"update_id":50198637,"fetch_time":1756900932496}
{"symbol":"TONUSDT","bids":[],"asks":[["3.1556","5400.4"],["3.1557","1268.8"]],"timestamp":1756900932529,"update_id":50198641,"fetch_time":1756900932577}
{"symbol":"TONUSDT","bids":[],"asks":[["3.1526","3113.8"]],"timestamp":1756900932550,"update_id":50198642,"fetch_time":1756900932600}
{"symbol":"TONUSDT","bids":[["3.1487","287.1"]],"asks":[],"timestamp":1756900932569,"update_id":50198643,"fetch_time":1756900932616}
{"symbol":"TONUSDT","bids":[],"asks":[["3.1540","1977.7"]],"timestamp":1756900932629,"update_id":50198644,"fetch_time":1756900932676}
{"symbol":"TONUSDT","bids":[],"asks":[["3.1547","2289.8"],["3.1557","952.0"]],"timestamp":1756900932709,"update_id":50198645,"fetch_time":1756900932758}
{"symbol":"TONUSDT","bids":[],"asks":[["3.1545","774.4"],["3.1550","1702.1"],["3.1556","5154.8"]],"timestamp":1756900932730,"update_id":50198646,"fetch_time":1756900932779}
{"symbol":"TONUSDT","bids":[],"asks":[["3.1544","3482.8"],["3.1555","2254.5"],["3.1556","3887.5"]],"timestamp":1756900932749,"update_id":50198647,"fetch_time":1756900932800}
{"symbol":"TONUSDT","bids":[],"asks":[["3.1514","1178.5"],["3.1515","1250.5"]],"timestamp":1756900932770,"update_id":50198648,"fetch_time":1756900932817}
{"symbol":"TONUSDT","bids":[["3.1510","0"],["3.1509","0"],["3.1508","0"],["3.1503","3.2"],["3.1502","420.0"],["3.1501","129.4"],["3.1500","723.1"],["3.1499","308.4"],["3.1498","1406.8"],["3.1495","890.8"],["3.1494","788.2"],["3.1493","556.8"],["3.1492","2029.9"],["3.1489","1850.2"],["3.1474","1850.1"],["3.1460","1657.9"],["3.1459","1653.8"],["3.1458","2513.7"]],"asks":[["3.1508","147.7"],["3.1509","20.0"],["3.1510","188.8"],["3.1512","247.4"],["3.1514","1479.6"],["3.1515","1228.7"],["3.1516","4386.8"],["3.1519","1223.2"],["3.1522","2002.4"],["3.1523","1660.2"],["3.1524","3306.6"],["3.1526","2474.5"],["3.1527","1558.2"],["3.1528","2599.6"],["3.1533","1693.8"],["3.1536","1518.4"],["3.1558","0"],["3.1559","0"],["3.1560","0"]],"timestamp":1756900932809,"update_id":50198649,"fetch_time":1756900932860}
{"symbol":"TONUSDT","bids":[["3.1507","0"],["3.1502","23.2"],["3.1500","335.8"],["3.1499","564.7"],["3.1496","2413.6"],["3.1495","652.4"],["3.1494","1097.7"],["3.1492","3316.6"],["3.1489","758.8"],["3.1480","832.5"],["3.1479","1501.9"],["3.1470","2831.5"],["3.1465","183.6"],["3.1463","7862.7"],["3.1462","1378.7"],["3.1458","3784.9"],["3.1457","647.8"]],"asks":[["3.1508","183.9"],["3.1509","39.9"],["3.1510","487.1"],["3.1511","1178.2"],["3.1512","1445.5"],["3.1513","358.7"],["3.1514","1533.8"],["3.1515","213.3"],["3.1516","3648.5"],["3.1517","1116.6"],["3.1518","1155.6"],["3.1519","1142.3"],["3.1520","1341.3"],["3.1526","2476.9"],["3.1528","3689.3"],["3.1532","1116.1"],["3.1533","1793.2"],["3.1534","1673.6"],["3.1535","806.9"],["3.1537","1364.6"],["3.1538","1417.1"],["3.1539","1251.9"],["3.1543","299.7"],["3.1544","6458.4"],["3.1545","1688.2"],["3.1546","2574.3"],["3.1548","2896.9"],["3.1549","1772.8"],["3.1553","462.4"]],"timestamp":1756900932830,"update_id":50198650,"fetch_time":1756900932877}
{"symbol":"TONUSDT","bids":[["3.1506","1.8"],["3.1505","3.2"],["3.1502","7.4"],["3.1500","505.8"],["3.1494","1429.2"],["3.1492","3300.8"],["3.1490","3447.5"],["3.1482","2306.2"],["3.1466","250.5"]],"asks":[["3.1507","51.6"],["3.1508","36.2"],["3.1510","672.8"],["3.1511","1151.4"],["3.1512","1448.7"],["3.1513","853.0"],["3.1514","2035.8"],["3.1515","908.2"],["3.1516","2737.8"],["3.1518","1105.6"],["3.1527","1705.6"],["3.1538","431.8"],["3.1542","2169.6"],["3.1543","297.7"],["3.1557","0"]],"timestamp":1756900932850,"update_id":50198651,"fetch_time":1756900932899}
{"symbol":"TONUSDT","bids":[],"asks":[["3.1509","185.7"],["3.1552","2565.6"]],"timestamp":1756900932950,"update_id":50198656,"fetch_time":1756900933001}
{"symbol":"TONUSDT","bids":[],"asks":[["3.1516","2238.2"],["3.1553","1729.8"],["3.1554","3825.8"]],"timestamp":1756900932969,"update_id":50198657,"fetch_time":1756900933019}
{"symbol":"TONUSDT","bids":[],"asks":[["3.1513","605.1"],["3.1516","2050.4"]],"timestamp":1756900932990,"update_id":50198658,"fetch_time":1756900933035}
{"symbol":"TONUSDT","bids":[],"asks":[["3.1509","8.3"],["3.1510","979.2"],["3.1515","277.2"]],"timestamp":1756900933010,"update_id":50198659,"fetch_time":1756900933062}
{"symbol":"TONUSDT","bids":[],"asks":[["3.1509","185.7"]],"timestamp":1756900933069,"update_id":50198662,"fetch_time":1756900933122}
{"symbol":"TONUSDT","bids":[],"asks":[["3.1509","8.3"]],"timestamp":1756900933130,"update_id":50198665,"fetch_time":1756900933181}
{"symbol":"TONUSDT","bids":[],"asks":[["3.1536","1520.2"]],"timestamp":1756900933170,"update_id":50198666,"fetch_time":1756900933219}
{"symbol":"TONUSDT","bids":[["3.1497","1279.2"]],"asks":[],"timestamp":1756900933250,"update_id":50198667,"fetch_time":1756900933295}
{"symbol":"TONUSDT","bids":[],"asks":[["3.1553","462.4"],["3.1554","5093.2"]],"timestamp":1756900933269,"update_id":50198668,"fetch_time":1756900933323}
{"symbol":"TONUSDT","bids":[],"asks":[["3.1510","1009.2"]],"timestamp":1756900933309,"update_id":50198669,"fetch_time":1756900933355}
{"symbol":"TONUSDT","bids":[["3.1493","1077.0"],["3.1492","3062.3"]],"asks":[],"timestamp":1756900933350,"update_id":50198670,"fetch_time":1756900933393}
{"symbol":"TONUSDT","bids":[],"asks":[["3.1508","31.6"],["3.1509","0"],["3.1510","993.2"],["3.1554","3825.8"],["3.1555","2254.6"],["3.1557","952.0"]],"timestamp":1756900933370,"update_id":50198671,"fetch_time":1756900933415}
{"symbol":"TONUSDT","bids":[["3.1493","838.6"]],"asks":[["3.1509","177.4"],["3.1512","2451.0"],["3.1513","888.5"],["3.1557","0"]],"timestamp":1756900933390,"update_id":50198672,"fetch_time":1756900933436}
{"symbol":"TONUSDT","bids":[],"asks":[["3.1509","0"],["3.1557","952.0"]],"timestamp":1756900933409,"update_id":50198673,"fetch_time":1756900933453}
{"symbol":"TONUSDT","bids":[["3.1465","576.3"]],"asks":[["3.1507","51.6"],["3.1509","177.4"],["3.1510","961.5"],["3.1511","1026.3"],["3.1524","3336.6"],["3.1526","2446.9"],["3.1542","2167.6"],["3.1557","0"]],"timestamp":1756900933430,"update_id":50198674,"fetch_time":1756900933475}
{"symbol":"TONUSDT","bids":[],"asks":[["3.1509","0"],["3.1542","2169.6"],["3.1557","952.0"]],"timestamp":1756900933449,"update_id":50198675,"fetch_time":1756900933496}
{"symbol":"TONUSDT","bids":[],"asks":[["3.1554","3825.8"],["3.1555","2254.6"]],"timestamp":1756900933509,"update_id":50198678,"fetch_time":1756900933556}
{"symbol":"TONUSDT","bids":[],"asks":[["3.1507","20.0"],["3.1511","995.0"],["3.1512","1975.0"],["3.1542","2167.6"]],"timestamp":1756900933529,"update_id":50198679,"fetch_time":1756900933578}
{"symbol":"TONUSDT","bids":[],"asks":[["3.1542","2169.6"]],"timestamp":1756900933549,"update_id":50198680,"fetch_time":1756900933595}
{"symbol":"TONUSDT","bids":[["3.1500","513.4"]],"asks":[],"timestamp":1756900933590,"update_id":50198681,"fetch_time":1756900933638}
{"symbol":"TONUSDT","bids":[["3.1480","1856.0"]],"asks":[],"timestamp":1756900933629,"update_id":50198683,"fetch_time":1756900933676}
{"symbol":"TONUSDT","bids":[["3.1499","813.3"]],"asks":[],"timestamp":1756900933690,"update_id":50198684,"fetch_time":1756900933736}
{"symbol":"TONUSDT","bids":[["3.1496","2500.1"]],"asks":[],"timestamp":1756900933769,"update_id":50198685,"fetch_time":1756900933817}
{"symbol":"TONUSDT","bids":[],"asks":[["3.1529","4652.7"]],"timestamp":1756900933810,"update_id":50198686,"fetch_time":1756900933855}
{"symbol":"TONUSDT","bids":[["3.1495","1047.3"],["3.1494","1429.2"]],"asks":[],"timestamp":1756900933830,"update_id":50198687,"fetch_time":1756900933877}
{"symbol":"TONUSDT","bids":[["3.1497","1150.2"],["3.1485","740.5"],["3.1469","241.1"]],"asks":[],"timestamp":1756900933850,"update_id":50198688,"fetch_time":1756900933899}
{"symbol":"TONUSDT","bids":[],"asks":[["3.1507","0"],["3.1512","972.7"],["3.1523","3530.2"],["3.1524","3366.6"],["3.1525","1242.6"],["3.1526","2416.9"],["3.1529","3852.7"],["3.1542","2167.6"],["3.1558","2954.1"]],"timestamp":1756900933869,"update_id":50198689,"fetch_time":1756900933920}
{"symbol":"TONUSDT","bids":[["3.1491","2405.1"],["3.1481","1153.2"],["3.1469","185.9"],["3.1457","838.8"]],"asks":[["3.1507","28.8"],["3.1512","1160.4"],["3.1513","1553.2"],["3.1524","3369.9"],["3.1532","1112.8"],["3.1542","2169.6"],["3.1558","0"]],"timestamp":1756900933890,"update_id":50198690,"fetch_time":1756900933937}
{"symbol":"TONUSDT","bids":[],"asks":[["3.1512","1223.8"]],"timestamp":1756900933909,"update_id":50198691,"fetch_time":1756900933959}
{"symbol":"TONUSDT","bids":[],"asks":[["3.1512","1505.5"]],"timestamp":1756900933930,"update_id":50198692,"fetch_time":1756900933980}
{"symbol":"TONUSDT","bids":[],"asks":[["3.1512","1974.8"],["3.1538","888.2"]],"timestamp":1756900933949,"update_id":50198693,"fetch_time":1756900934002}
{"symbol":"TONUSDT","bids":[],"asks":[["3.1513","802.2"],["3.1531","1511.1"]],"timestamp":1756900933990,"update_id":50198694,"fetch_time":1756900934035}
{"symbol":"TONUSDT","bids":[],"asks":[["3.1518","836.1"]],"timestamp":1756900934010,"update_id":50198695,"fetch_time":1756900934062}
{"symbol":"TONUSDT","bids":[["3.1477","935.2"]],"asks":[],"timestamp":1756900934050,"update_id":50198696,"fetch_time":1756900934095}
{"symbol":"TONUSDT","bids":[],"asks":[["3.1541","2002.3"]],"timestamp":1756900934089,"update_id":50198697,"fetch_time":1756900934137}
{"symbol":"TONUSDT","bids":[],"asks":[["3.1529","4514.1"],["3.1531","1835.8"],["3.1533","849.7"]],"timestamp":1756900934130,"update_id":50198698,"fetch_time":1756900934181}
{"symbol":"TONUSDT","bids":[],"asks":[["3.1514","2067.5"]],"timestamp":1756900934150,"update_id":50198699,"fetch_time":1756900934197}
{"symbol":"TONUSDT","bids":[],"asks":[["3.1540","1653.0"]],"timestamp":1756900934290,"update_id":50198701,"fetch_time":1756900934333}
{"symbol":"TONUSDT","bids":[],"asks":[["3.1510","962.8"],["3.1516","2039.9"]],"timestamp":1756900934309,"update_id":50198702,"fetch_time":1756900934355}
{"symbol":"TONUSDT","bids":[],"asks":[["3.1532","1456.6"]],"timestamp":1756900934409,"update_id":50198704,"fetch_time":1756900934453}
{"symbol":"TONUSDT","bids":[],"asks":[["3.1510","994.4"],["3.1530","1876.4"]],"timestamp":1756900934430,"update_id":50198705,"fetch_time":1756900934475}
{"symbol":"TONUSDT","bids":[],"asks":[["3.1520","2282.4"]],"timestamp":1756900934449,"update_id":50198706,"fetch_time":1756900934496}
{"symbol":"TONUSDT","bids":[["3.1494","1429.2"]],"asks":[],"timestamp":1756900934470,"update_id":50198707,"fetch_time":1756900934519}
{"symbol":"TONUSDT","bids":[],"asks":[["3.1511","1439.9"],["3.1512","1659.3"],["3.1513","729.2"]],"timestamp":1756900934489,"update_id":50198708,"fetch_time":1756900934535}
{"symbol":"TONUSDT","bids":[],"asks":[["3.1539","1251.9"]],"timestamp":1756900934570,"update_id":50198709,"fetch_time":1756900934617}
{"symbol":"TONUSDT","bids":[],"asks":[["3.1530","2143.8"]],"timestamp":1756900934629,"update_id":50198710,"fetch_time":1756900934676}
{"symbol":"TONUSDT","bids":[],"asks":[["3.1510","963.1"]],"timestamp":1756900934730,"update_id":50198711,"fetch_time":1756900934779}
{"symbol":"TONUSDT","bids":[],"asks":[["3.1537","4361.5"],["3.1556","890.1"]],"timestamp":1756900934750,"update_id":50198712,"fetch_time":1756900934807}
{"symbol":"TONUSDT","bids":[],"asks":[["3.1510","931.8"],["3.1511","963.9"],["3.1512","1381.5"],["3.1535","851.1"],["3.1536","2205.7"],["3.1545","1911.0"],["3.1554","2568.9"]],"timestamp":1756900934770,"update_id":50198713,"fetch_time":1756900934817}
{"symbol":"TONUSDT","bids":[],"asks":[["3.1510","585.3"],["3.1511","489.6"],["3.1554","3342.0"]],"timestamp":1756900934789,"update_id":50198714,"fetch_time":1756900934839}
{"symbol":"TONUSDT","bids":[["3.1494","1643.0"]],"asks":[],"timestamp":1756900934889,"update_id":50198716,"fetch_time":1756900934937}
{"symbol":"TONUSDT","bids":[],"asks":[["3.1508","0"],["3.1558","2954.1"]],"timestamp":1756900934970,"update_id":50198717,"fetch_time":1756900935019}
{"symbol":"TONUSDT","bids":[],"asks":[["3.1545","1644.0"],["3.1549","2280.4"]],"timestamp":1756900934989,"update_id":50198718,"fetch_time":1756900935040}
{"symbol":"TONUSDT","bids":[],"asks":[["3.1514","2266.3"],["3.1532","1454.8"]],"timestamp":1756900935170,"update_id":50198719,"fetch_time":1756900935220}
{"symbol":"TONUSDT","bids":[],"asks":[["3.1513","563.8"]],"timestamp":1756900935230,"update_id":50198720,"fetch_time":1756900935280}
{"symbol":"TONUSDT","bids":[],"asks":[["3.1507","31.0"],["3.1510","600.1"],["3.1513","760.9"],["3.1514","2069.3"]],"timestamp":1756900935450,"update_id":50198721,"fetch_time":1756900935503}
{"symbol":"TONUSDT","bids":[],"asks":[["3.1511","1243.4"]],"timestamp":1756900935550,"update_id":50198722,"fetch_time":1756900935596}
{"symbol":"TONUSDT","bids":[],"asks":[["3.1528","4531.0"],["3.1549","1439.3"]],"timestamp":1756900935570,"update_id":50198723,"fetch_time":1756900935616}
{"symbol":"TONUSDT","bids":[],"asks":[["3.1526","2893.0"]],"timestamp":1756900935589,"update_id":50198724,"fetch_time":1756900935633}
{"symbol":"TONUSDT","bids":[],"asks":[["3.1507","32.0"]],"timestamp":1756900935610,"update_id":50198725,"fetch_time":1756900935655}
{"symbol":"TONUSDT","bids":[],"asks":[["3.1510","630.1"]],"timestamp":1756900935789,"update_id":50198726,"fetch_time":1756900935839}
{"symbol":"TONUSDT","bids":[],"asks":[["3.1516","1801.9"]],"timestamp":1756900936010,"update_id":50198728,"fetch_time":1756900936058}
{"symbol":"TONUSDT","bids":[],"asks":[["3.1516","1803.7"]],"timestamp":1756900936170,"update_id":50198729,"fetch_time":1756900936215}
{"symbol":"TONUSDT","bids":[["3.1496","2585.6"]],"asks":[],"timestamp":1756900936209,"update_id":50198730,"fetch_time":1756900936263}
{"symbol":"TONUSDT","bids":[],"asks":[["3.1510","661.6"]],"timestamp":1756900936229,"update_id":50198731,"fetch_time":1756900936275}
{"symbol":"TONUSDT","bids":[],"asks":[["3.1510","1167.2"]],"timestamp":1756900936249,"update_id":50198732,"fetch_time":1756900936302}
{"symbol":"TONUSDT","bids":[],"asks":[["3.1513","811.9"]],"timestamp":1756900936309,"update_id":50198733,"fetch_time":1756900936356}
{"symbol":"TONUSDT","bids":[],"asks":[["3.1512","1393.9"],["3.1513","843.5"]],"timestamp":1756900936329,"update_id":50198734,"fetch_time":1756900936383}
{"symbol":"TONUSDT","bids":[],"asks":[["3.1513","1319.5"]],"timestamp":1756900936370,"update_id":50198735,"fetch_time":1756900936416}
{"symbol":"TONUSDT","bids":[],"asks":[["3.1539","1518.7"],["3.1549","931.7"]],"timestamp":1756900936469,"update_id":50198736,"fetch_time":1756900936525}
{"symbol":"TONUSDT","bids":[],"asks":[["3.1509","313.6"],["3.1548","2600.5"],["3.1558","0"]],"timestamp":1756900936490,"update_id":50198737,"fetch_time":1756900936535}
{"symbol":"TONUSDT","bids":[["3.1458","1979.1"]],"asks":[],"timestamp":1756900936829,"update_id":50198738,"fetch_time":1756900936878}
{"symbol":"TONUSDT","bids":[["3.1460","2091.4"]],"asks":[],"timestamp":1756900936849,"update_id":50198739,"fetch_time":1756900936893}
{"symbol":"TONUSDT","bids":[["3.1462","750.8"]],"asks":[],"timestamp":1756900936870,"update_id":50198740,"fetch_time":1756900936916}
{"symbol":"TONUSDT","bids":[],"asks":[["3.1510","1137.2"]],"timestamp":1756900937150,"update_id":50198741,"fetch_time":1756900937199}
{"symbol":"TONUSDT","bids":[],"asks":[["3.1513","1382.9"]],"timestamp":1756900937310,"update_id":50198742,"fetch_time":1756900937362}
{"symbol":"TONUSDT","bids":[],"asks":[["3.1541","2119.7"],["3.1542","2287.0"],["3.1543","415.1"],["3.1544","7065.6"],["3.1545","1761.4"],["3.1546","2691.7"],["3.1549","1049.1"],["3.1552","2683.0"],["3.1554","3459.4"],["3.1556","1007.5"]],"timestamp":1756900937429,"update_id":50198743,"fetch_time":1756900937481}
{"symbol":"TONUSDT","bids":[],"asks":[["3.1513","1185.8"],["3.1514","2303.2"]],"timestamp":1756900937650,"update_id":50198744,"fetch_time":1756900937705}
{"symbol":"TONUSDT","bids":[],"asks":[["3.1511","487.3"]],"timestamp":1756900937689,"update_id":50198746,"fetch_time":1756900937764}
{"symbol":"TONUSDT","bids":[],"asks":[["3.1520","1482.4"]],"timestamp":1756900937850,"update_id":50198748,"fetch_time":1756900937905}
{"symbol":"TONUSDT","bids":[],"asks":[["3.1513","1418.7"],["3.1514","2069.3"]],"timestamp":1756900938010,"update_id":50198749,"fetch_time":1756900938058}
{"symbol":"TONUSDT","bids":[],"asks":[["3.1510","1153.7"]],"timestamp":1756900938170,"update_id":50198750,"fetch_time":1756900938221}
{"symbol":"TONUSDT","bids":[],"asks":[["3.1514","2100.9"]],"timestamp":1756900938230,"update_id":50198751,"fetch_time":1756900938280}
{"symbol":"TONUSDT","bids":[["3.1497","1193.5"]],"asks":[],"timestamp":1756900938330,"update_id":50198752,"fetch_time":1756900938383}
{"symbol":"TONUSDT","bids":[["3.1506","0"],["3.1505","0"],["3.1504","5.0"],["3.1495","738.9"],["3.1493","1058.6"],["3.1486","623.1"],["3.1456","3788.9"],["3.1455","2146.1"]],"asks":[["3.1507","75.3"],["3.1508","177.4"],["3.1557","0"]],"timestamp":1756900938410,"update_id":50198753,"fetch_time":1756900938460}
{"symbol":"TONUSDT","bids":[["3.1504","1.8"],["3.1500","325.7"],["3.1494","1429.2"]],"asks":[["3.1506","28.8"],["3.1507","223.9"],["3.1508","0"],["3.1509","472.3"],["3.1510","1155.5"],["3.1512","1235.3"],["3.1513","1184.8"],["3.1521","2277.0"],["3.1526","1851.4"],["3.1530","2142.0"],["3.1541","2121.7"],["3.1542","2285.0"],["3.1556","2215.3"]],"timestamp":1756900938430,"update_id":50198754,"fetch_time":1756900938481}
{"symbol":"TONUSDT","bids":[["3.1499","1000.8"],["3.1493","838.6"]],"asks":[["3.1508","30.1"],["3.1509","915.8"],["3.1510","650.0"],["3.1511","1531.8"],["3.1512","2120.1"],["3.1513","1026.8"],["3.1556","0"]],"timestamp":1756900938470,"update_id":50198756,"fetch_time":1756900938525}
{"symbol":"TONUSDT","bids":[],"asks":[["3.1512","1472.3"],["3.1555","987.2"]],"timestamp":1756900938550,"update_id":50198760,"fetch_time":1756900938596}
{"symbol":"TONUSDT","bids":[],"asks":[["3.1555","2254.5"]],"timestamp":1756900938590,"update_id":50198762,"fetch_time":1756900938634}
